#######################################################################
# +-----------------------------------------------------------------+ #
# |                            BO3 object                           | #
# +-----------------------------------------------------------------+ #
#######################################################################

# This is the config file of a custom object.
# If you add this object correctly to your BiomeConfigs, it will spawn in the world.

# This is the creator of this BO3 object
Author: BO3 BulkEdit (by LanToaster)

# A short description of this BO3 object
Description: This Object was Created with BO3_BulkEdit

# The BO3 version, don't change this! It can be used by external applications to do a version check.
Version: 3

# The settings mode, WriteAll, WriteWithoutComments or WriteDisable. See WorldConfig.
SettingsMode: WriteDisable


#######################################################################
# +-----------------------------------------------------------------+ #
# |                          Main settings                          | #
# +-----------------------------------------------------------------+ #
#######################################################################

# This needs to be set to true to spawn the object in the Tree and Sapling resources.
Tree: true

# The frequency of the BO3 from 1 to 200. Tries this many times to spawn this BO3 when using the CustomObject(...) resource.
# Ignored by Tree(..), Sapling(..) and CustomStructure(..)
Frequency: 1

# The rarity of the BO3 from 0 to 100. Each spawn attempt has rarity% chance to succeed when using the CustomObject(...) resource.
# Ignored by Tree(..), Sapling(..) and CustomStructure(..)
Rarity: 100.0

# If you set this to true, the BO3 will be placed with a random rotation.
RotateRandomly: true

# The spawn height of the BO3 - randomY, highestBlock or highestSolid)Block.
SpawnHeight: randomY

# The height limits for the BO3.
MinHeight: 92

MaxHeight: 256

# Objects can have other objects attacthed to it: branches. Branches can also
# have branches attached to it, which can also have branches, etc. This is the
# maximum branch depth for this objects.
MaxBranchDepth: 10

# When spawned with the UseWorld keyword, this BO3 should NOT spawn in the following biomes.
# If you writer.write the BO3 name directly in the BiomeConfigs, this will be ignored.
ExcludedBiomes: All


#######################################################################
# +-----------------------------------------------------------------+ #
# |                      Source block settings                      | #
# +-----------------------------------------------------------------+ #
#######################################################################

# The block(s) the BO3 should spawn in.
SourceBlocks: AIR,minecraft:grass,minecraft:dirt

# The maximum percentage of the BO3 that can be outside the SourceBlock.
# The BO3 won't be placed on a location with more blocks outside the SourceBlock than this percentage.
MaxPercentageOutsideSourceBlock: 100

# What to do when a block is about to be placed outside the SourceBlock? (dontPlace, placeAnyway)
OutsideSourceBlock: placeAnyway


#######################################################################
# +-----------------------------------------------------------------+ #
# |                              Blocks                             | #
# +-----------------------------------------------------------------+ #
#######################################################################

# All the blocks used in the BO3 are listed here. Possible blocks:
# Block(x,y,z,id[.data][,nbtfile.nbt)
# RandomBlock(x,y,z,id[:data][,nbtfile.nbt],chance[,id[:data][,nbtfile.nbt],chance[,...]])
# So RandomBlock(0,0,0,CHEST,chest.nbt,50,CHEST,anotherchest.nbt,100) will spawn a chest at
# the BO3 origin, and give it a 50% chance to have the contents of chest.nbt, or, if that
# fails, a 100% percent chance to have the contents of anotherchest.nbt.
Block(3,0,-4,minecraft:log2:0)
Block(-3,0,-3,minecraft:log2:0)
Block(-2,0,-3,minecraft:log2:0)
Block(2,0,-3,minecraft:log2:0)
Block(3,0,-3,minecraft:log2:0)
Block(-2,0,-1,minecraft:log2:0)
Block(-1,0,-1,minecraft:log2:0)
Block(4,0,0,minecraft:log2:0)
Block(-1,0,2,minecraft:log2:0)
Block(0,0,2,minecraft:log2:0)
Block(-1,0,3,minecraft:log2:0)
Block(-2,1,-3,minecraft:log2:0)
Block(2,1,-3,minecraft:log2:0)
Block(-2,1,-2,minecraft:log2:0)
Block(-2,1,-1,minecraft:log2:0)
Block(1,1,0,minecraft:log2:0)
Block(4,1,0,minecraft:log2:0)
Block(0,1,2,minecraft:log2:0)
Block(2,2,-3,minecraft:log2:0)
Block(2,2,-2,minecraft:log2:0)
Block(-2,2,-1,minecraft:log2:0)
Block(1,2,0,minecraft:log2:0)
Block(3,2,0,minecraft:log2:0)
Block(4,2,0,minecraft:log2:0)
Block(0,2,2,minecraft:log2:0)
Block(1,3,-2,minecraft:log2:0)
Block(2,3,-2,minecraft:log2:0)
Block(-2,3,-1,minecraft:log2:0)
Block(-1,3,-1,minecraft:log2:0)
Block(1,3,0,minecraft:log2:0)
Block(3,3,0,minecraft:log2:0)
Block(0,3,1,minecraft:log2:0)
Block(0,3,2,minecraft:log2:0)
Block(0,4,-2,minecraft:log2:0)
Block(1,4,-2,minecraft:log2:0)
Block(-1,4,-1,minecraft:log2:0)
Block(0,4,-1,minecraft:log2:0)
Block(1,4,-1,minecraft:log2:0)
Block(2,4,-1,minecraft:log2:0)
Block(-1,4,0,minecraft:log2:0)
Block(0,4,0,minecraft:log2:0)
Block(1,4,0,minecraft:log2:0)
Block(2,4,0,minecraft:log2:0)
Block(3,4,0,minecraft:log2:0)
Block(0,4,1,minecraft:log2:0)
Block(1,4,1,minecraft:log2:0)
Block(2,4,1,minecraft:log2:0)
Block(5,5,-3,minecraft:leaves2:0)
Block(0,5,-2,minecraft:log2:0)
Block(1,5,-2,minecraft:log2:0)
Block(-1,5,-1,minecraft:log2:0)
Block(0,5,-1,minecraft:log2:0)
Block(1,5,-1,minecraft:log2:0)
Block(2,5,-1,minecraft:log2:0)
Block(-1,5,0,minecraft:log2:0)
Block(0,5,0,minecraft:log2:0)
Block(1,5,0,minecraft:log2:0)
Block(2,5,0,minecraft:log2:0)
Block(0,5,1,minecraft:log2:0)
Block(1,5,1,minecraft:log2:0)
Block(-3,6,-4,minecraft:leaves2:0)
Block(0,6,-4,minecraft:leaves2:0)
Block(2,6,-4,minecraft:leaves2:0)
Block(4,6,-3,minecraft:leaves2:0)
Block(-1,6,-2,minecraft:leaves2:0)
Block(0,6,-2,minecraft:log2:0)
Block(0,6,-1,minecraft:log2:0)
Block(1,6,-1,minecraft:log2:0)
Block(2,6,-1,minecraft:log2:0)
Block(-3,6,0,minecraft:leaves2:0)
Block(-1,6,0,minecraft:log2:0)
Block(0,6,0,minecraft:log2:0)
Block(1,6,0,minecraft:log2:0)
Block(2,6,0,minecraft:log2:0)
Block(5,6,0,minecraft:leaves2:0)
Block(0,6,1,minecraft:log2:0)
Block(1,6,1,minecraft:log2:0)
Block(4,6,1,minecraft:leaves2:0)
Block(-2,6,2,minecraft:leaves2:0)
Block(1,6,3,minecraft:leaves2:0)
Block(4,6,3,minecraft:leaves2:0)
Block(0,7,-4,minecraft:leaves2:0)
Block(-2,7,-3,minecraft:leaves2:0)
Block(-1,7,-3,minecraft:leaves2:0)
Block(1,7,-3,minecraft:leaves2:0)
Block(3,7,-3,minecraft:leaves2:0)
Block(4,7,-3,minecraft:leaves2:0)
Block(-5,7,-2,minecraft:leaves2:0)
Block(-2,7,-2,minecraft:leaves2:0)
Block(-1,7,-2,minecraft:leaves2:0)
Block(0,7,-2,minecraft:leaves2:0)
Block(1,7,-2,minecraft:leaves2:0)
Block(3,7,-2,minecraft:leaves2:0)
Block(-2,7,-1,minecraft:leaves2:0)
Block(-1,7,-1,minecraft:leaves2:0)
Block(0,7,-1,minecraft:log2:0)
Block(1,7,-1,minecraft:log2:0)
Block(2,7,-1,minecraft:leaves2:0)
Block(3,7,-1,minecraft:leaves2:0)
Block(-2,7,0,minecraft:leaves2:0)
Block(-1,7,0,minecraft:log2:0)
Block(0,7,0,minecraft:log2:0)
Block(1,7,0,minecraft:log2:0)
Block(2,7,0,minecraft:log2:0)
Block(5,7,0,minecraft:leaves2:0)
Block(-1,7,1,minecraft:leaves2:0)
Block(0,7,1,minecraft:leaves2:0)
Block(1,7,1,minecraft:log2:0)
Block(2,7,1,minecraft:leaves2:0)
Block(3,7,1,minecraft:leaves2:0)
Block(-2,7,2,minecraft:leaves2:0)
Block(0,7,2,minecraft:leaves2:0)
Block(1,7,2,minecraft:leaves2:0)
Block(1,7,3,minecraft:leaves2:0)
Block(3,7,3,minecraft:leaves2:0)
Block(4,7,3,minecraft:leaves2:0)
Block(-2,7,4,minecraft:leaves2:0)
Block(-2,7,5,minecraft:leaves2:0)
Block(1,7,5,minecraft:leaves2:0)
Block(-1,8,-4,minecraft:leaves2:0)
Block(2,8,-4,minecraft:leaves2:0)
Block(-1,8,-3,minecraft:leaves2:0)
Block(0,8,-3,minecraft:leaves2:0)
Block(3,8,-3,minecraft:leaves2:0)
Block(-4,8,-2,minecraft:leaves2:0)
Block(-3,8,-2,minecraft:leaves2:0)
Block(-2,8,-2,minecraft:leaves2:0)
Block(-1,8,-2,minecraft:leaves2:0)
Block(0,8,-2,minecraft:leaves2:0)
Block(1,8,-2,minecraft:leaves2:0)
Block(2,8,-2,minecraft:leaves2:0)
Block(3,8,-2,minecraft:leaves2:0)
Block(4,8,-2,minecraft:leaves2:0)
Block(-3,8,-1,minecraft:leaves2:0)
Block(-2,8,-1,minecraft:leaves2:0)
Block(-1,8,-1,minecraft:leaves2:0)
Block(0,8,-1,minecraft:log2:0)
Block(1,8,-1,minecraft:leaves2:0)
Block(2,8,-1,minecraft:leaves2:0)
Block(3,8,-1,minecraft:leaves2:0)
Block(5,8,-1,minecraft:leaves2:0)
Block(-2,8,0,minecraft:leaves2:0)
Block(-1,8,0,minecraft:log2:0)
Block(0,8,0,minecraft:log2:0)
Block(1,8,0,minecraft:log2:0)
Block(2,8,0,minecraft:log2:0)
Block(3,8,0,minecraft:leaves2:0)
Block(4,8,0,minecraft:leaves2:0)
Block(-1,8,1,minecraft:leaves2:0)
Block(0,8,1,minecraft:leaves2:0)
Block(1,8,1,minecraft:log2:0)
Block(2,8,1,minecraft:leaves2:0)
Block(3,8,1,minecraft:leaves2:0)
Block(-1,8,2,minecraft:leaves2:0)
Block(0,8,2,minecraft:leaves2:0)
Block(1,8,2,minecraft:leaves2:0)
Block(2,8,2,minecraft:leaves2:0)
Block(3,8,2,minecraft:leaves2:0)
Block(-4,8,3,minecraft:leaves2:0)
Block(-1,8,3,minecraft:leaves2:0)
Block(2,8,3,minecraft:leaves2:0)
Block(1,8,4,minecraft:leaves2:0)
Block(2,9,-4,minecraft:leaves2:0)
Block(-2,9,-3,minecraft:leaves2:0)
Block(-1,9,-3,minecraft:leaves2:0)
Block(0,9,-3,minecraft:leaves2:0)
Block(2,9,-3,minecraft:leaves2:0)
Block(-3,9,-2,minecraft:leaves2:0)
Block(-2,9,-2,minecraft:leaves2:0)
Block(-1,9,-2,minecraft:leaves2:0)
Block(0,9,-2,minecraft:leaves2:0)
Block(1,9,-2,minecraft:leaves2:0)
Block(2,9,-2,minecraft:leaves2:0)
Block(3,9,-2,minecraft:leaves2:0)
Block(-3,9,-1,minecraft:leaves2:0)
Block(-2,9,-1,minecraft:leaves2:0)
Block(-1,9,-1,minecraft:leaves2:0)
Block(0,9,-1,minecraft:log2:0)
Block(1,9,-1,minecraft:leaves2:0)
Block(2,9,-1,minecraft:leaves2:0)
Block(3,9,-1,minecraft:leaves2:0)
Block(4,9,-1,minecraft:leaves2:0)
Block(-3,9,0,minecraft:leaves2:0)
Block(-2,9,0,minecraft:leaves2:0)
Block(-1,9,0,minecraft:log2:0)
Block(0,9,0,minecraft:log2:0)
Block(1,9,0,minecraft:log2:0)
Block(2,9,0,minecraft:log2:0)
Block(3,9,0,minecraft:leaves2:0)
Block(-2,9,1,minecraft:leaves2:0)
Block(-1,9,1,minecraft:leaves2:0)
Block(0,9,1,minecraft:leaves2:0)
Block(1,9,1,minecraft:log2:0)
Block(2,9,1,minecraft:leaves2:0)
Block(3,9,1,minecraft:leaves2:0)
Block(-3,9,2,minecraft:leaves2:0)
Block(-1,9,2,minecraft:leaves2:0)
Block(1,9,2,minecraft:leaves2:0)
Block(2,9,2,minecraft:leaves2:0)
Block(5,9,2,minecraft:leaves2:0)
Block(-4,9,3,minecraft:leaves2:0)
Block(0,9,3,minecraft:leaves2:0)
Block(1,9,3,minecraft:leaves2:0)
Block(1,9,4,minecraft:leaves2:0)
Block(0,10,-5,minecraft:leaves2:0)
Block(-1,10,-3,minecraft:leaves2:0)
Block(2,10,-3,minecraft:leaves2:0)
Block(4,10,-3,minecraft:leaves2:0)
Block(-2,10,-2,minecraft:leaves2:0)
Block(-1,10,-2,minecraft:leaves2:0)
Block(0,10,-2,minecraft:leaves2:0)
Block(1,10,-2,minecraft:leaves2:0)
Block(2,10,-2,minecraft:leaves2:0)
Block(-3,10,-1,minecraft:leaves2:0)
Block(-2,10,-1,minecraft:leaves2:0)
Block(-1,10,-1,minecraft:leaves2:0)
Block(0,10,-1,minecraft:log2:0)
Block(1,10,-1,minecraft:leaves2:0)
Block(2,10,-1,minecraft:leaves2:0)
Block(3,10,-1,minecraft:leaves2:0)
Block(-4,10,0,minecraft:leaves2:0)
Block(-2,10,0,minecraft:leaves2:0)
Block(-1,10,0,minecraft:log2:0)
Block(0,10,0,minecraft:log2:0)
Block(1,10,0,minecraft:log2:0)
Block(2,10,0,minecraft:log2:0)
Block(3,10,0,minecraft:leaves2:0)
Block(-2,10,1,minecraft:leaves2:0)
Block(-1,10,1,minecraft:leaves2:0)
Block(0,10,1,minecraft:leaves2:0)
Block(1,10,1,minecraft:leaves2:0)
Block(2,10,1,minecraft:leaves2:0)
Block(3,10,1,minecraft:leaves2:0)
Block(-3,10,2,minecraft:leaves2:0)
Block(-2,10,2,minecraft:leaves2:0)
Block(-1,10,2,minecraft:leaves2:0)
Block(0,10,2,minecraft:leaves2:0)
Block(1,10,2,minecraft:leaves2:0)
Block(5,10,2,minecraft:leaves2:0)
Block(-1,10,3,minecraft:leaves2:0)
Block(4,10,3,minecraft:leaves2:0)
Block(0,11,-4,minecraft:leaves2:0)
Block(-3,11,-3,minecraft:leaves2:0)
Block(0,11,-3,minecraft:leaves2:0)
Block(1,11,-3,minecraft:leaves2:0)
Block(-2,11,-2,minecraft:leaves2:0)
Block(0,11,-2,minecraft:leaves2:0)
Block(1,11,-2,minecraft:leaves2:0)
Block(3,11,-2,minecraft:leaves2:0)
Block(-1,11,-1,minecraft:leaves2:0)
Block(0,11,-1,minecraft:log2:0)
Block(1,11,-1,minecraft:leaves2:0)
Block(2,11,-1,minecraft:leaves2:0)
Block(3,11,-1,minecraft:leaves2:0)
Block(4,11,-1,minecraft:leaves2:0)
Block(-3,11,0,minecraft:leaves2:0)
Block(-2,11,0,minecraft:leaves2:0)
Block(-1,11,0,minecraft:leaves2:0)
Block(0,11,0,minecraft:log2:0)
Block(1,11,0,minecraft:log2:0)
Block(2,11,0,minecraft:leaves2:0)
Block(-1,11,1,minecraft:leaves2:0)
Block(0,11,1,minecraft:leaves2:0)
Block(1,11,1,minecraft:leaves2:0)
Block(2,11,1,minecraft:leaves2:0)
Block(3,11,1,minecraft:leaves2:0)
Block(-1,11,2,minecraft:leaves2:0)
Block(2,11,2,minecraft:leaves2:0)
Block(3,11,2,minecraft:leaves2:0)
Block(4,11,2,minecraft:leaves2:0)
Block(3,11,3,minecraft:leaves2:0)
Block(1,11,4,minecraft:leaves2:0)
Block(-3,12,-3,minecraft:leaves2:0)
Block(-1,12,-3,minecraft:leaves2:0)
Block(0,12,-3,minecraft:leaves2:0)
Block(-1,12,-2,minecraft:leaves2:0)
Block(0,12,-2,minecraft:leaves2:0)
Block(1,12,-2,minecraft:leaves2:0)
Block(2,12,-2,minecraft:leaves2:0)
Block(-1,12,-1,minecraft:leaves2:0)
Block(0,12,-1,minecraft:log2:0)
Block(1,12,-1,minecraft:leaves2:0)
Block(2,12,-1,minecraft:leaves2:0)
Block(3,12,-1,minecraft:leaves2:0)
Block(-1,12,0,minecraft:leaves2:0)
Block(0,12,0,minecraft:log2:0)
Block(1,12,0,minecraft:log2:0)
Block(2,12,0,minecraft:leaves2:0)
Block(3,12,0,minecraft:leaves2:0)
Block(-2,12,1,minecraft:leaves2:0)
Block(0,12,1,minecraft:leaves2:0)
Block(1,12,1,minecraft:leaves2:0)
Block(3,12,1,minecraft:leaves2:0)
Block(4,12,1,minecraft:leaves2:0)
Block(1,12,2,minecraft:leaves2:0)
Block(3,12,2,minecraft:leaves2:0)
Block(-2,12,3,minecraft:leaves2:0)
Block(1,12,3,minecraft:leaves2:0)
Block(0,13,-4,minecraft:leaves2:0)
Block(-2,13,-2,minecraft:leaves2:0)
Block(-1,13,-2,minecraft:leaves2:0)
Block(0,13,-2,minecraft:leaves2:0)
Block(1,13,-2,minecraft:leaves2:0)
Block(3,13,-2,minecraft:leaves2:0)
Block(-1,13,-1,minecraft:leaves2:0)
Block(0,13,-1,minecraft:leaves2:0)
Block(1,13,-1,minecraft:leaves2:0)
Block(2,13,-1,minecraft:leaves2:0)
Block(-3,13,0,minecraft:leaves2:0)
Block(-1,13,0,minecraft:leaves2:0)
Block(0,13,0,minecraft:log2:0)
Block(1,13,0,minecraft:log2:0)
Block(3,13,0,minecraft:leaves2:0)
Block(-1,13,1,minecraft:leaves2:0)
Block(0,13,1,minecraft:leaves2:0)
Block(1,13,1,minecraft:leaves2:0)
Block(2,13,1,minecraft:leaves2:0)
Block(1,13,2,minecraft:leaves2:0)
Block(2,13,2,minecraft:leaves2:0)
Block(3,13,2,minecraft:leaves2:0)
Block(-2,13,3,minecraft:leaves2:0)
Block(0,13,4,minecraft:leaves2:0)
Block(0,14,-4,minecraft:leaves2:0)
Block(0,14,-3,minecraft:leaves2:0)
Block(0,14,-2,minecraft:leaves2:0)
Block(3,14,-2,minecraft:leaves2:0)
Block(-2,14,-1,minecraft:leaves2:0)
Block(-1,14,-1,minecraft:leaves2:0)
Block(0,14,-1,minecraft:leaves2:0)
Block(1,14,-1,minecraft:leaves2:0)
Block(-3,14,0,minecraft:leaves2:0)
Block(-1,14,0,minecraft:leaves2:0)
Block(0,14,0,minecraft:log2:0)
Block(1,14,0,minecraft:leaves2:0)
Block(2,14,0,minecraft:leaves2:0)
Block(-1,14,1,minecraft:leaves2:0)
Block(0,14,1,minecraft:leaves2:0)
Block(1,14,1,minecraft:leaves2:0)
Block(4,14,1,minecraft:leaves2:0)
Block(-2,14,2,minecraft:leaves2:0)
Block(-1,14,2,minecraft:leaves2:0)
Block(2,14,2,minecraft:leaves2:0)
Block(-2,14,3,minecraft:leaves2:0)
Block(2,14,3,minecraft:leaves2:0)
Block(0,14,4,minecraft:leaves2:0)
Block(-2,15,-3,minecraft:leaves2:0)
Block(0,15,-3,minecraft:leaves2:0)
Block(0,15,-2,minecraft:leaves2:0)
Block(0,15,-1,minecraft:leaves2:0)
Block(1,15,-1,minecraft:leaves2:0)
Block(2,15,-1,minecraft:leaves2:0)
Block(3,15,-1,minecraft:leaves2:0)
Block(-2,15,0,minecraft:leaves2:0)
Block(-1,15,0,minecraft:leaves2:0)
Block(0,15,0,minecraft:log2:0)
Block(1,15,0,minecraft:leaves2:0)
Block(2,15,0,minecraft:leaves2:0)
Block(0,15,1,minecraft:leaves2:0)
Block(1,15,1,minecraft:leaves2:0)
Block(2,15,1,minecraft:leaves2:0)
Block(-2,15,2,minecraft:leaves2:0)
Block(0,15,2,minecraft:leaves2:0)
Block(1,15,2,minecraft:leaves2:0)
Block(2,15,2,minecraft:leaves2:0)
Block(0,15,3,minecraft:leaves2:0)
Block(3,15,3,minecraft:leaves2:0)
Block(0,15,4,minecraft:leaves2:0)
Block(-2,16,-3,minecraft:leaves2:0)
Block(1,16,-3,minecraft:leaves2:0)
Block(0,16,-2,minecraft:leaves2:0)
Block(-1,16,-1,minecraft:leaves2:0)
Block(0,16,-1,minecraft:leaves2:0)
Block(1,16,-1,minecraft:leaves2:0)
Block(3,16,-1,minecraft:leaves2:0)
Block(-2,16,0,minecraft:leaves2:0)
Block(-1,16,0,minecraft:leaves2:0)
Block(0,16,0,minecraft:log2:0)
Block(1,16,0,minecraft:leaves2:0)
Block(2,16,0,minecraft:leaves2:0)
Block(-3,16,1,minecraft:leaves2:0)
Block(-1,16,1,minecraft:leaves2:0)
Block(0,16,1,minecraft:leaves2:0)
Block(1,16,1,minecraft:leaves2:0)
Block(-2,16,2,minecraft:leaves2:0)
Block(0,16,2,minecraft:leaves2:0)
Block(1,16,2,minecraft:leaves2:0)
Block(2,16,2,minecraft:leaves2:0)
Block(-1,16,3,minecraft:leaves2:0)
Block(0,16,3,minecraft:leaves2:0)
Block(1,16,3,minecraft:leaves2:0)
Block(-2,17,-3,minecraft:leaves2:0)
Block(-1,17,-3,minecraft:leaves2:0)
Block(1,17,-3,minecraft:leaves2:0)
Block(-1,17,-2,minecraft:leaves2:0)
Block(1,17,-2,minecraft:leaves2:0)
Block(0,17,-1,minecraft:leaves2:0)
Block(1,17,-1,minecraft:leaves2:0)
Block(2,17,-1,minecraft:leaves2:0)
Block(-1,17,0,minecraft:leaves2:0)
Block(0,17,0,minecraft:log2:0)
Block(1,17,0,minecraft:leaves2:0)
Block(2,17,0,minecraft:leaves2:0)
Block(-3,17,1,minecraft:leaves2:0)
Block(-2,17,1,minecraft:leaves2:0)
Block(-1,17,1,minecraft:leaves2:0)
Block(1,17,1,minecraft:leaves2:0)
Block(2,17,1,minecraft:leaves2:0)
Block(-1,17,2,minecraft:leaves2:0)
Block(0,17,3,minecraft:leaves2:0)
Block(-1,18,-3,minecraft:leaves2:0)
Block(-2,18,-2,minecraft:leaves2:0)
Block(-1,18,-2,minecraft:leaves2:0)
Block(1,18,-2,minecraft:leaves2:0)
Block(0,18,-1,minecraft:leaves2:0)
Block(1,18,-1,minecraft:leaves2:0)
Block(2,18,-1,minecraft:leaves2:0)
Block(-1,18,0,minecraft:leaves2:0)
Block(0,18,0,minecraft:log2:0)
Block(1,18,0,minecraft:leaves2:0)
Block(2,18,0,minecraft:leaves2:0)
Block(-2,18,1,minecraft:leaves2:0)
Block(0,18,1,minecraft:leaves2:0)
Block(1,18,1,minecraft:leaves2:0)
Block(0,18,2,minecraft:leaves2:0)
Block(-1,19,-3,minecraft:leaves2:0)
Block(1,19,-3,minecraft:leaves2:0)
Block(-1,19,-2,minecraft:leaves2:0)
Block(0,19,-2,minecraft:leaves2:0)
Block(1,19,-2,minecraft:leaves2:0)
Block(0,19,-1,minecraft:leaves2:0)
Block(1,19,-1,minecraft:leaves2:0)
Block(-1,19,0,minecraft:leaves2:0)
Block(0,19,0,minecraft:log2:0)
Block(1,19,0,minecraft:leaves2:0)
Block(2,19,0,minecraft:leaves2:0)
Block(-1,19,1,minecraft:leaves2:0)
Block(0,19,1,minecraft:leaves2:0)
Block(1,19,1,minecraft:leaves2:0)
Block(-1,19,2,minecraft:leaves2:0)
Block(2,19,2,minecraft:leaves2:0)
Block(1,20,-3,minecraft:leaves2:0)
Block(-1,20,-2,minecraft:leaves2:0)
Block(0,20,-2,minecraft:leaves2:0)
Block(-3,20,-1,minecraft:leaves2:0)
Block(-1,20,-1,minecraft:leaves2:0)
Block(0,20,-1,minecraft:leaves2:0)
Block(1,20,-1,minecraft:leaves2:0)
Block(3,20,-1,minecraft:leaves2:0)
Block(-1,20,0,minecraft:leaves2:0)
Block(0,20,0,minecraft:log2:0)
Block(1,20,0,minecraft:leaves2:0)
Block(0,20,1,minecraft:leaves2:0)
Block(2,20,2,minecraft:leaves2:0)
Block(1,21,-3,minecraft:leaves2:0)
Block(-1,21,-2,minecraft:leaves2:0)
Block(0,21,-2,minecraft:leaves2:0)
Block(1,21,-2,minecraft:leaves2:0)
Block(-3,21,-1,minecraft:leaves2:0)
Block(-2,21,-1,minecraft:leaves2:0)
Block(-1,21,-1,minecraft:leaves2:0)
Block(0,21,-1,minecraft:leaves2:0)
Block(1,21,-1,minecraft:leaves2:0)
Block(3,21,-1,minecraft:leaves2:0)
Block(-1,21,0,minecraft:leaves2:0)
Block(0,21,0,minecraft:log2:0)
Block(1,21,0,minecraft:leaves2:0)
Block(2,21,0,minecraft:leaves2:0)
Block(-1,21,1,minecraft:leaves2:0)
Block(0,21,1,minecraft:leaves2:0)
Block(1,21,1,minecraft:leaves2:0)
Block(0,21,2,minecraft:leaves2:0)
Block(0,22,-2,minecraft:leaves2:0)
Block(-2,22,-1,minecraft:leaves2:0)
Block(-1,22,-1,minecraft:leaves2:0)
Block(0,22,-1,minecraft:leaves2:0)
Block(1,22,-1,minecraft:leaves2:0)
Block(2,22,-1,minecraft:leaves2:0)
Block(-1,22,0,minecraft:leaves2:0)
Block(0,22,0,minecraft:log2:0)
Block(1,22,0,minecraft:leaves2:0)
Block(0,22,1,minecraft:leaves2:0)
Block(-2,22,2,minecraft:leaves2:0)
Block(-1,23,-2,minecraft:leaves2:0)
Block(0,23,-2,minecraft:leaves2:0)
Block(-1,23,-1,minecraft:leaves2:0)
Block(0,23,-1,minecraft:leaves2:0)
Block(1,23,-1,minecraft:leaves2:0)
Block(2,23,-1,minecraft:leaves2:0)
Block(-1,23,0,minecraft:leaves2:0)
Block(0,23,0,minecraft:log2:0)
Block(1,23,0,minecraft:leaves2:0)
Block(-1,23,1,minecraft:leaves2:0)
Block(0,23,1,minecraft:leaves2:0)
Block(1,23,1,minecraft:leaves2:0)
Block(-2,23,2,minecraft:leaves2:0)
Block(0,24,-3,minecraft:leaves2:0)
Block(-3,24,-1,minecraft:leaves2:0)
Block(-1,24,-1,minecraft:leaves2:0)
Block(0,24,-1,minecraft:leaves2:0)
Block(1,24,-1,minecraft:leaves2:0)
Block(-2,24,0,minecraft:leaves2:0)
Block(-1,24,0,minecraft:leaves2:0)
Block(0,24,0,minecraft:log2:0)
Block(1,24,0,minecraft:leaves2:0)
Block(2,24,0,minecraft:leaves2:0)
Block(-1,24,1,minecraft:leaves2:0)
Block(0,24,1,minecraft:leaves2:0)
Block(1,24,1,minecraft:leaves2:0)
Block(2,24,1,minecraft:leaves2:0)
Block(0,25,-2,minecraft:leaves2:0)
Block(2,25,-2,minecraft:leaves2:0)
Block(-2,25,-1,minecraft:leaves2:0)
Block(-1,25,-1,minecraft:leaves2:0)
Block(0,25,-1,minecraft:leaves2:0)
Block(1,25,-1,minecraft:leaves2:0)
Block(-1,25,0,minecraft:leaves2:0)
Block(0,25,0,minecraft:log2:0)
Block(1,25,0,minecraft:leaves2:0)
Block(2,25,0,minecraft:leaves2:0)
Block(-1,25,1,minecraft:leaves2:0)
Block(1,25,1,minecraft:leaves2:0)
Block(0,26,-2,minecraft:leaves2:0)
Block(1,26,-2,minecraft:leaves2:0)
Block(-1,26,-1,minecraft:leaves2:0)
Block(0,26,-1,minecraft:leaves2:0)
Block(-2,26,0,minecraft:leaves2:0)
Block(-1,26,0,minecraft:leaves2:0)
Block(0,26,0,minecraft:log2:0)
Block(1,26,0,minecraft:leaves2:0)
Block(0,26,1,minecraft:leaves2:0)
Block(1,26,2,minecraft:leaves2:0)
Block(0,27,-2,minecraft:leaves2:0)
Block(-1,27,-1,minecraft:leaves2:0)
Block(0,27,-1,minecraft:leaves2:0)
Block(1,27,-1,minecraft:leaves2:0)
Block(-1,27,0,minecraft:leaves2:0)
Block(0,27,0,minecraft:log2:0)
Block(1,27,0,minecraft:leaves2:0)
Block(-1,27,1,minecraft:leaves2:0)
Block(0,27,1,minecraft:leaves2:0)
Block(1,27,1,minecraft:leaves2:0)
Block(-2,28,-1,minecraft:leaves2:0)
Block(0,28,-1,minecraft:leaves2:0)
Block(-1,28,0,minecraft:leaves2:0)
Block(0,28,0,minecraft:log2:0)
Block(1,28,0,minecraft:leaves2:0)
Block(0,28,1,minecraft:leaves2:0)
Block(-1,28,2,minecraft:leaves2:0)
Block(0,29,-2,minecraft:leaves2:0)
Block(-1,29,-1,minecraft:leaves2:0)
Block(0,29,-1,minecraft:leaves2:0)
Block(1,29,-1,minecraft:leaves2:0)
Block(-1,29,0,minecraft:leaves2:0)
Block(0,29,0,minecraft:leaves2:0)
Block(1,29,0,minecraft:leaves2:0)
Block(-1,29,1,minecraft:leaves2:0)
Block(0,29,1,minecraft:leaves2:0)
Block(0,30,-1,minecraft:leaves2:0)
Block(1,30,-1,minecraft:leaves2:0)
Block(-1,30,0,minecraft:leaves2:0)
Block(0,30,0,minecraft:leaves2:0)
Block(0,30,1,minecraft:leaves2:0)
Block(0,31,-1,minecraft:leaves2:0)
Block(-1,31,0,minecraft:leaves2:0)
Block(0,31,0,minecraft:leaves2:0)
Block(1,31,0,minecraft:leaves2:0)
Block(0,32,0,minecraft:leaves2:0)
Block(0,32,1,minecraft:leaves2:0)
Block(0,33,-1,minecraft:leaves2:0)
Block(0,33,0,minecraft:leaves2:0)
Block(1,33,0,minecraft:leaves2:0)
Block(0,34,-1,minecraft:leaves2:0)
Block(0,34,0,minecraft:leaves2:0)
Block(0,35,0,minecraft:leaves2:0)
Block(0,36,0,minecraft:leaves2:0)

#######################################################################
# +-----------------------------------------------------------------+ #
# |                            BO3 checks                           | #
# +-----------------------------------------------------------------+ #
#######################################################################

BlockCheck(0,2,0,AIR)
BlockCheck(-4,0,-4,Solid)
BlockCheck(-3,0,-4,Solid)
BlockCheck(-2,0,-4,Solid)
BlockCheck(-1,0,-4,Solid)
BlockCheck(0,0,-4,Solid)
BlockCheck(1,0,-4,Solid)
BlockCheck(2,0,-4,Solid)
BlockCheck(3,0,-4,Solid)
BlockCheck(4,0,-4,Solid)
BlockCheck(-4,0,-3,Solid)
BlockCheck(-3,0,-3,Solid)
BlockCheck(-2,0,-3,Solid)
BlockCheck(-1,0,-3,Solid)
BlockCheck(0,0,-3,Solid)
BlockCheck(1,0,-3,Solid)
BlockCheck(2,0,-3,Solid)

BlockCheck(3,0,-3,Solid)
BlockCheck(4,0,-3,Solid)
BlockCheck(-4,0,-2,Solid)
BlockCheck(-3,0,-2,Solid)
BlockCheck(-2,0,-2,Solid)
BlockCheck(-1,0,-2,Solid)
BlockCheck(0,0,-2,Solid)
BlockCheck(1,0,-2,Solid)
BlockCheck(2,0,-2,Solid)
BlockCheck(3,0,-2,Solid)
BlockCheck(4,0,-2,Solid)
BlockCheck(-4,0,-1,Solid)
BlockCheck(-3,0,-1,Solid)
BlockCheck(-2,0,-1,Solid)
BlockCheck(-1,0,-1,Solid)

BlockCheck(0,0,-1,Solid)
BlockCheck(1,0,-1,Solid)
BlockCheck(2,0,-1,Solid)
BlockCheck(3,0,-1,Solid)
BlockCheck(4,0,-1,Solid)
BlockCheck(-4,0,0,Solid)
BlockCheck(-3,0,0,Solid)
BlockCheck(-2,0,0,Solid)
BlockCheck(-1,0,0,Solid)
BlockCheck(0,0,0,Solid)
BlockCheck(1,0,0,Solid)
BlockCheck(2,0,0,Solid)
BlockCheck(3,0,0,Solid)
BlockCheck(4,0,0,Solid)
BlockCheck(-4,0,1,Solid)
BlockCheck(-3,0,1,Solid)

BlockCheck(-2,0,1,Solid)
BlockCheck(-1,0,1,Solid)
BlockCheck(0,0,1,Solid)
BlockCheck(1,0,1,Solid)
BlockCheck(2,0,1,Solid)
BlockCheck(3,0,1,Solid)
BlockCheck(4,0,1,Solid)
BlockCheck(-4,0,2,Solid)
BlockCheck(-3,0,2,Solid)
BlockCheck(-2,0,2,Solid)
BlockCheck(-1,0,2,Solid)
BlockCheck(0,0,2,Solid)
BlockCheck(1,0,2,Solid)
BlockCheck(2,0,2,Solid)
BlockCheck(3,0,2,Solid)
BlockCheck(4,0,2,Solid)
BlockCheck(-4,0,3,Solid)
BlockCheck(-3,0,3,Solid)
BlockCheck(-2,0,3,Solid)
BlockCheck(-1,0,3,Solid)
BlockCheck(0,0,3,Solid)
BlockCheck(1,0,3,Solid)
BlockCheck(2,0,3,Solid)
BlockCheck(3,0,3,Solid)
BlockCheck(4,0,3,Solid)
BlockCheck(-4,0,4,Solid)
BlockCheck(-3,0,4,Solid)
BlockCheck(-2,0,4,Solid)
BlockCheck(-1,0,4,Solid)
BlockCheck(0,0,4,Solid)
BlockCheck(1,0,4,Solid)
BlockCheck(2,0,4,Solid)
BlockCheck(3,0,4,Solid)
BlockCheck(4,0,4,Solid)
# Examples:
#   LightCheck(0,0,0,0,1)          Require almost complete darkness just below the object


#######################################################################
# +-----------------------------------------------------------------+ #
# |                             Branches                            | #
# +-----------------------------------------------------------------+ #
#######################################################################

# Branches are objects that will spawn when this object spawns when it is used in
# the CustomStructure resource. Branches can also have branches, making complex
# structures possible. See the wiki for more details.

# Regular Branches spawn each branch with an independent chance of spawning.
# Branch(x,y,z,branchName,rotation,chance[,anotherBranchName,rotation,chance[,...]][IndividualChance])
# branchName - name of the object to spawn.
# rotation - NORTH, SOUTH, EAST or WEST.
# IndividualChance - The chance each branch has to spawn, assumed to be 100 when left blank

# Weighted Branches spawn branches with a dependent chance of spawning.
# WeightedBranch(x,y,z,branchName,rotation,chance[,anotherBranchName,rotation,chance[,...]][MaxChanceOutOf])
# MaxChanceOutOf - The chance all branches have to spawn out of, assumed to be 100 when left blank
