#######################################################################
# +-----------------------------------------------------------------+ #
# |                            BO3 object                           | #
# +-----------------------------------------------------------------+ #
#######################################################################

# This is the config file of a custom object.
# If you add this object correctly to your BiomeConfigs, it will spawn in the world.

# This is the creator of this BO3 object
Author: BO3 BulkEdit (by LanToaster)

# A short description of this BO3 object
Description: This Object was Created with BO3_BulkEdit

# The BO3 version, don't change this! It can be used by external applications to do a version check.
Version: 3

# The settings mode, WriteAll, WriteWithoutComments or WriteDisable. See WorldConfig.
SettingsMode: WriteDisable


#######################################################################
# +-----------------------------------------------------------------+ #
# |                          Main settings                          | #
# +-----------------------------------------------------------------+ #
#######################################################################

# This needs to be set to true to spawn the object in the Tree and Sapling resources.
Tree: true

# The frequency of the BO3 from 1 to 200. Tries this many times to spawn this BO3 when using the CustomObject(...) resource.
# Ignored by Tree(..), Sapling(..) and CustomStructure(..)
Frequency: 1

# The rarity of the BO3 from 0 to 100. Each spawn attempt has rarity% chance to succeed when using the CustomObject(...) resource.
# Ignored by Tree(..), Sapling(..) and CustomStructure(..)
Rarity: 100.0

# If you set this to true, the BO3 will be placed with a random rotation.
RotateRandomly: true

# The spawn height of the BO3 - randomY, highestBlock or highestSolid)Block.
SpawnHeight: randomY

# The height limits for the BO3.
MinHeight: 92

MaxHeight: 256

# Objects can have other objects attacthed to it: branches. Branches can also
# have branches attached to it, which can also have branches, etc. This is the
# maximum branch depth for this objects.
MaxBranchDepth: 10

# When spawned with the UseWorld keyword, this BO3 should NOT spawn in the following biomes.
# If you writer.write the BO3 name directly in the BiomeConfigs, this will be ignored.
ExcludedBiomes: All


#######################################################################
# +-----------------------------------------------------------------+ #
# |                      Source block settings                      | #
# +-----------------------------------------------------------------+ #
#######################################################################

# The block(s) the BO3 should spawn in.
SourceBlocks: AIR,minecraft:grass,minecraft:dirt

# The maximum percentage of the BO3 that can be outside the SourceBlock.
# The BO3 won't be placed on a location with more blocks outside the SourceBlock than this percentage.
MaxPercentageOutsideSourceBlock: 100

# What to do when a block is about to be placed outside the SourceBlock? (dontPlace, placeAnyway)
OutsideSourceBlock: placeAnyway


#######################################################################
# +-----------------------------------------------------------------+ #
# |                              Blocks                             | #
# +-----------------------------------------------------------------+ #
#######################################################################

# All the blocks used in the BO3 are listed here. Possible blocks:
# Block(x,y,z,id[.data][,nbtfile.nbt)
# RandomBlock(x,y,z,id[:data][,nbtfile.nbt],chance[,id[:data][,nbtfile.nbt],chance[,...]])
# So RandomBlock(0,0,0,CHEST,chest.nbt,50,CHEST,anotherchest.nbt,100) will spawn a chest at
# the BO3 origin, and give it a 50% chance to have the contents of chest.nbt, or, if that
# fails, a 100% percent chance to have the contents of anotherchest.nbt.
Block(-2,0,-4,biomesoplenty:log_1:5)
Block(-1,0,-4,biomesoplenty:log_1:5)
Block(0,0,-4,biomesoplenty:log_1:5)
Block(-3,0,-3,biomesoplenty:log_1:5)
Block(-2,0,-3,biomesoplenty:log_1:5)
Block(-1,0,-3,biomesoplenty:log_1:5)
Block(0,0,-3,biomesoplenty:log_1:5)
Block(1,0,-3,biomesoplenty:log_1:5)
Block(-4,0,-2,biomesoplenty:log_1:5)
Block(-3,0,-2,biomesoplenty:log_1:5)
Block(-2,0,-2,biomesoplenty:log_1:5)
Block(-1,0,-2,biomesoplenty:log_1:5)
Block(0,0,-2,biomesoplenty:log_1:5)
Block(1,0,-2,biomesoplenty:log_1:5)
Block(2,0,-2,biomesoplenty:log_1:5)
Block(-4,0,-1,biomesoplenty:log_1:5)
Block(-3,0,-1,biomesoplenty:log_1:5)
Block(-2,0,-1,biomesoplenty:log_1:5)
Block(-1,0,-1,biomesoplenty:log_1:5)
Block(0,0,-1,biomesoplenty:log_1:5)
Block(1,0,-1,biomesoplenty:log_1:5)
Block(2,0,-1,biomesoplenty:log_1:5)
Block(3,0,-1,biomesoplenty:log_1:5)
Block(-4,0,0,biomesoplenty:leaves_0:11)
Block(-3,0,0,biomesoplenty:log_1:5)
Block(-2,0,0,biomesoplenty:log_1:5)
Block(-1,0,0,biomesoplenty:log_1:5)
Block(0,0,0,biomesoplenty:log_1:5)
Block(1,0,0,biomesoplenty:log_1:5)
Block(2,0,0,biomesoplenty:log_1:5)
Block(3,0,0,biomesoplenty:log_1:5)
Block(-3,0,1,biomesoplenty:log_1:5)
Block(-2,0,1,biomesoplenty:log_1:5)
Block(-1,0,1,biomesoplenty:log_1:5)
Block(0,0,1,biomesoplenty:log_1:5)
Block(1,0,1,biomesoplenty:log_1:5)
Block(2,0,1,biomesoplenty:log_1:5)
Block(-2,0,2,biomesoplenty:log_1:5)
Block(-1,0,2,biomesoplenty:log_1:5)
Block(0,0,2,biomesoplenty:log_1:5)
Block(1,0,2,biomesoplenty:log_1:5)
Block(2,0,2,biomesoplenty:leaves_0:11)
Block(-2,0,3,biomesoplenty:log_1:5)
Block(-1,0,3,biomesoplenty:log_1:5)
Block(0,0,3,biomesoplenty:log_1:5)
Block(1,0,3,biomesoplenty:log_1:5)
Block(-2,1,-4,biomesoplenty:log_1:5)
Block(-1,1,-4,biomesoplenty:log_1:5)
Block(-2,1,-3,biomesoplenty:log_1:5)
Block(-1,1,-3,biomesoplenty:log_1:5)
Block(0,1,-3,biomesoplenty:log_1:5)
Block(-3,1,-2,biomesoplenty:log_1:5)
Block(-2,1,-2,biomesoplenty:log_1:5)
Block(-1,1,-2,biomesoplenty:log_1:5)
Block(0,1,-2,biomesoplenty:log_1:5)
Block(1,1,-2,biomesoplenty:log_1:5)
Block(2,1,-2,biomesoplenty:log_1:5)
Block(-3,1,-1,biomesoplenty:log_1:5)
Block(-2,1,-1,biomesoplenty:log_1:5)
Block(-1,1,-1,biomesoplenty:log_1:5)
Block(0,1,-1,biomesoplenty:log_1:5)
Block(1,1,-1,biomesoplenty:log_1:5)
Block(2,1,-1,biomesoplenty:log_1:5)
Block(-3,1,0,biomesoplenty:log_1:5)
Block(-2,1,0,biomesoplenty:log_1:5)
Block(-1,1,0,biomesoplenty:log_1:5)
Block(0,1,0,biomesoplenty:log_1:5)
Block(1,1,0,biomesoplenty:log_1:5)
Block(2,1,0,biomesoplenty:log_1:5)
Block(-3,1,1,biomesoplenty:leaves_0:11)
Block(-2,1,1,biomesoplenty:log_1:5)
Block(-1,1,1,biomesoplenty:log_1:5)
Block(0,1,1,biomesoplenty:log_1:5)
Block(1,1,1,biomesoplenty:log_1:5)
Block(2,1,1,biomesoplenty:log_1:5)
Block(-1,1,2,biomesoplenty:log_1:5)
Block(0,1,2,biomesoplenty:log_1:5)
Block(1,1,2,biomesoplenty:log_1:5)
Block(2,1,2,biomesoplenty:leaves_0:11)
Block(-1,1,3,biomesoplenty:log_1:5)
Block(0,1,3,biomesoplenty:log_1:5)
Block(-2,2,-3,biomesoplenty:log_1:5)
Block(-1,2,-3,biomesoplenty:log_1:5)
Block(0,2,-3,biomesoplenty:log_1:5)
Block(-2,2,-2,biomesoplenty:log_1:5)
Block(-1,2,-2,biomesoplenty:log_1:5)
Block(0,2,-2,biomesoplenty:log_1:5)
Block(1,2,-2,biomesoplenty:log_1:5)
Block(-3,2,-1,biomesoplenty:log_1:5)
Block(-2,2,-1,biomesoplenty:log_1:5)
Block(-1,2,-1,biomesoplenty:log_1:5)
Block(0,2,-1,biomesoplenty:log_1:5)
Block(1,2,-1,biomesoplenty:log_1:5)
Block(2,2,-1,biomesoplenty:log_1:5)
Block(-3,2,0,biomesoplenty:log_1:5)
Block(-2,2,0,biomesoplenty:log_1:5)
Block(-1,2,0,biomesoplenty:log_1:5)
Block(0,2,0,biomesoplenty:log_1:5)
Block(1,2,0,biomesoplenty:log_1:5)
Block(2,2,0,biomesoplenty:log_1:5)
Block(-3,2,1,biomesoplenty:leaves_0:11)
Block(-2,2,1,biomesoplenty:log_1:5)
Block(-1,2,1,biomesoplenty:log_1:5)
Block(0,2,1,biomesoplenty:log_1:5)
Block(1,2,1,biomesoplenty:log_1:5)
Block(2,2,1,biomesoplenty:leaves_0:11)
Block(-1,2,2,biomesoplenty:log_1:5)
Block(0,2,2,biomesoplenty:log_1:5)
Block(1,2,2,biomesoplenty:log_1:5)
Block(-1,2,3,biomesoplenty:log_1:5)
Block(-2,3,-3,biomesoplenty:log_1:5)
Block(-1,3,-3,biomesoplenty:log_1:5)
Block(-2,3,-2,biomesoplenty:log_1:5)
Block(-1,3,-2,biomesoplenty:log_1:5)
Block(0,3,-2,biomesoplenty:log_1:5)
Block(1,3,-2,biomesoplenty:log_1:5)
Block(-3,3,-1,biomesoplenty:log_1:5)
Block(-2,3,-1,biomesoplenty:log_1:5)
Block(-1,3,-1,biomesoplenty:log_1:5)
Block(0,3,-1,biomesoplenty:log_1:5)
Block(1,3,-1,biomesoplenty:log_1:5)
Block(2,3,-1,biomesoplenty:log_1:5)
Block(-4,3,0,biomesoplenty:log_1:5)
Block(-3,3,0,biomesoplenty:log_1:5)
Block(-2,3,0,biomesoplenty:log_1:5)
Block(-1,3,0,biomesoplenty:log_1:5)
Block(0,3,0,biomesoplenty:log_1:5)
Block(1,3,0,biomesoplenty:log_1:5)
Block(2,3,0,biomesoplenty:log_1:5)
Block(-2,3,1,biomesoplenty:log_1:5)
Block(-1,3,1,biomesoplenty:log_1:5)
Block(0,3,1,biomesoplenty:log_1:5)
Block(1,3,1,biomesoplenty:log_1:5)
Block(2,3,1,biomesoplenty:leaves_0:11)
Block(-2,3,2,biomesoplenty:leaves_0:11)
Block(-1,3,2,biomesoplenty:log_1:5)
Block(0,3,2,biomesoplenty:log_1:5)
Block(1,3,2,biomesoplenty:log_1:5)
Block(-2,4,-5,biomesoplenty:leaves_0:11)
Block(-2,4,-4,biomesoplenty:log_1:5)
Block(-1,4,-4,biomesoplenty:leaves_0:11)
Block(-2,4,-3,biomesoplenty:log_1:5)
Block(-1,4,-3,biomesoplenty:log_1:5)
Block(-3,4,-2,biomesoplenty:log_1:5)
Block(-2,4,-2,biomesoplenty:log_1:5)
Block(-1,4,-2,biomesoplenty:log_1:5)
Block(0,4,-2,biomesoplenty:log_1:5)
Block(-3,4,-1,biomesoplenty:log_1:5)
Block(-2,4,-1,biomesoplenty:log_1:5)
Block(-1,4,-1,biomesoplenty:log_1:5)
Block(0,4,-1,biomesoplenty:log_1:5)
Block(1,4,-1,biomesoplenty:log_1:5)
Block(2,4,-1,biomesoplenty:log_1:5)
Block(-4,4,0,biomesoplenty:log_1:5)
Block(-3,4,0,biomesoplenty:log_1:5)
Block(-2,4,0,biomesoplenty:log_1:5)
Block(-1,4,0,biomesoplenty:log_1:5)
Block(0,4,0,biomesoplenty:log_1:5)
Block(1,4,0,biomesoplenty:log_1:5)
Block(2,4,0,biomesoplenty:leaves_0:11)
Block(-2,4,1,biomesoplenty:log_1:5)
Block(-1,4,1,biomesoplenty:log_1:5)
Block(0,4,1,biomesoplenty:log_1:5)
Block(1,4,1,biomesoplenty:log_1:5)
Block(-2,4,2,biomesoplenty:log_1:5)
Block(-1,4,2,biomesoplenty:log_1:5)
Block(0,4,2,biomesoplenty:log_1:5)
Block(-2,4,3,biomesoplenty:leaves_0:11)
Block(-2,5,-6,biomesoplenty:log_1:5)
Block(-3,5,-5,biomesoplenty:leaves_0:11)
Block(-2,5,-5,biomesoplenty:log_1:5)
Block(-1,5,-5,biomesoplenty:log_1:5)
Block(-2,5,-4,biomesoplenty:log_1:5)
Block(-1,5,-4,biomesoplenty:log_1:5)
Block(0,5,-4,biomesoplenty:leaves_0:11)
Block(-3,5,-3,biomesoplenty:log_1:5)
Block(-2,5,-3,biomesoplenty:log_1:5)
Block(-1,5,-3,biomesoplenty:log_1:5)
Block(0,5,-3,biomesoplenty:log_1:5)
Block(-3,5,-2,biomesoplenty:log_1:5)
Block(-2,5,-2,biomesoplenty:log_1:5)
Block(-1,5,-2,biomesoplenty:log_1:5)
Block(0,5,-2,biomesoplenty:log_1:5)
Block(-4,5,-1,biomesoplenty:log_1:5)
Block(-3,5,-1,biomesoplenty:log_1:5)
Block(-2,5,-1,biomesoplenty:log_1:5)
Block(-1,5,-1,biomesoplenty:log_1:5)
Block(0,5,-1,biomesoplenty:log_1:5)
Block(1,5,-1,biomesoplenty:log_1:5)
Block(-4,5,0,biomesoplenty:log_1:5)
Block(-3,5,0,biomesoplenty:log_1:5)
Block(-2,5,0,biomesoplenty:log_1:5)
Block(-1,5,0,biomesoplenty:log_1:5)
Block(0,5,0,biomesoplenty:log_1:5)
Block(1,5,0,biomesoplenty:log_1:5)
Block(2,5,0,biomesoplenty:leaves_0:11)
Block(-3,5,1,biomesoplenty:log_1:5)
Block(-2,5,1,biomesoplenty:log_1:5)
Block(-1,5,1,biomesoplenty:log_1:5)
Block(0,5,1,biomesoplenty:log_1:5)
Block(-2,5,2,biomesoplenty:log_1:5)
Block(-1,5,2,biomesoplenty:log_1:5)
Block(0,5,2,biomesoplenty:log_1:5)
Block(-2,5,3,biomesoplenty:leaves_0:11)
Block(-1,6,-7,biomesoplenty:log_1:5)
Block(-3,6,-6,biomesoplenty:leaves_0:11)
Block(-2,6,-6,biomesoplenty:log_1:5)
Block(-1,6,-6,biomesoplenty:log_1:5)
Block(0,6,-6,biomesoplenty:log_1:5)
Block(-3,6,-5,biomesoplenty:log_1:5)
Block(-2,6,-5,biomesoplenty:log_1:5)
Block(-1,6,-5,biomesoplenty:log_1:5)
Block(0,6,-5,biomesoplenty:log_1:5)
Block(-3,6,-4,biomesoplenty:log_1:5)
Block(-2,6,-4,biomesoplenty:log_1:5)
Block(-1,6,-4,biomesoplenty:log_1:5)
Block(0,6,-4,biomesoplenty:log_1:5)
Block(-3,6,-3,biomesoplenty:log_1:5)
Block(-2,6,-3,biomesoplenty:log_1:5)
Block(-1,6,-3,biomesoplenty:log_1:5)
Block(0,6,-3,biomesoplenty:log_1:5)
Block(1,6,-3,biomesoplenty:leaves_0:11)
Block(-4,6,-2,biomesoplenty:log_1:5)
Block(-3,6,-2,biomesoplenty:log_1:5)
Block(-2,6,-2,biomesoplenty:log_1:5)
Block(-1,6,-2,biomesoplenty:log_1:5)
Block(0,6,-2,biomesoplenty:log_1:5)
Block(-4,6,-1,biomesoplenty:log_1:5)
Block(-3,6,-1,biomesoplenty:log_1:5)
Block(-2,6,-1,biomesoplenty:log_1:5)
Block(-1,6,-1,biomesoplenty:log_1:5)
Block(0,6,-1,biomesoplenty:log_1:5)
Block(1,6,-1,biomesoplenty:log_1:5)
Block(2,6,-1,biomesoplenty:leaves_0:11)
Block(-4,6,0,biomesoplenty:log_1:5)
Block(-3,6,0,biomesoplenty:log_1:5)
Block(-2,6,0,biomesoplenty:log_1:5)
Block(-1,6,0,biomesoplenty:log_1:5)
Block(0,6,0,biomesoplenty:log_1:5)
Block(1,6,0,biomesoplenty:log_1:5)
Block(-3,6,1,biomesoplenty:log_1:5)
Block(-2,6,1,biomesoplenty:log_1:5)
Block(-1,6,1,biomesoplenty:log_1:5)
Block(0,6,1,biomesoplenty:log_1:5)
Block(-2,6,2,biomesoplenty:log_1:5)
Block(-1,6,2,biomesoplenty:log_1:5)
Block(0,6,2,biomesoplenty:log_1:5)
Block(-1,6,3,biomesoplenty:leaves_0:11)
Block(-1,7,-10,biomesoplenty:leaves_0:11)
Block(0,7,-10,biomesoplenty:leaves_0:11)
Block(-1,7,-9,biomesoplenty:log_1:5)
Block(0,7,-9,biomesoplenty:log_1:5)
Block(-1,7,-8,biomesoplenty:log_1:5)
Block(0,7,-8,biomesoplenty:log_1:5)
Block(3,7,-8,biomesoplenty:leaves_0:11)
Block(-3,7,-7,biomesoplenty:leaves_0:11)
Block(-2,7,-7,biomesoplenty:log_1:5)
Block(-1,7,-7,biomesoplenty:log_1:5)
Block(0,7,-7,biomesoplenty:log_1:5)
Block(1,7,-7,biomesoplenty:log_1:5)
Block(-3,7,-6,biomesoplenty:log_1:5)
Block(-2,7,-6,biomesoplenty:log_1:5)
Block(-1,7,-6,biomesoplenty:log_1:5)
Block(0,7,-6,biomesoplenty:log_1:5)
Block(1,7,-6,biomesoplenty:log_1:5)
Block(-3,7,-5,biomesoplenty:log_1:5)
Block(-2,7,-5,biomesoplenty:log_1:5)
Block(-1,7,-5,biomesoplenty:log_1:5)
Block(0,7,-5,biomesoplenty:log_1:5)
Block(1,7,-5,biomesoplenty:log_1:5)
Block(-3,7,-4,biomesoplenty:log_1:5)
Block(-2,7,-4,biomesoplenty:log_1:5)
Block(-1,7,-4,biomesoplenty:log_1:5)
Block(0,7,-4,biomesoplenty:log_1:5)
Block(-3,7,-3,biomesoplenty:log_1:5)
Block(-2,7,-3,biomesoplenty:log_1:5)
Block(-1,7,-3,biomesoplenty:log_1:5)
Block(0,7,-3,biomesoplenty:log_1:5)
Block(-4,7,-2,biomesoplenty:log_1:5)
Block(-3,7,-2,biomesoplenty:log_1:5)
Block(-2,7,-2,biomesoplenty:log_1:5)
Block(-1,7,-2,biomesoplenty:log_1:5)
Block(0,7,-2,biomesoplenty:log_1:5)
Block(1,7,-2,biomesoplenty:leaves_0:11)
Block(-4,7,-1,biomesoplenty:log_1:5)
Block(-3,7,-1,biomesoplenty:log_1:5)
Block(-2,7,-1,biomesoplenty:log_1:5)
Block(-1,7,-1,biomesoplenty:log_1:5)
Block(0,7,-1,biomesoplenty:log_1:5)
Block(1,7,-1,biomesoplenty:log_1:5)
Block(-4,7,0,biomesoplenty:log_1:5)
Block(-3,7,0,biomesoplenty:log_1:5)
Block(-2,7,0,biomesoplenty:log_1:5)
Block(-1,7,0,biomesoplenty:log_1:5)
Block(0,7,0,biomesoplenty:log_1:5)
Block(1,7,0,biomesoplenty:log_1:5)
Block(-4,7,1,biomesoplenty:log_1:5)
Block(-3,7,1,biomesoplenty:log_1:5)
Block(-2,7,1,biomesoplenty:log_1:5)
Block(-1,7,1,biomesoplenty:log_1:5)
Block(0,7,1,biomesoplenty:log_1:5)
Block(-3,7,2,biomesoplenty:log_1:5)
Block(-2,7,2,biomesoplenty:log_1:5)
Block(-1,7,2,biomesoplenty:log_1:5)
Block(0,7,2,biomesoplenty:log_1:5)
Block(0,7,3,biomesoplenty:leaves_0:11)
Block(0,8,-16,biomesoplenty:leaves_0:11)
Block(-4,8,-11,biomesoplenty:leaves_0:11)
Block(0,8,-10,biomesoplenty:log_1:5)
Block(1,8,-10,biomesoplenty:leaves_0:11)
Block(-2,8,-9,biomesoplenty:leaves_0:11)
Block(-1,8,-9,biomesoplenty:log_1:5)
Block(0,8,-9,biomesoplenty:log_1:5)
Block(-2,8,-8,biomesoplenty:log_1:5)
Block(-1,8,-8,biomesoplenty:log_1:5)
Block(0,8,-8,biomesoplenty:log_1:5)
Block(1,8,-8,biomesoplenty:log_1:5)
Block(3,8,-8,biomesoplenty:leaves_0:11)
Block(-3,8,-7,biomesoplenty:leaves_0:11)
Block(-2,8,-7,biomesoplenty:log_1:5)
Block(-1,8,-7,biomesoplenty:log_1:5)
Block(0,8,-7,biomesoplenty:log_1:5)
Block(1,8,-7,biomesoplenty:log_1:5)
Block(-2,8,-6,biomesoplenty:log_1:5)
Block(-1,8,-6,biomesoplenty:log_1:5)
Block(0,8,-6,biomesoplenty:log_1:5)
Block(1,8,-6,biomesoplenty:log_1:5)
Block(-2,8,-5,biomesoplenty:log_1:5)
Block(-1,8,-5,biomesoplenty:log_1:5)
Block(0,8,-5,biomesoplenty:log_1:5)
Block(-3,8,-4,biomesoplenty:log_1:5)
Block(-2,8,-4,biomesoplenty:log_1:5)
Block(-1,8,-4,biomesoplenty:log_1:5)
Block(-3,8,-3,biomesoplenty:log_1:5)
Block(-2,8,-3,biomesoplenty:log_1:5)
Block(-1,8,-3,biomesoplenty:log_1:5)
Block(-4,8,-2,biomesoplenty:log_1:5)
Block(-3,8,-2,biomesoplenty:log_1:5)
Block(-2,8,-2,biomesoplenty:log_1:5)
Block(-1,8,-2,biomesoplenty:log_1:5)
Block(0,8,-2,biomesoplenty:log_1:5)
Block(1,8,-2,biomesoplenty:leaves_0:11)
Block(-5,8,-1,biomesoplenty:log_1:5)
Block(-4,8,-1,biomesoplenty:log_1:5)
Block(-3,8,-1,biomesoplenty:log_1:5)
Block(-2,8,-1,biomesoplenty:log_1:5)
Block(-1,8,-1,biomesoplenty:log_1:5)
Block(0,8,-1,biomesoplenty:log_1:5)
Block(-4,8,0,biomesoplenty:log_1:5)
Block(-3,8,0,biomesoplenty:log_1:5)
Block(-2,8,0,biomesoplenty:log_1:5)
Block(-1,8,0,biomesoplenty:log_1:5)
Block(0,8,0,biomesoplenty:log_1:5)
Block(1,8,0,biomesoplenty:log_1:5)
Block(-4,8,1,biomesoplenty:log_1:5)
Block(-3,8,1,biomesoplenty:log_1:5)
Block(-2,8,1,biomesoplenty:log_1:5)
Block(-1,8,1,biomesoplenty:log_1:5)
Block(0,8,1,biomesoplenty:log_1:5)
Block(-3,8,2,biomesoplenty:log_1:5)
Block(-2,8,2,biomesoplenty:log_1:5)
Block(-1,8,2,biomesoplenty:log_1:5)
Block(0,8,2,biomesoplenty:leaves_0:11)
Block(0,9,-16,biomesoplenty:leaves_0:11)
Block(-3,9,-14,biomesoplenty:leaves_0:11)
Block(3,9,-14,biomesoplenty:leaves_0:11)
Block(-4,9,-11,biomesoplenty:leaves_0:11)
Block(0,9,-11,biomesoplenty:log_1:5)
Block(1,9,-11,biomesoplenty:leaves_0:11)
Block(4,9,-11,biomesoplenty:leaves_0:11)
Block(-1,9,-10,biomesoplenty:log_1:5)
Block(0,9,-10,biomesoplenty:log_1:5)
Block(1,9,-10,biomesoplenty:log_1:5)
Block(-2,9,-9,biomesoplenty:log_1:5)
Block(-1,9,-9,biomesoplenty:log_1:5)
Block(0,9,-9,biomesoplenty:log_1:5)
Block(1,9,-9,biomesoplenty:log_1:5)
Block(-3,9,-8,biomesoplenty:leaves_0:11)
Block(-2,9,-8,biomesoplenty:log_1:5)
Block(-1,9,-8,biomesoplenty:log_1:5)
Block(0,9,-8,biomesoplenty:log_1:5)
Block(1,9,-8,biomesoplenty:log_1:5)
Block(3,9,-8,biomesoplenty:leaves_0:11)
Block(-2,9,-7,biomesoplenty:leaves_0:11)
Block(-1,9,-7,biomesoplenty:log_1:5)
Block(0,9,-7,biomesoplenty:log_1:5)
Block(-1,9,-6,biomesoplenty:log_1:5)
Block(-2,9,-4,biomesoplenty:log_1:5)
Block(-3,9,-3,biomesoplenty:log_1:5)
Block(-2,9,-3,biomesoplenty:log_1:5)
Block(-1,9,-3,biomesoplenty:leaves_0:11)
Block(-4,9,-2,biomesoplenty:log_1:5)
Block(-3,9,-2,biomesoplenty:log_1:5)
Block(-2,9,-2,biomesoplenty:log_1:5)
Block(-1,9,-2,biomesoplenty:log_1:5)
Block(0,9,-2,biomesoplenty:leaves_0:11)
Block(-5,9,-1,biomesoplenty:log_1:5)
Block(-4,9,-1,biomesoplenty:log_1:5)
Block(-3,9,-1,biomesoplenty:log_1:5)
Block(-2,9,-1,biomesoplenty:log_1:5)
Block(-1,9,-1,biomesoplenty:log_1:5)
Block(0,9,-1,biomesoplenty:log_1:5)
Block(-4,9,0,biomesoplenty:log_1:5)
Block(-3,9,0,biomesoplenty:log_1:5)
Block(-2,9,0,biomesoplenty:log_1:5)
Block(-1,9,0,biomesoplenty:log_1:5)
Block(0,9,0,biomesoplenty:log_1:5)
Block(-4,9,1,biomesoplenty:log_1:5)
Block(-3,9,1,biomesoplenty:log_1:5)
Block(-2,9,1,biomesoplenty:log_1:5)
Block(-1,9,1,biomesoplenty:log_1:5)
Block(0,9,1,biomesoplenty:log_1:5)
Block(-3,9,2,biomesoplenty:log_1:5)
Block(-2,9,2,biomesoplenty:log_1:5)
Block(-1,9,2,biomesoplenty:log_1:5)
Block(0,9,2,biomesoplenty:leaves_0:11)
Block(0,10,-16,biomesoplenty:leaves_0:11)
Block(0,10,-15,biomesoplenty:leaves_0:11)
Block(-3,10,-14,biomesoplenty:leaves_0:11)
Block(3,10,-14,biomesoplenty:leaves_0:11)
Block(-4,10,-11,biomesoplenty:leaves_0:11)
Block(-1,10,-11,biomesoplenty:log_1:5)
Block(0,10,-11,biomesoplenty:log_1:5)
Block(1,10,-11,biomesoplenty:log_1:5)
Block(2,10,-11,biomesoplenty:leaves_0:11)
Block(4,10,-11,biomesoplenty:leaves_0:11)
Block(-1,10,-10,biomesoplenty:log_1:5)
Block(0,10,-10,biomesoplenty:log_1:5)
Block(1,10,-10,biomesoplenty:log_1:5)
Block(-1,10,-9,biomesoplenty:log_1:5)
Block(0,10,-9,biomesoplenty:log_1:5)
Block(1,10,-9,biomesoplenty:log_1:5)
Block(-3,10,-8,biomesoplenty:leaves_0:11)
Block(-2,10,-8,biomesoplenty:leaves_0:11)
Block(0,10,-8,biomesoplenty:log_1:5)
Block(3,10,-8,biomesoplenty:leaves_0:11)
Block(-3,10,-3,biomesoplenty:log_1:5)
Block(-2,10,-3,biomesoplenty:log_1:5)
Block(-1,10,-3,biomesoplenty:leaves_0:11)
Block(-4,10,-2,biomesoplenty:log_1:5)
Block(-3,10,-2,biomesoplenty:log_1:5)
Block(-2,10,-2,biomesoplenty:log_1:5)
Block(-1,10,-2,biomesoplenty:log_1:5)
Block(-5,10,-1,biomesoplenty:log_1:5)
Block(-4,10,-1,biomesoplenty:log_1:5)
Block(-3,10,-1,biomesoplenty:log_1:5)
Block(-2,10,-1,biomesoplenty:log_1:5)
Block(-1,10,-1,biomesoplenty:log_1:5)
Block(0,10,-1,biomesoplenty:log_1:5)
Block(-5,10,0,biomesoplenty:log_1:5)
Block(-4,10,0,biomesoplenty:log_1:5)
Block(-3,10,0,biomesoplenty:log_1:5)
Block(-2,10,0,biomesoplenty:log_1:5)
Block(-1,10,0,biomesoplenty:log_1:5)
Block(0,10,0,biomesoplenty:log_1:5)
Block(-4,10,1,biomesoplenty:log_1:5)
Block(-3,10,1,biomesoplenty:log_1:5)
Block(-2,10,1,biomesoplenty:log_1:5)
Block(-1,10,1,biomesoplenty:log_1:5)
Block(0,10,1,biomesoplenty:leaves_0:11)
Block(-4,10,2,biomesoplenty:log_1:5)
Block(-3,10,2,biomesoplenty:log_1:5)
Block(-2,10,2,biomesoplenty:log_1:5)
Block(-1,10,2,biomesoplenty:log_1:5)
Block(0,11,-16,biomesoplenty:leaves_0:11)
Block(-1,11,-15,biomesoplenty:leaves_0:11)
Block(0,11,-15,biomesoplenty:leaves_0:11)
Block(2,11,-15,biomesoplenty:leaves_0:11)
Block(-3,11,-14,biomesoplenty:leaves_0:11)
Block(2,11,-14,biomesoplenty:leaves_0:11)
Block(3,11,-14,biomesoplenty:leaves_0:11)
Block(0,11,-13,biomesoplenty:log_1:5)
Block(4,11,-13,biomesoplenty:leaves_0:11)
Block(0,11,-12,biomesoplenty:log_1:5)
Block(1,11,-12,biomesoplenty:log_1:5)
Block(2,11,-12,biomesoplenty:leaves_0:11)
Block(5,11,-12,biomesoplenty:leaves_0:11)
Block(-4,11,-11,biomesoplenty:leaves_0:11)
Block(-1,11,-11,biomesoplenty:log_1:5)
Block(0,11,-11,biomesoplenty:log_1:5)
Block(1,11,-11,biomesoplenty:log_1:5)
Block(4,11,-11,biomesoplenty:leaves_0:11)
Block(-1,11,-10,biomesoplenty:log_1:5)
Block(0,11,-10,biomesoplenty:log_1:5)
Block(4,11,-10,biomesoplenty:leaves_0:11)
Block(-3,11,-9,biomesoplenty:leaves_0:11)
Block(0,11,-9,biomesoplenty:leaves_0:11)
Block(3,11,-9,biomesoplenty:leaves_0:11)
Block(-2,11,-8,biomesoplenty:leaves_0:11)
Block(-1,11,-8,biomesoplenty:leaves_0:11)
Block(0,11,-8,biomesoplenty:leaves_0:11)
Block(1,11,-8,biomesoplenty:leaves_0:11)
Block(3,11,-8,biomesoplenty:leaves_0:11)
Block(0,11,-7,biomesoplenty:leaves_0:11)
Block(1,11,-7,biomesoplenty:leaves_0:11)
Block(2,11,-7,biomesoplenty:leaves_0:11)
Block(-2,11,-4,biomesoplenty:leaves_0:11)
Block(-3,11,-3,biomesoplenty:log_1:5)
Block(-2,11,-3,biomesoplenty:log_1:5)
Block(-5,11,-2,biomesoplenty:log_1:5)
Block(-4,11,-2,biomesoplenty:log_1:5)
Block(-3,11,-2,biomesoplenty:log_1:5)
Block(-2,11,-2,biomesoplenty:log_1:5)
Block(-1,11,-2,biomesoplenty:log_1:5)
Block(-5,11,-1,biomesoplenty:log_1:5)
Block(-4,11,-1,biomesoplenty:log_1:5)
Block(-3,11,-1,biomesoplenty:log_1:5)
Block(-2,11,-1,biomesoplenty:log_1:5)
Block(-1,11,-1,biomesoplenty:log_1:5)
Block(0,11,-1,biomesoplenty:log_1:5)
Block(-5,11,0,biomesoplenty:log_1:5)
Block(-4,11,0,biomesoplenty:log_1:5)
Block(-3,11,0,biomesoplenty:log_1:5)
Block(-2,11,0,biomesoplenty:log_1:5)
Block(-1,11,0,biomesoplenty:log_1:5)
Block(-4,11,1,biomesoplenty:log_1:5)
Block(-3,11,1,biomesoplenty:log_1:5)
Block(-2,11,1,biomesoplenty:log_1:5)
Block(-1,11,1,biomesoplenty:log_1:5)
Block(-4,11,2,biomesoplenty:log_1:5)
Block(-3,11,2,biomesoplenty:log_1:5)
Block(-2,11,2,biomesoplenty:log_1:5)
Block(-1,11,2,biomesoplenty:leaves_0:11)
Block(0,12,-16,biomesoplenty:leaves_0:11)
Block(-2,12,-15,biomesoplenty:leaves_0:11)
Block(-1,12,-15,biomesoplenty:leaves_0:11)
Block(0,12,-15,biomesoplenty:leaves_0:11)
Block(1,12,-15,biomesoplenty:leaves_0:11)
Block(2,12,-15,biomesoplenty:leaves_0:11)
Block(3,12,-15,biomesoplenty:leaves_0:11)
Block(-3,12,-14,biomesoplenty:leaves_0:11)
Block(-2,12,-14,biomesoplenty:leaves_0:11)
Block(-1,12,-14,biomesoplenty:leaves_0:11)
Block(0,12,-14,biomesoplenty:log_1:5)
Block(1,12,-14,biomesoplenty:leaves_0:11)
Block(2,12,-14,biomesoplenty:leaves_0:11)
Block(3,12,-14,biomesoplenty:leaves_0:11)
Block(-4,12,-13,biomesoplenty:leaves_0:11)
Block(-3,12,-13,biomesoplenty:leaves_0:11)
Block(0,12,-13,biomesoplenty:leaves_0:11)
Block(1,12,-13,biomesoplenty:leaves_0:11)
Block(2,12,-13,biomesoplenty:leaves_0:11)
Block(3,12,-13,biomesoplenty:leaves_0:11)
Block(4,12,-13,biomesoplenty:leaves_0:11)
Block(5,12,-13,biomesoplenty:leaves_0:11)
Block(-4,12,-12,biomesoplenty:leaves_0:11)
Block(-3,12,-12,biomesoplenty:leaves_0:11)
Block(0,12,-12,biomesoplenty:log_1:5)
Block(1,12,-12,biomesoplenty:leaves_0:11)
Block(2,12,-12,biomesoplenty:leaves_0:11)
Block(3,12,-12,biomesoplenty:leaves_0:11)
Block(4,12,-12,biomesoplenty:leaves_0:11)
Block(5,12,-12,biomesoplenty:leaves_0:11)
Block(-4,12,-11,biomesoplenty:leaves_0:11)
Block(-1,12,-11,biomesoplenty:log_1:5)
Block(0,12,-11,biomesoplenty:log_1:5)
Block(1,12,-11,biomesoplenty:log_1:5)
Block(2,12,-11,biomesoplenty:log_1:5)
Block(4,12,-11,biomesoplenty:leaves_0:11)
Block(5,12,-11,biomesoplenty:leaves_0:11)
Block(-4,12,-10,biomesoplenty:leaves_0:11)
Block(-3,12,-10,biomesoplenty:leaves_0:11)
Block(0,12,-10,biomesoplenty:log_1:5)
Block(1,12,-10,biomesoplenty:leaves_0:11)
Block(3,12,-10,biomesoplenty:leaves_0:11)
Block(4,12,-10,biomesoplenty:leaves_0:11)
Block(-4,12,-9,biomesoplenty:leaves_0:11)
Block(-3,12,-9,biomesoplenty:leaves_0:11)
Block(-2,12,-9,biomesoplenty:leaves_0:11)
Block(-1,12,-9,biomesoplenty:leaves_0:11)
Block(0,12,-9,biomesoplenty:leaves_0:11)
Block(2,12,-9,biomesoplenty:leaves_0:11)
Block(3,12,-9,biomesoplenty:leaves_0:11)
Block(4,12,-9,biomesoplenty:leaves_0:11)
Block(-3,12,-8,biomesoplenty:leaves_0:11)
Block(-1,12,-8,biomesoplenty:leaves_0:11)
Block(0,12,-8,biomesoplenty:leaves_0:11)
Block(1,12,-8,biomesoplenty:leaves_0:11)
Block(2,12,-8,biomesoplenty:leaves_0:11)
Block(-2,12,-7,biomesoplenty:leaves_0:11)
Block(-1,12,-7,biomesoplenty:leaves_0:11)
Block(1,12,-7,biomesoplenty:leaves_0:11)
Block(2,12,-7,biomesoplenty:leaves_0:11)
Block(3,12,-7,biomesoplenty:leaves_0:11)
Block(-3,12,-4,biomesoplenty:leaves_0:11)
Block(-3,12,-3,biomesoplenty:log_1:5)
Block(-2,12,-3,biomesoplenty:log_1:5)
Block(-5,12,-2,biomesoplenty:log_1:5)
Block(-4,12,-2,biomesoplenty:log_1:5)
Block(-3,12,-2,biomesoplenty:log_1:5)
Block(-2,12,-2,biomesoplenty:log_1:5)
Block(-1,12,-2,biomesoplenty:log_1:5)
Block(-5,12,-1,biomesoplenty:log_1:5)
Block(-4,12,-1,biomesoplenty:log_1:5)
Block(-3,12,-1,biomesoplenty:log_1:5)
Block(-2,12,-1,biomesoplenty:log_1:5)
Block(-1,12,-1,biomesoplenty:log_1:5)
Block(0,12,-1,biomesoplenty:log_1:5)
Block(-5,12,0,biomesoplenty:log_1:5)
Block(-4,12,0,biomesoplenty:log_1:5)
Block(-3,12,0,biomesoplenty:log_1:5)
Block(-2,12,0,biomesoplenty:log_1:5)
Block(-1,12,0,biomesoplenty:log_1:5)
Block(-4,12,1,biomesoplenty:log_1:5)
Block(-3,12,1,biomesoplenty:log_1:5)
Block(-2,12,1,biomesoplenty:log_1:5)
Block(-4,12,2,biomesoplenty:log_1:5)
Block(-3,12,2,biomesoplenty:log_1:5)
Block(-2,12,2,biomesoplenty:leaves_0:11)
Block(-1,12,2,biomesoplenty:leaves_0:11)
Block(0,13,-15,biomesoplenty:leaves_0:11)
Block(1,13,-15,biomesoplenty:leaves_0:11)
Block(2,13,-15,biomesoplenty:leaves_0:11)
Block(-3,13,-14,biomesoplenty:leaves_0:11)
Block(-2,13,-14,biomesoplenty:leaves_0:11)
Block(-1,13,-14,biomesoplenty:leaves_0:11)
Block(0,13,-14,biomesoplenty:leaves_0:11)
Block(1,13,-14,biomesoplenty:leaves_0:11)
Block(2,13,-14,biomesoplenty:leaves_0:11)
Block(3,13,-14,biomesoplenty:leaves_0:11)
Block(-3,13,-13,biomesoplenty:leaves_0:11)
Block(-2,13,-13,biomesoplenty:leaves_0:11)
Block(-1,13,-13,biomesoplenty:leaves_0:11)
Block(0,13,-13,biomesoplenty:leaves_0:11)
Block(1,13,-13,biomesoplenty:leaves_0:11)
Block(2,13,-13,biomesoplenty:leaves_0:11)
Block(3,13,-13,biomesoplenty:leaves_0:11)
Block(4,13,-13,biomesoplenty:leaves_0:11)
Block(-4,13,-12,biomesoplenty:leaves_0:11)
Block(-3,13,-12,biomesoplenty:leaves_0:11)
Block(-2,13,-12,biomesoplenty:leaves_0:11)
Block(-1,13,-12,biomesoplenty:leaves_0:11)
Block(0,13,-12,biomesoplenty:log_1:5)
Block(1,13,-12,biomesoplenty:leaves_0:11)
Block(2,13,-12,biomesoplenty:leaves_0:11)
Block(3,13,-12,biomesoplenty:leaves_0:11)
Block(4,13,-12,biomesoplenty:leaves_0:11)
Block(5,13,-12,biomesoplenty:leaves_0:11)
Block(-4,13,-11,biomesoplenty:leaves_0:11)
Block(-3,13,-11,biomesoplenty:leaves_0:11)
Block(-2,13,-11,biomesoplenty:log_1:5)
Block(-1,13,-11,biomesoplenty:log_1:5)
Block(0,13,-11,biomesoplenty:log_1:5)
Block(1,13,-11,biomesoplenty:log_1:5)
Block(2,13,-11,biomesoplenty:leaves_0:11)
Block(3,13,-11,biomesoplenty:log_1:5)
Block(4,13,-11,biomesoplenty:leaves_0:11)
Block(-3,13,-10,biomesoplenty:leaves_0:11)
Block(-2,13,-10,biomesoplenty:leaves_0:11)
Block(-1,13,-10,biomesoplenty:leaves_0:11)
Block(0,13,-10,biomesoplenty:log_1:5)
Block(1,13,-10,biomesoplenty:leaves_0:11)
Block(3,13,-10,biomesoplenty:leaves_0:11)
Block(4,13,-10,biomesoplenty:leaves_0:11)
Block(-3,13,-9,biomesoplenty:leaves_0:11)
Block(-2,13,-9,biomesoplenty:leaves_0:11)
Block(-1,13,-9,biomesoplenty:leaves_0:11)
Block(0,13,-9,biomesoplenty:leaves_0:11)
Block(1,13,-9,biomesoplenty:leaves_0:11)
Block(2,13,-9,biomesoplenty:leaves_0:11)
Block(3,13,-9,biomesoplenty:leaves_0:11)
Block(-2,13,-8,biomesoplenty:leaves_0:11)
Block(-1,13,-8,biomesoplenty:leaves_0:11)
Block(0,13,-8,biomesoplenty:leaves_0:11)
Block(1,13,-8,biomesoplenty:leaves_0:11)
Block(2,13,-8,biomesoplenty:leaves_0:11)
Block(3,13,-8,biomesoplenty:leaves_0:11)
Block(-1,13,-7,biomesoplenty:leaves_0:11)
Block(0,13,-7,biomesoplenty:leaves_0:11)
Block(1,13,-7,biomesoplenty:leaves_0:11)
Block(2,13,-7,biomesoplenty:leaves_0:11)
Block(0,13,-6,biomesoplenty:leaves_0:11)
Block(1,13,-6,biomesoplenty:leaves_0:11)
Block(-4,13,-4,biomesoplenty:leaves_0:11)
Block(-4,13,-3,biomesoplenty:log_1:5)
Block(-3,13,-3,biomesoplenty:log_1:5)
Block(-2,13,-3,biomesoplenty:log_1:5)
Block(-5,13,-2,biomesoplenty:log_1:5)
Block(-4,13,-2,biomesoplenty:log_1:5)
Block(-3,13,-2,biomesoplenty:log_1:5)
Block(-2,13,-2,biomesoplenty:log_1:5)
Block(-1,13,-2,biomesoplenty:log_1:5)
Block(-6,13,-1,biomesoplenty:log_1:5)
Block(-5,13,-1,biomesoplenty:log_1:5)
Block(-4,13,-1,biomesoplenty:log_1:5)
Block(-3,13,-1,biomesoplenty:log_1:5)
Block(-2,13,-1,biomesoplenty:log_1:5)
Block(-1,13,-1,biomesoplenty:log_1:5)
Block(0,13,-1,biomesoplenty:log_1:5)
Block(-5,13,0,biomesoplenty:log_1:5)
Block(-4,13,0,biomesoplenty:log_1:5)
Block(-3,13,0,biomesoplenty:log_1:5)
Block(-2,13,0,biomesoplenty:log_1:5)
Block(-1,13,0,biomesoplenty:log_1:5)
Block(-4,13,1,biomesoplenty:log_1:5)
Block(-3,13,1,biomesoplenty:log_1:5)
Block(-2,13,1,biomesoplenty:log_1:5)
Block(-4,13,2,biomesoplenty:log_1:5)
Block(-3,13,2,biomesoplenty:log_1:5)
Block(-2,13,2,biomesoplenty:leaves_0:11)
Block(-2,13,3,biomesoplenty:leaves_0:11)
Block(-2,14,-14,biomesoplenty:leaves_0:11)
Block(0,14,-14,biomesoplenty:leaves_0:11)
Block(1,14,-14,biomesoplenty:leaves_0:11)
Block(-3,14,-13,biomesoplenty:leaves_0:11)
Block(-1,14,-13,biomesoplenty:leaves_0:11)
Block(0,14,-13,biomesoplenty:leaves_0:11)
Block(1,14,-13,biomesoplenty:leaves_0:11)
Block(2,14,-13,biomesoplenty:leaves_0:11)
Block(3,14,-13,biomesoplenty:leaves_0:11)
Block(-2,14,-12,biomesoplenty:leaves_0:11)
Block(0,14,-12,biomesoplenty:leaves_0:11)
Block(1,14,-12,biomesoplenty:leaves_0:11)
Block(2,14,-12,biomesoplenty:leaves_0:11)
Block(4,14,-12,biomesoplenty:leaves_0:11)
Block(-3,14,-11,biomesoplenty:leaves_0:11)
Block(-2,14,-11,biomesoplenty:leaves_0:11)
Block(-1,14,-11,biomesoplenty:leaves_0:11)
Block(0,14,-11,biomesoplenty:leaves_0:11)
Block(1,14,-11,biomesoplenty:leaves_0:11)
Block(2,14,-11,biomesoplenty:leaves_0:11)
Block(3,14,-11,biomesoplenty:leaves_0:11)
Block(4,14,-11,biomesoplenty:leaves_0:11)
Block(-2,14,-10,biomesoplenty:leaves_0:11)
Block(0,14,-10,biomesoplenty:leaves_0:11)
Block(1,14,-10,biomesoplenty:leaves_0:11)
Block(2,14,-10,biomesoplenty:leaves_0:11)
Block(3,14,-10,biomesoplenty:leaves_0:11)
Block(-2,14,-9,biomesoplenty:leaves_0:11)
Block(-1,14,-9,biomesoplenty:leaves_0:11)
Block(0,14,-9,biomesoplenty:leaves_0:11)
Block(2,14,-9,biomesoplenty:leaves_0:11)
Block(-1,14,-8,biomesoplenty:leaves_0:11)
Block(0,14,-8,biomesoplenty:leaves_0:11)
Block(1,14,-8,biomesoplenty:leaves_0:11)
Block(-5,14,-3,biomesoplenty:leaves_0:11)
Block(-4,14,-3,biomesoplenty:log_1:5)
Block(-3,14,-3,biomesoplenty:log_1:5)
Block(-2,14,-3,biomesoplenty:log_1:5)
Block(-5,14,-2,biomesoplenty:log_1:5)
Block(-4,14,-2,biomesoplenty:log_1:5)
Block(-3,14,-2,biomesoplenty:log_1:5)
Block(-2,14,-2,biomesoplenty:log_1:5)
Block(-1,14,-2,biomesoplenty:log_1:5)
Block(-6,14,-1,biomesoplenty:log_1:5)
Block(-5,14,-1,biomesoplenty:log_1:5)
Block(-4,14,-1,biomesoplenty:log_1:5)
Block(-3,14,-1,biomesoplenty:log_1:5)
Block(-2,14,-1,biomesoplenty:log_1:5)
Block(-1,14,-1,biomesoplenty:log_1:5)
Block(-5,14,0,biomesoplenty:log_1:5)
Block(-4,14,0,biomesoplenty:log_1:5)
Block(-3,14,0,biomesoplenty:log_1:5)
Block(-2,14,0,biomesoplenty:log_1:5)
Block(-1,14,0,biomesoplenty:log_1:5)
Block(-5,14,1,biomesoplenty:log_1:5)
Block(-4,14,1,biomesoplenty:log_1:5)
Block(-3,14,1,biomesoplenty:log_1:5)
Block(-2,14,1,biomesoplenty:log_1:5)
Block(-4,14,2,biomesoplenty:leaves_0:11)
Block(-3,14,2,biomesoplenty:log_1:5)
Block(-2,14,2,biomesoplenty:log_1:5)
Block(-3,14,3,biomesoplenty:leaves_0:11)
Block(0,15,-14,biomesoplenty:leaves_0:11)
Block(0,15,-13,biomesoplenty:leaves_0:11)
Block(1,15,-13,biomesoplenty:leaves_0:11)
Block(-1,15,-12,biomesoplenty:leaves_0:11)
Block(0,15,-12,biomesoplenty:leaves_0:11)
Block(2,15,-12,biomesoplenty:leaves_0:11)
Block(-2,15,-11,biomesoplenty:leaves_0:11)
Block(1,15,-11,biomesoplenty:leaves_0:11)
Block(2,15,-11,biomesoplenty:leaves_0:11)
Block(-2,15,-10,biomesoplenty:leaves_0:11)
Block(0,15,-10,biomesoplenty:leaves_0:11)
Block(1,15,-10,biomesoplenty:leaves_0:11)
Block(2,15,-10,biomesoplenty:leaves_0:11)
Block(3,15,-10,biomesoplenty:leaves_0:11)
Block(-1,15,-9,biomesoplenty:leaves_0:11)
Block(0,15,-9,biomesoplenty:leaves_0:11)
Block(-5,15,-3,biomesoplenty:leaves_0:11)
Block(-4,15,-3,biomesoplenty:log_1:5)
Block(-3,15,-3,biomesoplenty:log_1:5)
Block(-2,15,-3,biomesoplenty:log_1:5)
Block(-5,15,-2,biomesoplenty:log_1:5)
Block(-4,15,-2,biomesoplenty:log_1:5)
Block(-3,15,-2,biomesoplenty:log_1:5)
Block(-2,15,-2,biomesoplenty:log_1:5)
Block(-1,15,-2,biomesoplenty:log_1:5)
Block(-6,15,-1,biomesoplenty:log_1:5)
Block(-5,15,-1,biomesoplenty:log_1:5)
Block(-4,15,-1,biomesoplenty:log_1:5)
Block(-3,15,-1,biomesoplenty:log_1:5)
Block(-2,15,-1,biomesoplenty:log_1:5)
Block(-1,15,-1,biomesoplenty:log_1:5)
Block(-6,15,0,biomesoplenty:log_1:5)
Block(-5,15,0,biomesoplenty:log_1:5)
Block(-4,15,0,biomesoplenty:log_1:5)
Block(-3,15,0,biomesoplenty:log_1:5)
Block(-2,15,0,biomesoplenty:log_1:5)
Block(-1,15,0,biomesoplenty:log_1:5)
Block(-5,15,1,biomesoplenty:log_1:5)
Block(-4,15,1,biomesoplenty:log_1:5)
Block(-3,15,1,biomesoplenty:log_1:5)
Block(-2,15,1,biomesoplenty:log_1:5)
Block(-1,15,1,biomesoplenty:log_1:5)
Block(-4,15,2,biomesoplenty:leaves_0:11)
Block(-3,15,2,biomesoplenty:log_1:5)
Block(-2,15,2,biomesoplenty:log_1:5)
Block(-5,16,-4,biomesoplenty:leaves_0:11)
Block(-6,16,-3,biomesoplenty:leaves_0:11)
Block(-5,16,-3,biomesoplenty:log_1:5)
Block(-4,16,-3,biomesoplenty:log_1:5)
Block(-3,16,-3,biomesoplenty:log_1:5)
Block(-2,16,-3,biomesoplenty:log_1:5)
Block(-6,16,-2,biomesoplenty:log_1:5)
Block(-5,16,-2,biomesoplenty:log_1:5)
Block(-4,16,-2,biomesoplenty:log_1:5)
Block(-3,16,-2,biomesoplenty:log_1:5)
Block(-2,16,-2,biomesoplenty:log_1:5)
Block(-6,16,-1,biomesoplenty:log_1:5)
Block(-5,16,-1,biomesoplenty:log_1:5)
Block(-4,16,-1,biomesoplenty:log_1:5)
Block(-3,16,-1,biomesoplenty:log_1:5)
Block(-2,16,-1,biomesoplenty:log_1:5)
Block(-1,16,-1,biomesoplenty:log_1:5)
Block(-6,16,0,biomesoplenty:log_1:5)
Block(-5,16,0,biomesoplenty:log_1:5)
Block(-4,16,0,biomesoplenty:log_1:5)
Block(-3,16,0,biomesoplenty:log_1:5)
Block(-2,16,0,biomesoplenty:log_1:5)
Block(-1,16,0,biomesoplenty:log_1:5)
Block(-5,16,1,biomesoplenty:log_1:5)
Block(-4,16,1,biomesoplenty:log_1:5)
Block(-3,16,1,biomesoplenty:log_1:5)
Block(-2,16,1,biomesoplenty:log_1:5)
Block(-1,16,1,biomesoplenty:log_1:5)
Block(0,16,1,biomesoplenty:log_1:5)
Block(-5,16,2,biomesoplenty:leaves_0:11)
Block(-3,16,2,biomesoplenty:log_1:5)
Block(-2,16,2,biomesoplenty:log_1:5)
Block(-1,16,2,biomesoplenty:log_1:5)
Block(0,16,2,biomesoplenty:log_1:5)
Block(1,16,2,biomesoplenty:leaves_0:11)
Block(0,16,3,biomesoplenty:log_1:5)
Block(1,16,3,biomesoplenty:leaves_0:11)
Block(13,16,4,biomesoplenty:leaves_0:11)
Block(4,16,10,biomesoplenty:leaves_0:11)
Block(-4,17,-4,biomesoplenty:leaves_0:11)
Block(-6,17,-3,biomesoplenty:leaves_0:11)
Block(-5,17,-3,biomesoplenty:log_1:5)
Block(-4,17,-3,biomesoplenty:log_1:5)
Block(-3,17,-3,biomesoplenty:log_1:5)
Block(-6,17,-2,biomesoplenty:log_1:5)
Block(-5,17,-2,biomesoplenty:log_1:5)
Block(-4,17,-2,biomesoplenty:log_1:5)
Block(-3,17,-2,biomesoplenty:log_1:5)
Block(-2,17,-2,biomesoplenty:log_1:5)
Block(-7,17,-1,biomesoplenty:log_1:5)
Block(-6,17,-1,biomesoplenty:log_1:5)
Block(-5,17,-1,biomesoplenty:log_1:5)
Block(-4,17,-1,biomesoplenty:log_1:5)
Block(-3,17,-1,biomesoplenty:log_1:5)
Block(-2,17,-1,biomesoplenty:log_1:5)
Block(-1,17,-1,biomesoplenty:log_1:5)
Block(-6,17,0,biomesoplenty:log_1:5)
Block(-5,17,0,biomesoplenty:log_1:5)
Block(-4,17,0,biomesoplenty:log_1:5)
Block(-3,17,0,biomesoplenty:log_1:5)
Block(-2,17,0,biomesoplenty:log_1:5)
Block(-1,17,0,biomesoplenty:log_1:5)
Block(0,17,0,biomesoplenty:log_1:5)
Block(-5,17,1,biomesoplenty:log_1:5)
Block(-4,17,1,biomesoplenty:log_1:5)
Block(-3,17,1,biomesoplenty:log_1:5)
Block(-2,17,1,biomesoplenty:log_1:5)
Block(-1,17,1,biomesoplenty:log_1:5)
Block(0,17,1,biomesoplenty:log_1:5)
Block(1,17,1,biomesoplenty:log_1:5)
Block(2,17,1,biomesoplenty:leaves_0:11)
Block(-5,17,2,biomesoplenty:leaves_0:11)
Block(-2,17,2,biomesoplenty:log_1:5)
Block(-1,17,2,biomesoplenty:log_1:5)
Block(0,17,2,biomesoplenty:log_1:5)
Block(1,17,2,biomesoplenty:log_1:5)
Block(-1,17,3,biomesoplenty:log_1:5)
Block(0,17,3,biomesoplenty:log_1:5)
Block(1,17,3,biomesoplenty:log_1:5)
Block(0,17,4,biomesoplenty:log_1:5)
Block(1,17,4,biomesoplenty:leaves_0:11)
Block(13,17,4,biomesoplenty:leaves_0:11)
Block(4,17,10,biomesoplenty:leaves_0:11)
Block(-4,18,-4,biomesoplenty:log_1:5)
Block(-3,18,-4,biomesoplenty:leaves_0:11)
Block(-7,18,-3,biomesoplenty:leaves_0:11)
Block(-6,18,-3,biomesoplenty:log_1:5)
Block(-5,18,-3,biomesoplenty:log_1:5)
Block(-4,18,-3,biomesoplenty:log_1:5)
Block(-3,18,-3,biomesoplenty:log_1:5)
Block(-6,18,-2,biomesoplenty:log_1:5)
Block(-5,18,-2,biomesoplenty:log_1:5)
Block(-4,18,-2,biomesoplenty:log_1:5)
Block(-3,18,-2,biomesoplenty:log_1:5)
Block(-2,18,-2,biomesoplenty:log_1:5)
Block(-7,18,-1,biomesoplenty:log_1:5)
Block(-6,18,-1,biomesoplenty:log_1:5)
Block(-5,18,-1,biomesoplenty:log_1:5)
Block(-4,18,-1,biomesoplenty:log_1:5)
Block(-3,18,-1,biomesoplenty:log_1:5)
Block(-2,18,-1,biomesoplenty:log_1:5)
Block(-1,18,-1,biomesoplenty:log_1:5)
Block(-6,18,0,biomesoplenty:log_1:5)
Block(-5,18,0,biomesoplenty:log_1:5)
Block(-4,18,0,biomesoplenty:log_1:5)
Block(-3,18,0,biomesoplenty:log_1:5)
Block(-2,18,0,biomesoplenty:log_1:5)
Block(-1,18,0,biomesoplenty:log_1:5)
Block(1,18,0,biomesoplenty:leaves_0:11)
Block(-6,18,1,biomesoplenty:leaves_0:11)
Block(-4,18,1,biomesoplenty:log_1:5)
Block(-3,18,1,biomesoplenty:log_1:5)
Block(-2,18,1,biomesoplenty:log_1:5)
Block(-1,18,1,biomesoplenty:log_1:5)
Block(0,18,1,biomesoplenty:log_1:5)
Block(1,18,1,biomesoplenty:log_1:5)
Block(-1,18,2,biomesoplenty:log_1:5)
Block(0,18,2,biomesoplenty:log_1:5)
Block(1,18,2,biomesoplenty:log_1:5)
Block(-1,18,3,biomesoplenty:log_1:5)
Block(0,18,3,biomesoplenty:log_1:5)
Block(1,18,3,biomesoplenty:log_1:5)
Block(2,18,3,biomesoplenty:log_1:5)
Block(-1,18,4,biomesoplenty:log_1:5)
Block(0,18,4,biomesoplenty:log_1:5)
Block(1,18,4,biomesoplenty:log_1:5)
Block(2,18,4,biomesoplenty:log_1:5)
Block(13,18,4,biomesoplenty:leaves_0:11)
Block(2,18,5,biomesoplenty:log_1:5)
Block(4,18,6,biomesoplenty:leaves_0:11)
Block(4,18,7,biomesoplenty:leaves_0:11)
Block(4,18,10,biomesoplenty:leaves_0:11)
Block(8,18,15,biomesoplenty:leaves_0:11)
Block(-5,19,-4,biomesoplenty:log_1:5)
Block(-4,19,-4,biomesoplenty:log_1:5)
Block(-3,19,-4,biomesoplenty:leaves_0:11)
Block(-7,19,-3,biomesoplenty:leaves_0:11)
Block(-6,19,-3,biomesoplenty:log_1:5)
Block(-5,19,-3,biomesoplenty:log_1:5)
Block(-4,19,-3,biomesoplenty:log_1:5)
Block(-3,19,-3,biomesoplenty:log_1:5)
Block(-2,19,-3,biomesoplenty:log_1:5)
Block(-7,19,-2,biomesoplenty:log_1:5)
Block(-6,19,-2,biomesoplenty:log_1:5)
Block(-5,19,-2,biomesoplenty:log_1:5)
Block(-4,19,-2,biomesoplenty:log_1:5)
Block(-3,19,-2,biomesoplenty:log_1:5)
Block(-2,19,-2,biomesoplenty:log_1:5)
Block(-7,19,-1,biomesoplenty:log_1:5)
Block(-6,19,-1,biomesoplenty:log_1:5)
Block(-5,19,-1,biomesoplenty:log_1:5)
Block(-4,19,-1,biomesoplenty:log_1:5)
Block(-3,19,-1,biomesoplenty:log_1:5)
Block(-2,19,-1,biomesoplenty:log_1:5)
Block(-6,19,0,biomesoplenty:log_1:5)
Block(-5,19,0,biomesoplenty:log_1:5)
Block(-4,19,0,biomesoplenty:log_1:5)
Block(-3,19,0,biomesoplenty:log_1:5)
Block(-2,19,0,biomesoplenty:log_1:5)
Block(-1,19,0,biomesoplenty:log_1:5)
Block(0,19,0,biomesoplenty:leaves_0:11)
Block(-7,19,1,biomesoplenty:leaves_0:11)
Block(-6,19,1,biomesoplenty:leaves_0:11)
Block(-2,19,1,biomesoplenty:log_1:5)
Block(-1,19,1,biomesoplenty:log_1:5)
Block(0,19,1,biomesoplenty:log_1:5)
Block(-1,19,2,biomesoplenty:log_1:5)
Block(0,19,2,biomesoplenty:log_1:5)
Block(1,19,2,biomesoplenty:log_1:5)
Block(2,19,2,biomesoplenty:log_1:5)
Block(7,19,2,biomesoplenty:leaves_0:11)
Block(10,19,2,biomesoplenty:leaves_0:11)
Block(-1,19,3,biomesoplenty:log_1:5)
Block(0,19,3,biomesoplenty:log_1:5)
Block(1,19,3,biomesoplenty:log_1:5)
Block(2,19,3,biomesoplenty:log_1:5)
Block(0,19,4,biomesoplenty:log_1:5)
Block(1,19,4,biomesoplenty:log_1:5)
Block(2,19,4,biomesoplenty:log_1:5)
Block(13,19,4,biomesoplenty:leaves_0:11)
Block(1,19,5,biomesoplenty:log_1:5)
Block(2,19,5,biomesoplenty:log_1:5)
Block(3,19,5,biomesoplenty:log_1:5)
Block(2,19,6,biomesoplenty:log_1:5)
Block(3,19,6,biomesoplenty:log_1:5)
Block(4,19,6,biomesoplenty:log_1:5)
Block(5,19,6,biomesoplenty:leaves_0:11)
Block(14,19,6,biomesoplenty:leaves_0:11)
Block(3,19,7,biomesoplenty:log_1:5)
Block(4,19,7,biomesoplenty:log_1:5)
Block(5,19,7,biomesoplenty:log_1:5)
Block(3,19,8,biomesoplenty:leaves_0:11)
Block(4,19,8,biomesoplenty:log_1:5)
Block(5,19,8,biomesoplenty:log_1:5)
Block(4,19,10,biomesoplenty:leaves_0:11)
Block(7,19,10,biomesoplenty:leaves_0:11)
Block(14,19,11,biomesoplenty:leaves_0:11)
Block(5,19,13,biomesoplenty:leaves_0:11)
Block(8,19,15,biomesoplenty:leaves_0:11)
Block(-5,20,-4,biomesoplenty:log_1:5)
Block(-4,20,-4,biomesoplenty:log_1:5)
Block(-3,20,-4,biomesoplenty:log_1:5)
Block(-2,20,-4,biomesoplenty:leaves_0:11)
Block(-6,20,-3,biomesoplenty:log_1:5)
Block(-5,20,-3,biomesoplenty:log_1:5)
Block(-4,20,-3,biomesoplenty:log_1:5)
Block(-3,20,-3,biomesoplenty:log_1:5)
Block(-2,20,-3,biomesoplenty:log_1:5)
Block(-8,20,-2,biomesoplenty:leaves_0:11)
Block(-7,20,-2,biomesoplenty:log_1:5)
Block(-6,20,-2,biomesoplenty:log_1:5)
Block(-5,20,-2,biomesoplenty:log_1:5)
Block(-4,20,-2,biomesoplenty:log_1:5)
Block(-3,20,-2,biomesoplenty:log_1:5)
Block(-2,20,-2,biomesoplenty:log_1:5)
Block(-7,20,-1,biomesoplenty:log_1:5)
Block(-6,20,-1,biomesoplenty:log_1:5)
Block(-5,20,-1,biomesoplenty:log_1:5)
Block(-4,20,-1,biomesoplenty:log_1:5)
Block(-3,20,-1,biomesoplenty:log_1:5)
Block(-2,20,-1,biomesoplenty:log_1:5)
Block(-1,20,-1,biomesoplenty:leaves_0:11)
Block(-8,20,0,biomesoplenty:log_1:5)
Block(-7,20,0,biomesoplenty:log_1:5)
Block(-6,20,0,biomesoplenty:log_1:5)
Block(-5,20,0,biomesoplenty:log_1:5)
Block(-4,20,0,biomesoplenty:log_1:5)
Block(-3,20,0,biomesoplenty:log_1:5)
Block(-1,20,0,biomesoplenty:leaves_0:11)
Block(-8,20,1,biomesoplenty:log_1:5)
Block(-7,20,1,biomesoplenty:log_1:5)
Block(-6,20,1,biomesoplenty:log_1:5)
Block(-8,20,2,biomesoplenty:leaves_0:11)
Block(-7,20,2,biomesoplenty:log_1:5)
Block(7,20,2,biomesoplenty:leaves_0:11)
Block(10,20,2,biomesoplenty:leaves_0:11)
Block(0,20,3,biomesoplenty:log_1:5)
Block(1,20,3,biomesoplenty:log_1:5)
Block(2,20,3,biomesoplenty:log_1:5)
Block(1,20,4,biomesoplenty:log_1:5)
Block(2,20,4,biomesoplenty:log_1:5)
Block(3,20,4,biomesoplenty:log_1:5)
Block(13,20,4,biomesoplenty:leaves_0:11)
Block(1,20,5,biomesoplenty:log_1:5)
Block(2,20,5,biomesoplenty:log_1:5)
Block(3,20,5,biomesoplenty:log_1:5)
Block(4,20,5,biomesoplenty:log_1:5)
Block(1,20,6,biomesoplenty:log_1:5)
Block(2,20,6,biomesoplenty:log_1:5)
Block(3,20,6,biomesoplenty:log_1:5)
Block(4,20,6,biomesoplenty:log_1:5)
Block(5,20,6,biomesoplenty:log_1:5)
Block(6,20,6,biomesoplenty:leaves_0:11)
Block(11,20,6,biomesoplenty:leaves_0:11)
Block(14,20,6,biomesoplenty:leaves_0:11)
Block(2,20,7,biomesoplenty:log_1:5)
Block(3,20,7,biomesoplenty:log_1:5)
Block(4,20,7,biomesoplenty:log_1:5)
Block(5,20,7,biomesoplenty:log_1:5)
Block(6,20,7,biomesoplenty:log_1:5)
Block(2,20,8,biomesoplenty:leaves_0:11)
Block(3,20,8,biomesoplenty:log_1:5)
Block(4,20,8,biomesoplenty:log_1:5)
Block(5,20,8,biomesoplenty:log_1:5)
Block(6,20,8,biomesoplenty:log_1:5)
Block(7,20,8,biomesoplenty:log_1:5)
Block(3,20,9,biomesoplenty:leaves_0:11)
Block(4,20,9,biomesoplenty:log_1:5)
Block(5,20,9,biomesoplenty:log_1:5)
Block(15,20,9,biomesoplenty:leaves_0:11)
Block(4,20,10,biomesoplenty:leaves_0:11)
Block(7,20,10,biomesoplenty:leaves_0:11)
Block(14,20,11,biomesoplenty:leaves_0:11)
Block(5,20,13,biomesoplenty:leaves_0:11)
Block(12,20,14,biomesoplenty:leaves_0:11)
Block(8,20,15,biomesoplenty:leaves_0:11)
Block(-4,21,-5,biomesoplenty:log_1:5)
Block(-5,21,-4,biomesoplenty:log_1:5)
Block(-4,21,-4,biomesoplenty:log_1:5)
Block(-3,21,-4,biomesoplenty:log_1:5)
Block(-2,21,-4,biomesoplenty:log_1:5)
Block(-1,21,-4,biomesoplenty:leaves_0:11)
Block(-6,21,-3,biomesoplenty:log_1:5)
Block(-5,21,-3,biomesoplenty:log_1:5)
Block(-4,21,-3,biomesoplenty:log_1:5)
Block(-3,21,-3,biomesoplenty:log_1:5)
Block(-2,21,-3,biomesoplenty:log_1:5)
Block(-6,21,-2,biomesoplenty:log_1:5)
Block(-5,21,-2,biomesoplenty:log_1:5)
Block(-4,21,-2,biomesoplenty:log_1:5)
Block(-3,21,-2,biomesoplenty:log_1:5)
Block(-2,21,-2,biomesoplenty:log_1:5)
Block(-8,21,-1,biomesoplenty:leaves_0:11)
Block(-7,21,-1,biomesoplenty:log_1:5)
Block(-6,21,-1,biomesoplenty:log_1:5)
Block(-5,21,-1,biomesoplenty:log_1:5)
Block(-4,21,-1,biomesoplenty:log_1:5)
Block(-3,21,-1,biomesoplenty:log_1:5)
Block(-2,21,-1,biomesoplenty:leaves_0:11)
Block(-8,21,0,biomesoplenty:log_1:5)
Block(-7,21,0,biomesoplenty:log_1:5)
Block(-6,21,0,biomesoplenty:log_1:5)
Block(-5,21,0,biomesoplenty:log_1:5)
Block(-4,21,0,biomesoplenty:log_1:5)
Block(-9,21,1,biomesoplenty:leaves_0:11)
Block(-8,21,1,biomesoplenty:log_1:5)
Block(-7,21,1,biomesoplenty:log_1:5)
Block(-6,21,1,biomesoplenty:log_1:5)
Block(-5,21,1,biomesoplenty:log_1:5)
Block(-9,21,2,biomesoplenty:log_1:5)
Block(-8,21,2,biomesoplenty:log_1:5)
Block(-7,21,2,biomesoplenty:log_1:5)
Block(-6,21,2,biomesoplenty:log_1:5)
Block(7,21,2,biomesoplenty:leaves_0:11)
Block(10,21,2,biomesoplenty:leaves_0:11)
Block(-8,21,3,biomesoplenty:log_1:5)
Block(2,21,4,biomesoplenty:log_1:5)
Block(13,21,4,biomesoplenty:leaves_0:11)
Block(2,21,5,biomesoplenty:log_1:5)
Block(3,21,5,biomesoplenty:log_1:5)
Block(2,21,6,biomesoplenty:log_1:5)
Block(3,21,6,biomesoplenty:log_1:5)
Block(4,21,6,biomesoplenty:log_1:5)
Block(5,21,6,biomesoplenty:leaves_0:11)
Block(11,21,6,biomesoplenty:leaves_0:11)
Block(14,21,6,biomesoplenty:leaves_0:11)
Block(3,21,7,biomesoplenty:log_1:5)
Block(4,21,7,biomesoplenty:log_1:5)
Block(5,21,7,biomesoplenty:log_1:5)
Block(6,21,7,biomesoplenty:log_1:5)
Block(7,21,7,biomesoplenty:log_1:5)
Block(3,21,8,biomesoplenty:leaves_0:11)
Block(4,21,8,biomesoplenty:log_1:5)
Block(5,21,8,biomesoplenty:log_1:5)
Block(6,21,8,biomesoplenty:log_1:5)
Block(7,21,8,biomesoplenty:log_1:5)
Block(8,21,8,biomesoplenty:log_1:5)
Block(5,21,9,biomesoplenty:log_1:5)
Block(6,21,9,biomesoplenty:log_1:5)
Block(7,21,9,biomesoplenty:log_1:5)
Block(15,21,9,biomesoplenty:leaves_0:11)
Block(4,21,10,biomesoplenty:leaves_0:11)
Block(7,21,10,biomesoplenty:leaves_0:11)
Block(14,21,11,biomesoplenty:leaves_0:11)
Block(5,21,13,biomesoplenty:leaves_0:11)
Block(12,21,14,biomesoplenty:leaves_0:11)
Block(8,21,15,biomesoplenty:leaves_0:11)
Block(-4,22,-5,biomesoplenty:log_1:5)
Block(-3,22,-5,biomesoplenty:log_1:5)
Block(-5,22,-4,biomesoplenty:log_1:5)
Block(-4,22,-4,biomesoplenty:log_1:5)
Block(-3,22,-4,biomesoplenty:log_1:5)
Block(-2,22,-4,biomesoplenty:log_1:5)
Block(-1,22,-4,biomesoplenty:leaves_0:11)
Block(-6,22,-3,biomesoplenty:log_1:5)
Block(-5,22,-3,biomesoplenty:log_1:5)
Block(-4,22,-3,biomesoplenty:log_1:5)
Block(-3,22,-3,biomesoplenty:log_1:5)
Block(-2,22,-3,biomesoplenty:log_1:5)
Block(-1,22,-3,biomesoplenty:log_1:5)
Block(-6,22,-2,biomesoplenty:log_1:5)
Block(-5,22,-2,biomesoplenty:log_1:5)
Block(-4,22,-2,biomesoplenty:log_1:5)
Block(-3,22,-2,biomesoplenty:log_1:5)
Block(-2,22,-2,biomesoplenty:log_1:5)
Block(-8,22,-1,biomesoplenty:leaves_0:11)
Block(-6,22,-1,biomesoplenty:log_1:5)
Block(-5,22,-1,biomesoplenty:log_1:5)
Block(-4,22,-1,biomesoplenty:log_1:5)
Block(-3,22,-1,biomesoplenty:log_1:5)
Block(-9,22,0,biomesoplenty:log_1:5)
Block(-8,22,0,biomesoplenty:log_1:5)
Block(-7,22,0,biomesoplenty:log_1:5)
Block(-6,22,0,biomesoplenty:log_1:5)
Block(-5,22,0,biomesoplenty:log_1:5)
Block(-10,22,1,biomesoplenty:leaves_0:11)
Block(-9,22,1,biomesoplenty:log_1:5)
Block(-8,22,1,biomesoplenty:log_1:5)
Block(-7,22,1,biomesoplenty:log_1:5)
Block(-6,22,1,biomesoplenty:log_1:5)
Block(8,22,1,biomesoplenty:leaves_0:11)
Block(-9,22,2,biomesoplenty:log_1:5)
Block(-8,22,2,biomesoplenty:log_1:5)
Block(-7,22,2,biomesoplenty:log_1:5)
Block(6,22,2,biomesoplenty:leaves_0:11)
Block(7,22,2,biomesoplenty:leaves_0:11)
Block(8,22,2,biomesoplenty:leaves_0:11)
Block(9,22,2,biomesoplenty:leaves_0:11)
Block(10,22,2,biomesoplenty:leaves_0:11)
Block(-10,22,3,biomesoplenty:log_1:5)
Block(-9,22,3,biomesoplenty:log_1:5)
Block(-8,22,3,biomesoplenty:log_1:5)
Block(-7,22,3,biomesoplenty:log_1:5)
Block(5,22,3,biomesoplenty:leaves_0:11)
Block(6,22,3,biomesoplenty:leaves_0:11)
Block(7,22,3,biomesoplenty:leaves_0:11)
Block(8,22,3,biomesoplenty:leaves_0:11)
Block(11,22,3,biomesoplenty:leaves_0:11)
Block(-9,22,4,biomesoplenty:log_1:5)
Block(-8,22,4,biomesoplenty:log_1:5)
Block(5,22,4,biomesoplenty:leaves_0:11)
Block(6,22,4,biomesoplenty:leaves_0:11)
Block(8,22,4,biomesoplenty:leaves_0:11)
Block(9,22,4,biomesoplenty:leaves_0:11)
Block(12,22,4,biomesoplenty:leaves_0:11)
Block(13,22,4,biomesoplenty:leaves_0:11)
Block(3,22,5,biomesoplenty:leaves_0:11)
Block(4,22,5,biomesoplenty:leaves_0:11)
Block(11,22,5,biomesoplenty:leaves_0:11)
Block(12,22,5,biomesoplenty:leaves_0:11)
Block(13,22,5,biomesoplenty:leaves_0:11)
Block(14,22,5,biomesoplenty:leaves_0:11)
Block(4,22,6,biomesoplenty:leaves_0:11)
Block(11,22,6,biomesoplenty:leaves_0:11)
Block(13,22,6,biomesoplenty:leaves_0:11)
Block(14,22,6,biomesoplenty:leaves_0:11)
Block(-13,22,7,biomesoplenty:leaves_0:11)
Block(3,22,7,biomesoplenty:leaves_0:11)
Block(4,22,7,biomesoplenty:leaves_0:11)
Block(5,22,7,biomesoplenty:leaves_0:11)
Block(6,22,7,biomesoplenty:log_1:5)
Block(7,22,7,biomesoplenty:log_1:5)
Block(8,22,7,biomesoplenty:log_1:5)
Block(13,22,7,biomesoplenty:leaves_0:11)
Block(14,22,7,biomesoplenty:leaves_0:11)
Block(15,22,7,biomesoplenty:leaves_0:11)
Block(4,22,8,biomesoplenty:leaves_0:11)
Block(5,22,8,biomesoplenty:log_1:5)
Block(6,22,8,biomesoplenty:log_1:5)
Block(7,22,8,biomesoplenty:log_1:5)
Block(8,22,8,biomesoplenty:log_1:5)
Block(9,22,8,biomesoplenty:log_1:5)
Block(14,22,8,biomesoplenty:leaves_0:11)
Block(3,22,9,biomesoplenty:leaves_0:11)
Block(4,22,9,biomesoplenty:leaves_0:11)
Block(5,22,9,biomesoplenty:leaves_0:11)
Block(6,22,9,biomesoplenty:log_1:5)
Block(7,22,9,biomesoplenty:log_1:5)
Block(8,22,9,biomesoplenty:log_1:5)
Block(10,22,9,biomesoplenty:leaves_0:11)
Block(15,22,9,biomesoplenty:leaves_0:11)
Block(4,22,10,biomesoplenty:leaves_0:11)
Block(5,22,10,biomesoplenty:leaves_0:11)
Block(7,22,10,biomesoplenty:leaves_0:11)
Block(10,22,10,biomesoplenty:leaves_0:11)
Block(15,22,10,biomesoplenty:leaves_0:11)
Block(4,22,11,biomesoplenty:leaves_0:11)
Block(5,22,11,biomesoplenty:leaves_0:11)
Block(12,22,11,biomesoplenty:leaves_0:11)
Block(13,22,11,biomesoplenty:leaves_0:11)
Block(14,22,11,biomesoplenty:leaves_0:11)
Block(5,22,12,biomesoplenty:leaves_0:11)
Block(12,22,12,biomesoplenty:leaves_0:11)
Block(4,22,13,biomesoplenty:leaves_0:11)
Block(5,22,13,biomesoplenty:leaves_0:11)
Block(6,22,13,biomesoplenty:leaves_0:11)
Block(11,22,13,biomesoplenty:leaves_0:11)
Block(5,22,14,biomesoplenty:leaves_0:11)
Block(6,22,14,biomesoplenty:leaves_0:11)
Block(7,22,14,biomesoplenty:leaves_0:11)
Block(9,22,14,biomesoplenty:leaves_0:11)
Block(10,22,14,biomesoplenty:leaves_0:11)
Block(12,22,14,biomesoplenty:leaves_0:11)
Block(8,22,15,biomesoplenty:leaves_0:11)
Block(9,22,15,biomesoplenty:leaves_0:11)
Block(-4,23,-6,biomesoplenty:log_1:5)
Block(-5,23,-5,biomesoplenty:log_1:5)
Block(-4,23,-5,biomesoplenty:log_1:5)
Block(-3,23,-5,biomesoplenty:log_1:5)
Block(-2,23,-5,biomesoplenty:log_1:5)
Block(-6,23,-4,biomesoplenty:log_1:5)
Block(-5,23,-4,biomesoplenty:log_1:5)
Block(-4,23,-4,biomesoplenty:log_1:5)
Block(-3,23,-4,biomesoplenty:log_1:5)
Block(-2,23,-4,biomesoplenty:log_1:5)
Block(0,23,-4,biomesoplenty:leaves_0:11)
Block(-6,23,-3,biomesoplenty:log_1:5)
Block(-5,23,-3,biomesoplenty:log_1:5)
Block(-4,23,-3,biomesoplenty:log_1:5)
Block(-3,23,-3,biomesoplenty:log_1:5)
Block(-2,23,-3,biomesoplenty:log_1:5)
Block(-1,23,-3,biomesoplenty:log_1:5)
Block(-6,23,-2,biomesoplenty:log_1:5)
Block(-5,23,-2,biomesoplenty:log_1:5)
Block(-4,23,-2,biomesoplenty:log_1:5)
Block(-3,23,-2,biomesoplenty:log_1:5)
Block(-2,23,-2,biomesoplenty:log_1:5)
Block(-1,23,-2,biomesoplenty:log_1:5)
Block(-6,23,-1,biomesoplenty:log_1:5)
Block(-5,23,-1,biomesoplenty:log_1:5)
Block(-4,23,-1,biomesoplenty:log_1:5)
Block(-3,23,-1,biomesoplenty:log_1:5)
Block(-2,23,-1,biomesoplenty:log_1:5)
Block(-9,23,0,biomesoplenty:leaves_0:11)
Block(-8,23,0,biomesoplenty:log_1:5)
Block(-7,23,0,biomesoplenty:leaves_0:11)
Block(-6,23,0,biomesoplenty:leaves_0:11)
Block(-9,23,1,biomesoplenty:log_1:5)
Block(-8,23,1,biomesoplenty:log_1:5)
Block(-7,23,1,biomesoplenty:log_1:5)
Block(7,23,1,biomesoplenty:leaves_0:11)
Block(8,23,1,biomesoplenty:leaves_0:11)
Block(9,23,1,biomesoplenty:leaves_0:11)
Block(-10,23,2,biomesoplenty:log_1:5)
Block(-9,23,2,biomesoplenty:log_1:5)
Block(-8,23,2,biomesoplenty:log_1:5)
Block(-7,23,2,biomesoplenty:log_1:5)
Block(5,23,2,biomesoplenty:leaves_0:11)
Block(6,23,2,biomesoplenty:leaves_0:11)
Block(7,23,2,biomesoplenty:leaves_0:11)
Block(9,23,2,biomesoplenty:leaves_0:11)
Block(10,23,2,biomesoplenty:leaves_0:11)
Block(11,23,2,biomesoplenty:leaves_0:11)
Block(-10,23,3,biomesoplenty:log_1:5)
Block(-9,23,3,biomesoplenty:log_1:5)
Block(-8,23,3,biomesoplenty:log_1:5)
Block(-7,23,3,biomesoplenty:log_1:5)
Block(5,23,3,biomesoplenty:leaves_0:11)
Block(6,23,3,biomesoplenty:leaves_0:11)
Block(7,23,3,biomesoplenty:leaves_0:11)
Block(8,23,3,biomesoplenty:leaves_0:11)
Block(9,23,3,biomesoplenty:leaves_0:11)
Block(10,23,3,biomesoplenty:leaves_0:11)
Block(11,23,3,biomesoplenty:leaves_0:11)
Block(12,23,3,biomesoplenty:leaves_0:11)
Block(13,23,3,biomesoplenty:leaves_0:11)
Block(-10,23,4,biomesoplenty:log_1:5)
Block(-9,23,4,biomesoplenty:log_1:5)
Block(-8,23,4,biomesoplenty:log_1:5)
Block(-7,23,4,biomesoplenty:log_1:5)
Block(4,23,4,biomesoplenty:leaves_0:11)
Block(5,23,4,biomesoplenty:leaves_0:11)
Block(6,23,4,biomesoplenty:leaves_0:11)
Block(7,23,4,biomesoplenty:log_1:5)
Block(8,23,4,biomesoplenty:log_1:5)
Block(9,23,4,biomesoplenty:leaves_0:11)
Block(10,23,4,biomesoplenty:leaves_0:11)
Block(11,23,4,biomesoplenty:leaves_0:11)
Block(13,23,4,biomesoplenty:leaves_0:11)
Block(14,23,4,biomesoplenty:leaves_0:11)
Block(-10,23,5,biomesoplenty:leaves_0:11)
Block(-9,23,5,biomesoplenty:log_1:5)
Block(4,23,5,biomesoplenty:leaves_0:11)
Block(5,23,5,biomesoplenty:leaves_0:11)
Block(7,23,5,biomesoplenty:log_1:5)
Block(9,23,5,biomesoplenty:leaves_0:11)
Block(10,23,5,biomesoplenty:leaves_0:11)
Block(11,23,5,biomesoplenty:leaves_0:11)
Block(12,23,5,biomesoplenty:leaves_0:11)
Block(13,23,5,biomesoplenty:leaves_0:11)
Block(14,23,5,biomesoplenty:leaves_0:11)
Block(-9,23,6,biomesoplenty:leaves_0:11)
Block(3,23,6,biomesoplenty:leaves_0:11)
Block(4,23,6,biomesoplenty:leaves_0:11)
Block(7,23,6,biomesoplenty:log_1:5)
Block(11,23,6,biomesoplenty:leaves_0:11)
Block(13,23,6,biomesoplenty:leaves_0:11)
Block(14,23,6,biomesoplenty:leaves_0:11)
Block(-13,23,7,biomesoplenty:leaves_0:11)
Block(3,23,7,biomesoplenty:leaves_0:11)
Block(4,23,7,biomesoplenty:leaves_0:11)
Block(5,23,7,biomesoplenty:leaves_0:11)
Block(6,23,7,biomesoplenty:leaves_0:11)
Block(7,23,7,biomesoplenty:leaves_0:11)
Block(8,23,7,biomesoplenty:log_1:5)
Block(12,23,7,biomesoplenty:leaves_0:11)
Block(13,23,7,biomesoplenty:leaves_0:11)
Block(14,23,7,biomesoplenty:leaves_0:11)
Block(15,23,7,biomesoplenty:leaves_0:11)
Block(3,23,8,biomesoplenty:leaves_0:11)
Block(4,23,8,biomesoplenty:leaves_0:11)
Block(5,23,8,biomesoplenty:leaves_0:11)
Block(6,23,8,biomesoplenty:leaves_0:11)
Block(7,23,8,biomesoplenty:leaves_0:11)
Block(8,23,8,biomesoplenty:leaves_0:11)
Block(9,23,8,biomesoplenty:log_1:5)
Block(10,23,8,biomesoplenty:log_1:5)
Block(13,23,8,biomesoplenty:leaves_0:11)
Block(14,23,8,biomesoplenty:leaves_0:11)
Block(15,23,8,biomesoplenty:leaves_0:11)
Block(3,23,9,biomesoplenty:leaves_0:11)
Block(4,23,9,biomesoplenty:leaves_0:11)
Block(5,23,9,biomesoplenty:leaves_0:11)
Block(6,23,9,biomesoplenty:leaves_0:11)
Block(7,23,9,biomesoplenty:leaves_0:11)
Block(8,23,9,biomesoplenty:leaves_0:11)
Block(9,23,9,biomesoplenty:leaves_0:11)
Block(10,23,9,biomesoplenty:leaves_0:11)
Block(14,23,9,biomesoplenty:leaves_0:11)
Block(15,23,9,biomesoplenty:leaves_0:11)
Block(3,23,10,biomesoplenty:leaves_0:11)
Block(4,23,10,biomesoplenty:leaves_0:11)
Block(5,23,10,biomesoplenty:leaves_0:11)
Block(6,23,10,biomesoplenty:leaves_0:11)
Block(7,23,10,biomesoplenty:leaves_0:11)
Block(8,23,10,biomesoplenty:leaves_0:11)
Block(10,23,10,biomesoplenty:leaves_0:11)
Block(12,23,10,biomesoplenty:leaves_0:11)
Block(13,23,10,biomesoplenty:leaves_0:11)
Block(14,23,10,biomesoplenty:leaves_0:11)
Block(15,23,10,biomesoplenty:leaves_0:11)
Block(-9,23,11,biomesoplenty:leaves_0:11)
Block(4,23,11,biomesoplenty:leaves_0:11)
Block(5,23,11,biomesoplenty:leaves_0:11)
Block(6,23,11,biomesoplenty:leaves_0:11)
Block(13,23,11,biomesoplenty:leaves_0:11)
Block(14,23,11,biomesoplenty:leaves_0:11)
Block(15,23,11,biomesoplenty:leaves_0:11)
Block(4,23,12,biomesoplenty:leaves_0:11)
Block(5,23,12,biomesoplenty:leaves_0:11)
Block(6,23,12,biomesoplenty:leaves_0:11)
Block(7,23,12,biomesoplenty:leaves_0:11)
Block(11,23,12,biomesoplenty:leaves_0:11)
Block(12,23,12,biomesoplenty:leaves_0:11)
Block(13,23,12,biomesoplenty:leaves_0:11)
Block(14,23,12,biomesoplenty:leaves_0:11)
Block(4,23,13,biomesoplenty:leaves_0:11)
Block(5,23,13,biomesoplenty:leaves_0:11)
Block(6,23,13,biomesoplenty:leaves_0:11)
Block(7,23,13,biomesoplenty:leaves_0:11)
Block(8,23,13,biomesoplenty:leaves_0:11)
Block(10,23,13,biomesoplenty:leaves_0:11)
Block(11,23,13,biomesoplenty:leaves_0:11)
Block(12,23,13,biomesoplenty:leaves_0:11)
Block(13,23,13,biomesoplenty:leaves_0:11)
Block(4,23,14,biomesoplenty:leaves_0:11)
Block(6,23,14,biomesoplenty:leaves_0:11)
Block(7,23,14,biomesoplenty:leaves_0:11)
Block(8,23,14,biomesoplenty:leaves_0:11)
Block(9,23,14,biomesoplenty:leaves_0:11)
Block(10,23,14,biomesoplenty:leaves_0:11)
Block(11,23,14,biomesoplenty:leaves_0:11)
Block(12,23,14,biomesoplenty:leaves_0:11)
Block(6,23,15,biomesoplenty:leaves_0:11)
Block(7,23,15,biomesoplenty:leaves_0:11)
Block(8,23,15,biomesoplenty:leaves_0:11)
Block(9,23,15,biomesoplenty:leaves_0:11)
Block(10,23,15,biomesoplenty:leaves_0:11)
Block(11,23,15,biomesoplenty:leaves_0:11)
Block(-4,24,-6,biomesoplenty:log_1:5)
Block(-3,24,-6,biomesoplenty:log_1:5)
Block(-5,24,-5,biomesoplenty:log_1:5)
Block(-4,24,-5,biomesoplenty:log_1:5)
Block(-3,24,-5,biomesoplenty:log_1:5)
Block(-2,24,-5,biomesoplenty:log_1:5)
Block(-6,24,-4,biomesoplenty:log_1:5)
Block(-5,24,-4,biomesoplenty:log_1:5)
Block(-4,24,-4,biomesoplenty:log_1:5)
Block(-3,24,-4,biomesoplenty:log_1:5)
Block(-2,24,-4,biomesoplenty:log_1:5)
Block(-1,24,-4,biomesoplenty:log_1:5)
Block(0,24,-4,biomesoplenty:leaves_0:11)
Block(-6,24,-3,biomesoplenty:log_1:5)
Block(-5,24,-3,biomesoplenty:log_1:5)
Block(-4,24,-3,biomesoplenty:log_1:5)
Block(-3,24,-3,biomesoplenty:log_1:5)
Block(-2,24,-3,biomesoplenty:log_1:5)
Block(-1,24,-3,biomesoplenty:log_1:5)
Block(0,24,-3,biomesoplenty:log_1:5)
Block(-6,24,-2,biomesoplenty:log_1:5)
Block(-5,24,-2,biomesoplenty:log_1:5)
Block(-4,24,-2,biomesoplenty:log_1:5)
Block(-3,24,-2,biomesoplenty:log_1:5)
Block(-2,24,-2,biomesoplenty:log_1:5)
Block(-1,24,-2,biomesoplenty:log_1:5)
Block(-6,24,-1,biomesoplenty:leaves_0:11)
Block(-5,24,-1,biomesoplenty:log_1:5)
Block(-4,24,-1,biomesoplenty:log_1:5)
Block(-3,24,-1,biomesoplenty:log_1:5)
Block(-2,24,-1,biomesoplenty:log_1:5)
Block(-5,24,0,biomesoplenty:leaves_0:11)
Block(-11,24,1,biomesoplenty:leaves_0:11)
Block(8,24,1,biomesoplenty:leaves_0:11)
Block(-10,24,2,biomesoplenty:log_1:5)
Block(-9,24,2,biomesoplenty:log_1:5)
Block(-8,24,2,biomesoplenty:log_1:5)
Block(6,24,2,biomesoplenty:leaves_0:11)
Block(7,24,2,biomesoplenty:leaves_0:11)
Block(8,24,2,biomesoplenty:leaves_0:11)
Block(9,24,2,biomesoplenty:leaves_0:11)
Block(-10,24,3,biomesoplenty:log_1:5)
Block(-9,24,3,biomesoplenty:log_1:5)
Block(-8,24,3,biomesoplenty:log_1:5)
Block(-7,24,3,biomesoplenty:log_1:5)
Block(5,24,3,biomesoplenty:leaves_0:11)
Block(6,24,3,biomesoplenty:leaves_0:11)
Block(7,24,3,biomesoplenty:leaves_0:11)
Block(8,24,3,biomesoplenty:leaves_0:11)
Block(9,24,3,biomesoplenty:leaves_0:11)
Block(10,24,3,biomesoplenty:leaves_0:11)
Block(11,24,3,biomesoplenty:leaves_0:11)
Block(-10,24,4,biomesoplenty:log_1:5)
Block(-9,24,4,biomesoplenty:log_1:5)
Block(-8,24,4,biomesoplenty:log_1:5)
Block(6,24,4,biomesoplenty:leaves_0:11)
Block(7,24,4,biomesoplenty:leaves_0:11)
Block(9,24,4,biomesoplenty:leaves_0:11)
Block(10,24,4,biomesoplenty:leaves_0:11)
Block(11,24,4,biomesoplenty:leaves_0:11)
Block(12,24,4,biomesoplenty:leaves_0:11)
Block(-15,24,5,biomesoplenty:leaves_0:11)
Block(-11,24,5,biomesoplenty:leaves_0:11)
Block(-10,24,5,biomesoplenty:log_1:5)
Block(-9,24,5,biomesoplenty:log_1:5)
Block(-8,24,5,biomesoplenty:log_1:5)
Block(4,24,5,biomesoplenty:leaves_0:11)
Block(5,24,5,biomesoplenty:leaves_0:11)
Block(6,24,5,biomesoplenty:leaves_0:11)
Block(7,24,5,biomesoplenty:leaves_0:11)
Block(8,24,5,biomesoplenty:leaves_0:11)
Block(9,24,5,biomesoplenty:leaves_0:11)
Block(10,24,5,biomesoplenty:leaves_0:11)
Block(11,24,5,biomesoplenty:leaves_0:11)
Block(12,24,5,biomesoplenty:leaves_0:11)
Block(13,24,5,biomesoplenty:leaves_0:11)
Block(14,24,5,biomesoplenty:leaves_0:11)
Block(-9,24,6,biomesoplenty:log_1:5)
Block(-8,24,6,biomesoplenty:leaves_0:11)
Block(4,24,6,biomesoplenty:leaves_0:11)
Block(5,24,6,biomesoplenty:leaves_0:11)
Block(6,24,6,biomesoplenty:leaves_0:11)
Block(7,24,6,biomesoplenty:leaves_0:11)
Block(8,24,6,biomesoplenty:leaves_0:11)
Block(9,24,6,biomesoplenty:leaves_0:11)
Block(10,24,6,biomesoplenty:leaves_0:11)
Block(11,24,6,biomesoplenty:leaves_0:11)
Block(13,24,6,biomesoplenty:leaves_0:11)
Block(14,24,6,biomesoplenty:leaves_0:11)
Block(-13,24,7,biomesoplenty:leaves_0:11)
Block(-6,24,7,biomesoplenty:leaves_0:11)
Block(3,24,7,biomesoplenty:leaves_0:11)
Block(4,24,7,biomesoplenty:leaves_0:11)
Block(5,24,7,biomesoplenty:leaves_0:11)
Block(6,24,7,biomesoplenty:leaves_0:11)
Block(7,24,7,biomesoplenty:leaves_0:11)
Block(8,24,7,biomesoplenty:log_1:5)
Block(9,24,7,biomesoplenty:leaves_0:11)
Block(10,24,7,biomesoplenty:leaves_0:11)
Block(11,24,7,biomesoplenty:leaves_0:11)
Block(12,24,7,biomesoplenty:leaves_0:11)
Block(13,24,7,biomesoplenty:leaves_0:11)
Block(14,24,7,biomesoplenty:leaves_0:11)
Block(3,24,8,biomesoplenty:leaves_0:11)
Block(4,24,8,biomesoplenty:leaves_0:11)
Block(5,24,8,biomesoplenty:leaves_0:11)
Block(6,24,8,biomesoplenty:leaves_0:11)
Block(7,24,8,biomesoplenty:log_1:5)
Block(8,24,8,biomesoplenty:log_1:5)
Block(9,24,8,biomesoplenty:log_1:5)
Block(10,24,8,biomesoplenty:leaves_0:11)
Block(11,24,8,biomesoplenty:log_1:5)
Block(12,24,8,biomesoplenty:log_1:5)
Block(14,24,8,biomesoplenty:leaves_0:11)
Block(15,24,8,biomesoplenty:leaves_0:11)
Block(3,24,9,biomesoplenty:leaves_0:11)
Block(4,24,9,biomesoplenty:leaves_0:11)
Block(5,24,9,biomesoplenty:leaves_0:11)
Block(6,24,9,biomesoplenty:leaves_0:11)
Block(7,24,9,biomesoplenty:leaves_0:11)
Block(8,24,9,biomesoplenty:log_1:5)
Block(9,24,9,biomesoplenty:leaves_0:11)
Block(10,24,9,biomesoplenty:leaves_0:11)
Block(11,24,9,biomesoplenty:leaves_0:11)
Block(12,24,9,biomesoplenty:log_1:5)
Block(13,24,9,biomesoplenty:leaves_0:11)
Block(14,24,9,biomesoplenty:leaves_0:11)
Block(15,24,9,biomesoplenty:leaves_0:11)
Block(-11,24,10,biomesoplenty:leaves_0:11)
Block(-7,24,10,biomesoplenty:leaves_0:11)
Block(4,24,10,biomesoplenty:leaves_0:11)
Block(5,24,10,biomesoplenty:leaves_0:11)
Block(6,24,10,biomesoplenty:leaves_0:11)
Block(7,24,10,biomesoplenty:leaves_0:11)
Block(8,24,10,biomesoplenty:leaves_0:11)
Block(9,24,10,biomesoplenty:leaves_0:11)
Block(10,24,10,biomesoplenty:leaves_0:11)
Block(11,24,10,biomesoplenty:leaves_0:11)
Block(12,24,10,biomesoplenty:leaves_0:11)
Block(13,24,10,biomesoplenty:leaves_0:11)
Block(14,24,10,biomesoplenty:leaves_0:11)
Block(15,24,10,biomesoplenty:leaves_0:11)
Block(-9,24,11,biomesoplenty:leaves_0:11)
Block(4,24,11,biomesoplenty:leaves_0:11)
Block(5,24,11,biomesoplenty:leaves_0:11)
Block(6,24,11,biomesoplenty:leaves_0:11)
Block(7,24,11,biomesoplenty:leaves_0:11)
Block(8,24,11,biomesoplenty:leaves_0:11)
Block(10,24,11,biomesoplenty:leaves_0:11)
Block(12,24,11,biomesoplenty:leaves_0:11)
Block(13,24,11,biomesoplenty:leaves_0:11)
Block(14,24,11,biomesoplenty:leaves_0:11)
Block(4,24,12,biomesoplenty:leaves_0:11)
Block(5,24,12,biomesoplenty:leaves_0:11)
Block(7,24,12,biomesoplenty:leaves_0:11)
Block(8,24,12,biomesoplenty:leaves_0:11)
Block(10,24,12,biomesoplenty:leaves_0:11)
Block(11,24,12,biomesoplenty:leaves_0:11)
Block(12,24,12,biomesoplenty:leaves_0:11)
Block(13,24,12,biomesoplenty:leaves_0:11)
Block(14,24,12,biomesoplenty:leaves_0:11)
Block(4,24,13,biomesoplenty:leaves_0:11)
Block(5,24,13,biomesoplenty:leaves_0:11)
Block(6,24,13,biomesoplenty:leaves_0:11)
Block(7,24,13,biomesoplenty:leaves_0:11)
Block(8,24,13,biomesoplenty:leaves_0:11)
Block(9,24,13,biomesoplenty:leaves_0:11)
Block(10,24,13,biomesoplenty:leaves_0:11)
Block(12,24,13,biomesoplenty:leaves_0:11)
Block(13,24,13,biomesoplenty:leaves_0:11)
Block(5,24,14,biomesoplenty:leaves_0:11)
Block(6,24,14,biomesoplenty:leaves_0:11)
Block(7,24,14,biomesoplenty:leaves_0:11)
Block(8,24,14,biomesoplenty:leaves_0:11)
Block(9,24,14,biomesoplenty:leaves_0:11)
Block(10,24,14,biomesoplenty:leaves_0:11)
Block(7,24,15,biomesoplenty:leaves_0:11)
Block(8,24,15,biomesoplenty:leaves_0:11)
Block(9,24,15,biomesoplenty:leaves_0:11)
Block(-4,25,-6,biomesoplenty:log_1:5)
Block(-3,25,-6,biomesoplenty:log_1:5)
Block(-5,25,-5,biomesoplenty:log_1:5)
Block(-4,25,-5,biomesoplenty:log_1:5)
Block(-3,25,-5,biomesoplenty:log_1:5)
Block(-2,25,-5,biomesoplenty:log_1:5)
Block(-1,25,-5,biomesoplenty:log_1:5)
Block(-6,25,-4,biomesoplenty:log_1:5)
Block(-5,25,-4,biomesoplenty:log_1:5)
Block(-4,25,-4,biomesoplenty:log_1:5)
Block(-3,25,-4,biomesoplenty:log_1:5)
Block(-2,25,-4,biomesoplenty:log_1:5)
Block(-1,25,-4,biomesoplenty:log_1:5)
Block(1,25,-4,biomesoplenty:leaves_0:11)
Block(-6,25,-3,biomesoplenty:log_1:5)
Block(-5,25,-3,biomesoplenty:log_1:5)
Block(-4,25,-3,biomesoplenty:log_1:5)
Block(-3,25,-3,biomesoplenty:log_1:5)
Block(-2,25,-3,biomesoplenty:log_1:5)
Block(-1,25,-3,biomesoplenty:log_1:5)
Block(0,25,-3,biomesoplenty:log_1:5)
Block(1,25,-3,biomesoplenty:log_1:5)
Block(2,25,-3,biomesoplenty:leaves_0:11)
Block(-6,25,-2,biomesoplenty:leaves_0:11)
Block(-5,25,-2,biomesoplenty:log_1:5)
Block(-4,25,-2,biomesoplenty:log_1:5)
Block(-3,25,-2,biomesoplenty:log_1:5)
Block(-2,25,-2,biomesoplenty:log_1:5)
Block(-1,25,-2,biomesoplenty:log_1:5)
Block(0,25,-2,biomesoplenty:log_1:5)
Block(-4,25,-1,biomesoplenty:log_1:5)
Block(-3,25,-1,biomesoplenty:log_1:5)
Block(-2,25,-1,biomesoplenty:log_1:5)
Block(-4,25,0,biomesoplenty:leaves_0:11)
Block(-11,25,1,biomesoplenty:leaves_0:11)
Block(-9,25,2,biomesoplenty:log_1:5)
Block(-13,25,3,biomesoplenty:leaves_0:11)
Block(-10,25,3,biomesoplenty:log_1:5)
Block(-9,25,3,biomesoplenty:log_1:5)
Block(7,25,3,biomesoplenty:leaves_0:11)
Block(8,25,3,biomesoplenty:leaves_0:11)
Block(9,25,3,biomesoplenty:leaves_0:11)
Block(10,25,3,biomesoplenty:leaves_0:11)
Block(-11,25,4,biomesoplenty:leaves_0:11)
Block(-10,25,4,biomesoplenty:log_1:5)
Block(-9,25,4,biomesoplenty:log_1:5)
Block(-8,25,4,biomesoplenty:log_1:5)
Block(-6,25,4,biomesoplenty:leaves_0:11)
Block(6,25,4,biomesoplenty:leaves_0:11)
Block(8,25,4,biomesoplenty:leaves_0:11)
Block(9,25,4,biomesoplenty:leaves_0:11)
Block(11,25,4,biomesoplenty:leaves_0:11)
Block(-15,25,5,biomesoplenty:leaves_0:11)
Block(-11,25,5,biomesoplenty:log_1:5)
Block(-10,25,5,biomesoplenty:log_1:5)
Block(-9,25,5,biomesoplenty:log_1:5)
Block(-8,25,5,biomesoplenty:log_1:5)
Block(6,25,5,biomesoplenty:leaves_0:11)
Block(7,25,5,biomesoplenty:leaves_0:11)
Block(8,25,5,biomesoplenty:leaves_0:11)
Block(9,25,5,biomesoplenty:leaves_0:11)
Block(10,25,5,biomesoplenty:leaves_0:11)
Block(11,25,5,biomesoplenty:leaves_0:11)
Block(12,25,5,biomesoplenty:leaves_0:11)
Block(-10,25,6,biomesoplenty:log_1:5)
Block(-9,25,6,biomesoplenty:log_1:5)
Block(-8,25,6,biomesoplenty:log_1:5)
Block(5,25,6,biomesoplenty:leaves_0:11)
Block(7,25,6,biomesoplenty:leaves_0:11)
Block(8,25,6,biomesoplenty:leaves_0:11)
Block(9,25,6,biomesoplenty:leaves_0:11)
Block(10,25,6,biomesoplenty:leaves_0:11)
Block(12,25,6,biomesoplenty:leaves_0:11)
Block(13,25,6,biomesoplenty:leaves_0:11)
Block(-13,25,7,biomesoplenty:leaves_0:11)
Block(-8,25,7,biomesoplenty:leaves_0:11)
Block(-6,25,7,biomesoplenty:leaves_0:11)
Block(5,25,7,biomesoplenty:leaves_0:11)
Block(6,25,7,biomesoplenty:leaves_0:11)
Block(7,25,7,biomesoplenty:leaves_0:11)
Block(8,25,7,biomesoplenty:leaves_0:11)
Block(9,25,7,biomesoplenty:leaves_0:11)
Block(10,25,7,biomesoplenty:leaves_0:11)
Block(11,25,7,biomesoplenty:leaves_0:11)
Block(13,25,7,biomesoplenty:leaves_0:11)
Block(3,25,8,biomesoplenty:leaves_0:11)
Block(4,25,8,biomesoplenty:leaves_0:11)
Block(6,25,8,biomesoplenty:leaves_0:11)
Block(7,25,8,biomesoplenty:leaves_0:11)
Block(8,25,8,biomesoplenty:leaves_0:11)
Block(9,25,8,biomesoplenty:leaves_0:11)
Block(10,25,8,biomesoplenty:leaves_0:11)
Block(11,25,8,biomesoplenty:leaves_0:11)
Block(12,25,8,biomesoplenty:leaves_0:11)
Block(14,25,8,biomesoplenty:leaves_0:11)
Block(5,25,9,biomesoplenty:leaves_0:11)
Block(6,25,9,biomesoplenty:leaves_0:11)
Block(7,25,9,biomesoplenty:leaves_0:11)
Block(8,25,9,biomesoplenty:leaves_0:11)
Block(9,25,9,biomesoplenty:leaves_0:11)
Block(10,25,9,biomesoplenty:leaves_0:11)
Block(11,25,9,biomesoplenty:leaves_0:11)
Block(12,25,9,biomesoplenty:leaves_0:11)
Block(13,25,9,biomesoplenty:leaves_0:11)
Block(14,25,9,biomesoplenty:leaves_0:11)
Block(-11,25,10,biomesoplenty:leaves_0:11)
Block(-7,25,10,biomesoplenty:leaves_0:11)
Block(4,25,10,biomesoplenty:leaves_0:11)
Block(7,25,10,biomesoplenty:leaves_0:11)
Block(8,25,10,biomesoplenty:leaves_0:11)
Block(9,25,10,biomesoplenty:leaves_0:11)
Block(10,25,10,biomesoplenty:leaves_0:11)
Block(12,25,10,biomesoplenty:leaves_0:11)
Block(13,25,10,biomesoplenty:leaves_0:11)
Block(-9,25,11,biomesoplenty:leaves_0:11)
Block(5,25,11,biomesoplenty:leaves_0:11)
Block(6,25,11,biomesoplenty:leaves_0:11)
Block(7,25,11,biomesoplenty:leaves_0:11)
Block(8,25,11,biomesoplenty:leaves_0:11)
Block(9,25,11,biomesoplenty:leaves_0:11)
Block(10,25,11,biomesoplenty:leaves_0:11)
Block(11,25,11,biomesoplenty:leaves_0:11)
Block(12,25,11,biomesoplenty:leaves_0:11)
Block(13,25,11,biomesoplenty:leaves_0:11)
Block(14,25,11,biomesoplenty:leaves_0:11)
Block(5,25,12,biomesoplenty:leaves_0:11)
Block(7,25,12,biomesoplenty:leaves_0:11)
Block(8,25,12,biomesoplenty:leaves_0:11)
Block(9,25,12,biomesoplenty:leaves_0:11)
Block(10,25,12,biomesoplenty:leaves_0:11)
Block(11,25,12,biomesoplenty:leaves_0:11)
Block(12,25,12,biomesoplenty:leaves_0:11)
Block(13,25,12,biomesoplenty:leaves_0:11)
Block(5,25,13,biomesoplenty:leaves_0:11)
Block(6,25,13,biomesoplenty:leaves_0:11)
Block(7,25,13,biomesoplenty:leaves_0:11)
Block(9,25,13,biomesoplenty:leaves_0:11)
Block(12,25,13,biomesoplenty:leaves_0:11)
Block(7,25,14,biomesoplenty:leaves_0:11)
Block(8,25,14,biomesoplenty:leaves_0:11)
Block(-4,26,-6,biomesoplenty:log_1:5)
Block(-3,26,-6,biomesoplenty:log_1:5)
Block(-5,26,-5,biomesoplenty:log_1:5)
Block(-4,26,-5,biomesoplenty:log_1:5)
Block(-3,26,-5,biomesoplenty:log_1:5)
Block(-2,26,-5,biomesoplenty:log_1:5)
Block(-1,26,-5,biomesoplenty:log_1:5)
Block(0,26,-5,biomesoplenty:log_1:5)
Block(1,26,-5,biomesoplenty:leaves_0:11)
Block(-6,26,-4,biomesoplenty:log_1:5)
Block(-5,26,-4,biomesoplenty:log_1:5)
Block(-4,26,-4,biomesoplenty:log_1:5)
Block(-3,26,-4,biomesoplenty:log_1:5)
Block(-2,26,-4,biomesoplenty:log_1:5)
Block(-1,26,-4,biomesoplenty:log_1:5)
Block(0,26,-4,biomesoplenty:log_1:5)
Block(1,26,-4,biomesoplenty:log_1:5)
Block(-6,26,-3,biomesoplenty:leaves_0:11)
Block(-5,26,-3,biomesoplenty:log_1:5)
Block(-4,26,-3,biomesoplenty:log_1:5)
Block(-3,26,-3,biomesoplenty:log_1:5)
Block(-2,26,-3,biomesoplenty:log_1:5)
Block(-1,26,-3,biomesoplenty:log_1:5)
Block(0,26,-3,biomesoplenty:log_1:5)
Block(1,26,-3,biomesoplenty:log_1:5)
Block(2,26,-3,biomesoplenty:log_1:5)
Block(3,26,-3,biomesoplenty:log_1:5)
Block(-5,26,-2,biomesoplenty:log_1:5)
Block(-4,26,-2,biomesoplenty:log_1:5)
Block(-3,26,-2,biomesoplenty:log_1:5)
Block(-2,26,-2,biomesoplenty:log_1:5)
Block(-1,26,-2,biomesoplenty:log_1:5)
Block(0,26,-2,biomesoplenty:log_1:5)
Block(1,26,-2,biomesoplenty:leaves_0:11)
Block(-4,26,-1,biomesoplenty:leaves_0:11)
Block(-3,26,-1,biomesoplenty:log_1:5)
Block(-2,26,-1,biomesoplenty:log_1:5)
Block(-11,26,1,biomesoplenty:leaves_0:11)
Block(-8,26,1,biomesoplenty:leaves_0:11)
Block(-13,26,3,biomesoplenty:leaves_0:11)
Block(-12,26,4,biomesoplenty:leaves_0:11)
Block(-11,26,4,biomesoplenty:log_1:5)
Block(-10,26,4,biomesoplenty:log_1:5)
Block(-9,26,4,biomesoplenty:log_1:5)
Block(-6,26,4,biomesoplenty:leaves_0:11)
Block(8,26,4,biomesoplenty:leaves_0:11)
Block(9,26,4,biomesoplenty:leaves_0:11)
Block(-15,26,5,biomesoplenty:leaves_0:11)
Block(-11,26,5,biomesoplenty:log_1:5)
Block(-10,26,5,biomesoplenty:log_1:5)
Block(-9,26,5,biomesoplenty:log_1:5)
Block(-8,26,5,biomesoplenty:log_1:5)
Block(7,26,5,biomesoplenty:leaves_0:11)
Block(8,26,5,biomesoplenty:leaves_0:11)
Block(9,26,5,biomesoplenty:leaves_0:11)
Block(10,26,5,biomesoplenty:leaves_0:11)
Block(11,26,5,biomesoplenty:leaves_0:11)
Block(-11,26,6,biomesoplenty:log_1:5)
Block(-10,26,6,biomesoplenty:log_1:5)
Block(-9,26,6,biomesoplenty:log_1:5)
Block(-8,26,6,biomesoplenty:log_1:5)
Block(7,26,6,biomesoplenty:leaves_0:11)
Block(8,26,6,biomesoplenty:leaves_0:11)
Block(10,26,6,biomesoplenty:leaves_0:11)
Block(11,26,6,biomesoplenty:leaves_0:11)
Block(12,26,6,biomesoplenty:leaves_0:11)
Block(-13,26,7,biomesoplenty:leaves_0:11)
Block(-9,26,7,biomesoplenty:log_1:5)
Block(-8,26,7,biomesoplenty:leaves_0:11)
Block(-6,26,7,biomesoplenty:leaves_0:11)
Block(6,26,7,biomesoplenty:leaves_0:11)
Block(8,26,7,biomesoplenty:leaves_0:11)
Block(9,26,7,biomesoplenty:leaves_0:11)
Block(10,26,7,biomesoplenty:leaves_0:11)
Block(12,26,7,biomesoplenty:leaves_0:11)
Block(5,26,8,biomesoplenty:leaves_0:11)
Block(6,26,8,biomesoplenty:leaves_0:11)
Block(7,26,8,biomesoplenty:leaves_0:11)
Block(8,26,8,biomesoplenty:leaves_0:11)
Block(9,26,8,biomesoplenty:leaves_0:11)
Block(10,26,8,biomesoplenty:leaves_0:11)
Block(11,26,8,biomesoplenty:leaves_0:11)
Block(12,26,8,biomesoplenty:leaves_0:11)
Block(13,26,8,biomesoplenty:leaves_0:11)
Block(5,26,9,biomesoplenty:leaves_0:11)
Block(6,26,9,biomesoplenty:leaves_0:11)
Block(7,26,9,biomesoplenty:leaves_0:11)
Block(9,26,9,biomesoplenty:leaves_0:11)
Block(10,26,9,biomesoplenty:leaves_0:11)
Block(12,26,9,biomesoplenty:leaves_0:11)
Block(13,26,9,biomesoplenty:leaves_0:11)
Block(-11,26,10,biomesoplenty:leaves_0:11)
Block(-7,26,10,biomesoplenty:leaves_0:11)
Block(6,26,10,biomesoplenty:leaves_0:11)
Block(7,26,10,biomesoplenty:leaves_0:11)
Block(8,26,10,biomesoplenty:leaves_0:11)
Block(9,26,10,biomesoplenty:leaves_0:11)
Block(10,26,10,biomesoplenty:leaves_0:11)
Block(11,26,10,biomesoplenty:leaves_0:11)
Block(12,26,10,biomesoplenty:leaves_0:11)
Block(-10,26,11,biomesoplenty:leaves_0:11)
Block(-9,26,11,biomesoplenty:leaves_0:11)
Block(6,26,11,biomesoplenty:leaves_0:11)
Block(8,26,11,biomesoplenty:leaves_0:11)
Block(9,26,11,biomesoplenty:leaves_0:11)
Block(10,26,11,biomesoplenty:leaves_0:11)
Block(11,26,11,biomesoplenty:leaves_0:11)
Block(13,26,11,biomesoplenty:leaves_0:11)
Block(7,26,12,biomesoplenty:leaves_0:11)
Block(8,26,12,biomesoplenty:leaves_0:11)
Block(11,26,12,biomesoplenty:leaves_0:11)
Block(12,26,12,biomesoplenty:leaves_0:11)
Block(9,26,13,biomesoplenty:leaves_0:11)
Block(10,26,13,biomesoplenty:leaves_0:11)
Block(-4,27,-6,biomesoplenty:log_1:5)
Block(-3,27,-6,biomesoplenty:log_1:5)
Block(-2,27,-6,biomesoplenty:log_1:5)
Block(-5,27,-5,biomesoplenty:log_1:5)
Block(-4,27,-5,biomesoplenty:log_1:5)
Block(-3,27,-5,biomesoplenty:log_1:5)
Block(-2,27,-5,biomesoplenty:log_1:5)
Block(-1,27,-5,biomesoplenty:log_1:5)
Block(0,27,-5,biomesoplenty:log_1:5)
Block(1,27,-5,biomesoplenty:leaves_0:11)
Block(-6,27,-4,biomesoplenty:leaves_0:11)
Block(-5,27,-4,biomesoplenty:log_1:5)
Block(-4,27,-4,biomesoplenty:log_1:5)
Block(-3,27,-4,biomesoplenty:log_1:5)
Block(-2,27,-4,biomesoplenty:log_1:5)
Block(-1,27,-4,biomesoplenty:log_1:5)
Block(0,27,-4,biomesoplenty:log_1:5)
Block(1,27,-4,biomesoplenty:log_1:5)
Block(2,27,-4,biomesoplenty:log_1:5)
Block(3,27,-4,biomesoplenty:log_1:5)
Block(-5,27,-3,biomesoplenty:log_1:5)
Block(-4,27,-3,biomesoplenty:log_1:5)
Block(-3,27,-3,biomesoplenty:log_1:5)
Block(-2,27,-3,biomesoplenty:log_1:5)
Block(-1,27,-3,biomesoplenty:log_1:5)
Block(0,27,-3,biomesoplenty:log_1:5)
Block(1,27,-3,biomesoplenty:log_1:5)
Block(2,27,-3,biomesoplenty:log_1:5)
Block(3,27,-3,biomesoplenty:log_1:5)
Block(4,27,-3,biomesoplenty:log_1:5)
Block(-4,27,-2,biomesoplenty:log_1:5)
Block(-3,27,-2,biomesoplenty:log_1:5)
Block(-2,27,-2,biomesoplenty:log_1:5)
Block(-1,27,-2,biomesoplenty:log_1:5)
Block(0,27,-2,biomesoplenty:log_1:5)
Block(1,27,-2,biomesoplenty:log_1:5)
Block(2,27,-2,biomesoplenty:log_1:5)
Block(3,27,-2,biomesoplenty:log_1:5)
Block(4,27,-2,biomesoplenty:log_1:5)
Block(5,27,-2,biomesoplenty:log_1:5)
Block(-4,27,-1,biomesoplenty:leaves_0:11)
Block(-3,27,-1,biomesoplenty:log_1:5)
Block(1,27,-1,biomesoplenty:leaves_0:11)
Block(4,27,-1,biomesoplenty:log_1:5)
Block(-11,27,1,biomesoplenty:leaves_0:11)
Block(-9,27,1,biomesoplenty:leaves_0:11)
Block(-8,27,1,biomesoplenty:leaves_0:11)
Block(-12,27,2,biomesoplenty:leaves_0:11)
Block(-10,27,2,biomesoplenty:leaves_0:11)
Block(-14,27,3,biomesoplenty:leaves_0:11)
Block(-13,27,3,biomesoplenty:leaves_0:11)
Block(-10,27,3,biomesoplenty:leaves_0:11)
Block(-9,27,3,biomesoplenty:leaves_0:11)
Block(-8,27,3,biomesoplenty:leaves_0:11)
Block(-7,27,3,biomesoplenty:leaves_0:11)
Block(-14,27,4,biomesoplenty:leaves_0:11)
Block(-12,27,4,biomesoplenty:leaves_0:11)
Block(-11,27,4,biomesoplenty:leaves_0:11)
Block(-10,27,4,biomesoplenty:log_1:5)
Block(-8,27,4,biomesoplenty:leaves_0:11)
Block(-6,27,4,biomesoplenty:leaves_0:11)
Block(-15,27,5,biomesoplenty:leaves_0:11)
Block(-14,27,5,biomesoplenty:leaves_0:11)
Block(-11,27,5,biomesoplenty:log_1:5)
Block(-10,27,5,biomesoplenty:log_1:5)
Block(-9,27,5,biomesoplenty:log_1:5)
Block(-8,27,5,biomesoplenty:leaves_0:11)
Block(-6,27,5,biomesoplenty:leaves_0:11)
Block(-5,27,5,biomesoplenty:leaves_0:11)
Block(8,27,5,biomesoplenty:leaves_0:11)
Block(-14,27,6,biomesoplenty:leaves_0:11)
Block(-11,27,6,biomesoplenty:log_1:5)
Block(-10,27,6,biomesoplenty:log_1:5)
Block(-9,27,6,biomesoplenty:log_1:5)
Block(-8,27,6,biomesoplenty:log_1:5)
Block(-6,27,6,biomesoplenty:leaves_0:11)
Block(-5,27,6,biomesoplenty:leaves_0:11)
Block(1,27,6,biomesoplenty:leaves_0:11)
Block(9,27,6,biomesoplenty:leaves_0:11)
Block(10,27,6,biomesoplenty:leaves_0:11)
Block(-13,27,7,biomesoplenty:leaves_0:11)
Block(-10,27,7,biomesoplenty:log_1:5)
Block(-9,27,7,biomesoplenty:log_1:5)
Block(-6,27,7,biomesoplenty:leaves_0:11)
Block(8,27,7,biomesoplenty:leaves_0:11)
Block(9,27,7,biomesoplenty:leaves_0:11)
Block(-12,27,8,biomesoplenty:leaves_0:11)
Block(-9,27,8,biomesoplenty:leaves_0:11)
Block(-7,27,8,biomesoplenty:leaves_0:11)
Block(7,27,8,biomesoplenty:leaves_0:11)
Block(9,27,8,biomesoplenty:leaves_0:11)
Block(12,27,8,biomesoplenty:leaves_0:11)
Block(-13,27,9,biomesoplenty:leaves_0:11)
Block(-12,27,9,biomesoplenty:leaves_0:11)
Block(-11,27,9,biomesoplenty:leaves_0:11)
Block(-9,27,9,biomesoplenty:leaves_0:11)
Block(-8,27,9,biomesoplenty:leaves_0:11)
Block(-7,27,9,biomesoplenty:leaves_0:11)
Block(7,27,9,biomesoplenty:leaves_0:11)
Block(10,27,9,biomesoplenty:leaves_0:11)
Block(12,27,9,biomesoplenty:leaves_0:11)
Block(-12,27,10,biomesoplenty:leaves_0:11)
Block(-11,27,10,biomesoplenty:leaves_0:11)
Block(-10,27,10,biomesoplenty:leaves_0:11)
Block(-7,27,10,biomesoplenty:leaves_0:11)
Block(8,27,10,biomesoplenty:leaves_0:11)
Block(9,27,10,biomesoplenty:leaves_0:11)
Block(10,27,10,biomesoplenty:leaves_0:11)
Block(11,27,10,biomesoplenty:leaves_0:11)
Block(-11,27,11,biomesoplenty:leaves_0:11)
Block(-10,27,11,biomesoplenty:leaves_0:11)
Block(-9,27,11,biomesoplenty:leaves_0:11)
Block(9,27,11,biomesoplenty:leaves_0:11)
Block(10,27,11,biomesoplenty:leaves_0:11)
Block(8,28,-11,biomesoplenty:leaves_0:11)
Block(-4,28,-6,biomesoplenty:log_1:5)
Block(-3,28,-6,biomesoplenty:log_1:5)
Block(-2,28,-6,biomesoplenty:log_1:5)
Block(-5,28,-5,biomesoplenty:leaves_0:11)
Block(-4,28,-5,biomesoplenty:log_1:5)
Block(-3,28,-5,biomesoplenty:log_1:5)
Block(-2,28,-5,biomesoplenty:log_1:5)
Block(-1,28,-5,biomesoplenty:log_1:5)
Block(0,28,-5,biomesoplenty:log_1:5)
Block(1,28,-5,biomesoplenty:log_1:5)
Block(2,28,-5,biomesoplenty:leaves_0:11)
Block(-5,28,-4,biomesoplenty:log_1:5)
Block(-4,28,-4,biomesoplenty:log_1:5)
Block(-3,28,-4,biomesoplenty:log_1:5)
Block(-2,28,-4,biomesoplenty:log_1:5)
Block(-1,28,-4,biomesoplenty:log_1:5)
Block(0,28,-4,biomesoplenty:log_1:5)
Block(1,28,-4,biomesoplenty:log_1:5)
Block(2,28,-4,biomesoplenty:log_1:5)
Block(3,28,-4,biomesoplenty:log_1:5)
Block(4,28,-4,biomesoplenty:log_1:5)
Block(-5,28,-3,biomesoplenty:log_1:5)
Block(-4,28,-3,biomesoplenty:log_1:5)
Block(-3,28,-3,biomesoplenty:log_1:5)
Block(-2,28,-3,biomesoplenty:log_1:5)
Block(-1,28,-3,biomesoplenty:log_1:5)
Block(0,28,-3,biomesoplenty:log_1:5)
Block(1,28,-3,biomesoplenty:log_1:5)
Block(2,28,-3,biomesoplenty:log_1:5)
Block(3,28,-3,biomesoplenty:log_1:5)
Block(4,28,-3,biomesoplenty:log_1:5)
Block(5,28,-3,biomesoplenty:log_1:5)
Block(6,28,-3,biomesoplenty:leaves_0:11)
Block(-4,28,-2,biomesoplenty:log_1:5)
Block(-3,28,-2,biomesoplenty:log_1:5)
Block(-2,28,-2,biomesoplenty:log_1:5)
Block(-1,28,-2,biomesoplenty:log_1:5)
Block(0,28,-2,biomesoplenty:log_1:5)
Block(1,28,-2,biomesoplenty:log_1:5)
Block(2,28,-2,biomesoplenty:log_1:5)
Block(3,28,-2,biomesoplenty:log_1:5)
Block(4,28,-2,biomesoplenty:log_1:5)
Block(5,28,-2,biomesoplenty:log_1:5)
Block(6,28,-2,biomesoplenty:log_1:5)
Block(7,28,-2,biomesoplenty:leaves_0:11)
Block(14,28,-2,biomesoplenty:leaves_0:11)
Block(-3,28,-1,biomesoplenty:leaves_0:11)
Block(1,28,-1,biomesoplenty:leaves_0:11)
Block(3,28,-1,biomesoplenty:log_1:5)
Block(4,28,-1,biomesoplenty:log_1:5)
Block(5,28,-1,biomesoplenty:log_1:5)
Block(-12,28,1,biomesoplenty:leaves_0:11)
Block(-11,28,1,biomesoplenty:leaves_0:11)
Block(-10,28,1,biomesoplenty:leaves_0:11)
Block(-9,28,1,biomesoplenty:leaves_0:11)
Block(-13,28,2,biomesoplenty:leaves_0:11)
Block(-12,28,2,biomesoplenty:leaves_0:11)
Block(-11,28,2,biomesoplenty:leaves_0:11)
Block(-10,28,2,biomesoplenty:leaves_0:11)
Block(-9,28,2,biomesoplenty:leaves_0:11)
Block(-8,28,2,biomesoplenty:leaves_0:11)
Block(-7,28,2,biomesoplenty:leaves_0:11)
Block(-14,28,3,biomesoplenty:leaves_0:11)
Block(-13,28,3,biomesoplenty:leaves_0:11)
Block(-12,28,3,biomesoplenty:leaves_0:11)
Block(-11,28,3,biomesoplenty:leaves_0:11)
Block(-10,28,3,biomesoplenty:leaves_0:11)
Block(-9,28,3,biomesoplenty:leaves_0:11)
Block(-8,28,3,biomesoplenty:leaves_0:11)
Block(-7,28,3,biomesoplenty:leaves_0:11)
Block(-6,28,3,biomesoplenty:leaves_0:11)
Block(-15,28,4,biomesoplenty:leaves_0:11)
Block(-13,28,4,biomesoplenty:leaves_0:11)
Block(-12,28,4,biomesoplenty:leaves_0:11)
Block(-11,28,4,biomesoplenty:leaves_0:11)
Block(-10,28,4,biomesoplenty:leaves_0:11)
Block(-9,28,4,biomesoplenty:leaves_0:11)
Block(-8,28,4,biomesoplenty:leaves_0:11)
Block(-7,28,4,biomesoplenty:leaves_0:11)
Block(-6,28,4,biomesoplenty:leaves_0:11)
Block(-5,28,4,biomesoplenty:leaves_0:11)
Block(-15,28,5,biomesoplenty:leaves_0:11)
Block(-14,28,5,biomesoplenty:log_1:5)
Block(-13,28,5,biomesoplenty:log_1:5)
Block(-11,28,5,biomesoplenty:leaves_0:11)
Block(-10,28,5,biomesoplenty:leaves_0:11)
Block(-9,28,5,biomesoplenty:leaves_0:11)
Block(-8,28,5,biomesoplenty:leaves_0:11)
Block(-7,28,5,biomesoplenty:leaves_0:11)
Block(-5,28,5,biomesoplenty:leaves_0:11)
Block(-15,28,6,biomesoplenty:leaves_0:11)
Block(-14,28,6,biomesoplenty:leaves_0:11)
Block(-13,28,6,biomesoplenty:log_1:5)
Block(-12,28,6,biomesoplenty:log_1:5)
Block(-11,28,6,biomesoplenty:log_1:5)
Block(-10,28,6,biomesoplenty:log_1:5)
Block(-9,28,6,biomesoplenty:log_1:5)
Block(-8,28,6,biomesoplenty:leaves_0:11)
Block(-6,28,6,biomesoplenty:leaves_0:11)
Block(-5,28,6,biomesoplenty:leaves_0:11)
Block(1,28,6,biomesoplenty:leaves_0:11)
Block(-15,28,7,biomesoplenty:leaves_0:11)
Block(-14,28,7,biomesoplenty:leaves_0:11)
Block(-13,28,7,biomesoplenty:leaves_0:11)
Block(-11,28,7,biomesoplenty:log_1:5)
Block(-10,28,7,biomesoplenty:log_1:5)
Block(-9,28,7,biomesoplenty:leaves_0:11)
Block(-8,28,7,biomesoplenty:leaves_0:11)
Block(-7,28,7,biomesoplenty:leaves_0:11)
Block(-6,28,7,biomesoplenty:leaves_0:11)
Block(-5,28,7,biomesoplenty:leaves_0:11)
Block(-14,28,8,biomesoplenty:leaves_0:11)
Block(-13,28,8,biomesoplenty:leaves_0:11)
Block(-11,28,8,biomesoplenty:leaves_0:11)
Block(-9,28,8,biomesoplenty:log_1:5)
Block(-8,28,8,biomesoplenty:log_1:5)
Block(-7,28,8,biomesoplenty:leaves_0:11)
Block(-6,28,8,biomesoplenty:leaves_0:11)
Block(-5,28,8,biomesoplenty:leaves_0:11)
Block(-14,28,9,biomesoplenty:leaves_0:11)
Block(-13,28,9,biomesoplenty:leaves_0:11)
Block(-12,28,9,biomesoplenty:leaves_0:11)
Block(-11,28,9,biomesoplenty:leaves_0:11)
Block(-10,28,9,biomesoplenty:leaves_0:11)
Block(-9,28,9,biomesoplenty:leaves_0:11)
Block(-8,28,9,biomesoplenty:leaves_0:11)
Block(-7,28,9,biomesoplenty:leaves_0:11)
Block(-6,28,9,biomesoplenty:leaves_0:11)
Block(-13,28,10,biomesoplenty:leaves_0:11)
Block(-12,28,10,biomesoplenty:leaves_0:11)
Block(-11,28,10,biomesoplenty:leaves_0:11)
Block(-10,28,10,biomesoplenty:leaves_0:11)
Block(-9,28,10,biomesoplenty:leaves_0:11)
Block(-8,28,10,biomesoplenty:leaves_0:11)
Block(-7,28,10,biomesoplenty:leaves_0:11)
Block(-12,28,11,biomesoplenty:leaves_0:11)
Block(-11,28,11,biomesoplenty:leaves_0:11)
Block(-10,28,11,biomesoplenty:leaves_0:11)
Block(-9,28,11,biomesoplenty:leaves_0:11)
Block(-8,28,11,biomesoplenty:leaves_0:11)
Block(5,29,-12,biomesoplenty:leaves_0:11)
Block(8,29,-11,biomesoplenty:leaves_0:11)
Block(-3,29,-6,biomesoplenty:log_1:5)
Block(-2,29,-6,biomesoplenty:log_1:5)
Block(-1,29,-6,biomesoplenty:log_1:5)
Block(12,29,-6,biomesoplenty:leaves_0:11)
Block(-5,29,-5,biomesoplenty:leaves_0:11)
Block(-4,29,-5,biomesoplenty:log_1:5)
Block(-3,29,-5,biomesoplenty:log_1:5)
Block(-2,29,-5,biomesoplenty:log_1:5)
Block(-1,29,-5,biomesoplenty:log_1:5)
Block(0,29,-5,biomesoplenty:log_1:5)
Block(1,29,-5,biomesoplenty:log_1:5)
Block(3,29,-5,biomesoplenty:leaves_0:11)
Block(-5,29,-4,biomesoplenty:log_1:5)
Block(-4,29,-4,biomesoplenty:log_1:5)
Block(-3,29,-4,biomesoplenty:log_1:5)
Block(-2,29,-4,biomesoplenty:log_1:5)
Block(-1,29,-4,biomesoplenty:log_1:5)
Block(0,29,-4,biomesoplenty:log_1:5)
Block(1,29,-4,biomesoplenty:log_1:5)
Block(2,29,-4,biomesoplenty:log_1:5)
Block(3,29,-4,biomesoplenty:log_1:5)
Block(4,29,-4,biomesoplenty:leaves_0:11)
Block(6,29,-4,biomesoplenty:leaves_0:11)
Block(-4,29,-3,biomesoplenty:log_1:5)
Block(-3,29,-3,biomesoplenty:log_1:5)
Block(-2,29,-3,biomesoplenty:log_1:5)
Block(-1,29,-3,biomesoplenty:log_1:5)
Block(0,29,-3,biomesoplenty:log_1:5)
Block(1,29,-3,biomesoplenty:log_1:5)
Block(2,29,-3,biomesoplenty:log_1:5)
Block(3,29,-3,biomesoplenty:log_1:5)
Block(4,29,-3,biomesoplenty:log_1:5)
Block(5,29,-3,biomesoplenty:log_1:5)
Block(6,29,-3,biomesoplenty:log_1:5)
Block(-4,29,-2,biomesoplenty:log_1:5)
Block(-3,29,-2,biomesoplenty:log_1:5)
Block(-2,29,-2,biomesoplenty:log_1:5)
Block(-1,29,-2,biomesoplenty:log_1:5)
Block(0,29,-2,biomesoplenty:log_1:5)
Block(1,29,-2,biomesoplenty:leaves_0:11)
Block(3,29,-2,biomesoplenty:log_1:5)
Block(4,29,-2,biomesoplenty:log_1:5)
Block(5,29,-2,biomesoplenty:log_1:5)
Block(6,29,-2,biomesoplenty:log_1:5)
Block(7,29,-2,biomesoplenty:log_1:5)
Block(14,29,-2,biomesoplenty:leaves_0:11)
Block(-3,29,-1,biomesoplenty:leaves_0:11)
Block(4,29,-1,biomesoplenty:log_1:5)
Block(5,29,-1,biomesoplenty:log_1:5)
Block(6,29,-1,biomesoplenty:log_1:5)
Block(7,29,-1,biomesoplenty:leaves_0:11)
Block(-11,29,1,biomesoplenty:leaves_0:11)
Block(-13,29,2,biomesoplenty:leaves_0:11)
Block(-12,29,2,biomesoplenty:leaves_0:11)
Block(-11,29,2,biomesoplenty:leaves_0:11)
Block(-10,29,2,biomesoplenty:leaves_0:11)
Block(-9,29,2,biomesoplenty:leaves_0:11)
Block(-8,29,2,biomesoplenty:leaves_0:11)
Block(-13,29,3,biomesoplenty:leaves_0:11)
Block(-12,29,3,biomesoplenty:leaves_0:11)
Block(-11,29,3,biomesoplenty:leaves_0:11)
Block(-10,29,3,biomesoplenty:leaves_0:11)
Block(-8,29,3,biomesoplenty:leaves_0:11)
Block(-7,29,3,biomesoplenty:leaves_0:11)
Block(-14,29,4,biomesoplenty:leaves_0:11)
Block(-13,29,4,biomesoplenty:leaves_0:11)
Block(-12,29,4,biomesoplenty:leaves_0:11)
Block(-11,29,4,biomesoplenty:leaves_0:11)
Block(-10,29,4,biomesoplenty:leaves_0:11)
Block(-9,29,4,biomesoplenty:leaves_0:11)
Block(-8,29,4,biomesoplenty:leaves_0:11)
Block(-7,29,4,biomesoplenty:leaves_0:11)
Block(-6,29,4,biomesoplenty:leaves_0:11)
Block(-15,29,5,biomesoplenty:leaves_0:11)
Block(-14,29,5,biomesoplenty:leaves_0:11)
Block(-13,29,5,biomesoplenty:leaves_0:11)
Block(-12,29,5,biomesoplenty:leaves_0:11)
Block(-11,29,5,biomesoplenty:leaves_0:11)
Block(-10,29,5,biomesoplenty:log_1:5)
Block(-9,29,5,biomesoplenty:leaves_0:11)
Block(-8,29,5,biomesoplenty:leaves_0:11)
Block(-7,29,5,biomesoplenty:leaves_0:11)
Block(-6,29,5,biomesoplenty:leaves_0:11)
Block(-5,29,5,biomesoplenty:leaves_0:11)
Block(-15,29,6,biomesoplenty:leaves_0:11)
Block(-14,29,6,biomesoplenty:leaves_0:11)
Block(-13,29,6,biomesoplenty:leaves_0:11)
Block(-12,29,6,biomesoplenty:leaves_0:11)
Block(-11,29,6,biomesoplenty:leaves_0:11)
Block(-10,29,6,biomesoplenty:log_1:5)
Block(-9,29,6,biomesoplenty:log_1:5)
Block(-8,29,6,biomesoplenty:leaves_0:11)
Block(-7,29,6,biomesoplenty:leaves_0:11)
Block(-6,29,6,biomesoplenty:leaves_0:11)
Block(1,29,6,biomesoplenty:leaves_0:11)
Block(-15,29,7,biomesoplenty:leaves_0:11)
Block(-14,29,7,biomesoplenty:leaves_0:11)
Block(-13,29,7,biomesoplenty:leaves_0:11)
Block(-12,29,7,biomesoplenty:leaves_0:11)
Block(-11,29,7,biomesoplenty:leaves_0:11)
Block(-10,29,7,biomesoplenty:leaves_0:11)
Block(-9,29,7,biomesoplenty:leaves_0:11)
Block(-8,29,7,biomesoplenty:leaves_0:11)
Block(-6,29,7,biomesoplenty:leaves_0:11)
Block(-13,29,8,biomesoplenty:leaves_0:11)
Block(-12,29,8,biomesoplenty:leaves_0:11)
Block(-11,29,8,biomesoplenty:leaves_0:11)
Block(-10,29,8,biomesoplenty:leaves_0:11)
Block(-9,29,8,biomesoplenty:leaves_0:11)
Block(-8,29,8,biomesoplenty:log_1:5)
Block(-7,29,8,biomesoplenty:leaves_0:11)
Block(-13,29,9,biomesoplenty:leaves_0:11)
Block(-12,29,9,biomesoplenty:leaves_0:11)
Block(-11,29,9,biomesoplenty:leaves_0:11)
Block(-10,29,9,biomesoplenty:leaves_0:11)
Block(-9,29,9,biomesoplenty:leaves_0:11)
Block(-8,29,9,biomesoplenty:leaves_0:11)
Block(-7,29,9,biomesoplenty:leaves_0:11)
Block(-12,29,10,biomesoplenty:leaves_0:11)
Block(-11,29,10,biomesoplenty:leaves_0:11)
Block(-10,29,10,biomesoplenty:leaves_0:11)
Block(-9,29,10,biomesoplenty:leaves_0:11)
Block(-8,29,10,biomesoplenty:leaves_0:11)
Block(-10,29,11,biomesoplenty:leaves_0:11)
Block(5,30,-12,biomesoplenty:leaves_0:11)
Block(8,30,-11,biomesoplenty:leaves_0:11)
Block(-4,30,-6,biomesoplenty:leaves_0:11)
Block(-3,30,-6,biomesoplenty:log_1:5)
Block(-2,30,-6,biomesoplenty:log_1:5)
Block(-1,30,-6,biomesoplenty:log_1:5)
Block(12,30,-6,biomesoplenty:leaves_0:11)
Block(-4,30,-5,biomesoplenty:log_1:5)
Block(-3,30,-5,biomesoplenty:log_1:5)
Block(-2,30,-5,biomesoplenty:log_1:5)
Block(-1,30,-5,biomesoplenty:log_1:5)
Block(0,30,-5,biomesoplenty:log_1:5)
Block(1,30,-5,biomesoplenty:log_1:5)
Block(-10,30,-4,biomesoplenty:leaves_0:11)
Block(-4,30,-4,biomesoplenty:log_1:5)
Block(-3,30,-4,biomesoplenty:log_1:5)
Block(-2,30,-4,biomesoplenty:log_1:5)
Block(-1,30,-4,biomesoplenty:log_1:5)
Block(0,30,-4,biomesoplenty:log_1:5)
Block(1,30,-4,biomesoplenty:log_1:5)
Block(2,30,-4,biomesoplenty:log_1:5)
Block(5,30,-4,biomesoplenty:leaves_0:11)
Block(15,30,-4,biomesoplenty:leaves_0:11)
Block(-4,30,-3,biomesoplenty:log_1:5)
Block(-3,30,-3,biomesoplenty:log_1:5)
Block(-2,30,-3,biomesoplenty:log_1:5)
Block(-1,30,-3,biomesoplenty:log_1:5)
Block(0,30,-3,biomesoplenty:log_1:5)
Block(1,30,-3,biomesoplenty:log_1:5)
Block(5,30,-3,biomesoplenty:log_1:5)
Block(6,30,-3,biomesoplenty:log_1:5)
Block(7,30,-3,biomesoplenty:log_1:5)
Block(-3,30,-2,biomesoplenty:log_1:5)
Block(-2,30,-2,biomesoplenty:log_1:5)
Block(-1,30,-2,biomesoplenty:log_1:5)
Block(0,30,-2,biomesoplenty:leaves_0:11)
Block(4,30,-2,biomesoplenty:log_1:5)
Block(5,30,-2,biomesoplenty:log_1:5)
Block(6,30,-2,biomesoplenty:log_1:5)
Block(7,30,-2,biomesoplenty:log_1:5)
Block(14,30,-2,biomesoplenty:leaves_0:11)
Block(-2,30,-1,biomesoplenty:leaves_0:11)
Block(4,30,-1,biomesoplenty:log_1:5)
Block(5,30,-1,biomesoplenty:log_1:5)
Block(6,30,-1,biomesoplenty:log_1:5)
Block(7,30,-1,biomesoplenty:log_1:5)
Block(6,30,0,biomesoplenty:leaves_0:11)
Block(15,30,0,biomesoplenty:leaves_0:11)
Block(-10,30,2,biomesoplenty:leaves_0:11)
Block(-13,30,3,biomesoplenty:leaves_0:11)
Block(-12,30,3,biomesoplenty:leaves_0:11)
Block(-11,30,3,biomesoplenty:leaves_0:11)
Block(-10,30,3,biomesoplenty:leaves_0:11)
Block(-8,30,3,biomesoplenty:leaves_0:11)
Block(-14,30,4,biomesoplenty:leaves_0:11)
Block(-13,30,4,biomesoplenty:leaves_0:11)
Block(-12,30,4,biomesoplenty:leaves_0:11)
Block(-11,30,4,biomesoplenty:leaves_0:11)
Block(-10,30,4,biomesoplenty:leaves_0:11)
Block(-9,30,4,biomesoplenty:leaves_0:11)
Block(-8,30,4,biomesoplenty:leaves_0:11)
Block(-7,30,4,biomesoplenty:leaves_0:11)
Block(-14,30,5,biomesoplenty:leaves_0:11)
Block(-12,30,5,biomesoplenty:leaves_0:11)
Block(-11,30,5,biomesoplenty:leaves_0:11)
Block(-10,30,5,biomesoplenty:leaves_0:11)
Block(-9,30,5,biomesoplenty:leaves_0:11)
Block(-8,30,5,biomesoplenty:leaves_0:11)
Block(9,30,5,biomesoplenty:leaves_0:11)
Block(-14,30,6,biomesoplenty:leaves_0:11)
Block(-13,30,6,biomesoplenty:leaves_0:11)
Block(-12,30,6,biomesoplenty:leaves_0:11)
Block(-11,30,6,biomesoplenty:leaves_0:11)
Block(-10,30,6,biomesoplenty:leaves_0:11)
Block(-9,30,6,biomesoplenty:leaves_0:11)
Block(-8,30,6,biomesoplenty:leaves_0:11)
Block(-7,30,6,biomesoplenty:leaves_0:11)
Block(-6,30,6,biomesoplenty:leaves_0:11)
Block(1,30,6,biomesoplenty:leaves_0:11)
Block(-14,30,7,biomesoplenty:leaves_0:11)
Block(-13,30,7,biomesoplenty:leaves_0:11)
Block(-12,30,7,biomesoplenty:leaves_0:11)
Block(-11,30,7,biomesoplenty:leaves_0:11)
Block(-10,30,7,biomesoplenty:leaves_0:11)
Block(-9,30,7,biomesoplenty:leaves_0:11)
Block(-8,30,7,biomesoplenty:leaves_0:11)
Block(-7,30,7,biomesoplenty:leaves_0:11)
Block(3,30,7,biomesoplenty:leaves_0:11)
Block(-13,30,8,biomesoplenty:leaves_0:11)
Block(-12,30,8,biomesoplenty:leaves_0:11)
Block(-11,30,8,biomesoplenty:leaves_0:11)
Block(-10,30,8,biomesoplenty:leaves_0:11)
Block(-9,30,8,biomesoplenty:leaves_0:11)
Block(-8,30,8,biomesoplenty:leaves_0:11)
Block(-12,30,9,biomesoplenty:leaves_0:11)
Block(-11,30,9,biomesoplenty:leaves_0:11)
Block(-10,30,9,biomesoplenty:leaves_0:11)
Block(-11,30,10,biomesoplenty:leaves_0:11)
Block(-9,30,10,biomesoplenty:leaves_0:11)
Block(3,31,-14,biomesoplenty:leaves_0:11)
Block(1,31,-12,biomesoplenty:leaves_0:11)
Block(5,31,-12,biomesoplenty:leaves_0:11)
Block(8,31,-11,biomesoplenty:leaves_0:11)
Block(10,31,-8,biomesoplenty:leaves_0:11)
Block(-4,31,-6,biomesoplenty:leaves_0:11)
Block(-3,31,-6,biomesoplenty:log_1:5)
Block(-2,31,-6,biomesoplenty:log_1:5)
Block(-1,31,-6,biomesoplenty:log_1:5)
Block(12,31,-6,biomesoplenty:leaves_0:11)
Block(-3,31,-5,biomesoplenty:log_1:5)
Block(-2,31,-5,biomesoplenty:log_1:5)
Block(-1,31,-5,biomesoplenty:log_1:5)
Block(0,31,-5,biomesoplenty:log_1:5)
Block(1,31,-5,biomesoplenty:log_1:5)
Block(-10,31,-4,biomesoplenty:leaves_0:11)
Block(-4,31,-4,biomesoplenty:log_1:5)
Block(-3,31,-4,biomesoplenty:log_1:5)
Block(-2,31,-4,biomesoplenty:log_1:5)
Block(-1,31,-4,biomesoplenty:log_1:5)
Block(0,31,-4,biomesoplenty:log_1:5)
Block(1,31,-4,biomesoplenty:log_1:5)
Block(6,31,-4,biomesoplenty:leaves_0:11)
Block(15,31,-4,biomesoplenty:leaves_0:11)
Block(-4,31,-3,biomesoplenty:log_1:5)
Block(-3,31,-3,biomesoplenty:log_1:5)
Block(-2,31,-3,biomesoplenty:log_1:5)
Block(-1,31,-3,biomesoplenty:log_1:5)
Block(0,31,-3,biomesoplenty:log_1:5)
Block(1,31,-3,biomesoplenty:log_1:5)
Block(5,31,-3,biomesoplenty:log_1:5)
Block(6,31,-3,biomesoplenty:log_1:5)
Block(7,31,-3,biomesoplenty:log_1:5)
Block(-3,31,-2,biomesoplenty:log_1:5)
Block(-2,31,-2,biomesoplenty:log_1:5)
Block(-1,31,-2,biomesoplenty:log_1:5)
Block(0,31,-2,biomesoplenty:leaves_0:11)
Block(4,31,-2,biomesoplenty:log_1:5)
Block(5,31,-2,biomesoplenty:log_1:5)
Block(6,31,-2,biomesoplenty:log_1:5)
Block(7,31,-2,biomesoplenty:log_1:5)
Block(8,31,-2,biomesoplenty:log_1:5)
Block(14,31,-2,biomesoplenty:leaves_0:11)
Block(-1,31,-1,biomesoplenty:leaves_0:11)
Block(5,31,-1,biomesoplenty:log_1:5)
Block(6,31,-1,biomesoplenty:log_1:5)
Block(7,31,-1,biomesoplenty:log_1:5)
Block(6,31,0,biomesoplenty:leaves_0:11)
Block(15,31,0,biomesoplenty:leaves_0:11)
Block(13,31,2,biomesoplenty:leaves_0:11)
Block(-12,31,3,biomesoplenty:leaves_0:11)
Block(-10,31,3,biomesoplenty:leaves_0:11)
Block(6,31,3,biomesoplenty:leaves_0:11)
Block(-12,31,4,biomesoplenty:leaves_0:11)
Block(-11,31,4,biomesoplenty:leaves_0:11)
Block(-10,31,4,biomesoplenty:leaves_0:11)
Block(-9,31,4,biomesoplenty:leaves_0:11)
Block(11,31,4,biomesoplenty:leaves_0:11)
Block(-13,31,5,biomesoplenty:leaves_0:11)
Block(-10,31,5,biomesoplenty:leaves_0:11)
Block(-9,31,5,biomesoplenty:leaves_0:11)
Block(9,31,5,biomesoplenty:leaves_0:11)
Block(-13,31,6,biomesoplenty:leaves_0:11)
Block(-11,31,6,biomesoplenty:leaves_0:11)
Block(-9,31,6,biomesoplenty:leaves_0:11)
Block(-8,31,6,biomesoplenty:leaves_0:11)
Block(1,31,6,biomesoplenty:leaves_0:11)
Block(7,31,6,biomesoplenty:leaves_0:11)
Block(-13,31,7,biomesoplenty:leaves_0:11)
Block(-12,31,7,biomesoplenty:leaves_0:11)
Block(-11,31,7,biomesoplenty:leaves_0:11)
Block(-10,31,7,biomesoplenty:leaves_0:11)
Block(-9,31,7,biomesoplenty:leaves_0:11)
Block(3,31,7,biomesoplenty:leaves_0:11)
Block(-12,31,8,biomesoplenty:leaves_0:11)
Block(-10,31,8,biomesoplenty:leaves_0:11)
Block(5,31,8,biomesoplenty:leaves_0:11)
Block(3,32,-14,biomesoplenty:leaves_0:11)
Block(-3,32,-13,biomesoplenty:leaves_0:11)
Block(1,32,-12,biomesoplenty:leaves_0:11)
Block(5,32,-12,biomesoplenty:leaves_0:11)
Block(-5,32,-11,biomesoplenty:leaves_0:11)
Block(8,32,-11,biomesoplenty:leaves_0:11)
Block(-8,32,-9,biomesoplenty:leaves_0:11)
Block(10,32,-8,biomesoplenty:leaves_0:11)
Block(-3,32,-6,biomesoplenty:leaves_0:11)
Block(-2,32,-6,biomesoplenty:log_1:5)
Block(-1,32,-6,biomesoplenty:log_1:5)
Block(0,32,-6,biomesoplenty:log_1:5)
Block(6,32,-6,biomesoplenty:leaves_0:11)
Block(12,32,-6,biomesoplenty:leaves_0:11)
Block(-3,32,-5,biomesoplenty:log_1:5)
Block(-2,32,-5,biomesoplenty:log_1:5)
Block(-1,32,-5,biomesoplenty:log_1:5)
Block(0,32,-5,biomesoplenty:log_1:5)
