#######################################################################
# +-----------------------------------------------------------------+ #
# |                            BO3 object                           | #
# +-----------------------------------------------------------------+ #
#######################################################################

# This is the config file of a custom object.
# If you add this object correctly to your BiomeConfigs, it will spawn in the world.

# This is the creator of this BO3 object
Author: BO3 BulkEdit (by LanToaster)

# A short description of this BO3 object
Description: This Object was Created with BO3_BulkEdit

# The BO3 version, don't change this! It can be used by external applications to do a version check.
Version: 3

# The settings mode, WriteAll, WriteWithoutComments or WriteDisable. See WorldConfig.
SettingsMode: WriteDisable


#######################################################################
# +-----------------------------------------------------------------+ #
# |                          Main settings                          | #
# +-----------------------------------------------------------------+ #
#######################################################################

# This needs to be set to true to spawn the object in the Tree and Sapling resources.
Tree: true

# The frequency of the BO3 from 1 to 200. Tries this many times to spawn this BO3 when using the CustomObject(...) resource.
# Ignored by Tree(..), Sapling(..) and CustomStructure(..)
Frequency: 1

# The rarity of the BO3 from 0 to 100. Each spawn attempt has rarity% chance to succeed when using the CustomObject(...) resource.
# Ignored by Tree(..), Sapling(..) and CustomStructure(..)
Rarity: 100.0

# If you set this to true, the BO3 will be placed with a random rotation.
RotateRandomly: true

# The spawn height of the BO3 - randomY, highestBlock or highestSolid)Block.
SpawnHeight: randomY

# The height limits for the BO3.
MinHeight: 92

MaxHeight: 256

# Objects can have other objects attacthed to it: branches. Branches can also
# have branches attached to it, which can also have branches, etc. This is the
# maximum branch depth for this objects.
MaxBranchDepth: 10

# When spawned with the UseWorld keyword, this BO3 should NOT spawn in the following biomes.
# If you writer.write the BO3 name directly in the BiomeConfigs, this will be ignored.
ExcludedBiomes: All


#######################################################################
# +-----------------------------------------------------------------+ #
# |                      Source block settings                      | #
# +-----------------------------------------------------------------+ #
#######################################################################

# The block(s) the BO3 should spawn in.
SourceBlocks: AIR,minecraft:grass,minecraft:dirt

# The maximum percentage of the BO3 that can be outside the SourceBlock.
# The BO3 won't be placed on a location with more blocks outside the SourceBlock than this percentage.
MaxPercentageOutsideSourceBlock: 100

# What to do when a block is about to be placed outside the SourceBlock? (dontPlace, placeAnyway)
OutsideSourceBlock: placeAnyway


#######################################################################
# +-----------------------------------------------------------------+ #
# |                              Blocks                             | #
# +-----------------------------------------------------------------+ #
#######################################################################

# All the blocks used in the BO3 are listed here. Possible blocks:
# Block(x,y,z,id[.data][,nbtfile.nbt)
# RandomBlock(x,y,z,id[:data][,nbtfile.nbt],chance[,id[:data][,nbtfile.nbt],chance[,...]])
# So RandomBlock(0,0,0,CHEST,chest.nbt,50,CHEST,anotherchest.nbt,100) will spawn a chest at
# the BO3 origin, and give it a 50% chance to have the contents of chest.nbt, or, if that
# fails, a 100% percent chance to have the contents of anotherchest.nbt.
Block(1,0,-7,minecraft:log2:1)
Block(2,0,-7,minecraft:log2:1)
Block(-1,0,-6,minecraft:leaves2:1)
Block(0,0,-6,minecraft:log2:1)
Block(1,0,-6,minecraft:log2:1)
Block(2,0,-6,minecraft:log2:1)
Block(3,0,-6,minecraft:log2:1)
Block(4,0,-6,minecraft:log2:1)
Block(5,0,-6,minecraft:log2:1)
Block(-1,0,-5,minecraft:log2:1)
Block(0,0,-5,minecraft:log2:1)
Block(1,0,-5,minecraft:log2:1)
Block(2,0,-5,minecraft:log2:1)
Block(3,0,-5,minecraft:log2:1)
Block(4,0,-5,minecraft:log2:1)
Block(5,0,-5,minecraft:log2:1)
Block(6,0,-5,minecraft:log2:1)
Block(-1,0,-4,minecraft:log2:1)
Block(0,0,-4,minecraft:log2:1)
Block(1,0,-4,minecraft:log2:1)
Block(2,0,-4,minecraft:log2:1)
Block(3,0,-4,minecraft:log2:1)
Block(4,0,-4,minecraft:log2:1)
Block(5,0,-4,minecraft:log2:1)
Block(6,0,-4,minecraft:log2:1)
Block(7,0,-4,minecraft:log2:1)
Block(-2,0,-3,minecraft:log2:1)
Block(-1,0,-3,minecraft:log2:1)
Block(0,0,-3,minecraft:log2:1)
Block(1,0,-3,minecraft:log2:1)
Block(2,0,-3,minecraft:log2:1)
Block(3,0,-3,minecraft:log2:1)
Block(4,0,-3,minecraft:log2:1)
Block(5,0,-3,minecraft:log2:1)
Block(6,0,-3,minecraft:log2:1)
Block(7,0,-3,minecraft:log2:1)
Block(-2,0,-2,minecraft:log2:1)
Block(-1,0,-2,minecraft:log2:1)
Block(0,0,-2,minecraft:log2:1)
Block(1,0,-2,minecraft:log2:1)
Block(2,0,-2,minecraft:log2:1)
Block(3,0,-2,minecraft:log2:1)
Block(4,0,-2,minecraft:log2:1)
Block(5,0,-2,minecraft:log2:1)
Block(6,0,-2,minecraft:log2:1)
Block(-1,0,-1,minecraft:log2:1)
Block(0,0,-1,minecraft:log2:1)
Block(1,0,-1,minecraft:log2:1)
Block(2,0,-1,minecraft:log2:1)
Block(3,0,-1,minecraft:log2:1)
Block(4,0,-1,minecraft:log2:1)
Block(5,0,-1,minecraft:log2:1)
Block(6,0,-1,minecraft:log2:1)
Block(1,0,0,minecraft:log2:1)
Block(2,0,0,minecraft:log2:1)
Block(3,0,0,minecraft:log2:1)
Block(4,0,0,minecraft:log2:1)
Block(5,0,0,minecraft:log2:1)
Block(6,0,0,minecraft:leaves2:1)
Block(1,0,1,minecraft:leaves2:1)
Block(2,0,1,minecraft:log2:1)
Block(3,0,1,minecraft:log2:1)
Block(1,1,-6,minecraft:log2:1)
Block(2,1,-6,minecraft:log2:1)
Block(3,1,-6,minecraft:log2:1)
Block(-1,1,-5,minecraft:leaves2:1)
Block(0,1,-5,minecraft:log2:1)
Block(1,1,-5,minecraft:log2:1)
Block(2,1,-5,minecraft:log2:1)
Block(3,1,-5,minecraft:log2:1)
Block(4,1,-5,minecraft:log2:1)
Block(-1,1,-4,minecraft:log2:1)
Block(0,1,-4,minecraft:log2:1)
Block(1,1,-4,minecraft:log2:1)
Block(2,1,-4,minecraft:log2:1)
Block(3,1,-4,minecraft:log2:1)
Block(4,1,-4,minecraft:log2:1)
Block(5,1,-4,minecraft:log2:1)
Block(-1,1,-3,minecraft:log2:1)
Block(0,1,-3,minecraft:log2:1)
Block(1,1,-3,minecraft:log2:1)
Block(2,1,-3,minecraft:log2:1)
Block(3,1,-3,minecraft:log2:1)
Block(4,1,-3,minecraft:log2:1)
Block(5,1,-3,minecraft:log2:1)
Block(-1,1,-2,minecraft:log2:1)
Block(0,1,-2,minecraft:log2:1)
Block(1,1,-2,minecraft:log2:1)
Block(2,1,-2,minecraft:log2:1)
Block(3,1,-2,minecraft:log2:1)
Block(4,1,-2,minecraft:log2:1)
Block(5,1,-2,minecraft:log2:1)
Block(0,1,-1,minecraft:leaves2:1)
Block(1,1,-1,minecraft:log2:1)
Block(2,1,-1,minecraft:log2:1)
Block(3,1,-1,minecraft:log2:1)
Block(4,1,-1,minecraft:log2:1)
Block(5,1,-1,minecraft:leaves2:1)
Block(1,1,0,minecraft:leaves2:1)
Block(2,1,0,minecraft:log2:1)
Block(3,1,0,minecraft:log2:1)
Block(0,2,-6,minecraft:leaves2:1)
Block(1,2,-6,minecraft:log2:1)
Block(2,2,-6,minecraft:log2:1)
Block(3,2,-6,minecraft:log2:1)
Block(-1,2,-5,minecraft:log2:1)
Block(0,2,-5,minecraft:log2:1)
Block(1,2,-5,minecraft:log2:1)
Block(2,2,-5,minecraft:log2:1)
Block(3,2,-5,minecraft:log2:1)
Block(4,2,-5,minecraft:log2:1)
Block(-1,2,-4,minecraft:log2:1)
Block(0,2,-4,minecraft:log2:1)
Block(1,2,-4,minecraft:log2:1)
Block(2,2,-4,minecraft:log2:1)
Block(3,2,-4,minecraft:log2:1)
Block(4,2,-4,minecraft:log2:1)
Block(5,2,-4,minecraft:log2:1)
Block(-1,2,-3,minecraft:log2:1)
Block(0,2,-3,minecraft:log2:1)
Block(1,2,-3,minecraft:log2:1)
Block(2,2,-3,minecraft:log2:1)
Block(3,2,-3,minecraft:log2:1)
Block(4,2,-3,minecraft:log2:1)
Block(5,2,-3,minecraft:log2:1)
Block(-1,2,-2,minecraft:log2:1)
Block(0,2,-2,minecraft:log2:1)
Block(1,2,-2,minecraft:log2:1)
Block(2,2,-2,minecraft:log2:1)
Block(3,2,-2,minecraft:log2:1)
Block(4,2,-2,minecraft:log2:1)
Block(0,2,-1,minecraft:leaves2:1)
Block(1,2,-1,minecraft:log2:1)
Block(2,2,-1,minecraft:log2:1)
Block(3,2,-1,minecraft:log2:1)
Block(4,2,-1,minecraft:log2:1)
Block(5,2,-1,minecraft:leaves2:1)
Block(2,2,0,minecraft:log2:1)
Block(0,3,-7,minecraft:leaves2:1)
Block(0,3,-6,minecraft:log2:1)
Block(1,3,-6,minecraft:log2:1)
Block(2,3,-6,minecraft:log2:1)
Block(-1,3,-5,minecraft:log2:1)
Block(0,3,-5,minecraft:log2:1)
Block(1,3,-5,minecraft:log2:1)
Block(2,3,-5,minecraft:log2:1)
Block(3,3,-5,minecraft:log2:1)
Block(-2,3,-4,minecraft:log2:1)
Block(-1,3,-4,minecraft:log2:1)
Block(0,3,-4,minecraft:log2:1)
Block(1,3,-4,minecraft:log2:1)
Block(2,3,-4,minecraft:log2:1)
Block(3,3,-4,minecraft:log2:1)
Block(4,3,-4,minecraft:log2:1)
Block(-1,3,-3,minecraft:log2:1)
Block(0,3,-3,minecraft:log2:1)
Block(1,3,-3,minecraft:log2:1)
Block(2,3,-3,minecraft:log2:1)
Block(3,3,-3,minecraft:log2:1)
Block(4,3,-3,minecraft:log2:1)
Block(0,3,-2,minecraft:log2:1)
Block(1,3,-2,minecraft:log2:1)
Block(2,3,-2,minecraft:log2:1)
Block(3,3,-2,minecraft:log2:1)
Block(4,3,-2,minecraft:log2:1)
Block(0,3,-1,minecraft:leaves2:1)
Block(1,3,-1,minecraft:log2:1)
Block(2,3,-1,minecraft:log2:1)
Block(3,3,-1,minecraft:log2:1)
Block(4,3,-1,minecraft:leaves2:1)
Block(-5,4,-15,minecraft:leaves2:1)
Block(-2,4,-7,minecraft:log2:1)
Block(-1,4,-7,minecraft:log2:1)
Block(0,4,-7,minecraft:leaves2:1)
Block(-2,4,-6,minecraft:log2:1)
Block(-1,4,-6,minecraft:log2:1)
Block(0,4,-6,minecraft:log2:1)
Block(1,4,-6,minecraft:log2:1)
Block(-2,4,-5,minecraft:log2:1)
Block(-1,4,-5,minecraft:log2:1)
Block(0,4,-5,minecraft:log2:1)
Block(1,4,-5,minecraft:log2:1)
Block(2,4,-5,minecraft:log2:1)
Block(3,4,-5,minecraft:log2:1)
Block(-2,4,-4,minecraft:log2:1)
Block(-1,4,-4,minecraft:log2:1)
Block(0,4,-4,minecraft:log2:1)
Block(1,4,-4,minecraft:log2:1)
Block(2,4,-4,minecraft:log2:1)
Block(3,4,-4,minecraft:log2:1)
Block(-1,4,-3,minecraft:log2:1)
Block(0,4,-3,minecraft:log2:1)
Block(1,4,-3,minecraft:log2:1)
Block(2,4,-3,minecraft:log2:1)
Block(3,4,-3,minecraft:log2:1)
Block(4,4,-3,minecraft:log2:1)
Block(-1,4,-2,minecraft:leaves2:1)
Block(0,4,-2,minecraft:log2:1)
Block(1,4,-2,minecraft:log2:1)
Block(2,4,-2,minecraft:log2:1)
Block(3,4,-2,minecraft:log2:1)
Block(4,4,-2,minecraft:log2:1)
Block(1,4,-1,minecraft:log2:1)
Block(2,4,-1,minecraft:log2:1)
Block(3,4,-1,minecraft:log2:1)
Block(4,4,-1,minecraft:leaves2:1)
Block(-5,5,-15,minecraft:leaves2:1)
Block(-2,5,-12,minecraft:leaves2:1)
Block(-10,5,-10,minecraft:leaves2:1)
Block(-6,5,-8,minecraft:leaves2:1)
Block(-3,5,-8,minecraft:log2:1)
Block(-3,5,-7,minecraft:log2:1)
Block(-2,5,-7,minecraft:log2:1)
Block(-1,5,-7,minecraft:log2:1)
Block(0,5,-7,minecraft:log2:1)
Block(1,5,-7,minecraft:leaves2:1)
Block(-3,5,-6,minecraft:log2:1)
Block(-2,5,-6,minecraft:log2:1)
Block(-1,5,-6,minecraft:log2:1)
Block(0,5,-6,minecraft:log2:1)
Block(1,5,-6,minecraft:log2:1)
Block(-2,5,-5,minecraft:log2:1)
Block(-1,5,-5,minecraft:log2:1)
Block(0,5,-5,minecraft:log2:1)
Block(1,5,-5,minecraft:log2:1)
Block(2,5,-5,minecraft:log2:1)
Block(-2,5,-4,minecraft:log2:1)
Block(-1,5,-4,minecraft:log2:1)
Block(0,5,-4,minecraft:log2:1)
Block(1,5,-4,minecraft:log2:1)
Block(2,5,-4,minecraft:log2:1)
Block(3,5,-4,minecraft:log2:1)
Block(-1,5,-3,minecraft:log2:1)
Block(0,5,-3,minecraft:log2:1)
Block(1,5,-3,minecraft:log2:1)
Block(2,5,-3,minecraft:log2:1)
Block(3,5,-3,minecraft:log2:1)
Block(-1,5,-2,minecraft:leaves2:1)
Block(0,5,-2,minecraft:log2:1)
Block(1,5,-2,minecraft:log2:1)
Block(2,5,-2,minecraft:log2:1)
Block(3,5,-2,minecraft:log2:1)
Block(4,5,-2,minecraft:log2:1)
Block(0,5,-1,minecraft:log2:1)
Block(1,5,-1,minecraft:log2:1)
Block(2,5,-1,minecraft:log2:1)
Block(3,5,-1,minecraft:log2:1)
Block(4,5,-1,minecraft:log2:1)
Block(2,5,0,minecraft:log2:1)
Block(3,5,0,minecraft:leaves2:1)
Block(-8,6,-15,minecraft:leaves2:1)
Block(-5,6,-15,minecraft:leaves2:1)
Block(-2,6,-12,minecraft:leaves2:1)
Block(-5,6,-11,minecraft:log2:1)
Block(-10,6,-10,minecraft:leaves2:1)
Block(-6,6,-10,minecraft:log2:1)
Block(-5,6,-10,minecraft:log2:1)
Block(-4,6,-10,minecraft:log2:1)
Block(-5,6,-9,minecraft:log2:1)
Block(-4,6,-9,minecraft:log2:1)
Block(-3,6,-9,minecraft:log2:1)
Block(-6,6,-8,minecraft:leaves2:1)
Block(-4,6,-8,minecraft:log2:1)
Block(-3,6,-8,minecraft:log2:1)
Block(-2,6,-8,minecraft:log2:1)
Block(-8,6,-7,minecraft:leaves2:1)
Block(-4,6,-7,minecraft:log2:1)
Block(-3,6,-7,minecraft:log2:1)
Block(-2,6,-7,minecraft:log2:1)
Block(-1,6,-7,minecraft:log2:1)
Block(-4,6,-6,minecraft:log2:1)
Block(-3,6,-6,minecraft:log2:1)
Block(-2,6,-6,minecraft:log2:1)
Block(-1,6,-6,minecraft:log2:1)
Block(0,6,-6,minecraft:log2:1)
Block(1,6,-6,minecraft:leaves2:1)
Block(-3,6,-5,minecraft:log2:1)
Block(-2,6,-5,minecraft:log2:1)
Block(-1,6,-5,minecraft:log2:1)
Block(0,6,-5,minecraft:log2:1)
Block(1,6,-5,minecraft:log2:1)
Block(2,6,-5,minecraft:log2:1)
Block(-2,6,-4,minecraft:log2:1)
Block(-1,6,-4,minecraft:log2:1)
Block(0,6,-4,minecraft:log2:1)
Block(1,6,-4,minecraft:log2:1)
Block(2,6,-4,minecraft:log2:1)
Block(-2,6,-3,minecraft:log2:1)
Block(-1,6,-3,minecraft:log2:1)
Block(0,6,-3,minecraft:log2:1)
Block(1,6,-3,minecraft:log2:1)
Block(2,6,-3,minecraft:log2:1)
Block(3,6,-3,minecraft:log2:1)
Block(-2,6,-2,minecraft:leaves2:1)
Block(-1,6,-2,minecraft:log2:1)
Block(0,6,-2,minecraft:log2:1)
Block(1,6,-2,minecraft:log2:1)
Block(2,6,-2,minecraft:log2:1)
Block(3,6,-2,minecraft:log2:1)
Block(4,6,-2,minecraft:log2:1)
Block(-1,6,-1,minecraft:leaves2:1)
Block(0,6,-1,minecraft:log2:1)
Block(1,6,-1,minecraft:log2:1)
Block(2,6,-1,minecraft:log2:1)
Block(3,6,-1,minecraft:log2:1)
Block(4,6,-1,minecraft:log2:1)
Block(2,6,0,minecraft:log2:1)
Block(3,6,0,minecraft:log2:1)
Block(4,6,0,minecraft:leaves2:1)
Block(-8,7,-15,minecraft:leaves2:1)
Block(-5,7,-15,minecraft:leaves2:1)
Block(-5,7,-14,minecraft:leaves2:1)
Block(-9,7,-12,minecraft:leaves2:1)
Block(-6,7,-12,minecraft:log2:1)
Block(-5,7,-12,minecraft:log2:1)
Block(-2,7,-12,minecraft:leaves2:1)
Block(-7,7,-11,minecraft:log2:1)
Block(-6,7,-11,minecraft:log2:1)
Block(-5,7,-11,minecraft:log2:1)
Block(-4,7,-11,minecraft:log2:1)
Block(-10,7,-10,minecraft:leaves2:1)
Block(-6,7,-10,minecraft:log2:1)
Block(-5,7,-10,minecraft:log2:1)
Block(-4,7,-10,minecraft:log2:1)
Block(-3,7,-10,minecraft:log2:1)
Block(-5,7,-9,minecraft:log2:1)
Block(-4,7,-9,minecraft:log2:1)
Block(-3,7,-9,minecraft:log2:1)
Block(-10,7,-8,minecraft:leaves2:1)
Block(-6,7,-8,minecraft:leaves2:1)
Block(-5,7,-8,minecraft:log2:1)
Block(-4,7,-8,minecraft:log2:1)
Block(-3,7,-8,minecraft:log2:1)
Block(-8,7,-7,minecraft:leaves2:1)
Block(-4,7,-7,minecraft:log2:1)
Block(-3,7,-7,minecraft:log2:1)
Block(-2,7,-7,minecraft:log2:1)
Block(-3,7,-6,minecraft:log2:1)
Block(-2,7,-6,minecraft:log2:1)
Block(-1,7,-6,minecraft:log2:1)
Block(1,7,-6,minecraft:leaves2:1)
Block(-3,7,-5,minecraft:log2:1)
Block(-2,7,-5,minecraft:log2:1)
Block(0,7,-5,minecraft:log2:1)
Block(1,7,-5,minecraft:log2:1)
Block(-3,7,-4,minecraft:log2:1)
Block(-2,7,-4,minecraft:log2:1)
Block(-1,7,-4,minecraft:log2:1)
Block(0,7,-4,minecraft:log2:1)
Block(1,7,-4,minecraft:log2:1)
Block(2,7,-4,minecraft:log2:1)
Block(-2,7,-3,minecraft:log2:1)
Block(-1,7,-3,minecraft:log2:1)
Block(0,7,-3,minecraft:log2:1)
Block(1,7,-3,minecraft:log2:1)
Block(2,7,-3,minecraft:log2:1)
Block(3,7,-3,minecraft:log2:1)
Block(-2,7,-2,minecraft:leaves2:1)
Block(-1,7,-2,minecraft:log2:1)
Block(0,7,-2,minecraft:log2:1)
Block(1,7,-2,minecraft:log2:1)
Block(2,7,-2,minecraft:log2:1)
Block(3,7,-2,minecraft:log2:1)
Block(0,7,-1,minecraft:log2:1)
Block(1,7,-1,minecraft:log2:1)
Block(2,7,-1,minecraft:log2:1)
Block(3,7,-1,minecraft:log2:1)
Block(4,7,-1,minecraft:log2:1)
Block(0,7,0,minecraft:leaves2:1)
Block(1,7,0,minecraft:log2:1)
Block(2,7,0,minecraft:log2:1)
Block(3,7,0,minecraft:log2:1)
Block(4,7,0,minecraft:log2:1)
Block(5,7,0,minecraft:leaves2:1)
Block(2,7,1,minecraft:log2:1)
Block(3,7,1,minecraft:log2:1)
Block(4,7,1,minecraft:log2:1)
Block(3,7,2,minecraft:log2:1)
Block(4,7,2,minecraft:log2:1)
Block(5,7,2,minecraft:log2:1)
Block(4,7,3,minecraft:log2:1)
Block(5,7,3,minecraft:log2:1)
Block(-8,8,-15,minecraft:leaves2:1)
Block(-5,8,-15,minecraft:leaves2:1)
Block(-7,8,-14,minecraft:leaves2:1)
Block(-6,8,-14,minecraft:leaves2:1)
Block(-5,8,-14,minecraft:log2:1)
Block(-4,8,-14,minecraft:leaves2:1)
Block(-8,8,-13,minecraft:leaves2:1)
Block(-7,8,-13,minecraft:leaves2:1)
Block(-6,8,-13,minecraft:leaves2:1)
Block(-5,8,-13,minecraft:log2:1)
Block(-3,8,-13,minecraft:leaves2:1)
Block(-9,8,-12,minecraft:leaves2:1)
Block(-7,8,-12,minecraft:log2:1)
Block(-6,8,-12,minecraft:log2:1)
Block(-5,8,-12,minecraft:log2:1)
Block(-4,8,-12,minecraft:log2:1)
Block(-3,8,-12,minecraft:leaves2:1)
Block(-2,8,-12,minecraft:leaves2:1)
Block(-10,8,-11,minecraft:leaves2:1)
Block(-9,8,-11,minecraft:leaves2:1)
Block(-8,8,-11,minecraft:leaves2:1)
Block(-7,8,-11,minecraft:log2:1)
Block(-6,8,-11,minecraft:log2:1)
Block(-5,8,-11,minecraft:log2:1)
Block(-4,8,-11,minecraft:log2:1)
Block(-3,8,-11,minecraft:leaves2:1)
Block(-2,8,-11,minecraft:leaves2:1)
Block(-10,8,-10,minecraft:leaves2:1)
Block(-9,8,-10,minecraft:leaves2:1)
Block(-7,8,-10,minecraft:log2:1)
Block(-6,8,-10,minecraft:log2:1)
Block(-5,8,-10,minecraft:log2:1)
Block(-4,8,-10,minecraft:log2:1)
Block(-3,8,-10,minecraft:leaves2:1)
Block(-11,8,-9,minecraft:leaves2:1)
Block(-10,8,-9,minecraft:leaves2:1)
Block(-9,8,-9,minecraft:leaves2:1)
Block(-6,8,-9,minecraft:log2:1)
Block(-5,8,-9,minecraft:log2:1)
Block(-10,8,-8,minecraft:leaves2:1)
Block(-9,8,-8,minecraft:leaves2:1)
Block(-8,8,-8,minecraft:leaves2:1)
Block(-7,8,-8,minecraft:leaves2:1)
Block(-6,8,-8,minecraft:leaves2:1)
Block(-5,8,-8,minecraft:log2:1)
Block(-9,8,-7,minecraft:leaves2:1)
Block(-8,8,-7,minecraft:leaves2:1)
Block(-7,8,-7,minecraft:leaves2:1)
Block(-6,8,-7,minecraft:leaves2:1)
Block(-7,8,-6,minecraft:leaves2:1)
Block(-2,8,-6,minecraft:log2:1)
Block(-1,8,-6,minecraft:log2:1)
Block(-3,8,-5,minecraft:log2:1)
Block(-2,8,-5,minecraft:log2:1)
Block(-1,8,-5,minecraft:log2:1)
Block(0,8,-5,minecraft:log2:1)
Block(1,8,-5,minecraft:log2:1)
Block(2,8,-5,minecraft:leaves2:1)
Block(-2,8,-4,minecraft:log2:1)
Block(-1,8,-4,minecraft:log2:1)
Block(0,8,-4,minecraft:log2:1)
Block(1,8,-4,minecraft:log2:1)
Block(2,8,-4,minecraft:log2:1)
Block(-2,8,-3,minecraft:log2:1)
Block(-1,8,-3,minecraft:log2:1)
Block(0,8,-3,minecraft:log2:1)
Block(1,8,-3,minecraft:log2:1)
Block(2,8,-3,minecraft:log2:1)
Block(-3,8,-2,minecraft:leaves2:1)
Block(-2,8,-2,minecraft:log2:1)
Block(-1,8,-2,minecraft:log2:1)
Block(0,8,-2,minecraft:log2:1)
Block(1,8,-2,minecraft:log2:1)
Block(2,8,-2,minecraft:log2:1)
Block(3,8,-2,minecraft:log2:1)
Block(-1,8,-1,minecraft:log2:1)
Block(0,8,-1,minecraft:log2:1)
Block(1,8,-1,minecraft:log2:1)
Block(2,8,-1,minecraft:log2:1)
Block(3,8,-1,minecraft:log2:1)
Block(0,8,0,minecraft:leaves2:1)
Block(1,8,0,minecraft:log2:1)
Block(2,8,0,minecraft:log2:1)
Block(3,8,0,minecraft:log2:1)
Block(4,8,0,minecraft:log2:1)
Block(5,8,0,minecraft:leaves2:1)
Block(2,8,1,minecraft:log2:1)
Block(3,8,1,minecraft:log2:1)
Block(4,8,1,minecraft:log2:1)
Block(5,8,1,minecraft:log2:1)
Block(2,8,2,minecraft:log2:1)
Block(3,8,2,minecraft:log2:1)
Block(4,8,2,minecraft:log2:1)
Block(5,8,2,minecraft:log2:1)
Block(3,8,3,minecraft:log2:1)
Block(4,8,3,minecraft:log2:1)
Block(5,8,3,minecraft:log2:1)
Block(4,8,4,minecraft:log2:1)
Block(5,8,4,minecraft:log2:1)
Block(6,8,4,minecraft:log2:1)
Block(5,8,5,minecraft:log2:1)
Block(6,8,5,minecraft:log2:1)
Block(6,8,6,minecraft:leaves2:1)
Block(-8,9,-15,minecraft:leaves2:1)
Block(-7,9,-15,minecraft:leaves2:1)
Block(-6,9,-15,minecraft:leaves2:1)
Block(-5,9,-15,minecraft:leaves2:1)
Block(-4,9,-15,minecraft:leaves2:1)
Block(-9,9,-14,minecraft:leaves2:1)
Block(-8,9,-14,minecraft:leaves2:1)
Block(-7,9,-14,minecraft:leaves2:1)
Block(-6,9,-14,minecraft:leaves2:1)
Block(-5,9,-14,minecraft:leaves2:1)
Block(-4,9,-14,minecraft:leaves2:1)
Block(-3,9,-14,minecraft:leaves2:1)
Block(-10,9,-13,minecraft:leaves2:1)
Block(-9,9,-13,minecraft:leaves2:1)
Block(-8,9,-13,minecraft:leaves2:1)
Block(-7,9,-13,minecraft:leaves2:1)
Block(-6,9,-13,minecraft:leaves2:1)
Block(-5,9,-13,minecraft:leaves2:1)
Block(-4,9,-13,minecraft:leaves2:1)
Block(-3,9,-13,minecraft:leaves2:1)
Block(-2,9,-13,minecraft:leaves2:1)
Block(-10,9,-12,minecraft:leaves2:1)
Block(-9,9,-12,minecraft:leaves2:1)
Block(-8,9,-12,minecraft:leaves2:1)
Block(-7,9,-12,minecraft:leaves2:1)
Block(-6,9,-12,minecraft:leaves2:1)
Block(-5,9,-12,minecraft:leaves2:1)
Block(-4,9,-12,minecraft:leaves2:1)
Block(-3,9,-12,minecraft:leaves2:1)
Block(-10,9,-11,minecraft:leaves2:1)
Block(-9,9,-11,minecraft:leaves2:1)
Block(-8,9,-11,minecraft:leaves2:1)
Block(-7,9,-11,minecraft:leaves2:1)
Block(-6,9,-11,minecraft:leaves2:1)
Block(-5,9,-11,minecraft:leaves2:1)
Block(-4,9,-11,minecraft:leaves2:1)
Block(-3,9,-11,minecraft:leaves2:1)
Block(-2,9,-11,minecraft:leaves2:1)
Block(-11,9,-10,minecraft:leaves2:1)
Block(-10,9,-10,minecraft:leaves2:1)
Block(-9,9,-10,minecraft:leaves2:1)
Block(-8,9,-10,minecraft:leaves2:1)
Block(-7,9,-10,minecraft:leaves2:1)
Block(-6,9,-10,minecraft:leaves2:1)
Block(-5,9,-10,minecraft:leaves2:1)
Block(-4,9,-10,minecraft:leaves2:1)
Block(-3,9,-10,minecraft:leaves2:1)
Block(-11,9,-9,minecraft:leaves2:1)
Block(-10,9,-9,minecraft:leaves2:1)
Block(-9,9,-9,minecraft:leaves2:1)
Block(-8,9,-9,minecraft:leaves2:1)
Block(-7,9,-9,minecraft:leaves2:1)
Block(-6,9,-9,minecraft:leaves2:1)
Block(-5,9,-9,minecraft:leaves2:1)
Block(-4,9,-9,minecraft:leaves2:1)
Block(-3,9,-9,minecraft:leaves2:1)
Block(-2,9,-9,minecraft:leaves2:1)
Block(-11,9,-8,minecraft:leaves2:1)
Block(-10,9,-8,minecraft:leaves2:1)
Block(-9,9,-8,minecraft:leaves2:1)
Block(-8,9,-8,minecraft:leaves2:1)
Block(-7,9,-8,minecraft:leaves2:1)
Block(-6,9,-8,minecraft:leaves2:1)
Block(-5,9,-8,minecraft:leaves2:1)
Block(-4,9,-8,minecraft:leaves2:1)
Block(-3,9,-8,minecraft:leaves2:1)
Block(-10,9,-7,minecraft:leaves2:1)
Block(-9,9,-7,minecraft:leaves2:1)
Block(-8,9,-7,minecraft:leaves2:1)
Block(-7,9,-7,minecraft:leaves2:1)
Block(-6,9,-7,minecraft:leaves2:1)
Block(-4,9,-7,minecraft:leaves2:1)
Block(-8,9,-6,minecraft:leaves2:1)
Block(-7,9,-6,minecraft:leaves2:1)
Block(-6,9,-6,minecraft:leaves2:1)
Block(-2,9,-5,minecraft:log2:1)
Block(-1,9,-5,minecraft:log2:1)
Block(0,9,-5,minecraft:log2:1)
Block(1,9,-5,minecraft:log2:1)
Block(2,9,-5,minecraft:leaves2:1)
Block(-2,9,-4,minecraft:log2:1)
Block(-1,9,-4,minecraft:log2:1)
Block(0,9,-4,minecraft:log2:1)
Block(1,9,-4,minecraft:log2:1)
Block(2,9,-4,minecraft:log2:1)
Block(-2,9,-3,minecraft:log2:1)
Block(-1,9,-3,minecraft:log2:1)
Block(0,9,-3,minecraft:log2:1)
Block(1,9,-3,minecraft:log2:1)
Block(2,9,-3,minecraft:log2:1)
Block(-3,9,-2,minecraft:leaves2:1)
Block(-2,9,-2,minecraft:log2:1)
Block(-1,9,-2,minecraft:log2:1)
Block(0,9,-2,minecraft:log2:1)
Block(1,9,-2,minecraft:log2:1)
Block(2,9,-2,minecraft:log2:1)
Block(-1,9,-1,minecraft:log2:1)
Block(0,9,-1,minecraft:log2:1)
Block(1,9,-1,minecraft:log2:1)
Block(2,9,-1,minecraft:log2:1)
Block(3,9,-1,minecraft:log2:1)
Block(1,9,0,minecraft:leaves2:1)
Block(2,9,0,minecraft:log2:1)
Block(3,9,0,minecraft:log2:1)
Block(2,9,1,minecraft:log2:1)
Block(3,9,1,minecraft:log2:1)
Block(4,9,1,minecraft:log2:1)
Block(5,9,1,minecraft:leaves2:1)
Block(2,9,2,minecraft:log2:1)
Block(3,9,2,minecraft:log2:1)
Block(4,9,2,minecraft:log2:1)
Block(5,9,2,minecraft:log2:1)
Block(7,9,2,minecraft:leaves2:1)
Block(2,9,3,minecraft:log2:1)
Block(3,9,3,minecraft:log2:1)
Block(4,9,3,minecraft:log2:1)
Block(5,9,3,minecraft:log2:1)
Block(6,9,3,minecraft:log2:1)
Block(3,9,4,minecraft:log2:1)
Block(4,9,4,minecraft:log2:1)
Block(5,9,4,minecraft:log2:1)
Block(6,9,4,minecraft:log2:1)
Block(4,9,5,minecraft:log2:1)
Block(5,9,5,minecraft:log2:1)
Block(6,9,5,minecraft:log2:1)
Block(7,9,5,minecraft:leaves2:1)
Block(2,9,6,minecraft:leaves2:1)
Block(5,9,6,minecraft:log2:1)
Block(6,9,6,minecraft:log2:1)
Block(10,9,6,minecraft:leaves2:1)
Block(5,9,7,minecraft:leaves2:1)
Block(-5,10,-15,minecraft:leaves2:1)
Block(-9,10,-14,minecraft:leaves2:1)
Block(-8,10,-14,minecraft:leaves2:1)
Block(-7,10,-14,minecraft:leaves2:1)
Block(-6,10,-14,minecraft:leaves2:1)
Block(-5,10,-14,minecraft:leaves2:1)
Block(-4,10,-14,minecraft:leaves2:1)
Block(-9,10,-13,minecraft:leaves2:1)
Block(-8,10,-13,minecraft:leaves2:1)
Block(-7,10,-13,minecraft:leaves2:1)
Block(-6,10,-13,minecraft:leaves2:1)
Block(-5,10,-13,minecraft:leaves2:1)
Block(-4,10,-13,minecraft:leaves2:1)
Block(-10,10,-12,minecraft:leaves2:1)
Block(-9,10,-12,minecraft:leaves2:1)
Block(-8,10,-12,minecraft:leaves2:1)
Block(-6,10,-12,minecraft:leaves2:1)
Block(-5,10,-12,minecraft:leaves2:1)
Block(-4,10,-12,minecraft:leaves2:1)
Block(-3,10,-12,minecraft:leaves2:1)
Block(-10,10,-11,minecraft:leaves2:1)
Block(-8,10,-11,minecraft:leaves2:1)
Block(-6,10,-11,minecraft:leaves2:1)
Block(-5,10,-11,minecraft:leaves2:1)
Block(-4,10,-11,minecraft:leaves2:1)
Block(-3,10,-11,minecraft:leaves2:1)
Block(-2,10,-11,minecraft:leaves2:1)
Block(-10,10,-10,minecraft:leaves2:1)
Block(-9,10,-10,minecraft:leaves2:1)
Block(-8,10,-10,minecraft:leaves2:1)
Block(-7,10,-10,minecraft:leaves2:1)
Block(-6,10,-10,minecraft:leaves2:1)
Block(-5,10,-10,minecraft:leaves2:1)
Block(-4,10,-10,minecraft:leaves2:1)
Block(-3,10,-10,minecraft:leaves2:1)
Block(-11,10,-9,minecraft:leaves2:1)
Block(-10,10,-9,minecraft:leaves2:1)
Block(-9,10,-9,minecraft:leaves2:1)
Block(-8,10,-9,minecraft:leaves2:1)
Block(-7,10,-9,minecraft:leaves2:1)
Block(-6,10,-9,minecraft:leaves2:1)
Block(-5,10,-9,minecraft:leaves2:1)
Block(-4,10,-9,minecraft:leaves2:1)
Block(-3,10,-9,minecraft:leaves2:1)
Block(-10,10,-8,minecraft:leaves2:1)
Block(-9,10,-8,minecraft:leaves2:1)
Block(-8,10,-8,minecraft:leaves2:1)
Block(-7,10,-8,minecraft:leaves2:1)
Block(-6,10,-8,minecraft:leaves2:1)
Block(-5,10,-8,minecraft:leaves2:1)
Block(-4,10,-8,minecraft:leaves2:1)
Block(-3,10,-8,minecraft:leaves2:1)
Block(-9,10,-7,minecraft:leaves2:1)
Block(-8,10,-7,minecraft:leaves2:1)
Block(-7,10,-7,minecraft:leaves2:1)
Block(-6,10,-7,minecraft:leaves2:1)
Block(-5,10,-7,minecraft:leaves2:1)
Block(-4,10,-7,minecraft:leaves2:1)
Block(-7,10,-6,minecraft:leaves2:1)
Block(-6,10,-6,minecraft:leaves2:1)
Block(-5,10,-6,minecraft:leaves2:1)
Block(0,10,-6,minecraft:log2:1)
Block(1,10,-6,minecraft:log2:1)
Block(-1,10,-5,minecraft:log2:1)
Block(0,10,-5,minecraft:log2:1)
Block(1,10,-5,minecraft:log2:1)
Block(2,10,-5,minecraft:log2:1)
Block(3,10,-5,minecraft:leaves2:1)
Block(-2,10,-4,minecraft:log2:1)
Block(-1,10,-4,minecraft:log2:1)
Block(0,10,-4,minecraft:log2:1)
Block(1,10,-4,minecraft:log2:1)
Block(2,10,-4,minecraft:log2:1)
Block(-3,10,-3,minecraft:leaves2:1)
Block(-2,10,-3,minecraft:log2:1)
Block(-1,10,-3,minecraft:log2:1)
Block(0,10,-3,minecraft:log2:1)
Block(1,10,-3,minecraft:log2:1)
Block(2,10,-3,minecraft:log2:1)
Block(-2,10,-2,minecraft:log2:1)
Block(-1,10,-2,minecraft:log2:1)
Block(0,10,-2,minecraft:log2:1)
Block(1,10,-2,minecraft:log2:1)
Block(2,10,-2,minecraft:log2:1)
Block(-2,10,-1,minecraft:log2:1)
Block(-1,10,-1,minecraft:log2:1)
Block(0,10,-1,minecraft:log2:1)
Block(1,10,-1,minecraft:log2:1)
Block(2,10,-1,minecraft:log2:1)
Block(1,10,0,minecraft:leaves2:1)
Block(2,10,0,minecraft:log2:1)
Block(3,10,0,minecraft:log2:1)
Block(2,10,1,minecraft:log2:1)
Block(3,10,1,minecraft:log2:1)
Block(4,10,1,minecraft:leaves2:1)
Block(3,10,2,minecraft:log2:1)
Block(4,10,2,minecraft:log2:1)
Block(7,10,2,minecraft:leaves2:1)
Block(3,10,3,minecraft:log2:1)
Block(4,10,3,minecraft:log2:1)
Block(5,10,3,minecraft:log2:1)
Block(4,10,4,minecraft:log2:1)
Block(5,10,4,minecraft:log2:1)
Block(6,10,4,minecraft:log2:1)
Block(7,10,4,minecraft:leaves2:1)
Block(4,10,5,minecraft:log2:1)
Block(5,10,5,minecraft:log2:1)
Block(6,10,5,minecraft:log2:1)
Block(7,10,5,minecraft:log2:1)
Block(2,10,6,minecraft:leaves2:1)
Block(4,10,6,minecraft:log2:1)
Block(5,10,6,minecraft:log2:1)
Block(6,10,6,minecraft:log2:1)
Block(10,10,6,minecraft:leaves2:1)
Block(4,10,7,minecraft:leaves2:1)
Block(5,10,7,minecraft:log2:1)
Block(4,10,9,minecraft:leaves2:1)
Block(6,10,10,minecraft:leaves2:1)
Block(-8,11,-14,minecraft:leaves2:1)
Block(-6,11,-14,minecraft:leaves2:1)
Block(-8,11,-13,minecraft:leaves2:1)
Block(-7,11,-13,minecraft:leaves2:1)
Block(-6,11,-13,minecraft:leaves2:1)
Block(-5,11,-13,minecraft:leaves2:1)
Block(-9,11,-12,minecraft:leaves2:1)
Block(-6,11,-12,minecraft:leaves2:1)
Block(-9,11,-11,minecraft:leaves2:1)
Block(-7,11,-11,minecraft:leaves2:1)
Block(-6,11,-11,minecraft:leaves2:1)
Block(-5,11,-11,minecraft:leaves2:1)
Block(-4,11,-11,minecraft:leaves2:1)
Block(-3,11,-11,minecraft:leaves2:1)
Block(-10,11,-10,minecraft:leaves2:1)
Block(-9,11,-10,minecraft:leaves2:1)
Block(-8,11,-10,minecraft:leaves2:1)
Block(-7,11,-10,minecraft:leaves2:1)
Block(-6,11,-10,minecraft:leaves2:1)
Block(-5,11,-10,minecraft:leaves2:1)
Block(-4,11,-10,minecraft:leaves2:1)
Block(-9,11,-9,minecraft:leaves2:1)
Block(-7,11,-9,minecraft:leaves2:1)
Block(-6,11,-9,minecraft:leaves2:1)
Block(-5,11,-9,minecraft:leaves2:1)
Block(-4,11,-9,minecraft:leaves2:1)
Block(-3,11,-9,minecraft:leaves2:1)
Block(-8,11,-8,minecraft:leaves2:1)
Block(-7,11,-8,minecraft:leaves2:1)
Block(-6,11,-8,minecraft:leaves2:1)
Block(-5,11,-8,minecraft:leaves2:1)
Block(-4,11,-8,minecraft:leaves2:1)
Block(-7,11,-7,minecraft:leaves2:1)
Block(-6,11,-7,minecraft:leaves2:1)
Block(-5,11,-7,minecraft:leaves2:1)
Block(-6,11,-6,minecraft:leaves2:1)
Block(-1,11,-6,minecraft:log2:1)
Block(0,11,-6,minecraft:log2:1)
Block(1,11,-6,minecraft:log2:1)
Block(2,11,-6,minecraft:log2:1)
Block(-1,11,-5,minecraft:log2:1)
Block(0,11,-5,minecraft:log2:1)
Block(1,11,-5,minecraft:log2:1)
Block(2,11,-5,minecraft:log2:1)
Block(-1,11,-4,minecraft:log2:1)
Block(0,11,-4,minecraft:log2:1)
Block(1,11,-4,minecraft:log2:1)
Block(2,11,-4,minecraft:log2:1)
Block(3,11,-4,minecraft:leaves2:1)
Block(-3,11,-3,minecraft:leaves2:1)
Block(-2,11,-3,minecraft:log2:1)
Block(-1,11,-3,minecraft:log2:1)
Block(0,11,-3,minecraft:log2:1)
Block(1,11,-3,minecraft:log2:1)
Block(2,11,-3,minecraft:log2:1)
Block(-3,11,-2,minecraft:log2:1)
Block(-2,11,-2,minecraft:log2:1)
Block(-1,11,-2,minecraft:log2:1)
Block(0,11,-2,minecraft:log2:1)
Block(1,11,-2,minecraft:log2:1)
Block(2,11,-2,minecraft:log2:1)
Block(-3,11,-1,minecraft:log2:1)
Block(-2,11,-1,minecraft:log2:1)
Block(-1,11,-1,minecraft:log2:1)
Block(0,11,-1,minecraft:log2:1)
Block(1,11,-1,minecraft:log2:1)
Block(2,11,-1,minecraft:leaves2:1)
Block(-4,11,0,minecraft:log2:1)
Block(-3,11,0,minecraft:log2:1)
Block(0,11,0,minecraft:leaves2:1)
Block(3,11,2,minecraft:leaves2:1)
Block(4,11,2,minecraft:leaves2:1)
Block(7,11,2,minecraft:leaves2:1)
Block(4,11,3,minecraft:leaves2:1)
Block(9,11,3,minecraft:leaves2:1)
Block(5,11,4,minecraft:log2:1)
Block(6,11,4,minecraft:log2:1)
Block(7,11,4,minecraft:log2:1)
Block(8,11,4,minecraft:leaves2:1)
Block(4,11,5,minecraft:log2:1)
Block(5,11,5,minecraft:log2:1)
Block(6,11,5,minecraft:log2:1)
Block(7,11,5,minecraft:log2:1)
Block(2,11,6,minecraft:leaves2:1)
Block(4,11,6,minecraft:log2:1)
Block(5,11,6,minecraft:log2:1)
Block(6,11,6,minecraft:log2:1)
Block(7,11,6,minecraft:log2:1)
Block(10,11,6,minecraft:leaves2:1)
Block(4,11,7,minecraft:leaves2:1)
Block(5,11,7,minecraft:log2:1)
Block(6,11,7,minecraft:log2:1)
Block(10,11,8,minecraft:leaves2:1)
Block(4,11,9,minecraft:leaves2:1)
Block(6,11,10,minecraft:leaves2:1)
Block(8,11,10,minecraft:leaves2:1)
Block(-7,12,-13,minecraft:leaves2:1)
Block(-8,12,-12,minecraft:leaves2:1)
Block(-7,12,-12,minecraft:leaves2:1)
Block(-6,12,-12,minecraft:leaves2:1)
Block(-7,12,-11,minecraft:leaves2:1)
Block(-5,12,-11,minecraft:leaves2:1)
Block(-4,12,-11,minecraft:leaves2:1)
Block(-9,12,-10,minecraft:leaves2:1)
Block(-8,12,-10,minecraft:leaves2:1)
Block(-6,12,-10,minecraft:leaves2:1)
Block(-7,12,-9,minecraft:leaves2:1)
Block(-6,12,-9,minecraft:leaves2:1)
Block(-5,12,-9,minecraft:leaves2:1)
Block(-4,12,-9,minecraft:leaves2:1)
Block(-7,12,-8,minecraft:leaves2:1)
Block(-6,12,-8,minecraft:leaves2:1)
Block(-5,12,-8,minecraft:leaves2:1)
Block(-6,12,-7,minecraft:leaves2:1)
Block(2,12,-7,minecraft:log2:1)
Block(0,12,-6,minecraft:log2:1)
Block(1,12,-6,minecraft:log2:1)
Block(2,12,-6,minecraft:log2:1)
Block(3,12,-6,minecraft:log2:1)
Block(-1,12,-5,minecraft:log2:1)
Block(0,12,-5,minecraft:log2:1)
Block(1,12,-5,minecraft:log2:1)
Block(2,12,-5,minecraft:log2:1)
Block(3,12,-5,minecraft:log2:1)
Block(-2,12,-4,minecraft:leaves2:1)
Block(-1,12,-4,minecraft:log2:1)
Block(0,12,-4,minecraft:log2:1)
Block(1,12,-4,minecraft:log2:1)
Block(2,12,-4,minecraft:log2:1)
Block(3,12,-4,minecraft:leaves2:1)
Block(-3,12,-3,minecraft:log2:1)
Block(-2,12,-3,minecraft:log2:1)
Block(-1,12,-3,minecraft:log2:1)
Block(0,12,-3,minecraft:log2:1)
Block(1,12,-3,minecraft:log2:1)
Block(2,12,-3,minecraft:log2:1)
Block(-3,12,-2,minecraft:log2:1)
Block(-2,12,-2,minecraft:log2:1)
Block(-1,12,-2,minecraft:log2:1)
Block(0,12,-2,minecraft:log2:1)
Block(1,12,-2,minecraft:log2:1)
Block(2,12,-2,minecraft:log2:1)
Block(-4,12,-1,minecraft:log2:1)
Block(-3,12,-1,minecraft:log2:1)
Block(-2,12,-1,minecraft:log2:1)
Block(-1,12,-1,minecraft:log2:1)
Block(0,12,-1,minecraft:log2:1)
Block(1,12,-1,minecraft:log2:1)
Block(2,12,-1,minecraft:leaves2:1)
Block(-5,12,0,minecraft:log2:1)
Block(-4,12,0,minecraft:log2:1)
Block(-3,12,0,minecraft:log2:1)
Block(-2,12,0,minecraft:log2:1)
Block(0,12,0,minecraft:leaves2:1)
Block(-5,12,1,minecraft:log2:1)
Block(-4,12,1,minecraft:log2:1)
Block(5,12,2,minecraft:leaves2:1)
Block(7,12,2,minecraft:leaves2:1)
Block(3,12,3,minecraft:leaves2:1)
Block(4,12,3,minecraft:leaves2:1)
Block(5,12,3,minecraft:leaves2:1)
Block(6,12,3,minecraft:leaves2:1)
Block(7,12,3,minecraft:leaves2:1)
Block(9,12,3,minecraft:leaves2:1)
Block(3,12,4,minecraft:leaves2:1)
Block(4,12,4,minecraft:leaves2:1)
Block(5,12,4,minecraft:leaves2:1)
Block(6,12,4,minecraft:log2:1)
Block(7,12,4,minecraft:log2:1)
Block(8,12,4,minecraft:leaves2:1)
Block(4,12,5,minecraft:leaves2:1)
Block(5,12,5,minecraft:log2:1)
Block(6,12,5,minecraft:log2:1)
Block(7,12,5,minecraft:log2:1)
Block(8,12,5,minecraft:log2:1)
Block(9,12,5,minecraft:leaves2:1)
Block(2,12,6,minecraft:leaves2:1)
Block(3,12,6,minecraft:leaves2:1)
Block(4,12,6,minecraft:leaves2:1)
Block(5,12,6,minecraft:log2:1)
Block(6,12,6,minecraft:log2:1)
Block(7,12,6,minecraft:log2:1)
Block(8,12,6,minecraft:log2:1)
Block(9,12,6,minecraft:log2:1)
Block(10,12,6,minecraft:leaves2:1)
Block(3,12,7,minecraft:leaves2:1)
Block(4,12,7,minecraft:leaves2:1)
Block(5,12,7,minecraft:leaves2:1)
Block(6,12,7,minecraft:log2:1)
Block(7,12,7,minecraft:log2:1)
Block(9,12,7,minecraft:leaves2:1)
Block(4,12,8,minecraft:leaves2:1)
Block(5,12,8,minecraft:leaves2:1)
Block(10,12,8,minecraft:leaves2:1)
Block(4,12,9,minecraft:leaves2:1)
Block(5,12,10,minecraft:leaves2:1)
Block(6,12,10,minecraft:leaves2:1)
Block(8,12,10,minecraft:leaves2:1)
Block(3,13,-11,minecraft:leaves2:1)
Block(2,13,-7,minecraft:log2:1)
Block(3,13,-7,minecraft:log2:1)
Block(1,13,-6,minecraft:log2:1)
Block(2,13,-6,minecraft:log2:1)
Block(3,13,-6,minecraft:log2:1)
Block(4,13,-6,minecraft:log2:1)
Block(-1,13,-5,minecraft:log2:1)
Block(0,13,-5,minecraft:log2:1)
Block(1,13,-5,minecraft:log2:1)
Block(2,13,-5,minecraft:log2:1)
Block(3,13,-5,minecraft:log2:1)
Block(4,13,-5,minecraft:log2:1)
Block(-2,13,-4,minecraft:leaves2:1)
Block(-1,13,-4,minecraft:log2:1)
Block(0,13,-4,minecraft:log2:1)
Block(1,13,-4,minecraft:log2:1)
Block(2,13,-4,minecraft:log2:1)
Block(3,13,-4,minecraft:log2:1)
Block(4,13,-4,minecraft:leaves2:1)
Block(-3,13,-3,minecraft:log2:1)
Block(-2,13,-3,minecraft:log2:1)
Block(-1,13,-3,minecraft:log2:1)
Block(0,13,-3,minecraft:log2:1)
Block(1,13,-3,minecraft:log2:1)
Block(2,13,-3,minecraft:log2:1)
Block(-4,13,-2,minecraft:log2:1)
Block(-3,13,-2,minecraft:log2:1)
Block(-2,13,-2,minecraft:log2:1)
Block(-1,13,-2,minecraft:log2:1)
Block(0,13,-2,minecraft:log2:1)
Block(1,13,-2,minecraft:log2:1)
Block(2,13,-2,minecraft:log2:1)
Block(-5,13,-1,minecraft:log2:1)
Block(-4,13,-1,minecraft:log2:1)
Block(-3,13,-1,minecraft:log2:1)
Block(-2,13,-1,minecraft:log2:1)
Block(-1,13,-1,minecraft:log2:1)
Block(0,13,-1,minecraft:log2:1)
Block(1,13,-1,minecraft:log2:1)
Block(2,13,-1,minecraft:leaves2:1)
Block(-6,13,0,minecraft:log2:1)
Block(-5,13,0,minecraft:log2:1)
Block(-4,13,0,minecraft:log2:1)
Block(-3,13,0,minecraft:log2:1)
Block(-2,13,0,minecraft:log2:1)
Block(-1,13,0,minecraft:leaves2:1)
Block(-8,13,1,minecraft:leaves2:1)
Block(-7,13,1,minecraft:log2:1)
Block(-6,13,1,minecraft:log2:1)
Block(-5,13,1,minecraft:log2:1)
Block(-4,13,1,minecraft:log2:1)
Block(-3,13,1,minecraft:log2:1)
Block(4,13,1,minecraft:leaves2:1)
Block(5,13,1,minecraft:leaves2:1)
Block(6,13,1,minecraft:leaves2:1)
Block(7,13,1,minecraft:leaves2:1)
Block(8,13,1,minecraft:leaves2:1)
Block(-14,13,2,minecraft:leaves2:1)
Block(-7,13,2,minecraft:leaves2:1)
Block(-5,13,2,minecraft:log2:1)
Block(-4,13,2,minecraft:log2:1)
Block(4,13,2,minecraft:leaves2:1)
Block(5,13,2,minecraft:leaves2:1)
Block(6,13,2,minecraft:leaves2:1)
Block(7,13,2,minecraft:leaves2:1)
Block(8,13,2,minecraft:leaves2:1)
Block(5,13,3,minecraft:leaves2:1)
Block(6,13,3,minecraft:leaves2:1)
Block(7,13,3,minecraft:leaves2:1)
Block(8,13,3,minecraft:leaves2:1)
Block(9,13,3,minecraft:leaves2:1)
Block(2,13,4,minecraft:leaves2:1)
Block(3,13,4,minecraft:leaves2:1)
Block(4,13,4,minecraft:leaves2:1)
Block(5,13,4,minecraft:leaves2:1)
Block(6,13,4,minecraft:leaves2:1)
Block(7,13,4,minecraft:leaves2:1)
Block(8,13,4,minecraft:leaves2:1)
Block(9,13,4,minecraft:leaves2:1)
Block(10,13,4,minecraft:leaves2:1)
Block(2,13,5,minecraft:leaves2:1)
Block(3,13,5,minecraft:leaves2:1)
Block(4,13,5,minecraft:leaves2:1)
Block(5,13,5,minecraft:leaves2:1)
Block(6,13,5,minecraft:leaves2:1)
Block(7,13,5,minecraft:log2:1)
Block(8,13,5,minecraft:leaves2:1)
Block(9,13,5,minecraft:leaves2:1)
Block(10,13,5,minecraft:leaves2:1)
Block(3,13,6,minecraft:leaves2:1)
Block(4,13,6,minecraft:leaves2:1)
Block(5,13,6,minecraft:leaves2:1)
Block(6,13,6,minecraft:log2:1)
Block(7,13,6,minecraft:log2:1)
Block(8,13,6,minecraft:log2:1)
Block(9,13,6,minecraft:leaves2:1)
Block(10,13,6,minecraft:leaves2:1)
Block(2,13,7,minecraft:leaves2:1)
Block(3,13,7,minecraft:leaves2:1)
Block(4,13,7,minecraft:leaves2:1)
Block(5,13,7,minecraft:leaves2:1)
Block(6,13,7,minecraft:leaves2:1)
Block(7,13,7,minecraft:log2:1)
Block(9,13,7,minecraft:leaves2:1)
Block(10,13,7,minecraft:leaves2:1)
Block(2,13,8,minecraft:leaves2:1)
Block(3,13,8,minecraft:leaves2:1)
Block(4,13,8,minecraft:leaves2:1)
Block(5,13,8,minecraft:leaves2:1)
Block(6,13,8,minecraft:leaves2:1)
Block(7,13,8,minecraft:log2:1)
Block(9,13,8,minecraft:leaves2:1)
Block(10,13,8,minecraft:leaves2:1)
Block(3,13,9,minecraft:leaves2:1)
Block(4,13,9,minecraft:leaves2:1)
Block(5,13,9,minecraft:leaves2:1)
Block(6,13,9,minecraft:leaves2:1)
Block(7,13,9,minecraft:log2:1)
Block(8,13,9,minecraft:leaves2:1)
Block(9,13,9,minecraft:leaves2:1)
Block(4,13,10,minecraft:leaves2:1)
Block(5,13,10,minecraft:leaves2:1)
Block(6,13,10,minecraft:leaves2:1)
Block(7,13,10,minecraft:leaves2:1)
Block(8,13,10,minecraft:leaves2:1)
Block(3,14,-11,minecraft:leaves2:1)
Block(8,14,-10,minecraft:leaves2:1)
Block(3,14,-7,minecraft:log2:1)
Block(4,14,-7,minecraft:log2:1)
Block(5,14,-7,minecraft:leaves2:1)
Block(2,14,-6,minecraft:log2:1)
Block(3,14,-6,minecraft:log2:1)
Block(4,14,-6,minecraft:log2:1)
Block(5,14,-6,minecraft:log2:1)
Block(-1,14,-5,minecraft:log2:1)
Block(0,14,-5,minecraft:log2:1)
Block(1,14,-5,minecraft:log2:1)
Block(2,14,-5,minecraft:log2:1)
Block(3,14,-5,minecraft:log2:1)
Block(4,14,-5,minecraft:log2:1)
Block(5,14,-5,minecraft:leaves2:1)
Block(-2,14,-4,minecraft:leaves2:1)
Block(-1,14,-4,minecraft:log2:1)
Block(0,14,-4,minecraft:log2:1)
Block(1,14,-4,minecraft:log2:1)
Block(2,14,-4,minecraft:log2:1)
Block(3,14,-4,minecraft:log2:1)
Block(4,14,-4,minecraft:log2:1)
Block(-12,14,-3,minecraft:leaves2:1)
Block(-7,14,-3,minecraft:leaves2:1)
Block(-2,14,-3,minecraft:log2:1)
Block(-1,14,-3,minecraft:log2:1)
Block(0,14,-3,minecraft:log2:1)
Block(1,14,-3,minecraft:log2:1)
Block(2,14,-3,minecraft:log2:1)
Block(3,14,-3,minecraft:log2:1)
Block(-3,14,-2,minecraft:log2:1)
Block(-2,14,-2,minecraft:log2:1)
Block(-1,14,-2,minecraft:log2:1)
Block(0,14,-2,minecraft:log2:1)
Block(1,14,-2,minecraft:log2:1)
Block(2,14,-2,minecraft:log2:1)
Block(-6,14,-1,minecraft:log2:1)
Block(-5,14,-1,minecraft:log2:1)
Block(-4,14,-1,minecraft:log2:1)
Block(-3,14,-1,minecraft:log2:1)
Block(-2,14,-1,minecraft:log2:1)
Block(-1,14,-1,minecraft:log2:1)
Block(0,14,-1,minecraft:log2:1)
Block(1,14,-1,minecraft:log2:1)
Block(2,14,-1,minecraft:log2:1)
Block(3,14,-1,minecraft:leaves2:1)
Block(-8,14,0,minecraft:leaves2:1)
Block(-7,14,0,minecraft:log2:1)
Block(-6,14,0,minecraft:log2:1)
Block(-5,14,0,minecraft:log2:1)
Block(-4,14,0,minecraft:log2:1)
Block(-3,14,0,minecraft:log2:1)
Block(-8,14,1,minecraft:log2:1)
Block(-7,14,1,minecraft:log2:1)
Block(-6,14,1,minecraft:log2:1)
Block(-5,14,1,minecraft:log2:1)
Block(-4,14,1,minecraft:log2:1)
Block(6,14,1,minecraft:leaves2:1)
Block(7,14,1,minecraft:leaves2:1)
Block(-14,14,2,minecraft:leaves2:1)
Block(-7,14,2,minecraft:log2:1)
Block(-6,14,2,minecraft:log2:1)
Block(-5,14,2,minecraft:log2:1)
Block(5,14,2,minecraft:leaves2:1)
Block(7,14,2,minecraft:leaves2:1)
Block(8,14,2,minecraft:leaves2:1)
Block(-7,14,3,minecraft:leaves2:1)
Block(4,14,3,minecraft:leaves2:1)
Block(5,14,3,minecraft:leaves2:1)
Block(6,14,3,minecraft:leaves2:1)
Block(7,14,3,minecraft:leaves2:1)
Block(8,14,3,minecraft:leaves2:1)
Block(3,14,4,minecraft:leaves2:1)
Block(4,14,4,minecraft:leaves2:1)
Block(6,14,4,minecraft:leaves2:1)
Block(7,14,4,minecraft:leaves2:1)
Block(8,14,4,minecraft:leaves2:1)
Block(9,14,4,minecraft:leaves2:1)
Block(-5,14,5,minecraft:leaves2:1)
Block(5,14,5,minecraft:leaves2:1)
Block(6,14,5,minecraft:leaves2:1)
Block(7,14,5,minecraft:leaves2:1)
Block(8,14,5,minecraft:leaves2:1)
Block(9,14,5,minecraft:leaves2:1)
Block(2,14,6,minecraft:leaves2:1)
Block(3,14,6,minecraft:leaves2:1)
Block(4,14,6,minecraft:leaves2:1)
Block(5,14,6,minecraft:leaves2:1)
Block(6,14,6,minecraft:leaves2:1)
Block(7,14,6,minecraft:log2:1)
Block(8,14,6,minecraft:leaves2:1)
Block(9,14,6,minecraft:leaves2:1)
Block(10,14,6,minecraft:leaves2:1)
Block(2,14,7,minecraft:leaves2:1)
Block(3,14,7,minecraft:leaves2:1)
Block(4,14,7,minecraft:leaves2:1)
Block(5,14,7,minecraft:leaves2:1)
Block(6,14,7,minecraft:leaves2:1)
Block(7,14,7,minecraft:leaves2:1)
Block(9,14,7,minecraft:leaves2:1)
Block(10,14,7,minecraft:leaves2:1)
Block(-11,14,8,minecraft:leaves2:1)
Block(3,14,8,minecraft:leaves2:1)
Block(4,14,8,minecraft:leaves2:1)
Block(6,14,8,minecraft:leaves2:1)
Block(7,14,8,minecraft:leaves2:1)
Block(8,14,8,minecraft:leaves2:1)
Block(9,14,8,minecraft:leaves2:1)
Block(10,14,8,minecraft:leaves2:1)
Block(4,14,9,minecraft:leaves2:1)
Block(5,14,9,minecraft:leaves2:1)
Block(7,14,9,minecraft:leaves2:1)
Block(8,14,9,minecraft:leaves2:1)
Block(5,14,10,minecraft:leaves2:1)
Block(6,14,10,minecraft:leaves2:1)
Block(3,15,-11,minecraft:leaves2:1)
Block(8,15,-10,minecraft:leaves2:1)
Block(3,15,-8,minecraft:log2:1)
Block(4,15,-8,minecraft:log2:1)
Block(5,15,-8,minecraft:leaves2:1)
Block(3,15,-7,minecraft:log2:1)
Block(4,15,-7,minecraft:log2:1)
Block(5,15,-7,minecraft:log2:1)
Block(3,15,-6,minecraft:log2:1)
Block(4,15,-6,minecraft:log2:1)
Block(5,15,-6,minecraft:log2:1)
Block(6,15,-6,minecraft:leaves2:1)
Block(-1,15,-5,minecraft:log2:1)
Block(0,15,-5,minecraft:log2:1)
Block(1,15,-5,minecraft:log2:1)
Block(2,15,-5,minecraft:log2:1)
Block(3,15,-5,minecraft:log2:1)
Block(4,15,-5,minecraft:log2:1)
Block(5,15,-5,minecraft:log2:1)
Block(-2,15,-4,minecraft:log2:1)
Block(-1,15,-4,minecraft:log2:1)
Block(0,15,-4,minecraft:log2:1)
Block(1,15,-4,minecraft:log2:1)
Block(2,15,-4,minecraft:log2:1)
Block(3,15,-4,minecraft:log2:1)
Block(7,15,-4,minecraft:leaves2:1)
Block(-12,15,-3,minecraft:leaves2:1)
Block(-7,15,-3,minecraft:leaves2:1)
Block(-2,15,-3,minecraft:log2:1)
Block(-1,15,-3,minecraft:log2:1)
Block(0,15,-3,minecraft:log2:1)
Block(1,15,-3,minecraft:log2:1)
Block(2,15,-3,minecraft:log2:1)
Block(-2,15,-2,minecraft:log2:1)
Block(-1,15,-2,minecraft:log2:1)
Block(0,15,-2,minecraft:log2:1)
Block(1,15,-2,minecraft:log2:1)
Block(2,15,-2,minecraft:log2:1)
Block(3,15,-2,minecraft:leaves2:1)
Block(-13,15,-1,minecraft:leaves2:1)
Block(-7,15,-1,minecraft:log2:1)
Block(-6,15,-1,minecraft:log2:1)
Block(-5,15,-1,minecraft:log2:1)
Block(-1,15,-1,minecraft:log2:1)
Block(0,15,-1,minecraft:log2:1)
Block(1,15,-1,minecraft:log2:1)
Block(2,15,-1,minecraft:log2:1)
Block(-9,15,0,minecraft:leaves2:1)
Block(-8,15,0,minecraft:log2:1)
Block(-7,15,0,minecraft:log2:1)
Block(-6,15,0,minecraft:log2:1)
Block(-5,15,0,minecraft:log2:1)
Block(-4,15,0,minecraft:log2:1)
Block(1,15,0,minecraft:log2:1)
Block(-9,15,1,minecraft:log2:1)
Block(-8,15,1,minecraft:log2:1)
Block(-7,15,1,minecraft:log2:1)
Block(-6,15,1,minecraft:log2:1)
Block(-5,15,1,minecraft:log2:1)
Block(-14,15,2,minecraft:leaves2:1)
Block(-8,15,2,minecraft:log2:1)
Block(-7,15,2,minecraft:log2:1)
Block(-6,15,2,minecraft:log2:1)
Block(-6,15,3,minecraft:leaves2:1)
Block(6,15,3,minecraft:leaves2:1)
Block(7,15,3,minecraft:leaves2:1)
Block(-15,15,4,minecraft:leaves2:1)
Block(-3,15,4,minecraft:leaves2:1)
Block(6,15,4,minecraft:leaves2:1)
Block(8,15,4,minecraft:leaves2:1)
Block(-5,15,5,minecraft:leaves2:1)
Block(5,15,5,minecraft:leaves2:1)
Block(6,15,5,minecraft:leaves2:1)
Block(7,15,5,minecraft:leaves2:1)
Block(8,15,5,minecraft:leaves2:1)
Block(9,15,5,minecraft:leaves2:1)
Block(-13,15,6,minecraft:leaves2:1)
Block(3,15,6,minecraft:leaves2:1)
Block(5,15,6,minecraft:leaves2:1)
Block(6,15,6,minecraft:leaves2:1)
Block(7,15,6,minecraft:leaves2:1)
Block(9,15,6,minecraft:leaves2:1)
Block(-7,15,7,minecraft:leaves2:1)
Block(3,15,7,minecraft:leaves2:1)
Block(4,15,7,minecraft:leaves2:1)
Block(5,15,7,minecraft:leaves2:1)
Block(6,15,7,minecraft:leaves2:1)
Block(7,15,7,minecraft:leaves2:1)
Block(8,15,7,minecraft:leaves2:1)
Block(9,15,7,minecraft:leaves2:1)
Block(10,15,7,minecraft:leaves2:1)
Block(-11,15,8,minecraft:leaves2:1)
Block(4,15,8,minecraft:leaves2:1)
Block(6,15,8,minecraft:leaves2:1)
Block(8,15,8,minecraft:leaves2:1)
Block(9,15,8,minecraft:leaves2:1)
Block(7,15,9,minecraft:leaves2:1)
Block(5,16,-12,minecraft:leaves2:1)
Block(3,16,-11,minecraft:leaves2:1)
Block(8,16,-10,minecraft:leaves2:1)
Block(4,16,-9,minecraft:leaves2:1)
Block(3,16,-8,minecraft:log2:1)
Block(4,16,-8,minecraft:log2:1)
Block(5,16,-8,minecraft:log2:1)
Block(3,16,-7,minecraft:log2:1)
Block(4,16,-7,minecraft:log2:1)
Block(5,16,-7,minecraft:log2:1)
Block(6,16,-7,minecraft:log2:1)
Block(10,16,-7,minecraft:leaves2:1)
Block(3,16,-6,minecraft:log2:1)
Block(4,16,-6,minecraft:log2:1)
Block(5,16,-6,minecraft:log2:1)
Block(6,16,-6,minecraft:log2:1)
Block(7,16,-6,minecraft:leaves2:1)
Block(-3,16,-5,minecraft:leaves2:1)
Block(-2,16,-5,minecraft:log2:1)
Block(-1,16,-5,minecraft:log2:1)
Block(0,16,-5,minecraft:log2:1)
Block(1,16,-5,minecraft:log2:1)
Block(4,16,-5,minecraft:log2:1)
Block(5,16,-5,minecraft:log2:1)
Block(-10,16,-4,minecraft:leaves2:1)
Block(-3,16,-4,minecraft:log2:1)
Block(-2,16,-4,minecraft:log2:1)
Block(-1,16,-4,minecraft:log2:1)
Block(0,16,-4,minecraft:log2:1)
Block(1,16,-4,minecraft:log2:1)
Block(2,16,-4,minecraft:log2:1)
Block(7,16,-4,minecraft:leaves2:1)
Block(-12,16,-3,minecraft:leaves2:1)
Block(-7,16,-3,minecraft:leaves2:1)
Block(-3,16,-3,minecraft:log2:1)
Block(-2,16,-3,minecraft:log2:1)
Block(-1,16,-3,minecraft:log2:1)
Block(0,16,-3,minecraft:log2:1)
Block(1,16,-3,minecraft:log2:1)
Block(2,16,-3,minecraft:log2:1)
Block(5,16,-3,minecraft:leaves2:1)
Block(-3,16,-2,minecraft:log2:1)
Block(-2,16,-2,minecraft:log2:1)
Block(-1,16,-2,minecraft:log2:1)
Block(0,16,-2,minecraft:log2:1)
Block(1,16,-2,minecraft:log2:1)
Block(2,16,-2,minecraft:log2:1)
Block(3,16,-2,minecraft:leaves2:1)
Block(-13,16,-1,minecraft:leaves2:1)
Block(-9,16,-1,minecraft:leaves2:1)
Block(-2,16,-1,minecraft:log2:1)
Block(-1,16,-1,minecraft:log2:1)
Block(0,16,-1,minecraft:log2:1)
Block(1,16,-1,minecraft:log2:1)
Block(2,16,-1,minecraft:log2:1)
Block(3,16,-1,minecraft:log2:1)
Block(-9,16,0,minecraft:log2:1)
Block(-8,16,0,minecraft:log2:1)
Block(-7,16,0,minecraft:log2:1)
Block(-6,16,0,minecraft:log2:1)
Block(-5,16,0,minecraft:log2:1)
Block(0,16,0,minecraft:log2:1)
Block(1,16,0,minecraft:log2:1)
Block(2,16,0,minecraft:log2:1)
Block(3,16,0,minecraft:log2:1)
Block(4,16,0,minecraft:log2:1)
Block(-10,16,1,minecraft:log2:1)
Block(-9,16,1,minecraft:log2:1)
Block(-8,16,1,minecraft:log2:1)
Block(-7,16,1,minecraft:log2:1)
Block(-6,16,1,minecraft:log2:1)
Block(2,16,1,minecraft:log2:1)
Block(3,16,1,minecraft:log2:1)
Block(4,16,1,minecraft:log2:1)
Block(5,16,1,minecraft:log2:1)
Block(-14,16,2,minecraft:leaves2:1)
Block(-9,16,2,minecraft:log2:1)
Block(-8,16,2,minecraft:log2:1)
Block(-7,16,2,minecraft:log2:1)
Block(3,16,2,minecraft:log2:1)
Block(4,16,2,minecraft:log2:1)
Block(5,16,2,minecraft:log2:1)
Block(-8,16,3,minecraft:log2:1)
Block(-6,16,3,minecraft:leaves2:1)
Block(4,16,3,minecraft:log2:1)
Block(-15,16,4,minecraft:leaves2:1)
Block(-3,16,4,minecraft:leaves2:1)
Block(-5,16,5,minecraft:leaves2:1)
Block(-13,16,6,minecraft:leaves2:1)
Block(-11,16,6,minecraft:leaves2:1)
Block(7,16,6,minecraft:leaves2:1)
Block(-7,16,7,minecraft:leaves2:1)
Block(6,16,7,minecraft:leaves2:1)
Block(7,16,7,minecraft:leaves2:1)
Block(-11,16,8,minecraft:leaves2:1)
Block(7,16,8,minecraft:leaves2:1)
Block(8,16,8,minecraft:leaves2:1)
Block(5,17,-12,minecraft:leaves2:1)
Block(3,17,-11,minecraft:leaves2:1)
Block(8,17,-10,minecraft:leaves2:1)
Block(1,17,-9,minecraft:leaves2:1)
Block(4,17,-9,minecraft:leaves2:1)
Block(5,17,-9,minecraft:log2:1)
Block(4,17,-8,minecraft:log2:1)
Block(5,17,-8,minecraft:log2:1)
Block(6,17,-8,minecraft:log2:1)
Block(3,17,-7,minecraft:log2:1)
Block(4,17,-7,minecraft:log2:1)
Block(5,17,-7,minecraft:log2:1)
Block(6,17,-7,minecraft:log2:1)
Block(7,17,-7,minecraft:log2:1)
Block(10,17,-7,minecraft:leaves2:1)
Block(-1,17,-6,minecraft:log2:1)
Block(4,17,-6,minecraft:log2:1)
Block(5,17,-6,minecraft:log2:1)
Block(6,17,-6,minecraft:log2:1)
Block(7,17,-6,minecraft:leaves2:1)
Block(-3,17,-5,minecraft:leaves2:1)
Block(-2,17,-5,minecraft:log2:1)
Block(-1,17,-5,minecraft:log2:1)
Block(0,17,-5,minecraft:log2:1)
Block(5,17,-5,minecraft:log2:1)
Block(9,17,-5,minecraft:leaves2:1)
Block(-10,17,-4,minecraft:leaves2:1)
Block(-3,17,-4,minecraft:log2:1)
Block(-2,17,-4,minecraft:log2:1)
Block(-1,17,-4,minecraft:log2:1)
Block(0,17,-4,minecraft:log2:1)
Block(1,17,-4,minecraft:log2:1)
Block(7,17,-4,minecraft:leaves2:1)
Block(-12,17,-3,minecraft:leaves2:1)
Block(-10,17,-3,minecraft:leaves2:1)
Block(-8,17,-3,minecraft:leaves2:1)
Block(-7,17,-3,minecraft:leaves2:1)
Block(-3,17,-3,minecraft:log2:1)
Block(-2,17,-3,minecraft:log2:1)
Block(-1,17,-3,minecraft:log2:1)
Block(0,17,-3,minecraft:log2:1)
Block(1,17,-3,minecraft:log2:1)
Block(2,17,-3,minecraft:log2:1)
Block(5,17,-3,minecraft:leaves2:1)
Block(-12,17,-2,minecraft:leaves2:1)
Block(-11,17,-2,minecraft:leaves2:1)
Block(-10,17,-2,minecraft:leaves2:1)
Block(-9,17,-2,minecraft:leaves2:1)
Block(-8,17,-2,minecraft:leaves2:1)
Block(-7,17,-2,minecraft:leaves2:1)
Block(-3,17,-2,minecraft:log2:1)
Block(-2,17,-2,minecraft:log2:1)
Block(-1,17,-2,minecraft:log2:1)
Block(0,17,-2,minecraft:log2:1)
Block(1,17,-2,minecraft:log2:1)
Block(2,17,-2,minecraft:log2:1)
Block(3,17,-2,minecraft:leaves2:1)
Block(-13,17,-1,minecraft:leaves2:1)
Block(-12,17,-1,minecraft:leaves2:1)
Block(-11,17,-1,minecraft:leaves2:1)
Block(-10,17,-1,minecraft:leaves2:1)
Block(-8,17,-1,minecraft:leaves2:1)
Block(-6,17,-1,minecraft:leaves2:1)
Block(-2,17,-1,minecraft:log2:1)
Block(-1,17,-1,minecraft:log2:1)
Block(0,17,-1,minecraft:log2:1)
Block(1,17,-1,minecraft:log2:1)
Block(2,17,-1,minecraft:log2:1)
Block(3,17,-1,minecraft:log2:1)
Block(-14,17,0,minecraft:leaves2:1)
Block(-12,17,0,minecraft:leaves2:1)
Block(-9,17,0,minecraft:log2:1)
Block(-8,17,0,minecraft:log2:1)
Block(-7,17,0,minecraft:leaves2:1)
Block(-6,17,0,minecraft:leaves2:1)
Block(-5,17,0,minecraft:leaves2:1)
Block(0,17,0,minecraft:log2:1)
Block(1,17,0,minecraft:log2:1)
Block(2,17,0,minecraft:log2:1)
Block(3,17,0,minecraft:log2:1)
Block(4,17,0,minecraft:log2:1)
Block(-13,17,1,minecraft:leaves2:1)
Block(-11,17,1,minecraft:leaves2:1)
Block(-10,17,1,minecraft:log2:1)
Block(-9,17,1,minecraft:log2:1)
Block(-8,17,1,minecraft:log2:1)
Block(-7,17,1,minecraft:log2:1)
Block(-6,17,1,minecraft:leaves2:1)
Block(1,17,1,minecraft:log2:1)
Block(2,17,1,minecraft:log2:1)
Block(3,17,1,minecraft:log2:1)
Block(4,17,1,minecraft:log2:1)
Block(5,17,1,minecraft:log2:1)
Block(-14,17,2,minecraft:leaves2:1)
Block(-13,17,2,minecraft:leaves2:1)
Block(-11,17,2,minecraft:log2:1)
Block(-10,17,2,minecraft:log2:1)
Block(-9,17,2,minecraft:log2:1)
Block(-8,17,2,minecraft:log2:1)
Block(-7,17,2,minecraft:log2:1)
Block(-5,17,2,minecraft:leaves2:1)
Block(2,17,2,minecraft:log2:1)
Block(3,17,2,minecraft:log2:1)
Block(4,17,2,minecraft:log2:1)
Block(5,17,2,minecraft:log2:1)
Block(-14,17,3,minecraft:leaves2:1)
Block(-13,17,3,minecraft:leaves2:1)
Block(-9,17,3,minecraft:log2:1)
Block(-8,17,3,minecraft:log2:1)
Block(-7,17,3,minecraft:log2:1)
Block(-6,17,3,minecraft:leaves2:1)
Block(-4,17,3,minecraft:leaves2:1)
Block(3,17,3,minecraft:log2:1)
Block(4,17,3,minecraft:log2:1)
Block(5,17,3,minecraft:log2:1)
Block(-15,17,4,minecraft:leaves2:1)
Block(-13,17,4,minecraft:leaves2:1)
Block(-9,17,4,minecraft:log2:1)
Block(-8,17,4,minecraft:leaves2:1)
Block(-6,17,4,minecraft:leaves2:1)
Block(-5,17,4,minecraft:leaves2:1)
Block(-3,17,4,minecraft:leaves2:1)
Block(4,17,4,minecraft:log2:1)
Block(5,17,4,minecraft:log2:1)
Block(6,17,4,minecraft:log2:1)
Block(-14,17,5,minecraft:leaves2:1)
Block(-13,17,5,minecraft:leaves2:1)
Block(-12,17,5,minecraft:leaves2:1)
Block(-9,17,5,minecraft:leaves2:1)
Block(-7,17,5,minecraft:leaves2:1)
Block(-6,17,5,minecraft:leaves2:1)
Block(-5,17,5,minecraft:leaves2:1)
Block(5,17,5,minecraft:log2:1)
Block(-13,17,6,minecraft:leaves2:1)
Block(-11,17,6,minecraft:leaves2:1)
Block(-9,17,6,minecraft:leaves2:1)
Block(-8,17,6,minecraft:leaves2:1)
Block(-6,17,6,minecraft:leaves2:1)
Block(-9,17,7,minecraft:leaves2:1)
Block(-7,17,7,minecraft:leaves2:1)
Block(-12,17,8,minecraft:leaves2:1)
Block(-11,17,8,minecraft:leaves2:1)
Block(-10,17,8,minecraft:leaves2:1)
Block(5,18,-12,minecraft:leaves2:1)
Block(3,18,-11,minecraft:leaves2:1)
Block(8,18,-10,minecraft:leaves2:1)
Block(1,18,-9,minecraft:leaves2:1)
Block(5,18,-9,minecraft:log2:1)
Block(6,18,-9,minecraft:log2:1)
Block(4,18,-8,minecraft:leaves2:1)
Block(5,18,-8,minecraft:log2:1)
Block(6,18,-8,minecraft:log2:1)
Block(7,18,-8,minecraft:log2:1)
Block(4,18,-7,minecraft:log2:1)
Block(5,18,-7,minecraft:log2:1)
Block(6,18,-7,minecraft:log2:1)
Block(7,18,-7,minecraft:log2:1)
Block(8,18,-7,minecraft:log2:1)
Block(9,18,-7,minecraft:leaves2:1)
Block(10,18,-7,minecraft:leaves2:1)
Block(-3,18,-6,minecraft:leaves2:1)
Block(-2,18,-6,minecraft:log2:1)
Block(-1,18,-6,minecraft:log2:1)
Block(5,18,-6,minecraft:log2:1)
Block(6,18,-6,minecraft:log2:1)
Block(8,18,-6,minecraft:leaves2:1)
Block(-3,18,-5,minecraft:log2:1)
Block(-2,18,-5,minecraft:log2:1)
Block(-1,18,-5,minecraft:log2:1)
Block(0,18,-5,minecraft:log2:1)
Block(1,18,-5,minecraft:log2:1)
Block(9,18,-5,minecraft:leaves2:1)
Block(-11,18,-4,minecraft:leaves2:1)
Block(-10,18,-4,minecraft:leaves2:1)
Block(-9,18,-4,minecraft:leaves2:1)
Block(-3,18,-4,minecraft:log2:1)
Block(-2,18,-4,minecraft:log2:1)
Block(-1,18,-4,minecraft:log2:1)
Block(0,18,-4,minecraft:log2:1)
Block(1,18,-4,minecraft:log2:1)
Block(7,18,-4,minecraft:leaves2:1)
Block(-13,18,-3,minecraft:leaves2:1)
Block(-12,18,-3,minecraft:leaves2:1)
Block(-11,18,-3,minecraft:leaves2:1)
Block(-10,18,-3,minecraft:leaves2:1)
Block(-9,18,-3,minecraft:leaves2:1)
Block(-8,18,-3,minecraft:leaves2:1)
Block(-7,18,-3,minecraft:leaves2:1)
Block(-6,18,-3,minecraft:leaves2:1)
Block(-3,18,-3,minecraft:log2:1)
Block(-2,18,-3,minecraft:log2:1)
Block(-1,18,-3,minecraft:log2:1)
Block(0,18,-3,minecraft:log2:1)
Block(1,18,-3,minecraft:log2:1)
Block(5,18,-3,minecraft:leaves2:1)
Block(-14,18,-2,minecraft:leaves2:1)
Block(-13,18,-2,minecraft:leaves2:1)
Block(-12,18,-2,minecraft:leaves2:1)
Block(-11,18,-2,minecraft:leaves2:1)
Block(-10,18,-2,minecraft:leaves2:1)
Block(-9,18,-2,minecraft:leaves2:1)
Block(-8,18,-2,minecraft:leaves2:1)
Block(-7,18,-2,minecraft:leaves2:1)
Block(-6,18,-2,minecraft:leaves2:1)
Block(-5,18,-2,minecraft:leaves2:1)
Block(-3,18,-2,minecraft:log2:1)
Block(-2,18,-2,minecraft:log2:1)
Block(-1,18,-2,minecraft:log2:1)
Block(0,18,-2,minecraft:log2:1)
Block(1,18,-2,minecraft:log2:1)
Block(2,18,-2,minecraft:log2:1)
Block(-14,18,-1,minecraft:leaves2:1)
Block(-13,18,-1,minecraft:leaves2:1)
Block(-12,18,-1,minecraft:leaves2:1)
Block(-11,18,-1,minecraft:leaves2:1)
Block(-10,18,-1,minecraft:leaves2:1)
Block(-9,18,-1,minecraft:leaves2:1)
Block(-8,18,-1,minecraft:leaves2:1)
Block(-7,18,-1,minecraft:leaves2:1)
Block(-6,18,-1,minecraft:leaves2:1)
Block(-5,18,-1,minecraft:leaves2:1)
Block(-1,18,-1,minecraft:log2:1)
Block(0,18,-1,minecraft:log2:1)
Block(1,18,-1,minecraft:log2:1)
Block(2,18,-1,minecraft:log2:1)
Block(3,18,-1,minecraft:leaves2:1)
Block(-15,18,0,minecraft:leaves2:1)
Block(-14,18,0,minecraft:leaves2:1)
Block(-13,18,0,minecraft:leaves2:1)
Block(-11,18,0,minecraft:leaves2:1)
Block(-10,18,0,minecraft:leaves2:1)
Block(-9,18,0,minecraft:leaves2:1)
Block(-8,18,0,minecraft:leaves2:1)
Block(-7,18,0,minecraft:leaves2:1)
Block(-6,18,0,minecraft:leaves2:1)
Block(-5,18,0,minecraft:leaves2:1)
Block(-4,18,0,minecraft:leaves2:1)
Block(1,18,0,minecraft:log2:1)
Block(2,18,0,minecraft:log2:1)
Block(3,18,0,minecraft:log2:1)
Block(-15,18,1,minecraft:leaves2:1)
Block(-14,18,1,minecraft:leaves2:1)
Block(-13,18,1,minecraft:leaves2:1)
Block(-11,18,1,minecraft:leaves2:1)
Block(-10,18,1,minecraft:leaves2:1)
Block(-9,18,1,minecraft:leaves2:1)
Block(-8,18,1,minecraft:leaves2:1)
Block(-7,18,1,minecraft:leaves2:1)
Block(-6,18,1,minecraft:leaves2:1)
Block(-5,18,1,minecraft:leaves2:1)
Block(-4,18,1,minecraft:leaves2:1)
Block(2,18,1,minecraft:log2:1)
Block(3,18,1,minecraft:log2:1)
Block(4,18,1,minecraft:log2:1)
Block(-15,18,2,minecraft:leaves2:1)
Block(-14,18,2,minecraft:leaves2:1)
Block(-13,18,2,minecraft:leaves2:1)
Block(-12,18,2,minecraft:log2:1)
Block(-11,18,2,minecraft:leaves2:1)
Block(-10,18,2,minecraft:leaves2:1)
Block(-9,18,2,minecraft:leaves2:1)
Block(-8,18,2,minecraft:leaves2:1)
Block(-7,18,2,minecraft:leaves2:1)
Block(-6,18,2,minecraft:leaves2:1)
Block(-5,18,2,minecraft:leaves2:1)
Block(-4,18,2,minecraft:leaves2:1)
Block(-3,18,2,minecraft:leaves2:1)
Block(3,18,2,minecraft:log2:1)
Block(4,18,2,minecraft:log2:1)
Block(5,18,2,minecraft:log2:1)
Block(6,18,2,minecraft:log2:1)
Block(-15,18,3,minecraft:leaves2:1)
Block(-14,18,3,minecraft:leaves2:1)
Block(-13,18,3,minecraft:leaves2:1)
Block(-12,18,3,minecraft:leaves2:1)
Block(-11,18,3,minecraft:leaves2:1)
Block(-10,18,3,minecraft:leaves2:1)
Block(-9,18,3,minecraft:leaves2:1)
Block(-8,18,3,minecraft:leaves2:1)
Block(-7,18,3,minecraft:leaves2:1)
Block(-6,18,3,minecraft:leaves2:1)
Block(-5,18,3,minecraft:leaves2:1)
Block(-4,18,3,minecraft:leaves2:1)
Block(-3,18,3,minecraft:leaves2:1)
Block(3,18,3,minecraft:log2:1)
Block(4,18,3,minecraft:log2:1)
Block(5,18,3,minecraft:log2:1)
Block(6,18,3,minecraft:log2:1)
Block(7,18,3,minecraft:log2:1)
Block(-15,18,4,minecraft:leaves2:1)
Block(-14,18,4,minecraft:leaves2:1)
Block(-13,18,4,minecraft:leaves2:1)
Block(-12,18,4,minecraft:leaves2:1)
Block(-11,18,4,minecraft:leaves2:1)
Block(-10,18,4,minecraft:log2:1)
Block(-9,18,4,minecraft:leaves2:1)
Block(-8,18,4,minecraft:leaves2:1)
Block(-7,18,4,minecraft:leaves2:1)
Block(-6,18,4,minecraft:leaves2:1)
Block(-5,18,4,minecraft:leaves2:1)
Block(-4,18,4,minecraft:leaves2:1)
Block(-3,18,4,minecraft:leaves2:1)
Block(3,18,4,minecraft:log2:1)
Block(4,18,4,minecraft:log2:1)
Block(5,18,4,minecraft:log2:1)
Block(6,18,4,minecraft:log2:1)
Block(7,18,4,minecraft:log2:1)
Block(-14,18,5,minecraft:leaves2:1)
Block(-13,18,5,minecraft:leaves2:1)
Block(-12,18,5,minecraft:leaves2:1)
Block(-11,18,5,minecraft:leaves2:1)
Block(-10,18,5,minecraft:log2:1)
Block(-9,18,5,minecraft:leaves2:1)
Block(-8,18,5,minecraft:leaves2:1)
Block(-7,18,5,minecraft:leaves2:1)
Block(-6,18,5,minecraft:leaves2:1)
Block(-5,18,5,minecraft:leaves2:1)
Block(-4,18,5,minecraft:leaves2:1)
Block(4,18,5,minecraft:log2:1)
Block(5,18,5,minecraft:log2:1)
Block(6,18,5,minecraft:log2:1)
Block(-14,18,6,minecraft:leaves2:1)
Block(-13,18,6,minecraft:leaves2:1)
Block(-12,18,6,minecraft:leaves2:1)
Block(-11,18,6,minecraft:leaves2:1)
Block(-10,18,6,minecraft:log2:1)
Block(-9,18,6,minecraft:leaves2:1)
Block(-8,18,6,minecraft:leaves2:1)
Block(-7,18,6,minecraft:leaves2:1)
Block(-6,18,6,minecraft:leaves2:1)
Block(-5,18,6,minecraft:leaves2:1)
Block(-4,18,6,minecraft:leaves2:1)
Block(12,18,6,minecraft:leaves2:1)
Block(-13,18,7,minecraft:leaves2:1)
Block(-12,18,7,minecraft:leaves2:1)
Block(-11,18,7,minecraft:leaves2:1)
Block(-10,18,7,minecraft:leaves2:1)
Block(-9,18,7,minecraft:leaves2:1)
Block(-8,18,7,minecraft:leaves2:1)
Block(-7,18,7,minecraft:leaves2:1)
Block(-6,18,7,minecraft:leaves2:1)
Block(-5,18,7,minecraft:leaves2:1)
Block(7,18,7,minecraft:leaves2:1)
Block(8,18,7,minecraft:leaves2:1)
Block(-11,18,8,minecraft:leaves2:1)
Block(-10,18,8,minecraft:leaves2:1)
Block(-9,18,8,minecraft:leaves2:1)
Block(-8,18,8,minecraft:leaves2:1)
Block(4,18,11,minecraft:leaves2:1)
Block(4,19,-12,minecraft:leaves2:1)
Block(5,19,-12,minecraft:leaves2:1)
Block(3,19,-11,minecraft:leaves2:1)
Block(4,19,-11,minecraft:leaves2:1)
Block(5,19,-11,minecraft:leaves2:1)
Block(6,19,-11,minecraft:leaves2:1)
Block(2,19,-10,minecraft:leaves2:1)
Block(3,19,-10,minecraft:leaves2:1)
Block(8,19,-10,minecraft:leaves2:1)
Block(1,19,-9,minecraft:leaves2:1)
Block(2,19,-9,minecraft:leaves2:1)
Block(5,19,-9,minecraft:log2:1)
Block(6,19,-9,minecraft:log2:1)
Block(7,19,-9,minecraft:log2:1)
Block(8,19,-9,minecraft:leaves2:1)
Block(9,19,-9,minecraft:leaves2:1)
Block(1,19,-8,minecraft:leaves2:1)
Block(4,19,-8,minecraft:leaves2:1)
Block(5,19,-8,minecraft:log2:1)
Block(6,19,-8,minecraft:log2:1)
Block(7,19,-8,minecraft:log2:1)
Block(8,19,-8,minecraft:log2:1)
Block(-2,19,-7,minecraft:leaves2:1)
Block(1,19,-7,minecraft:leaves2:1)
Block(2,19,-7,minecraft:leaves2:1)
Block(4,19,-7,minecraft:log2:1)
Block(5,19,-7,minecraft:log2:1)
Block(6,19,-7,minecraft:log2:1)
Block(7,19,-7,minecraft:log2:1)
Block(8,19,-7,minecraft:log2:1)
Block(9,19,-7,minecraft:leaves2:1)
Block(10,19,-7,minecraft:leaves2:1)
Block(-2,19,-6,minecraft:log2:1)
Block(-1,19,-6,minecraft:log2:1)
Block(0,19,-6,minecraft:log2:1)
Block(2,19,-6,minecraft:leaves2:1)
Block(5,19,-6,minecraft:log2:1)
Block(6,19,-6,minecraft:log2:1)
Block(7,19,-6,minecraft:log2:1)
Block(10,19,-6,minecraft:leaves2:1)
Block(-3,19,-5,minecraft:log2:1)
Block(-2,19,-5,minecraft:log2:1)
Block(-1,19,-5,minecraft:log2:1)
Block(0,19,-5,minecraft:log2:1)
Block(1,19,-5,minecraft:log2:1)
Block(2,19,-5,minecraft:leaves2:1)
Block(9,19,-5,minecraft:leaves2:1)
Block(-11,19,-4,minecraft:leaves2:1)
Block(-4,19,-4,minecraft:log2:1)
Block(-3,19,-4,minecraft:log2:1)
Block(-2,19,-4,minecraft:log2:1)
Block(-1,19,-4,minecraft:log2:1)
Block(0,19,-4,minecraft:log2:1)
Block(1,19,-4,minecraft:log2:1)
Block(3,19,-4,minecraft:leaves2:1)
Block(6,19,-4,minecraft:leaves2:1)
Block(7,19,-4,minecraft:leaves2:1)
Block(8,19,-4,minecraft:leaves2:1)
Block(-12,19,-3,minecraft:leaves2:1)
Block(-11,19,-3,minecraft:leaves2:1)
Block(-10,19,-3,minecraft:leaves2:1)
Block(-9,19,-3,minecraft:leaves2:1)
Block(-8,19,-3,minecraft:leaves2:1)
Block(-3,19,-3,minecraft:log2:1)
Block(-2,19,-3,minecraft:log2:1)
Block(-1,19,-3,minecraft:log2:1)
Block(0,19,-3,minecraft:log2:1)
Block(1,19,-3,minecraft:log2:1)
Block(5,19,-3,minecraft:leaves2:1)
Block(7,19,-3,minecraft:leaves2:1)
Block(-13,19,-2,minecraft:leaves2:1)
Block(-12,19,-2,minecraft:leaves2:1)
Block(-11,19,-2,minecraft:leaves2:1)
Block(-10,19,-2,minecraft:leaves2:1)
Block(-9,19,-2,minecraft:leaves2:1)
Block(-8,19,-2,minecraft:leaves2:1)
Block(-7,19,-2,minecraft:leaves2:1)
Block(-6,19,-2,minecraft:leaves2:1)
Block(-5,19,-2,minecraft:leaves2:1)
Block(-2,19,-2,minecraft:log2:1)
Block(-1,19,-2,minecraft:log2:1)
Block(0,19,-2,minecraft:log2:1)
Block(1,19,-2,minecraft:log2:1)
Block(-13,19,-1,minecraft:leaves2:1)
Block(-12,19,-1,minecraft:leaves2:1)
Block(-11,19,-1,minecraft:leaves2:1)
Block(-10,19,-1,minecraft:leaves2:1)
Block(-9,19,-1,minecraft:leaves2:1)
Block(-8,19,-1,minecraft:leaves2:1)
Block(-7,19,-1,minecraft:leaves2:1)
Block(-6,19,-1,minecraft:leaves2:1)
Block(-5,19,-1,minecraft:leaves2:1)
Block(-14,19,0,minecraft:leaves2:1)
Block(-13,19,0,minecraft:leaves2:1)
Block(-12,19,0,minecraft:leaves2:1)
Block(-11,19,0,minecraft:leaves2:1)
Block(-10,19,0,minecraft:leaves2:1)
Block(-9,19,0,minecraft:leaves2:1)
Block(-8,19,0,minecraft:leaves2:1)
Block(-7,19,0,minecraft:leaves2:1)
Block(-6,19,0,minecraft:leaves2:1)
Block(-5,19,0,minecraft:leaves2:1)
Block(2,19,0,minecraft:leaves2:1)
Block(-14,19,1,minecraft:leaves2:1)
Block(-13,19,1,minecraft:leaves2:1)
Block(-12,19,1,minecraft:leaves2:1)
Block(-11,19,1,minecraft:leaves2:1)
Block(-10,19,1,minecraft:leaves2:1)
Block(-9,19,1,minecraft:leaves2:1)
Block(-8,19,1,minecraft:leaves2:1)
Block(-7,19,1,minecraft:leaves2:1)
Block(2,19,1,minecraft:leaves2:1)
Block(3,19,1,minecraft:log2:1)
Block(-15,19,2,minecraft:leaves2:1)
Block(-14,19,2,minecraft:leaves2:1)
Block(-13,19,2,minecraft:leaves2:1)
Block(-12,19,2,minecraft:leaves2:1)
Block(-10,19,2,minecraft:leaves2:1)
Block(-9,19,2,minecraft:leaves2:1)
Block(-8,19,2,minecraft:leaves2:1)
Block(-5,19,2,minecraft:leaves2:1)
Block(3,19,2,minecraft:log2:1)
Block(4,19,2,minecraft:log2:1)
Block(5,19,2,minecraft:log2:1)
Block(-15,19,3,minecraft:leaves2:1)
Block(-14,19,3,minecraft:leaves2:1)
Block(-13,19,3,minecraft:leaves2:1)
Block(-12,19,3,minecraft:leaves2:1)
Block(-11,19,3,minecraft:leaves2:1)
Block(-10,19,3,minecraft:leaves2:1)
Block(-9,19,3,minecraft:leaves2:1)
Block(-8,19,3,minecraft:leaves2:1)
Block(-7,19,3,minecraft:leaves2:1)
Block(-5,19,3,minecraft:leaves2:1)
Block(-4,19,3,minecraft:leaves2:1)
Block(3,19,3,minecraft:log2:1)
Block(4,19,3,minecraft:log2:1)
Block(5,19,3,minecraft:log2:1)
Block(6,19,3,minecraft:log2:1)
Block(7,19,3,minecraft:log2:1)
Block(-15,19,4,minecraft:leaves2:1)
Block(-14,19,4,minecraft:leaves2:1)
Block(-13,19,4,minecraft:leaves2:1)
Block(-12,19,4,minecraft:leaves2:1)
Block(-11,19,4,minecraft:leaves2:1)
Block(-10,19,4,minecraft:leaves2:1)
Block(-9,19,4,minecraft:leaves2:1)
Block(-8,19,4,minecraft:leaves2:1)
Block(-7,19,4,minecraft:leaves2:1)
Block(-6,19,4,minecraft:leaves2:1)
Block(-5,19,4,minecraft:leaves2:1)
Block(-4,19,4,minecraft:leaves2:1)
Block(4,19,4,minecraft:log2:1)
Block(5,19,4,minecraft:log2:1)
Block(6,19,4,minecraft:log2:1)
Block(7,19,4,minecraft:log2:1)
Block(10,19,4,minecraft:leaves2:1)
Block(-14,19,5,minecraft:leaves2:1)
Block(-13,19,5,minecraft:leaves2:1)
Block(-12,19,5,minecraft:leaves2:1)
Block(-11,19,5,minecraft:leaves2:1)
Block(-10,19,5,minecraft:leaves2:1)
Block(-9,19,5,minecraft:leaves2:1)
Block(-8,19,5,minecraft:leaves2:1)
Block(-7,19,5,minecraft:leaves2:1)
Block(-6,19,5,minecraft:leaves2:1)
Block(-5,19,5,minecraft:leaves2:1)
Block(5,19,5,minecraft:log2:1)
Block(6,19,5,minecraft:log2:1)
Block(7,19,5,minecraft:log2:1)
Block(-13,19,6,minecraft:leaves2:1)
Block(-12,19,6,minecraft:leaves2:1)
Block(-11,19,6,minecraft:leaves2:1)
Block(-10,19,6,minecraft:leaves2:1)
Block(-9,19,6,minecraft:leaves2:1)
Block(-8,19,6,minecraft:leaves2:1)
Block(-7,19,6,minecraft:leaves2:1)
Block(-6,19,6,minecraft:leaves2:1)
Block(6,19,6,minecraft:log2:1)
Block(7,19,6,minecraft:log2:1)
Block(8,19,6,minecraft:log2:1)
Block(12,19,6,minecraft:leaves2:1)
Block(-12,19,7,minecraft:leaves2:1)
Block(-11,19,7,minecraft:leaves2:1)
Block(-10,19,7,minecraft:leaves2:1)
Block(-9,19,7,minecraft:leaves2:1)
Block(-8,19,7,minecraft:leaves2:1)
Block(-7,19,7,minecraft:leaves2:1)
Block(6,19,7,minecraft:leaves2:1)
Block(7,19,7,minecraft:log2:1)
Block(8,19,7,minecraft:log2:1)
Block(9,19,7,minecraft:leaves2:1)
Block(-10,19,8,minecraft:leaves2:1)
Block(-9,19,8,minecraft:leaves2:1)
Block(8,19,8,minecraft:log2:1)
Block(14,19,10,minecraft:leaves2:1)
Block(4,19,11,minecraft:leaves2:1)
Block(9,19,13,minecraft:leaves2:1)
Block(3,20,-12,minecraft:leaves2:1)
Block(4,20,-12,minecraft:leaves2:1)
Block(5,20,-12,minecraft:leaves2:1)
Block(6,20,-12,minecraft:leaves2:1)
Block(3,20,-11,minecraft:leaves2:1)
Block(5,20,-11,minecraft:leaves2:1)
Block(6,20,-11,minecraft:leaves2:1)
Block(7,20,-11,minecraft:leaves2:1)
Block(1,20,-10,minecraft:leaves2:1)
Block(2,20,-10,minecraft:leaves2:1)
Block(3,20,-10,minecraft:leaves2:1)
Block(4,20,-10,minecraft:leaves2:1)
Block(5,20,-10,minecraft:leaves2:1)
Block(6,20,-10,minecraft:leaves2:1)
Block(7,20,-10,minecraft:leaves2:1)
Block(8,20,-10,minecraft:leaves2:1)
Block(9,20,-10,minecraft:leaves2:1)
Block(1,20,-9,minecraft:leaves2:1)
Block(2,20,-9,minecraft:leaves2:1)
Block(3,20,-9,minecraft:leaves2:1)
Block(4,20,-9,minecraft:leaves2:1)
Block(5,20,-9,minecraft:leaves2:1)
Block(6,20,-9,minecraft:leaves2:1)
Block(7,20,-9,minecraft:leaves2:1)
Block(8,20,-9,minecraft:leaves2:1)
Block(9,20,-9,minecraft:leaves2:1)
Block(10,20,-9,minecraft:leaves2:1)
Block(0,20,-8,minecraft:leaves2:1)
Block(1,20,-8,minecraft:leaves2:1)
Block(2,20,-8,minecraft:leaves2:1)
Block(4,20,-8,minecraft:leaves2:1)
Block(5,20,-8,minecraft:log2:1)
Block(6,20,-8,minecraft:log2:1)
Block(7,20,-8,minecraft:leaves2:1)
Block(8,20,-8,minecraft:leaves2:1)
Block(9,20,-8,minecraft:leaves2:1)
Block(10,20,-8,minecraft:leaves2:1)
Block(-2,20,-7,minecraft:leaves2:1)
Block(1,20,-7,minecraft:leaves2:1)
Block(2,20,-7,minecraft:leaves2:1)
Block(3,20,-7,minecraft:leaves2:1)
Block(4,20,-7,minecraft:leaves2:1)
Block(5,20,-7,minecraft:leaves2:1)
Block(6,20,-7,minecraft:log2:1)
Block(7,20,-7,minecraft:leaves2:1)
Block(8,20,-7,minecraft:leaves2:1)
Block(9,20,-7,minecraft:leaves2:1)
Block(10,20,-7,minecraft:leaves2:1)
Block(-3,20,-6,minecraft:log2:1)
Block(-2,20,-6,minecraft:log2:1)
Block(-1,20,-6,minecraft:log2:1)
Block(0,20,-6,minecraft:log2:1)
Block(1,20,-6,minecraft:leaves2:1)
Block(2,20,-6,minecraft:leaves2:1)
Block(3,20,-6,minecraft:leaves2:1)
Block(4,20,-6,minecraft:leaves2:1)
Block(5,20,-6,minecraft:leaves2:1)
Block(6,20,-6,minecraft:leaves2:1)
Block(7,20,-6,minecraft:leaves2:1)
Block(8,20,-6,minecraft:leaves2:1)
Block(9,20,-6,minecraft:leaves2:1)
Block(10,20,-6,minecraft:leaves2:1)
Block(-3,20,-5,minecraft:log2:1)
Block(-2,20,-5,minecraft:log2:1)
Block(-1,20,-5,minecraft:log2:1)
Block(0,20,-5,minecraft:log2:1)
Block(1,20,-5,minecraft:leaves2:1)
Block(2,20,-5,minecraft:leaves2:1)
Block(3,20,-5,minecraft:leaves2:1)
Block(4,20,-5,minecraft:leaves2:1)
Block(5,20,-5,minecraft:leaves2:1)
Block(6,20,-5,minecraft:leaves2:1)
Block(7,20,-5,minecraft:leaves2:1)
Block(8,20,-5,minecraft:leaves2:1)
Block(9,20,-5,minecraft:leaves2:1)
Block(-4,20,-4,minecraft:log2:1)
Block(-3,20,-4,minecraft:log2:1)
Block(-2,20,-4,minecraft:log2:1)
Block(-1,20,-4,minecraft:log2:1)
Block(0,20,-4,minecraft:log2:1)
Block(1,20,-4,minecraft:log2:1)
Block(2,20,-4,minecraft:leaves2:1)
Block(3,20,-4,minecraft:leaves2:1)
Block(4,20,-4,minecraft:leaves2:1)
Block(5,20,-4,minecraft:leaves2:1)
Block(6,20,-4,minecraft:leaves2:1)
Block(7,20,-4,minecraft:leaves2:1)
Block(8,20,-4,minecraft:leaves2:1)
Block(-11,20,-3,minecraft:leaves2:1)
Block(-10,20,-3,minecraft:leaves2:1)
Block(-9,20,-3,minecraft:leaves2:1)
Block(-3,20,-3,minecraft:log2:1)
Block(-2,20,-3,minecraft:log2:1)
Block(-1,20,-3,minecraft:log2:1)
Block(0,20,-3,minecraft:log2:1)
Block(1,20,-3,minecraft:log2:1)
Block(3,20,-3,minecraft:leaves2:1)
Block(4,20,-3,minecraft:leaves2:1)
Block(5,20,-3,minecraft:leaves2:1)
Block(6,20,-3,minecraft:leaves2:1)
Block(7,20,-3,minecraft:leaves2:1)
Block(8,20,-3,minecraft:leaves2:1)
Block(-13,20,-2,minecraft:leaves2:1)
Block(-12,20,-2,minecraft:leaves2:1)
Block(-10,20,-2,minecraft:leaves2:1)
Block(-9,20,-2,minecraft:leaves2:1)
Block(-8,20,-2,minecraft:leaves2:1)
Block(-6,20,-2,minecraft:leaves2:1)
Block(-2,20,-2,minecraft:log2:1)
Block(-1,20,-2,minecraft:log2:1)
Block(0,20,-2,minecraft:log2:1)
Block(-12,20,-1,minecraft:leaves2:1)
Block(-11,20,-1,minecraft:leaves2:1)
Block(-10,20,-1,minecraft:leaves2:1)
Block(-9,20,-1,minecraft:leaves2:1)
Block(-8,20,-1,minecraft:leaves2:1)
Block(-7,20,-1,minecraft:leaves2:1)
Block(-6,20,-1,minecraft:leaves2:1)
Block(-5,20,-1,minecraft:leaves2:1)
Block(-13,20,0,minecraft:leaves2:1)
Block(-12,20,0,minecraft:leaves2:1)
Block(-11,20,0,minecraft:leaves2:1)
Block(-10,20,0,minecraft:leaves2:1)
Block(-9,20,0,minecraft:leaves2:1)
Block(-8,20,0,minecraft:leaves2:1)
Block(-7,20,0,minecraft:leaves2:1)
Block(-6,20,0,minecraft:leaves2:1)
Block(-14,20,1,minecraft:leaves2:1)
Block(-13,20,1,minecraft:leaves2:1)
Block(-12,20,1,minecraft:leaves2:1)
Block(-11,20,1,minecraft:leaves2:1)
Block(-10,20,1,minecraft:leaves2:1)
Block(-9,20,1,minecraft:leaves2:1)
Block(-8,20,1,minecraft:leaves2:1)
Block(-7,20,1,minecraft:leaves2:1)
Block(-5,20,1,minecraft:leaves2:1)
Block(-14,20,2,minecraft:leaves2:1)
Block(-13,20,2,minecraft:leaves2:1)
Block(-12,20,2,minecraft:leaves2:1)
Block(-11,20,2,minecraft:leaves2:1)
Block(-10,20,2,minecraft:leaves2:1)
Block(-9,20,2,minecraft:leaves2:1)
Block(-8,20,2,minecraft:leaves2:1)
Block(-7,20,2,minecraft:leaves2:1)
Block(-6,20,2,minecraft:leaves2:1)
Block(-5,20,2,minecraft:leaves2:1)
Block(3,20,2,minecraft:leaves2:1)
Block(4,20,2,minecraft:leaves2:1)
Block(-15,20,3,minecraft:leaves2:1)
Block(-14,20,3,minecraft:leaves2:1)
Block(-13,20,3,minecraft:leaves2:1)
Block(-12,20,3,minecraft:leaves2:1)
Block(-11,20,3,minecraft:leaves2:1)
Block(-10,20,3,minecraft:leaves2:1)
Block(-9,20,3,minecraft:leaves2:1)
Block(-8,20,3,minecraft:leaves2:1)
Block(-7,20,3,minecraft:leaves2:1)
Block(-6,20,3,minecraft:leaves2:1)
Block(4,20,3,minecraft:log2:1)
Block(5,20,3,minecraft:log2:1)
Block(6,20,3,minecraft:log2:1)
Block(-14,20,4,minecraft:leaves2:1)
Block(-13,20,4,minecraft:leaves2:1)
Block(-12,20,4,minecraft:leaves2:1)
Block(-11,20,4,minecraft:leaves2:1)
Block(-10,20,4,minecraft:leaves2:1)
Block(-9,20,4,minecraft:leaves2:1)
Block(-8,20,4,minecraft:leaves2:1)
Block(-7,20,4,minecraft:leaves2:1)
Block(-6,20,4,minecraft:leaves2:1)
Block(-5,20,4,minecraft:leaves2:1)
Block(5,20,4,minecraft:log2:1)
Block(6,20,4,minecraft:log2:1)
Block(7,20,4,minecraft:log2:1)
Block(10,20,4,minecraft:leaves2:1)
Block(-13,20,5,minecraft:leaves2:1)
Block(-12,20,5,minecraft:leaves2:1)
Block(-11,20,5,minecraft:leaves2:1)
Block(-10,20,5,minecraft:leaves2:1)
Block(-9,20,5,minecraft:leaves2:1)
Block(-8,20,5,minecraft:leaves2:1)
Block(-6,20,5,minecraft:leaves2:1)
Block(5,20,5,minecraft:log2:1)
Block(6,20,5,minecraft:log2:1)
Block(7,20,5,minecraft:log2:1)
Block(8,20,5,minecraft:log2:1)
Block(-12,20,6,minecraft:leaves2:1)
Block(-11,20,6,minecraft:leaves2:1)
Block(-10,20,6,minecraft:leaves2:1)
Block(-9,20,6,minecraft:leaves2:1)
Block(-8,20,6,minecraft:leaves2:1)
Block(-7,20,6,minecraft:leaves2:1)
Block(5,20,6,minecraft:log2:1)
Block(6,20,6,minecraft:log2:1)
Block(7,20,6,minecraft:log2:1)
Block(8,20,6,minecraft:log2:1)
Block(9,20,6,minecraft:log2:1)
Block(12,20,6,minecraft:leaves2:1)
Block(-11,20,7,minecraft:leaves2:1)
Block(-10,20,7,minecraft:leaves2:1)
Block(-8,20,7,minecraft:leaves2:1)
Block(5,20,7,minecraft:leaves2:1)
Block(6,20,7,minecraft:log2:1)
Block(7,20,7,minecraft:log2:1)
Block(8,20,7,minecraft:log2:1)
Block(9,20,7,minecraft:log2:1)
Block(3,20,8,minecraft:leaves2:1)
Block(7,20,8,minecraft:log2:1)
Block(8,20,8,minecraft:log2:1)
Block(9,20,8,minecraft:log2:1)
Block(10,20,8,minecraft:leaves2:1)
Block(14,20,10,minecraft:leaves2:1)
Block(4,20,11,minecraft:leaves2:1)
Block(6,20,13,minecraft:leaves2:1)
Block(9,20,13,minecraft:leaves2:1)
Block(5,21,-12,minecraft:leaves2:1)
Block(3,21,-11,minecraft:leaves2:1)
Block(4,21,-11,minecraft:leaves2:1)
Block(5,21,-11,minecraft:leaves2:1)
Block(7,21,-11,minecraft:leaves2:1)
Block(2,21,-10,minecraft:leaves2:1)
Block(3,21,-10,minecraft:leaves2:1)
Block(4,21,-10,minecraft:leaves2:1)
Block(5,21,-10,minecraft:leaves2:1)
Block(6,21,-10,minecraft:leaves2:1)
Block(7,21,-10,minecraft:leaves2:1)
Block(8,21,-10,minecraft:leaves2:1)
Block(1,21,-9,minecraft:leaves2:1)
Block(2,21,-9,minecraft:leaves2:1)
Block(3,21,-9,minecraft:leaves2:1)
Block(4,21,-9,minecraft:leaves2:1)
Block(5,21,-9,minecraft:leaves2:1)
Block(6,21,-9,minecraft:leaves2:1)
Block(7,21,-9,minecraft:leaves2:1)
Block(8,21,-9,minecraft:leaves2:1)
Block(9,21,-9,minecraft:leaves2:1)
Block(2,21,-8,minecraft:leaves2:1)
Block(3,21,-8,minecraft:leaves2:1)
Block(4,21,-8,minecraft:leaves2:1)
Block(5,21,-8,minecraft:leaves2:1)
Block(6,21,-8,minecraft:leaves2:1)
Block(7,21,-8,minecraft:leaves2:1)
Block(8,21,-8,minecraft:leaves2:1)
Block(9,21,-8,minecraft:leaves2:1)
Block(10,21,-8,minecraft:leaves2:1)
Block(-1,21,-7,minecraft:leaves2:1)
Block(2,21,-7,minecraft:leaves2:1)
Block(3,21,-7,minecraft:leaves2:1)
Block(4,21,-7,minecraft:leaves2:1)
Block(5,21,-7,minecraft:leaves2:1)
Block(6,21,-7,minecraft:leaves2:1)
Block(7,21,-7,minecraft:leaves2:1)
Block(8,21,-7,minecraft:leaves2:1)
Block(9,21,-7,minecraft:leaves2:1)
Block(10,21,-7,minecraft:leaves2:1)
Block(-3,21,-6,minecraft:log2:1)
Block(-2,21,-6,minecraft:log2:1)
Block(-1,21,-6,minecraft:log2:1)
Block(3,21,-6,minecraft:leaves2:1)
Block(4,21,-6,minecraft:leaves2:1)
Block(5,21,-6,minecraft:leaves2:1)
Block(6,21,-6,minecraft:leaves2:1)
Block(7,21,-6,minecraft:leaves2:1)
Block(9,21,-6,minecraft:leaves2:1)
Block(-4,21,-5,minecraft:log2:1)
Block(-3,21,-5,minecraft:log2:1)
Block(-2,21,-5,minecraft:log2:1)
Block(-1,21,-5,minecraft:log2:1)
Block(0,21,-5,minecraft:log2:1)
Block(2,21,-5,minecraft:leaves2:1)
Block(3,21,-5,minecraft:leaves2:1)
Block(4,21,-5,minecraft:leaves2:1)
Block(5,21,-5,minecraft:leaves2:1)
Block(6,21,-5,minecraft:leaves2:1)
Block(7,21,-5,minecraft:leaves2:1)
Block(8,21,-5,minecraft:leaves2:1)
Block(-4,21,-4,minecraft:log2:1)
Block(-3,21,-4,minecraft:log2:1)
Block(-2,21,-4,minecraft:log2:1)
Block(-1,21,-4,minecraft:log2:1)
Block(0,21,-4,minecraft:log2:1)
Block(3,21,-4,minecraft:leaves2:1)
Block(4,21,-4,minecraft:leaves2:1)
Block(5,21,-4,minecraft:leaves2:1)
Block(6,21,-4,minecraft:leaves2:1)
Block(7,21,-4,minecraft:leaves2:1)
Block(8,21,-4,minecraft:leaves2:1)
Block(-3,21,-3,minecraft:log2:1)
Block(-2,21,-3,minecraft:log2:1)
Block(-1,21,-3,minecraft:log2:1)
Block(0,21,-3,minecraft:log2:1)
Block(5,21,-3,minecraft:leaves2:1)
Block(6,21,-3,minecraft:leaves2:1)
Block(-11,21,-2,minecraft:leaves2:1)
Block(-10,21,-2,minecraft:leaves2:1)
Block(-9,21,-2,minecraft:leaves2:1)
Block(-3,21,-2,minecraft:log2:1)
Block(-2,21,-2,minecraft:log2:1)
Block(-1,21,-2,minecraft:log2:1)
Block(-10,21,-1,minecraft:leaves2:1)
Block(-9,21,-1,minecraft:leaves2:1)
Block(-8,21,-1,minecraft:leaves2:1)
Block(-12,21,0,minecraft:leaves2:1)
Block(-11,21,0,minecraft:leaves2:1)
Block(-8,21,0,minecraft:leaves2:1)
Block(-7,21,0,minecraft:leaves2:1)
Block(-12,21,1,minecraft:leaves2:1)
Block(-11,21,1,minecraft:leaves2:1)
Block(-10,21,1,minecraft:leaves2:1)
Block(-9,21,1,minecraft:leaves2:1)
Block(-7,21,1,minecraft:leaves2:1)
Block(-6,21,1,minecraft:leaves2:1)
Block(-13,21,2,minecraft:leaves2:1)
Block(-12,21,2,minecraft:leaves2:1)
Block(-10,21,2,minecraft:leaves2:1)
Block(-9,21,2,minecraft:leaves2:1)
Block(-8,21,2,minecraft:leaves2:1)
Block(-7,21,2,minecraft:leaves2:1)
Block(-6,21,2,minecraft:leaves2:1)
Block(-13,21,3,minecraft:leaves2:1)
Block(-11,21,3,minecraft:leaves2:1)
Block(-9,21,3,minecraft:leaves2:1)
Block(-7,21,3,minecraft:leaves2:1)
Block(-6,21,3,minecraft:leaves2:1)
Block(5,21,3,minecraft:leaves2:1)
Block(-13,21,4,minecraft:leaves2:1)
Block(-12,21,4,minecraft:leaves2:1)
Block(-11,21,4,minecraft:leaves2:1)
Block(-9,21,4,minecraft:leaves2:1)
Block(-8,21,4,minecraft:leaves2:1)
Block(-7,21,4,minecraft:leaves2:1)
Block(6,21,4,minecraft:log2:1)
Block(10,21,4,minecraft:leaves2:1)
Block(-12,21,5,minecraft:leaves2:1)
Block(-11,21,5,minecraft:leaves2:1)
Block(-10,21,5,minecraft:leaves2:1)
Block(-9,21,5,minecraft:leaves2:1)
Block(-8,21,5,minecraft:leaves2:1)
Block(6,21,5,minecraft:log2:1)
Block(7,21,5,minecraft:log2:1)
Block(-10,21,6,minecraft:leaves2:1)
Block(-9,21,6,minecraft:leaves2:1)
Block(6,21,6,minecraft:log2:1)
Block(7,21,6,minecraft:log2:1)
Block(8,21,6,minecraft:log2:1)
Block(12,21,6,minecraft:leaves2:1)
Block(5,21,7,minecraft:leaves2:1)
Block(6,21,7,minecraft:log2:1)
Block(7,21,7,minecraft:log2:1)
Block(8,21,7,minecraft:log2:1)
Block(9,21,7,minecraft:log2:1)
Block(3,21,8,minecraft:leaves2:1)
Block(7,21,8,minecraft:log2:1)
Block(8,21,8,minecraft:log2:1)
Block(9,21,8,minecraft:log2:1)
Block(10,21,8,minecraft:log2:1)
Block(9,21,9,minecraft:log2:1)
Block(10,21,9,minecraft:leaves2:1)
Block(14,21,10,minecraft:leaves2:1)
Block(4,21,11,minecraft:leaves2:1)
Block(11,21,12,minecraft:leaves2:1)
Block(6,21,13,minecraft:leaves2:1)
Block(9,21,13,minecraft:leaves2:1)
Block(5,22,-11,minecraft:leaves2:1)
Block(6,22,-11,minecraft:leaves2:1)
Block(3,22,-10,minecraft:leaves2:1)
Block(5,22,-10,minecraft:leaves2:1)
Block(6,22,-10,minecraft:leaves2:1)
Block(7,22,-10,minecraft:leaves2:1)
Block(3,22,-9,minecraft:leaves2:1)
Block(4,22,-9,minecraft:leaves2:1)
Block(6,22,-9,minecraft:leaves2:1)
Block(7,22,-9,minecraft:leaves2:1)
Block(8,22,-9,minecraft:leaves2:1)
Block(2,22,-8,minecraft:leaves2:1)
Block(3,22,-8,minecraft:leaves2:1)
Block(4,22,-8,minecraft:leaves2:1)
Block(5,22,-8,minecraft:leaves2:1)
Block(8,22,-8,minecraft:leaves2:1)
Block(9,22,-8,minecraft:leaves2:1)
Block(-1,22,-7,minecraft:leaves2:1)
Block(2,22,-7,minecraft:leaves2:1)
Block(3,22,-7,minecraft:leaves2:1)
Block(5,22,-7,minecraft:leaves2:1)
Block(7,22,-7,minecraft:leaves2:1)
Block(8,22,-7,minecraft:leaves2:1)
Block(-3,22,-6,minecraft:log2:1)
Block(-2,22,-6,minecraft:log2:1)
Block(-1,22,-6,minecraft:log2:1)
Block(2,22,-6,minecraft:leaves2:1)
Block(3,22,-6,minecraft:leaves2:1)
Block(4,22,-6,minecraft:leaves2:1)
Block(5,22,-6,minecraft:leaves2:1)
Block(6,22,-6,minecraft:leaves2:1)
Block(7,22,-6,minecraft:leaves2:1)
Block(8,22,-6,minecraft:leaves2:1)
Block(-4,22,-5,minecraft:log2:1)
Block(-3,22,-5,minecraft:log2:1)
Block(-2,22,-5,minecraft:log2:1)
Block(-1,22,-5,minecraft:log2:1)
Block(0,22,-5,minecraft:log2:1)
Block(4,22,-5,minecraft:leaves2:1)
Block(5,22,-5,minecraft:leaves2:1)
Block(7,22,-5,minecraft:leaves2:1)
Block(-4,22,-4,minecraft:log2:1)
Block(-3,22,-4,minecraft:log2:1)
Block(-2,22,-4,minecraft:log2:1)
Block(-1,22,-4,minecraft:log2:1)
Block(0,22,-4,minecraft:log2:1)
Block(5,22,-4,minecraft:leaves2:1)
Block(6,22,-4,minecraft:leaves2:1)
Block(-3,22,-3,minecraft:log2:1)
Block(-2,22,-3,minecraft:log2:1)
Block(-1,22,-3,minecraft:log2:1)
Block(0,22,-3,minecraft:log2:1)
Block(-3,22,-2,minecraft:log2:1)
Block(-2,22,-2,minecraft:log2:1)
Block(-1,22,-2,minecraft:log2:1)
Block(-2,22,-1,minecraft:log2:1)
Block(6,22,3,minecraft:leaves2:1)
Block(8,22,3,minecraft:leaves2:1)
Block(6,22,4,minecraft:leaves2:1)
Block(7,22,4,minecraft:leaves2:1)
Block(8,22,4,minecraft:leaves2:1)
Block(9,22,4,minecraft:leaves2:1)
Block(10,22,4,minecraft:leaves2:1)
Block(5,22,5,minecraft:leaves2:1)
Block(6,22,5,minecraft:leaves2:1)
Block(7,22,5,minecraft:leaves2:1)
Block(8,22,5,minecraft:leaves2:1)
Block(9,22,5,minecraft:leaves2:1)
Block(10,22,5,minecraft:leaves2:1)
Block(11,22,5,minecraft:leaves2:1)
Block(5,22,6,minecraft:leaves2:1)
Block(6,22,6,minecraft:leaves2:1)
Block(7,22,6,minecraft:leaves2:1)
Block(8,22,6,minecraft:leaves2:1)
Block(10,22,6,minecraft:leaves2:1)
Block(12,22,6,minecraft:leaves2:1)
Block(3,22,7,minecraft:leaves2:1)
Block(6,22,7,minecraft:leaves2:1)
Block(7,22,7,minecraft:leaves2:1)
Block(8,22,7,minecraft:log2:1)
Block(9,22,7,minecraft:log2:1)
Block(10,22,7,minecraft:log2:1)
Block(12,22,7,minecraft:leaves2:1)
Block(13,22,7,minecraft:leaves2:1)
Block(3,22,8,minecraft:leaves2:1)
Block(4,22,8,minecraft:leaves2:1)
Block(7,22,8,minecraft:log2:1)
Block(8,22,8,minecraft:log2:1)
Block(9,22,8,minecraft:log2:1)
Block(10,22,8,minecraft:log2:1)
Block(12,22,8,minecraft:leaves2:1)
Block(3,22,9,minecraft:leaves2:1)
Block(5,22,9,minecraft:leaves2:1)
Block(8,22,9,minecraft:log2:1)
Block(9,22,9,minecraft:log2:1)
Block(10,22,9,minecraft:log2:1)
Block(11,22,9,minecraft:leaves2:1)
Block(13,22,9,minecraft:leaves2:1)
Block(4,22,10,minecraft:leaves2:1)
Block(9,22,10,minecraft:log2:1)
Block(13,22,10,minecraft:leaves2:1)
Block(14,22,10,minecraft:leaves2:1)
Block(4,22,11,minecraft:leaves2:1)
Block(5,22,11,minecraft:leaves2:1)
Block(6,22,11,minecraft:leaves2:1)
Block(13,22,11,minecraft:leaves2:1)
Block(5,22,12,minecraft:leaves2:1)
Block(6,22,12,minecraft:leaves2:1)
Block(7,22,12,minecraft:leaves2:1)
Block(8,22,12,minecraft:leaves2:1)
Block(9,22,12,minecraft:leaves2:1)
Block(10,22,12,minecraft:leaves2:1)
Block(11,22,12,minecraft:leaves2:1)
Block(6,22,13,minecraft:leaves2:1)
Block(7,22,13,minecraft:leaves2:1)
Block(8,22,13,minecraft:leaves2:1)
Block(9,22,13,minecraft:leaves2:1)
Block(10,22,13,minecraft:leaves2:1)
Block(8,22,14,minecraft:leaves2:1)
Block(-2,23,-7,minecraft:leaves2:1)
Block(-3,23,-6,minecraft:log2:1)
Block(-2,23,-6,minecraft:log2:1)
Block(-1,23,-6,minecraft:log2:1)
Block(0,23,-6,minecraft:leaves2:1)
Block(-4,23,-5,minecraft:log2:1)
Block(-3,23,-5,minecraft:log2:1)
Block(-2,23,-5,minecraft:log2:1)
Block(-1,23,-5,minecraft:log2:1)
Block(0,23,-5,minecraft:log2:1)
Block(-4,23,-4,minecraft:log2:1)
Block(-3,23,-4,minecraft:log2:1)
Block(-2,23,-4,minecraft:log2:1)
Block(-1,23,-4,minecraft:log2:1)
Block(0,23,-4,minecraft:log2:1)
Block(-4,23,-3,minecraft:log2:1)
Block(-3,23,-3,minecraft:log2:1)
Block(-2,23,-3,minecraft:log2:1)
Block(-1,23,-3,minecraft:log2:1)
Block(0,23,-3,minecraft:log2:1)
Block(-3,23,-2,minecraft:log2:1)
Block(-2,23,-2,minecraft:log2:1)
Block(-1,23,-2,minecraft:log2:1)
Block(-2,23,-1,minecraft:log2:1)
Block(7,23,3,minecraft:leaves2:1)
Block(8,23,3,minecraft:leaves2:1)
Block(9,23,3,minecraft:leaves2:1)
Block(10,23,3,minecraft:leaves2:1)
Block(5,23,4,minecraft:leaves2:1)
Block(6,23,4,minecraft:leaves2:1)
Block(7,23,4,minecraft:leaves2:1)
Block(8,23,4,minecraft:leaves2:1)
Block(9,23,4,minecraft:leaves2:1)
Block(10,23,4,minecraft:leaves2:1)
Block(11,23,4,minecraft:leaves2:1)
Block(4,23,5,minecraft:leaves2:1)
Block(5,23,5,minecraft:leaves2:1)
Block(6,23,5,minecraft:leaves2:1)
Block(7,23,5,minecraft:leaves2:1)
Block(8,23,5,minecraft:leaves2:1)
Block(9,23,5,minecraft:leaves2:1)
Block(10,23,5,minecraft:leaves2:1)
Block(11,23,5,minecraft:leaves2:1)
Block(12,23,5,minecraft:leaves2:1)
Block(3,23,6,minecraft:leaves2:1)
Block(4,23,6,minecraft:leaves2:1)
Block(5,23,6,minecraft:leaves2:1)
Block(6,23,6,minecraft:leaves2:1)
Block(7,23,6,minecraft:leaves2:1)
Block(8,23,6,minecraft:leaves2:1)
Block(9,23,6,minecraft:leaves2:1)
Block(10,23,6,minecraft:leaves2:1)
Block(11,23,6,minecraft:leaves2:1)
Block(12,23,6,minecraft:leaves2:1)
Block(13,23,6,minecraft:leaves2:1)
Block(3,23,7,minecraft:leaves2:1)
Block(4,23,7,minecraft:leaves2:1)
Block(5,23,7,minecraft:leaves2:1)
Block(6,23,7,minecraft:leaves2:1)
Block(7,23,7,minecraft:leaves2:1)
Block(8,23,7,minecraft:leaves2:1)
Block(9,23,7,minecraft:leaves2:1)
Block(10,23,7,minecraft:leaves2:1)
Block(12,23,7,minecraft:leaves2:1)
Block(13,23,7,minecraft:leaves2:1)
Block(3,23,8,minecraft:leaves2:1)
Block(4,23,8,minecraft:leaves2:1)
Block(5,23,8,minecraft:leaves2:1)
Block(6,23,8,minecraft:log2:1)
Block(7,23,8,minecraft:log2:1)
Block(8,23,8,minecraft:log2:1)
Block(9,23,8,minecraft:leaves2:1)
Block(10,23,8,minecraft:leaves2:1)
Block(12,23,8,minecraft:leaves2:1)
Block(13,23,8,minecraft:leaves2:1)
Block(4,23,9,minecraft:leaves2:1)
Block(5,23,9,minecraft:leaves2:1)
Block(6,23,9,minecraft:log2:1)
Block(7,23,9,minecraft:leaves2:1)
Block(8,23,9,minecraft:log2:1)
Block(9,23,9,minecraft:leaves2:1)
Block(10,23,9,minecraft:log2:1)
Block(11,23,9,minecraft:log2:1)
Block(12,23,9,minecraft:log2:1)
Block(13,23,9,minecraft:leaves2:1)
Block(14,23,9,minecraft:leaves2:1)
Block(3,23,10,minecraft:leaves2:1)
Block(4,23,10,minecraft:leaves2:1)
Block(5,23,10,minecraft:log2:1)
Block(6,23,10,minecraft:log2:1)
Block(9,23,10,minecraft:log2:1)
Block(11,23,10,minecraft:leaves2:1)
Block(12,23,10,minecraft:log2:1)
Block(13,23,10,minecraft:leaves2:1)
Block(14,23,10,minecraft:leaves2:1)
Block(4,23,11,minecraft:leaves2:1)
Block(5,23,11,minecraft:leaves2:1)
Block(6,23,11,minecraft:leaves2:1)
Block(7,23,11,minecraft:leaves2:1)
Block(8,23,11,minecraft:leaves2:1)
Block(9,23,11,minecraft:log2:1)
Block(11,23,11,minecraft:leaves2:1)
Block(12,23,11,minecraft:leaves2:1)
Block(13,23,11,minecraft:leaves2:1)
Block(14,23,11,minecraft:leaves2:1)
Block(4,23,12,minecraft:leaves2:1)
Block(5,23,12,minecraft:leaves2:1)
Block(6,23,12,minecraft:leaves2:1)
Block(7,23,12,minecraft:leaves2:1)
Block(8,23,12,minecraft:leaves2:1)
Block(9,23,12,minecraft:leaves2:1)
Block(10,23,12,minecraft:leaves2:1)
Block(11,23,12,minecraft:leaves2:1)
Block(12,23,12,minecraft:leaves2:1)
Block(13,23,12,minecraft:leaves2:1)
Block(5,23,13,minecraft:leaves2:1)
Block(6,23,13,minecraft:leaves2:1)
Block(7,23,13,minecraft:leaves2:1)
Block(8,23,13,minecraft:leaves2:1)
Block(9,23,13,minecraft:leaves2:1)
Block(10,23,13,minecraft:leaves2:1)
Block(11,23,13,minecraft:leaves2:1)
Block(6,23,14,minecraft:leaves2:1)
Block(7,23,14,minecraft:leaves2:1)
Block(8,23,14,minecraft:leaves2:1)
Block(9,23,14,minecraft:leaves2:1)
Block(10,24,-8,minecraft:leaves2:1)
Block(-3,24,-6,minecraft:leaves2:1)
Block(-2,24,-6,minecraft:log2:1)
Block(-1,24,-6,minecraft:log2:1)
Block(-9,24,-5,minecraft:leaves2:1)
Block(-4,24,-5,minecraft:log2:1)
Block(-3,24,-5,minecraft:log2:1)
Block(-2,24,-5,minecraft:log2:1)
Block(-1,24,-5,minecraft:log2:1)
Block(1,24,-5,minecraft:leaves2:1)
Block(-4,24,-4,minecraft:log2:1)
Block(-3,24,-4,minecraft:log2:1)
Block(-2,24,-4,minecraft:log2:1)
Block(-1,24,-4,minecraft:log2:1)
Block(0,24,-4,minecraft:log2:1)
Block(-4,24,-3,minecraft:log2:1)
Block(-3,24,-3,minecraft:log2:1)
Block(-2,24,-3,minecraft:log2:1)
Block(-1,24,-3,minecraft:log2:1)
Block(0,24,-3,minecraft:log2:1)
Block(-2,24,-2,minecraft:log2:1)
Block(-1,24,-2,minecraft:log2:1)
Block(0,24,-2,minecraft:log2:1)
Block(-2,24,-1,minecraft:log2:1)
Block(-1,24,-1,minecraft:log2:1)
Block(7,24,3,minecraft:leaves2:1)
Block(6,24,4,minecraft:leaves2:1)
Block(7,24,4,minecraft:leaves2:1)
Block(8,24,4,minecraft:leaves2:1)
Block(9,24,4,minecraft:leaves2:1)
Block(10,24,4,minecraft:leaves2:1)
Block(5,24,5,minecraft:leaves2:1)
Block(6,24,5,minecraft:leaves2:1)
Block(7,24,5,minecraft:leaves2:1)
Block(8,24,5,minecraft:leaves2:1)
Block(9,24,5,minecraft:leaves2:1)
Block(10,24,5,minecraft:leaves2:1)
Block(11,24,5,minecraft:leaves2:1)
Block(4,24,6,minecraft:leaves2:1)
Block(5,24,6,minecraft:leaves2:1)
Block(6,24,6,minecraft:leaves2:1)
Block(7,24,6,minecraft:leaves2:1)
Block(8,24,6,minecraft:leaves2:1)
Block(9,24,6,minecraft:leaves2:1)
Block(10,24,6,minecraft:leaves2:1)
Block(11,24,6,minecraft:leaves2:1)
Block(12,24,6,minecraft:leaves2:1)
Block(4,24,7,minecraft:leaves2:1)
Block(6,24,7,minecraft:leaves2:1)
Block(7,24,7,minecraft:leaves2:1)
Block(8,24,7,minecraft:leaves2:1)
Block(9,24,7,minecraft:leaves2:1)
Block(10,24,7,minecraft:leaves2:1)
Block(11,24,7,minecraft:leaves2:1)
Block(12,24,7,minecraft:leaves2:1)
Block(13,24,7,minecraft:leaves2:1)
Block(3,24,8,minecraft:leaves2:1)
Block(4,24,8,minecraft:leaves2:1)
Block(5,24,8,minecraft:leaves2:1)
Block(6,24,8,minecraft:leaves2:1)
Block(7,24,8,minecraft:leaves2:1)
Block(8,24,8,minecraft:leaves2:1)
Block(9,24,8,minecraft:leaves2:1)
Block(10,24,8,minecraft:leaves2:1)
Block(11,24,8,minecraft:leaves2:1)
Block(12,24,8,minecraft:leaves2:1)
Block(-5,24,9,minecraft:leaves2:1)
Block(3,24,9,minecraft:leaves2:1)
Block(4,24,9,minecraft:leaves2:1)
Block(5,24,9,minecraft:leaves2:1)
Block(6,24,9,minecraft:leaves2:1)
Block(7,24,9,minecraft:leaves2:1)
Block(8,24,9,minecraft:leaves2:1)
Block(9,24,9,minecraft:leaves2:1)
Block(10,24,9,minecraft:leaves2:1)
Block(11,24,9,minecraft:leaves2:1)
Block(12,24,9,minecraft:leaves2:1)
Block(13,24,9,minecraft:leaves2:1)
Block(4,24,10,minecraft:leaves2:1)
Block(5,24,10,minecraft:leaves2:1)
Block(6,24,10,minecraft:leaves2:1)
Block(7,24,10,minecraft:leaves2:1)
Block(8,24,10,minecraft:leaves2:1)
Block(9,24,10,minecraft:leaves2:1)
Block(10,24,10,minecraft:leaves2:1)
Block(11,24,10,minecraft:leaves2:1)
Block(12,24,10,minecraft:leaves2:1)
Block(13,24,10,minecraft:leaves2:1)
Block(14,24,10,minecraft:leaves2:1)
Block(4,24,11,minecraft:leaves2:1)
Block(5,24,11,minecraft:leaves2:1)
Block(6,24,11,minecraft:leaves2:1)
Block(7,24,11,minecraft:leaves2:1)
Block(8,24,11,minecraft:leaves2:1)
Block(9,24,11,minecraft:leaves2:1)
Block(10,24,11,minecraft:leaves2:1)
Block(11,24,11,minecraft:leaves2:1)
Block(12,24,11,minecraft:leaves2:1)
Block(13,24,11,minecraft:leaves2:1)
Block(5,24,12,minecraft:leaves2:1)
Block(6,24,12,minecraft:leaves2:1)
Block(7,24,12,minecraft:leaves2:1)
Block(8,24,12,minecraft:leaves2:1)
Block(9,24,12,minecraft:leaves2:1)
Block(10,24,12,minecraft:leaves2:1)
Block(11,24,12,minecraft:leaves2:1)
Block(6,24,13,minecraft:leaves2:1)
Block(7,24,13,minecraft:leaves2:1)
Block(8,24,13,minecraft:leaves2:1)
Block(9,24,13,minecraft:leaves2:1)
Block(10,24,13,minecraft:leaves2:1)
Block(7,24,14,minecraft:leaves2:1)
Block(8,24,14,minecraft:leaves2:1)
Block(10,25,-8,minecraft:leaves2:1)
Block(-3,25,-6,minecraft:leaves2:1)
Block(-2,25,-6,minecraft:log2:1)
Block(-1,25,-6,minecraft:log2:1)
Block(-9,25,-5,minecraft:leaves2:1)
Block(-3,25,-5,minecraft:log2:1)
Block(-2,25,-5,minecraft:log2:1)
Block(-1,25,-5,minecraft:log2:1)
Block(-4,25,-4,minecraft:log2:1)
Block(-3,25,-4,minecraft:log2:1)
Block(-2,25,-4,minecraft:log2:1)
Block(-1,25,-4,minecraft:log2:1)
Block(0,25,-4,minecraft:log2:1)
Block(1,25,-4,minecraft:leaves2:1)
Block(-4,25,-3,minecraft:log2:1)
Block(-3,25,-3,minecraft:log2:1)
Block(-2,25,-3,minecraft:log2:1)
Block(-1,25,-3,minecraft:log2:1)
Block(0,25,-3,minecraft:log2:1)
Block(-2,25,-2,minecraft:log2:1)
Block(-1,25,-2,minecraft:log2:1)
Block(0,25,-2,minecraft:log2:1)
Block(-2,25,-1,minecraft:log2:1)
Block(-1,25,-1,minecraft:log2:1)
Block(0,25,-1,minecraft:log2:1)
Block(1,25,-1,minecraft:log2:1)
Block(-1,25,0,minecraft:log2:1)
Block(0,25,0,minecraft:log2:1)
Block(1,25,0,minecraft:log2:1)
Block(2,25,0,minecraft:log2:1)
Block(0,25,1,minecraft:log2:1)
Block(1,25,1,minecraft:log2:1)
Block(8,25,4,minecraft:leaves2:1)
Block(7,25,5,minecraft:leaves2:1)
Block(8,25,5,minecraft:leaves2:1)
Block(9,25,5,minecraft:leaves2:1)
Block(10,25,5,minecraft:leaves2:1)
Block(6,25,6,minecraft:leaves2:1)
Block(7,25,6,minecraft:leaves2:1)
Block(9,25,6,minecraft:leaves2:1)
Block(10,25,6,minecraft:leaves2:1)
Block(11,25,6,minecraft:leaves2:1)
Block(5,25,7,minecraft:leaves2:1)
Block(6,25,7,minecraft:leaves2:1)
Block(7,25,7,minecraft:leaves2:1)
Block(8,25,7,minecraft:leaves2:1)
Block(11,25,7,minecraft:leaves2:1)
Block(6,25,8,minecraft:leaves2:1)
Block(8,25,8,minecraft:leaves2:1)
Block(11,25,8,minecraft:leaves2:1)
Block(12,25,8,minecraft:leaves2:1)
Block(-5,25,9,minecraft:leaves2:1)
Block(4,25,9,minecraft:leaves2:1)
Block(5,25,9,minecraft:leaves2:1)
Block(7,25,9,minecraft:leaves2:1)
Block(8,25,9,minecraft:leaves2:1)
Block(9,25,9,minecraft:leaves2:1)
Block(10,25,9,minecraft:leaves2:1)
Block(11,25,9,minecraft:leaves2:1)
Block(12,25,9,minecraft:leaves2:1)
Block(4,25,10,minecraft:leaves2:1)
Block(5,25,10,minecraft:leaves2:1)
Block(6,25,10,minecraft:leaves2:1)
Block(7,25,10,minecraft:leaves2:1)
Block(8,25,10,minecraft:leaves2:1)
Block(10,25,10,minecraft:leaves2:1)
Block(11,25,10,minecraft:leaves2:1)
Block(2,25,11,minecraft:leaves2:1)
Block(5,25,11,minecraft:leaves2:1)
Block(6,25,11,minecraft:leaves2:1)
Block(7,25,11,minecraft:leaves2:1)
Block(8,25,11,minecraft:leaves2:1)
Block(9,25,11,minecraft:leaves2:1)
Block(10,25,11,minecraft:leaves2:1)
Block(12,25,11,minecraft:leaves2:1)
Block(6,25,12,minecraft:leaves2:1)
Block(7,25,12,minecraft:leaves2:1)
Block(8,25,12,minecraft:leaves2:1)
Block(10,25,12,minecraft:leaves2:1)
Block(10,26,-8,minecraft:leaves2:1)
Block(-2,26,-6,minecraft:log2:1)
Block(-1,26,-6,minecraft:log2:1)
Block(-9,26,-5,minecraft:leaves2:1)
Block(-4,26,-5,minecraft:leaves2:1)
Block(-3,26,-5,minecraft:log2:1)
Block(-2,26,-5,minecraft:log2:1)
Block(-1,26,-5,minecraft:log2:1)
Block(-4,26,-4,minecraft:log2:1)
Block(-3,26,-4,minecraft:log2:1)
Block(-2,26,-4,minecraft:log2:1)
Block(-1,26,-4,minecraft:log2:1)
Block(0,26,-4,minecraft:log2:1)
Block(4,26,-4,minecraft:leaves2:1)
Block(-4,26,-3,minecraft:log2:1)
Block(-3,26,-3,minecraft:log2:1)
Block(-2,26,-3,minecraft:log2:1)
Block(-1,26,-3,minecraft:log2:1)
Block(0,26,-3,minecraft:log2:1)
Block(1,26,-3,minecraft:log2:1)
Block(2,26,-3,minecraft:leaves2:1)
Block(-3,26,-2,minecraft:log2:1)
Block(-2,26,-2,minecraft:log2:1)
Block(-1,26,-2,minecraft:log2:1)
Block(0,26,-2,minecraft:log2:1)
Block(1,26,-2,minecraft:log2:1)
Block(-2,26,-1,minecraft:log2:1)
Block(-1,26,-1,minecraft:log2:1)
Block(0,26,-1,minecraft:log2:1)
Block(1,26,-1,minecraft:log2:1)
Block(2,26,-1,minecraft:log2:1)
Block(-2,26,0,minecraft:log2:1)
Block(-1,26,0,minecraft:log2:1)
Block(0,26,0,minecraft:log2:1)
Block(1,26,0,minecraft:log2:1)
Block(2,26,0,minecraft:log2:1)
Block(3,26,0,minecraft:log2:1)
Block(0,26,1,minecraft:log2:1)
Block(1,26,1,minecraft:log2:1)
Block(2,26,1,minecraft:log2:1)
Block(3,26,1,minecraft:log2:1)
Block(1,26,2,minecraft:log2:1)
Block(2,26,2,minecraft:log2:1)
Block(3,26,2,minecraft:log2:1)
Block(3,26,3,minecraft:leaves2:1)
Block(-5,26,9,minecraft:leaves2:1)
Block(2,26,11,minecraft:leaves2:1)
Block(-5,27,-11,minecraft:leaves2:1)
Block(8,27,-10,minecraft:leaves2:1)
Block(10,27,-8,minecraft:leaves2:1)
Block(-2,27,-7,minecraft:leaves2:1)
Block(-2,27,-6,minecraft:log2:1)
Block(-1,27,-6,minecraft:log2:1)
Block(-9,27,-5,minecraft:leaves2:1)
Block(-4,27,-5,minecraft:log2:1)
Block(-3,27,-5,minecraft:log2:1)
Block(-2,27,-5,minecraft:log2:1)
Block(-1,27,-5,minecraft:log2:1)
Block(0,27,-5,minecraft:log2:1)
Block(-5,27,-4,minecraft:leaves2:1)
Block(-4,27,-4,minecraft:log2:1)
Block(-3,27,-4,minecraft:log2:1)
Block(-2,27,-4,minecraft:log2:1)
Block(-1,27,-4,minecraft:log2:1)
Block(0,27,-4,minecraft:log2:1)
Block(4,27,-4,minecraft:leaves2:1)
Block(-4,27,-3,minecraft:log2:1)
Block(-3,27,-3,minecraft:log2:1)
Block(-2,27,-3,minecraft:log2:1)
Block(-1,27,-3,minecraft:log2:1)
Block(0,27,-3,minecraft:log2:1)
Block(-3,27,-2,minecraft:log2:1)
Block(-2,27,-2,minecraft:log2:1)
Block(-1,27,-2,minecraft:log2:1)
Block(0,27,-2,minecraft:log2:1)
Block(1,27,-2,minecraft:log2:1)
Block(2,27,-2,minecraft:leaves2:1)
Block(-3,27,-1,minecraft:log2:1)
Block(-2,27,-1,minecraft:log2:1)
Block(-1,27,-1,minecraft:log2:1)
Block(0,27,-1,minecraft:log2:1)
Block(1,27,-1,minecraft:log2:1)
Block(-2,27,0,minecraft:log2:1)
Block(-1,27,0,minecraft:log2:1)
Block(0,27,0,minecraft:log2:1)
Block(1,27,0,minecraft:log2:1)
Block(2,27,0,minecraft:log2:1)
Block(3,27,0,minecraft:log2:1)
Block(-1,27,1,minecraft:log2:1)
Block(0,27,1,minecraft:log2:1)
Block(1,27,1,minecraft:log2:1)
Block(2,27,1,minecraft:log2:1)
Block(3,27,1,minecraft:log2:1)
Block(4,27,1,minecraft:log2:1)
Block(0,27,2,minecraft:log2:1)
Block(1,27,2,minecraft:log2:1)
Block(2,27,2,minecraft:log2:1)
Block(3,27,2,minecraft:log2:1)
Block(4,27,2,minecraft:leaves2:1)
Block(1,27,3,minecraft:log2:1)
Block(2,27,3,minecraft:log2:1)
Block(3,27,3,minecraft:log2:1)
Block(2,27,4,minecraft:leaves2:1)
Block(-8,27,6,minecraft:leaves2:1)
Block(-5,27,9,minecraft:leaves2:1)
Block(8,27,9,minecraft:leaves2:1)
Block(-1,27,10,minecraft:leaves2:1)
Block(2,27,11,minecraft:leaves2:1)
Block(5,27,11,minecraft:leaves2:1)
Block(-5,28,-11,minecraft:leaves2:1)
Block(8,28,-10,minecraft:leaves2:1)
Block(10,28,-8,minecraft:leaves2:1)
Block(-2,28,-7,minecraft:leaves2:1)
Block(-1,28,-7,minecraft:leaves2:1)
Block(-2,28,-6,minecraft:log2:1)
Block(-1,28,-6,minecraft:log2:1)
Block(0,28,-6,minecraft:log2:1)
Block(-9,28,-5,minecraft:leaves2:1)
Block(-4,28,-5,minecraft:log2:1)
Block(-3,28,-5,minecraft:log2:1)
Block(-2,28,-5,minecraft:log2:1)
Block(-1,28,-5,minecraft:log2:1)
Block(0,28,-5,minecraft:log2:1)
Block(-5,28,-4,minecraft:leaves2:1)
Block(-4,28,-4,minecraft:log2:1)
Block(-3,28,-4,minecraft:log2:1)
Block(-2,28,-4,minecraft:log2:1)
Block(-1,28,-4,minecraft:log2:1)
Block(0,28,-4,minecraft:log2:1)
Block(4,28,-4,minecraft:leaves2:1)
Block(-4,28,-3,minecraft:log2:1)
Block(-3,28,-3,minecraft:log2:1)
Block(-2,28,-3,minecraft:log2:1)
Block(-1,28,-3,minecraft:log2:1)
Block(0,28,-3,minecraft:log2:1)
