#######################################################################
# +-----------------------------------------------------------------+ #
# |                            BO3 object                           | #
# +-----------------------------------------------------------------+ #
#######################################################################

# This is the config file of a custom object.
# If you add this object correctly to your BiomeConfigs, it will spawn in the world.

# This is the creator of this BO3 object
Author: BO3 BulkEdit (by LanToaster)

# A short description of this BO3 object
Description: This Object was Created with BO3_BulkEdit

# The BO3 version, don't change this! It can be used by external applications to do a version check.
Version: 3

# The settings mode, WriteAll, WriteWithoutComments or WriteDisable. See WorldConfig.
SettingsMode: WriteDisable


#######################################################################
# +-----------------------------------------------------------------+ #
# |                          Main settings                          | #
# +-----------------------------------------------------------------+ #
#######################################################################

# This needs to be set to true to spawn the object in the Tree and Sapling resources.
Tree: true

# The frequency of the BO3 from 1 to 200. Tries this many times to spawn this BO3 when using the CustomObject(...) resource.
# Ignored by Tree(..), Sapling(..) and CustomStructure(..)
Frequency: 1

# The rarity of the BO3 from 0 to 100. Each spawn attempt has rarity% chance to succeed when using the CustomObject(...) resource.
# Ignored by Tree(..), Sapling(..) and CustomStructure(..)
Rarity: 100.0

# If you set this to true, the BO3 will be placed with a random rotation.
RotateRandomly: true

# The spawn height of the BO3 - randomY, highestBlock or highestSolid)Block.
SpawnHeight: randomY

# The height limits for the BO3.
MinHeight: 92

MaxHeight: 256

# Objects can have other objects attacthed to it: branches. Branches can also
# have branches attached to it, which can also have branches, etc. This is the
# maximum branch depth for this objects.
MaxBranchDepth: 10

# When spawned with the UseWorld keyword, this BO3 should NOT spawn in the following biomes.
# If you writer.write the BO3 name directly in the BiomeConfigs, this will be ignored.
ExcludedBiomes: All


#######################################################################
# +-----------------------------------------------------------------+ #
# |                      Source block settings                      | #
# +-----------------------------------------------------------------+ #
#######################################################################

# The block(s) the BO3 should spawn in.
SourceBlocks: AIR,minecraft:grass,minecraft:dirt

# The maximum percentage of the BO3 that can be outside the SourceBlock.
# The BO3 won't be placed on a location with more blocks outside the SourceBlock than this percentage.
MaxPercentageOutsideSourceBlock: 100

# What to do when a block is about to be placed outside the SourceBlock? (dontPlace, placeAnyway)
OutsideSourceBlock: placeAnyway


#######################################################################
# +-----------------------------------------------------------------+ #
# |                              Blocks                             | #
# +-----------------------------------------------------------------+ #
#######################################################################

# All the blocks used in the BO3 are listed here. Possible blocks:
# Block(x,y,z,id[.data][,nbtfile.nbt)
# RandomBlock(x,y,z,id[:data][,nbtfile.nbt],chance[,id[:data][,nbtfile.nbt],chance[,...]])
# So RandomBlock(0,0,0,CHEST,chest.nbt,50,CHEST,anotherchest.nbt,100) will spawn a chest at
# the BO3 origin, and give it a 50% chance to have the contents of chest.nbt, or, if that
# fails, a 100% percent chance to have the contents of anotherchest.nbt.
Block(-6,0,-6,minecraft:log2:1)
Block(-5,0,-6,minecraft:log2:1)
Block(-4,0,-6,minecraft:log2:1)
Block(-7,0,-5,minecraft:log2:1)
Block(-6,0,-5,minecraft:log2:1)
Block(-5,0,-5,minecraft:log2:1)
Block(-4,0,-5,minecraft:log2:1)
Block(-3,0,-5,minecraft:log2:1)
Block(-2,0,-5,minecraft:log2:1)
Block(-8,0,-4,minecraft:leaves2:1)
Block(-7,0,-4,minecraft:log2:1)
Block(-6,0,-4,minecraft:log2:1)
Block(-5,0,-4,minecraft:log2:1)
Block(-4,0,-4,minecraft:log2:1)
Block(-3,0,-4,minecraft:log2:1)
Block(-2,0,-4,minecraft:log2:1)
Block(-1,0,-4,minecraft:log2:1)
Block(-8,0,-3,minecraft:log2:1)
Block(-7,0,-3,minecraft:log2:1)
Block(-6,0,-3,minecraft:log2:1)
Block(-5,0,-3,minecraft:log2:1)
Block(-4,0,-3,minecraft:log2:1)
Block(-3,0,-3,minecraft:log2:1)
Block(-2,0,-3,minecraft:log2:1)
Block(-1,0,-3,minecraft:log2:1)
Block(0,0,-3,minecraft:leaves2:1)
Block(-8,0,-2,minecraft:log2:1)
Block(-7,0,-2,minecraft:log2:1)
Block(-6,0,-2,minecraft:log2:1)
Block(-5,0,-2,minecraft:log2:1)
Block(-4,0,-2,minecraft:log2:1)
Block(-3,0,-2,minecraft:log2:1)
Block(-2,0,-2,minecraft:log2:1)
Block(-1,0,-2,minecraft:log2:1)
Block(0,0,-2,minecraft:log2:1)
Block(-8,0,-1,minecraft:log2:1)
Block(-7,0,-1,minecraft:log2:1)
Block(-6,0,-1,minecraft:log2:1)
Block(-5,0,-1,minecraft:log2:1)
Block(-4,0,-1,minecraft:log2:1)
Block(-3,0,-1,minecraft:log2:1)
Block(-2,0,-1,minecraft:log2:1)
Block(-1,0,-1,minecraft:log2:1)
Block(0,0,-1,minecraft:log2:1)
Block(-7,0,0,minecraft:log2:1)
Block(-6,0,0,minecraft:log2:1)
Block(-5,0,0,minecraft:log2:1)
Block(-4,0,0,minecraft:log2:1)
Block(-3,0,0,minecraft:log2:1)
Block(-2,0,0,minecraft:log2:1)
Block(-1,0,0,minecraft:log2:1)
Block(0,0,0,minecraft:log2:1)
Block(-6,0,1,minecraft:log2:1)
Block(-5,0,1,minecraft:log2:1)
Block(-4,0,1,minecraft:log2:1)
Block(-3,0,1,minecraft:log2:1)
Block(-2,0,1,minecraft:log2:1)
Block(-1,0,1,minecraft:log2:1)
Block(-5,0,2,minecraft:log2:1)
Block(-4,0,2,minecraft:log2:1)
Block(-3,0,2,minecraft:log2:1)
Block(-2,0,2,minecraft:log2:1)
Block(-5,1,-6,minecraft:log2:1)
Block(-7,1,-5,minecraft:log2:1)
Block(-6,1,-5,minecraft:log2:1)
Block(-5,1,-5,minecraft:log2:1)
Block(-4,1,-5,minecraft:log2:1)
Block(-7,1,-4,minecraft:log2:1)
Block(-6,1,-4,minecraft:log2:1)
Block(-5,1,-4,minecraft:log2:1)
Block(-4,1,-4,minecraft:log2:1)
Block(-3,1,-4,minecraft:log2:1)
Block(-2,1,-4,minecraft:leaves2:1)
Block(-8,1,-3,minecraft:leaves2:1)
Block(-7,1,-3,minecraft:log2:1)
Block(-6,1,-3,minecraft:log2:1)
Block(-5,1,-3,minecraft:log2:1)
Block(-4,1,-3,minecraft:log2:1)
Block(-3,1,-3,minecraft:log2:1)
Block(-2,1,-3,minecraft:log2:1)
Block(-1,1,-3,minecraft:leaves2:1)
Block(-7,1,-2,minecraft:log2:1)
Block(-6,1,-2,minecraft:log2:1)
Block(-5,1,-2,minecraft:log2:1)
Block(-4,1,-2,minecraft:log2:1)
Block(-3,1,-2,minecraft:log2:1)
Block(-2,1,-2,minecraft:log2:1)
Block(-1,1,-2,minecraft:log2:1)
Block(0,1,-2,minecraft:log2:1)
Block(-6,1,-1,minecraft:log2:1)
Block(-5,1,-1,minecraft:log2:1)
Block(-4,1,-1,minecraft:log2:1)
Block(-3,1,-1,minecraft:log2:1)
Block(-2,1,-1,minecraft:log2:1)
Block(-1,1,-1,minecraft:log2:1)
Block(-5,1,0,minecraft:log2:1)
Block(-4,1,0,minecraft:log2:1)
Block(-3,1,0,minecraft:log2:1)
Block(-2,1,0,minecraft:log2:1)
Block(-5,1,1,minecraft:log2:1)
Block(-4,1,1,minecraft:log2:1)
Block(-3,1,1,minecraft:log2:1)
Block(-2,1,1,minecraft:log2:1)
Block(-4,1,2,minecraft:log2:1)
Block(-3,1,2,minecraft:log2:1)
Block(-6,2,-5,minecraft:log2:1)
Block(-5,2,-5,minecraft:log2:1)
Block(-4,2,-5,minecraft:log2:1)
Block(-3,2,-5,minecraft:leaves2:1)
Block(-7,2,-4,minecraft:log2:1)
Block(-6,2,-4,minecraft:log2:1)
Block(-5,2,-4,minecraft:log2:1)
Block(-4,2,-4,minecraft:log2:1)
Block(-3,2,-4,minecraft:log2:1)
Block(-8,2,-3,minecraft:leaves2:1)
Block(-7,2,-3,minecraft:log2:1)
Block(-6,2,-3,minecraft:log2:1)
Block(-5,2,-3,minecraft:log2:1)
Block(-4,2,-3,minecraft:log2:1)
Block(-3,2,-3,minecraft:log2:1)
Block(-2,2,-3,minecraft:log2:1)
Block(-1,2,-3,minecraft:log2:1)
Block(-8,2,-2,minecraft:leaves2:1)
Block(-7,2,-2,minecraft:log2:1)
Block(-6,2,-2,minecraft:log2:1)
Block(-5,2,-2,minecraft:log2:1)
Block(-4,2,-2,minecraft:log2:1)
Block(-3,2,-2,minecraft:log2:1)
Block(-2,2,-2,minecraft:log2:1)
Block(-1,2,-2,minecraft:log2:1)
Block(-6,2,-1,minecraft:log2:1)
Block(-5,2,-1,minecraft:log2:1)
Block(-4,2,-1,minecraft:log2:1)
Block(-3,2,-1,minecraft:log2:1)
Block(-2,2,-1,minecraft:log2:1)
Block(-1,2,-1,minecraft:log2:1)
Block(-4,2,0,minecraft:log2:1)
Block(-3,2,0,minecraft:log2:1)
Block(-2,2,0,minecraft:log2:1)
Block(-2,2,1,minecraft:leaves2:1)
Block(-6,3,-5,minecraft:log2:1)
Block(-5,3,-5,minecraft:log2:1)
Block(-4,3,-5,minecraft:log2:1)
Block(-3,3,-5,minecraft:leaves2:1)
Block(-6,3,-4,minecraft:log2:1)
Block(-5,3,-4,minecraft:log2:1)
Block(-4,3,-4,minecraft:log2:1)
Block(-3,3,-4,minecraft:log2:1)
Block(-2,3,-4,minecraft:log2:1)
Block(-7,3,-3,minecraft:log2:1)
Block(-6,3,-3,minecraft:log2:1)
Block(-5,3,-3,minecraft:log2:1)
Block(-4,3,-3,minecraft:log2:1)
Block(-3,3,-3,minecraft:log2:1)
Block(-2,3,-3,minecraft:log2:1)
Block(-1,3,-3,minecraft:log2:1)
Block(-8,3,-2,minecraft:leaves2:1)
Block(-7,3,-2,minecraft:log2:1)
Block(-6,3,-2,minecraft:log2:1)
Block(-5,3,-2,minecraft:log2:1)
Block(-4,3,-2,minecraft:log2:1)
Block(-3,3,-2,minecraft:log2:1)
Block(-2,3,-2,minecraft:log2:1)
Block(-1,3,-2,minecraft:log2:1)
Block(-7,3,-1,minecraft:leaves2:1)
Block(-6,3,-1,minecraft:log2:1)
Block(-5,3,-1,minecraft:log2:1)
Block(-4,3,-1,minecraft:log2:1)
Block(-3,3,-1,minecraft:log2:1)
Block(-2,3,-1,minecraft:log2:1)
Block(-3,3,0,minecraft:log2:1)
Block(-2,3,0,minecraft:leaves2:1)
Block(10,4,-9,minecraft:leaves2:1)
Block(-3,4,-6,minecraft:leaves2:1)
Block(-5,4,-5,minecraft:log2:1)
Block(-4,4,-5,minecraft:log2:1)
Block(-3,4,-5,minecraft:log2:1)
Block(-6,4,-4,minecraft:log2:1)
Block(-5,4,-4,minecraft:log2:1)
Block(-4,4,-4,minecraft:log2:1)
Block(-3,4,-4,minecraft:log2:1)
Block(-2,4,-4,minecraft:log2:1)
Block(-1,4,-4,minecraft:log2:1)
Block(-7,4,-3,minecraft:log2:1)
Block(-6,4,-3,minecraft:log2:1)
Block(-5,4,-3,minecraft:log2:1)
Block(-4,4,-3,minecraft:log2:1)
Block(-3,4,-3,minecraft:log2:1)
Block(-2,4,-3,minecraft:log2:1)
Block(-1,4,-3,minecraft:log2:1)
Block(-8,4,-2,minecraft:leaves2:1)
Block(-7,4,-2,minecraft:log2:1)
Block(-6,4,-2,minecraft:log2:1)
Block(-5,4,-2,minecraft:log2:1)
Block(-4,4,-2,minecraft:log2:1)
Block(-3,4,-2,minecraft:log2:1)
Block(-2,4,-2,minecraft:log2:1)
Block(-7,4,-1,minecraft:leaves2:1)
Block(-5,4,-1,minecraft:log2:1)
Block(-4,4,-1,minecraft:log2:1)
Block(-3,4,-1,minecraft:log2:1)
Block(-2,4,-1,minecraft:log2:1)
Block(-3,4,0,minecraft:leaves2:1)
Block(10,5,-9,minecraft:leaves2:1)
Block(13,5,-8,minecraft:leaves2:1)
Block(-4,5,-6,minecraft:leaves2:1)
Block(-4,5,-5,minecraft:log2:1)
Block(-3,5,-5,minecraft:log2:1)
Block(-2,5,-5,minecraft:log2:1)
Block(-1,5,-5,minecraft:log2:1)
Block(1,5,-5,minecraft:leaves2:1)
Block(-6,5,-4,minecraft:log2:1)
Block(-5,5,-4,minecraft:log2:1)
Block(-4,5,-4,minecraft:log2:1)
Block(-3,5,-4,minecraft:log2:1)
Block(-2,5,-4,minecraft:log2:1)
Block(-1,5,-4,minecraft:log2:1)
Block(0,5,-4,minecraft:log2:1)
Block(1,5,-4,minecraft:log2:1)
Block(2,5,-4,minecraft:leaves2:1)
Block(-7,5,-3,minecraft:log2:1)
Block(-6,5,-3,minecraft:log2:1)
Block(-5,5,-3,minecraft:log2:1)
Block(-4,5,-3,minecraft:log2:1)
Block(-3,5,-3,minecraft:log2:1)
Block(-2,5,-3,minecraft:log2:1)
Block(-1,5,-3,minecraft:log2:1)
Block(0,5,-3,minecraft:log2:1)
Block(-6,5,-2,minecraft:log2:1)
Block(-5,5,-2,minecraft:log2:1)
Block(-4,5,-2,minecraft:log2:1)
Block(-3,5,-2,minecraft:log2:1)
Block(-2,5,-2,minecraft:log2:1)
Block(-6,5,-1,minecraft:leaves2:1)
Block(-5,5,-1,minecraft:log2:1)
Block(-4,5,-1,minecraft:log2:1)
Block(-3,5,-1,minecraft:log2:1)
Block(-2,5,-1,minecraft:log2:1)
Block(-4,5,0,minecraft:log2:1)
Block(-3,5,0,minecraft:leaves2:1)
Block(6,6,-12,minecraft:leaves2:1)
Block(11,6,-12,minecraft:leaves2:1)
Block(10,6,-9,minecraft:leaves2:1)
Block(5,6,-8,minecraft:leaves2:1)
Block(13,6,-8,minecraft:leaves2:1)
Block(3,6,-7,minecraft:log2:1)
Block(5,6,-7,minecraft:leaves2:1)
Block(-4,6,-6,minecraft:leaves2:1)
Block(0,6,-6,minecraft:leaves2:1)
Block(2,6,-6,minecraft:log2:1)
Block(3,6,-6,minecraft:log2:1)
Block(4,6,-6,minecraft:log2:1)
Block(6,6,-6,minecraft:leaves2:1)
Block(-4,6,-5,minecraft:log2:1)
Block(-3,6,-5,minecraft:log2:1)
Block(-2,6,-5,minecraft:log2:1)
Block(-1,6,-5,minecraft:log2:1)
Block(0,6,-5,minecraft:log2:1)
Block(1,6,-5,minecraft:log2:1)
Block(2,6,-5,minecraft:log2:1)
Block(3,6,-5,minecraft:log2:1)
Block(-5,6,-4,minecraft:log2:1)
Block(-4,6,-4,minecraft:log2:1)
Block(-3,6,-4,minecraft:log2:1)
Block(-2,6,-4,minecraft:log2:1)
Block(-1,6,-4,minecraft:log2:1)
Block(0,6,-4,minecraft:log2:1)
Block(1,6,-4,minecraft:log2:1)
Block(2,6,-4,minecraft:log2:1)
Block(-6,6,-3,minecraft:log2:1)
Block(-5,6,-3,minecraft:log2:1)
Block(-4,6,-3,minecraft:log2:1)
Block(-3,6,-3,minecraft:log2:1)
Block(-2,6,-3,minecraft:log2:1)
Block(-1,6,-3,minecraft:log2:1)
Block(0,6,-3,minecraft:log2:1)
Block(1,6,-3,minecraft:log2:1)
Block(2,6,-3,minecraft:leaves2:1)
Block(6,6,-3,minecraft:leaves2:1)
Block(10,6,-3,minecraft:leaves2:1)
Block(-6,6,-2,minecraft:log2:1)
Block(-5,6,-2,minecraft:log2:1)
Block(-4,6,-2,minecraft:log2:1)
Block(-3,6,-2,minecraft:log2:1)
Block(-2,6,-2,minecraft:log2:1)
Block(-1,6,-2,minecraft:log2:1)
Block(-6,6,-1,minecraft:log2:1)
Block(-5,6,-1,minecraft:log2:1)
Block(-4,6,-1,minecraft:log2:1)
Block(-3,6,-1,minecraft:log2:1)
Block(-2,6,-1,minecraft:log2:1)
Block(-6,6,0,minecraft:leaves2:1)
Block(-5,6,0,minecraft:log2:1)
Block(-4,6,0,minecraft:log2:1)
Block(-3,6,0,minecraft:log2:1)
Block(-4,6,1,minecraft:leaves2:1)
Block(6,7,-12,minecraft:leaves2:1)
Block(11,7,-12,minecraft:leaves2:1)
Block(5,7,-9,minecraft:leaves2:1)
Block(10,7,-9,minecraft:leaves2:1)
Block(13,7,-8,minecraft:leaves2:1)
Block(0,7,-7,minecraft:leaves2:1)
Block(1,7,-7,minecraft:log2:1)
Block(2,7,-7,minecraft:log2:1)
Block(3,7,-7,minecraft:log2:1)
Block(4,7,-7,minecraft:log2:1)
Block(5,7,-7,minecraft:log2:1)
Block(6,7,-7,minecraft:log2:1)
Block(7,7,-7,minecraft:log2:1)
Block(-1,7,-6,minecraft:log2:1)
Block(0,7,-6,minecraft:log2:1)
Block(1,7,-6,minecraft:log2:1)
Block(2,7,-6,minecraft:log2:1)
Block(3,7,-6,minecraft:log2:1)
Block(4,7,-6,minecraft:log2:1)
Block(5,7,-6,minecraft:log2:1)
Block(6,7,-6,minecraft:log2:1)
Block(-4,7,-5,minecraft:leaves2:1)
Block(-3,7,-5,minecraft:log2:1)
Block(-2,7,-5,minecraft:log2:1)
Block(-1,7,-5,minecraft:log2:1)
Block(0,7,-5,minecraft:log2:1)
Block(1,7,-5,minecraft:log2:1)
Block(2,7,-5,minecraft:log2:1)
Block(3,7,-5,minecraft:log2:1)
Block(4,7,-5,minecraft:log2:1)
Block(6,7,-5,minecraft:leaves2:1)
Block(12,7,-5,minecraft:leaves2:1)
Block(-5,7,-4,minecraft:log2:1)
Block(-4,7,-4,minecraft:log2:1)
Block(-3,7,-4,minecraft:log2:1)
Block(-2,7,-4,minecraft:log2:1)
Block(-1,7,-4,minecraft:log2:1)
Block(0,7,-4,minecraft:log2:1)
Block(1,7,-4,minecraft:log2:1)
Block(2,7,-4,minecraft:log2:1)
Block(3,7,-4,minecraft:log2:1)
Block(-6,7,-3,minecraft:log2:1)
Block(-5,7,-3,minecraft:log2:1)
Block(-4,7,-3,minecraft:log2:1)
Block(-3,7,-3,minecraft:log2:1)
Block(-2,7,-3,minecraft:log2:1)
Block(-1,7,-3,minecraft:log2:1)
Block(0,7,-3,minecraft:log2:1)
Block(1,7,-3,minecraft:log2:1)
Block(2,7,-3,minecraft:log2:1)
Block(3,7,-3,minecraft:leaves2:1)
Block(6,7,-3,minecraft:leaves2:1)
Block(10,7,-3,minecraft:leaves2:1)
Block(-6,7,-2,minecraft:log2:1)
Block(-5,7,-2,minecraft:log2:1)
Block(-4,7,-2,minecraft:log2:1)
Block(-3,7,-2,minecraft:log2:1)
Block(-2,7,-2,minecraft:log2:1)
Block(-1,7,-2,minecraft:log2:1)
Block(-6,7,-1,minecraft:log2:1)
Block(-5,7,-1,minecraft:log2:1)
Block(-4,7,-1,minecraft:log2:1)
Block(-3,7,-1,minecraft:log2:1)
Block(-2,7,-1,minecraft:log2:1)
Block(-6,7,0,minecraft:leaves2:1)
Block(-5,7,0,minecraft:log2:1)
Block(-4,7,0,minecraft:log2:1)
Block(-3,7,0,minecraft:log2:1)
Block(-4,7,1,minecraft:leaves2:1)
Block(8,8,-13,minecraft:leaves2:1)
Block(6,8,-12,minecraft:leaves2:1)
Block(10,8,-12,minecraft:leaves2:1)
Block(11,8,-12,minecraft:leaves2:1)
Block(12,8,-12,minecraft:leaves2:1)
Block(5,8,-11,minecraft:leaves2:1)
Block(6,8,-11,minecraft:leaves2:1)
Block(10,8,-11,minecraft:leaves2:1)
Block(11,8,-11,minecraft:leaves2:1)
Block(3,8,-10,minecraft:leaves2:1)
Block(4,8,-10,minecraft:leaves2:1)
Block(11,8,-10,minecraft:leaves2:1)
Block(12,8,-10,minecraft:leaves2:1)
Block(2,8,-9,minecraft:leaves2:1)
Block(5,8,-9,minecraft:leaves2:1)
Block(10,8,-9,minecraft:leaves2:1)
Block(5,8,-8,minecraft:log2:1)
Block(6,8,-8,minecraft:log2:1)
Block(7,8,-8,minecraft:log2:1)
Block(8,8,-8,minecraft:log2:1)
Block(13,8,-8,minecraft:leaves2:1)
Block(1,8,-7,minecraft:leaves2:1)
Block(2,8,-7,minecraft:log2:1)
Block(3,8,-7,minecraft:log2:1)
Block(4,8,-7,minecraft:log2:1)
Block(5,8,-7,minecraft:log2:1)
Block(6,8,-7,minecraft:log2:1)
Block(7,8,-7,minecraft:log2:1)
Block(8,8,-7,minecraft:log2:1)
Block(9,8,-7,minecraft:log2:1)
Block(13,8,-7,minecraft:leaves2:1)
Block(1,8,-6,minecraft:log2:1)
Block(2,8,-6,minecraft:log2:1)
Block(3,8,-6,minecraft:log2:1)
Block(4,8,-6,minecraft:log2:1)
Block(5,8,-6,minecraft:log2:1)
Block(6,8,-6,minecraft:log2:1)
Block(7,8,-6,minecraft:log2:1)
Block(12,8,-6,minecraft:leaves2:1)
Block(-3,8,-5,minecraft:leaves2:1)
Block(0,8,-5,minecraft:log2:1)
Block(1,8,-5,minecraft:log2:1)
Block(2,8,-5,minecraft:log2:1)
Block(3,8,-5,minecraft:log2:1)
Block(4,8,-5,minecraft:log2:1)
Block(5,8,-5,minecraft:log2:1)
Block(11,8,-5,minecraft:leaves2:1)
Block(-4,8,-4,minecraft:log2:1)
Block(-3,8,-4,minecraft:log2:1)
Block(-2,8,-4,minecraft:log2:1)
Block(-1,8,-4,minecraft:log2:1)
Block(0,8,-4,minecraft:log2:1)
Block(1,8,-4,minecraft:log2:1)
Block(2,8,-4,minecraft:log2:1)
Block(3,8,-4,minecraft:leaves2:1)
Block(5,8,-4,minecraft:leaves2:1)
Block(6,8,-4,minecraft:leaves2:1)
Block(10,8,-4,minecraft:leaves2:1)
Block(11,8,-4,minecraft:leaves2:1)
Block(-6,8,-3,minecraft:log2:1)
Block(-5,8,-3,minecraft:log2:1)
Block(-4,8,-3,minecraft:log2:1)
Block(-3,8,-3,minecraft:log2:1)
Block(-2,8,-3,minecraft:log2:1)
Block(-1,8,-3,minecraft:log2:1)
Block(0,8,-3,minecraft:log2:1)
Block(6,8,-3,minecraft:leaves2:1)
Block(8,8,-3,minecraft:leaves2:1)
Block(9,8,-3,minecraft:leaves2:1)
Block(10,8,-3,minecraft:leaves2:1)
Block(-6,8,-2,minecraft:log2:1)
Block(-5,8,-2,minecraft:log2:1)
Block(-4,8,-2,minecraft:log2:1)
Block(-3,8,-2,minecraft:log2:1)
Block(-2,8,-2,minecraft:log2:1)
Block(9,8,-2,minecraft:leaves2:1)
Block(-6,8,-1,minecraft:log2:1)
Block(-5,8,-1,minecraft:log2:1)
Block(-4,8,-1,minecraft:log2:1)
Block(-3,8,-1,minecraft:log2:1)
Block(-2,8,-1,minecraft:log2:1)
Block(-6,8,0,minecraft:log2:1)
Block(-5,8,0,minecraft:log2:1)
Block(-4,8,0,minecraft:log2:1)
Block(-3,8,0,minecraft:log2:1)
Block(-2,8,0,minecraft:log2:1)
Block(-5,8,1,minecraft:leaves2:1)
Block(-4,8,1,minecraft:log2:1)
Block(-3,8,1,minecraft:log2:1)
Block(8,9,-13,minecraft:leaves2:1)
Block(9,9,-13,minecraft:leaves2:1)
Block(6,9,-12,minecraft:leaves2:1)
Block(7,9,-12,minecraft:leaves2:1)
Block(8,9,-12,minecraft:leaves2:1)
Block(10,9,-12,minecraft:leaves2:1)
Block(12,9,-12,minecraft:leaves2:1)
Block(4,9,-11,minecraft:leaves2:1)
Block(5,9,-11,minecraft:leaves2:1)
Block(6,9,-11,minecraft:leaves2:1)
Block(7,9,-11,minecraft:leaves2:1)
Block(8,9,-11,minecraft:leaves2:1)
Block(9,9,-11,minecraft:leaves2:1)
Block(10,9,-11,minecraft:leaves2:1)
Block(11,9,-11,minecraft:leaves2:1)
Block(3,9,-10,minecraft:leaves2:1)
Block(4,9,-10,minecraft:leaves2:1)
Block(5,9,-10,minecraft:leaves2:1)
Block(7,9,-10,minecraft:leaves2:1)
Block(8,9,-10,minecraft:log2:1)
Block(9,9,-10,minecraft:leaves2:1)
Block(10,9,-10,minecraft:leaves2:1)
Block(11,9,-10,minecraft:leaves2:1)
Block(3,9,-9,minecraft:leaves2:1)
Block(4,9,-9,minecraft:leaves2:1)
Block(5,9,-9,minecraft:leaves2:1)
Block(6,9,-9,minecraft:leaves2:1)
Block(8,9,-9,minecraft:log2:1)
Block(10,9,-9,minecraft:leaves2:1)
Block(11,9,-9,minecraft:leaves2:1)
Block(12,9,-9,minecraft:leaves2:1)
Block(13,9,-9,minecraft:leaves2:1)
Block(1,9,-8,minecraft:leaves2:1)
Block(2,9,-8,minecraft:leaves2:1)
Block(3,9,-8,minecraft:leaves2:1)
Block(4,9,-8,minecraft:leaves2:1)
Block(5,9,-8,minecraft:leaves2:1)
Block(6,9,-8,minecraft:leaves2:1)
Block(7,9,-8,minecraft:leaves2:1)
Block(8,9,-8,minecraft:leaves2:1)
Block(9,9,-8,minecraft:leaves2:1)
Block(12,9,-8,minecraft:leaves2:1)
Block(1,9,-7,minecraft:leaves2:1)
Block(2,9,-7,minecraft:leaves2:1)
Block(3,9,-7,minecraft:leaves2:1)
Block(4,9,-7,minecraft:leaves2:1)
Block(5,9,-7,minecraft:leaves2:1)
Block(6,9,-7,minecraft:leaves2:1)
Block(7,9,-7,minecraft:leaves2:1)
Block(8,9,-7,minecraft:leaves2:1)
Block(9,9,-7,minecraft:leaves2:1)
Block(11,9,-7,minecraft:leaves2:1)
Block(12,9,-7,minecraft:leaves2:1)
Block(13,9,-7,minecraft:leaves2:1)
Block(2,9,-6,minecraft:leaves2:1)
Block(3,9,-6,minecraft:log2:1)
Block(4,9,-6,minecraft:leaves2:1)
Block(5,9,-6,minecraft:leaves2:1)
Block(6,9,-6,minecraft:leaves2:1)
Block(8,9,-6,minecraft:log2:1)
Block(9,9,-6,minecraft:leaves2:1)
Block(11,9,-6,minecraft:leaves2:1)
Block(12,9,-6,minecraft:leaves2:1)
Block(13,9,-6,minecraft:leaves2:1)
Block(3,9,-5,minecraft:leaves2:1)
Block(4,9,-5,minecraft:leaves2:1)
Block(5,9,-5,minecraft:leaves2:1)
Block(6,9,-5,minecraft:leaves2:1)
Block(8,9,-5,minecraft:log2:1)
Block(9,9,-5,minecraft:log2:1)
Block(10,9,-5,minecraft:leaves2:1)
Block(11,9,-5,minecraft:leaves2:1)
Block(-3,9,-4,minecraft:leaves2:1)
Block(4,9,-4,minecraft:leaves2:1)
Block(5,9,-4,minecraft:leaves2:1)
Block(6,9,-4,minecraft:leaves2:1)
Block(7,9,-4,minecraft:leaves2:1)
Block(8,9,-4,minecraft:leaves2:1)
Block(9,9,-4,minecraft:log2:1)
Block(10,9,-4,minecraft:leaves2:1)
Block(11,9,-4,minecraft:leaves2:1)
Block(12,9,-4,minecraft:leaves2:1)
Block(-5,9,-3,minecraft:log2:1)
Block(-4,9,-3,minecraft:log2:1)
Block(-3,9,-3,minecraft:log2:1)
Block(-2,9,-3,minecraft:leaves2:1)
Block(6,9,-3,minecraft:leaves2:1)
Block(7,9,-3,minecraft:leaves2:1)
Block(9,9,-3,minecraft:log2:1)
Block(10,9,-3,minecraft:leaves2:1)
Block(-6,9,-2,minecraft:log2:1)
Block(-5,9,-2,minecraft:log2:1)
Block(-4,9,-2,minecraft:log2:1)
Block(-3,9,-2,minecraft:log2:1)
Block(-2,9,-2,minecraft:log2:1)
Block(-1,9,-2,minecraft:leaves2:1)
Block(7,9,-2,minecraft:leaves2:1)
Block(9,9,-2,minecraft:leaves2:1)
Block(10,9,-2,minecraft:leaves2:1)
Block(-6,9,-1,minecraft:log2:1)
Block(-5,9,-1,minecraft:log2:1)
Block(-4,9,-1,minecraft:log2:1)
Block(-3,9,-1,minecraft:log2:1)
Block(-2,9,-1,minecraft:log2:1)
Block(-6,9,0,minecraft:log2:1)
Block(-5,9,0,minecraft:log2:1)
Block(-4,9,0,minecraft:log2:1)
Block(-3,9,0,minecraft:log2:1)
Block(-2,9,0,minecraft:log2:1)
Block(-6,9,1,minecraft:leaves2:1)
Block(-5,9,1,minecraft:log2:1)
Block(-4,9,1,minecraft:log2:1)
Block(-3,9,1,minecraft:log2:1)
Block(-2,9,1,minecraft:log2:1)
Block(-5,9,2,minecraft:leaves2:1)
Block(7,10,-14,minecraft:leaves2:1)
Block(8,10,-14,minecraft:leaves2:1)
Block(10,10,-14,minecraft:leaves2:1)
Block(5,10,-13,minecraft:leaves2:1)
Block(6,10,-13,minecraft:leaves2:1)
Block(7,10,-13,minecraft:leaves2:1)
Block(8,10,-13,minecraft:leaves2:1)
Block(9,10,-13,minecraft:leaves2:1)
Block(10,10,-13,minecraft:leaves2:1)
Block(11,10,-13,minecraft:leaves2:1)
Block(4,10,-12,minecraft:leaves2:1)
Block(5,10,-12,minecraft:leaves2:1)
Block(6,10,-12,minecraft:leaves2:1)
Block(7,10,-12,minecraft:leaves2:1)
Block(8,10,-12,minecraft:leaves2:1)
Block(9,10,-12,minecraft:leaves2:1)
Block(10,10,-12,minecraft:leaves2:1)
Block(11,10,-12,minecraft:leaves2:1)
Block(12,10,-12,minecraft:leaves2:1)
Block(3,10,-11,minecraft:leaves2:1)
Block(4,10,-11,minecraft:leaves2:1)
Block(5,10,-11,minecraft:leaves2:1)
Block(6,10,-11,minecraft:leaves2:1)
Block(7,10,-11,minecraft:leaves2:1)
Block(8,10,-11,minecraft:leaves2:1)
Block(9,10,-11,minecraft:leaves2:1)
Block(10,10,-11,minecraft:leaves2:1)
Block(11,10,-11,minecraft:leaves2:1)
Block(12,10,-11,minecraft:leaves2:1)
Block(13,10,-11,minecraft:leaves2:1)
Block(2,10,-10,minecraft:leaves2:1)
Block(4,10,-10,minecraft:leaves2:1)
Block(5,10,-10,minecraft:leaves2:1)
Block(6,10,-10,minecraft:leaves2:1)
Block(7,10,-10,minecraft:leaves2:1)
Block(8,10,-10,minecraft:leaves2:1)
Block(9,10,-10,minecraft:leaves2:1)
Block(10,10,-10,minecraft:leaves2:1)
Block(11,10,-10,minecraft:leaves2:1)
Block(12,10,-10,minecraft:leaves2:1)
Block(13,10,-10,minecraft:leaves2:1)
Block(2,10,-9,minecraft:leaves2:1)
Block(3,10,-9,minecraft:leaves2:1)
Block(4,10,-9,minecraft:leaves2:1)
Block(5,10,-9,minecraft:leaves2:1)
Block(7,10,-9,minecraft:leaves2:1)
Block(8,10,-9,minecraft:leaves2:1)
Block(9,10,-9,minecraft:leaves2:1)
Block(10,10,-9,minecraft:leaves2:1)
Block(12,10,-9,minecraft:leaves2:1)
Block(13,10,-9,minecraft:leaves2:1)
Block(14,10,-9,minecraft:leaves2:1)
Block(3,10,-8,minecraft:leaves2:1)
Block(4,10,-8,minecraft:leaves2:1)
Block(5,10,-8,minecraft:leaves2:1)
Block(6,10,-8,minecraft:leaves2:1)
Block(7,10,-8,minecraft:leaves2:1)
Block(8,10,-8,minecraft:leaves2:1)
Block(9,10,-8,minecraft:leaves2:1)
Block(11,10,-8,minecraft:leaves2:1)
Block(12,10,-8,minecraft:leaves2:1)
Block(13,10,-8,minecraft:leaves2:1)
Block(14,10,-8,minecraft:leaves2:1)
Block(3,10,-7,minecraft:leaves2:1)
Block(4,10,-7,minecraft:leaves2:1)
Block(5,10,-7,minecraft:leaves2:1)
Block(6,10,-7,minecraft:leaves2:1)
Block(8,10,-7,minecraft:leaves2:1)
Block(9,10,-7,minecraft:leaves2:1)
Block(10,10,-7,minecraft:leaves2:1)
Block(11,10,-7,minecraft:leaves2:1)
Block(12,10,-7,minecraft:leaves2:1)
Block(13,10,-7,minecraft:leaves2:1)
Block(14,10,-7,minecraft:leaves2:1)
Block(3,10,-6,minecraft:leaves2:1)
Block(4,10,-6,minecraft:leaves2:1)
Block(5,10,-6,minecraft:leaves2:1)
Block(6,10,-6,minecraft:leaves2:1)
Block(7,10,-6,minecraft:leaves2:1)
Block(8,10,-6,minecraft:leaves2:1)
Block(11,10,-6,minecraft:leaves2:1)
Block(4,10,-5,minecraft:leaves2:1)
Block(5,10,-5,minecraft:leaves2:1)
Block(6,10,-5,minecraft:leaves2:1)
Block(7,10,-5,minecraft:leaves2:1)
Block(8,10,-5,minecraft:leaves2:1)
Block(9,10,-5,minecraft:leaves2:1)
Block(10,10,-5,minecraft:leaves2:1)
Block(11,10,-5,minecraft:leaves2:1)
Block(5,10,-4,minecraft:leaves2:1)
Block(7,10,-4,minecraft:leaves2:1)
Block(8,10,-4,minecraft:leaves2:1)
Block(10,10,-4,minecraft:leaves2:1)
Block(-5,10,-3,minecraft:log2:1)
Block(-4,10,-3,minecraft:log2:1)
Block(5,10,-3,minecraft:leaves2:1)
Block(6,10,-3,minecraft:leaves2:1)
Block(7,10,-3,minecraft:leaves2:1)
Block(8,10,-3,minecraft:leaves2:1)
Block(9,10,-3,minecraft:leaves2:1)
Block(11,10,-3,minecraft:leaves2:1)
Block(-6,10,-2,minecraft:log2:1)
Block(-5,10,-2,minecraft:log2:1)
Block(-4,10,-2,minecraft:log2:1)
Block(-3,10,-2,minecraft:log2:1)
Block(-2,10,-2,minecraft:log2:1)
Block(6,10,-2,minecraft:leaves2:1)
Block(7,10,-2,minecraft:leaves2:1)
Block(8,10,-2,minecraft:leaves2:1)
Block(9,10,-2,minecraft:leaves2:1)
Block(-6,10,-1,minecraft:log2:1)
Block(-5,10,-1,minecraft:log2:1)
Block(-4,10,-1,minecraft:log2:1)
Block(-3,10,-1,minecraft:log2:1)
Block(-2,10,-1,minecraft:log2:1)
Block(-1,10,-1,minecraft:log2:1)
Block(0,10,-1,minecraft:leaves2:1)
Block(9,10,-1,minecraft:leaves2:1)
Block(-6,10,0,minecraft:leaves2:1)
Block(-5,10,0,minecraft:log2:1)
Block(-4,10,0,minecraft:log2:1)
Block(-3,10,0,minecraft:log2:1)
Block(-2,10,0,minecraft:log2:1)
Block(-1,10,0,minecraft:log2:1)
Block(-5,10,1,minecraft:log2:1)
Block(-4,10,1,minecraft:log2:1)
Block(-3,10,1,minecraft:log2:1)
Block(-2,10,1,minecraft:log2:1)
Block(-1,10,1,minecraft:log2:1)
Block(-4,10,2,minecraft:leaves2:1)
Block(-3,10,2,minecraft:log2:1)
Block(-2,10,2,minecraft:log2:1)
Block(-3,10,3,minecraft:leaves2:1)
Block(8,11,-13,minecraft:leaves2:1)
Block(9,11,-13,minecraft:leaves2:1)
Block(5,11,-12,minecraft:leaves2:1)
Block(7,11,-12,minecraft:leaves2:1)
Block(8,11,-12,minecraft:leaves2:1)
Block(10,11,-12,minecraft:leaves2:1)
Block(5,11,-11,minecraft:leaves2:1)
Block(6,11,-11,minecraft:leaves2:1)
Block(7,11,-11,minecraft:leaves2:1)
Block(8,11,-11,minecraft:leaves2:1)
Block(10,11,-11,minecraft:leaves2:1)
Block(11,11,-11,minecraft:leaves2:1)
Block(12,11,-11,minecraft:leaves2:1)
Block(4,11,-10,minecraft:leaves2:1)
Block(5,11,-10,minecraft:leaves2:1)
Block(7,11,-10,minecraft:leaves2:1)
Block(8,11,-10,minecraft:leaves2:1)
Block(9,11,-10,minecraft:leaves2:1)
Block(10,11,-10,minecraft:leaves2:1)
Block(12,11,-10,minecraft:leaves2:1)
Block(4,11,-9,minecraft:leaves2:1)
Block(5,11,-9,minecraft:leaves2:1)
Block(6,11,-9,minecraft:leaves2:1)
Block(7,11,-9,minecraft:leaves2:1)
Block(8,11,-9,minecraft:leaves2:1)
Block(9,11,-9,minecraft:leaves2:1)
Block(10,11,-9,minecraft:leaves2:1)
Block(11,11,-9,minecraft:leaves2:1)
Block(12,11,-9,minecraft:leaves2:1)
Block(13,11,-9,minecraft:leaves2:1)
Block(5,11,-8,minecraft:leaves2:1)
Block(6,11,-8,minecraft:leaves2:1)
Block(7,11,-8,minecraft:leaves2:1)
Block(8,11,-8,minecraft:leaves2:1)
Block(9,11,-8,minecraft:leaves2:1)
Block(10,11,-8,minecraft:leaves2:1)
Block(11,11,-8,minecraft:leaves2:1)
Block(12,11,-8,minecraft:leaves2:1)
Block(4,11,-7,minecraft:leaves2:1)
Block(5,11,-7,minecraft:leaves2:1)
Block(6,11,-7,minecraft:leaves2:1)
Block(7,11,-7,minecraft:leaves2:1)
Block(9,11,-7,minecraft:leaves2:1)
Block(10,11,-7,minecraft:leaves2:1)
Block(11,11,-7,minecraft:leaves2:1)
Block(12,11,-7,minecraft:leaves2:1)
Block(4,11,-6,minecraft:leaves2:1)
Block(5,11,-6,minecraft:leaves2:1)
Block(6,11,-6,minecraft:leaves2:1)
Block(7,11,-6,minecraft:leaves2:1)
Block(8,11,-6,minecraft:leaves2:1)
Block(9,11,-6,minecraft:leaves2:1)
Block(10,11,-6,minecraft:leaves2:1)
Block(11,11,-6,minecraft:leaves2:1)
Block(12,11,-6,minecraft:leaves2:1)
Block(13,11,-6,minecraft:leaves2:1)
Block(6,11,-5,minecraft:leaves2:1)
Block(7,11,-5,minecraft:leaves2:1)
Block(8,11,-5,minecraft:leaves2:1)
Block(9,11,-5,minecraft:leaves2:1)
Block(10,11,-5,minecraft:leaves2:1)
Block(11,11,-5,minecraft:leaves2:1)
Block(5,11,-4,minecraft:leaves2:1)
Block(7,11,-4,minecraft:leaves2:1)
Block(8,11,-4,minecraft:leaves2:1)
Block(10,11,-4,minecraft:leaves2:1)
Block(12,11,-4,minecraft:leaves2:1)
Block(8,11,-3,minecraft:leaves2:1)
Block(9,11,-3,minecraft:leaves2:1)
Block(-5,11,-2,minecraft:log2:1)
Block(-4,11,-2,minecraft:log2:1)
Block(-3,11,-2,minecraft:log2:1)
Block(-2,11,-2,minecraft:log2:1)
Block(-6,11,-1,minecraft:leaves2:1)
Block(-5,11,-1,minecraft:log2:1)
Block(-4,11,-1,minecraft:log2:1)
Block(-3,11,-1,minecraft:log2:1)
Block(-2,11,-1,minecraft:log2:1)
Block(-1,11,-1,minecraft:log2:1)
Block(-6,11,0,minecraft:leaves2:1)
Block(-5,11,0,minecraft:log2:1)
Block(-4,11,0,minecraft:log2:1)
Block(-3,11,0,minecraft:log2:1)
Block(-2,11,0,minecraft:log2:1)
Block(-1,11,0,minecraft:log2:1)
Block(0,11,0,minecraft:leaves2:1)
Block(-5,11,1,minecraft:log2:1)
Block(-4,11,1,minecraft:log2:1)
Block(-3,11,1,minecraft:log2:1)
Block(-2,11,1,minecraft:log2:1)
Block(-1,11,1,minecraft:log2:1)
Block(-4,11,2,minecraft:log2:1)
Block(-3,11,2,minecraft:log2:1)
Block(-2,11,2,minecraft:log2:1)
Block(-1,11,2,minecraft:log2:1)
Block(-2,11,3,minecraft:leaves2:1)
Block(-1,11,3,minecraft:log2:1)
Block(7,12,-11,minecraft:leaves2:1)
Block(9,12,-11,minecraft:leaves2:1)
Block(6,12,-10,minecraft:leaves2:1)
Block(8,12,-10,minecraft:leaves2:1)
Block(9,12,-10,minecraft:leaves2:1)
Block(10,12,-10,minecraft:leaves2:1)
Block(5,12,-9,minecraft:leaves2:1)
Block(6,12,-9,minecraft:leaves2:1)
Block(10,12,-9,minecraft:leaves2:1)
Block(11,12,-9,minecraft:leaves2:1)
Block(13,12,-9,minecraft:leaves2:1)
Block(5,12,-8,minecraft:leaves2:1)
Block(7,12,-8,minecraft:leaves2:1)
Block(9,12,-8,minecraft:leaves2:1)
Block(10,12,-8,minecraft:leaves2:1)
Block(11,12,-8,minecraft:leaves2:1)
Block(6,12,-7,minecraft:leaves2:1)
Block(7,12,-7,minecraft:leaves2:1)
Block(8,12,-7,minecraft:leaves2:1)
Block(9,12,-7,minecraft:leaves2:1)
Block(11,12,-7,minecraft:leaves2:1)
Block(6,12,-6,minecraft:leaves2:1)
Block(7,12,-6,minecraft:leaves2:1)
Block(9,12,-6,minecraft:leaves2:1)
Block(10,12,-6,minecraft:leaves2:1)
Block(8,12,-5,minecraft:leaves2:1)
Block(9,12,-5,minecraft:leaves2:1)
Block(11,12,-5,minecraft:leaves2:1)
Block(-4,12,-2,minecraft:log2:1)
Block(-3,12,-2,minecraft:log2:1)
Block(-6,12,-1,minecraft:leaves2:1)
Block(-5,12,-1,minecraft:log2:1)
Block(-4,12,-1,minecraft:log2:1)
Block(-3,12,-1,minecraft:log2:1)
Block(-2,12,-1,minecraft:log2:1)
Block(-1,12,-1,minecraft:log2:1)
Block(-5,12,0,minecraft:log2:1)
Block(-4,12,0,minecraft:log2:1)
Block(-3,12,0,minecraft:log2:1)
Block(-2,12,0,minecraft:log2:1)
Block(-1,12,0,minecraft:log2:1)
Block(0,12,0,minecraft:log2:1)
Block(-4,12,1,minecraft:log2:1)
Block(-3,12,1,minecraft:log2:1)
Block(-2,12,1,minecraft:log2:1)
Block(-1,12,1,minecraft:log2:1)
Block(0,12,1,minecraft:log2:1)
Block(1,12,1,minecraft:leaves2:1)
Block(-4,12,2,minecraft:log2:1)
Block(-3,12,2,minecraft:log2:1)
Block(-2,12,2,minecraft:log2:1)
Block(-1,12,2,minecraft:log2:1)
Block(0,12,2,minecraft:log2:1)
Block(-2,12,3,minecraft:log2:1)
Block(-1,12,3,minecraft:log2:1)
Block(0,12,3,minecraft:log2:1)
Block(1,12,3,minecraft:log2:1)
Block(-2,12,4,minecraft:leaves2:1)
Block(-1,12,4,minecraft:log2:1)
Block(0,12,4,minecraft:log2:1)
Block(1,12,4,minecraft:log2:1)
Block(2,12,4,minecraft:leaves2:1)
Block(1,12,5,minecraft:log2:1)
Block(2,12,5,minecraft:leaves2:1)
Block(1,12,6,minecraft:leaves2:1)
Block(-5,13,-1,minecraft:leaves2:1)
Block(-4,13,-1,minecraft:log2:1)
Block(-3,13,-1,minecraft:log2:1)
Block(-2,13,-1,minecraft:log2:1)
Block(-1,13,-1,minecraft:log2:1)
Block(-4,13,0,minecraft:log2:1)
Block(-3,13,0,minecraft:log2:1)
Block(-2,13,0,minecraft:log2:1)
Block(-1,13,0,minecraft:log2:1)
Block(0,13,0,minecraft:log2:1)
Block(-4,13,1,minecraft:log2:1)
Block(-3,13,1,minecraft:log2:1)
Block(-2,13,1,minecraft:log2:1)
Block(-1,13,1,minecraft:log2:1)
Block(0,13,1,minecraft:log2:1)
Block(-4,13,2,minecraft:log2:1)
Block(-3,13,2,minecraft:log2:1)
Block(-2,13,2,minecraft:log2:1)
Block(-1,13,2,minecraft:log2:1)
Block(0,13,2,minecraft:log2:1)
Block(1,13,2,minecraft:log2:1)
Block(2,13,2,minecraft:leaves2:1)
Block(-3,13,3,minecraft:log2:1)
Block(-2,13,3,minecraft:log2:1)
Block(-1,13,3,minecraft:log2:1)
Block(0,13,3,minecraft:log2:1)
Block(1,13,3,minecraft:log2:1)
Block(2,13,3,minecraft:log2:1)
Block(-2,13,4,minecraft:leaves2:1)
Block(-1,13,4,minecraft:log2:1)
Block(0,13,4,minecraft:log2:1)
Block(1,13,4,minecraft:log2:1)
Block(2,13,4,minecraft:log2:1)
Block(-1,13,5,minecraft:log2:1)
Block(0,13,5,minecraft:log2:1)
Block(1,13,5,minecraft:log2:1)
Block(2,13,5,minecraft:log2:1)
Block(3,13,5,minecraft:log2:1)
Block(0,13,6,minecraft:leaves2:1)
Block(1,13,6,minecraft:log2:1)
Block(2,13,6,minecraft:log2:1)
Block(3,13,6,minecraft:log2:1)
Block(4,13,6,minecraft:log2:1)
Block(2,13,7,minecraft:log2:1)
Block(3,13,7,minecraft:log2:1)
Block(-4,14,-1,minecraft:leaves2:1)
Block(-3,14,-1,minecraft:log2:1)
Block(-2,14,-1,minecraft:log2:1)
Block(-4,14,0,minecraft:log2:1)
Block(-3,14,0,minecraft:log2:1)
Block(-2,14,0,minecraft:log2:1)
Block(-1,14,0,minecraft:log2:1)
Block(0,14,0,minecraft:log2:1)
Block(-4,14,1,minecraft:log2:1)
Block(-3,14,1,minecraft:log2:1)
Block(-2,14,1,minecraft:log2:1)
Block(-1,14,1,minecraft:log2:1)
Block(0,14,1,minecraft:log2:1)
Block(1,14,1,minecraft:log2:1)
Block(-3,14,2,minecraft:log2:1)
Block(-2,14,2,minecraft:log2:1)
Block(-1,14,2,minecraft:log2:1)
Block(0,14,2,minecraft:log2:1)
Block(1,14,2,minecraft:log2:1)
Block(2,14,2,minecraft:leaves2:1)
Block(-3,14,3,minecraft:log2:1)
Block(-2,14,3,minecraft:log2:1)
Block(-1,14,3,minecraft:log2:1)
Block(0,14,3,minecraft:log2:1)
Block(1,14,3,minecraft:log2:1)
Block(2,14,3,minecraft:log2:1)
Block(-2,14,4,minecraft:log2:1)
Block(-1,14,4,minecraft:log2:1)
Block(0,14,4,minecraft:log2:1)
Block(1,14,4,minecraft:log2:1)
Block(2,14,4,minecraft:log2:1)
Block(-2,14,5,minecraft:leaves2:1)
Block(-1,14,5,minecraft:log2:1)
Block(0,14,5,minecraft:log2:1)
Block(1,14,5,minecraft:log2:1)
Block(2,14,5,minecraft:log2:1)
Block(3,14,5,minecraft:log2:1)
Block(4,14,5,minecraft:log2:1)
Block(7,14,5,minecraft:leaves2:1)
Block(0,14,6,minecraft:log2:1)
Block(1,14,6,minecraft:log2:1)
Block(2,14,6,minecraft:log2:1)
Block(3,14,6,minecraft:log2:1)
Block(4,14,6,minecraft:log2:1)
Block(0,14,7,minecraft:leaves2:1)
Block(1,14,7,minecraft:log2:1)
Block(2,14,7,minecraft:log2:1)
Block(3,14,7,minecraft:log2:1)
Block(4,14,7,minecraft:log2:1)
Block(5,14,7,minecraft:log2:1)
Block(2,14,8,minecraft:log2:1)
Block(3,14,8,minecraft:log2:1)
Block(4,14,8,minecraft:leaves2:1)
Block(5,14,8,minecraft:leaves2:1)
Block(10,14,10,minecraft:leaves2:1)
Block(7,14,14,minecraft:leaves2:1)
Block(-3,15,-1,minecraft:leaves2:1)
Block(-3,15,0,minecraft:log2:1)
Block(-2,15,0,minecraft:log2:1)
Block(-1,15,0,minecraft:log2:1)
Block(0,15,0,minecraft:log2:1)
Block(1,15,0,minecraft:log2:1)
Block(-3,15,1,minecraft:log2:1)
Block(-2,15,1,minecraft:log2:1)
Block(-1,15,1,minecraft:log2:1)
Block(0,15,1,minecraft:log2:1)
Block(1,15,1,minecraft:log2:1)
Block(-3,15,2,minecraft:log2:1)
Block(-2,15,2,minecraft:log2:1)
Block(-1,15,2,minecraft:log2:1)
Block(0,15,2,minecraft:log2:1)
Block(1,15,2,minecraft:log2:1)
Block(-3,15,3,minecraft:log2:1)
Block(-2,15,3,minecraft:log2:1)
Block(-1,15,3,minecraft:log2:1)
Block(0,15,3,minecraft:log2:1)
Block(1,15,3,minecraft:log2:1)
Block(2,15,3,minecraft:leaves2:1)
Block(-2,15,4,minecraft:log2:1)
Block(-1,15,4,minecraft:log2:1)
Block(0,15,4,minecraft:log2:1)
Block(1,15,4,minecraft:log2:1)
Block(2,15,4,minecraft:log2:1)
Block(3,15,4,minecraft:leaves2:1)
Block(-2,15,5,minecraft:leaves2:1)
Block(-1,15,5,minecraft:log2:1)
Block(0,15,5,minecraft:log2:1)
Block(1,15,5,minecraft:log2:1)
Block(2,15,5,minecraft:log2:1)
Block(3,15,5,minecraft:log2:1)
Block(4,15,5,minecraft:leaves2:1)
Block(7,15,5,minecraft:leaves2:1)
Block(1,15,6,minecraft:log2:1)
Block(2,15,6,minecraft:log2:1)
Block(3,15,6,minecraft:log2:1)
Block(4,15,6,minecraft:log2:1)
Block(5,15,6,minecraft:log2:1)
Block(1,15,7,minecraft:leaves2:1)
Block(2,15,7,minecraft:log2:1)
Block(3,15,7,minecraft:log2:1)
Block(4,15,7,minecraft:log2:1)
Block(5,15,7,minecraft:log2:1)
Block(6,15,7,minecraft:leaves2:1)
Block(9,15,7,minecraft:leaves2:1)
Block(2,15,8,minecraft:log2:1)
Block(3,15,8,minecraft:log2:1)
Block(4,15,8,minecraft:log2:1)
Block(5,15,8,minecraft:log2:1)
Block(3,15,9,minecraft:leaves2:1)
Block(4,15,10,minecraft:leaves2:1)
Block(10,15,10,minecraft:leaves2:1)
Block(5,15,12,minecraft:leaves2:1)
Block(7,15,14,minecraft:leaves2:1)
Block(0,16,-3,minecraft:log2:1)
Block(-1,16,-2,minecraft:log2:1)
Block(0,16,-2,minecraft:log2:1)
Block(1,16,-2,minecraft:log2:1)
Block(-2,16,-1,minecraft:leaves2:1)
Block(-1,16,-1,minecraft:log2:1)
Block(0,16,-1,minecraft:log2:1)
Block(1,16,-1,minecraft:log2:1)
Block(-2,16,0,minecraft:log2:1)
Block(-1,16,0,minecraft:log2:1)
Block(0,16,0,minecraft:log2:1)
Block(1,16,0,minecraft:log2:1)
Block(-3,16,1,minecraft:log2:1)
Block(-2,16,1,minecraft:log2:1)
Block(-1,16,1,minecraft:log2:1)
Block(0,16,1,minecraft:log2:1)
Block(1,16,1,minecraft:log2:1)
Block(-3,16,2,minecraft:log2:1)
Block(-2,16,2,minecraft:log2:1)
Block(-1,16,2,minecraft:log2:1)
Block(0,16,2,minecraft:log2:1)
Block(1,16,2,minecraft:log2:1)
Block(-3,16,3,minecraft:log2:1)
Block(-2,16,3,minecraft:log2:1)
Block(-1,16,3,minecraft:log2:1)
Block(0,16,3,minecraft:log2:1)
Block(1,16,3,minecraft:log2:1)
Block(-3,16,4,minecraft:log2:1)
Block(-2,16,4,minecraft:log2:1)
Block(-1,16,4,minecraft:log2:1)
Block(0,16,4,minecraft:log2:1)
Block(1,16,4,minecraft:log2:1)
Block(2,16,4,minecraft:leaves2:1)
Block(-2,16,5,minecraft:leaves2:1)
Block(-1,16,5,minecraft:log2:1)
Block(0,16,5,minecraft:log2:1)
Block(3,16,5,minecraft:leaves2:1)
Block(4,16,5,minecraft:leaves2:1)
Block(7,16,5,minecraft:leaves2:1)
Block(2,16,6,minecraft:leaves2:1)
Block(3,16,6,minecraft:log2:1)
Block(4,16,6,minecraft:log2:1)
Block(5,16,6,minecraft:leaves2:1)
Block(2,16,7,minecraft:log2:1)
Block(3,16,7,minecraft:log2:1)
Block(4,16,7,minecraft:log2:1)
Block(5,16,7,minecraft:log2:1)
Block(9,16,7,minecraft:leaves2:1)
Block(2,16,8,minecraft:leaves2:1)
Block(3,16,8,minecraft:log2:1)
Block(4,16,8,minecraft:log2:1)
Block(5,16,8,minecraft:log2:1)
Block(6,16,8,minecraft:log2:1)
Block(4,16,9,minecraft:log2:1)
Block(5,16,9,minecraft:log2:1)
Block(4,16,10,minecraft:leaves2:1)
Block(6,16,10,minecraft:leaves2:1)
Block(10,16,10,minecraft:leaves2:1)
Block(5,16,11,minecraft:leaves2:1)
Block(5,16,12,minecraft:leaves2:1)
Block(7,16,14,minecraft:leaves2:1)
Block(8,17,-5,minecraft:leaves2:1)
Block(0,17,-4,minecraft:log2:1)
Block(1,17,-4,minecraft:log2:1)
Block(-1,17,-3,minecraft:log2:1)
Block(0,17,-3,minecraft:log2:1)
Block(1,17,-3,minecraft:log2:1)
Block(2,17,-3,minecraft:log2:1)
Block(-2,17,-2,minecraft:leaves2:1)
Block(-1,17,-2,minecraft:log2:1)
Block(0,17,-2,minecraft:log2:1)
Block(1,17,-2,minecraft:log2:1)
Block(2,17,-2,minecraft:log2:1)
Block(-2,17,-1,minecraft:log2:1)
Block(-1,17,-1,minecraft:log2:1)
Block(0,17,-1,minecraft:log2:1)
Block(1,17,-1,minecraft:log2:1)
Block(-2,17,0,minecraft:log2:1)
Block(-1,17,0,minecraft:log2:1)
Block(0,17,0,minecraft:log2:1)
Block(1,17,0,minecraft:log2:1)
Block(-2,17,1,minecraft:log2:1)
Block(-1,17,1,minecraft:log2:1)
Block(0,17,1,minecraft:log2:1)
Block(-3,17,2,minecraft:log2:1)
Block(-2,17,2,minecraft:log2:1)
Block(-1,17,2,minecraft:log2:1)
Block(0,17,2,minecraft:log2:1)
Block(1,17,2,minecraft:log2:1)
Block(-3,17,3,minecraft:log2:1)
Block(-2,17,3,minecraft:log2:1)
Block(-1,17,3,minecraft:log2:1)
Block(0,17,3,minecraft:log2:1)
Block(1,17,3,minecraft:log2:1)
Block(-3,17,4,minecraft:log2:1)
Block(-2,17,4,minecraft:log2:1)
Block(-1,17,4,minecraft:log2:1)
Block(0,17,4,minecraft:log2:1)
Block(1,17,4,minecraft:log2:1)
Block(-3,17,5,minecraft:leaves2:1)
Block(-2,17,5,minecraft:log2:1)
Block(-1,17,5,minecraft:log2:1)
Block(0,17,5,minecraft:log2:1)
Block(5,17,5,minecraft:leaves2:1)
Block(6,17,5,minecraft:leaves2:1)
Block(7,17,5,minecraft:leaves2:1)
Block(3,17,6,minecraft:leaves2:1)
Block(4,17,6,minecraft:leaves2:1)
Block(5,17,6,minecraft:leaves2:1)
Block(9,17,6,minecraft:leaves2:1)
Block(4,17,7,minecraft:log2:1)
Block(5,17,7,minecraft:log2:1)
Block(6,17,7,minecraft:log2:1)
Block(9,17,7,minecraft:leaves2:1)
Block(10,17,7,minecraft:leaves2:1)
Block(4,17,8,minecraft:log2:1)
Block(5,17,8,minecraft:log2:1)
Block(6,17,8,minecraft:log2:1)
Block(10,17,8,minecraft:leaves2:1)
Block(3,17,9,minecraft:leaves2:1)
Block(4,17,9,minecraft:log2:1)
Block(5,17,9,minecraft:log2:1)
Block(6,17,9,minecraft:log2:1)
Block(7,17,9,minecraft:leaves2:1)
Block(4,17,10,minecraft:leaves2:1)
Block(5,17,10,minecraft:log2:1)
Block(6,17,10,minecraft:log2:1)
Block(7,17,10,minecraft:log2:1)
Block(10,17,10,minecraft:leaves2:1)
Block(4,17,11,minecraft:leaves2:1)
Block(9,17,11,minecraft:leaves2:1)
Block(5,17,12,minecraft:leaves2:1)
Block(6,17,13,minecraft:leaves2:1)
Block(7,17,13,minecraft:leaves2:1)
Block(7,17,14,minecraft:leaves2:1)
Block(1,18,-5,minecraft:log2:1)
Block(8,18,-5,minecraft:leaves2:1)
Block(0,18,-4,minecraft:log2:1)
Block(1,18,-4,minecraft:log2:1)
Block(2,18,-4,minecraft:log2:1)
Block(-1,18,-3,minecraft:log2:1)
Block(0,18,-3,minecraft:log2:1)
Block(1,18,-3,minecraft:log2:1)
Block(2,18,-3,minecraft:log2:1)
Block(-1,18,-2,minecraft:log2:1)
Block(0,18,-2,minecraft:log2:1)
Block(1,18,-2,minecraft:log2:1)
Block(2,18,-2,minecraft:log2:1)
Block(-2,18,-1,minecraft:leaves2:1)
Block(-1,18,-1,minecraft:log2:1)
Block(0,18,-1,minecraft:log2:1)
Block(1,18,-1,minecraft:log2:1)
Block(2,18,-1,minecraft:log2:1)
Block(-2,18,0,minecraft:log2:1)
Block(-1,18,0,minecraft:log2:1)
Block(0,18,0,minecraft:log2:1)
Block(-2,18,1,minecraft:log2:1)
Block(-1,18,1,minecraft:log2:1)
Block(0,18,1,minecraft:log2:1)
Block(-3,18,2,minecraft:log2:1)
Block(-2,18,2,minecraft:log2:1)
Block(-1,18,2,minecraft:log2:1)
Block(0,18,2,minecraft:log2:1)
Block(1,18,2,minecraft:log2:1)
Block(-3,18,3,minecraft:log2:1)
Block(-2,18,3,minecraft:log2:1)
Block(-1,18,3,minecraft:log2:1)
Block(0,18,3,minecraft:log2:1)
Block(1,18,3,minecraft:log2:1)
Block(2,18,3,minecraft:log2:1)
Block(-3,18,4,minecraft:log2:1)
Block(-2,18,4,minecraft:log2:1)
Block(-1,18,4,minecraft:log2:1)
Block(0,18,4,minecraft:log2:1)
Block(1,18,4,minecraft:log2:1)
Block(-3,18,5,minecraft:leaves2:1)
Block(-2,18,5,minecraft:log2:1)
Block(-1,18,5,minecraft:log2:1)
Block(0,18,5,minecraft:log2:1)
Block(1,18,5,minecraft:log2:1)
Block(5,18,5,minecraft:leaves2:1)
Block(6,18,5,minecraft:leaves2:1)
Block(8,18,5,minecraft:leaves2:1)
Block(0,18,6,minecraft:log2:1)
Block(4,18,6,minecraft:leaves2:1)
Block(5,18,6,minecraft:leaves2:1)
Block(6,18,6,minecraft:leaves2:1)
Block(7,18,6,minecraft:leaves2:1)
Block(8,18,6,minecraft:leaves2:1)
Block(9,18,6,minecraft:leaves2:1)
Block(10,18,6,minecraft:leaves2:1)
Block(4,18,7,minecraft:leaves2:1)
Block(5,18,7,minecraft:leaves2:1)
Block(6,18,7,minecraft:leaves2:1)
Block(8,18,7,minecraft:leaves2:1)
Block(3,18,8,minecraft:leaves2:1)
Block(5,18,8,minecraft:leaves2:1)
Block(6,18,8,minecraft:log2:1)
Block(9,18,8,minecraft:leaves2:1)
Block(10,18,8,minecraft:leaves2:1)
Block(11,18,8,minecraft:leaves2:1)
Block(3,18,9,minecraft:leaves2:1)
Block(4,18,9,minecraft:leaves2:1)
Block(5,18,9,minecraft:leaves2:1)
Block(6,18,9,minecraft:log2:1)
Block(7,18,9,minecraft:log2:1)
Block(10,18,9,minecraft:leaves2:1)
Block(11,18,9,minecraft:leaves2:1)
Block(3,18,10,minecraft:leaves2:1)
Block(5,18,10,minecraft:leaves2:1)
Block(6,18,10,minecraft:leaves2:1)
Block(7,18,10,minecraft:leaves2:1)
Block(8,18,10,minecraft:log2:1)
Block(9,18,10,minecraft:leaves2:1)
Block(10,18,10,minecraft:leaves2:1)
Block(11,18,10,minecraft:leaves2:1)
Block(4,18,11,minecraft:leaves2:1)
Block(5,18,11,minecraft:leaves2:1)
Block(7,18,11,minecraft:log2:1)
Block(9,18,11,minecraft:leaves2:1)
Block(10,18,11,minecraft:leaves2:1)
Block(4,18,12,minecraft:leaves2:1)
Block(5,18,12,minecraft:leaves2:1)
Block(6,18,12,minecraft:leaves2:1)
Block(7,18,12,minecraft:log2:1)
Block(8,18,12,minecraft:leaves2:1)
Block(9,18,12,minecraft:leaves2:1)
Block(6,18,13,minecraft:leaves2:1)
Block(7,18,13,minecraft:leaves2:1)
Block(8,18,13,minecraft:leaves2:1)
Block(9,18,13,minecraft:leaves2:1)
Block(7,18,14,minecraft:leaves2:1)
Block(8,18,14,minecraft:leaves2:1)
Block(4,19,-10,minecraft:leaves2:1)
Block(-2,19,-6,minecraft:leaves2:1)
Block(0,19,-5,minecraft:log2:1)
Block(1,19,-5,minecraft:log2:1)
Block(8,19,-5,minecraft:leaves2:1)
Block(0,19,-4,minecraft:log2:1)
Block(1,19,-4,minecraft:log2:1)
Block(2,19,-4,minecraft:log2:1)
Block(3,19,-4,minecraft:log2:1)
Block(0,19,-3,minecraft:log2:1)
Block(1,19,-3,minecraft:log2:1)
Block(2,19,-3,minecraft:log2:1)
Block(3,19,-3,minecraft:log2:1)
Block(0,19,-2,minecraft:log2:1)
Block(1,19,-2,minecraft:log2:1)
Block(2,19,-2,minecraft:log2:1)
Block(1,19,-1,minecraft:log2:1)
Block(-1,19,0,minecraft:leaves2:1)
Block(-2,19,1,minecraft:log2:1)
Block(-1,19,1,minecraft:log2:1)
Block(0,19,1,minecraft:log2:1)
Block(-3,19,2,minecraft:log2:1)
Block(-2,19,2,minecraft:log2:1)
Block(-1,19,2,minecraft:log2:1)
Block(0,19,2,minecraft:log2:1)
Block(1,19,2,minecraft:log2:1)
Block(-3,19,3,minecraft:log2:1)
Block(-2,19,3,minecraft:log2:1)
Block(-1,19,3,minecraft:log2:1)
Block(0,19,3,minecraft:log2:1)
Block(1,19,3,minecraft:log2:1)
Block(2,19,3,minecraft:log2:1)
Block(-3,19,4,minecraft:log2:1)
Block(-2,19,4,minecraft:log2:1)
Block(-1,19,4,minecraft:log2:1)
Block(0,19,4,minecraft:log2:1)
Block(1,19,4,minecraft:log2:1)
Block(2,19,4,minecraft:log2:1)
Block(-2,19,5,minecraft:log2:1)
Block(-1,19,5,minecraft:log2:1)
Block(0,19,5,minecraft:log2:1)
Block(1,19,5,minecraft:log2:1)
Block(6,19,5,minecraft:leaves2:1)
Block(7,19,5,minecraft:leaves2:1)
Block(-2,19,6,minecraft:leaves2:1)
Block(-1,19,6,minecraft:log2:1)
Block(0,19,6,minecraft:log2:1)
Block(5,19,6,minecraft:leaves2:1)
Block(6,19,6,minecraft:leaves2:1)
Block(7,19,6,minecraft:leaves2:1)
Block(8,19,6,minecraft:leaves2:1)
Block(9,19,6,minecraft:leaves2:1)
Block(5,19,7,minecraft:leaves2:1)
Block(7,19,7,minecraft:leaves2:1)
Block(8,19,7,minecraft:leaves2:1)
Block(9,19,7,minecraft:leaves2:1)
Block(10,19,7,minecraft:leaves2:1)
Block(4,19,8,minecraft:leaves2:1)
Block(5,19,8,minecraft:leaves2:1)
Block(6,19,8,minecraft:leaves2:1)
Block(7,19,8,minecraft:leaves2:1)
Block(8,19,8,minecraft:leaves2:1)
Block(9,19,8,minecraft:leaves2:1)
Block(10,19,8,minecraft:leaves2:1)
Block(11,19,8,minecraft:leaves2:1)
Block(3,19,9,minecraft:leaves2:1)
Block(5,19,9,minecraft:leaves2:1)
Block(6,19,9,minecraft:leaves2:1)
Block(7,19,9,minecraft:leaves2:1)
Block(8,19,9,minecraft:leaves2:1)
Block(9,19,9,minecraft:leaves2:1)
Block(10,19,9,minecraft:leaves2:1)
Block(11,19,9,minecraft:leaves2:1)
Block(6,19,10,minecraft:leaves2:1)
Block(7,19,10,minecraft:leaves2:1)
Block(8,19,10,minecraft:leaves2:1)
Block(9,19,10,minecraft:leaves2:1)
Block(10,19,10,minecraft:leaves2:1)
Block(4,19,11,minecraft:leaves2:1)
Block(5,19,11,minecraft:leaves2:1)
Block(6,19,11,minecraft:leaves2:1)
Block(7,19,11,minecraft:leaves2:1)
Block(8,19,11,minecraft:leaves2:1)
Block(9,19,11,minecraft:leaves2:1)
Block(5,19,12,minecraft:leaves2:1)
Block(6,19,12,minecraft:leaves2:1)
Block(7,19,12,minecraft:leaves2:1)
Block(8,19,12,minecraft:leaves2:1)
Block(9,19,12,minecraft:leaves2:1)
Block(7,19,13,minecraft:leaves2:1)
Block(8,19,13,minecraft:leaves2:1)
Block(4,20,-10,minecraft:leaves2:1)
Block(7,20,-7,minecraft:leaves2:1)
Block(-2,20,-6,minecraft:leaves2:1)
Block(0,20,-5,minecraft:log2:1)
Block(1,20,-5,minecraft:log2:1)
Block(2,20,-5,minecraft:log2:1)
Block(3,20,-5,minecraft:log2:1)
Block(8,20,-5,minecraft:leaves2:1)
Block(0,20,-4,minecraft:log2:1)
Block(1,20,-4,minecraft:log2:1)
Block(2,20,-4,minecraft:log2:1)
Block(3,20,-4,minecraft:log2:1)
Block(0,20,-3,minecraft:log2:1)
Block(1,20,-3,minecraft:log2:1)
Block(2,20,-3,minecraft:log2:1)
Block(7,20,-3,minecraft:leaves2:1)
Block(5,20,-2,minecraft:leaves2:1)
Block(-1,20,1,minecraft:log2:1)
Block(0,20,1,minecraft:leaves2:1)
Block(-2,20,2,minecraft:log2:1)
Block(-1,20,2,minecraft:log2:1)
Block(0,20,2,minecraft:log2:1)
Block(1,20,2,minecraft:log2:1)
Block(-3,20,3,minecraft:log2:1)
Block(-2,20,3,minecraft:log2:1)
Block(-1,20,3,minecraft:log2:1)
Block(0,20,3,minecraft:log2:1)
Block(1,20,3,minecraft:log2:1)
Block(2,20,3,minecraft:log2:1)
Block(-2,20,4,minecraft:log2:1)
Block(-1,20,4,minecraft:log2:1)
Block(0,20,4,minecraft:log2:1)
Block(1,20,4,minecraft:log2:1)
Block(2,20,4,minecraft:log2:1)
Block(-2,20,5,minecraft:log2:1)
Block(-1,20,5,minecraft:log2:1)
Block(0,20,5,minecraft:log2:1)
Block(1,20,5,minecraft:log2:1)
Block(2,20,5,minecraft:log2:1)
Block(-2,20,6,minecraft:leaves2:1)
Block(-1,20,6,minecraft:log2:1)
Block(0,20,6,minecraft:log2:1)
Block(1,20,6,minecraft:log2:1)
Block(7,20,6,minecraft:leaves2:1)
Block(9,20,7,minecraft:leaves2:1)
Block(6,20,8,minecraft:leaves2:1)
Block(7,20,8,minecraft:leaves2:1)
Block(8,20,8,minecraft:leaves2:1)
Block(10,20,8,minecraft:leaves2:1)
Block(6,20,9,minecraft:leaves2:1)
Block(7,20,9,minecraft:leaves2:1)
Block(8,20,9,minecraft:leaves2:1)
Block(9,20,9,minecraft:leaves2:1)
Block(10,20,9,minecraft:leaves2:1)
Block(6,20,10,minecraft:leaves2:1)
Block(8,20,10,minecraft:leaves2:1)
Block(9,20,10,minecraft:leaves2:1)
Block(6,20,11,minecraft:leaves2:1)
Block(7,20,11,minecraft:leaves2:1)
Block(8,20,11,minecraft:leaves2:1)
Block(7,20,12,minecraft:leaves2:1)
Block(4,21,-10,minecraft:leaves2:1)
Block(6,21,-10,minecraft:leaves2:1)
Block(0,21,-9,minecraft:leaves2:1)
Block(7,21,-7,minecraft:leaves2:1)
Block(-2,21,-6,minecraft:leaves2:1)
Block(3,21,-6,minecraft:log2:1)
Block(1,21,-5,minecraft:log2:1)
Block(2,21,-5,minecraft:log2:1)
Block(3,21,-5,minecraft:log2:1)
Block(8,21,-5,minecraft:leaves2:1)
Block(-1,21,-4,minecraft:leaves2:1)
Block(0,21,-4,minecraft:log2:1)
Block(1,21,-4,minecraft:log2:1)
Block(2,21,-4,minecraft:log2:1)
Block(3,21,-4,minecraft:log2:1)
Block(4,21,-4,minecraft:log2:1)
Block(1,21,-3,minecraft:log2:1)
Block(7,21,-3,minecraft:leaves2:1)
Block(3,21,-2,minecraft:leaves2:1)
Block(5,21,-2,minecraft:leaves2:1)
Block(-13,21,-1,minecraft:leaves2:1)
Block(1,21,1,minecraft:leaves2:1)
Block(-2,21,2,minecraft:log2:1)
Block(-1,21,2,minecraft:log2:1)
Block(0,21,2,minecraft:log2:1)
Block(1,21,2,minecraft:log2:1)
Block(-3,21,3,minecraft:leaves2:1)
Block(-2,21,3,minecraft:log2:1)
Block(-1,21,3,minecraft:log2:1)
Block(0,21,3,minecraft:log2:1)
Block(1,21,3,minecraft:log2:1)
Block(2,21,3,minecraft:log2:1)
Block(-3,21,4,minecraft:leaves2:1)
Block(-2,21,4,minecraft:log2:1)
Block(-1,21,4,minecraft:log2:1)
Block(0,21,4,minecraft:log2:1)
Block(1,21,4,minecraft:log2:1)
Block(2,21,4,minecraft:log2:1)
Block(-2,21,5,minecraft:log2:1)
Block(-1,21,5,minecraft:log2:1)
Block(0,21,5,minecraft:log2:1)
Block(1,21,5,minecraft:log2:1)
Block(2,21,5,minecraft:log2:1)
Block(-1,21,6,minecraft:log2:1)
Block(0,21,6,minecraft:log2:1)
Block(1,21,6,minecraft:log2:1)
Block(-1,21,7,minecraft:leaves2:1)
Block(1,22,-11,minecraft:leaves2:1)
Block(2,22,-11,minecraft:leaves2:1)
Block(3,22,-11,minecraft:leaves2:1)
Block(5,22,-11,minecraft:leaves2:1)
Block(3,22,-10,minecraft:leaves2:1)
Block(4,22,-10,minecraft:leaves2:1)
Block(5,22,-10,minecraft:leaves2:1)
Block(6,22,-10,minecraft:leaves2:1)
Block(-1,22,-9,minecraft:leaves2:1)
Block(0,22,-9,minecraft:leaves2:1)
Block(4,22,-9,minecraft:log2:1)
Block(5,22,-9,minecraft:leaves2:1)
Block(6,22,-9,minecraft:leaves2:1)
Block(7,22,-9,minecraft:leaves2:1)
Block(1,22,-8,minecraft:log2:1)
Block(4,22,-8,minecraft:log2:1)
Block(6,22,-8,minecraft:leaves2:1)
Block(7,22,-8,minecraft:leaves2:1)
Block(-1,22,-7,minecraft:leaves2:1)
Block(1,22,-7,minecraft:log2:1)
Block(2,22,-7,minecraft:log2:1)
Block(3,22,-7,minecraft:log2:1)
Block(4,22,-7,minecraft:log2:1)
Block(7,22,-7,minecraft:leaves2:1)
Block(8,22,-7,minecraft:leaves2:1)
Block(-2,22,-6,minecraft:leaves2:1)
Block(-1,22,-6,minecraft:leaves2:1)
Block(2,22,-6,minecraft:log2:1)
Block(3,22,-6,minecraft:log2:1)
Block(6,22,-6,minecraft:leaves2:1)
Block(7,22,-6,minecraft:leaves2:1)
Block(-1,22,-5,minecraft:leaves2:1)
Block(0,22,-5,minecraft:leaves2:1)
Block(1,22,-5,minecraft:log2:1)
Block(2,22,-5,minecraft:log2:1)
Block(3,22,-5,minecraft:leaves2:1)
Block(5,22,-5,minecraft:log2:1)
Block(6,22,-5,minecraft:log2:1)
Block(7,22,-5,minecraft:leaves2:1)
Block(8,22,-5,minecraft:leaves2:1)
Block(-1,22,-4,minecraft:leaves2:1)
Block(1,22,-4,minecraft:leaves2:1)
Block(3,22,-4,minecraft:leaves2:1)
Block(4,22,-4,minecraft:log2:1)
Block(5,22,-4,minecraft:log2:1)
Block(6,22,-4,minecraft:leaves2:1)
Block(7,22,-4,minecraft:leaves2:1)
Block(0,22,-3,minecraft:leaves2:1)
Block(2,22,-3,minecraft:leaves2:1)
Block(3,22,-3,minecraft:leaves2:1)
Block(4,22,-3,minecraft:leaves2:1)
Block(5,22,-3,minecraft:leaves2:1)
Block(6,22,-3,minecraft:leaves2:1)
Block(7,22,-3,minecraft:leaves2:1)
Block(1,22,-2,minecraft:leaves2:1)
Block(3,22,-2,minecraft:leaves2:1)
Block(4,22,-2,minecraft:leaves2:1)
Block(5,22,-2,minecraft:leaves2:1)
Block(6,22,-2,minecraft:leaves2:1)
Block(-13,22,-1,minecraft:leaves2:1)
Block(4,22,-1,minecraft:leaves2:1)
Block(-3,22,2,minecraft:leaves2:1)
Block(-1,22,2,minecraft:log2:1)
Block(0,22,2,minecraft:log2:1)
Block(1,22,2,minecraft:log2:1)
Block(2,22,2,minecraft:leaves2:1)
Block(-5,22,3,minecraft:log2:1)
Block(-4,22,3,minecraft:log2:1)
Block(-3,22,3,minecraft:log2:1)
Block(-2,22,3,minecraft:log2:1)
Block(-1,22,3,minecraft:log2:1)
Block(0,22,3,minecraft:log2:1)
Block(1,22,3,minecraft:log2:1)
Block(2,22,3,minecraft:log2:1)
Block(-4,22,4,minecraft:leaves2:1)
Block(-2,22,4,minecraft:log2:1)
Block(-1,22,4,minecraft:log2:1)
Block(0,22,4,minecraft:log2:1)
Block(1,22,4,minecraft:log2:1)
Block(2,22,4,minecraft:log2:1)
Block(-2,22,5,minecraft:log2:1)
Block(-1,22,5,minecraft:log2:1)
Block(0,22,5,minecraft:log2:1)
Block(1,22,5,minecraft:log2:1)
Block(2,22,5,minecraft:log2:1)
Block(-1,22,6,minecraft:log2:1)
Block(0,22,6,minecraft:log2:1)
Block(1,22,6,minecraft:log2:1)
Block(-1,22,7,minecraft:leaves2:1)
Block(2,23,-12,minecraft:leaves2:1)
Block(3,23,-12,minecraft:leaves2:1)
Block(0,23,-11,minecraft:leaves2:1)
Block(1,23,-11,minecraft:leaves2:1)
Block(2,23,-11,minecraft:leaves2:1)
Block(3,23,-11,minecraft:leaves2:1)
Block(4,23,-11,minecraft:leaves2:1)
Block(5,23,-11,minecraft:leaves2:1)
Block(-1,23,-10,minecraft:leaves2:1)
Block(0,23,-10,minecraft:leaves2:1)
Block(1,23,-10,minecraft:leaves2:1)
Block(2,23,-10,minecraft:leaves2:1)
Block(3,23,-10,minecraft:leaves2:1)
Block(4,23,-10,minecraft:leaves2:1)
Block(6,23,-10,minecraft:leaves2:1)
Block(7,23,-10,minecraft:leaves2:1)
Block(-1,23,-9,minecraft:leaves2:1)
Block(3,23,-9,minecraft:leaves2:1)
Block(4,23,-9,minecraft:leaves2:1)
Block(5,23,-9,minecraft:leaves2:1)
Block(-1,23,-8,minecraft:leaves2:1)
Block(0,23,-8,minecraft:leaves2:1)
Block(1,23,-8,minecraft:leaves2:1)
Block(5,23,-8,minecraft:leaves2:1)
Block(6,23,-8,minecraft:leaves2:1)
Block(7,23,-8,minecraft:leaves2:1)
Block(8,23,-8,minecraft:leaves2:1)
Block(-2,23,-7,minecraft:leaves2:1)
Block(0,23,-7,minecraft:leaves2:1)
Block(1,23,-7,minecraft:leaves2:1)
Block(3,23,-7,minecraft:leaves2:1)
Block(4,23,-7,minecraft:leaves2:1)
Block(6,23,-7,minecraft:leaves2:1)
Block(7,23,-7,minecraft:leaves2:1)
Block(8,23,-7,minecraft:leaves2:1)
Block(-2,23,-6,minecraft:leaves2:1)
Block(-1,23,-6,minecraft:leaves2:1)
Block(1,23,-6,minecraft:leaves2:1)
Block(2,23,-6,minecraft:leaves2:1)
Block(3,23,-6,minecraft:leaves2:1)
Block(4,23,-6,minecraft:leaves2:1)
Block(5,23,-6,minecraft:leaves2:1)
Block(6,23,-6,minecraft:leaves2:1)
Block(7,23,-6,minecraft:leaves2:1)
Block(8,23,-6,minecraft:leaves2:1)
Block(-2,23,-5,minecraft:leaves2:1)
Block(-1,23,-5,minecraft:leaves2:1)
Block(0,23,-5,minecraft:leaves2:1)
Block(1,23,-5,minecraft:leaves2:1)
Block(2,23,-5,minecraft:leaves2:1)
Block(3,23,-5,minecraft:leaves2:1)
Block(5,23,-5,minecraft:leaves2:1)
Block(6,23,-5,minecraft:leaves2:1)
Block(7,23,-5,minecraft:leaves2:1)
Block(8,23,-5,minecraft:leaves2:1)
Block(-2,23,-4,minecraft:leaves2:1)
Block(-1,23,-4,minecraft:leaves2:1)
Block(2,23,-4,minecraft:leaves2:1)
Block(3,23,-4,minecraft:leaves2:1)
Block(4,23,-4,minecraft:leaves2:1)
Block(5,23,-4,minecraft:leaves2:1)
Block(6,23,-4,minecraft:leaves2:1)
Block(7,23,-4,minecraft:leaves2:1)
Block(8,23,-4,minecraft:leaves2:1)
Block(-1,23,-3,minecraft:leaves2:1)
Block(0,23,-3,minecraft:leaves2:1)
Block(1,23,-3,minecraft:leaves2:1)
Block(2,23,-3,minecraft:leaves2:1)
Block(3,23,-3,minecraft:leaves2:1)
Block(4,23,-3,minecraft:leaves2:1)
Block(5,23,-3,minecraft:leaves2:1)
Block(6,23,-3,minecraft:leaves2:1)
Block(7,23,-3,minecraft:leaves2:1)
Block(-1,23,-2,minecraft:leaves2:1)
Block(0,23,-2,minecraft:leaves2:1)
Block(2,23,-2,minecraft:leaves2:1)
Block(3,23,-2,minecraft:leaves2:1)
Block(4,23,-2,minecraft:leaves2:1)
Block(5,23,-2,minecraft:leaves2:1)
Block(6,23,-2,minecraft:leaves2:1)
Block(7,23,-2,minecraft:leaves2:1)
Block(-13,23,-1,minecraft:leaves2:1)
Block(-10,23,-1,minecraft:leaves2:1)
Block(3,23,-1,minecraft:leaves2:1)
Block(4,23,-1,minecraft:leaves2:1)
Block(5,23,-1,minecraft:leaves2:1)
Block(6,23,-1,minecraft:leaves2:1)
Block(-7,23,0,minecraft:leaves2:1)
Block(-5,23,1,minecraft:log2:1)
Block(-2,23,1,minecraft:leaves2:1)
Block(-7,23,2,minecraft:log2:1)
Block(-6,23,2,minecraft:log2:1)
Block(-5,23,2,minecraft:log2:1)
Block(-4,23,2,minecraft:log2:1)
Block(-3,23,2,minecraft:log2:1)
Block(-2,23,2,minecraft:leaves2:1)
Block(-1,23,2,minecraft:log2:1)
Block(0,23,2,minecraft:log2:1)
Block(1,23,2,minecraft:log2:1)
Block(2,23,2,minecraft:leaves2:1)
Block(-8,23,3,minecraft:log2:1)
Block(-7,23,3,minecraft:log2:1)
Block(-6,23,3,minecraft:log2:1)
Block(-5,23,3,minecraft:log2:1)
Block(-4,23,3,minecraft:log2:1)
Block(-3,23,3,minecraft:log2:1)
Block(-2,23,3,minecraft:log2:1)
Block(-1,23,3,minecraft:log2:1)
Block(0,23,3,minecraft:log2:1)
Block(1,23,3,minecraft:log2:1)
Block(2,23,3,minecraft:log2:1)
Block(-6,23,4,minecraft:log2:1)
Block(-5,23,4,minecraft:log2:1)
Block(-4,23,4,minecraft:log2:1)
Block(-3,23,4,minecraft:log2:1)
Block(-2,23,4,minecraft:log2:1)
Block(-1,23,4,minecraft:log2:1)
Block(0,23,4,minecraft:log2:1)
Block(1,23,4,minecraft:log2:1)
Block(2,23,4,minecraft:log2:1)
Block(-12,23,5,minecraft:leaves2:1)
Block(-5,23,5,minecraft:leaves2:1)
Block(-2,23,5,minecraft:log2:1)
Block(-1,23,5,minecraft:log2:1)
Block(0,23,5,minecraft:log2:1)
Block(1,23,5,minecraft:log2:1)
Block(2,23,5,minecraft:log2:1)
Block(0,23,6,minecraft:log2:1)
Block(1,23,6,minecraft:log2:1)
Block(-7,23,7,minecraft:leaves2:1)
Block(0,23,7,minecraft:leaves2:1)
Block(4,24,-11,minecraft:leaves2:1)
Block(5,24,-11,minecraft:leaves2:1)
Block(0,24,-10,minecraft:leaves2:1)
Block(1,24,-10,minecraft:leaves2:1)
Block(2,24,-10,minecraft:leaves2:1)
Block(3,24,-10,minecraft:leaves2:1)
Block(4,24,-10,minecraft:leaves2:1)
Block(5,24,-10,minecraft:leaves2:1)
Block(6,24,-10,minecraft:leaves2:1)
Block(0,24,-9,minecraft:leaves2:1)
Block(1,24,-9,minecraft:leaves2:1)
Block(2,24,-9,minecraft:leaves2:1)
Block(3,24,-9,minecraft:leaves2:1)
Block(4,24,-9,minecraft:leaves2:1)
Block(5,24,-9,minecraft:leaves2:1)
Block(6,24,-9,minecraft:leaves2:1)
Block(7,24,-9,minecraft:leaves2:1)
Block(-1,24,-8,minecraft:leaves2:1)
Block(0,24,-8,minecraft:leaves2:1)
Block(1,24,-8,minecraft:leaves2:1)
Block(2,24,-8,minecraft:leaves2:1)
Block(3,24,-8,minecraft:leaves2:1)
Block(4,24,-8,minecraft:leaves2:1)
Block(5,24,-8,minecraft:leaves2:1)
Block(6,24,-8,minecraft:leaves2:1)
Block(7,24,-8,minecraft:leaves2:1)
Block(-1,24,-7,minecraft:leaves2:1)
Block(0,24,-7,minecraft:leaves2:1)
Block(1,24,-7,minecraft:leaves2:1)
Block(2,24,-7,minecraft:leaves2:1)
Block(3,24,-7,minecraft:leaves2:1)
Block(4,24,-7,minecraft:leaves2:1)
Block(5,24,-7,minecraft:leaves2:1)
Block(6,24,-7,minecraft:leaves2:1)
Block(7,24,-7,minecraft:leaves2:1)
Block(8,24,-7,minecraft:leaves2:1)
Block(-2,24,-6,minecraft:leaves2:1)
Block(-1,24,-6,minecraft:leaves2:1)
Block(0,24,-6,minecraft:leaves2:1)
Block(1,24,-6,minecraft:leaves2:1)
Block(2,24,-6,minecraft:leaves2:1)
Block(3,24,-6,minecraft:leaves2:1)
Block(4,24,-6,minecraft:leaves2:1)
Block(5,24,-6,minecraft:leaves2:1)
Block(6,24,-6,minecraft:leaves2:1)
Block(7,24,-6,minecraft:leaves2:1)
Block(-2,24,-5,minecraft:leaves2:1)
Block(-1,24,-5,minecraft:leaves2:1)
Block(0,24,-5,minecraft:leaves2:1)
Block(2,24,-5,minecraft:leaves2:1)
Block(3,24,-5,minecraft:leaves2:1)
Block(4,24,-5,minecraft:leaves2:1)
Block(5,24,-5,minecraft:leaves2:1)
Block(6,24,-5,minecraft:leaves2:1)
Block(7,24,-5,minecraft:leaves2:1)
Block(8,24,-5,minecraft:leaves2:1)
Block(-1,24,-4,minecraft:leaves2:1)
Block(1,24,-4,minecraft:leaves2:1)
Block(3,24,-4,minecraft:leaves2:1)
Block(4,24,-4,minecraft:leaves2:1)
Block(5,24,-4,minecraft:leaves2:1)
Block(6,24,-4,minecraft:leaves2:1)
Block(7,24,-4,minecraft:leaves2:1)
Block(0,24,-3,minecraft:leaves2:1)
Block(1,24,-3,minecraft:leaves2:1)
Block(2,24,-3,minecraft:leaves2:1)
Block(3,24,-3,minecraft:leaves2:1)
Block(4,24,-3,minecraft:leaves2:1)
Block(6,24,-3,minecraft:leaves2:1)
Block(7,24,-3,minecraft:leaves2:1)
Block(3,24,-2,minecraft:leaves2:1)
Block(5,24,-2,minecraft:leaves2:1)
Block(6,24,-2,minecraft:leaves2:1)
Block(-13,24,-1,minecraft:leaves2:1)
Block(-10,24,-1,minecraft:leaves2:1)
Block(4,24,-1,minecraft:leaves2:1)
Block(-7,24,0,minecraft:leaves2:1)
Block(-2,24,0,minecraft:leaves2:1)
Block(-6,24,1,minecraft:log2:1)
Block(-5,24,1,minecraft:log2:1)
Block(-4,24,1,minecraft:log2:1)
Block(-3,24,1,minecraft:log2:1)
Block(-2,24,1,minecraft:log2:1)
Block(-13,24,2,minecraft:leaves2:1)
Block(-8,24,2,minecraft:log2:1)
Block(-7,24,2,minecraft:log2:1)
Block(-6,24,2,minecraft:log2:1)
Block(-5,24,2,minecraft:log2:1)
Block(-4,24,2,minecraft:log2:1)
Block(-3,24,2,minecraft:log2:1)
Block(-2,24,2,minecraft:log2:1)
Block(-1,24,2,minecraft:log2:1)
Block(0,24,2,minecraft:log2:1)
Block(2,24,2,minecraft:leaves2:1)
Block(-9,24,3,minecraft:log2:1)
Block(-8,24,3,minecraft:log2:1)
Block(-7,24,3,minecraft:log2:1)
Block(-6,24,3,minecraft:log2:1)
Block(-5,24,3,minecraft:log2:1)
Block(-4,24,3,minecraft:log2:1)
Block(-3,24,3,minecraft:log2:1)
Block(-2,24,3,minecraft:log2:1)
Block(-1,24,3,minecraft:log2:1)
Block(0,24,3,minecraft:log2:1)
Block(1,24,3,minecraft:log2:1)
Block(2,24,3,minecraft:log2:1)
Block(-8,24,4,minecraft:log2:1)
Block(-7,24,4,minecraft:log2:1)
Block(-6,24,4,minecraft:log2:1)
Block(-5,24,4,minecraft:log2:1)
Block(-3,24,4,minecraft:log2:1)
Block(-2,24,4,minecraft:log2:1)
Block(-1,24,4,minecraft:log2:1)
Block(0,24,4,minecraft:log2:1)
Block(1,24,4,minecraft:log2:1)
Block(2,24,4,minecraft:log2:1)
Block(-12,24,5,minecraft:leaves2:1)
Block(-5,24,5,minecraft:leaves2:1)
Block(-2,24,5,minecraft:log2:1)
Block(-1,24,5,minecraft:log2:1)
Block(0,24,5,minecraft:log2:1)
Block(1,24,5,minecraft:log2:1)
Block(0,24,6,minecraft:log2:1)
Block(1,24,6,minecraft:log2:1)
Block(-10,24,7,minecraft:leaves2:1)
Block(-7,24,7,minecraft:leaves2:1)
Block(0,24,7,minecraft:leaves2:1)
Block(2,25,-10,minecraft:leaves2:1)
Block(3,25,-10,minecraft:leaves2:1)
Block(4,25,-10,minecraft:leaves2:1)
Block(5,25,-10,minecraft:leaves2:1)
Block(1,25,-9,minecraft:leaves2:1)
Block(2,25,-9,minecraft:leaves2:1)
Block(3,25,-9,minecraft:leaves2:1)
Block(4,25,-9,minecraft:leaves2:1)
Block(5,25,-9,minecraft:leaves2:1)
Block(6,25,-9,minecraft:leaves2:1)
Block(0,25,-8,minecraft:leaves2:1)
Block(1,25,-8,minecraft:leaves2:1)
Block(2,25,-8,minecraft:leaves2:1)
Block(3,25,-8,minecraft:leaves2:1)
Block(4,25,-8,minecraft:leaves2:1)
Block(5,25,-8,minecraft:leaves2:1)
Block(6,25,-8,minecraft:leaves2:1)
Block(7,25,-8,minecraft:leaves2:1)
Block(0,25,-7,minecraft:leaves2:1)
Block(1,25,-7,minecraft:leaves2:1)
Block(2,25,-7,minecraft:leaves2:1)
Block(3,25,-7,minecraft:leaves2:1)
Block(4,25,-7,minecraft:leaves2:1)
Block(5,25,-7,minecraft:leaves2:1)
Block(6,25,-7,minecraft:leaves2:1)
Block(7,25,-7,minecraft:leaves2:1)
Block(-1,25,-6,minecraft:leaves2:1)
Block(0,25,-6,minecraft:leaves2:1)
Block(1,25,-6,minecraft:leaves2:1)
Block(2,25,-6,minecraft:leaves2:1)
Block(3,25,-6,minecraft:leaves2:1)
Block(4,25,-6,minecraft:leaves2:1)
Block(5,25,-6,minecraft:leaves2:1)
Block(6,25,-6,minecraft:leaves2:1)
Block(7,25,-6,minecraft:leaves2:1)
Block(-1,25,-5,minecraft:leaves2:1)
Block(0,25,-5,minecraft:leaves2:1)
Block(1,25,-5,minecraft:leaves2:1)
Block(2,25,-5,minecraft:leaves2:1)
Block(3,25,-5,minecraft:leaves2:1)
Block(4,25,-5,minecraft:leaves2:1)
Block(5,25,-5,minecraft:leaves2:1)
Block(6,25,-5,minecraft:leaves2:1)
Block(0,25,-4,minecraft:leaves2:1)
Block(1,25,-4,minecraft:leaves2:1)
Block(2,25,-4,minecraft:leaves2:1)
Block(3,25,-4,minecraft:leaves2:1)
Block(4,25,-4,minecraft:leaves2:1)
Block(5,25,-4,minecraft:leaves2:1)
Block(6,25,-4,minecraft:leaves2:1)
Block(3,25,-3,minecraft:leaves2:1)
Block(4,25,-3,minecraft:leaves2:1)
Block(5,25,-3,minecraft:leaves2:1)
Block(4,25,-2,minecraft:leaves2:1)
Block(-13,25,-1,minecraft:leaves2:1)
Block(-10,25,-1,minecraft:leaves2:1)
Block(-7,25,0,minecraft:leaves2:1)
Block(-3,25,0,minecraft:leaves2:1)
Block(-5,25,1,minecraft:log2:1)
Block(-4,25,1,minecraft:log2:1)
Block(-3,25,1,minecraft:log2:1)
Block(-2,25,1,minecraft:log2:1)
Block(-1,25,1,minecraft:log2:1)
Block(-13,25,2,minecraft:leaves2:1)
Block(-9,25,2,minecraft:log2:1)
Block(-8,25,2,minecraft:log2:1)
Block(-7,25,2,minecraft:log2:1)
Block(-6,25,2,minecraft:log2:1)
Block(-5,25,2,minecraft:log2:1)
Block(-4,25,2,minecraft:log2:1)
Block(-3,25,2,minecraft:log2:1)
Block(-2,25,2,minecraft:log2:1)
Block(-1,25,2,minecraft:log2:1)
Block(0,25,2,minecraft:log2:1)
Block(-9,25,3,minecraft:log2:1)
Block(-8,25,3,minecraft:log2:1)
Block(-7,25,3,minecraft:log2:1)
Block(-6,25,3,minecraft:log2:1)
Block(-5,25,3,minecraft:log2:1)
Block(-4,25,3,minecraft:log2:1)
Block(-3,25,3,minecraft:log2:1)
Block(-2,25,3,minecraft:log2:1)
Block(-1,25,3,minecraft:log2:1)
Block(0,25,3,minecraft:log2:1)
Block(1,25,3,minecraft:log2:1)
Block(2,25,3,minecraft:leaves2:1)
Block(-9,25,4,minecraft:log2:1)
Block(-8,25,4,minecraft:log2:1)
Block(-7,25,4,minecraft:log2:1)
Block(-6,25,4,minecraft:log2:1)
Block(-2,25,4,minecraft:log2:1)
Block(-1,25,4,minecraft:log2:1)
Block(0,25,4,minecraft:log2:1)
Block(1,25,4,minecraft:log2:1)
Block(2,25,4,minecraft:log2:1)
Block(-12,25,5,minecraft:leaves2:1)
Block(-6,25,5,minecraft:leaves2:1)
Block(-1,25,5,minecraft:log2:1)
Block(0,25,5,minecraft:log2:1)
Block(1,25,5,minecraft:log2:1)
Block(-10,25,6,minecraft:leaves2:1)
Block(-1,25,6,minecraft:log2:1)
Block(0,25,6,minecraft:log2:1)
Block(1,25,6,minecraft:log2:1)
Block(-10,25,7,minecraft:leaves2:1)
Block(-7,25,7,minecraft:leaves2:1)
Block(1,25,7,minecraft:leaves2:1)
Block(2,26,-9,minecraft:leaves2:1)
Block(4,26,-9,minecraft:leaves2:1)
Block(1,26,-8,minecraft:leaves2:1)
Block(4,26,-8,minecraft:leaves2:1)
Block(5,26,-8,minecraft:leaves2:1)
Block(1,26,-7,minecraft:leaves2:1)
Block(2,26,-7,minecraft:leaves2:1)
Block(4,26,-7,minecraft:leaves2:1)
Block(6,26,-7,minecraft:leaves2:1)
Block(0,26,-6,minecraft:leaves2:1)
Block(1,26,-6,minecraft:leaves2:1)
Block(3,26,-6,minecraft:leaves2:1)
Block(5,26,-6,minecraft:leaves2:1)
Block(0,26,-5,minecraft:leaves2:1)
Block(1,26,-5,minecraft:leaves2:1)
Block(2,26,-5,minecraft:leaves2:1)
Block(3,26,-5,minecraft:leaves2:1)
Block(4,26,-5,minecraft:leaves2:1)
Block(5,26,-5,minecraft:leaves2:1)
Block(1,26,-4,minecraft:leaves2:1)
Block(4,26,-4,minecraft:leaves2:1)
Block(-11,26,-2,minecraft:leaves2:1)
Block(-10,26,-2,minecraft:leaves2:1)
Block(-13,26,-1,minecraft:leaves2:1)
Block(-11,26,-1,minecraft:leaves2:1)
Block(-10,26,-1,minecraft:leaves2:1)
Block(-9,26,-1,minecraft:leaves2:1)
Block(-13,26,0,minecraft:leaves2:1)
Block(-10,26,0,minecraft:log2:1)
Block(-9,26,0,minecraft:log2:1)
Block(-7,26,0,minecraft:leaves2:1)
Block(-14,26,1,minecraft:leaves2:1)
Block(-13,26,1,minecraft:leaves2:1)
Block(-9,26,1,minecraft:log2:1)
Block(-8,26,1,minecraft:leaves2:1)
Block(-7,26,1,minecraft:leaves2:1)
Block(-6,26,1,minecraft:leaves2:1)
Block(-4,26,1,minecraft:leaves2:1)
Block(-3,26,1,minecraft:log2:1)
Block(-2,26,1,minecraft:log2:1)
Block(-1,26,1,minecraft:log2:1)
Block(-13,26,2,minecraft:leaves2:1)
Block(-12,26,2,minecraft:leaves2:1)
Block(-11,26,2,minecraft:log2:1)
Block(-10,26,2,minecraft:log2:1)
Block(-9,26,2,minecraft:log2:1)
Block(-8,26,2,minecraft:log2:1)
Block(-7,26,2,minecraft:leaves2:1)
Block(-4,26,2,minecraft:log2:1)
Block(-3,26,2,minecraft:log2:1)
Block(-2,26,2,minecraft:log2:1)
Block(-1,26,2,minecraft:log2:1)
Block(0,26,2,minecraft:log2:1)
Block(3,26,2,minecraft:leaves2:1)
Block(4,26,2,minecraft:leaves2:1)
Block(-13,26,3,minecraft:leaves2:1)
Block(-9,26,3,minecraft:log2:1)
Block(-8,26,3,minecraft:log2:1)
Block(-7,26,3,minecraft:log2:1)
Block(-6,26,3,minecraft:leaves2:1)
Block(-3,26,3,minecraft:log2:1)
Block(-2,26,3,minecraft:log2:1)
Block(-1,26,3,minecraft:log2:1)
Block(0,26,3,minecraft:log2:1)
Block(1,26,3,minecraft:log2:1)
Block(2,26,3,minecraft:leaves2:1)
Block(-12,26,4,minecraft:leaves2:1)
Block(-8,26,4,minecraft:log2:1)
Block(-7,26,4,minecraft:leaves2:1)
Block(-6,26,4,minecraft:leaves2:1)
Block(-5,26,4,minecraft:leaves2:1)
Block(-1,26,4,minecraft:log2:1)
Block(0,26,4,minecraft:log2:1)
Block(1,26,4,minecraft:log2:1)
Block(2,26,4,minecraft:log2:1)
Block(-12,26,5,minecraft:leaves2:1)
Block(-6,26,5,minecraft:leaves2:1)
Block(-1,26,5,minecraft:log2:1)
Block(0,26,5,minecraft:log2:1)
Block(1,26,5,minecraft:log2:1)
Block(-12,26,6,minecraft:leaves2:1)
Block(-10,26,6,minecraft:leaves2:1)
Block(-7,26,6,minecraft:leaves2:1)
Block(-6,26,6,minecraft:leaves2:1)
Block(-1,26,6,minecraft:log2:1)
Block(0,26,6,minecraft:log2:1)
Block(1,26,6,minecraft:leaves2:1)
Block(-11,26,7,minecraft:leaves2:1)
Block(-10,26,7,minecraft:leaves2:1)
Block(-7,26,7,minecraft:leaves2:1)
Block(-8,26,8,minecraft:leaves2:1)
Block(3,27,-3,minecraft:leaves2:1)
Block(4,27,-3,minecraft:leaves2:1)
Block(-13,27,-2,minecraft:leaves2:1)
Block(-12,27,-2,minecraft:leaves2:1)
Block(-10,27,-2,minecraft:leaves2:1)
Block(-9,27,-2,minecraft:leaves2:1)
Block(4,27,-2,minecraft:log2:1)
Block(-14,27,-1,minecraft:leaves2:1)
Block(-13,27,-1,minecraft:leaves2:1)
Block(-12,27,-1,minecraft:leaves2:1)
Block(-11,27,-1,minecraft:leaves2:1)
Block(-10,27,-1,minecraft:leaves2:1)
Block(-9,27,-1,minecraft:leaves2:1)
Block(-8,27,-1,minecraft:leaves2:1)
Block(-7,27,-1,minecraft:leaves2:1)
Block(3,27,-1,minecraft:log2:1)
Block(4,27,-1,minecraft:log2:1)
Block(5,27,-1,minecraft:log2:1)
Block(-15,27,0,minecraft:leaves2:1)
Block(-14,27,0,minecraft:leaves2:1)
Block(-13,27,0,minecraft:leaves2:1)
Block(-12,27,0,minecraft:leaves2:1)
Block(-11,27,0,minecraft:leaves2:1)
Block(-10,27,0,minecraft:leaves2:1)
Block(-9,27,0,minecraft:leaves2:1)
Block(-8,27,0,minecraft:leaves2:1)
Block(-7,27,0,minecraft:leaves2:1)
Block(-6,27,0,minecraft:leaves2:1)
Block(2,27,0,minecraft:log2:1)
Block(3,27,0,minecraft:log2:1)
Block(4,27,0,minecraft:log2:1)
Block(-15,27,1,minecraft:leaves2:1)
Block(-14,27,1,minecraft:leaves2:1)
Block(-13,27,1,minecraft:leaves2:1)
Block(-12,27,1,minecraft:leaves2:1)
Block(-11,27,1,minecraft:leaves2:1)
Block(-10,27,1,minecraft:leaves2:1)
Block(-9,27,1,minecraft:log2:1)
Block(-8,27,1,minecraft:leaves2:1)
Block(-7,27,1,minecraft:leaves2:1)
Block(-6,27,1,minecraft:leaves2:1)
Block(-5,27,1,minecraft:leaves2:1)
Block(-2,27,1,minecraft:log2:1)
Block(-1,27,1,minecraft:log2:1)
Block(0,27,1,minecraft:log2:1)
Block(1,27,1,minecraft:log2:1)
Block(2,27,1,minecraft:log2:1)
Block(3,27,1,minecraft:log2:1)
Block(4,27,1,minecraft:log2:1)
Block(5,27,1,minecraft:leaves2:1)
Block(-15,27,2,minecraft:leaves2:1)
Block(-14,27,2,minecraft:leaves2:1)
Block(-13,27,2,minecraft:leaves2:1)
Block(-12,27,2,minecraft:leaves2:1)
Block(-11,27,2,minecraft:leaves2:1)
Block(-10,27,2,minecraft:log2:1)
Block(-9,27,2,minecraft:log2:1)
Block(-8,27,2,minecraft:leaves2:1)
Block(-7,27,2,minecraft:leaves2:1)
Block(-6,27,2,minecraft:leaves2:1)
Block(-5,27,2,minecraft:leaves2:1)
Block(-3,27,2,minecraft:log2:1)
Block(-2,27,2,minecraft:log2:1)
Block(-1,27,2,minecraft:log2:1)
Block(0,27,2,minecraft:log2:1)
Block(1,27,2,minecraft:log2:1)
Block(2,27,2,minecraft:log2:1)
Block(3,27,2,minecraft:log2:1)
Block(4,27,2,minecraft:log2:1)
Block(-15,27,3,minecraft:leaves2:1)
Block(-14,27,3,minecraft:leaves2:1)
Block(-13,27,3,minecraft:leaves2:1)
Block(-12,27,3,minecraft:leaves2:1)
Block(-11,27,3,minecraft:leaves2:1)
Block(-10,27,3,minecraft:leaves2:1)
Block(-9,27,3,minecraft:log2:1)
Block(-8,27,3,minecraft:leaves2:1)
Block(-7,27,3,minecraft:leaves2:1)
Block(-6,27,3,minecraft:leaves2:1)
Block(-5,27,3,minecraft:leaves2:1)
Block(-3,27,3,minecraft:log2:1)
Block(-2,27,3,minecraft:log2:1)
Block(-1,27,3,minecraft:log2:1)
Block(0,27,3,minecraft:log2:1)
Block(1,27,3,minecraft:log2:1)
Block(2,27,3,minecraft:log2:1)
Block(3,27,3,minecraft:log2:1)
Block(-14,27,4,minecraft:leaves2:1)
Block(-13,27,4,minecraft:leaves2:1)
Block(-12,27,4,minecraft:leaves2:1)
Block(-11,27,4,minecraft:leaves2:1)
Block(-8,27,4,minecraft:leaves2:1)
Block(-7,27,4,minecraft:leaves2:1)
Block(-6,27,4,minecraft:leaves2:1)
Block(-5,27,4,minecraft:leaves2:1)
Block(-2,27,4,minecraft:log2:1)
Block(-1,27,4,minecraft:log2:1)
Block(0,27,4,minecraft:log2:1)
Block(1,27,4,minecraft:log2:1)
Block(2,27,4,minecraft:log2:1)
Block(-14,27,5,minecraft:leaves2:1)
Block(-13,27,5,minecraft:leaves2:1)
Block(-12,27,5,minecraft:leaves2:1)
Block(-11,27,5,minecraft:leaves2:1)
Block(-10,27,5,minecraft:leaves2:1)
Block(-9,27,5,minecraft:leaves2:1)
Block(-8,27,5,minecraft:leaves2:1)
Block(-7,27,5,minecraft:leaves2:1)
Block(-6,27,5,minecraft:leaves2:1)
Block(-5,27,5,minecraft:leaves2:1)
Block(-1,27,5,minecraft:log2:1)
Block(0,27,5,minecraft:log2:1)
Block(1,27,5,minecraft:log2:1)
Block(2,27,5,minecraft:log2:1)
Block(-12,27,6,minecraft:leaves2:1)
Block(-11,27,6,minecraft:leaves2:1)
Block(-10,27,6,minecraft:leaves2:1)
Block(-9,27,6,minecraft:leaves2:1)
Block(-8,27,6,minecraft:leaves2:1)
Block(-6,27,6,minecraft:leaves2:1)
Block(-1,27,6,minecraft:log2:1)
Block(0,27,6,minecraft:log2:1)
Block(1,27,6,minecraft:log2:1)
Block(2,27,6,minecraft:leaves2:1)
Block(-12,27,7,minecraft:leaves2:1)
Block(-11,27,7,minecraft:leaves2:1)
Block(-9,27,7,minecraft:leaves2:1)
Block(-8,27,7,minecraft:leaves2:1)
Block(-7,27,7,minecraft:leaves2:1)
Block(-6,27,7,minecraft:leaves2:1)
Block(-10,27,8,minecraft:leaves2:1)
Block(-9,27,8,minecraft:leaves2:1)
Block(-8,27,8,minecraft:leaves2:1)
Block(-7,27,8,minecraft:leaves2:1)
Block(3,28,-12,minecraft:leaves2:1)
Block(4,28,-4,minecraft:log2:1)
Block(5,28,-4,minecraft:leaves2:1)
Block(3,28,-3,minecraft:log2:1)
Block(4,28,-3,minecraft:log2:1)
Block(5,28,-3,minecraft:log2:1)
Block(-10,28,-2,minecraft:leaves2:1)
Block(2,28,-2,minecraft:leaves2:1)
Block(3,28,-2,minecraft:log2:1)
Block(4,28,-2,minecraft:log2:1)
Block(5,28,-2,minecraft:log2:1)
Block(10,28,-2,minecraft:leaves2:1)
Block(-14,28,-1,minecraft:leaves2:1)
Block(-12,28,-1,minecraft:leaves2:1)
Block(-11,28,-1,minecraft:leaves2:1)
Block(-10,28,-1,minecraft:leaves2:1)
Block(-9,28,-1,minecraft:leaves2:1)
Block(-8,28,-1,minecraft:leaves2:1)
Block(2,28,-1,minecraft:log2:1)
Block(3,28,-1,minecraft:log2:1)
Block(4,28,-1,minecraft:log2:1)
Block(5,28,-1,minecraft:log2:1)
Block(-14,28,0,minecraft:leaves2:1)
Block(-13,28,0,minecraft:leaves2:1)
Block(-12,28,0,minecraft:leaves2:1)
Block(-11,28,0,minecraft:leaves2:1)
Block(-10,28,0,minecraft:leaves2:1)
Block(-9,28,0,minecraft:leaves2:1)
Block(-8,28,0,minecraft:leaves2:1)
Block(-7,28,0,minecraft:leaves2:1)
Block(2,28,0,minecraft:log2:1)
Block(3,28,0,minecraft:log2:1)
Block(4,28,0,minecraft:log2:1)
Block(5,28,0,minecraft:log2:1)
Block(-15,28,1,minecraft:leaves2:1)
Block(-14,28,1,minecraft:leaves2:1)
Block(-13,28,1,minecraft:leaves2:1)
Block(-12,28,1,minecraft:leaves2:1)
Block(-11,28,1,minecraft:leaves2:1)
Block(-10,28,1,minecraft:leaves2:1)
Block(-9,28,1,minecraft:leaves2:1)
Block(-8,28,1,minecraft:leaves2:1)
Block(-7,28,1,minecraft:leaves2:1)
Block(-6,28,1,minecraft:leaves2:1)
Block(0,28,1,minecraft:log2:1)
Block(1,28,1,minecraft:log2:1)
Block(2,28,1,minecraft:log2:1)
Block(3,28,1,minecraft:log2:1)
Block(4,28,1,minecraft:log2:1)
Block(5,28,1,minecraft:leaves2:1)
Block(-15,28,2,minecraft:leaves2:1)
Block(-14,28,2,minecraft:leaves2:1)
Block(-13,28,2,minecraft:leaves2:1)
Block(-12,28,2,minecraft:leaves2:1)
Block(-11,28,2,minecraft:leaves2:1)
Block(-10,28,2,minecraft:leaves2:1)
Block(-9,28,2,minecraft:log2:1)
Block(-8,28,2,minecraft:leaves2:1)
Block(-2,28,2,minecraft:log2:1)
Block(-1,28,2,minecraft:log2:1)
Block(0,28,2,minecraft:log2:1)
Block(1,28,2,minecraft:log2:1)
Block(2,28,2,minecraft:log2:1)
Block(3,28,2,minecraft:log2:1)
Block(4,28,2,minecraft:log2:1)
Block(-14,28,3,minecraft:leaves2:1)
Block(-13,28,3,minecraft:leaves2:1)
Block(-12,28,3,minecraft:leaves2:1)
Block(-11,28,3,minecraft:leaves2:1)
Block(-10,28,3,minecraft:leaves2:1)
Block(-8,28,3,minecraft:leaves2:1)
Block(-7,28,3,minecraft:leaves2:1)
Block(-6,28,3,minecraft:leaves2:1)
Block(-2,28,3,minecraft:log2:1)
Block(-1,28,3,minecraft:log2:1)
Block(0,28,3,minecraft:log2:1)
Block(1,28,3,minecraft:log2:1)
Block(2,28,3,minecraft:log2:1)
Block(3,28,3,minecraft:log2:1)
Block(4,28,3,minecraft:log2:1)
Block(-14,28,4,minecraft:leaves2:1)
Block(-13,28,4,minecraft:leaves2:1)
Block(-12,28,4,minecraft:leaves2:1)
Block(-11,28,4,minecraft:leaves2:1)
Block(-10,28,4,minecraft:leaves2:1)
Block(-9,28,4,minecraft:leaves2:1)
Block(-8,28,4,minecraft:leaves2:1)
Block(-7,28,4,minecraft:leaves2:1)
Block(-6,28,4,minecraft:leaves2:1)
Block(-5,28,4,minecraft:leaves2:1)
Block(-2,28,4,minecraft:log2:1)
Block(-1,28,4,minecraft:log2:1)
Block(0,28,4,minecraft:log2:1)
Block(1,28,4,minecraft:log2:1)
Block(2,28,4,minecraft:log2:1)
Block(3,28,4,minecraft:log2:1)
Block(-13,28,5,minecraft:leaves2:1)
Block(-12,28,5,minecraft:leaves2:1)
Block(-11,28,5,minecraft:leaves2:1)
Block(-10,28,5,minecraft:leaves2:1)
Block(-9,28,5,minecraft:leaves2:1)
Block(-8,28,5,minecraft:leaves2:1)
Block(-7,28,5,minecraft:leaves2:1)
Block(-6,28,5,minecraft:leaves2:1)
Block(-1,28,5,minecraft:log2:1)
Block(0,28,5,minecraft:log2:1)
Block(1,28,5,minecraft:log2:1)
Block(2,28,5,minecraft:log2:1)
Block(-12,28,6,minecraft:leaves2:1)
Block(-9,28,6,minecraft:leaves2:1)
Block(-8,28,6,minecraft:leaves2:1)
Block(-6,28,6,minecraft:leaves2:1)
Block(-1,28,6,minecraft:log2:1)
Block(0,28,6,minecraft:log2:1)
Block(1,28,6,minecraft:log2:1)
Block(2,28,6,minecraft:leaves2:1)
Block(-11,28,7,minecraft:leaves2:1)
Block(-9,28,7,minecraft:leaves2:1)
Block(-8,28,7,minecraft:leaves2:1)
Block(-7,28,7,minecraft:leaves2:1)
Block(-9,28,8,minecraft:leaves2:1)
Block(1,29,-13,minecraft:leaves2:1)
Block(3,29,-12,minecraft:leaves2:1)
Block(-3,29,-11,minecraft:leaves2:1)
Block(7,29,-11,minecraft:leaves2:1)
Block(3,29,-6,minecraft:log2:1)
Block(2,29,-5,minecraft:log2:1)
Block(3,29,-5,minecraft:log2:1)
Block(4,29,-5,minecraft:log2:1)
Block(5,29,-5,minecraft:leaves2:1)
Block(-9,29,-4,minecraft:leaves2:1)
Block(-3,29,-4,minecraft:leaves2:1)
Block(3,29,-4,minecraft:log2:1)
Block(4,29,-4,minecraft:log2:1)
Block(5,29,-4,minecraft:log2:1)
Block(3,29,-3,minecraft:log2:1)
Block(4,29,-3,minecraft:log2:1)
Block(5,29,-3,minecraft:log2:1)
Block(-1,29,-2,minecraft:leaves2:1)
Block(2,29,-2,minecraft:leaves2:1)
Block(3,29,-2,minecraft:log2:1)
Block(4,29,-2,minecraft:log2:1)
Block(5,29,-2,minecraft:log2:1)
Block(10,29,-2,minecraft:leaves2:1)
Block(-10,29,-1,minecraft:leaves2:1)
Block(-9,29,-1,minecraft:leaves2:1)
Block(1,29,-1,minecraft:leaves2:1)
Block(3,29,-1,minecraft:log2:1)
Block(4,29,-1,minecraft:log2:1)
Block(5,29,-1,minecraft:log2:1)
Block(-13,29,0,minecraft:leaves2:1)
Block(-11,29,0,minecraft:leaves2:1)
Block(-10,29,0,minecraft:leaves2:1)
Block(-9,29,0,minecraft:leaves2:1)
Block(-8,29,0,minecraft:leaves2:1)
Block(2,29,0,minecraft:log2:1)
Block(3,29,0,minecraft:log2:1)
Block(4,29,0,minecraft:log2:1)
Block(5,29,0,minecraft:leaves2:1)
Block(-14,29,1,minecraft:leaves2:1)
Block(-12,29,1,minecraft:leaves2:1)
Block(-11,29,1,minecraft:leaves2:1)
Block(-9,29,1,minecraft:leaves2:1)
Block(-7,29,1,minecraft:leaves2:1)
Block(2,29,1,minecraft:log2:1)
Block(3,29,1,minecraft:log2:1)
Block(4,29,1,minecraft:log2:1)
Block(-14,29,2,minecraft:leaves2:1)
Block(-11,29,2,minecraft:leaves2:1)
Block(-10,29,2,minecraft:leaves2:1)
Block(-9,29,2,minecraft:leaves2:1)
Block(-8,29,2,minecraft:leaves2:1)
Block(-7,29,2,minecraft:leaves2:1)
Block(-6,29,2,minecraft:leaves2:1)
Block(-1,29,2,minecraft:log2:1)
Block(0,29,2,minecraft:log2:1)
Block(1,29,2,minecraft:log2:1)
Block(2,29,2,minecraft:log2:1)
Block(3,29,2,minecraft:log2:1)
Block(4,29,2,minecraft:log2:1)
Block(-13,29,3,minecraft:leaves2:1)
Block(-12,29,3,minecraft:leaves2:1)
Block(-11,29,3,minecraft:leaves2:1)
Block(-10,29,3,minecraft:leaves2:1)
Block(-9,29,3,minecraft:leaves2:1)
Block(-8,29,3,minecraft:leaves2:1)
Block(-7,29,3,minecraft:leaves2:1)
Block(-6,29,3,minecraft:leaves2:1)
Block(-2,29,3,minecraft:log2:1)
Block(-1,29,3,minecraft:log2:1)
Block(0,29,3,minecraft:log2:1)
Block(1,29,3,minecraft:log2:1)
Block(2,29,3,minecraft:log2:1)
Block(3,29,3,minecraft:log2:1)
Block(-12,29,4,minecraft:leaves2:1)
Block(-11,29,4,minecraft:leaves2:1)
Block(-9,29,4,minecraft:leaves2:1)
Block(-8,29,4,minecraft:leaves2:1)
Block(-7,29,4,minecraft:leaves2:1)
Block(-6,29,4,minecraft:leaves2:1)
Block(-2,29,4,minecraft:log2:1)
Block(-1,29,4,minecraft:log2:1)
Block(0,29,4,minecraft:log2:1)
Block(1,29,4,minecraft:log2:1)
Block(2,29,4,minecraft:log2:1)
Block(-12,29,5,minecraft:leaves2:1)
Block(-7,29,5,minecraft:leaves2:1)
Block(-2,29,5,minecraft:log2:1)
Block(-1,29,5,minecraft:log2:1)
Block(0,29,5,minecraft:log2:1)
Block(1,29,5,minecraft:log2:1)
Block(2,29,5,minecraft:log2:1)
Block(3,29,5,minecraft:leaves2:1)
Block(-11,29,6,minecraft:leaves2:1)
Block(-10,29,6,minecraft:leaves2:1)
Block(-9,29,6,minecraft:leaves2:1)
Block(-8,29,6,minecraft:leaves2:1)
Block(-1,29,6,minecraft:log2:1)
Block(0,29,6,minecraft:log2:1)
Block(1,29,6,minecraft:log2:1)
Block(-10,29,7,minecraft:leaves2:1)
Block(-9,29,7,minecraft:leaves2:1)
Block(5,29,10,minecraft:leaves2:1)
Block(1,30,-13,minecraft:leaves2:1)
Block(3,30,-12,minecraft:leaves2:1)
Block(-3,30,-11,minecraft:leaves2:1)
Block(7,30,-11,minecraft:leaves2:1)
Block(-5,30,-9,minecraft:leaves2:1)
Block(-4,30,-7,minecraft:leaves2:1)
Block(3,30,-7,minecraft:log2:1)
Block(2,30,-6,minecraft:log2:1)
Block(3,30,-6,minecraft:log2:1)
Block(4,30,-6,minecraft:log2:1)
Block(-3,30,-5,minecraft:leaves2:1)
Block(2,30,-5,minecraft:log2:1)
Block(3,30,-5,minecraft:log2:1)
Block(4,30,-5,minecraft:log2:1)
Block(5,30,-5,minecraft:leaves2:1)
Block(-9,30,-4,minecraft:leaves2:1)
Block(-3,30,-4,minecraft:leaves2:1)
Block(2,30,-4,minecraft:log2:1)
Block(3,30,-4,minecraft:log2:1)
Block(4,30,-4,minecraft:log2:1)
Block(3,30,-3,minecraft:log2:1)
Block(4,30,-3,minecraft:log2:1)
Block(5,30,-3,minecraft:log2:1)
Block(-1,30,-2,minecraft:leaves2:1)
Block(3,30,-2,minecraft:log2:1)
Block(4,30,-2,minecraft:log2:1)
Block(5,30,-2,minecraft:log2:1)
Block(10,30,-2,minecraft:leaves2:1)
Block(1,30,-1,minecraft:leaves2:1)
Block(3,30,-1,minecraft:leaves2:1)
Block(4,30,-1,minecraft:log2:1)
Block(-12,30,0,minecraft:leaves2:1)
Block(4,30,0,minecraft:leaves2:1)
Block(-12,30,1,minecraft:leaves2:1)
Block(-11,30,1,minecraft:leaves2:1)
Block(-10,30,1,minecraft:leaves2:1)
Block(-8,30,1,minecraft:leaves2:1)
Block(-10,30,2,minecraft:leaves2:1)
Block(-9,30,2,minecraft:leaves2:1)
Block(-8,30,2,minecraft:leaves2:1)
Block(-1,30,2,minecraft:log2:1)
Block(0,30,2,minecraft:log2:1)
Block(1,30,2,minecraft:log2:1)
Block(2,30,2,minecraft:log2:1)
Block(-12,30,3,minecraft:leaves2:1)
Block(-11,30,3,minecraft:leaves2:1)
Block(-9,30,3,minecraft:leaves2:1)
Block(-2,30,3,minecraft:log2:1)
Block(-1,30,3,minecraft:log2:1)
Block(0,30,3,minecraft:log2:1)
Block(1,30,3,minecraft:log2:1)
Block(2,30,3,minecraft:log2:1)
Block(-11,30,4,minecraft:leaves2:1)
Block(-10,30,4,minecraft:leaves2:1)
Block(-9,30,4,minecraft:leaves2:1)
Block(-8,30,4,minecraft:leaves2:1)
Block(-7,30,4,minecraft:leaves2:1)
Block(-2,30,4,minecraft:log2:1)
Block(-1,30,4,minecraft:log2:1)
Block(0,30,4,minecraft:log2:1)
Block(1,30,4,minecraft:log2:1)
Block(2,30,4,minecraft:log2:1)
Block(-10,30,5,minecraft:leaves2:1)
Block(-8,30,5,minecraft:leaves2:1)
Block(-2,30,5,minecraft:log2:1)
Block(-1,30,5,minecraft:log2:1)
Block(0,30,5,minecraft:log2:1)
Block(1,30,5,minecraft:log2:1)
Block(2,30,5,minecraft:log2:1)
Block(3,30,5,minecraft:leaves2:1)
Block(0,30,6,minecraft:log2:1)
Block(1,30,6,minecraft:log2:1)
Block(-4,30,9,minecraft:leaves2:1)
Block(5,30,10,minecraft:leaves2:1)
Block(0,31,-13,minecraft:leaves2:1)
Block(1,31,-13,minecraft:leaves2:1)
Block(-3,31,-12,minecraft:leaves2:1)
Block(0,31,-12,minecraft:leaves2:1)
Block(1,31,-12,minecraft:leaves2:1)
Block(2,31,-12,minecraft:leaves2:1)
Block(3,31,-12,minecraft:leaves2:1)
Block(-3,31,-11,minecraft:leaves2:1)
Block(1,31,-11,minecraft:leaves2:1)
Block(2,31,-11,minecraft:leaves2:1)
Block(3,31,-11,minecraft:leaves2:1)
Block(4,31,-11,minecraft:leaves2:1)
Block(6,31,-11,minecraft:leaves2:1)
Block(7,31,-11,minecraft:leaves2:1)
Block(3,31,-10,minecraft:leaves2:1)
Block(6,31,-10,minecraft:leaves2:1)
Block(7,31,-10,minecraft:leaves2:1)
Block(8,31,-10,minecraft:leaves2:1)
Block(-5,31,-9,minecraft:leaves2:1)
Block(4,31,-9,minecraft:leaves2:1)
Block(5,31,-9,minecraft:leaves2:1)
Block(7,31,-9,minecraft:leaves2:1)
Block(4,31,-8,minecraft:leaves2:1)
Block(-4,31,-7,minecraft:leaves2:1)
Block(2,31,-7,minecraft:log2:1)
Block(3,31,-7,minecraft:log2:1)
Block(4,31,-7,minecraft:log2:1)
Block(8,31,-7,minecraft:leaves2:1)
Block(-6,31,-6,minecraft:leaves2:1)
Block(1,31,-6,minecraft:log2:1)
Block(2,31,-6,minecraft:log2:1)
Block(3,31,-6,minecraft:log2:1)
Block(4,31,-6,minecraft:log2:1)
Block(5,31,-6,minecraft:leaves2:1)
Block(7,31,-6,minecraft:leaves2:1)
Block(9,31,-6,minecraft:leaves2:1)
Block(-3,31,-5,minecraft:leaves2:1)
Block(2,31,-5,minecraft:log2:1)
Block(3,31,-5,minecraft:log2:1)
Block(4,31,-5,minecraft:log2:1)
Block(6,31,-5,minecraft:leaves2:1)
Block(8,31,-5,minecraft:leaves2:1)
Block(-9,31,-4,minecraft:leaves2:1)
Block(-3,31,-4,minecraft:leaves2:1)
Block(3,31,-4,minecraft:log2:1)
Block(5,31,-4,minecraft:leaves2:1)
Block(6,31,-4,minecraft:leaves2:1)
Block(7,31,-4,minecraft:leaves2:1)
Block(6,31,-3,minecraft:leaves2:1)
Block(10,31,-3,minecraft:leaves2:1)
Block(-2,31,-2,minecraft:leaves2:1)
Block(-1,31,-2,minecraft:leaves2:1)
Block(1,31,-2,minecraft:leaves2:1)
Block(10,31,-2,minecraft:leaves2:1)
Block(-1,31,-1,minecraft:leaves2:1)
Block(1,31,-1,minecraft:leaves2:1)
Block(-1,31,1,minecraft:log2:1)
Block(0,31,1,minecraft:log2:1)
Block(-2,31,2,minecraft:log2:1)
Block(-1,31,2,minecraft:log2:1)
Block(0,31,2,minecraft:log2:1)
Block(1,31,2,minecraft:log2:1)
Block(2,31,2,minecraft:log2:1)
Block(-2,31,3,minecraft:log2:1)
Block(-1,31,3,minecraft:log2:1)
Block(0,31,3,minecraft:log2:1)
Block(1,31,3,minecraft:log2:1)
Block(2,31,3,minecraft:log2:1)
Block(11,31,3,minecraft:leaves2:1)
Block(-2,31,4,minecraft:log2:1)
Block(-1,31,4,minecraft:log2:1)
Block(0,31,4,minecraft:log2:1)
Block(1,31,4,minecraft:log2:1)
Block(2,31,4,minecraft:log2:1)
Block(3,31,4,minecraft:leaves2:1)
Block(-2,31,5,minecraft:log2:1)
Block(-1,31,5,minecraft:log2:1)
Block(0,31,5,minecraft:log2:1)
Block(1,31,5,minecraft:log2:1)
Block(7,31,5,minecraft:leaves2:1)
Block(0,31,6,minecraft:log2:1)
Block(-4,31,9,minecraft:leaves2:1)
Block(5,31,10,minecraft:leaves2:1)
Block(0,31,11,minecraft:leaves2:1)
Block(0,32,-14,minecraft:leaves2:1)
Block(1,32,-14,minecraft:leaves2:1)
Block(2,32,-14,minecraft:leaves2:1)
Block(-2,32,-13,minecraft:leaves2:1)
Block(-1,32,-13,minecraft:leaves2:1)
Block(0,32,-13,minecraft:leaves2:1)
Block(1,32,-13,minecraft:leaves2:1)
Block(4,32,-13,minecraft:leaves2:1)
Block(-3,32,-12,minecraft:leaves2:1)
Block(-2,32,-12,minecraft:leaves2:1)
Block(-1,32,-12,minecraft:leaves2:1)
Block(0,32,-12,minecraft:leaves2:1)
Block(1,32,-12,minecraft:leaves2:1)
Block(2,32,-12,minecraft:leaves2:1)
Block(3,32,-12,minecraft:leaves2:1)
Block(4,32,-12,minecraft:leaves2:1)
Block(5,32,-12,minecraft:leaves2:1)
Block(-3,32,-11,minecraft:leaves2:1)
Block(-2,32,-11,minecraft:leaves2:1)
Block(0,32,-11,minecraft:leaves2:1)
Block(1,32,-11,minecraft:leaves2:1)
Block(2,32,-11,minecraft:leaves2:1)
Block(3,32,-11,minecraft:leaves2:1)
Block(4,32,-11,minecraft:leaves2:1)
Block(5,32,-11,minecraft:leaves2:1)
Block(7,32,-11,minecraft:leaves2:1)
Block(8,32,-11,minecraft:leaves2:1)
Block(-4,32,-10,minecraft:leaves2:1)
Block(-3,32,-10,minecraft:leaves2:1)
Block(-2,32,-10,minecraft:leaves2:1)
Block(2,32,-10,minecraft:leaves2:1)
Block(3,32,-10,minecraft:leaves2:1)
Block(4,32,-10,minecraft:leaves2:1)
Block(5,32,-10,minecraft:leaves2:1)
Block(6,32,-10,minecraft:leaves2:1)
Block(7,32,-10,minecraft:leaves2:1)
Block(8,32,-10,minecraft:leaves2:1)
Block(-4,32,-9,minecraft:leaves2:1)
Block(0,32,-9,minecraft:log2:1)
Block(1,32,-9,minecraft:log2:1)
Block(3,32,-9,minecraft:leaves2:1)
Block(4,32,-9,minecraft:leaves2:1)
Block(5,32,-9,minecraft:leaves2:1)
Block(6,32,-9,minecraft:leaves2:1)
Block(7,32,-9,minecraft:leaves2:1)
Block(8,32,-9,minecraft:leaves2:1)
Block(-4,32,-8,minecraft:leaves2:1)
Block(-1,32,-8,minecraft:leaves2:1)
Block(0,32,-8,minecraft:leaves2:1)
Block(1,32,-8,minecraft:log2:1)
Block(3,32,-8,minecraft:leaves2:1)
Block(4,32,-8,minecraft:leaves2:1)
Block(5,32,-8,minecraft:leaves2:1)
Block(7,32,-8,minecraft:leaves2:1)
Block(8,32,-8,minecraft:leaves2:1)
Block(9,32,-8,minecraft:leaves2:1)
Block(-4,32,-7,minecraft:leaves2:1)
Block(-1,32,-7,minecraft:log2:1)
Block(0,32,-7,minecraft:log2:1)
Block(1,32,-7,minecraft:log2:1)
Block(2,32,-7,minecraft:log2:1)
Block(3,32,-7,minecraft:leaves2:1)
Block(4,32,-7,minecraft:leaves2:1)
Block(5,32,-7,minecraft:leaves2:1)
Block(6,32,-7,minecraft:leaves2:1)
Block(7,32,-7,minecraft:leaves2:1)
Block(8,32,-7,minecraft:leaves2:1)
Block(9,32,-7,minecraft:leaves2:1)
Block(-6,32,-6,minecraft:leaves2:1)
Block(-4,32,-6,minecraft:leaves2:1)
Block(1,32,-6,minecraft:leaves2:1)
Block(2,32,-6,minecraft:leaves2:1)
Block(3,32,-6,minecraft:leaves2:1)
Block(4,32,-6,minecraft:leaves2:1)
Block(5,32,-6,minecraft:leaves2:1)
Block(6,32,-6,minecraft:leaves2:1)
Block(7,32,-6,minecraft:leaves2:1)
Block(8,32,-6,minecraft:leaves2:1)
Block(9,32,-6,minecraft:leaves2:1)
Block(-4,32,-5,minecraft:leaves2:1)
Block(-3,32,-5,minecraft:leaves2:1)
Block(0,32,-5,minecraft:log2:1)
Block(1,32,-5,minecraft:log2:1)
Block(2,32,-5,minecraft:leaves2:1)
Block(3,32,-5,minecraft:leaves2:1)
Block(4,32,-5,minecraft:leaves2:1)
Block(5,32,-5,minecraft:leaves2:1)
Block(6,32,-5,minecraft:leaves2:1)
Block(7,32,-5,minecraft:leaves2:1)
Block(8,32,-5,minecraft:leaves2:1)
Block(9,32,-5,minecraft:leaves2:1)
Block(-9,32,-4,minecraft:leaves2:1)
Block(-4,32,-4,minecraft:leaves2:1)
Block(-3,32,-4,minecraft:leaves2:1)
Block(-2,32,-4,minecraft:leaves2:1)
Block(0,32,-4,minecraft:log2:1)
Block(1,32,-4,minecraft:leaves2:1)
Block(2,32,-4,minecraft:leaves2:1)
Block(3,32,-4,minecraft:log2:1)
Block(4,32,-4,minecraft:leaves2:1)
Block(5,32,-4,minecraft:leaves2:1)
Block(6,32,-4,minecraft:leaves2:1)
Block(7,32,-4,minecraft:leaves2:1)
Block(8,32,-4,minecraft:leaves2:1)
Block(-3,32,-3,minecraft:leaves2:1)
Block(-2,32,-3,minecraft:leaves2:1)
Block(-1,32,-3,minecraft:leaves2:1)
Block(0,32,-3,minecraft:leaves2:1)
Block(3,32,-3,minecraft:log2:1)
Block(5,32,-3,minecraft:leaves2:1)
Block(6,32,-3,minecraft:leaves2:1)
Block(7,32,-3,minecraft:leaves2:1)
Block(10,32,-3,minecraft:leaves2:1)
Block(-3,32,-2,minecraft:leaves2:1)
Block(-2,32,-2,minecraft:leaves2:1)
Block(-1,32,-2,minecraft:leaves2:1)
Block(0,32,-2,minecraft:leaves2:1)
Block(6,32,-2,minecraft:leaves2:1)
Block(7,32,-2,minecraft:leaves2:1)
Block(10,32,-2,minecraft:leaves2:1)
Block(-11,32,-1,minecraft:leaves2:1)
Block(-2,32,-1,minecraft:leaves2:1)
Block(0,32,-1,minecraft:leaves2:1)
Block(1,32,-1,minecraft:leaves2:1)
Block(2,32,-1,minecraft:leaves2:1)
Block(4,32,-1,minecraft:leaves2:1)
Block(5,32,-1,minecraft:leaves2:1)
Block(6,32,-1,minecraft:leaves2:1)
Block(0,32,0,minecraft:leaves2:1)
Block(1,32,0,minecraft:leaves2:1)
Block(2,32,0,minecraft:leaves2:1)
Block(4,32,0,minecraft:leaves2:1)
Block(-1,32,1,minecraft:log2:1)
Block(0,32,1,minecraft:log2:1)
Block(1,32,1,minecraft:log2:1)
Block(9,32,1,minecraft:leaves2:1)
Block(-2,32,2,minecraft:log2:1)
Block(-1,32,2,minecraft:log2:1)
Block(0,32,2,minecraft:log2:1)
Block(1,32,2,minecraft:log2:1)
Block(2,32,2,minecraft:log2:1)
Block(-2,32,3,minecraft:log2:1)
Block(-1,32,3,minecraft:log2:1)
Block(0,32,3,minecraft:log2:1)
Block(1,32,3,minecraft:log2:1)
Block(2,32,3,minecraft:log2:1)
Block(3,32,3,minecraft:leaves2:1)
Block(11,32,3,minecraft:leaves2:1)
Block(-2,32,4,minecraft:log2:1)
Block(-1,32,4,minecraft:log2:1)
Block(0,32,4,minecraft:log2:1)
Block(1,32,4,minecraft:log2:1)
Block(2,32,4,minecraft:log2:1)
Block(-9,32,5,minecraft:leaves2:1)
Block(-1,32,5,minecraft:log2:1)
Block(0,32,5,minecraft:log2:1)
Block(1,32,5,minecraft:log2:1)
Block(7,32,5,minecraft:leaves2:1)
Block(10,32,5,minecraft:leaves2:1)
Block(-2,32,8,minecraft:leaves2:1)
Block(-4,32,9,minecraft:leaves2:1)
Block(5,32,10,minecraft:leaves2:1)
Block(0,32,11,minecraft:leaves2:1)
Block(0,33,-14,minecraft:leaves2:1)
Block(-1,33,-13,minecraft:leaves2:1)
Block(0,33,-13,minecraft:leaves2:1)
Block(1,33,-13,minecraft:leaves2:1)
Block(2,33,-13,minecraft:leaves2:1)
Block(3,33,-13,minecraft:leaves2:1)
Block(5,33,-13,minecraft:leaves2:1)
Block(-3,33,-12,minecraft:leaves2:1)
Block(-2,33,-12,minecraft:leaves2:1)
Block(-1,33,-12,minecraft:leaves2:1)
Block(0,33,-12,minecraft:leaves2:1)
Block(1,33,-12,minecraft:leaves2:1)
Block(2,33,-12,minecraft:leaves2:1)
Block(4,33,-12,minecraft:leaves2:1)
Block(5,33,-12,minecraft:leaves2:1)
Block(6,33,-12,minecraft:leaves2:1)
Block(-3,33,-11,minecraft:leaves2:1)
Block(-2,33,-11,minecraft:leaves2:1)
Block(-1,33,-11,minecraft:leaves2:1)
Block(0,33,-11,minecraft:leaves2:1)
Block(1,33,-11,minecraft:leaves2:1)
Block(2,33,-11,minecraft:leaves2:1)
Block(3,33,-11,minecraft:leaves2:1)
Block(4,33,-11,minecraft:leaves2:1)
Block(5,33,-11,minecraft:leaves2:1)
Block(6,33,-11,minecraft:leaves2:1)
Block(7,33,-11,minecraft:leaves2:1)
Block(-5,33,-10,minecraft:leaves2:1)
Block(-4,33,-10,minecraft:leaves2:1)
Block(-3,33,-10,minecraft:leaves2:1)
Block(-2,33,-10,minecraft:leaves2:1)
Block(-1,33,-10,minecraft:leaves2:1)
Block(0,33,-10,minecraft:log2:1)
Block(1,33,-10,minecraft:leaves2:1)
Block(2,33,-10,minecraft:leaves2:1)
Block(3,33,-10,minecraft:leaves2:1)
Block(4,33,-10,minecraft:leaves2:1)
Block(6,33,-10,minecraft:leaves2:1)
Block(7,33,-10,minecraft:leaves2:1)
Block(8,33,-10,minecraft:leaves2:1)
Block(-5,33,-9,minecraft:leaves2:1)
Block(-4,33,-9,minecraft:leaves2:1)
Block(-2,33,-9,minecraft:leaves2:1)
Block(0,33,-9,minecraft:leaves2:1)
Block(1,33,-9,minecraft:leaves2:1)
Block(2,33,-9,minecraft:leaves2:1)
Block(3,33,-9,minecraft:leaves2:1)
Block(5,33,-9,minecraft:leaves2:1)
Block(6,33,-9,minecraft:leaves2:1)
Block(7,33,-9,minecraft:leaves2:1)
Block(8,33,-9,minecraft:leaves2:1)
Block(9,33,-9,minecraft:leaves2:1)
Block(-5,33,-8,minecraft:leaves2:1)
Block(-4,33,-8,minecraft:leaves2:1)
Block(-3,33,-8,minecraft:leaves2:1)
Block(-2,33,-8,minecraft:leaves2:1)
Block(-1,33,-8,minecraft:leaves2:1)
Block(0,33,-8,minecraft:leaves2:1)
Block(1,33,-8,minecraft:leaves2:1)
Block(2,33,-8,minecraft:leaves2:1)
Block(3,33,-8,minecraft:leaves2:1)
Block(4,33,-8,minecraft:leaves2:1)
Block(5,33,-8,minecraft:leaves2:1)
Block(6,33,-8,minecraft:leaves2:1)
Block(7,33,-8,minecraft:leaves2:1)
Block(9,33,-8,minecraft:leaves2:1)
Block(-5,33,-7,minecraft:leaves2:1)
Block(-4,33,-7,minecraft:leaves2:1)
Block(-3,33,-7,minecraft:leaves2:1)
Block(-2,33,-7,minecraft:log2:1)
Block(-1,33,-7,minecraft:leaves2:1)
Block(0,33,-7,minecraft:leaves2:1)
Block(1,33,-7,minecraft:leaves2:1)
Block(2,33,-7,minecraft:leaves2:1)
Block(3,33,-7,minecraft:leaves2:1)
Block(4,33,-7,minecraft:leaves2:1)
Block(5,33,-7,minecraft:leaves2:1)
Block(6,33,-7,minecraft:leaves2:1)
Block(7,33,-7,minecraft:leaves2:1)
Block(8,33,-7,minecraft:leaves2:1)
Block(-6,33,-6,minecraft:leaves2:1)
Block(-5,33,-6,minecraft:leaves2:1)
Block(-4,33,-6,minecraft:leaves2:1)
Block(0,33,-6,minecraft:leaves2:1)
Block(1,33,-6,minecraft:leaves2:1)
Block(2,33,-6,minecraft:log2:1)
Block(3,33,-6,minecraft:leaves2:1)
Block(4,33,-6,minecraft:leaves2:1)
Block(5,33,-6,minecraft:leaves2:1)
Block(6,33,-6,minecraft:leaves2:1)
Block(7,33,-6,minecraft:leaves2:1)
Block(8,33,-6,minecraft:leaves2:1)
Block(9,33,-6,minecraft:leaves2:1)
Block(-6,33,-5,minecraft:leaves2:1)
Block(-5,33,-5,minecraft:leaves2:1)
Block(-4,33,-5,minecraft:leaves2:1)
Block(-3,33,-5,minecraft:leaves2:1)
Block(-2,33,-5,minecraft:leaves2:1)
Block(-1,33,-5,minecraft:leaves2:1)
Block(0,33,-5,minecraft:leaves2:1)
Block(1,33,-5,minecraft:leaves2:1)
Block(2,33,-5,minecraft:leaves2:1)
Block(3,33,-5,minecraft:leaves2:1)
Block(4,33,-5,minecraft:leaves2:1)
Block(5,33,-5,minecraft:leaves2:1)
Block(6,33,-5,minecraft:leaves2:1)
Block(7,33,-5,minecraft:leaves2:1)
Block(8,33,-5,minecraft:leaves2:1)
Block(-9,33,-4,minecraft:leaves2:1)
Block(-6,33,-4,minecraft:leaves2:1)
Block(-5,33,-4,minecraft:leaves2:1)
Block(-4,33,-4,minecraft:leaves2:1)
Block(-3,33,-4,minecraft:leaves2:1)
Block(-2,33,-4,minecraft:leaves2:1)
Block(-1,33,-4,minecraft:log2:1)
Block(1,33,-4,minecraft:leaves2:1)
Block(2,33,-4,minecraft:leaves2:1)
Block(3,33,-4,minecraft:leaves2:1)
Block(4,33,-4,minecraft:leaves2:1)
Block(5,33,-4,minecraft:leaves2:1)
Block(6,33,-4,minecraft:leaves2:1)
Block(7,33,-4,minecraft:leaves2:1)
Block(-5,33,-3,minecraft:leaves2:1)
Block(-4,33,-3,minecraft:leaves2:1)
Block(-1,33,-3,minecraft:leaves2:1)
Block(1,33,-3,minecraft:leaves2:1)
Block(2,33,-3,minecraft:log2:1)
Block(3,33,-3,minecraft:leaves2:1)
Block(4,33,-3,minecraft:leaves2:1)
Block(5,33,-3,minecraft:leaves2:1)
Block(6,33,-3,minecraft:leaves2:1)
Block(10,33,-3,minecraft:leaves2:1)
Block(-6,33,-2,minecraft:leaves2:1)
Block(-5,33,-2,minecraft:leaves2:1)
Block(-4,33,-2,minecraft:leaves2:1)
Block(-3,33,-2,minecraft:leaves2:1)
Block(4,33,-2,minecraft:leaves2:1)
Block(5,33,-2,minecraft:leaves2:1)
Block(6,33,-2,minecraft:leaves2:1)
Block(10,33,-2,minecraft:leaves2:1)
Block(11,33,-2,minecraft:leaves2:1)
Block(-11,33,-1,minecraft:leaves2:1)
Block(-5,33,-1,minecraft:leaves2:1)
Block(-4,33,-1,minecraft:leaves2:1)
Block(-3,33,-1,minecraft:leaves2:1)
Block(-2,33,-1,minecraft:leaves2:1)
Block(-1,33,-1,minecraft:leaves2:1)
Block(0,33,-1,minecraft:leaves2:1)
Block(1,33,-1,minecraft:leaves2:1)
Block(2,33,-1,minecraft:leaves2:1)
Block(3,33,-1,minecraft:leaves2:1)
Block(4,33,-1,minecraft:leaves2:1)
Block(5,33,-1,minecraft:leaves2:1)
Block(-5,33,0,minecraft:leaves2:1)
Block(-4,33,0,minecraft:leaves2:1)
Block(-2,33,0,minecraft:leaves2:1)
Block(-1,33,0,minecraft:leaves2:1)
Block(0,33,0,minecraft:leaves2:1)
Block(1,33,0,minecraft:leaves2:1)
Block(2,33,0,minecraft:leaves2:1)
Block(3,33,0,minecraft:leaves2:1)
Block(4,33,0,minecraft:leaves2:1)
Block(5,33,0,minecraft:leaves2:1)
Block(-4,33,1,minecraft:leaves2:1)
Block(-3,33,1,minecraft:leaves2:1)
Block(-2,33,1,minecraft:leaves2:1)
Block(-1,33,1,minecraft:leaves2:1)
Block(0,33,1,minecraft:leaves2:1)
Block(2,33,1,minecraft:leaves2:1)
Block(3,33,1,minecraft:log2:1)
Block(4,33,1,minecraft:log2:1)
Block(5,33,1,minecraft:log2:1)
Block(9,33,1,minecraft:leaves2:1)
Block(-3,33,2,minecraft:log2:1)
Block(-2,33,2,minecraft:leaves2:1)
Block(-1,33,2,minecraft:leaves2:1)
