#######################################################################
# +-----------------------------------------------------------------+ #
# |                            BO3 object                           | #
# +-----------------------------------------------------------------+ #
#######################################################################

# This is the config file of a custom object.
# If you add this object correctly to your BiomeConfigs, it will spawn in the world.

# This is the creator of this BO3 object
Author: BO3 BulkEdit (by LanToaster)

# A short description of this BO3 object
Description: This Object was Created with BO3_BulkEdit

# The BO3 version, don't change this! It can be used by external applications to do a version check.
Version: 3

# The settings mode, WriteAll, WriteWithoutComments or WriteDisable. See WorldConfig.
SettingsMode: WriteDisable


#######################################################################
# +-----------------------------------------------------------------+ #
# |                          Main settings                          | #
# +-----------------------------------------------------------------+ #
#######################################################################

# This needs to be set to true to spawn the object in the Tree and Sapling resources.
Tree: true

# The frequency of the BO3 from 1 to 200. Tries this many times to spawn this BO3 when using the CustomObject(...) resource.
# Ignored by Tree(..), Sapling(..) and CustomStructure(..)
Frequency: 1

# The rarity of the BO3 from 0 to 100. Each spawn attempt has rarity% chance to succeed when using the CustomObject(...) resource.
# Ignored by Tree(..), Sapling(..) and CustomStructure(..)
Rarity: 100.0

# If you set this to true, the BO3 will be placed with a random rotation.
RotateRandomly: true

# The spawn height of the BO3 - randomY, highestBlock or highestSolid)Block.
SpawnHeight: randomY

# The height limits for the BO3.
MinHeight: 92

MaxHeight: 256

# Objects can have other objects attacthed to it: branches. Branches can also
# have branches attached to it, which can also have branches, etc. This is the
# maximum branch depth for this objects.
MaxBranchDepth: 10

# When spawned with the UseWorld keyword, this BO3 should NOT spawn in the following biomes.
# If you writer.write the BO3 name directly in the BiomeConfigs, this will be ignored.
ExcludedBiomes: All


#######################################################################
# +-----------------------------------------------------------------+ #
# |                      Source block settings                      | #
# +-----------------------------------------------------------------+ #
#######################################################################

# The block(s) the BO3 should spawn in.
SourceBlocks: AIR,minecraft:grass,minecraft:dirt

# The maximum percentage of the BO3 that can be outside the SourceBlock.
# The BO3 won't be placed on a location with more blocks outside the SourceBlock than this percentage.
MaxPercentageOutsideSourceBlock: 100

# What to do when a block is about to be placed outside the SourceBlock? (dontPlace, placeAnyway)
OutsideSourceBlock: placeAnyway


#######################################################################
# +-----------------------------------------------------------------+ #
# |                              Blocks                             | #
# +-----------------------------------------------------------------+ #
#######################################################################

# All the blocks used in the BO3 are listed here. Possible blocks:
# Block(x,y,z,id[.data][,nbtfile.nbt)
# RandomBlock(x,y,z,id[:data][,nbtfile.nbt],chance[,id[:data][,nbtfile.nbt],chance[,...]])
# So RandomBlock(0,0,0,CHEST,chest.nbt,50,CHEST,anotherchest.nbt,100) will spawn a chest at
# the BO3 origin, and give it a 50% chance to have the contents of chest.nbt, or, if that
# fails, a 100% percent chance to have the contents of anotherchest.nbt.
Block(-1,0,-2,minecraft:log2:1)
Block(0,0,-2,minecraft:log2:1)
Block(1,0,-2,minecraft:log2:1)
Block(2,0,-2,minecraft:log2:1)
Block(-2,0,-1,minecraft:log2:1)
Block(-1,0,-1,minecraft:log2:1)
Block(0,0,-1,minecraft:log2:1)
Block(1,0,-1,minecraft:log2:1)
Block(2,0,-1,minecraft:log2:1)
Block(3,0,-1,minecraft:log2:1)
Block(-2,0,0,minecraft:log2:1)
Block(-1,0,0,minecraft:log2:1)
Block(0,0,0,minecraft:log2:1)
Block(1,0,0,minecraft:log2:1)
Block(2,0,0,minecraft:log2:1)
Block(3,0,0,minecraft:log2:1)
Block(-2,0,1,minecraft:log2:1)
Block(-1,0,1,minecraft:log2:1)
Block(0,0,1,minecraft:log2:1)
Block(1,0,1,minecraft:log2:1)
Block(2,0,1,minecraft:log2:1)
Block(3,0,1,minecraft:log2:1)
Block(-2,0,2,minecraft:log2:1)
Block(-1,0,2,minecraft:log2:1)
Block(0,0,2,minecraft:log2:1)
Block(1,0,2,minecraft:log2:1)
Block(2,0,2,minecraft:log2:1)
Block(3,0,2,minecraft:log2:1)
Block(-1,0,3,minecraft:log2:1)
Block(0,0,3,minecraft:log2:1)
Block(1,0,3,minecraft:log2:1)
Block(2,0,3,minecraft:log2:1)
Block(-1,1,-2,minecraft:log2:1)
Block(0,1,-2,minecraft:log2:1)
Block(1,1,-2,minecraft:log2:1)
Block(2,1,-2,minecraft:log2:1)
Block(-2,1,-1,minecraft:log2:1)
Block(-1,1,-1,minecraft:log2:1)
Block(0,1,-1,minecraft:log2:1)
Block(1,1,-1,minecraft:log2:1)
Block(2,1,-1,minecraft:log2:1)
Block(3,1,-1,minecraft:log2:1)
Block(-2,1,0,minecraft:log2:1)
Block(-1,1,0,minecraft:log2:1)
Block(0,1,0,minecraft:log2:1)
Block(1,1,0,minecraft:log2:1)
Block(2,1,0,minecraft:log2:1)
Block(3,1,0,minecraft:log2:1)
Block(-2,1,1,minecraft:log2:1)
Block(-1,1,1,minecraft:log2:1)
Block(0,1,1,minecraft:log2:1)
Block(1,1,1,minecraft:log2:1)
Block(2,1,1,minecraft:log2:1)
Block(3,1,1,minecraft:log2:1)
Block(-2,1,2,minecraft:log2:1)
Block(-1,1,2,minecraft:log2:1)
Block(0,1,2,minecraft:log2:1)
Block(1,1,2,minecraft:log2:1)
Block(2,1,2,minecraft:log2:1)
Block(3,1,2,minecraft:log2:1)
Block(0,1,3,minecraft:log2:1)
Block(1,1,3,minecraft:log2:1)
Block(2,1,3,minecraft:log2:1)
Block(0,2,-2,minecraft:log2:1)
Block(1,2,-2,minecraft:log2:1)
Block(-1,2,-1,minecraft:log2:1)
Block(0,2,-1,minecraft:log2:1)
Block(1,2,-1,minecraft:log2:1)
Block(2,2,-1,minecraft:log2:1)
Block(-2,2,0,minecraft:log2:1)
Block(-1,2,0,minecraft:log2:1)
Block(0,2,0,minecraft:log2:1)
Block(1,2,0,minecraft:log2:1)
Block(2,2,0,minecraft:log2:1)
Block(3,2,0,minecraft:log2:1)
Block(-2,2,1,minecraft:log2:1)
Block(-1,2,1,minecraft:log2:1)
Block(0,2,1,minecraft:log2:1)
Block(1,2,1,minecraft:log2:1)
Block(2,2,1,minecraft:log2:1)
Block(3,2,1,minecraft:log2:1)
Block(-1,2,2,minecraft:log2:1)
Block(0,2,2,minecraft:log2:1)
Block(1,2,2,minecraft:log2:1)
Block(2,2,2,minecraft:log2:1)
Block(3,2,2,minecraft:log2:1)
Block(0,2,3,minecraft:log2:1)
Block(1,2,3,minecraft:log2:1)
Block(0,3,-2,minecraft:log2:1)
Block(-1,3,-1,minecraft:log2:1)
Block(0,3,-1,minecraft:log2:1)
Block(1,3,-1,minecraft:log2:1)
Block(2,3,-1,minecraft:log2:1)
Block(-2,3,0,minecraft:log2:1)
Block(-1,3,0,minecraft:log2:1)
Block(0,3,0,minecraft:log2:1)
Block(1,3,0,minecraft:log2:1)
Block(2,3,0,minecraft:log2:1)
Block(3,3,0,minecraft:log2:1)
Block(-2,3,1,minecraft:log2:1)
Block(-1,3,1,minecraft:log2:1)
Block(0,3,1,minecraft:log2:1)
Block(1,3,1,minecraft:log2:1)
Block(2,3,1,minecraft:log2:1)
Block(3,3,1,minecraft:log2:1)
Block(0,3,2,minecraft:log2:1)
Block(1,3,2,minecraft:log2:1)
Block(1,3,3,minecraft:log2:1)
Block(-1,4,-1,minecraft:log2:1)
Block(0,4,-1,minecraft:log2:1)
Block(1,4,-1,minecraft:log2:1)
Block(-2,4,0,minecraft:log2:1)
Block(-1,4,0,minecraft:log2:1)
Block(0,4,0,minecraft:log2:1)
Block(1,4,0,minecraft:log2:1)
Block(2,4,0,minecraft:log2:1)
Block(3,4,0,minecraft:log2:1)
Block(-2,4,1,minecraft:log2:1)
Block(-1,4,1,minecraft:log2:1)
Block(0,4,1,minecraft:log2:1)
Block(1,4,1,minecraft:log2:1)
Block(2,4,1,minecraft:log2:1)
Block(3,4,1,minecraft:log2:1)
Block(-1,4,2,minecraft:log2:1)
Block(0,4,2,minecraft:log2:1)
Block(1,4,2,minecraft:log2:1)
Block(1,4,3,minecraft:leaves2:1)
Block(0,5,-2,minecraft:leaves2:1)
Block(0,5,-1,minecraft:log2:1)
Block(1,5,-1,minecraft:log2:1)
Block(-2,5,0,minecraft:leaves2:1)
Block(-1,5,0,minecraft:log2:1)
Block(0,5,0,minecraft:log2:1)
Block(1,5,0,minecraft:log2:1)
Block(2,5,0,minecraft:log2:1)
Block(3,5,0,minecraft:leaves2:1)
Block(-2,5,1,minecraft:leaves2:1)
Block(-1,5,1,minecraft:log2:1)
Block(0,5,1,minecraft:log2:1)
Block(1,5,1,minecraft:log2:1)
Block(2,5,1,minecraft:log2:1)
Block(3,5,1,minecraft:log2:1)
Block(-1,5,2,minecraft:log2:1)
Block(0,5,2,minecraft:log2:1)
Block(1,5,2,minecraft:log2:1)
Block(2,5,2,minecraft:log2:1)
Block(3,5,2,minecraft:leaves2:1)
Block(0,5,3,minecraft:leaves2:1)
Block(1,5,3,minecraft:leaves2:1)
Block(-1,6,-4,minecraft:leaves2:1)
Block(0,6,-4,minecraft:leaves2:1)
Block(-1,6,-3,minecraft:leaves2:1)
Block(0,6,-3,minecraft:leaves2:1)
Block(1,6,-3,minecraft:leaves2:1)
Block(2,6,-3,minecraft:leaves2:1)
Block(3,6,-3,minecraft:leaves2:1)
Block(-2,6,-2,minecraft:leaves2:1)
Block(-1,6,-2,minecraft:leaves2:1)
Block(0,6,-2,minecraft:leaves2:1)
Block(2,6,-2,minecraft:leaves2:1)
Block(-2,6,-1,minecraft:leaves2:1)
Block(-1,6,-1,minecraft:log2:1)
Block(0,6,-1,minecraft:log2:1)
Block(1,6,-1,minecraft:log2:1)
Block(2,6,-1,minecraft:leaves2:1)
Block(4,6,-1,minecraft:leaves2:1)
Block(-3,6,0,minecraft:leaves2:1)
Block(-2,6,0,minecraft:log2:1)
Block(-1,6,0,minecraft:log2:1)
Block(0,6,0,minecraft:log2:1)
Block(1,6,0,minecraft:log2:1)
Block(2,6,0,minecraft:log2:1)
Block(3,6,0,minecraft:leaves2:1)
Block(-1,6,1,minecraft:log2:1)
Block(0,6,1,minecraft:log2:1)
Block(1,6,1,minecraft:log2:1)
Block(2,6,1,minecraft:log2:1)
Block(3,6,1,minecraft:log2:1)
Block(4,6,1,minecraft:leaves2:1)
Block(-1,6,2,minecraft:leaves2:1)
Block(0,6,2,minecraft:log2:1)
Block(1,6,2,minecraft:log2:1)
Block(2,6,2,minecraft:log2:1)
Block(3,6,2,minecraft:leaves2:1)
Block(-3,6,3,minecraft:leaves2:1)
Block(-1,6,3,minecraft:leaves2:1)
Block(0,6,3,minecraft:leaves2:1)
Block(1,6,3,minecraft:leaves2:1)
Block(-2,6,4,minecraft:leaves2:1)
Block(1,6,4,minecraft:leaves2:1)
Block(-2,7,-5,minecraft:leaves2:1)
Block(-1,7,-5,minecraft:leaves2:1)
Block(0,7,-5,minecraft:leaves2:1)
Block(1,7,-5,minecraft:leaves2:1)
Block(2,7,-5,minecraft:leaves2:1)
Block(-3,7,-4,minecraft:leaves2:1)
Block(-2,7,-4,minecraft:leaves2:1)
Block(-1,7,-4,minecraft:leaves2:1)
Block(0,7,-4,minecraft:leaves2:1)
Block(1,7,-4,minecraft:leaves2:1)
Block(2,7,-4,minecraft:leaves2:1)
Block(3,7,-4,minecraft:leaves2:1)
Block(-4,7,-3,minecraft:leaves2:1)
Block(-1,7,-3,minecraft:leaves2:1)
Block(0,7,-3,minecraft:leaves2:1)
Block(1,7,-3,minecraft:leaves2:1)
Block(2,7,-3,minecraft:leaves2:1)
Block(3,7,-3,minecraft:leaves2:1)
Block(4,7,-3,minecraft:leaves2:1)
Block(-5,7,-2,minecraft:leaves2:1)
Block(-3,7,-2,minecraft:leaves2:1)
Block(-2,7,-2,minecraft:leaves2:1)
Block(-1,7,-2,minecraft:leaves2:1)
Block(0,7,-2,minecraft:leaves2:1)
Block(1,7,-2,minecraft:leaves2:1)
Block(2,7,-2,minecraft:leaves2:1)
Block(3,7,-2,minecraft:leaves2:1)
Block(4,7,-2,minecraft:leaves2:1)
Block(5,7,-2,minecraft:leaves2:1)
Block(-4,7,-1,minecraft:leaves2:1)
Block(-3,7,-1,minecraft:leaves2:1)
Block(-2,7,-1,minecraft:leaves2:1)
Block(-1,7,-1,minecraft:log2:1)
Block(0,7,-1,minecraft:log2:1)
Block(1,7,-1,minecraft:log2:1)
Block(2,7,-1,minecraft:log2:1)
Block(3,7,-1,minecraft:leaves2:1)
Block(4,7,-1,minecraft:leaves2:1)
Block(5,7,-1,minecraft:leaves2:1)
Block(-3,7,0,minecraft:leaves2:1)
Block(-2,7,0,minecraft:log2:1)
Block(-1,7,0,minecraft:log2:1)
Block(0,7,0,minecraft:leaves2:1)
Block(1,7,0,minecraft:log2:1)
Block(2,7,0,minecraft:log2:1)
Block(3,7,0,minecraft:log2:1)
Block(4,7,0,minecraft:leaves2:1)
Block(5,7,0,minecraft:leaves2:1)
Block(-5,7,1,minecraft:leaves2:1)
Block(-3,7,1,minecraft:leaves2:1)
Block(-2,7,1,minecraft:log2:1)
Block(-1,7,1,minecraft:log2:1)
Block(0,7,1,minecraft:log2:1)
Block(1,7,1,minecraft:log2:1)
Block(2,7,1,minecraft:log2:1)
Block(3,7,1,minecraft:log2:1)
Block(4,7,1,minecraft:leaves2:1)
Block(5,7,1,minecraft:leaves2:1)
Block(-4,7,2,minecraft:leaves2:1)
Block(-3,7,2,minecraft:leaves2:1)
Block(-2,7,2,minecraft:leaves2:1)
Block(-1,7,2,minecraft:log2:1)
Block(0,7,2,minecraft:log2:1)
Block(1,7,2,minecraft:log2:1)
Block(2,7,2,minecraft:log2:1)
Block(3,7,2,minecraft:leaves2:1)
Block(4,7,2,minecraft:leaves2:1)
Block(5,7,2,minecraft:leaves2:1)
Block(-4,7,3,minecraft:leaves2:1)
Block(-3,7,3,minecraft:leaves2:1)
Block(-2,7,3,minecraft:leaves2:1)
Block(-1,7,3,minecraft:leaves2:1)
Block(0,7,3,minecraft:leaves2:1)
Block(1,7,3,minecraft:leaves2:1)
Block(2,7,3,minecraft:leaves2:1)
Block(3,7,3,minecraft:leaves2:1)
Block(4,7,3,minecraft:leaves2:1)
Block(-3,7,4,minecraft:leaves2:1)
Block(-2,7,4,minecraft:leaves2:1)
Block(-1,7,4,minecraft:leaves2:1)
Block(0,7,4,minecraft:leaves2:1)
Block(1,7,4,minecraft:leaves2:1)
Block(2,7,4,minecraft:leaves2:1)
Block(3,7,4,minecraft:leaves2:1)
Block(-2,7,5,minecraft:leaves2:1)
Block(-1,7,5,minecraft:leaves2:1)
Block(1,7,5,minecraft:leaves2:1)
Block(1,8,-5,minecraft:leaves2:1)
Block(-3,8,-4,minecraft:leaves2:1)
Block(-2,8,-4,minecraft:leaves2:1)
Block(0,8,-4,minecraft:leaves2:1)
Block(-3,8,-3,minecraft:leaves2:1)
Block(-2,8,-3,minecraft:leaves2:1)
Block(1,8,-3,minecraft:leaves2:1)
Block(2,8,-3,minecraft:leaves2:1)
Block(-5,8,-2,minecraft:leaves2:1)
Block(5,8,-2,minecraft:leaves2:1)
Block(-3,8,-1,minecraft:leaves2:1)
Block(-1,8,-1,minecraft:log2:1)
Block(0,8,-1,minecraft:log2:1)
Block(1,8,-1,minecraft:log2:1)
Block(2,8,-1,minecraft:log2:1)
Block(3,8,-1,minecraft:leaves2:1)
Block(4,8,-1,minecraft:leaves2:1)
Block(-2,8,0,minecraft:log2:1)
Block(-1,8,0,minecraft:log2:1)
Block(0,8,0,minecraft:log2:1)
Block(1,8,0,minecraft:log2:1)
Block(2,8,0,minecraft:log2:1)
Block(3,8,0,minecraft:log2:1)
Block(-5,8,1,minecraft:leaves2:1)
Block(-2,8,1,minecraft:leaves2:1)
Block(-1,8,1,minecraft:log2:1)
Block(0,8,1,minecraft:log2:1)
Block(1,8,1,minecraft:log2:1)
Block(2,8,1,minecraft:log2:1)
Block(3,8,1,minecraft:log2:1)
Block(-1,8,2,minecraft:leaves2:1)
Block(0,8,2,minecraft:log2:1)
Block(1,8,2,minecraft:log2:1)
Block(2,8,2,minecraft:log2:1)
Block(-4,8,3,minecraft:leaves2:1)
Block(1,8,3,minecraft:leaves2:1)
Block(2,8,3,minecraft:leaves2:1)
Block(3,8,3,minecraft:leaves2:1)
Block(4,8,3,minecraft:leaves2:1)
Block(2,8,5,minecraft:leaves2:1)
Block(-2,9,-7,minecraft:leaves2:1)
Block(0,9,-7,minecraft:leaves2:1)
Block(1,9,-7,minecraft:leaves2:1)
Block(2,9,-7,minecraft:leaves2:1)
Block(-3,9,-6,minecraft:leaves2:1)
Block(-2,9,-6,minecraft:leaves2:1)
Block(-1,9,-6,minecraft:leaves2:1)
Block(0,9,-6,minecraft:leaves2:1)
Block(1,9,-6,minecraft:leaves2:1)
Block(2,9,-6,minecraft:leaves2:1)
Block(3,9,-6,minecraft:leaves2:1)
Block(4,9,-6,minecraft:leaves2:1)
Block(-5,9,-5,minecraft:leaves2:1)
Block(-4,9,-5,minecraft:leaves2:1)
Block(-3,9,-5,minecraft:leaves2:1)
Block(-2,9,-5,minecraft:leaves2:1)
Block(-1,9,-5,minecraft:leaves2:1)
Block(0,9,-5,minecraft:leaves2:1)
Block(2,9,-5,minecraft:leaves2:1)
Block(4,9,-5,minecraft:leaves2:1)
Block(5,9,-5,minecraft:leaves2:1)
Block(-6,9,-4,minecraft:leaves2:1)
Block(-5,9,-4,minecraft:leaves2:1)
Block(-4,9,-4,minecraft:leaves2:1)
Block(-3,9,-4,minecraft:leaves2:1)
Block(-1,9,-4,minecraft:leaves2:1)
Block(0,9,-4,minecraft:leaves2:1)
Block(1,9,-4,minecraft:leaves2:1)
Block(2,9,-4,minecraft:leaves2:1)
Block(3,9,-4,minecraft:leaves2:1)
Block(4,9,-4,minecraft:leaves2:1)
Block(5,9,-4,minecraft:leaves2:1)
Block(6,9,-4,minecraft:leaves2:1)
Block(-6,9,-3,minecraft:leaves2:1)
Block(-5,9,-3,minecraft:leaves2:1)
Block(-4,9,-3,minecraft:leaves2:1)
Block(-2,9,-3,minecraft:leaves2:1)
Block(-1,9,-3,minecraft:leaves2:1)
Block(0,9,-3,minecraft:leaves2:1)
Block(1,9,-3,minecraft:leaves2:1)
Block(2,9,-3,minecraft:leaves2:1)
Block(3,9,-3,minecraft:leaves2:1)
Block(4,9,-3,minecraft:leaves2:1)
Block(6,9,-3,minecraft:leaves2:1)
Block(-7,9,-2,minecraft:leaves2:1)
Block(-6,9,-2,minecraft:leaves2:1)
Block(-5,9,-2,minecraft:leaves2:1)
Block(-4,9,-2,minecraft:leaves2:1)
Block(-3,9,-2,minecraft:leaves2:1)
Block(-2,9,-2,minecraft:leaves2:1)
Block(-1,9,-2,minecraft:leaves2:1)
Block(0,9,-2,minecraft:leaves2:1)
Block(1,9,-2,minecraft:leaves2:1)
Block(2,9,-2,minecraft:leaves2:1)
Block(3,9,-2,minecraft:leaves2:1)
Block(4,9,-2,minecraft:leaves2:1)
Block(5,9,-2,minecraft:leaves2:1)
Block(6,9,-2,minecraft:leaves2:1)
Block(7,9,-2,minecraft:leaves2:1)
Block(-7,9,-1,minecraft:leaves2:1)
Block(-6,9,-1,minecraft:leaves2:1)
Block(-5,9,-1,minecraft:leaves2:1)
Block(-4,9,-1,minecraft:leaves2:1)
Block(-3,9,-1,minecraft:leaves2:1)
Block(-2,9,-1,minecraft:leaves2:1)
Block(-1,9,-1,minecraft:log2:1)
Block(0,9,-1,minecraft:log2:1)
Block(1,9,-1,minecraft:log2:1)
Block(2,9,-1,minecraft:log2:1)
Block(3,9,-1,minecraft:leaves2:1)
Block(5,9,-1,minecraft:leaves2:1)
Block(6,9,-1,minecraft:leaves2:1)
Block(7,9,-1,minecraft:leaves2:1)
Block(-3,9,0,minecraft:leaves2:1)
Block(-2,9,0,minecraft:log2:1)
Block(-1,9,0,minecraft:log2:1)
Block(0,9,0,minecraft:leaves2:1)
Block(1,9,0,minecraft:log2:1)
Block(2,9,0,minecraft:log2:1)
Block(3,9,0,minecraft:log2:1)
Block(4,9,0,minecraft:leaves2:1)
Block(5,9,0,minecraft:leaves2:1)
Block(6,9,0,minecraft:leaves2:1)
Block(7,9,0,minecraft:leaves2:1)
Block(-7,9,1,minecraft:leaves2:1)
Block(-6,9,1,minecraft:leaves2:1)
Block(-4,9,1,minecraft:leaves2:1)
Block(-3,9,1,minecraft:leaves2:1)
Block(-2,9,1,minecraft:log2:1)
Block(-1,9,1,minecraft:log2:1)
Block(0,9,1,minecraft:log2:1)
Block(1,9,1,minecraft:log2:1)
Block(2,9,1,minecraft:log2:1)
Block(3,9,1,minecraft:log2:1)
Block(4,9,1,minecraft:leaves2:1)
Block(5,9,1,minecraft:leaves2:1)
Block(6,9,1,minecraft:leaves2:1)
Block(7,9,1,minecraft:leaves2:1)
Block(-7,9,2,minecraft:leaves2:1)
Block(-6,9,2,minecraft:leaves2:1)
Block(-5,9,2,minecraft:leaves2:1)
Block(-4,9,2,minecraft:leaves2:1)
Block(-3,9,2,minecraft:leaves2:1)
Block(-2,9,2,minecraft:leaves2:1)
Block(-1,9,2,minecraft:log2:1)
Block(0,9,2,minecraft:leaves2:1)
Block(1,9,2,minecraft:log2:1)
Block(2,9,2,minecraft:log2:1)
Block(3,9,2,minecraft:leaves2:1)
Block(4,9,2,minecraft:leaves2:1)
Block(5,9,2,minecraft:leaves2:1)
Block(6,9,2,minecraft:leaves2:1)
Block(7,9,2,minecraft:leaves2:1)
Block(-6,9,3,minecraft:leaves2:1)
Block(-5,9,3,minecraft:leaves2:1)
Block(-3,9,3,minecraft:leaves2:1)
Block(-2,9,3,minecraft:leaves2:1)
Block(-1,9,3,minecraft:leaves2:1)
Block(0,9,3,minecraft:leaves2:1)
Block(1,9,3,minecraft:leaves2:1)
Block(2,9,3,minecraft:leaves2:1)
Block(3,9,3,minecraft:leaves2:1)
Block(4,9,3,minecraft:leaves2:1)
Block(5,9,3,minecraft:leaves2:1)
Block(6,9,3,minecraft:leaves2:1)
Block(-6,9,4,minecraft:leaves2:1)
Block(-5,9,4,minecraft:leaves2:1)
Block(-4,9,4,minecraft:leaves2:1)
Block(-3,9,4,minecraft:leaves2:1)
Block(-2,9,4,minecraft:leaves2:1)
Block(-1,9,4,minecraft:leaves2:1)
Block(0,9,4,minecraft:leaves2:1)
Block(1,9,4,minecraft:leaves2:1)
Block(2,9,4,minecraft:leaves2:1)
Block(3,9,4,minecraft:leaves2:1)
Block(4,9,4,minecraft:leaves2:1)
Block(5,9,4,minecraft:leaves2:1)
Block(6,9,4,minecraft:leaves2:1)
Block(-5,9,5,minecraft:leaves2:1)
Block(-4,9,5,minecraft:leaves2:1)
Block(-3,9,5,minecraft:leaves2:1)
Block(-2,9,5,minecraft:leaves2:1)
Block(-1,9,5,minecraft:leaves2:1)
Block(0,9,5,minecraft:leaves2:1)
Block(1,9,5,minecraft:leaves2:1)
Block(2,9,5,minecraft:leaves2:1)
Block(3,9,5,minecraft:leaves2:1)
Block(4,9,5,minecraft:leaves2:1)
Block(-4,9,6,minecraft:leaves2:1)
Block(-3,9,6,minecraft:leaves2:1)
Block(-2,9,6,minecraft:leaves2:1)
Block(-1,9,6,minecraft:leaves2:1)
Block(0,9,6,minecraft:leaves2:1)
Block(1,9,6,minecraft:leaves2:1)
Block(2,9,6,minecraft:leaves2:1)
Block(-2,9,7,minecraft:leaves2:1)
Block(-1,9,7,minecraft:leaves2:1)
Block(2,9,7,minecraft:leaves2:1)
Block(-2,10,-7,minecraft:leaves2:1)
Block(2,10,-7,minecraft:leaves2:1)
Block(-1,10,-6,minecraft:leaves2:1)
Block(3,10,-6,minecraft:leaves2:1)
Block(4,10,-6,minecraft:leaves2:1)
Block(-4,10,-5,minecraft:leaves2:1)
Block(-3,10,-5,minecraft:leaves2:1)
Block(0,10,-5,minecraft:leaves2:1)
Block(-6,10,-4,minecraft:leaves2:1)
Block(-5,10,-4,minecraft:leaves2:1)
Block(-3,10,-4,minecraft:leaves2:1)
Block(-2,10,-4,minecraft:leaves2:1)
Block(-1,10,-4,minecraft:leaves2:1)
Block(2,10,-4,minecraft:leaves2:1)
Block(3,10,-4,minecraft:leaves2:1)
Block(4,10,-4,minecraft:leaves2:1)
Block(-2,10,-3,minecraft:leaves2:1)
Block(4,10,-3,minecraft:leaves2:1)
Block(-3,10,-2,minecraft:leaves2:1)
Block(-2,10,-2,minecraft:leaves2:1)
Block(-1,10,-2,minecraft:log2:1)
Block(0,10,-2,minecraft:log2:1)
Block(1,10,-2,minecraft:log2:1)
Block(4,10,-2,minecraft:leaves2:1)
Block(-5,10,-1,minecraft:leaves2:1)
Block(-4,10,-1,minecraft:leaves2:1)
Block(-2,10,-1,minecraft:leaves2:1)
Block(-1,10,-1,minecraft:log2:1)
Block(0,10,-1,minecraft:log2:1)
Block(1,10,-1,minecraft:log2:1)
Block(2,10,-1,minecraft:log2:1)
Block(-3,10,0,minecraft:leaves2:1)
Block(-2,10,0,minecraft:log2:1)
Block(-1,10,0,minecraft:log2:1)
Block(0,10,0,minecraft:log2:1)
Block(1,10,0,minecraft:log2:1)
Block(2,10,0,minecraft:log2:1)
Block(3,10,0,minecraft:leaves2:1)
Block(6,10,0,minecraft:leaves2:1)
Block(7,10,0,minecraft:leaves2:1)
Block(-7,10,1,minecraft:leaves2:1)
Block(-4,10,1,minecraft:leaves2:1)
Block(-3,10,1,minecraft:leaves2:1)
Block(-2,10,1,minecraft:log2:1)
Block(-1,10,1,minecraft:log2:1)
Block(0,10,1,minecraft:log2:1)
Block(1,10,1,minecraft:log2:1)
Block(2,10,1,minecraft:log2:1)
Block(3,10,1,minecraft:leaves2:1)
Block(6,10,1,minecraft:leaves2:1)
Block(7,10,1,minecraft:leaves2:1)
Block(-7,10,2,minecraft:leaves2:1)
Block(-5,10,2,minecraft:leaves2:1)
Block(-4,10,2,minecraft:leaves2:1)
Block(-1,10,2,minecraft:log2:1)
Block(0,10,2,minecraft:log2:1)
Block(1,10,2,minecraft:log2:1)
Block(2,10,2,minecraft:log2:1)
Block(7,10,2,minecraft:leaves2:1)
Block(-6,10,3,minecraft:leaves2:1)
Block(-5,10,3,minecraft:leaves2:1)
Block(2,10,3,minecraft:leaves2:1)
Block(5,10,3,minecraft:leaves2:1)
Block(-2,10,4,minecraft:leaves2:1)
Block(-1,10,4,minecraft:leaves2:1)
Block(3,10,4,minecraft:leaves2:1)
Block(4,10,4,minecraft:leaves2:1)
Block(6,10,4,minecraft:leaves2:1)
Block(-5,10,5,minecraft:leaves2:1)
Block(-4,10,5,minecraft:leaves2:1)
Block(-3,10,5,minecraft:leaves2:1)
Block(-4,10,6,minecraft:leaves2:1)
Block(-3,10,6,minecraft:leaves2:1)
Block(-2,10,6,minecraft:leaves2:1)
Block(1,10,6,minecraft:leaves2:1)
Block(2,10,6,minecraft:leaves2:1)
Block(-1,10,7,minecraft:leaves2:1)
Block(2,10,7,minecraft:leaves2:1)
Block(-3,11,-9,minecraft:leaves2:1)
Block(-2,11,-9,minecraft:leaves2:1)
Block(-1,11,-9,minecraft:leaves2:1)
Block(0,11,-9,minecraft:leaves2:1)
Block(1,11,-9,minecraft:leaves2:1)
Block(2,11,-9,minecraft:leaves2:1)
Block(-4,11,-8,minecraft:leaves2:1)
Block(-3,11,-8,minecraft:leaves2:1)
Block(-1,11,-8,minecraft:leaves2:1)
Block(0,11,-8,minecraft:leaves2:1)
Block(1,11,-8,minecraft:leaves2:1)
Block(3,11,-8,minecraft:leaves2:1)
Block(5,11,-8,minecraft:leaves2:1)
Block(-6,11,-7,minecraft:leaves2:1)
Block(-5,11,-7,minecraft:leaves2:1)
Block(-2,11,-7,minecraft:leaves2:1)
Block(-1,11,-7,minecraft:leaves2:1)
Block(0,11,-7,minecraft:leaves2:1)
Block(1,11,-7,minecraft:leaves2:1)
Block(2,11,-7,minecraft:leaves2:1)
Block(5,11,-7,minecraft:leaves2:1)
Block(6,11,-7,minecraft:leaves2:1)
Block(-6,11,-6,minecraft:leaves2:1)
Block(-5,11,-6,minecraft:leaves2:1)
Block(-4,11,-6,minecraft:leaves2:1)
Block(-3,11,-6,minecraft:leaves2:1)
Block(-2,11,-6,minecraft:leaves2:1)
Block(-1,11,-6,minecraft:leaves2:1)
Block(0,11,-6,minecraft:leaves2:1)
Block(1,11,-6,minecraft:leaves2:1)
Block(2,11,-6,minecraft:leaves2:1)
Block(3,11,-6,minecraft:leaves2:1)
Block(5,11,-6,minecraft:leaves2:1)
Block(7,11,-6,minecraft:leaves2:1)
Block(-8,11,-5,minecraft:leaves2:1)
Block(-7,11,-5,minecraft:leaves2:1)
Block(-6,11,-5,minecraft:leaves2:1)
Block(-5,11,-5,minecraft:leaves2:1)
Block(-3,11,-5,minecraft:leaves2:1)
Block(-2,11,-5,minecraft:leaves2:1)
Block(-1,11,-5,minecraft:leaves2:1)
Block(0,11,-5,minecraft:leaves2:1)
Block(1,11,-5,minecraft:leaves2:1)
Block(2,11,-5,minecraft:leaves2:1)
Block(3,11,-5,minecraft:leaves2:1)
Block(4,11,-5,minecraft:leaves2:1)
Block(5,11,-5,minecraft:leaves2:1)
Block(6,11,-5,minecraft:leaves2:1)
Block(7,11,-5,minecraft:leaves2:1)
Block(8,11,-5,minecraft:leaves2:1)
Block(-8,11,-4,minecraft:leaves2:1)
Block(-6,11,-4,minecraft:leaves2:1)
Block(-4,11,-4,minecraft:leaves2:1)
Block(-2,11,-4,minecraft:leaves2:1)
Block(0,11,-4,minecraft:leaves2:1)
Block(1,11,-4,minecraft:leaves2:1)
Block(2,11,-4,minecraft:leaves2:1)
Block(4,11,-4,minecraft:leaves2:1)
Block(5,11,-4,minecraft:leaves2:1)
Block(6,11,-4,minecraft:leaves2:1)
Block(8,11,-4,minecraft:leaves2:1)
Block(-9,11,-3,minecraft:leaves2:1)
Block(-8,11,-3,minecraft:leaves2:1)
Block(-7,11,-3,minecraft:leaves2:1)
Block(-6,11,-3,minecraft:leaves2:1)
Block(-5,11,-3,minecraft:leaves2:1)
Block(-4,11,-3,minecraft:leaves2:1)
Block(-3,11,-3,minecraft:leaves2:1)
Block(-1,11,-3,minecraft:leaves2:1)
Block(0,11,-3,minecraft:leaves2:1)
Block(1,11,-3,minecraft:leaves2:1)
Block(2,11,-3,minecraft:leaves2:1)
Block(3,11,-3,minecraft:leaves2:1)
Block(6,11,-3,minecraft:leaves2:1)
Block(7,11,-3,minecraft:leaves2:1)
Block(8,11,-3,minecraft:leaves2:1)
Block(9,11,-3,minecraft:leaves2:1)
Block(-9,11,-2,minecraft:leaves2:1)
Block(-8,11,-2,minecraft:leaves2:1)
Block(-7,11,-2,minecraft:leaves2:1)
Block(-6,11,-2,minecraft:leaves2:1)
Block(-5,11,-2,minecraft:leaves2:1)
Block(-4,11,-2,minecraft:leaves2:1)
Block(-3,11,-2,minecraft:leaves2:1)
Block(-2,11,-2,minecraft:leaves2:1)
Block(-1,11,-2,minecraft:log2:1)
Block(0,11,-2,minecraft:log2:1)
Block(1,11,-2,minecraft:log2:1)
Block(2,11,-2,minecraft:leaves2:1)
Block(3,11,-2,minecraft:leaves2:1)
Block(4,11,-2,minecraft:leaves2:1)
Block(5,11,-2,minecraft:leaves2:1)
Block(6,11,-2,minecraft:leaves2:1)
Block(7,11,-2,minecraft:leaves2:1)
Block(-9,11,-1,minecraft:leaves2:1)
Block(-8,11,-1,minecraft:leaves2:1)
Block(-7,11,-1,minecraft:leaves2:1)
Block(-6,11,-1,minecraft:leaves2:1)
Block(-4,11,-1,minecraft:leaves2:1)
Block(-3,11,-1,minecraft:leaves2:1)
Block(-2,11,-1,minecraft:leaves2:1)
Block(-1,11,-1,minecraft:log2:1)
Block(0,11,-1,minecraft:log2:1)
Block(1,11,-1,minecraft:log2:1)
Block(2,11,-1,minecraft:log2:1)
Block(3,11,-1,minecraft:leaves2:1)
Block(4,11,-1,minecraft:leaves2:1)
Block(5,11,-1,minecraft:leaves2:1)
Block(6,11,-1,minecraft:leaves2:1)
Block(7,11,-1,minecraft:leaves2:1)
Block(8,11,-1,minecraft:leaves2:1)
Block(9,11,-1,minecraft:leaves2:1)
Block(-9,11,0,minecraft:leaves2:1)
Block(-8,11,0,minecraft:leaves2:1)
Block(-7,11,0,minecraft:leaves2:1)
Block(-6,11,0,minecraft:leaves2:1)
Block(-5,11,0,minecraft:leaves2:1)
Block(-4,11,0,minecraft:leaves2:1)
Block(-3,11,0,minecraft:leaves2:1)
Block(-2,11,0,minecraft:log2:1)
Block(-1,11,0,minecraft:log2:1)
Block(0,11,0,minecraft:leaves2:1)
Block(1,11,0,minecraft:log2:1)
Block(2,11,0,minecraft:log2:1)
Block(3,11,0,minecraft:leaves2:1)
Block(4,11,0,minecraft:leaves2:1)
Block(5,11,0,minecraft:leaves2:1)
Block(6,11,0,minecraft:leaves2:1)
Block(7,11,0,minecraft:leaves2:1)
Block(8,11,0,minecraft:leaves2:1)
Block(9,11,0,minecraft:leaves2:1)
Block(-9,11,1,minecraft:leaves2:1)
Block(-8,11,1,minecraft:leaves2:1)
Block(-6,11,1,minecraft:leaves2:1)
Block(-5,11,1,minecraft:leaves2:1)
Block(-4,11,1,minecraft:leaves2:1)
Block(-3,11,1,minecraft:leaves2:1)
Block(-2,11,1,minecraft:log2:1)
Block(-1,11,1,minecraft:log2:1)
Block(0,11,1,minecraft:log2:1)
Block(1,11,1,minecraft:log2:1)
Block(2,11,1,minecraft:log2:1)
Block(3,11,1,minecraft:leaves2:1)
Block(4,11,1,minecraft:leaves2:1)
Block(5,11,1,minecraft:leaves2:1)
Block(7,11,1,minecraft:leaves2:1)
Block(8,11,1,minecraft:leaves2:1)
Block(9,11,1,minecraft:leaves2:1)
Block(-9,11,2,minecraft:leaves2:1)
Block(-7,11,2,minecraft:leaves2:1)
Block(-6,11,2,minecraft:leaves2:1)
Block(-5,11,2,minecraft:leaves2:1)
Block(-4,11,2,minecraft:leaves2:1)
Block(-3,11,2,minecraft:leaves2:1)
Block(-2,11,2,minecraft:leaves2:1)
Block(-1,11,2,minecraft:log2:1)
Block(0,11,2,minecraft:log2:1)
Block(1,11,2,minecraft:log2:1)
Block(2,11,2,minecraft:log2:1)
Block(3,11,2,minecraft:leaves2:1)
Block(4,11,2,minecraft:leaves2:1)
Block(5,11,2,minecraft:leaves2:1)
Block(6,11,2,minecraft:leaves2:1)
Block(8,11,2,minecraft:leaves2:1)
Block(9,11,2,minecraft:leaves2:1)
Block(-9,11,3,minecraft:leaves2:1)
Block(-8,11,3,minecraft:leaves2:1)
Block(-7,11,3,minecraft:leaves2:1)
Block(-5,11,3,minecraft:leaves2:1)
Block(-4,11,3,minecraft:leaves2:1)
Block(-3,11,3,minecraft:leaves2:1)
Block(-2,11,3,minecraft:leaves2:1)
Block(-1,11,3,minecraft:leaves2:1)
Block(0,11,3,minecraft:leaves2:1)
Block(1,11,3,minecraft:leaves2:1)
Block(3,11,3,minecraft:leaves2:1)
Block(4,11,3,minecraft:leaves2:1)
Block(5,11,3,minecraft:leaves2:1)
Block(6,11,3,minecraft:leaves2:1)
Block(7,11,3,minecraft:leaves2:1)
Block(8,11,3,minecraft:leaves2:1)
Block(9,11,3,minecraft:leaves2:1)
Block(-8,11,4,minecraft:leaves2:1)
Block(-7,11,4,minecraft:leaves2:1)
Block(-6,11,4,minecraft:leaves2:1)
Block(-5,11,4,minecraft:leaves2:1)
Block(-4,11,4,minecraft:leaves2:1)
Block(-3,11,4,minecraft:leaves2:1)
Block(-2,11,4,minecraft:leaves2:1)
Block(-1,11,4,minecraft:leaves2:1)
Block(0,11,4,minecraft:leaves2:1)
Block(1,11,4,minecraft:leaves2:1)
Block(2,11,4,minecraft:leaves2:1)
Block(5,11,4,minecraft:leaves2:1)
Block(6,11,4,minecraft:leaves2:1)
Block(7,11,4,minecraft:leaves2:1)
Block(8,11,4,minecraft:leaves2:1)
Block(-7,11,5,minecraft:leaves2:1)
Block(-6,11,5,minecraft:leaves2:1)
Block(-4,11,5,minecraft:leaves2:1)
Block(-3,11,5,minecraft:leaves2:1)
Block(-2,11,5,minecraft:leaves2:1)
Block(-1,11,5,minecraft:leaves2:1)
Block(0,11,5,minecraft:leaves2:1)
Block(1,11,5,minecraft:leaves2:1)
Block(2,11,5,minecraft:leaves2:1)
Block(3,11,5,minecraft:leaves2:1)
Block(4,11,5,minecraft:leaves2:1)
Block(5,11,5,minecraft:leaves2:1)
Block(6,11,5,minecraft:leaves2:1)
Block(8,11,5,minecraft:leaves2:1)
Block(-7,11,6,minecraft:leaves2:1)
Block(-6,11,6,minecraft:leaves2:1)
Block(-5,11,6,minecraft:leaves2:1)
Block(-4,11,6,minecraft:leaves2:1)
Block(-1,11,6,minecraft:leaves2:1)
Block(0,11,6,minecraft:leaves2:1)
Block(1,11,6,minecraft:leaves2:1)
Block(3,11,6,minecraft:leaves2:1)
Block(5,11,6,minecraft:leaves2:1)
Block(6,11,6,minecraft:leaves2:1)
Block(7,11,6,minecraft:leaves2:1)
Block(-6,11,7,minecraft:leaves2:1)
Block(-4,11,7,minecraft:leaves2:1)
Block(-3,11,7,minecraft:leaves2:1)
Block(-2,11,7,minecraft:leaves2:1)
Block(-1,11,7,minecraft:leaves2:1)
Block(0,11,7,minecraft:leaves2:1)
Block(1,11,7,minecraft:leaves2:1)
Block(2,11,7,minecraft:leaves2:1)
Block(3,11,7,minecraft:leaves2:1)
Block(4,11,7,minecraft:leaves2:1)
Block(5,11,7,minecraft:leaves2:1)
Block(6,11,7,minecraft:leaves2:1)
Block(-5,11,8,minecraft:leaves2:1)
Block(-4,11,8,minecraft:leaves2:1)
Block(-2,11,8,minecraft:leaves2:1)
Block(-1,11,8,minecraft:leaves2:1)
Block(0,11,8,minecraft:leaves2:1)
Block(1,11,8,minecraft:leaves2:1)
Block(2,11,8,minecraft:leaves2:1)
Block(4,11,8,minecraft:leaves2:1)
Block(-2,11,9,minecraft:leaves2:1)
Block(0,11,9,minecraft:leaves2:1)
Block(1,11,9,minecraft:leaves2:1)
Block(2,11,9,minecraft:leaves2:1)
Block(3,11,9,minecraft:leaves2:1)
Block(-1,12,-9,minecraft:leaves2:1)
Block(2,12,-9,minecraft:leaves2:1)
Block(-2,12,-8,minecraft:leaves2:1)
Block(-1,12,-8,minecraft:leaves2:1)
Block(3,12,-8,minecraft:leaves2:1)
Block(5,12,-8,minecraft:leaves2:1)
Block(0,12,-7,minecraft:leaves2:1)
Block(1,12,-7,minecraft:leaves2:1)
Block(3,12,-7,minecraft:leaves2:1)
Block(5,12,-7,minecraft:leaves2:1)
Block(-1,12,-6,minecraft:leaves2:1)
Block(5,12,-6,minecraft:leaves2:1)
Block(7,12,-6,minecraft:leaves2:1)
Block(-7,12,-5,minecraft:leaves2:1)
Block(-2,12,-5,minecraft:leaves2:1)
Block(0,12,-5,minecraft:leaves2:1)
Block(4,12,-5,minecraft:leaves2:1)
Block(5,12,-5,minecraft:leaves2:1)
Block(6,12,-5,minecraft:leaves2:1)
Block(0,12,-4,minecraft:leaves2:1)
Block(2,12,-4,minecraft:leaves2:1)
Block(4,12,-4,minecraft:leaves2:1)
Block(5,12,-4,minecraft:leaves2:1)
Block(-7,12,-3,minecraft:leaves2:1)
Block(-5,12,-3,minecraft:leaves2:1)
Block(-4,12,-3,minecraft:leaves2:1)
Block(0,12,-3,minecraft:leaves2:1)
Block(1,12,-3,minecraft:leaves2:1)
Block(2,12,-3,minecraft:leaves2:1)
Block(-9,12,-2,minecraft:leaves2:1)
Block(-7,12,-2,minecraft:leaves2:1)
Block(-5,12,-2,minecraft:leaves2:1)
Block(-3,12,-2,minecraft:leaves2:1)
Block(-1,12,-2,minecraft:log2:1)
Block(0,12,-2,minecraft:log2:1)
Block(1,12,-2,minecraft:log2:1)
Block(3,12,-2,minecraft:leaves2:1)
Block(6,12,-2,minecraft:leaves2:1)
Block(-7,12,-1,minecraft:leaves2:1)
Block(-5,12,-1,minecraft:leaves2:1)
Block(-3,12,-1,minecraft:leaves2:1)
Block(-2,12,-1,minecraft:leaves2:1)
Block(-1,12,-1,minecraft:log2:1)
Block(0,12,-1,minecraft:log2:1)
Block(1,12,-1,minecraft:log2:1)
Block(2,12,-1,minecraft:log2:1)
Block(6,12,-1,minecraft:leaves2:1)
Block(-9,12,0,minecraft:leaves2:1)
Block(-8,12,0,minecraft:leaves2:1)
Block(-7,12,0,minecraft:leaves2:1)
Block(-6,12,0,minecraft:leaves2:1)
Block(-5,12,0,minecraft:leaves2:1)
Block(-4,12,0,minecraft:leaves2:1)
Block(-2,12,0,minecraft:log2:1)
Block(-1,12,0,minecraft:log2:1)
Block(0,12,0,minecraft:log2:1)
Block(1,12,0,minecraft:log2:1)
Block(2,12,0,minecraft:log2:1)
Block(3,12,0,minecraft:leaves2:1)
Block(6,12,0,minecraft:leaves2:1)
Block(9,12,0,minecraft:leaves2:1)
Block(-4,12,1,minecraft:leaves2:1)
Block(-2,12,1,minecraft:log2:1)
Block(-1,12,1,minecraft:log2:1)
Block(0,12,1,minecraft:log2:1)
Block(1,12,1,minecraft:log2:1)
Block(2,12,1,minecraft:log2:1)
Block(-3,12,2,minecraft:leaves2:1)
Block(-2,12,2,minecraft:leaves2:1)
Block(-1,12,2,minecraft:log2:1)
Block(0,12,2,minecraft:log2:1)
Block(1,12,2,minecraft:log2:1)
Block(4,12,2,minecraft:leaves2:1)
Block(5,12,2,minecraft:leaves2:1)
Block(6,12,2,minecraft:leaves2:1)
Block(-8,12,3,minecraft:leaves2:1)
Block(-7,12,3,minecraft:leaves2:1)
Block(-5,12,3,minecraft:leaves2:1)
Block(-4,12,3,minecraft:leaves2:1)
Block(-3,12,3,minecraft:leaves2:1)
Block(1,12,3,minecraft:leaves2:1)
Block(4,12,3,minecraft:leaves2:1)
Block(5,12,3,minecraft:leaves2:1)
Block(8,12,3,minecraft:leaves2:1)
Block(-5,12,4,minecraft:leaves2:1)
Block(-3,12,4,minecraft:leaves2:1)
Block(2,12,4,minecraft:leaves2:1)
Block(6,12,4,minecraft:leaves2:1)
Block(-3,12,5,minecraft:leaves2:1)
Block(-2,12,5,minecraft:leaves2:1)
Block(-1,12,5,minecraft:leaves2:1)
Block(1,12,5,minecraft:leaves2:1)
Block(4,12,5,minecraft:leaves2:1)
Block(5,12,5,minecraft:leaves2:1)
Block(6,12,5,minecraft:leaves2:1)
Block(-3,12,6,minecraft:leaves2:1)
Block(-1,12,6,minecraft:leaves2:1)
Block(1,12,6,minecraft:leaves2:1)
Block(3,12,6,minecraft:leaves2:1)
Block(7,12,6,minecraft:leaves2:1)
Block(-6,12,7,minecraft:leaves2:1)
Block(-5,12,7,minecraft:leaves2:1)
Block(-4,12,7,minecraft:leaves2:1)
Block(6,12,7,minecraft:leaves2:1)
Block(-5,12,8,minecraft:leaves2:1)
Block(2,12,8,minecraft:leaves2:1)
Block(4,12,8,minecraft:leaves2:1)
Block(1,12,9,minecraft:leaves2:1)
Block(-2,13,-7,minecraft:leaves2:1)
Block(-1,13,-7,minecraft:leaves2:1)
Block(0,13,-7,minecraft:leaves2:1)
Block(2,13,-7,minecraft:leaves2:1)
Block(-4,13,-6,minecraft:leaves2:1)
Block(-3,13,-6,minecraft:leaves2:1)
Block(-2,13,-6,minecraft:leaves2:1)
Block(-1,13,-6,minecraft:leaves2:1)
Block(0,13,-6,minecraft:leaves2:1)
Block(1,13,-6,minecraft:leaves2:1)
Block(2,13,-6,minecraft:leaves2:1)
Block(3,13,-6,minecraft:leaves2:1)
Block(4,13,-6,minecraft:leaves2:1)
Block(5,13,-6,minecraft:leaves2:1)
Block(-5,13,-5,minecraft:leaves2:1)
Block(-4,13,-5,minecraft:leaves2:1)
Block(-3,13,-5,minecraft:leaves2:1)
Block(-1,13,-5,minecraft:leaves2:1)
Block(0,13,-5,minecraft:leaves2:1)
Block(1,13,-5,minecraft:leaves2:1)
Block(2,13,-5,minecraft:leaves2:1)
Block(3,13,-5,minecraft:leaves2:1)
Block(4,13,-5,minecraft:leaves2:1)
Block(5,13,-5,minecraft:leaves2:1)
Block(-6,13,-4,minecraft:leaves2:1)
Block(-5,13,-4,minecraft:leaves2:1)
Block(-4,13,-4,minecraft:leaves2:1)
Block(-3,13,-4,minecraft:leaves2:1)
Block(-2,13,-4,minecraft:leaves2:1)
Block(-1,13,-4,minecraft:leaves2:1)
Block(0,13,-4,minecraft:leaves2:1)
Block(1,13,-4,minecraft:leaves2:1)
Block(3,13,-4,minecraft:leaves2:1)
Block(4,13,-4,minecraft:leaves2:1)
Block(6,13,-4,minecraft:leaves2:1)
Block(-6,13,-3,minecraft:leaves2:1)
Block(-4,13,-3,minecraft:leaves2:1)
Block(-3,13,-3,minecraft:leaves2:1)
Block(-2,13,-3,minecraft:leaves2:1)
Block(-1,13,-3,minecraft:leaves2:1)
Block(0,13,-3,minecraft:leaves2:1)
Block(1,13,-3,minecraft:leaves2:1)
Block(2,13,-3,minecraft:leaves2:1)
Block(3,13,-3,minecraft:leaves2:1)
Block(4,13,-3,minecraft:leaves2:1)
Block(6,13,-3,minecraft:leaves2:1)
Block(-7,13,-2,minecraft:leaves2:1)
Block(-6,13,-2,minecraft:leaves2:1)
Block(-4,13,-2,minecraft:leaves2:1)
Block(-2,13,-2,minecraft:leaves2:1)
Block(-1,13,-2,minecraft:log2:1)
Block(0,13,-2,minecraft:log2:1)
Block(1,13,-2,minecraft:log2:1)
Block(2,13,-2,minecraft:leaves2:1)
Block(3,13,-2,minecraft:leaves2:1)
Block(4,13,-2,minecraft:leaves2:1)
Block(5,13,-2,minecraft:leaves2:1)
Block(6,13,-2,minecraft:leaves2:1)
Block(7,13,-2,minecraft:leaves2:1)
Block(-6,13,-1,minecraft:leaves2:1)
Block(-5,13,-1,minecraft:leaves2:1)
Block(-4,13,-1,minecraft:leaves2:1)
Block(-3,13,-1,minecraft:leaves2:1)
Block(-2,13,-1,minecraft:leaves2:1)
Block(-1,13,-1,minecraft:log2:1)
Block(0,13,-1,minecraft:log2:1)
Block(1,13,-1,minecraft:log2:1)
Block(2,13,-1,minecraft:log2:1)
Block(3,13,-1,minecraft:leaves2:1)
Block(4,13,-1,minecraft:leaves2:1)
Block(5,13,-1,minecraft:leaves2:1)
Block(6,13,-1,minecraft:leaves2:1)
Block(7,13,-1,minecraft:leaves2:1)
Block(-9,13,0,minecraft:leaves2:1)
Block(-7,13,0,minecraft:leaves2:1)
Block(-5,13,0,minecraft:leaves2:1)
Block(-4,13,0,minecraft:leaves2:1)
Block(-3,13,0,minecraft:leaves2:1)
Block(-2,13,0,minecraft:log2:1)
Block(-1,13,0,minecraft:log2:1)
Block(0,13,0,minecraft:leaves2:1)
Block(1,13,0,minecraft:log2:1)
Block(2,13,0,minecraft:log2:1)
Block(4,13,0,minecraft:leaves2:1)
Block(5,13,0,minecraft:leaves2:1)
Block(7,13,0,minecraft:leaves2:1)
Block(-7,13,1,minecraft:leaves2:1)
Block(-6,13,1,minecraft:leaves2:1)
Block(-5,13,1,minecraft:leaves2:1)
Block(-4,13,1,minecraft:leaves2:1)
Block(-3,13,1,minecraft:leaves2:1)
Block(-2,13,1,minecraft:log2:1)
Block(-1,13,1,minecraft:log2:1)
Block(0,13,1,minecraft:log2:1)
Block(1,13,1,minecraft:log2:1)
Block(2,13,1,minecraft:log2:1)
Block(3,13,1,minecraft:leaves2:1)
Block(4,13,1,minecraft:leaves2:1)
Block(5,13,1,minecraft:leaves2:1)
Block(6,13,1,minecraft:leaves2:1)
Block(7,13,1,minecraft:leaves2:1)
Block(-7,13,2,minecraft:leaves2:1)
Block(-6,13,2,minecraft:leaves2:1)
Block(-5,13,2,minecraft:leaves2:1)
Block(-4,13,2,minecraft:leaves2:1)
Block(-3,13,2,minecraft:leaves2:1)
Block(-1,13,2,minecraft:log2:1)
Block(0,13,2,minecraft:log2:1)
Block(1,13,2,minecraft:log2:1)
Block(2,13,2,minecraft:leaves2:1)
Block(3,13,2,minecraft:leaves2:1)
Block(6,13,2,minecraft:leaves2:1)
Block(7,13,2,minecraft:leaves2:1)
Block(-6,13,3,minecraft:leaves2:1)
Block(-4,13,3,minecraft:leaves2:1)
Block(-3,13,3,minecraft:leaves2:1)
Block(-2,13,3,minecraft:leaves2:1)
Block(-1,13,3,minecraft:leaves2:1)
Block(0,13,3,minecraft:leaves2:1)
Block(2,13,3,minecraft:leaves2:1)
Block(3,13,3,minecraft:leaves2:1)
Block(4,13,3,minecraft:leaves2:1)
Block(5,13,3,minecraft:leaves2:1)
Block(6,13,3,minecraft:leaves2:1)
Block(-6,13,4,minecraft:leaves2:1)
Block(-5,13,4,minecraft:leaves2:1)
Block(-4,13,4,minecraft:leaves2:1)
Block(-3,13,4,minecraft:leaves2:1)
Block(-2,13,4,minecraft:leaves2:1)
Block(-1,13,4,minecraft:leaves2:1)
Block(0,13,4,minecraft:leaves2:1)
Block(1,13,4,minecraft:leaves2:1)
Block(2,13,4,minecraft:leaves2:1)
Block(3,13,4,minecraft:leaves2:1)
Block(4,13,4,minecraft:leaves2:1)
Block(5,13,4,minecraft:leaves2:1)
Block(-5,13,5,minecraft:leaves2:1)
Block(-4,13,5,minecraft:leaves2:1)
Block(-2,13,5,minecraft:leaves2:1)
Block(-1,13,5,minecraft:leaves2:1)
Block(0,13,5,minecraft:leaves2:1)
Block(1,13,5,minecraft:leaves2:1)
Block(2,13,5,minecraft:leaves2:1)
Block(3,13,5,minecraft:leaves2:1)
Block(5,13,5,minecraft:leaves2:1)
Block(6,13,5,minecraft:leaves2:1)
Block(-4,13,6,minecraft:leaves2:1)
Block(-3,13,6,minecraft:leaves2:1)
Block(-2,13,6,minecraft:leaves2:1)
Block(-1,13,6,minecraft:leaves2:1)
Block(0,13,6,minecraft:leaves2:1)
Block(1,13,6,minecraft:leaves2:1)
Block(2,13,6,minecraft:leaves2:1)
Block(3,13,6,minecraft:leaves2:1)
Block(4,13,6,minecraft:leaves2:1)
Block(-2,13,7,minecraft:leaves2:1)
Block(-1,13,7,minecraft:leaves2:1)
Block(0,13,7,minecraft:leaves2:1)
Block(1,13,7,minecraft:leaves2:1)
Block(2,13,7,minecraft:leaves2:1)
Block(6,13,7,minecraft:leaves2:1)
Block(3,13,8,minecraft:leaves2:1)
Block(-3,14,-9,minecraft:leaves2:1)
Block(-2,14,-9,minecraft:leaves2:1)
Block(0,14,-9,minecraft:leaves2:1)
Block(1,14,-9,minecraft:leaves2:1)
Block(-5,14,-8,minecraft:leaves2:1)
Block(-4,14,-8,minecraft:leaves2:1)
Block(-2,14,-8,minecraft:leaves2:1)
Block(-1,14,-8,minecraft:leaves2:1)
Block(0,14,-8,minecraft:leaves2:1)
Block(1,14,-8,minecraft:leaves2:1)
Block(2,14,-8,minecraft:leaves2:1)
Block(3,14,-8,minecraft:leaves2:1)
Block(4,14,-8,minecraft:leaves2:1)
Block(5,14,-8,minecraft:leaves2:1)
Block(-6,14,-7,minecraft:leaves2:1)
Block(-5,14,-7,minecraft:leaves2:1)
Block(-4,14,-7,minecraft:leaves2:1)
Block(-3,14,-7,minecraft:leaves2:1)
Block(-2,14,-7,minecraft:leaves2:1)
Block(-1,14,-7,minecraft:leaves2:1)
Block(0,14,-7,minecraft:leaves2:1)
Block(1,14,-7,minecraft:leaves2:1)
Block(2,14,-7,minecraft:leaves2:1)
Block(3,14,-7,minecraft:leaves2:1)
Block(4,14,-7,minecraft:leaves2:1)
Block(5,14,-7,minecraft:leaves2:1)
Block(6,14,-7,minecraft:leaves2:1)
Block(-7,14,-6,minecraft:leaves2:1)
Block(-6,14,-6,minecraft:leaves2:1)
Block(-5,14,-6,minecraft:leaves2:1)
Block(-4,14,-6,minecraft:leaves2:1)
Block(-3,14,-6,minecraft:leaves2:1)
Block(-2,14,-6,minecraft:leaves2:1)
Block(-1,14,-6,minecraft:leaves2:1)
Block(0,14,-6,minecraft:leaves2:1)
Block(1,14,-6,minecraft:leaves2:1)
Block(2,14,-6,minecraft:leaves2:1)
Block(3,14,-6,minecraft:leaves2:1)
Block(4,14,-6,minecraft:leaves2:1)
Block(5,14,-6,minecraft:leaves2:1)
Block(6,14,-6,minecraft:leaves2:1)
Block(7,14,-6,minecraft:leaves2:1)
Block(-8,14,-5,minecraft:leaves2:1)
Block(-6,14,-5,minecraft:leaves2:1)
Block(-5,14,-5,minecraft:leaves2:1)
Block(-4,14,-5,minecraft:leaves2:1)
Block(-3,14,-5,minecraft:leaves2:1)
Block(-2,14,-5,minecraft:leaves2:1)
Block(-1,14,-5,minecraft:leaves2:1)
Block(0,14,-5,minecraft:leaves2:1)
Block(1,14,-5,minecraft:leaves2:1)
Block(2,14,-5,minecraft:leaves2:1)
Block(3,14,-5,minecraft:leaves2:1)
Block(4,14,-5,minecraft:leaves2:1)
Block(5,14,-5,minecraft:leaves2:1)
Block(7,14,-5,minecraft:leaves2:1)
Block(8,14,-5,minecraft:leaves2:1)
Block(-8,14,-4,minecraft:leaves2:1)
Block(-7,14,-4,minecraft:leaves2:1)
Block(-6,14,-4,minecraft:leaves2:1)
Block(-5,14,-4,minecraft:leaves2:1)
Block(-4,14,-4,minecraft:leaves2:1)
Block(-3,14,-4,minecraft:leaves2:1)
Block(-2,14,-4,minecraft:leaves2:1)
Block(-1,14,-4,minecraft:leaves2:1)
Block(1,14,-4,minecraft:leaves2:1)
Block(2,14,-4,minecraft:leaves2:1)
Block(3,14,-4,minecraft:leaves2:1)
Block(4,14,-4,minecraft:leaves2:1)
Block(5,14,-4,minecraft:leaves2:1)
Block(6,14,-4,minecraft:leaves2:1)
Block(7,14,-4,minecraft:leaves2:1)
Block(-9,14,-3,minecraft:leaves2:1)
Block(-8,14,-3,minecraft:leaves2:1)
Block(-6,14,-3,minecraft:leaves2:1)
Block(-5,14,-3,minecraft:leaves2:1)
Block(-4,14,-3,minecraft:leaves2:1)
Block(-3,14,-3,minecraft:leaves2:1)
Block(-2,14,-3,minecraft:leaves2:1)
Block(-1,14,-3,minecraft:leaves2:1)
Block(0,14,-3,minecraft:leaves2:1)
Block(1,14,-3,minecraft:leaves2:1)
Block(2,14,-3,minecraft:leaves2:1)
Block(3,14,-3,minecraft:leaves2:1)
Block(4,14,-3,minecraft:leaves2:1)
Block(5,14,-3,minecraft:leaves2:1)
Block(6,14,-3,minecraft:leaves2:1)
Block(7,14,-3,minecraft:leaves2:1)
Block(8,14,-3,minecraft:leaves2:1)
Block(-8,14,-2,minecraft:leaves2:1)
Block(-7,14,-2,minecraft:leaves2:1)
Block(-6,14,-2,minecraft:leaves2:1)
Block(-5,14,-2,minecraft:leaves2:1)
Block(-4,14,-2,minecraft:leaves2:1)
Block(-3,14,-2,minecraft:leaves2:1)
Block(-2,14,-2,minecraft:leaves2:1)
Block(-1,14,-2,minecraft:log2:1)
Block(0,14,-2,minecraft:log2:1)
Block(1,14,-2,minecraft:log2:1)
Block(2,14,-2,minecraft:leaves2:1)
Block(4,14,-2,minecraft:leaves2:1)
Block(5,14,-2,minecraft:leaves2:1)
Block(6,14,-2,minecraft:leaves2:1)
Block(7,14,-2,minecraft:leaves2:1)
Block(8,14,-2,minecraft:leaves2:1)
Block(-9,14,-1,minecraft:leaves2:1)
Block(-8,14,-1,minecraft:leaves2:1)
Block(-7,14,-1,minecraft:leaves2:1)
Block(-6,14,-1,minecraft:leaves2:1)
Block(-5,14,-1,minecraft:leaves2:1)
Block(-4,14,-1,minecraft:leaves2:1)
Block(-3,14,-1,minecraft:leaves2:1)
Block(-2,14,-1,minecraft:leaves2:1)
Block(-1,14,-1,minecraft:log2:1)
Block(0,14,-1,minecraft:log2:1)
Block(1,14,-1,minecraft:log2:1)
Block(2,14,-1,minecraft:log2:1)
Block(3,14,-1,minecraft:leaves2:1)
Block(4,14,-1,minecraft:leaves2:1)
Block(5,14,-1,minecraft:leaves2:1)
Block(6,14,-1,minecraft:leaves2:1)
Block(7,14,-1,minecraft:leaves2:1)
Block(8,14,-1,minecraft:leaves2:1)
Block(9,14,-1,minecraft:leaves2:1)
Block(-8,14,0,minecraft:leaves2:1)
Block(-7,14,0,minecraft:leaves2:1)
Block(-6,14,0,minecraft:leaves2:1)
Block(-5,14,0,minecraft:leaves2:1)
Block(-4,14,0,minecraft:leaves2:1)
Block(-3,14,0,minecraft:leaves2:1)
Block(-2,14,0,minecraft:log2:1)
Block(-1,14,0,minecraft:log2:1)
Block(0,14,0,minecraft:leaves2:1)
Block(1,14,0,minecraft:log2:1)
Block(2,14,0,minecraft:log2:1)
Block(3,14,0,minecraft:leaves2:1)
Block(4,14,0,minecraft:leaves2:1)
Block(5,14,0,minecraft:leaves2:1)
Block(6,14,0,minecraft:leaves2:1)
Block(7,14,0,minecraft:leaves2:1)
Block(8,14,0,minecraft:leaves2:1)
Block(-8,14,1,minecraft:leaves2:1)
Block(-7,14,1,minecraft:leaves2:1)
Block(-6,14,1,minecraft:leaves2:1)
Block(-5,14,1,minecraft:leaves2:1)
Block(-4,14,1,minecraft:leaves2:1)
Block(-3,14,1,minecraft:leaves2:1)
Block(-2,14,1,minecraft:log2:1)
Block(-1,14,1,minecraft:log2:1)
Block(0,14,1,minecraft:log2:1)
Block(1,14,1,minecraft:log2:1)
Block(2,14,1,minecraft:log2:1)
Block(3,14,1,minecraft:leaves2:1)
Block(4,14,1,minecraft:leaves2:1)
Block(5,14,1,minecraft:leaves2:1)
Block(6,14,1,minecraft:leaves2:1)
Block(7,14,1,minecraft:leaves2:1)
Block(8,14,1,minecraft:leaves2:1)
Block(9,14,1,minecraft:leaves2:1)
Block(-9,14,2,minecraft:leaves2:1)
Block(-8,14,2,minecraft:leaves2:1)
Block(-7,14,2,minecraft:leaves2:1)
Block(-6,14,2,minecraft:leaves2:1)
Block(-5,14,2,minecraft:leaves2:1)
Block(-4,14,2,minecraft:leaves2:1)
Block(-3,14,2,minecraft:leaves2:1)
Block(-2,14,2,minecraft:leaves2:1)
Block(-1,14,2,minecraft:log2:1)
Block(0,14,2,minecraft:log2:1)
Block(1,14,2,minecraft:log2:1)
Block(2,14,2,minecraft:leaves2:1)
Block(3,14,2,minecraft:leaves2:1)
Block(4,14,2,minecraft:leaves2:1)
Block(5,14,2,minecraft:leaves2:1)
Block(6,14,2,minecraft:leaves2:1)
Block(7,14,2,minecraft:leaves2:1)
Block(8,14,2,minecraft:leaves2:1)
Block(-9,14,3,minecraft:leaves2:1)
Block(-8,14,3,minecraft:leaves2:1)
Block(-6,14,3,minecraft:leaves2:1)
Block(-5,14,3,minecraft:leaves2:1)
Block(-4,14,3,minecraft:leaves2:1)
Block(-3,14,3,minecraft:leaves2:1)
Block(-2,14,3,minecraft:leaves2:1)
Block(-1,14,3,minecraft:leaves2:1)
Block(0,14,3,minecraft:leaves2:1)
Block(1,14,3,minecraft:leaves2:1)
Block(2,14,3,minecraft:leaves2:1)
Block(3,14,3,minecraft:leaves2:1)
Block(4,14,3,minecraft:leaves2:1)
Block(5,14,3,minecraft:leaves2:1)
Block(6,14,3,minecraft:leaves2:1)
Block(7,14,3,minecraft:leaves2:1)
Block(8,14,3,minecraft:leaves2:1)
Block(9,14,3,minecraft:leaves2:1)
Block(-7,14,4,minecraft:leaves2:1)
Block(-6,14,4,minecraft:leaves2:1)
Block(-5,14,4,minecraft:leaves2:1)
Block(-4,14,4,minecraft:leaves2:1)
Block(-3,14,4,minecraft:leaves2:1)
Block(-2,14,4,minecraft:leaves2:1)
Block(-1,14,4,minecraft:leaves2:1)
Block(0,14,4,minecraft:leaves2:1)
Block(1,14,4,minecraft:leaves2:1)
Block(2,14,4,minecraft:leaves2:1)
Block(3,14,4,minecraft:leaves2:1)
Block(4,14,4,minecraft:leaves2:1)
Block(5,14,4,minecraft:leaves2:1)
Block(6,14,4,minecraft:leaves2:1)
Block(7,14,4,minecraft:leaves2:1)
Block(8,14,4,minecraft:leaves2:1)
Block(-8,14,5,minecraft:leaves2:1)
Block(-7,14,5,minecraft:leaves2:1)
Block(-6,14,5,minecraft:leaves2:1)
Block(-5,14,5,minecraft:leaves2:1)
Block(-4,14,5,minecraft:leaves2:1)
Block(-3,14,5,minecraft:leaves2:1)
Block(-2,14,5,minecraft:leaves2:1)
Block(-1,14,5,minecraft:leaves2:1)
Block(0,14,5,minecraft:leaves2:1)
Block(2,14,5,minecraft:leaves2:1)
Block(3,14,5,minecraft:leaves2:1)
Block(4,14,5,minecraft:leaves2:1)
Block(5,14,5,minecraft:leaves2:1)
Block(6,14,5,minecraft:leaves2:1)
Block(-7,14,6,minecraft:leaves2:1)
Block(-6,14,6,minecraft:leaves2:1)
Block(-5,14,6,minecraft:leaves2:1)
Block(-4,14,6,minecraft:leaves2:1)
Block(-3,14,6,minecraft:leaves2:1)
Block(-2,14,6,minecraft:leaves2:1)
Block(-1,14,6,minecraft:leaves2:1)
Block(0,14,6,minecraft:leaves2:1)
Block(1,14,6,minecraft:leaves2:1)
Block(2,14,6,minecraft:leaves2:1)
Block(3,14,6,minecraft:leaves2:1)
Block(4,14,6,minecraft:leaves2:1)
Block(5,14,6,minecraft:leaves2:1)
Block(6,14,6,minecraft:leaves2:1)
Block(-6,14,7,minecraft:leaves2:1)
Block(-5,14,7,minecraft:leaves2:1)
Block(-4,14,7,minecraft:leaves2:1)
Block(-3,14,7,minecraft:leaves2:1)
Block(-2,14,7,minecraft:leaves2:1)
Block(-1,14,7,minecraft:leaves2:1)
Block(0,14,7,minecraft:leaves2:1)
Block(1,14,7,minecraft:leaves2:1)
Block(2,14,7,minecraft:leaves2:1)
Block(3,14,7,minecraft:leaves2:1)
Block(4,14,7,minecraft:leaves2:1)
Block(5,14,7,minecraft:leaves2:1)
Block(6,14,7,minecraft:leaves2:1)
Block(-2,14,8,minecraft:leaves2:1)
Block(-1,14,8,minecraft:leaves2:1)
Block(0,14,8,minecraft:leaves2:1)
Block(1,14,8,minecraft:leaves2:1)
Block(3,14,8,minecraft:leaves2:1)
Block(5,14,8,minecraft:leaves2:1)
Block(-3,14,9,minecraft:leaves2:1)
Block(-2,14,9,minecraft:leaves2:1)
Block(0,14,9,minecraft:leaves2:1)
Block(2,14,9,minecraft:leaves2:1)
Block(3,14,9,minecraft:leaves2:1)
Block(1,15,-8,minecraft:leaves2:1)
Block(2,15,-7,minecraft:leaves2:1)
Block(-2,15,-6,minecraft:leaves2:1)
Block(1,15,-6,minecraft:leaves2:1)
Block(5,15,-6,minecraft:leaves2:1)
Block(-5,15,-5,minecraft:leaves2:1)
Block(-2,15,-5,minecraft:leaves2:1)
Block(3,15,-5,minecraft:leaves2:1)
Block(-7,15,-4,minecraft:leaves2:1)
Block(-5,15,-4,minecraft:leaves2:1)
Block(-2,15,-4,minecraft:leaves2:1)
Block(-1,15,-4,minecraft:leaves2:1)
Block(2,15,-4,minecraft:leaves2:1)
Block(4,15,-4,minecraft:leaves2:1)
Block(6,15,-4,minecraft:leaves2:1)
Block(-7,15,-3,minecraft:leaves2:1)
Block(-4,15,-3,minecraft:leaves2:1)
Block(-3,15,-3,minecraft:leaves2:1)
Block(-1,15,-3,minecraft:leaves2:1)
Block(2,15,-3,minecraft:leaves2:1)
Block(4,15,-3,minecraft:leaves2:1)
Block(-7,15,-2,minecraft:leaves2:1)
Block(-6,15,-2,minecraft:leaves2:1)
Block(-4,15,-2,minecraft:leaves2:1)
Block(-1,15,-2,minecraft:log2:1)
Block(0,15,-2,minecraft:log2:1)
Block(1,15,-2,minecraft:log2:1)
Block(4,15,-2,minecraft:leaves2:1)
Block(-4,15,-1,minecraft:leaves2:1)
Block(-1,15,-1,minecraft:log2:1)
Block(0,15,-1,minecraft:log2:1)
Block(1,15,-1,minecraft:log2:1)
Block(2,15,-1,minecraft:log2:1)
Block(3,15,-1,minecraft:leaves2:1)
Block(4,15,-1,minecraft:leaves2:1)
Block(6,15,-1,minecraft:leaves2:1)
Block(7,15,-1,minecraft:leaves2:1)
Block(8,15,-1,minecraft:leaves2:1)
Block(-8,15,0,minecraft:leaves2:1)
Block(-6,15,0,minecraft:leaves2:1)
Block(-4,15,0,minecraft:leaves2:1)
Block(-2,15,0,minecraft:log2:1)
Block(-1,15,0,minecraft:log2:1)
Block(0,15,0,minecraft:log2:1)
Block(5,15,0,minecraft:leaves2:1)
Block(6,15,0,minecraft:leaves2:1)
Block(-8,15,1,minecraft:leaves2:1)
Block(-6,15,1,minecraft:leaves2:1)
Block(-2,15,1,minecraft:log2:1)
Block(-1,15,1,minecraft:log2:1)
Block(0,15,1,minecraft:log2:1)
Block(1,15,1,minecraft:log2:1)
Block(2,15,1,minecraft:log2:1)
Block(4,15,1,minecraft:leaves2:1)
Block(5,15,1,minecraft:leaves2:1)
Block(6,15,1,minecraft:leaves2:1)
Block(7,15,1,minecraft:leaves2:1)
Block(-8,15,2,minecraft:leaves2:1)
Block(-6,15,2,minecraft:leaves2:1)
Block(-4,15,2,minecraft:leaves2:1)
Block(-1,15,2,minecraft:log2:1)
Block(0,15,2,minecraft:log2:1)
Block(1,15,2,minecraft:log2:1)
Block(3,15,2,minecraft:leaves2:1)
Block(6,15,2,minecraft:leaves2:1)
Block(7,15,2,minecraft:leaves2:1)
Block(-6,15,3,minecraft:leaves2:1)
Block(-3,15,3,minecraft:leaves2:1)
Block(-2,15,3,minecraft:leaves2:1)
Block(1,15,3,minecraft:leaves2:1)
Block(5,15,3,minecraft:leaves2:1)
Block(-6,15,4,minecraft:leaves2:1)
Block(-2,15,4,minecraft:leaves2:1)
Block(-1,15,4,minecraft:leaves2:1)
Block(1,15,4,minecraft:leaves2:1)
Block(4,15,4,minecraft:leaves2:1)
Block(5,15,4,minecraft:leaves2:1)
Block(-6,15,5,minecraft:leaves2:1)
Block(-3,15,5,minecraft:leaves2:1)
Block(-2,15,5,minecraft:leaves2:1)
Block(3,15,5,minecraft:leaves2:1)
Block(4,15,5,minecraft:leaves2:1)
Block(-5,15,6,minecraft:leaves2:1)
Block(0,15,6,minecraft:leaves2:1)
Block(2,15,6,minecraft:leaves2:1)
Block(5,15,6,minecraft:leaves2:1)
Block(-1,15,7,minecraft:leaves2:1)
Block(1,15,7,minecraft:leaves2:1)
Block(-2,15,8,minecraft:leaves2:1)
Block(0,15,8,minecraft:leaves2:1)
Block(1,15,8,minecraft:leaves2:1)
Block(2,15,8,minecraft:leaves2:1)
Block(-2,16,-8,minecraft:leaves2:1)
Block(-1,16,-8,minecraft:leaves2:1)
Block(0,16,-8,minecraft:leaves2:1)
Block(1,16,-8,minecraft:leaves2:1)
Block(2,16,-8,minecraft:leaves2:1)
Block(-4,16,-7,minecraft:leaves2:1)
Block(-3,16,-7,minecraft:leaves2:1)
Block(-2,16,-7,minecraft:leaves2:1)
Block(-1,16,-7,minecraft:leaves2:1)
Block(0,16,-7,minecraft:leaves2:1)
Block(1,16,-7,minecraft:leaves2:1)
Block(2,16,-7,minecraft:leaves2:1)
Block(3,16,-7,minecraft:leaves2:1)
Block(4,16,-7,minecraft:leaves2:1)
Block(-6,16,-6,minecraft:leaves2:1)
Block(-5,16,-6,minecraft:leaves2:1)
Block(-4,16,-6,minecraft:leaves2:1)
Block(-3,16,-6,minecraft:leaves2:1)
Block(-2,16,-6,minecraft:leaves2:1)
Block(-1,16,-6,minecraft:leaves2:1)
Block(0,16,-6,minecraft:leaves2:1)
Block(1,16,-6,minecraft:leaves2:1)
Block(2,16,-6,minecraft:leaves2:1)
Block(3,16,-6,minecraft:leaves2:1)
Block(4,16,-6,minecraft:leaves2:1)
Block(6,16,-6,minecraft:leaves2:1)
Block(-6,16,-5,minecraft:leaves2:1)
Block(-4,16,-5,minecraft:leaves2:1)
Block(-3,16,-5,minecraft:leaves2:1)
Block(-1,16,-5,minecraft:leaves2:1)
Block(0,16,-5,minecraft:leaves2:1)
Block(1,16,-5,minecraft:leaves2:1)
Block(2,16,-5,minecraft:leaves2:1)
Block(3,16,-5,minecraft:leaves2:1)
Block(4,16,-5,minecraft:leaves2:1)
Block(5,16,-5,minecraft:leaves2:1)
Block(6,16,-5,minecraft:leaves2:1)
Block(-6,16,-4,minecraft:leaves2:1)
Block(-4,16,-4,minecraft:leaves2:1)
Block(-3,16,-4,minecraft:leaves2:1)
Block(-2,16,-4,minecraft:leaves2:1)
Block(0,16,-4,minecraft:leaves2:1)
Block(1,16,-4,minecraft:leaves2:1)
Block(2,16,-4,minecraft:leaves2:1)
Block(3,16,-4,minecraft:leaves2:1)
Block(4,16,-4,minecraft:leaves2:1)
Block(5,16,-4,minecraft:leaves2:1)
Block(6,16,-4,minecraft:leaves2:1)
Block(7,16,-4,minecraft:leaves2:1)
Block(-7,16,-3,minecraft:leaves2:1)
Block(-6,16,-3,minecraft:leaves2:1)
Block(-5,16,-3,minecraft:leaves2:1)
Block(-3,16,-3,minecraft:leaves2:1)
Block(-2,16,-3,minecraft:leaves2:1)
Block(-1,16,-3,minecraft:leaves2:1)
Block(0,16,-3,minecraft:leaves2:1)
Block(1,16,-3,minecraft:leaves2:1)
Block(3,16,-3,minecraft:leaves2:1)
Block(5,16,-3,minecraft:leaves2:1)
Block(6,16,-3,minecraft:leaves2:1)
Block(7,16,-3,minecraft:leaves2:1)
Block(-8,16,-2,minecraft:leaves2:1)
Block(-7,16,-2,minecraft:leaves2:1)
Block(-6,16,-2,minecraft:leaves2:1)
Block(-5,16,-2,minecraft:leaves2:1)
Block(-3,16,-2,minecraft:leaves2:1)
Block(-2,16,-2,minecraft:leaves2:1)
Block(-1,16,-2,minecraft:log2:1)
Block(0,16,-2,minecraft:log2:1)
Block(1,16,-2,minecraft:log2:1)
Block(2,16,-2,minecraft:leaves2:1)
Block(3,16,-2,minecraft:leaves2:1)
Block(4,16,-2,minecraft:leaves2:1)
Block(5,16,-2,minecraft:leaves2:1)
Block(6,16,-2,minecraft:leaves2:1)
Block(7,16,-2,minecraft:leaves2:1)
Block(8,16,-2,minecraft:leaves2:1)
Block(-8,16,-1,minecraft:leaves2:1)
Block(-7,16,-1,minecraft:leaves2:1)
Block(-6,16,-1,minecraft:leaves2:1)
Block(-5,16,-1,minecraft:leaves2:1)
Block(-4,16,-1,minecraft:leaves2:1)
Block(-3,16,-1,minecraft:leaves2:1)
Block(-2,16,-1,minecraft:leaves2:1)
Block(-1,16,-1,minecraft:log2:1)
Block(0,16,-1,minecraft:log2:1)
Block(1,16,-1,minecraft:log2:1)
Block(2,16,-1,minecraft:log2:1)
Block(3,16,-1,minecraft:leaves2:1)
Block(4,16,-1,minecraft:leaves2:1)
Block(5,16,-1,minecraft:leaves2:1)
Block(6,16,-1,minecraft:leaves2:1)
Block(7,16,-1,minecraft:leaves2:1)
Block(8,16,-1,minecraft:leaves2:1)
Block(-7,16,0,minecraft:leaves2:1)
Block(-6,16,0,minecraft:leaves2:1)
Block(-5,16,0,minecraft:leaves2:1)
Block(-4,16,0,minecraft:leaves2:1)
Block(-3,16,0,minecraft:leaves2:1)
Block(-2,16,0,minecraft:log2:1)
Block(-1,16,0,minecraft:log2:1)
Block(0,16,0,minecraft:leaves2:1)
Block(1,16,0,minecraft:log2:1)
Block(2,16,0,minecraft:log2:1)
Block(3,16,0,minecraft:leaves2:1)
Block(4,16,0,minecraft:leaves2:1)
Block(5,16,0,minecraft:leaves2:1)
Block(6,16,0,minecraft:leaves2:1)
Block(7,16,0,minecraft:leaves2:1)
Block(8,16,0,minecraft:leaves2:1)
Block(-7,16,1,minecraft:leaves2:1)
Block(-6,16,1,minecraft:leaves2:1)
Block(-5,16,1,minecraft:leaves2:1)
Block(-4,16,1,minecraft:leaves2:1)
Block(-3,16,1,minecraft:leaves2:1)
Block(-2,16,1,minecraft:log2:1)
Block(-1,16,1,minecraft:log2:1)
Block(0,16,1,minecraft:log2:1)
Block(1,16,1,minecraft:log2:1)
Block(2,16,1,minecraft:log2:1)
Block(3,16,1,minecraft:leaves2:1)
Block(5,16,1,minecraft:leaves2:1)
Block(6,16,1,minecraft:leaves2:1)
Block(8,16,1,minecraft:leaves2:1)
Block(-8,16,2,minecraft:leaves2:1)
Block(-7,16,2,minecraft:leaves2:1)
Block(-6,16,2,minecraft:leaves2:1)
Block(-5,16,2,minecraft:leaves2:1)
Block(-3,16,2,minecraft:leaves2:1)
Block(-2,16,2,minecraft:leaves2:1)
Block(-1,16,2,minecraft:log2:1)
Block(0,16,2,minecraft:log2:1)
Block(1,16,2,minecraft:log2:1)
Block(2,16,2,minecraft:leaves2:1)
Block(4,16,2,minecraft:leaves2:1)
Block(5,16,2,minecraft:leaves2:1)
Block(6,16,2,minecraft:leaves2:1)
Block(7,16,2,minecraft:leaves2:1)
Block(8,16,2,minecraft:leaves2:1)
Block(-7,16,3,minecraft:leaves2:1)
Block(-6,16,3,minecraft:leaves2:1)
Block(-5,16,3,minecraft:leaves2:1)
Block(-4,16,3,minecraft:leaves2:1)
Block(-3,16,3,minecraft:leaves2:1)
Block(-2,16,3,minecraft:leaves2:1)
Block(-1,16,3,minecraft:leaves2:1)
Block(0,16,3,minecraft:leaves2:1)
Block(1,16,3,minecraft:leaves2:1)
Block(2,16,3,minecraft:leaves2:1)
Block(3,16,3,minecraft:leaves2:1)
Block(4,16,3,minecraft:leaves2:1)
Block(5,16,3,minecraft:leaves2:1)
Block(6,16,3,minecraft:leaves2:1)
Block(7,16,3,minecraft:leaves2:1)
Block(-7,16,4,minecraft:leaves2:1)
Block(-6,16,4,minecraft:leaves2:1)
Block(-5,16,4,minecraft:leaves2:1)
Block(-4,16,4,minecraft:leaves2:1)
Block(-3,16,4,minecraft:leaves2:1)
Block(-2,16,4,minecraft:leaves2:1)
Block(-1,16,4,minecraft:leaves2:1)
Block(0,16,4,minecraft:leaves2:1)
Block(1,16,4,minecraft:leaves2:1)
Block(2,16,4,minecraft:leaves2:1)
Block(3,16,4,minecraft:leaves2:1)
Block(4,16,4,minecraft:leaves2:1)
Block(5,16,4,minecraft:leaves2:1)
Block(6,16,4,minecraft:leaves2:1)
Block(7,16,4,minecraft:leaves2:1)
Block(-6,16,5,minecraft:leaves2:1)
Block(-5,16,5,minecraft:leaves2:1)
Block(-4,16,5,minecraft:leaves2:1)
Block(-1,16,5,minecraft:leaves2:1)
Block(0,16,5,minecraft:leaves2:1)
Block(1,16,5,minecraft:leaves2:1)
Block(2,16,5,minecraft:leaves2:1)
Block(4,16,5,minecraft:leaves2:1)
Block(5,16,5,minecraft:leaves2:1)
Block(6,16,5,minecraft:leaves2:1)
Block(-6,16,6,minecraft:leaves2:1)
Block(-4,16,6,minecraft:leaves2:1)
Block(-3,16,6,minecraft:leaves2:1)
Block(-2,16,6,minecraft:leaves2:1)
Block(-1,16,6,minecraft:leaves2:1)
Block(1,16,6,minecraft:leaves2:1)
Block(3,16,6,minecraft:leaves2:1)
Block(4,16,6,minecraft:leaves2:1)
Block(5,16,6,minecraft:leaves2:1)
Block(6,16,6,minecraft:leaves2:1)
Block(-4,16,7,minecraft:leaves2:1)
Block(-3,16,7,minecraft:leaves2:1)
Block(-2,16,7,minecraft:leaves2:1)
Block(0,16,7,minecraft:leaves2:1)
Block(1,16,7,minecraft:leaves2:1)
Block(2,16,7,minecraft:leaves2:1)
Block(3,16,7,minecraft:leaves2:1)
Block(4,16,7,minecraft:leaves2:1)
Block(-2,16,8,minecraft:leaves2:1)
Block(-1,16,8,minecraft:leaves2:1)
Block(0,16,8,minecraft:leaves2:1)
Block(2,16,8,minecraft:leaves2:1)
Block(2,17,-8,minecraft:leaves2:1)
Block(0,17,-7,minecraft:leaves2:1)
Block(-6,17,-6,minecraft:leaves2:1)
Block(-4,17,-6,minecraft:leaves2:1)
Block(-2,17,-6,minecraft:leaves2:1)
Block(0,17,-6,minecraft:leaves2:1)
Block(1,17,-6,minecraft:leaves2:1)
Block(-6,17,-5,minecraft:leaves2:1)
Block(-4,17,-5,minecraft:leaves2:1)
Block(4,17,-5,minecraft:leaves2:1)
Block(-7,17,-4,minecraft:leaves2:1)
Block(-6,17,-4,minecraft:leaves2:1)
Block(-1,17,-4,minecraft:leaves2:1)
Block(3,17,-4,minecraft:leaves2:1)
Block(5,17,-4,minecraft:leaves2:1)
Block(-2,17,-3,minecraft:leaves2:1)
Block(-1,17,-3,minecraft:leaves2:1)
Block(0,17,-3,minecraft:leaves2:1)
Block(5,17,-3,minecraft:leaves2:1)
Block(6,17,-3,minecraft:leaves2:1)
Block(7,17,-3,minecraft:leaves2:1)
Block(-8,17,-2,minecraft:leaves2:1)
Block(-2,17,-2,minecraft:leaves2:1)
Block(-1,17,-2,minecraft:log2:1)
Block(0,17,-2,minecraft:log2:1)
Block(1,17,-2,minecraft:log2:1)
Block(2,17,-2,minecraft:leaves2:1)
Block(7,17,-2,minecraft:leaves2:1)
Block(-8,17,-1,minecraft:leaves2:1)
Block(-2,17,-1,minecraft:log2:1)
Block(-1,17,-1,minecraft:log2:1)
Block(0,17,-1,minecraft:log2:1)
Block(1,17,-1,minecraft:log2:1)
Block(2,17,-1,minecraft:log2:1)
Block(5,17,-1,minecraft:leaves2:1)
Block(-7,17,0,minecraft:leaves2:1)
Block(-2,17,0,minecraft:log2:1)
Block(-1,17,0,minecraft:log2:1)
Block(0,17,0,minecraft:log2:1)
Block(1,17,0,minecraft:log2:1)
Block(2,17,0,minecraft:log2:1)
Block(-5,17,1,minecraft:leaves2:1)
Block(-2,17,1,minecraft:log2:1)
Block(-1,17,1,minecraft:log2:1)
Block(0,17,1,minecraft:log2:1)
Block(1,17,1,minecraft:log2:1)
Block(2,17,1,minecraft:log2:1)
Block(4,17,1,minecraft:leaves2:1)
Block(-7,17,2,minecraft:leaves2:1)
Block(-5,17,2,minecraft:leaves2:1)
Block(-2,17,2,minecraft:leaves2:1)
Block(-1,17,2,minecraft:log2:1)
Block(0,17,2,minecraft:log2:1)
Block(1,17,2,minecraft:log2:1)
Block(3,17,2,minecraft:leaves2:1)
Block(8,17,2,minecraft:leaves2:1)
Block(-5,17,3,minecraft:leaves2:1)
Block(0,17,3,minecraft:leaves2:1)
Block(2,17,3,minecraft:leaves2:1)
Block(6,17,3,minecraft:leaves2:1)
Block(-7,17,4,minecraft:leaves2:1)
Block(-4,17,4,minecraft:leaves2:1)
Block(-3,17,4,minecraft:leaves2:1)
Block(-2,17,4,minecraft:leaves2:1)
Block(6,17,4,minecraft:leaves2:1)
Block(7,17,4,minecraft:leaves2:1)
Block(-5,17,5,minecraft:leaves2:1)
Block(0,17,5,minecraft:leaves2:1)
Block(2,17,5,minecraft:leaves2:1)
Block(3,17,5,minecraft:leaves2:1)
Block(-6,17,6,minecraft:leaves2:1)
Block(-2,17,6,minecraft:leaves2:1)
Block(-1,17,6,minecraft:leaves2:1)
Block(0,17,6,minecraft:leaves2:1)
Block(0,17,7,minecraft:leaves2:1)
Block(2,17,7,minecraft:leaves2:1)
Block(3,17,7,minecraft:leaves2:1)
Block(4,17,7,minecraft:leaves2:1)
Block(-1,17,8,minecraft:leaves2:1)
Block(-2,18,-8,minecraft:leaves2:1)
Block(-1,18,-8,minecraft:leaves2:1)
Block(0,18,-8,minecraft:leaves2:1)
Block(1,18,-8,minecraft:leaves2:1)
Block(2,18,-8,minecraft:leaves2:1)
Block(-4,18,-7,minecraft:leaves2:1)
Block(-3,18,-7,minecraft:leaves2:1)
Block(-2,18,-7,minecraft:leaves2:1)
Block(-1,18,-7,minecraft:leaves2:1)
Block(1,18,-7,minecraft:leaves2:1)
Block(2,18,-7,minecraft:leaves2:1)
Block(3,18,-7,minecraft:leaves2:1)
Block(4,18,-7,minecraft:leaves2:1)
Block(-6,18,-6,minecraft:leaves2:1)
Block(-5,18,-6,minecraft:leaves2:1)
Block(-3,18,-6,minecraft:leaves2:1)
Block(-2,18,-6,minecraft:leaves2:1)
Block(-1,18,-6,minecraft:leaves2:1)
Block(0,18,-6,minecraft:leaves2:1)
Block(2,18,-6,minecraft:leaves2:1)
Block(3,18,-6,minecraft:leaves2:1)
Block(4,18,-6,minecraft:leaves2:1)
Block(5,18,-6,minecraft:leaves2:1)
Block(6,18,-6,minecraft:leaves2:1)
Block(-6,18,-5,minecraft:leaves2:1)
Block(-5,18,-5,minecraft:leaves2:1)
Block(-3,18,-5,minecraft:leaves2:1)
Block(-2,18,-5,minecraft:leaves2:1)
Block(-1,18,-5,minecraft:leaves2:1)
Block(0,18,-5,minecraft:leaves2:1)
Block(1,18,-5,minecraft:leaves2:1)
Block(2,18,-5,minecraft:leaves2:1)
Block(3,18,-5,minecraft:leaves2:1)
Block(4,18,-5,minecraft:leaves2:1)
Block(5,18,-5,minecraft:leaves2:1)
Block(6,18,-5,minecraft:leaves2:1)
Block(-7,18,-4,minecraft:leaves2:1)
Block(-6,18,-4,minecraft:leaves2:1)
Block(-5,18,-4,minecraft:leaves2:1)
Block(-4,18,-4,minecraft:leaves2:1)
Block(-3,18,-4,minecraft:leaves2:1)
Block(-2,18,-4,minecraft:leaves2:1)
Block(0,18,-4,minecraft:leaves2:1)
Block(1,18,-4,minecraft:leaves2:1)
Block(2,18,-4,minecraft:leaves2:1)
Block(3,18,-4,minecraft:leaves2:1)
Block(4,18,-4,minecraft:leaves2:1)
Block(6,18,-4,minecraft:leaves2:1)
Block(7,18,-4,minecraft:leaves2:1)
Block(-7,18,-3,minecraft:leaves2:1)
Block(-6,18,-3,minecraft:leaves2:1)
Block(-5,18,-3,minecraft:leaves2:1)
Block(-4,18,-3,minecraft:leaves2:1)
Block(-3,18,-3,minecraft:leaves2:1)
Block(-2,18,-3,minecraft:leaves2:1)
Block(1,18,-3,minecraft:leaves2:1)
Block(2,18,-3,minecraft:leaves2:1)
Block(3,18,-3,minecraft:leaves2:1)
Block(4,18,-3,minecraft:leaves2:1)
Block(5,18,-3,minecraft:leaves2:1)
Block(7,18,-3,minecraft:leaves2:1)
Block(-7,18,-2,minecraft:leaves2:1)
Block(-5,18,-2,minecraft:leaves2:1)
Block(-4,18,-2,minecraft:leaves2:1)
Block(-3,18,-2,minecraft:leaves2:1)
Block(-2,18,-2,minecraft:leaves2:1)
Block(-1,18,-2,minecraft:log2:1)
Block(0,18,-2,minecraft:log2:1)
Block(1,18,-2,minecraft:log2:1)
Block(2,18,-2,minecraft:leaves2:1)
Block(3,18,-2,minecraft:leaves2:1)
Block(4,18,-2,minecraft:leaves2:1)
Block(5,18,-2,minecraft:leaves2:1)
Block(6,18,-2,minecraft:leaves2:1)
Block(7,18,-2,minecraft:leaves2:1)
Block(8,18,-2,minecraft:leaves2:1)
Block(-8,18,-1,minecraft:leaves2:1)
Block(-7,18,-1,minecraft:leaves2:1)
Block(-6,18,-1,minecraft:leaves2:1)
Block(-5,18,-1,minecraft:leaves2:1)
Block(-4,18,-1,minecraft:leaves2:1)
Block(-3,18,-1,minecraft:leaves2:1)
Block(-2,18,-1,minecraft:log2:1)
Block(-1,18,-1,minecraft:log2:1)
Block(0,18,-1,minecraft:log2:1)
Block(1,18,-1,minecraft:log2:1)
Block(2,18,-1,minecraft:log2:1)
Block(3,18,-1,minecraft:leaves2:1)
Block(4,18,-1,minecraft:leaves2:1)
Block(5,18,-1,minecraft:leaves2:1)
Block(6,18,-1,minecraft:leaves2:1)
Block(7,18,-1,minecraft:leaves2:1)
Block(8,18,-1,minecraft:leaves2:1)
Block(-8,18,0,minecraft:leaves2:1)
Block(-6,18,0,minecraft:leaves2:1)
Block(-5,18,0,minecraft:leaves2:1)
Block(-4,18,0,minecraft:leaves2:1)
Block(-3,18,0,minecraft:leaves2:1)
Block(-2,18,0,minecraft:log2:1)
Block(-1,18,0,minecraft:log2:1)
Block(0,18,0,minecraft:leaves2:1)
Block(1,18,0,minecraft:log2:1)
Block(2,18,0,minecraft:log2:1)
Block(3,18,0,minecraft:leaves2:1)
Block(4,18,0,minecraft:leaves2:1)
Block(5,18,0,minecraft:leaves2:1)
Block(6,18,0,minecraft:leaves2:1)
Block(7,18,0,minecraft:leaves2:1)
Block(8,18,0,minecraft:leaves2:1)
Block(-8,18,1,minecraft:leaves2:1)
Block(-7,18,1,minecraft:leaves2:1)
Block(-6,18,1,minecraft:leaves2:1)
Block(-4,18,1,minecraft:leaves2:1)
Block(-3,18,1,minecraft:leaves2:1)
Block(-2,18,1,minecraft:log2:1)
Block(-1,18,1,minecraft:log2:1)
Block(0,18,1,minecraft:log2:1)
Block(1,18,1,minecraft:log2:1)
Block(2,18,1,minecraft:log2:1)
Block(3,18,1,minecraft:leaves2:1)
Block(4,18,1,minecraft:leaves2:1)
Block(5,18,1,minecraft:leaves2:1)
Block(6,18,1,minecraft:leaves2:1)
Block(7,18,1,minecraft:leaves2:1)
Block(8,18,1,minecraft:leaves2:1)
Block(-8,18,2,minecraft:leaves2:1)
Block(-6,18,2,minecraft:leaves2:1)
Block(-5,18,2,minecraft:leaves2:1)
Block(-4,18,2,minecraft:leaves2:1)
Block(-3,18,2,minecraft:leaves2:1)
Block(-1,18,2,minecraft:log2:1)
Block(0,18,2,minecraft:log2:1)
Block(1,18,2,minecraft:log2:1)
Block(2,18,2,minecraft:leaves2:1)
Block(3,18,2,minecraft:leaves2:1)
Block(4,18,2,minecraft:leaves2:1)
Block(5,18,2,minecraft:leaves2:1)
Block(6,18,2,minecraft:leaves2:1)
Block(7,18,2,minecraft:leaves2:1)
Block(-7,18,3,minecraft:leaves2:1)
Block(-6,18,3,minecraft:leaves2:1)
Block(-5,18,3,minecraft:leaves2:1)
Block(-4,18,3,minecraft:leaves2:1)
Block(-3,18,3,minecraft:leaves2:1)
Block(-2,18,3,minecraft:leaves2:1)
Block(-1,18,3,minecraft:leaves2:1)
Block(0,18,3,minecraft:leaves2:1)
Block(1,18,3,minecraft:leaves2:1)
Block(2,18,3,minecraft:leaves2:1)
Block(3,18,3,minecraft:leaves2:1)
Block(4,18,3,minecraft:leaves2:1)
Block(5,18,3,minecraft:leaves2:1)
Block(6,18,3,minecraft:leaves2:1)
Block(7,18,3,minecraft:leaves2:1)
Block(-6,18,4,minecraft:leaves2:1)
Block(-5,18,4,minecraft:leaves2:1)
Block(-3,18,4,minecraft:leaves2:1)
Block(-2,18,4,minecraft:leaves2:1)
Block(-1,18,4,minecraft:leaves2:1)
Block(0,18,4,minecraft:leaves2:1)
Block(2,18,4,minecraft:leaves2:1)
Block(3,18,4,minecraft:leaves2:1)
Block(4,18,4,minecraft:leaves2:1)
Block(5,18,4,minecraft:leaves2:1)
Block(6,18,4,minecraft:leaves2:1)
Block(7,18,4,minecraft:leaves2:1)
Block(-6,18,5,minecraft:leaves2:1)
Block(-5,18,5,minecraft:leaves2:1)
Block(-4,18,5,minecraft:leaves2:1)
Block(-3,18,5,minecraft:leaves2:1)
Block(-2,18,5,minecraft:leaves2:1)
Block(-1,18,5,minecraft:leaves2:1)
Block(0,18,5,minecraft:leaves2:1)
Block(1,18,5,minecraft:leaves2:1)
Block(5,18,5,minecraft:leaves2:1)
Block(6,18,5,minecraft:leaves2:1)
Block(-6,18,6,minecraft:leaves2:1)
Block(-5,18,6,minecraft:leaves2:1)
Block(-4,18,6,minecraft:leaves2:1)
Block(-3,18,6,minecraft:leaves2:1)
Block(-2,18,6,minecraft:leaves2:1)
Block(-1,18,6,minecraft:leaves2:1)
Block(0,18,6,minecraft:leaves2:1)
Block(1,18,6,minecraft:leaves2:1)
Block(2,18,6,minecraft:leaves2:1)
Block(3,18,6,minecraft:leaves2:1)
Block(4,18,6,minecraft:leaves2:1)
Block(5,18,6,minecraft:leaves2:1)
Block(6,18,6,minecraft:leaves2:1)
Block(-4,18,7,minecraft:leaves2:1)
Block(-3,18,7,minecraft:leaves2:1)
Block(-2,18,7,minecraft:leaves2:1)
Block(-1,18,7,minecraft:leaves2:1)
Block(1,18,7,minecraft:leaves2:1)
Block(2,18,7,minecraft:leaves2:1)
Block(4,18,7,minecraft:leaves2:1)
Block(-2,18,8,minecraft:leaves2:1)
Block(-1,18,8,minecraft:leaves2:1)
Block(0,18,8,minecraft:leaves2:1)
Block(1,18,8,minecraft:leaves2:1)
Block(2,18,8,minecraft:leaves2:1)
Block(-2,19,-7,minecraft:leaves2:1)
Block(-1,19,-7,minecraft:leaves2:1)
Block(0,19,-7,minecraft:leaves2:1)
Block(1,19,-7,minecraft:leaves2:1)
Block(2,19,-7,minecraft:leaves2:1)
Block(-4,19,-6,minecraft:leaves2:1)
Block(-3,19,-6,minecraft:leaves2:1)
Block(-2,19,-6,minecraft:leaves2:1)
Block(-1,19,-6,minecraft:leaves2:1)
Block(0,19,-6,minecraft:leaves2:1)
Block(1,19,-6,minecraft:leaves2:1)
Block(2,19,-6,minecraft:leaves2:1)
Block(3,19,-6,minecraft:leaves2:1)
Block(4,19,-6,minecraft:leaves2:1)
Block(-5,19,-5,minecraft:leaves2:1)
Block(-4,19,-5,minecraft:leaves2:1)
Block(-3,19,-5,minecraft:leaves2:1)
Block(-2,19,-5,minecraft:leaves2:1)
Block(-1,19,-5,minecraft:leaves2:1)
Block(0,19,-5,minecraft:leaves2:1)
Block(1,19,-5,minecraft:leaves2:1)
Block(2,19,-5,minecraft:leaves2:1)
Block(3,19,-5,minecraft:leaves2:1)
Block(4,19,-5,minecraft:leaves2:1)
Block(5,19,-5,minecraft:leaves2:1)
Block(-6,19,-4,minecraft:leaves2:1)
Block(-5,19,-4,minecraft:leaves2:1)
Block(-4,19,-4,minecraft:leaves2:1)
Block(-3,19,-4,minecraft:leaves2:1)
Block(-2,19,-4,minecraft:leaves2:1)
Block(-1,19,-4,minecraft:leaves2:1)
Block(0,19,-4,minecraft:leaves2:1)
Block(1,19,-4,minecraft:leaves2:1)
Block(2,19,-4,minecraft:leaves2:1)
Block(3,19,-4,minecraft:leaves2:1)
Block(4,19,-4,minecraft:leaves2:1)
Block(5,19,-4,minecraft:leaves2:1)
Block(6,19,-4,minecraft:leaves2:1)
Block(-6,19,-3,minecraft:leaves2:1)
Block(-5,19,-3,minecraft:leaves2:1)
Block(-4,19,-3,minecraft:leaves2:1)
Block(-3,19,-3,minecraft:leaves2:1)
Block(-2,19,-3,minecraft:leaves2:1)
Block(-1,19,-3,minecraft:leaves2:1)
Block(0,19,-3,minecraft:leaves2:1)
Block(1,19,-3,minecraft:leaves2:1)
Block(2,19,-3,minecraft:leaves2:1)
Block(3,19,-3,minecraft:leaves2:1)
Block(4,19,-3,minecraft:leaves2:1)
Block(5,19,-3,minecraft:leaves2:1)
Block(6,19,-3,minecraft:leaves2:1)
Block(-7,19,-2,minecraft:leaves2:1)
Block(-6,19,-2,minecraft:leaves2:1)
Block(-5,19,-2,minecraft:leaves2:1)
Block(-4,19,-2,minecraft:leaves2:1)
Block(-3,19,-2,minecraft:leaves2:1)
Block(-2,19,-2,minecraft:leaves2:1)
Block(-1,19,-2,minecraft:log2:1)
Block(0,19,-2,minecraft:log2:1)
Block(1,19,-2,minecraft:log2:1)
Block(2,19,-2,minecraft:leaves2:1)
Block(3,19,-2,minecraft:leaves2:1)
Block(4,19,-2,minecraft:leaves2:1)
Block(5,19,-2,minecraft:leaves2:1)
Block(6,19,-2,minecraft:leaves2:1)
Block(7,19,-2,minecraft:leaves2:1)
Block(-7,19,-1,minecraft:leaves2:1)
Block(-6,19,-1,minecraft:leaves2:1)
Block(-5,19,-1,minecraft:leaves2:1)
Block(-4,19,-1,minecraft:leaves2:1)
Block(-3,19,-1,minecraft:leaves2:1)
Block(-2,19,-1,minecraft:log2:1)
Block(-1,19,-1,minecraft:log2:1)
Block(0,19,-1,minecraft:log2:1)
Block(1,19,-1,minecraft:log2:1)
Block(2,19,-1,minecraft:log2:1)
Block(3,19,-1,minecraft:leaves2:1)
Block(4,19,-1,minecraft:leaves2:1)
Block(5,19,-1,minecraft:leaves2:1)
Block(6,19,-1,minecraft:leaves2:1)
Block(7,19,-1,minecraft:leaves2:1)
Block(-7,19,0,minecraft:leaves2:1)
Block(-6,19,0,minecraft:leaves2:1)
Block(-5,19,0,minecraft:leaves2:1)
Block(-4,19,0,minecraft:leaves2:1)
Block(-3,19,0,minecraft:leaves2:1)
Block(-2,19,0,minecraft:log2:1)
Block(-1,19,0,minecraft:log2:1)
Block(0,19,0,minecraft:leaves2:1)
Block(1,19,0,minecraft:log2:1)
Block(2,19,0,minecraft:log2:1)
Block(3,19,0,minecraft:leaves2:1)
Block(4,19,0,minecraft:leaves2:1)
Block(5,19,0,minecraft:leaves2:1)
Block(6,19,0,minecraft:leaves2:1)
Block(7,19,0,minecraft:leaves2:1)
Block(-7,19,1,minecraft:leaves2:1)
Block(-6,19,1,minecraft:leaves2:1)
Block(-5,19,1,minecraft:leaves2:1)
Block(-4,19,1,minecraft:leaves2:1)
Block(-3,19,1,minecraft:leaves2:1)
Block(-2,19,1,minecraft:log2:1)
Block(-1,19,1,minecraft:log2:1)
Block(0,19,1,minecraft:log2:1)
Block(1,19,1,minecraft:log2:1)
Block(2,19,1,minecraft:log2:1)
Block(3,19,1,minecraft:leaves2:1)
Block(4,19,1,minecraft:leaves2:1)
Block(5,19,1,minecraft:leaves2:1)
Block(6,19,1,minecraft:leaves2:1)
Block(7,19,1,minecraft:leaves2:1)
Block(-7,19,2,minecraft:leaves2:1)
Block(-6,19,2,minecraft:leaves2:1)
Block(-5,19,2,minecraft:leaves2:1)
Block(-4,19,2,minecraft:leaves2:1)
Block(-3,19,2,minecraft:leaves2:1)
Block(-2,19,2,minecraft:leaves2:1)
Block(-1,19,2,minecraft:log2:1)
Block(0,19,2,minecraft:log2:1)
Block(1,19,2,minecraft:log2:1)
Block(2,19,2,minecraft:leaves2:1)
Block(3,19,2,minecraft:leaves2:1)
Block(4,19,2,minecraft:leaves2:1)
Block(5,19,2,minecraft:leaves2:1)
Block(6,19,2,minecraft:leaves2:1)
Block(7,19,2,minecraft:leaves2:1)
Block(-6,19,3,minecraft:leaves2:1)
Block(-5,19,3,minecraft:leaves2:1)
Block(-4,19,3,minecraft:leaves2:1)
Block(-3,19,3,minecraft:leaves2:1)
Block(-2,19,3,minecraft:leaves2:1)
Block(-1,19,3,minecraft:leaves2:1)
Block(0,19,3,minecraft:leaves2:1)
Block(1,19,3,minecraft:leaves2:1)
Block(2,19,3,minecraft:leaves2:1)
Block(3,19,3,minecraft:leaves2:1)
Block(4,19,3,minecraft:leaves2:1)
Block(5,19,3,minecraft:leaves2:1)
Block(6,19,3,minecraft:leaves2:1)
Block(-6,19,4,minecraft:leaves2:1)
Block(-5,19,4,minecraft:leaves2:1)
Block(-4,19,4,minecraft:leaves2:1)
Block(-3,19,4,minecraft:leaves2:1)
Block(-1,19,4,minecraft:leaves2:1)
Block(0,19,4,minecraft:leaves2:1)
Block(1,19,4,minecraft:leaves2:1)
Block(2,19,4,minecraft:leaves2:1)
Block(3,19,4,minecraft:leaves2:1)
Block(4,19,4,minecraft:leaves2:1)
Block(5,19,4,minecraft:leaves2:1)
Block(6,19,4,minecraft:leaves2:1)
Block(-5,19,5,minecraft:leaves2:1)
Block(-4,19,5,minecraft:leaves2:1)
Block(-3,19,5,minecraft:leaves2:1)
Block(-2,19,5,minecraft:leaves2:1)
Block(-1,19,5,minecraft:leaves2:1)
Block(0,19,5,minecraft:leaves2:1)
Block(1,19,5,minecraft:leaves2:1)
Block(2,19,5,minecraft:leaves2:1)
Block(3,19,5,minecraft:leaves2:1)
Block(4,19,5,minecraft:leaves2:1)
Block(5,19,5,minecraft:leaves2:1)
Block(-4,19,6,minecraft:leaves2:1)
Block(-3,19,6,minecraft:leaves2:1)
Block(-2,19,6,minecraft:leaves2:1)
Block(-1,19,6,minecraft:leaves2:1)
Block(0,19,6,minecraft:leaves2:1)
Block(1,19,6,minecraft:leaves2:1)
Block(2,19,6,minecraft:leaves2:1)
Block(3,19,6,minecraft:leaves2:1)
Block(4,19,6,minecraft:leaves2:1)
Block(-2,19,7,minecraft:leaves2:1)
Block(-1,19,7,minecraft:leaves2:1)
Block(0,19,7,minecraft:leaves2:1)
Block(1,19,7,minecraft:leaves2:1)
Block(2,19,7,minecraft:leaves2:1)
Block(-2,20,-6,minecraft:leaves2:1)
Block(1,20,-6,minecraft:leaves2:1)
Block(-1,20,-5,minecraft:leaves2:1)
Block(1,20,-5,minecraft:leaves2:1)
Block(-5,20,-4,minecraft:leaves2:1)
Block(-2,20,-4,minecraft:leaves2:1)
Block(-1,20,-4,minecraft:leaves2:1)
Block(3,20,-4,minecraft:leaves2:1)
Block(4,20,-4,minecraft:leaves2:1)
Block(-3,20,-3,minecraft:leaves2:1)
Block(1,20,-3,minecraft:leaves2:1)
Block(2,20,-3,minecraft:leaves2:1)
Block(3,20,-3,minecraft:leaves2:1)
Block(-5,20,-2,minecraft:leaves2:1)
Block(-3,20,-2,minecraft:leaves2:1)
Block(-1,20,-2,minecraft:log2:1)
Block(0,20,-2,minecraft:log2:1)
Block(1,20,-2,minecraft:log2:1)
Block(5,20,-2,minecraft:leaves2:1)
Block(-6,20,-1,minecraft:leaves2:1)
Block(-5,20,-1,minecraft:leaves2:1)
Block(-3,20,-1,minecraft:leaves2:1)
Block(-2,20,-1,minecraft:log2:1)
Block(-1,20,-1,minecraft:log2:1)
Block(0,20,-1,minecraft:log2:1)
Block(1,20,-1,minecraft:log2:1)
Block(2,20,-1,minecraft:log2:1)
Block(3,20,-1,minecraft:leaves2:1)
Block(4,20,-1,minecraft:leaves2:1)
Block(-6,20,0,minecraft:leaves2:1)
Block(-2,20,0,minecraft:log2:1)
Block(-1,20,0,minecraft:log2:1)
Block(0,20,0,minecraft:log2:1)
Block(1,20,0,minecraft:log2:1)
Block(2,20,0,minecraft:log2:1)
Block(-6,20,1,minecraft:leaves2:1)
Block(-2,20,1,minecraft:log2:1)
Block(-1,20,1,minecraft:log2:1)
Block(0,20,1,minecraft:log2:1)
Block(1,20,1,minecraft:log2:1)
Block(2,20,1,minecraft:log2:1)
Block(4,20,1,minecraft:leaves2:1)
Block(5,20,1,minecraft:leaves2:1)
Block(-5,20,2,minecraft:leaves2:1)
Block(-2,20,2,minecraft:leaves2:1)
Block(-1,20,2,minecraft:log2:1)
Block(0,20,2,minecraft:log2:1)
Block(1,20,2,minecraft:log2:1)
Block(4,20,2,minecraft:leaves2:1)
Block(6,20,2,minecraft:leaves2:1)
Block(-5,20,3,minecraft:leaves2:1)
Block(-1,20,3,minecraft:leaves2:1)
Block(1,20,3,minecraft:leaves2:1)
Block(2,20,3,minecraft:leaves2:1)
Block(3,20,3,minecraft:leaves2:1)
Block(4,20,3,minecraft:leaves2:1)
Block(5,20,3,minecraft:leaves2:1)
Block(-3,20,4,minecraft:leaves2:1)
Block(-2,20,4,minecraft:leaves2:1)
Block(-1,20,4,minecraft:leaves2:1)
Block(0,20,4,minecraft:leaves2:1)
Block(1,20,4,minecraft:leaves2:1)
Block(2,20,4,minecraft:leaves2:1)
Block(5,20,4,minecraft:leaves2:1)
Block(-4,20,5,minecraft:leaves2:1)
Block(-3,20,5,minecraft:leaves2:1)
Block(2,20,5,minecraft:leaves2:1)
Block(4,20,5,minecraft:leaves2:1)
Block(1,20,6,minecraft:leaves2:1)
Block(-1,21,-6,minecraft:leaves2:1)
Block(0,21,-6,minecraft:leaves2:1)
Block(1,21,-6,minecraft:leaves2:1)
Block(2,21,-6,minecraft:leaves2:1)
Block(-4,21,-5,minecraft:leaves2:1)
Block(-3,21,-5,minecraft:leaves2:1)
Block(-2,21,-5,minecraft:leaves2:1)
Block(-1,21,-5,minecraft:leaves2:1)
Block(0,21,-5,minecraft:leaves2:1)
Block(1,21,-5,minecraft:leaves2:1)
Block(2,21,-5,minecraft:leaves2:1)
Block(3,21,-5,minecraft:leaves2:1)
Block(4,21,-5,minecraft:leaves2:1)
Block(-5,21,-4,minecraft:leaves2:1)
Block(-4,21,-4,minecraft:leaves2:1)
Block(-3,21,-4,minecraft:leaves2:1)
Block(-2,21,-4,minecraft:leaves2:1)
Block(0,21,-4,minecraft:leaves2:1)
Block(1,21,-4,minecraft:leaves2:1)
Block(2,21,-4,minecraft:leaves2:1)
Block(3,21,-4,minecraft:leaves2:1)
Block(5,21,-4,minecraft:leaves2:1)
Block(-5,21,-3,minecraft:leaves2:1)
Block(-4,21,-3,minecraft:leaves2:1)
Block(-3,21,-3,minecraft:leaves2:1)
Block(-2,21,-3,minecraft:leaves2:1)
Block(-1,21,-3,minecraft:leaves2:1)
Block(0,21,-3,minecraft:leaves2:1)
Block(1,21,-3,minecraft:leaves2:1)
Block(3,21,-3,minecraft:leaves2:1)
Block(4,21,-3,minecraft:leaves2:1)
Block(5,21,-3,minecraft:leaves2:1)
Block(-6,21,-2,minecraft:leaves2:1)
Block(-5,21,-2,minecraft:leaves2:1)
Block(-4,21,-2,minecraft:leaves2:1)
Block(-3,21,-2,minecraft:leaves2:1)
Block(-2,21,-2,minecraft:leaves2:1)
Block(-1,21,-2,minecraft:log2:1)
Block(0,21,-2,minecraft:log2:1)
Block(1,21,-2,minecraft:log2:1)
Block(2,21,-2,minecraft:leaves2:1)
Block(3,21,-2,minecraft:leaves2:1)
Block(4,21,-2,minecraft:leaves2:1)
Block(5,21,-2,minecraft:leaves2:1)
Block(6,21,-2,minecraft:leaves2:1)
Block(-4,21,-1,minecraft:leaves2:1)
Block(-3,21,-1,minecraft:leaves2:1)
Block(-2,21,-1,minecraft:log2:1)
Block(-1,21,-1,minecraft:log2:1)
Block(0,21,-1,minecraft:log2:1)
Block(1,21,-1,minecraft:log2:1)
Block(2,21,-1,minecraft:log2:1)
Block(3,21,-1,minecraft:leaves2:1)
Block(4,21,-1,minecraft:leaves2:1)
Block(5,21,-1,minecraft:leaves2:1)
Block(6,21,-1,minecraft:leaves2:1)
Block(-6,21,0,minecraft:leaves2:1)
Block(-5,21,0,minecraft:leaves2:1)
Block(-4,21,0,minecraft:leaves2:1)
Block(-3,21,0,minecraft:leaves2:1)
Block(-2,21,0,minecraft:log2:1)
Block(-1,21,0,minecraft:log2:1)
Block(0,21,0,minecraft:leaves2:1)
Block(1,21,0,minecraft:log2:1)
Block(2,21,0,minecraft:log2:1)
Block(3,21,0,minecraft:leaves2:1)
Block(4,21,0,minecraft:leaves2:1)
Block(5,21,0,minecraft:leaves2:1)
Block(6,21,0,minecraft:leaves2:1)
Block(-6,21,1,minecraft:leaves2:1)
Block(-5,21,1,minecraft:leaves2:1)
Block(-4,21,1,minecraft:leaves2:1)
Block(-3,21,1,minecraft:leaves2:1)
Block(-2,21,1,minecraft:log2:1)
Block(-1,21,1,minecraft:log2:1)
Block(0,21,1,minecraft:log2:1)
Block(1,21,1,minecraft:log2:1)
Block(2,21,1,minecraft:log2:1)
Block(3,21,1,minecraft:leaves2:1)
Block(4,21,1,minecraft:leaves2:1)
Block(5,21,1,minecraft:leaves2:1)
Block(6,21,1,minecraft:leaves2:1)
Block(-6,21,2,minecraft:leaves2:1)
Block(-4,21,2,minecraft:leaves2:1)
Block(-3,21,2,minecraft:leaves2:1)
Block(-2,21,2,minecraft:leaves2:1)
Block(-1,21,2,minecraft:log2:1)
Block(0,21,2,minecraft:log2:1)
Block(1,21,2,minecraft:log2:1)
Block(2,21,2,minecraft:leaves2:1)
Block(3,21,2,minecraft:leaves2:1)
Block(4,21,2,minecraft:leaves2:1)
Block(5,21,2,minecraft:leaves2:1)
Block(6,21,2,minecraft:leaves2:1)
Block(-5,21,3,minecraft:leaves2:1)
Block(-4,21,3,minecraft:leaves2:1)
Block(-3,21,3,minecraft:leaves2:1)
Block(-2,21,3,minecraft:leaves2:1)
Block(0,21,3,minecraft:leaves2:1)
Block(2,21,3,minecraft:leaves2:1)
Block(3,21,3,minecraft:leaves2:1)
Block(4,21,3,minecraft:leaves2:1)
Block(5,21,3,minecraft:leaves2:1)
Block(-5,21,4,minecraft:leaves2:1)
Block(-4,21,4,minecraft:leaves2:1)
Block(-3,21,4,minecraft:leaves2:1)
Block(-2,21,4,minecraft:leaves2:1)
Block(0,21,4,minecraft:leaves2:1)
Block(2,21,4,minecraft:leaves2:1)
Block(3,21,4,minecraft:leaves2:1)
Block(4,21,4,minecraft:leaves2:1)
Block(5,21,4,minecraft:leaves2:1)
Block(-4,21,5,minecraft:leaves2:1)
Block(-3,21,5,minecraft:leaves2:1)
Block(-2,21,5,minecraft:leaves2:1)
Block(-1,21,5,minecraft:leaves2:1)
Block(0,21,5,minecraft:leaves2:1)
Block(1,21,5,minecraft:leaves2:1)
Block(3,21,5,minecraft:leaves2:1)
Block(4,21,5,minecraft:leaves2:1)
Block(-2,21,6,minecraft:leaves2:1)
Block(-1,21,6,minecraft:leaves2:1)
Block(0,21,6,minecraft:leaves2:1)
Block(1,21,6,minecraft:leaves2:1)
Block(2,21,6,minecraft:leaves2:1)
Block(-2,22,-6,minecraft:leaves2:1)
Block(1,22,-6,minecraft:leaves2:1)
Block(2,22,-6,minecraft:leaves2:1)
Block(-3,22,-5,minecraft:leaves2:1)
Block(3,22,-5,minecraft:leaves2:1)
Block(4,22,-5,minecraft:leaves2:1)
Block(0,22,-4,minecraft:leaves2:1)
Block(1,22,-4,minecraft:leaves2:1)
Block(2,22,-4,minecraft:leaves2:1)
Block(5,22,-4,minecraft:leaves2:1)
Block(-5,22,-3,minecraft:leaves2:1)
Block(-3,22,-3,minecraft:leaves2:1)
Block(0,22,-3,minecraft:leaves2:1)
Block(-1,22,-2,minecraft:log2:1)
Block(0,22,-2,minecraft:log2:1)
Block(2,22,-2,minecraft:leaves2:1)
Block(4,22,-2,minecraft:leaves2:1)
Block(-3,22,-1,minecraft:leaves2:1)
Block(-2,22,-1,minecraft:log2:1)
Block(-1,22,-1,minecraft:log2:1)
Block(0,22,-1,minecraft:log2:1)
Block(1,22,-1,minecraft:log2:1)
Block(-5,22,0,minecraft:leaves2:1)
Block(-2,22,0,minecraft:log2:1)
Block(-1,22,0,minecraft:log2:1)
Block(0,22,0,minecraft:log2:1)
Block(1,22,0,minecraft:log2:1)
Block(2,22,0,minecraft:log2:1)
Block(5,22,0,minecraft:leaves2:1)
Block(-2,22,1,minecraft:log2:1)
Block(-1,22,1,minecraft:log2:1)
Block(0,22,1,minecraft:log2:1)
Block(1,22,1,minecraft:log2:1)
Block(2,22,1,minecraft:log2:1)
Block(4,22,1,minecraft:leaves2:1)
Block(6,22,1,minecraft:leaves2:1)
Block(-3,22,2,minecraft:leaves2:1)
Block(-1,22,2,minecraft:log2:1)
Block(0,22,2,minecraft:log2:1)
Block(1,22,2,minecraft:log2:1)
Block(-4,22,3,minecraft:leaves2:1)
Block(1,22,3,minecraft:leaves2:1)
Block(0,22,4,minecraft:leaves2:1)
Block(3,22,4,minecraft:leaves2:1)
Block(4,22,4,minecraft:leaves2:1)
Block(-4,22,5,minecraft:leaves2:1)
Block(1,22,5,minecraft:leaves2:1)
Block(3,22,5,minecraft:leaves2:1)
Block(0,22,6,minecraft:leaves2:1)
Block(-2,23,-6,minecraft:leaves2:1)
Block(-1,23,-6,minecraft:leaves2:1)
Block(0,23,-6,minecraft:leaves2:1)
Block(1,23,-6,minecraft:leaves2:1)
Block(2,23,-6,minecraft:leaves2:1)
Block(-4,23,-5,minecraft:leaves2:1)
Block(-3,23,-5,minecraft:leaves2:1)
Block(-2,23,-5,minecraft:leaves2:1)
Block(-1,23,-5,minecraft:leaves2:1)
Block(0,23,-5,minecraft:leaves2:1)
Block(1,23,-5,minecraft:leaves2:1)
Block(2,23,-5,minecraft:leaves2:1)
Block(4,23,-5,minecraft:leaves2:1)
Block(-5,23,-4,minecraft:leaves2:1)
Block(-4,23,-4,minecraft:leaves2:1)
Block(-3,23,-4,minecraft:leaves2:1)
Block(-2,23,-4,minecraft:leaves2:1)
Block(-1,23,-4,minecraft:leaves2:1)
Block(0,23,-4,minecraft:leaves2:1)
Block(1,23,-4,minecraft:leaves2:1)
Block(2,23,-4,minecraft:leaves2:1)
Block(3,23,-4,minecraft:leaves2:1)
Block(4,23,-4,minecraft:leaves2:1)
Block(-4,23,-3,minecraft:leaves2:1)
Block(-2,23,-3,minecraft:leaves2:1)
Block(-1,23,-3,minecraft:leaves2:1)
Block(0,23,-3,minecraft:leaves2:1)
Block(1,23,-3,minecraft:leaves2:1)
Block(2,23,-3,minecraft:leaves2:1)
Block(4,23,-3,minecraft:leaves2:1)
Block(5,23,-3,minecraft:leaves2:1)
Block(-6,23,-2,minecraft:leaves2:1)
Block(-5,23,-2,minecraft:leaves2:1)
Block(-4,23,-2,minecraft:leaves2:1)
Block(-3,23,-2,minecraft:leaves2:1)
Block(-2,23,-2,minecraft:leaves2:1)
Block(-1,23,-2,minecraft:log2:1)
Block(0,23,-2,minecraft:log2:1)
Block(1,23,-2,minecraft:log2:1)
Block(2,23,-2,minecraft:leaves2:1)
Block(3,23,-2,minecraft:leaves2:1)
Block(4,23,-2,minecraft:leaves2:1)
Block(5,23,-2,minecraft:leaves2:1)
Block(6,23,-2,minecraft:leaves2:1)
Block(-6,23,-1,minecraft:leaves2:1)
Block(-5,23,-1,minecraft:leaves2:1)
Block(-4,23,-1,minecraft:leaves2:1)
Block(-2,23,-1,minecraft:log2:1)
Block(-1,23,-1,minecraft:log2:1)
Block(0,23,-1,minecraft:log2:1)
Block(1,23,-1,minecraft:log2:1)
Block(2,23,-1,minecraft:log2:1)
Block(3,23,-1,minecraft:leaves2:1)
Block(4,23,-1,minecraft:leaves2:1)
Block(5,23,-1,minecraft:leaves2:1)
Block(6,23,-1,minecraft:leaves2:1)
Block(-6,23,0,minecraft:leaves2:1)
Block(-4,23,0,minecraft:leaves2:1)
Block(-3,23,0,minecraft:leaves2:1)
Block(-2,23,0,minecraft:log2:1)
Block(-1,23,0,minecraft:log2:1)
Block(0,23,0,minecraft:leaves2:1)
Block(1,23,0,minecraft:log2:1)
Block(2,23,0,minecraft:log2:1)
Block(3,23,0,minecraft:leaves2:1)
Block(4,23,0,minecraft:leaves2:1)
Block(5,23,0,minecraft:leaves2:1)
Block(6,23,0,minecraft:leaves2:1)
Block(-6,23,1,minecraft:leaves2:1)
Block(-5,23,1,minecraft:leaves2:1)
Block(-4,23,1,minecraft:leaves2:1)
Block(-3,23,1,minecraft:leaves2:1)
Block(-2,23,1,minecraft:log2:1)
Block(-1,23,1,minecraft:log2:1)
Block(0,23,1,minecraft:log2:1)
Block(1,23,1,minecraft:log2:1)
Block(2,23,1,minecraft:log2:1)
Block(3,23,1,minecraft:leaves2:1)
Block(5,23,1,minecraft:leaves2:1)
Block(-6,23,2,minecraft:leaves2:1)
Block(-5,23,2,minecraft:leaves2:1)
Block(-4,23,2,minecraft:leaves2:1)
Block(-3,23,2,minecraft:leaves2:1)
Block(-2,23,2,minecraft:leaves2:1)
Block(-1,23,2,minecraft:log2:1)
Block(0,23,2,minecraft:log2:1)
Block(1,23,2,minecraft:log2:1)
Block(2,23,2,minecraft:leaves2:1)
Block(3,23,2,minecraft:leaves2:1)
Block(4,23,2,minecraft:leaves2:1)
Block(5,23,2,minecraft:leaves2:1)
Block(6,23,2,minecraft:leaves2:1)
Block(-5,23,3,minecraft:leaves2:1)
Block(-4,23,3,minecraft:leaves2:1)
Block(-3,23,3,minecraft:leaves2:1)
Block(-2,23,3,minecraft:leaves2:1)
Block(-1,23,3,minecraft:leaves2:1)
Block(0,23,3,minecraft:leaves2:1)
Block(1,23,3,minecraft:leaves2:1)
Block(2,23,3,minecraft:leaves2:1)
Block(3,23,3,minecraft:leaves2:1)
Block(4,23,3,minecraft:leaves2:1)
Block(5,23,3,minecraft:leaves2:1)
Block(-5,23,4,minecraft:leaves2:1)
Block(-4,23,4,minecraft:leaves2:1)
Block(-3,23,4,minecraft:leaves2:1)
Block(-2,23,4,minecraft:leaves2:1)
Block(-1,23,4,minecraft:leaves2:1)
Block(0,23,4,minecraft:leaves2:1)
Block(1,23,4,minecraft:leaves2:1)
Block(2,23,4,minecraft:leaves2:1)
Block(3,23,4,minecraft:leaves2:1)
Block(4,23,4,minecraft:leaves2:1)
Block(5,23,4,minecraft:leaves2:1)
Block(-4,23,5,minecraft:leaves2:1)
Block(-3,23,5,minecraft:leaves2:1)
Block(-2,23,5,minecraft:leaves2:1)
Block(-1,23,5,minecraft:leaves2:1)
Block(0,23,5,minecraft:leaves2:1)
Block(1,23,5,minecraft:leaves2:1)
Block(2,23,5,minecraft:leaves2:1)
Block(3,23,5,minecraft:leaves2:1)
Block(4,23,5,minecraft:leaves2:1)
Block(-2,23,6,minecraft:leaves2:1)
Block(-1,23,6,minecraft:leaves2:1)
Block(1,23,6,minecraft:leaves2:1)
Block(2,23,6,minecraft:leaves2:1)
Block(-1,24,-6,minecraft:leaves2:1)
Block(2,24,-6,minecraft:leaves2:1)
Block(-2,24,-5,minecraft:leaves2:1)
Block(-1,24,-5,minecraft:leaves2:1)
Block(0,24,-5,minecraft:leaves2:1)
Block(1,24,-5,minecraft:leaves2:1)
Block(2,24,-5,minecraft:leaves2:1)
Block(4,24,-5,minecraft:leaves2:1)
Block(-4,24,-4,minecraft:leaves2:1)
Block(-3,24,-4,minecraft:leaves2:1)
Block(-2,24,-4,minecraft:leaves2:1)
Block(-1,24,-4,minecraft:leaves2:1)
Block(0,24,-4,minecraft:leaves2:1)
Block(1,24,-4,minecraft:leaves2:1)
Block(2,24,-4,minecraft:leaves2:1)
Block(3,24,-4,minecraft:leaves2:1)
Block(-5,24,-3,minecraft:leaves2:1)
Block(-4,24,-3,minecraft:leaves2:1)
Block(-3,24,-3,minecraft:leaves2:1)
Block(-2,24,-3,minecraft:leaves2:1)
Block(-1,24,-3,minecraft:leaves2:1)
Block(0,24,-3,minecraft:leaves2:1)
Block(1,24,-3,minecraft:leaves2:1)
Block(2,24,-3,minecraft:leaves2:1)
Block(3,24,-3,minecraft:leaves2:1)
Block(4,24,-3,minecraft:leaves2:1)
Block(-5,24,-2,minecraft:leaves2:1)
Block(-4,24,-2,minecraft:leaves2:1)
Block(-3,24,-2,minecraft:leaves2:1)
Block(-2,24,-2,minecraft:leaves2:1)
Block(-1,24,-2,minecraft:log2:1)
Block(0,24,-2,minecraft:log2:1)
Block(1,24,-2,minecraft:leaves2:1)
Block(2,24,-2,minecraft:leaves2:1)
Block(3,24,-2,minecraft:leaves2:1)
Block(4,24,-2,minecraft:leaves2:1)
Block(5,24,-2,minecraft:leaves2:1)
Block(-5,24,-1,minecraft:leaves2:1)
Block(-4,24,-1,minecraft:leaves2:1)
Block(-3,24,-1,minecraft:leaves2:1)
Block(-2,24,-1,minecraft:log2:1)
Block(-1,24,-1,minecraft:log2:1)
Block(0,24,-1,minecraft:log2:1)
Block(1,24,-1,minecraft:log2:1)
Block(2,24,-1,minecraft:log2:1)
Block(3,24,-1,minecraft:leaves2:1)
Block(4,24,-1,minecraft:leaves2:1)
Block(5,24,-1,minecraft:leaves2:1)
Block(6,24,-1,minecraft:leaves2:1)
Block(-5,24,0,minecraft:leaves2:1)
Block(-4,24,0,minecraft:leaves2:1)
Block(-3,24,0,minecraft:leaves2:1)
Block(-2,24,0,minecraft:log2:1)
Block(-1,24,0,minecraft:log2:1)
Block(0,24,0,minecraft:leaves2:1)
Block(1,24,0,minecraft:log2:1)
Block(2,24,0,minecraft:log2:1)
Block(3,24,0,minecraft:leaves2:1)
Block(4,24,0,minecraft:leaves2:1)
Block(5,24,0,minecraft:leaves2:1)
Block(-6,24,1,minecraft:leaves2:1)
Block(-5,24,1,minecraft:leaves2:1)
Block(-4,24,1,minecraft:leaves2:1)
Block(-3,24,1,minecraft:leaves2:1)
Block(-2,24,1,minecraft:log2:1)
Block(-1,24,1,minecraft:log2:1)
Block(0,24,1,minecraft:log2:1)
Block(1,24,1,minecraft:log2:1)
Block(2,24,1,minecraft:log2:1)
Block(3,24,1,minecraft:leaves2:1)
Block(5,24,1,minecraft:leaves2:1)
Block(-5,24,2,minecraft:leaves2:1)
Block(-4,24,2,minecraft:leaves2:1)
Block(-3,24,2,minecraft:leaves2:1)
Block(-2,24,2,minecraft:leaves2:1)
Block(-1,24,2,minecraft:leaves2:1)
Block(1,24,2,minecraft:log2:1)
Block(2,24,2,minecraft:leaves2:1)
Block(3,24,2,minecraft:leaves2:1)
Block(4,24,2,minecraft:leaves2:1)
Block(5,24,2,minecraft:leaves2:1)
Block(6,24,2,minecraft:leaves2:1)
Block(-3,24,3,minecraft:leaves2:1)
Block(-2,24,3,minecraft:leaves2:1)
Block(-1,24,3,minecraft:leaves2:1)
Block(0,24,3,minecraft:leaves2:1)
Block(1,24,3,minecraft:leaves2:1)
Block(2,24,3,minecraft:leaves2:1)
Block(3,24,3,minecraft:leaves2:1)
Block(4,24,3,minecraft:leaves2:1)
Block(5,24,3,minecraft:leaves2:1)
Block(-3,24,4,minecraft:leaves2:1)
Block(-2,24,4,minecraft:leaves2:1)
Block(-1,24,4,minecraft:leaves2:1)
Block(0,24,4,minecraft:leaves2:1)
Block(1,24,4,minecraft:leaves2:1)
Block(2,24,4,minecraft:leaves2:1)
Block(3,24,4,minecraft:leaves2:1)
Block(4,24,4,minecraft:leaves2:1)
Block(5,24,4,minecraft:leaves2:1)
Block(-2,24,5,minecraft:leaves2:1)
Block(-1,24,5,minecraft:leaves2:1)
Block(0,24,5,minecraft:leaves2:1)
Block(1,24,5,minecraft:leaves2:1)
Block(2,24,5,minecraft:leaves2:1)
Block(2,24,6,minecraft:leaves2:1)
Block(-1,25,-6,minecraft:leaves2:1)
Block(-1,25,-5,minecraft:leaves2:1)
Block(1,25,-5,minecraft:leaves2:1)
Block(2,25,-5,minecraft:leaves2:1)
Block(-3,25,-4,minecraft:leaves2:1)
Block(-1,25,-4,minecraft:leaves2:1)
Block(0,25,-4,minecraft:leaves2:1)
Block(3,25,-4,minecraft:leaves2:1)
Block(-4,25,-3,minecraft:leaves2:1)
Block(-3,25,-3,minecraft:leaves2:1)
Block(-2,25,-3,minecraft:leaves2:1)
Block(2,25,-3,minecraft:leaves2:1)
Block(4,25,-3,minecraft:leaves2:1)
Block(-1,25,-2,minecraft:log2:1)
Block(0,25,-2,minecraft:log2:1)
Block(2,25,-2,minecraft:leaves2:1)
Block(4,25,-2,minecraft:leaves2:1)
Block(-4,25,-1,minecraft:leaves2:1)
Block(-2,25,-1,minecraft:log2:1)
Block(-1,25,-1,minecraft:log2:1)
Block(0,25,-1,minecraft:log2:1)
Block(1,25,-1,minecraft:log2:1)
Block(4,25,-1,minecraft:leaves2:1)
Block(-3,25,0,minecraft:leaves2:1)
Block(-2,25,0,minecraft:log2:1)
Block(-1,25,0,minecraft:log2:1)
Block(0,25,0,minecraft:log2:1)
Block(1,25,0,minecraft:log2:1)
Block(5,25,0,minecraft:leaves2:1)
Block(-3,25,1,minecraft:leaves2:1)
Block(0,25,1,minecraft:log2:1)
Block(1,25,1,minecraft:log2:1)
Block(-2,25,2,minecraft:leaves2:1)
Block(4,25,2,minecraft:leaves2:1)
Block(-4,25,3,minecraft:leaves2:1)
Block(-3,25,3,minecraft:leaves2:1)
Block(2,25,3,minecraft:leaves2:1)
Block(4,25,3,minecraft:leaves2:1)
Block(-2,25,4,minecraft:leaves2:1)
Block(-2,25,5,minecraft:leaves2:1)
Block(0,25,5,minecraft:leaves2:1)
Block(2,25,5,minecraft:leaves2:1)
Block(-2,26,-6,minecraft:leaves2:1)
Block(-1,26,-6,minecraft:leaves2:1)
Block(0,26,-6,minecraft:leaves2:1)
Block(1,26,-6,minecraft:leaves2:1)
Block(2,26,-6,minecraft:leaves2:1)
Block(-4,26,-5,minecraft:leaves2:1)
Block(-3,26,-5,minecraft:leaves2:1)
Block(-2,26,-5,minecraft:leaves2:1)
Block(0,26,-5,minecraft:leaves2:1)
Block(1,26,-5,minecraft:leaves2:1)
Block(2,26,-5,minecraft:leaves2:1)
Block(3,26,-5,minecraft:leaves2:1)
Block(-5,26,-4,minecraft:leaves2:1)
Block(-3,26,-4,minecraft:leaves2:1)
Block(-2,26,-4,minecraft:leaves2:1)
Block(-1,26,-4,minecraft:leaves2:1)
Block(1,26,-4,minecraft:leaves2:1)
Block(2,26,-4,minecraft:leaves2:1)
Block(3,26,-4,minecraft:leaves2:1)
Block(4,26,-4,minecraft:leaves2:1)
Block(5,26,-4,minecraft:leaves2:1)
Block(-5,26,-3,minecraft:leaves2:1)
Block(-4,26,-3,minecraft:leaves2:1)
Block(-3,26,-3,minecraft:leaves2:1)
Block(-2,26,-3,minecraft:leaves2:1)
Block(-1,26,-3,minecraft:leaves2:1)
Block(0,26,-3,minecraft:leaves2:1)
Block(1,26,-3,minecraft:leaves2:1)
Block(2,26,-3,minecraft:leaves2:1)
Block(3,26,-3,minecraft:leaves2:1)
Block(4,26,-3,minecraft:leaves2:1)
Block(5,26,-3,minecraft:leaves2:1)
Block(-6,26,-2,minecraft:leaves2:1)
Block(-5,26,-2,minecraft:leaves2:1)
Block(-4,26,-2,minecraft:leaves2:1)
Block(-3,26,-2,minecraft:leaves2:1)
Block(-2,26,-2,minecraft:leaves2:1)
Block(0,26,-2,minecraft:log2:1)
Block(1,26,-2,minecraft:leaves2:1)
Block(2,26,-2,minecraft:leaves2:1)
Block(3,26,-2,minecraft:leaves2:1)
Block(4,26,-2,minecraft:leaves2:1)
Block(5,26,-2,minecraft:leaves2:1)
Block(6,26,-2,minecraft:leaves2:1)
Block(-6,26,-1,minecraft:leaves2:1)
Block(-5,26,-1,minecraft:leaves2:1)
Block(-3,26,-1,minecraft:leaves2:1)
Block(-1,26,-1,minecraft:log2:1)
Block(0,26,-1,minecraft:log2:1)
Block(1,26,-1,minecraft:log2:1)
Block(2,26,-1,minecraft:log2:1)
Block(3,26,-1,minecraft:leaves2:1)
Block(4,26,-1,minecraft:leaves2:1)
Block(5,26,-1,minecraft:leaves2:1)
Block(6,26,-1,minecraft:leaves2:1)
Block(-6,26,0,minecraft:leaves2:1)
Block(-5,26,0,minecraft:leaves2:1)
Block(-4,26,0,minecraft:leaves2:1)
Block(-3,26,0,minecraft:leaves2:1)
Block(-2,26,0,minecraft:log2:1)
Block(-1,26,0,minecraft:log2:1)
Block(0,26,0,minecraft:leaves2:1)
Block(1,26,0,minecraft:log2:1)
Block(2,26,0,minecraft:log2:1)
Block(3,26,0,minecraft:leaves2:1)
Block(4,26,0,minecraft:leaves2:1)
Block(5,26,0,minecraft:leaves2:1)
Block(6,26,0,minecraft:leaves2:1)
Block(-6,26,1,minecraft:leaves2:1)
Block(-5,26,1,minecraft:leaves2:1)
Block(-4,26,1,minecraft:leaves2:1)
Block(-3,26,1,minecraft:leaves2:1)
Block(-2,26,1,minecraft:log2:1)
Block(-1,26,1,minecraft:log2:1)
Block(0,26,1,minecraft:log2:1)
Block(1,26,1,minecraft:log2:1)
Block(2,26,1,minecraft:log2:1)
Block(3,26,1,minecraft:leaves2:1)
Block(4,26,1,minecraft:leaves2:1)
Block(5,26,1,minecraft:leaves2:1)
Block(6,26,1,minecraft:leaves2:1)
Block(-6,26,2,minecraft:leaves2:1)
Block(-5,26,2,minecraft:leaves2:1)
Block(-4,26,2,minecraft:leaves2:1)
Block(-3,26,2,minecraft:leaves2:1)
Block(-2,26,2,minecraft:leaves2:1)
Block(-1,26,2,minecraft:log2:1)
Block(0,26,2,minecraft:log2:1)
Block(1,26,2,minecraft:log2:1)
Block(2,26,2,minecraft:leaves2:1)
Block(3,26,2,minecraft:leaves2:1)
Block(4,26,2,minecraft:leaves2:1)
Block(5,26,2,minecraft:leaves2:1)
Block(-5,26,3,minecraft:leaves2:1)
Block(-4,26,3,minecraft:leaves2:1)
Block(-3,26,3,minecraft:leaves2:1)
Block(-2,26,3,minecraft:leaves2:1)
Block(-1,26,3,minecraft:leaves2:1)
Block(0,26,3,minecraft:leaves2:1)
Block(1,26,3,minecraft:leaves2:1)
Block(2,26,3,minecraft:leaves2:1)
Block(3,26,3,minecraft:leaves2:1)
Block(4,26,3,minecraft:leaves2:1)
Block(-5,26,4,minecraft:leaves2:1)
Block(-4,26,4,minecraft:leaves2:1)
Block(-3,26,4,minecraft:leaves2:1)
Block(-2,26,4,minecraft:leaves2:1)
Block(-1,26,4,minecraft:leaves2:1)
Block(0,26,4,minecraft:leaves2:1)
Block(1,26,4,minecraft:leaves2:1)
Block(2,26,4,minecraft:leaves2:1)
Block(3,26,4,minecraft:leaves2:1)
Block(-4,26,5,minecraft:leaves2:1)
Block(-3,26,5,minecraft:leaves2:1)
Block(-1,26,5,minecraft:leaves2:1)
Block(1,26,5,minecraft:leaves2:1)
Block(2,26,5,minecraft:leaves2:1)
Block(3,26,5,minecraft:leaves2:1)
Block(4,26,5,minecraft:leaves2:1)
Block(-2,26,6,minecraft:leaves2:1)
Block(-1,26,6,minecraft:leaves2:1)
Block(0,26,6,minecraft:leaves2:1)
Block(1,26,6,minecraft:leaves2:1)
Block(2,26,6,minecraft:leaves2:1)
Block(0,27,-5,minecraft:leaves2:1)
Block(-3,27,-4,minecraft:leaves2:1)
Block(1,27,-4,minecraft:leaves2:1)
Block(3,27,-4,minecraft:leaves2:1)
Block(-1,27,-3,minecraft:leaves2:1)
Block(3,27,-3,minecraft:leaves2:1)
Block(-2,27,-2,minecraft:leaves2:1)
Block(0,27,-2,minecraft:log2:1)
Block(2,27,-2,minecraft:leaves2:1)
Block(-2,27,-1,minecraft:leaves2:1)
Block(-1,27,-1,minecraft:log2:1)
Block(0,27,-1,minecraft:log2:1)
Block(1,27,-1,minecraft:log2:1)
Block(2,27,-1,minecraft:log2:1)
Block(3,27,-1,minecraft:leaves2:1)
Block(5,27,-1,minecraft:leaves2:1)
Block(-5,27,0,minecraft:leaves2:1)
Block(-4,27,0,minecraft:leaves2:1)
Block(-2,27,0,minecraft:log2:1)
Block(-1,27,0,minecraft:log2:1)
Block(0,27,0,minecraft:log2:1)
Block(1,27,0,minecraft:log2:1)
Block(2,27,0,minecraft:log2:1)
Block(-2,27,1,minecraft:leaves2:1)
Block(-1,27,1,minecraft:log2:1)
Block(0,27,1,minecraft:log2:1)
Block(1,27,1,minecraft:log2:1)
Block(2,27,1,minecraft:log2:1)
Block(-1,27,2,minecraft:log2:1)
Block(0,27,2,minecraft:log2:1)
Block(1,27,2,minecraft:log2:1)
Block(-4,27,3,minecraft:leaves2:1)
Block(-1,27,3,minecraft:leaves2:1)
Block(1,27,3,minecraft:leaves2:1)
Block(-2,28,-5,minecraft:leaves2:1)
Block(-1,28,-5,minecraft:leaves2:1)
Block(0,28,-5,minecraft:leaves2:1)
Block(1,28,-5,minecraft:leaves2:1)
Block(2,28,-5,minecraft:leaves2:1)
Block(-2,28,-4,minecraft:leaves2:1)
Block(-1,28,-4,minecraft:leaves2:1)
Block(0,28,-4,minecraft:leaves2:1)
Block(1,28,-4,minecraft:leaves2:1)
Block(2,28,-4,minecraft:leaves2:1)
Block(3,28,-4,minecraft:leaves2:1)
Block(-3,28,-3,minecraft:leaves2:1)
Block(-2,28,-3,minecraft:leaves2:1)
Block(-1,28,-3,minecraft:leaves2:1)
Block(0,28,-3,minecraft:leaves2:1)
Block(1,28,-3,minecraft:leaves2:1)
Block(2,28,-3,minecraft:leaves2:1)
Block(3,28,-3,minecraft:leaves2:1)
Block(4,28,-3,minecraft:leaves2:1)
Block(-5,28,-2,minecraft:leaves2:1)
Block(-4,28,-2,minecraft:leaves2:1)
Block(-3,28,-2,minecraft:leaves2:1)
Block(-2,28,-2,minecraft:leaves2:1)
Block(-1,28,-2,minecraft:leaves2:1)
Block(0,28,-2,minecraft:log2:1)
Block(1,28,-2,minecraft:leaves2:1)
Block(3,28,-2,minecraft:leaves2:1)
Block(4,28,-2,minecraft:leaves2:1)
Block(5,28,-2,minecraft:leaves2:1)
Block(-5,28,-1,minecraft:leaves2:1)
Block(-4,28,-1,minecraft:leaves2:1)
Block(-3,28,-1,minecraft:leaves2:1)
Block(-2,28,-1,minecraft:leaves2:1)
Block(-1,28,-1,minecraft:log2:1)
Block(0,28,-1,minecraft:log2:1)
Block(1,28,-1,minecraft:log2:1)
Block(2,28,-1,minecraft:leaves2:1)
Block(4,28,-1,minecraft:leaves2:1)
Block(5,28,-1,minecraft:leaves2:1)
Block(-5,28,0,minecraft:leaves2:1)
Block(-4,28,0,minecraft:leaves2:1)
Block(-3,28,0,minecraft:leaves2:1)
Block(-2,28,0,minecraft:leaves2:1)
Block(-1,28,0,minecraft:log2:1)
Block(0,28,0,minecraft:leaves2:1)
Block(1,28,0,minecraft:log2:1)
Block(2,28,0,minecraft:log2:1)
Block(3,28,0,minecraft:leaves2:1)
Block(4,28,0,minecraft:leaves2:1)
Block(5,28,0,minecraft:leaves2:1)
Block(-5,28,1,minecraft:leaves2:1)
Block(-4,28,1,minecraft:leaves2:1)
Block(-3,28,1,minecraft:leaves2:1)
Block(-2,28,1,minecraft:leaves2:1)
