#######################################################################
# +-----------------------------------------------------------------+ #
# |                            BO3 object                           | #
# +-----------------------------------------------------------------+ #
#######################################################################

# This is the config file of a custom object.
# If you add this object correctly to your BiomeConfigs, it will spawn in the world.

# This is the creator of this BO3 object
Author: BO3 BulkEdit (by LanToaster)

# A short description of this BO3 object
Description: This Object was Created with BO3_BulkEdit

# The BO3 version, don't change this! It can be used by external applications to do a version check.
Version: 3

# The settings mode, WriteAll, WriteWithoutComments or WriteDisable. See WorldConfig.
SettingsMode: WriteDisable


#######################################################################
# +-----------------------------------------------------------------+ #
# |                          Main settings                          | #
# +-----------------------------------------------------------------+ #
#######################################################################

# This needs to be set to true to spawn the object in the Tree and Sapling resources.
Tree: true

# The frequency of the BO3 from 1 to 200. Tries this many times to spawn this BO3 when using the CustomObject(...) resource.
# Ignored by Tree(..), Sapling(..) and CustomStructure(..)
Frequency: 1

# The rarity of the BO3 from 0 to 100. Each spawn attempt has rarity% chance to succeed when using the CustomObject(...) resource.
# Ignored by Tree(..), Sapling(..) and CustomStructure(..)
Rarity: 100.0

# If you set this to true, the BO3 will be placed with a random rotation.
RotateRandomly: true

# The spawn height of the BO3 - randomY, highestBlock or highestSolid)Block.
SpawnHeight: randomY

# The height limits for the BO3.
MinHeight: 92

MaxHeight: 256

# Objects can have other objects attacthed to it: branches. Branches can also
# have branches attached to it, which can also have branches, etc. This is the
# maximum branch depth for this objects.
MaxBranchDepth: 10

# When spawned with the UseWorld keyword, this BO3 should NOT spawn in the following biomes.
# If you writer.write the BO3 name directly in the BiomeConfigs, this will be ignored.
ExcludedBiomes: All


#######################################################################
# +-----------------------------------------------------------------+ #
# |                      Source block settings                      | #
# +-----------------------------------------------------------------+ #
#######################################################################

# The block(s) the BO3 should spawn in.
SourceBlocks: AIR,minecraft:grass,minecraft:dirt

# The maximum percentage of the BO3 that can be outside the SourceBlock.
# The BO3 won't be placed on a location with more blocks outside the SourceBlock than this percentage.
MaxPercentageOutsideSourceBlock: 100

# What to do when a block is about to be placed outside the SourceBlock? (dontPlace, placeAnyway)
OutsideSourceBlock: placeAnyway


#######################################################################
# +-----------------------------------------------------------------+ #
# |                              Blocks                             | #
# +-----------------------------------------------------------------+ #
#######################################################################

# All the blocks used in the BO3 are listed here. Possible blocks:
# Block(x,y,z,id[.data][,nbtfile.nbt)
# RandomBlock(x,y,z,id[:data][,nbtfile.nbt],chance[,id[:data][,nbtfile.nbt],chance[,...]])
# So RandomBlock(0,0,0,CHEST,chest.nbt,50,CHEST,anotherchest.nbt,100) will spawn a chest at
# the BO3 origin, and give it a 50% chance to have the contents of chest.nbt, or, if that
# fails, a 100% percent chance to have the contents of anotherchest.nbt.
Block(2,0,-14,biomesoplenty:log_3:6)
Block(3,0,-14,biomesoplenty:log_3:6)
Block(1,0,-13,biomesoplenty:log_3:6)
Block(2,0,-13,biomesoplenty:log_3:6)
Block(3,0,-13,biomesoplenty:log_3:6)
Block(1,0,-12,biomesoplenty:log_3:6)
Block(2,0,-12,biomesoplenty:log_3:6)
Block(0,0,-11,biomesoplenty:log_3:6)
Block(1,0,-11,biomesoplenty:log_3:6)
Block(2,0,-11,biomesoplenty:log_3:6)
Block(-2,0,-10,biomesoplenty:log_3:6)
Block(-1,0,-10,biomesoplenty:log_3:6)
Block(0,0,-10,biomesoplenty:log_3:6)
Block(1,0,-10,biomesoplenty:log_3:6)
Block(-13,0,-9,biomesoplenty:log_3:6)
Block(-12,0,-9,biomesoplenty:log_3:6)
Block(-11,0,-9,biomesoplenty:log_3:6)
Block(-10,0,-9,biomesoplenty:log_3:6)
Block(-9,0,-9,biomesoplenty:log_3:6)
Block(-3,0,-9,biomesoplenty:log_3:6)
Block(-2,0,-9,biomesoplenty:log_3:6)
Block(-1,0,-9,biomesoplenty:log_3:6)
Block(0,0,-9,biomesoplenty:log_3:6)
Block(1,0,-9,biomesoplenty:log_3:6)
Block(-10,0,-8,biomesoplenty:log_3:6)
Block(-9,0,-8,biomesoplenty:log_3:6)
Block(-8,0,-8,biomesoplenty:log_3:6)
Block(-7,0,-8,biomesoplenty:log_3:6)
Block(-6,0,-8,biomesoplenty:log_3:6)
Block(-5,0,-8,biomesoplenty:log_3:6)
Block(-4,0,-8,biomesoplenty:log_3:6)
Block(-3,0,-8,biomesoplenty:log_3:6)
Block(-2,0,-8,biomesoplenty:log_3:6)
Block(-1,0,-8,biomesoplenty:log_3:6)
Block(0,0,-8,biomesoplenty:log_3:6)
Block(1,0,-8,biomesoplenty:log_3:6)
Block(2,0,-8,biomesoplenty:log_3:6)
Block(-10,0,-7,biomesoplenty:log_3:6)
Block(-9,0,-7,biomesoplenty:log_3:6)
Block(-8,0,-7,biomesoplenty:log_3:6)
Block(-7,0,-7,biomesoplenty:log_3:6)
Block(-6,0,-7,biomesoplenty:log_3:6)
Block(-5,0,-7,biomesoplenty:log_3:6)
Block(-4,0,-7,biomesoplenty:log_3:6)
Block(-3,0,-7,biomesoplenty:log_3:6)
Block(-2,0,-7,biomesoplenty:log_3:6)
Block(-1,0,-7,biomesoplenty:log_3:6)
Block(0,0,-7,biomesoplenty:log_3:6)
Block(1,0,-7,biomesoplenty:log_3:6)
Block(2,0,-7,biomesoplenty:log_3:6)
Block(-8,0,-6,biomesoplenty:log_3:6)
Block(-7,0,-6,biomesoplenty:log_3:6)
Block(-6,0,-6,biomesoplenty:log_3:6)
Block(-5,0,-6,biomesoplenty:log_3:6)
Block(-4,0,-6,biomesoplenty:log_3:6)
Block(-3,0,-6,biomesoplenty:log_3:6)
Block(-2,0,-6,biomesoplenty:log_3:6)
Block(-1,0,-6,biomesoplenty:log_3:6)
Block(0,0,-6,biomesoplenty:log_3:6)
Block(1,0,-6,biomesoplenty:log_3:6)
Block(2,0,-6,biomesoplenty:log_3:6)
Block(3,0,-6,biomesoplenty:log_3:6)
Block(-8,0,-5,biomesoplenty:log_3:6)
Block(-7,0,-5,biomesoplenty:log_3:6)
Block(-6,0,-5,biomesoplenty:log_3:6)
Block(-5,0,-5,biomesoplenty:log_3:6)
Block(-4,0,-5,biomesoplenty:log_3:6)
Block(-3,0,-5,biomesoplenty:log_3:6)
Block(-2,0,-5,biomesoplenty:log_3:6)
Block(-1,0,-5,biomesoplenty:log_3:6)
Block(0,0,-5,biomesoplenty:log_3:6)
Block(1,0,-5,biomesoplenty:log_3:6)
Block(2,0,-5,biomesoplenty:log_3:6)
Block(3,0,-5,biomesoplenty:log_3:6)
Block(4,0,-5,biomesoplenty:log_3:6)
Block(5,0,-5,biomesoplenty:log_3:6)
Block(-11,0,-4,biomesoplenty:log_3:6)
Block(-10,0,-4,biomesoplenty:log_3:6)
Block(-9,0,-4,biomesoplenty:log_3:6)
Block(-8,0,-4,biomesoplenty:log_3:6)
Block(-7,0,-4,biomesoplenty:log_3:6)
Block(-6,0,-4,biomesoplenty:log_3:6)
Block(-5,0,-4,biomesoplenty:log_3:6)
Block(-4,0,-4,biomesoplenty:log_3:6)
Block(-3,0,-4,biomesoplenty:log_3:6)
Block(-2,0,-4,biomesoplenty:log_3:6)
Block(-1,0,-4,biomesoplenty:log_3:6)
Block(0,0,-4,biomesoplenty:log_3:6)
Block(1,0,-4,biomesoplenty:log_3:6)
Block(2,0,-4,biomesoplenty:log_3:6)
Block(3,0,-4,biomesoplenty:log_3:6)
Block(4,0,-4,biomesoplenty:log_3:6)
Block(5,0,-4,biomesoplenty:log_3:6)
Block(6,0,-4,biomesoplenty:log_3:6)
Block(7,0,-4,biomesoplenty:log_3:6)
Block(-13,0,-3,biomesoplenty:log_3:6)
Block(-12,0,-3,biomesoplenty:log_3:6)
Block(-11,0,-3,biomesoplenty:log_3:6)
Block(-8,0,-3,biomesoplenty:log_3:6)
Block(-7,0,-3,biomesoplenty:log_3:6)
Block(-6,0,-3,biomesoplenty:log_3:6)
Block(-5,0,-3,biomesoplenty:log_3:6)
Block(-4,0,-3,biomesoplenty:log_3:6)
Block(-3,0,-3,biomesoplenty:log_3:6)
Block(-2,0,-3,biomesoplenty:log_3:6)
Block(-1,0,-3,biomesoplenty:log_3:6)
Block(0,0,-3,biomesoplenty:log_3:6)
Block(1,0,-3,biomesoplenty:log_3:6)
Block(2,0,-3,biomesoplenty:log_3:6)
Block(3,0,-3,biomesoplenty:log_3:6)
Block(4,0,-3,biomesoplenty:log_3:6)
Block(5,0,-3,biomesoplenty:log_3:6)
Block(6,0,-3,biomesoplenty:log_3:6)
Block(7,0,-3,biomesoplenty:log_3:6)
Block(8,0,-3,biomesoplenty:log_3:6)
Block(9,0,-3,biomesoplenty:log_3:6)
Block(-8,0,-2,biomesoplenty:log_3:6)
Block(-7,0,-2,biomesoplenty:log_3:6)
Block(-6,0,-2,biomesoplenty:log_3:6)
Block(-5,0,-2,biomesoplenty:log_3:6)
Block(-4,0,-2,biomesoplenty:log_3:6)
Block(-3,0,-2,biomesoplenty:log_3:6)
Block(-2,0,-2,biomesoplenty:log_3:6)
Block(-1,0,-2,biomesoplenty:log_3:6)
Block(0,0,-2,biomesoplenty:log_3:6)
Block(1,0,-2,biomesoplenty:log_3:6)
Block(2,0,-2,biomesoplenty:log_3:6)
Block(3,0,-2,biomesoplenty:log_3:6)
Block(4,0,-2,biomesoplenty:log_3:6)
Block(5,0,-2,biomesoplenty:log_3:6)
Block(6,0,-2,biomesoplenty:log_3:6)
Block(7,0,-2,biomesoplenty:log_3:6)
Block(8,0,-2,biomesoplenty:log_3:6)
Block(9,0,-2,biomesoplenty:log_3:6)
Block(10,0,-2,biomesoplenty:log_3:6)
Block(11,0,-2,biomesoplenty:log_3:6)
Block(12,0,-2,biomesoplenty:log_3:6)
Block(-9,0,-1,biomesoplenty:log_3:6)
Block(-8,0,-1,biomesoplenty:log_3:6)
Block(-7,0,-1,biomesoplenty:log_3:6)
Block(-6,0,-1,biomesoplenty:log_3:6)
Block(-5,0,-1,biomesoplenty:log_3:6)
Block(-4,0,-1,biomesoplenty:log_3:6)
Block(-3,0,-1,biomesoplenty:log_3:6)
Block(-2,0,-1,biomesoplenty:log_3:6)
Block(-1,0,-1,biomesoplenty:log_3:6)
Block(0,0,-1,biomesoplenty:log_3:6)
Block(1,0,-1,biomesoplenty:log_3:6)
Block(2,0,-1,biomesoplenty:log_3:6)
Block(3,0,-1,biomesoplenty:log_3:6)
Block(4,0,-1,biomesoplenty:log_3:6)
Block(5,0,-1,biomesoplenty:log_3:6)
Block(6,0,-1,biomesoplenty:log_3:6)
Block(7,0,-1,biomesoplenty:log_3:6)
Block(8,0,-1,biomesoplenty:log_3:6)
Block(-9,0,0,biomesoplenty:log_3:6)
Block(-8,0,0,biomesoplenty:log_3:6)
Block(-7,0,0,biomesoplenty:log_3:6)
Block(-6,0,0,biomesoplenty:log_3:6)
Block(-5,0,0,biomesoplenty:log_3:6)
Block(-4,0,0,biomesoplenty:log_3:6)
Block(-3,0,0,biomesoplenty:log_3:6)
Block(-2,0,0,biomesoplenty:log_3:6)
Block(-1,0,0,biomesoplenty:log_3:6)
Block(0,0,0,biomesoplenty:log_3:6)
Block(1,0,0,biomesoplenty:log_3:6)
Block(2,0,0,biomesoplenty:log_3:6)
Block(3,0,0,biomesoplenty:log_3:6)
Block(4,0,0,biomesoplenty:log_3:6)
Block(5,0,0,biomesoplenty:log_3:6)
Block(6,0,0,biomesoplenty:log_3:6)
Block(-9,0,1,biomesoplenty:log_3:6)
Block(-8,0,1,biomesoplenty:log_3:6)
Block(-7,0,1,biomesoplenty:log_3:6)
Block(-6,0,1,biomesoplenty:log_3:6)
Block(-5,0,1,biomesoplenty:log_3:6)
Block(-4,0,1,biomesoplenty:log_3:6)
Block(-3,0,1,biomesoplenty:log_3:6)
Block(-2,0,1,biomesoplenty:log_3:6)
Block(-1,0,1,biomesoplenty:log_3:6)
Block(0,0,1,biomesoplenty:log_3:6)
Block(1,0,1,biomesoplenty:log_3:6)
Block(2,0,1,biomesoplenty:log_3:6)
Block(3,0,1,biomesoplenty:log_3:6)
Block(4,0,1,biomesoplenty:log_3:6)
Block(5,0,1,biomesoplenty:log_3:6)
Block(-10,0,2,biomesoplenty:log_3:6)
Block(-9,0,2,biomesoplenty:log_3:6)
Block(-8,0,2,biomesoplenty:log_3:6)
Block(-7,0,2,biomesoplenty:log_3:6)
Block(-6,0,2,biomesoplenty:log_3:6)
Block(-5,0,2,biomesoplenty:log_3:6)
Block(-4,0,2,biomesoplenty:log_3:6)
Block(-3,0,2,biomesoplenty:log_3:6)
Block(-2,0,2,biomesoplenty:log_3:6)
Block(-1,0,2,biomesoplenty:log_3:6)
Block(0,0,2,biomesoplenty:log_3:6)
Block(1,0,2,biomesoplenty:log_3:6)
Block(2,0,2,biomesoplenty:log_3:6)
Block(3,0,2,biomesoplenty:log_3:6)
Block(-11,0,3,biomesoplenty:log_3:6)
Block(-10,0,3,biomesoplenty:log_3:6)
Block(-9,0,3,biomesoplenty:log_3:6)
Block(-8,0,3,biomesoplenty:log_3:6)
Block(-6,0,3,biomesoplenty:log_3:6)
Block(-5,0,3,biomesoplenty:log_3:6)
Block(-4,0,3,biomesoplenty:log_3:6)
Block(-3,0,3,biomesoplenty:log_3:6)
Block(-2,0,3,biomesoplenty:log_3:6)
Block(-1,0,3,biomesoplenty:log_3:6)
Block(0,0,3,biomesoplenty:log_3:6)
Block(1,0,3,biomesoplenty:log_3:6)
Block(2,0,3,biomesoplenty:log_3:6)
Block(-12,0,4,biomesoplenty:log_3:6)
Block(-11,0,4,biomesoplenty:log_3:6)
Block(-10,0,4,biomesoplenty:log_3:6)
Block(-3,0,4,biomesoplenty:log_3:6)
Block(-2,0,4,biomesoplenty:log_3:6)
Block(-1,0,4,biomesoplenty:log_3:6)
Block(0,0,4,biomesoplenty:log_3:6)
Block(1,0,4,biomesoplenty:log_3:6)
Block(-13,0,5,biomesoplenty:log_3:6)
Block(-12,0,5,biomesoplenty:log_3:6)
Block(-11,0,5,biomesoplenty:log_3:6)
Block(-3,0,5,biomesoplenty:log_3:6)
Block(-2,0,5,biomesoplenty:log_3:6)
Block(-1,0,5,biomesoplenty:log_3:6)
Block(0,0,5,biomesoplenty:log_3:6)
Block(-13,0,6,biomesoplenty:log_3:6)
Block(-12,0,6,biomesoplenty:log_3:6)
Block(-11,0,6,biomesoplenty:log_3:6)
Block(-3,0,6,biomesoplenty:log_3:6)
Block(-2,0,6,biomesoplenty:log_3:6)
Block(-1,0,6,biomesoplenty:log_3:6)
Block(0,0,6,biomesoplenty:log_3:6)
Block(-13,0,7,biomesoplenty:log_3:6)
Block(-12,0,7,biomesoplenty:log_3:6)
Block(-11,0,7,biomesoplenty:log_3:6)
Block(-2,0,7,biomesoplenty:log_3:6)
Block(-1,0,7,biomesoplenty:log_3:6)
Block(0,0,7,biomesoplenty:log_3:6)
Block(-12,0,8,biomesoplenty:log_3:6)
Block(-2,0,8,biomesoplenty:log_3:6)
Block(-1,0,8,biomesoplenty:log_3:6)
Block(0,0,8,biomesoplenty:log_3:6)
Block(-2,0,9,biomesoplenty:log_3:6)
Block(-1,0,9,biomesoplenty:log_3:6)
Block(0,0,9,biomesoplenty:log_3:6)
Block(-3,0,10,biomesoplenty:log_3:6)
Block(-2,0,10,biomesoplenty:log_3:6)
Block(-1,0,10,biomesoplenty:log_3:6)
Block(-2,0,11,biomesoplenty:log_3:6)
Block(-1,0,11,biomesoplenty:log_3:6)
Block(-2,0,12,biomesoplenty:log_3:6)
Block(-1,0,12,biomesoplenty:log_3:6)
Block(-2,0,13,biomesoplenty:log_3:6)
Block(-2,1,-9,biomesoplenty:log_3:6)
Block(-1,1,-9,biomesoplenty:log_3:6)
Block(0,1,-9,biomesoplenty:log_3:6)
Block(-3,1,-8,biomesoplenty:log_3:6)
Block(-2,1,-8,biomesoplenty:log_3:6)
Block(-1,1,-8,biomesoplenty:log_3:6)
Block(0,1,-8,biomesoplenty:log_3:6)
Block(1,1,-8,biomesoplenty:log_3:6)
Block(-5,1,-7,biomesoplenty:log_3:6)
Block(-4,1,-7,biomesoplenty:log_3:6)
Block(-3,1,-7,biomesoplenty:log_3:6)
Block(-2,1,-7,biomesoplenty:log_3:6)
Block(-1,1,-7,biomesoplenty:log_3:6)
Block(0,1,-7,biomesoplenty:log_3:6)
Block(1,1,-7,biomesoplenty:log_3:6)
Block(-6,1,-6,biomesoplenty:log_3:6)
Block(-5,1,-6,biomesoplenty:log_3:6)
Block(-4,1,-6,biomesoplenty:log_3:6)
Block(-3,1,-6,biomesoplenty:log_3:6)
Block(-2,1,-6,biomesoplenty:log_3:6)
Block(-1,1,-6,biomesoplenty:log_3:6)
Block(0,1,-6,biomesoplenty:log_3:6)
Block(1,1,-6,biomesoplenty:log_3:6)
Block(2,1,-6,biomesoplenty:log_3:6)
Block(-6,1,-5,biomesoplenty:log_3:6)
Block(-5,1,-5,biomesoplenty:log_3:6)
Block(-4,1,-5,biomesoplenty:log_3:6)
Block(-3,1,-5,biomesoplenty:log_3:6)
Block(-2,1,-5,biomesoplenty:log_3:6)
Block(-1,1,-5,biomesoplenty:log_3:6)
Block(0,1,-5,biomesoplenty:log_3:6)
Block(1,1,-5,biomesoplenty:log_3:6)
Block(2,1,-5,biomesoplenty:log_3:6)
Block(3,1,-5,biomesoplenty:log_3:6)
Block(-9,1,-4,biomesoplenty:log_3:6)
Block(-8,1,-4,biomesoplenty:log_3:6)
Block(-7,1,-4,biomesoplenty:log_3:6)
Block(-6,1,-4,biomesoplenty:log_3:6)
Block(-5,1,-4,biomesoplenty:log_3:6)
Block(-4,1,-4,biomesoplenty:log_3:6)
Block(-3,1,-4,biomesoplenty:log_3:6)
Block(-2,1,-4,biomesoplenty:log_3:6)
Block(-1,1,-4,biomesoplenty:log_3:6)
Block(0,1,-4,biomesoplenty:log_3:6)
Block(1,1,-4,biomesoplenty:log_3:6)
Block(2,1,-4,biomesoplenty:log_3:6)
Block(3,1,-4,biomesoplenty:log_3:6)
Block(4,1,-4,biomesoplenty:log_3:6)
Block(5,1,-4,biomesoplenty:log_3:6)
Block(-8,1,-3,biomesoplenty:log_3:6)
Block(-7,1,-3,biomesoplenty:log_3:6)
Block(-6,1,-3,biomesoplenty:log_3:6)
Block(-5,1,-3,biomesoplenty:log_3:6)
Block(-4,1,-3,biomesoplenty:log_3:6)
Block(-3,1,-3,biomesoplenty:log_3:6)
Block(-2,1,-3,biomesoplenty:log_3:6)
Block(-1,1,-3,biomesoplenty:log_3:6)
Block(0,1,-3,biomesoplenty:log_3:6)
Block(1,1,-3,biomesoplenty:log_3:6)
Block(2,1,-3,biomesoplenty:log_3:6)
Block(3,1,-3,biomesoplenty:log_3:6)
Block(4,1,-3,biomesoplenty:log_3:6)
Block(5,1,-3,biomesoplenty:log_3:6)
Block(6,1,-3,biomesoplenty:log_3:6)
Block(7,1,-3,biomesoplenty:log_3:6)
Block(-7,1,-2,biomesoplenty:log_3:6)
Block(-6,1,-2,biomesoplenty:log_3:6)
Block(-5,1,-2,biomesoplenty:log_3:6)
Block(-4,1,-2,biomesoplenty:log_3:6)
Block(-3,1,-2,biomesoplenty:log_3:6)
Block(-2,1,-2,biomesoplenty:log_3:6)
Block(-1,1,-2,biomesoplenty:log_3:6)
Block(0,1,-2,biomesoplenty:log_3:6)
Block(1,1,-2,biomesoplenty:log_3:6)
Block(2,1,-2,biomesoplenty:log_3:6)
Block(3,1,-2,biomesoplenty:log_3:6)
Block(4,1,-2,biomesoplenty:log_3:6)
Block(5,1,-2,biomesoplenty:log_3:6)
Block(6,1,-2,biomesoplenty:log_3:6)
Block(-7,1,-1,biomesoplenty:log_3:6)
Block(-6,1,-1,biomesoplenty:log_3:6)
Block(-5,1,-1,biomesoplenty:log_3:6)
Block(-4,1,-1,biomesoplenty:log_3:6)
Block(-3,1,-1,biomesoplenty:log_3:6)
Block(-2,1,-1,biomesoplenty:log_3:6)
Block(-1,1,-1,biomesoplenty:log_3:6)
Block(0,1,-1,biomesoplenty:log_3:6)
Block(1,1,-1,biomesoplenty:log_3:6)
Block(2,1,-1,biomesoplenty:log_3:6)
Block(3,1,-1,biomesoplenty:log_3:6)
Block(4,1,-1,biomesoplenty:log_3:6)
Block(5,1,-1,biomesoplenty:log_3:6)
Block(6,1,-1,biomesoplenty:log_3:6)
Block(-8,1,0,biomesoplenty:log_3:6)
Block(-7,1,0,biomesoplenty:log_3:6)
Block(-6,1,0,biomesoplenty:log_3:6)
Block(-5,1,0,biomesoplenty:log_3:6)
Block(-4,1,0,biomesoplenty:log_3:6)
Block(-3,1,0,biomesoplenty:log_3:6)
Block(-2,1,0,biomesoplenty:log_3:6)
Block(-1,1,0,biomesoplenty:log_3:6)
Block(0,1,0,biomesoplenty:log_3:6)
Block(1,1,0,biomesoplenty:log_3:6)
Block(2,1,0,biomesoplenty:log_3:6)
Block(3,1,0,biomesoplenty:log_3:6)
Block(4,1,0,biomesoplenty:log_3:6)
Block(5,1,0,biomesoplenty:log_3:6)
Block(-8,1,1,biomesoplenty:log_3:6)
Block(-7,1,1,biomesoplenty:log_3:6)
Block(-6,1,1,biomesoplenty:log_3:6)
Block(-5,1,1,biomesoplenty:log_3:6)
Block(-4,1,1,biomesoplenty:log_3:6)
Block(-3,1,1,biomesoplenty:log_3:6)
Block(-2,1,1,biomesoplenty:log_3:6)
Block(-1,1,1,biomesoplenty:log_3:6)
Block(0,1,1,biomesoplenty:log_3:6)
Block(1,1,1,biomesoplenty:log_3:6)
Block(2,1,1,biomesoplenty:log_3:6)
Block(-5,1,2,biomesoplenty:log_3:6)
Block(-4,1,2,biomesoplenty:log_3:6)
Block(-3,1,2,biomesoplenty:log_3:6)
Block(-2,1,2,biomesoplenty:log_3:6)
Block(-1,1,2,biomesoplenty:log_3:6)
Block(0,1,2,biomesoplenty:log_3:6)
Block(1,1,2,biomesoplenty:log_3:6)
Block(2,1,2,biomesoplenty:log_3:6)
Block(-2,1,3,biomesoplenty:log_3:6)
Block(-1,1,3,biomesoplenty:log_3:6)
Block(0,1,3,biomesoplenty:log_3:6)
Block(1,1,3,biomesoplenty:log_3:6)
Block(2,1,3,biomesoplenty:log_3:6)
Block(-2,1,4,biomesoplenty:log_3:6)
Block(-1,1,4,biomesoplenty:log_3:6)
Block(-2,1,5,biomesoplenty:log_3:6)
Block(-1,1,5,biomesoplenty:log_3:6)
Block(-1,1,6,biomesoplenty:log_3:6)
Block(-1,1,7,biomesoplenty:log_3:6)
Block(-1,2,-8,biomesoplenty:log_3:6)
Block(-2,2,-7,biomesoplenty:log_3:6)
Block(-1,2,-7,biomesoplenty:log_3:6)
Block(0,2,-7,biomesoplenty:log_3:6)
Block(-4,2,-6,biomesoplenty:log_3:6)
Block(-3,2,-6,biomesoplenty:log_3:6)
Block(-2,2,-6,biomesoplenty:log_3:6)
Block(-1,2,-6,biomesoplenty:log_3:6)
Block(0,2,-6,biomesoplenty:log_3:6)
Block(-5,2,-5,biomesoplenty:log_3:6)
Block(-4,2,-5,biomesoplenty:log_3:6)
Block(-3,2,-5,biomesoplenty:log_3:6)
Block(-2,2,-5,biomesoplenty:log_3:6)
Block(-1,2,-5,biomesoplenty:log_3:6)
Block(0,2,-5,biomesoplenty:log_3:6)
Block(1,2,-5,biomesoplenty:log_3:6)
Block(2,2,-5,biomesoplenty:log_3:6)
Block(-5,2,-4,biomesoplenty:log_3:6)
Block(-4,2,-4,biomesoplenty:log_3:6)
Block(-3,2,-4,biomesoplenty:log_3:6)
Block(-2,2,-4,biomesoplenty:log_3:6)
Block(-1,2,-4,biomesoplenty:log_3:6)
Block(0,2,-4,biomesoplenty:log_3:6)
Block(1,2,-4,biomesoplenty:log_3:6)
Block(2,2,-4,biomesoplenty:log_3:6)
Block(-4,2,-3,biomesoplenty:log_3:6)
Block(-3,2,-3,biomesoplenty:log_3:6)
Block(-2,2,-3,biomesoplenty:log_3:6)
Block(-1,2,-3,biomesoplenty:log_3:6)
Block(0,2,-3,biomesoplenty:log_3:6)
Block(1,2,-3,biomesoplenty:log_3:6)
Block(2,2,-3,biomesoplenty:log_3:6)
Block(3,2,-3,biomesoplenty:log_3:6)
Block(-5,2,-2,biomesoplenty:log_3:6)
Block(-4,2,-2,biomesoplenty:log_3:6)
Block(-3,2,-2,biomesoplenty:log_3:6)
Block(-2,2,-2,biomesoplenty:log_3:6)
Block(-1,2,-2,biomesoplenty:log_3:6)
Block(0,2,-2,biomesoplenty:log_3:6)
Block(1,2,-2,biomesoplenty:log_3:6)
Block(2,2,-2,biomesoplenty:log_3:6)
Block(3,2,-2,biomesoplenty:log_3:6)
Block(4,2,-2,biomesoplenty:log_3:6)
Block(5,2,-2,biomesoplenty:log_3:6)
Block(-6,2,-1,biomesoplenty:log_3:6)
Block(-5,2,-1,biomesoplenty:log_3:6)
Block(-4,2,-1,biomesoplenty:log_3:6)
Block(-3,2,-1,biomesoplenty:log_3:6)
Block(-2,2,-1,biomesoplenty:log_3:6)
Block(-1,2,-1,biomesoplenty:log_3:6)
Block(0,2,-1,biomesoplenty:log_3:6)
Block(1,2,-1,biomesoplenty:log_3:6)
Block(2,2,-1,biomesoplenty:log_3:6)
Block(3,2,-1,biomesoplenty:log_3:6)
Block(4,2,-1,biomesoplenty:log_3:6)
Block(-5,2,0,biomesoplenty:log_3:6)
Block(-4,2,0,biomesoplenty:log_3:6)
Block(-3,2,0,biomesoplenty:log_3:6)
Block(-2,2,0,biomesoplenty:log_3:6)
Block(-1,2,0,biomesoplenty:log_3:6)
Block(0,2,0,biomesoplenty:log_3:6)
Block(1,2,0,biomesoplenty:log_3:6)
Block(2,2,0,biomesoplenty:log_3:6)
Block(-4,2,1,biomesoplenty:log_3:6)
Block(-3,2,1,biomesoplenty:log_3:6)
Block(-2,2,1,biomesoplenty:log_3:6)
Block(-1,2,1,biomesoplenty:log_3:6)
Block(0,2,1,biomesoplenty:log_3:6)
Block(1,2,1,biomesoplenty:log_3:6)
Block(-1,2,2,biomesoplenty:log_3:6)
Block(0,2,2,biomesoplenty:log_3:6)
Block(-2,3,-6,biomesoplenty:log_3:6)
Block(-1,3,-6,biomesoplenty:log_3:6)
Block(0,3,-6,biomesoplenty:log_3:6)
Block(-3,3,-5,biomesoplenty:log_3:6)
Block(-2,3,-5,biomesoplenty:log_3:6)
Block(-1,3,-5,biomesoplenty:log_3:6)
Block(0,3,-5,biomesoplenty:log_3:6)
Block(1,3,-5,biomesoplenty:log_3:6)
Block(-4,3,-4,biomesoplenty:log_3:6)
Block(-3,3,-4,biomesoplenty:log_3:6)
Block(-2,3,-4,biomesoplenty:log_3:6)
Block(-1,3,-4,biomesoplenty:log_3:6)
Block(0,3,-4,biomesoplenty:log_3:6)
Block(1,3,-4,biomesoplenty:log_3:6)
Block(2,3,-4,biomesoplenty:log_3:6)
Block(-4,3,-3,biomesoplenty:log_3:6)
Block(-3,3,-3,biomesoplenty:log_3:6)
Block(-2,3,-3,biomesoplenty:log_3:6)
Block(-1,3,-3,biomesoplenty:log_3:6)
Block(0,3,-3,biomesoplenty:log_3:6)
Block(1,3,-3,biomesoplenty:log_3:6)
Block(2,3,-3,biomesoplenty:log_3:6)
Block(-4,3,-2,biomesoplenty:log_3:6)
Block(-3,3,-2,biomesoplenty:log_3:6)
Block(-2,3,-2,biomesoplenty:log_3:6)
Block(-1,3,-2,biomesoplenty:log_3:6)
Block(0,3,-2,biomesoplenty:log_3:6)
Block(1,3,-2,biomesoplenty:log_3:6)
Block(2,3,-2,biomesoplenty:log_3:6)
Block(-3,3,-1,biomesoplenty:log_3:6)
Block(-2,3,-1,biomesoplenty:log_3:6)
Block(-1,3,-1,biomesoplenty:log_3:6)
Block(0,3,-1,biomesoplenty:log_3:6)
Block(1,3,-1,biomesoplenty:log_3:6)
Block(-2,3,0,biomesoplenty:log_3:6)
Block(-1,3,0,biomesoplenty:log_3:6)
Block(0,3,0,biomesoplenty:log_3:6)
Block(-2,4,-5,biomesoplenty:log_3:6)
Block(-1,4,-5,biomesoplenty:log_3:6)
Block(0,4,-5,biomesoplenty:log_3:6)
Block(1,4,-5,biomesoplenty:log_3:6)
Block(-3,4,-4,biomesoplenty:log_3:6)
Block(-2,4,-4,biomesoplenty:log_3:6)
Block(-1,4,-4,biomesoplenty:log_3:6)
Block(0,4,-4,biomesoplenty:log_3:6)
Block(1,4,-4,biomesoplenty:log_3:6)
Block(-3,4,-3,biomesoplenty:log_3:6)
Block(-2,4,-3,biomesoplenty:log_3:6)
Block(-1,4,-3,biomesoplenty:log_3:6)
Block(0,4,-3,biomesoplenty:log_3:6)
Block(1,4,-3,biomesoplenty:log_3:6)
Block(-3,4,-2,biomesoplenty:log_3:6)
Block(-2,4,-2,biomesoplenty:log_3:6)
Block(-1,4,-2,biomesoplenty:log_3:6)
Block(0,4,-2,biomesoplenty:log_3:6)
Block(1,4,-2,biomesoplenty:log_3:6)
Block(-3,4,-1,biomesoplenty:log_3:6)
Block(-2,4,-1,biomesoplenty:log_3:6)
Block(-1,4,-1,biomesoplenty:log_3:6)
Block(0,4,-1,biomesoplenty:log_3:6)
Block(1,4,-1,biomesoplenty:log_3:6)
Block(0,4,0,biomesoplenty:log_3:6)
Block(-2,5,-4,biomesoplenty:log_3:6)
Block(-1,5,-4,biomesoplenty:log_3:6)
Block(0,5,-4,biomesoplenty:log_3:6)
Block(1,5,-4,biomesoplenty:log_3:6)
Block(-2,5,-3,biomesoplenty:log_3:6)
Block(-1,5,-3,biomesoplenty:log_3:6)
Block(0,5,-3,biomesoplenty:log_3:6)
Block(1,5,-3,biomesoplenty:log_3:6)
Block(-2,5,-2,biomesoplenty:log_3:6)
Block(-1,5,-2,biomesoplenty:log_3:6)
Block(0,5,-2,biomesoplenty:log_3:6)
Block(1,5,-2,biomesoplenty:log_3:6)
Block(-1,5,-1,biomesoplenty:log_3:6)
Block(0,5,-1,biomesoplenty:log_3:6)
Block(1,5,-1,biomesoplenty:log_3:6)
Block(0,5,0,biomesoplenty:log_3:6)
Block(1,5,0,biomesoplenty:log_3:6)
Block(0,6,-4,biomesoplenty:log_3:6)
Block(-1,6,-3,biomesoplenty:log_3:6)
Block(0,6,-3,biomesoplenty:log_3:6)
Block(1,6,-3,biomesoplenty:log_3:6)
Block(-1,6,-2,biomesoplenty:log_3:6)
Block(0,6,-2,biomesoplenty:log_3:6)
Block(1,6,-2,biomesoplenty:log_3:6)
Block(-1,6,-1,biomesoplenty:log_3:6)
Block(0,6,-1,biomesoplenty:log_3:6)
Block(1,6,-1,biomesoplenty:log_3:6)
Block(0,6,0,biomesoplenty:log_3:6)
Block(1,6,0,biomesoplenty:log_3:6)
Block(-1,7,-3,biomesoplenty:log_3:6)
Block(0,7,-3,biomesoplenty:log_3:6)
Block(1,7,-3,biomesoplenty:log_3:6)
Block(-1,7,-2,biomesoplenty:log_3:6)
Block(0,7,-2,biomesoplenty:log_3:6)
Block(1,7,-2,biomesoplenty:log_3:6)
Block(-1,7,-1,biomesoplenty:log_3:6)
Block(0,7,-1,biomesoplenty:log_3:6)
Block(1,7,-1,biomesoplenty:log_3:6)
Block(2,7,-1,biomesoplenty:log_3:6)
Block(0,7,0,biomesoplenty:log_3:6)
Block(1,7,0,biomesoplenty:log_3:6)
Block(-1,8,-3,biomesoplenty:log_3:6)
Block(0,8,-3,biomesoplenty:log_3:6)
Block(1,8,-3,biomesoplenty:log_3:6)
Block(-1,8,-2,biomesoplenty:log_3:6)
Block(0,8,-2,biomesoplenty:log_3:6)
Block(1,8,-2,biomesoplenty:log_3:6)
Block(2,8,-2,biomesoplenty:log_3:6)
Block(-1,8,-1,biomesoplenty:log_3:6)
Block(0,8,-1,biomesoplenty:log_3:6)
Block(1,8,-1,biomesoplenty:log_3:6)
Block(2,8,-1,biomesoplenty:log_3:6)
Block(0,8,0,biomesoplenty:log_3:6)
Block(1,8,0,biomesoplenty:log_3:6)
Block(2,8,0,biomesoplenty:log_3:6)
Block(0,9,-3,biomesoplenty:log_3:6)
Block(-1,9,-2,biomesoplenty:log_3:6)
Block(0,9,-2,biomesoplenty:log_3:6)
Block(1,9,-2,biomesoplenty:log_3:6)
Block(0,9,-1,biomesoplenty:log_3:6)
Block(1,9,-1,biomesoplenty:log_3:6)
Block(2,9,-1,biomesoplenty:log_3:6)
Block(0,9,0,biomesoplenty:log_3:6)
Block(1,9,0,biomesoplenty:log_3:6)
Block(2,9,0,biomesoplenty:log_3:6)
Block(1,9,1,biomesoplenty:log_3:6)
Block(1,10,-3,biomesoplenty:leaves_5:10)
Block(2,10,-3,biomesoplenty:leaves_5:10)
Block(0,10,-2,biomesoplenty:log_3:6)
Block(1,10,-2,biomesoplenty:log_3:6)
Block(2,10,-2,biomesoplenty:leaves_5:10)
Block(3,10,-2,biomesoplenty:leaves_5:10)
Block(0,10,-1,biomesoplenty:log_3:6)
Block(1,10,-1,biomesoplenty:log_3:6)
Block(2,10,-1,biomesoplenty:log_3:6)
Block(0,10,0,biomesoplenty:log_3:6)
Block(1,10,0,biomesoplenty:log_3:6)
Block(2,10,0,biomesoplenty:log_3:6)
Block(0,10,1,biomesoplenty:log_3:6)
Block(1,10,1,biomesoplenty:log_3:6)
Block(2,11,-4,biomesoplenty:leaves_5:10)
Block(3,11,-4,biomesoplenty:leaves_5:10)
Block(-1,11,-3,biomesoplenty:leaves_5:10)
Block(0,11,-3,biomesoplenty:leaves_5:10)
Block(1,11,-3,biomesoplenty:leaves_5:10)
Block(2,11,-3,biomesoplenty:leaves_5:10)
Block(3,11,-3,biomesoplenty:leaves_5:10)
Block(4,11,-3,biomesoplenty:leaves_5:10)
Block(-2,11,-2,biomesoplenty:leaves_5:10)
Block(-1,11,-2,biomesoplenty:leaves_5:10)
Block(0,11,-2,biomesoplenty:log_3:6)
Block(1,11,-2,biomesoplenty:log_3:6)
Block(2,11,-2,biomesoplenty:leaves_5:10)
Block(3,11,-2,biomesoplenty:leaves_5:10)
Block(4,11,-2,biomesoplenty:leaves_5:10)
Block(-1,11,-1,biomesoplenty:leaves_5:10)
Block(0,11,-1,biomesoplenty:log_3:6)
Block(1,11,-1,biomesoplenty:log_3:6)
Block(2,11,-1,biomesoplenty:log_3:6)
Block(3,11,-1,biomesoplenty:leaves_5:10)
Block(4,11,-1,biomesoplenty:leaves_5:10)
Block(0,11,0,biomesoplenty:log_3:6)
Block(1,11,0,biomesoplenty:log_3:6)
Block(2,11,0,biomesoplenty:log_3:6)
Block(3,11,0,biomesoplenty:leaves_5:10)
Block(0,11,1,biomesoplenty:log_3:6)
Block(1,11,1,biomesoplenty:log_3:6)
Block(2,11,1,biomesoplenty:log_3:6)
Block(3,11,1,biomesoplenty:leaves_5:10)
Block(4,11,1,biomesoplenty:leaves_5:10)
Block(2,11,2,biomesoplenty:leaves_5:10)
Block(3,11,2,biomesoplenty:leaves_5:10)
Block(4,11,2,biomesoplenty:leaves_5:10)
Block(3,11,3,biomesoplenty:leaves_5:10)
Block(4,11,3,biomesoplenty:leaves_5:10)
Block(-2,12,-7,biomesoplenty:leaves_5:10)
Block(-3,12,-6,biomesoplenty:leaves_5:10)
Block(-2,12,-6,biomesoplenty:leaves_5:10)
Block(-1,12,-6,biomesoplenty:leaves_5:10)
Block(-5,12,-5,biomesoplenty:leaves_5:10)
Block(-4,12,-5,biomesoplenty:leaves_5:10)
Block(-3,12,-5,biomesoplenty:leaves_5:10)
Block(-2,12,-5,biomesoplenty:leaves_5:10)
Block(1,12,-5,biomesoplenty:leaves_5:10)
Block(2,12,-5,biomesoplenty:leaves_5:10)
Block(3,12,-5,biomesoplenty:leaves_5:10)
Block(-4,12,-4,biomesoplenty:leaves_5:10)
Block(-3,12,-4,biomesoplenty:leaves_5:10)
Block(-1,12,-4,biomesoplenty:leaves_5:10)
Block(0,12,-4,biomesoplenty:leaves_5:10)
Block(1,12,-4,biomesoplenty:leaves_5:10)
Block(2,12,-4,biomesoplenty:leaves_5:10)
Block(3,12,-4,biomesoplenty:leaves_5:10)
Block(-5,12,-3,biomesoplenty:leaves_5:10)
Block(-4,12,-3,biomesoplenty:leaves_5:10)
Block(-1,12,-3,biomesoplenty:leaves_5:10)
Block(1,12,-3,biomesoplenty:leaves_5:10)
Block(2,12,-3,biomesoplenty:leaves_5:10)
Block(3,12,-3,biomesoplenty:leaves_5:10)
Block(4,12,-3,biomesoplenty:leaves_5:10)
Block(-5,12,-2,biomesoplenty:leaves_5:10)
Block(-4,12,-2,biomesoplenty:leaves_5:10)
Block(-3,12,-2,biomesoplenty:leaves_5:10)
Block(-2,12,-2,biomesoplenty:leaves_5:10)
Block(-1,12,-2,biomesoplenty:leaves_5:10)
Block(0,12,-2,biomesoplenty:log_3:6)
Block(1,12,-2,biomesoplenty:leaves_5:10)
Block(2,12,-2,biomesoplenty:leaves_5:10)
Block(3,12,-2,biomesoplenty:leaves_5:10)
Block(4,12,-2,biomesoplenty:leaves_5:10)
Block(-4,12,-1,biomesoplenty:leaves_5:10)
Block(-3,12,-1,biomesoplenty:leaves_5:10)
Block(-1,12,-1,biomesoplenty:leaves_5:10)
Block(0,12,-1,biomesoplenty:log_3:6)
Block(1,12,-1,biomesoplenty:log_3:6)
Block(2,12,-1,biomesoplenty:log_3:6)
Block(3,12,-1,biomesoplenty:leaves_5:10)
Block(4,12,-1,biomesoplenty:leaves_5:10)
Block(-1,12,0,biomesoplenty:leaves_5:10)
Block(0,12,0,biomesoplenty:log_3:6)
Block(1,12,0,biomesoplenty:log_3:6)
Block(2,12,0,biomesoplenty:log_3:6)
Block(3,12,0,biomesoplenty:leaves_5:10)
Block(4,12,0,biomesoplenty:leaves_5:10)
Block(0,12,1,biomesoplenty:log_3:6)
Block(1,12,1,biomesoplenty:log_3:6)
Block(2,12,1,biomesoplenty:log_3:6)
Block(5,12,1,biomesoplenty:leaves_5:10)
Block(1,12,2,biomesoplenty:leaves_5:10)
Block(3,12,2,biomesoplenty:leaves_5:10)
Block(4,12,2,biomesoplenty:leaves_5:10)
Block(5,12,2,biomesoplenty:leaves_5:10)
Block(1,12,3,biomesoplenty:leaves_5:10)
Block(3,12,3,biomesoplenty:leaves_5:10)
Block(4,12,3,biomesoplenty:leaves_5:10)
Block(4,12,4,biomesoplenty:leaves_5:10)
Block(-1,13,-8,biomesoplenty:leaves_5:10)
Block(-4,13,-7,biomesoplenty:leaves_5:10)
Block(-3,13,-7,biomesoplenty:leaves_5:10)
Block(-2,13,-7,biomesoplenty:leaves_5:10)
Block(-4,13,-6,biomesoplenty:leaves_5:10)
Block(-2,13,-6,biomesoplenty:leaves_5:10)
Block(1,13,-6,biomesoplenty:leaves_5:10)
Block(-6,13,-5,biomesoplenty:leaves_5:10)
Block(-4,13,-5,biomesoplenty:leaves_5:10)
Block(-3,13,-5,biomesoplenty:leaves_5:10)
Block(-2,13,-5,biomesoplenty:leaves_5:10)
Block(0,13,-5,biomesoplenty:leaves_5:10)
Block(2,13,-5,biomesoplenty:leaves_5:10)
Block(4,13,-5,biomesoplenty:leaves_5:10)
Block(-6,13,-4,biomesoplenty:leaves_5:10)
Block(-5,13,-4,biomesoplenty:leaves_5:10)
Block(-4,13,-4,biomesoplenty:leaves_5:10)
Block(-3,13,-4,biomesoplenty:leaves_5:10)
Block(-2,13,-4,biomesoplenty:leaves_5:10)
Block(-1,13,-4,biomesoplenty:leaves_5:10)
Block(0,13,-4,biomesoplenty:leaves_5:10)
Block(1,13,-4,biomesoplenty:leaves_5:10)
Block(2,13,-4,biomesoplenty:leaves_5:10)
Block(3,13,-4,biomesoplenty:leaves_5:10)
Block(4,13,-4,biomesoplenty:leaves_5:10)
Block(-6,13,-3,biomesoplenty:leaves_5:10)
Block(-5,13,-3,biomesoplenty:leaves_5:10)
Block(-4,13,-3,biomesoplenty:leaves_5:10)
Block(-3,13,-3,biomesoplenty:leaves_5:10)
Block(-2,13,-3,biomesoplenty:leaves_5:10)
Block(-1,13,-3,biomesoplenty:leaves_5:10)
Block(0,13,-3,biomesoplenty:leaves_5:10)
Block(1,13,-3,biomesoplenty:leaves_5:10)
Block(2,13,-3,biomesoplenty:leaves_5:10)
Block(3,13,-3,biomesoplenty:leaves_5:10)
Block(4,13,-3,biomesoplenty:leaves_5:10)
Block(-6,13,-2,biomesoplenty:leaves_5:10)
Block(-5,13,-2,biomesoplenty:leaves_5:10)
Block(-4,13,-2,biomesoplenty:leaves_5:10)
Block(-3,13,-2,biomesoplenty:leaves_5:10)
Block(-2,13,-2,biomesoplenty:leaves_5:10)
Block(-1,13,-2,biomesoplenty:leaves_5:10)
Block(0,13,-2,biomesoplenty:leaves_5:10)
Block(1,13,-2,biomesoplenty:leaves_5:10)
Block(2,13,-2,biomesoplenty:leaves_5:10)
Block(3,13,-2,biomesoplenty:leaves_5:10)
Block(4,13,-2,biomesoplenty:leaves_5:10)
Block(5,13,-2,biomesoplenty:leaves_5:10)
Block(-6,13,-1,biomesoplenty:leaves_5:10)
Block(-5,13,-1,biomesoplenty:leaves_5:10)
Block(-4,13,-1,biomesoplenty:leaves_5:10)
Block(-3,13,-1,biomesoplenty:leaves_5:10)
Block(-2,13,-1,biomesoplenty:leaves_5:10)
Block(-1,13,-1,biomesoplenty:leaves_5:10)
Block(0,13,-1,biomesoplenty:log_3:6)
Block(1,13,-1,biomesoplenty:log_3:6)
Block(2,13,-1,biomesoplenty:log_3:6)
Block(3,13,-1,biomesoplenty:leaves_5:10)
Block(4,13,-1,biomesoplenty:leaves_5:10)
Block(5,13,-1,biomesoplenty:leaves_5:10)
Block(-6,13,0,biomesoplenty:leaves_5:10)
Block(-5,13,0,biomesoplenty:leaves_5:10)
Block(-4,13,0,biomesoplenty:leaves_5:10)
Block(-3,13,0,biomesoplenty:leaves_5:10)
Block(-2,13,0,biomesoplenty:leaves_5:10)
Block(-1,13,0,biomesoplenty:leaves_5:10)
Block(0,13,0,biomesoplenty:log_3:6)
Block(1,13,0,biomesoplenty:log_3:6)
Block(2,13,0,biomesoplenty:log_3:6)
Block(3,13,0,biomesoplenty:log_3:6)
Block(4,13,0,biomesoplenty:leaves_5:10)
Block(5,13,0,biomesoplenty:leaves_5:10)
Block(-6,13,1,biomesoplenty:leaves_5:10)
Block(-5,13,1,biomesoplenty:leaves_5:10)
Block(-4,13,1,biomesoplenty:leaves_5:10)
Block(0,13,1,biomesoplenty:log_3:6)
Block(1,13,1,biomesoplenty:log_3:6)
Block(2,13,1,biomesoplenty:log_3:6)
Block(3,13,1,biomesoplenty:leaves_5:10)
Block(4,13,1,biomesoplenty:leaves_5:10)
Block(5,13,1,biomesoplenty:leaves_5:10)
Block(-4,13,2,biomesoplenty:leaves_5:10)
Block(0,13,2,biomesoplenty:leaves_5:10)
Block(1,13,2,biomesoplenty:leaves_5:10)
Block(2,13,2,biomesoplenty:leaves_5:10)
Block(3,13,2,biomesoplenty:leaves_5:10)
Block(4,13,2,biomesoplenty:leaves_5:10)
Block(5,13,2,biomesoplenty:leaves_5:10)
Block(0,13,3,biomesoplenty:leaves_5:10)
Block(1,13,3,biomesoplenty:leaves_5:10)
Block(2,13,3,biomesoplenty:leaves_5:10)
Block(3,13,3,biomesoplenty:leaves_5:10)
Block(4,13,3,biomesoplenty:leaves_5:10)
Block(5,13,3,biomesoplenty:leaves_5:10)
Block(2,13,4,biomesoplenty:leaves_5:10)
Block(3,13,4,biomesoplenty:leaves_5:10)
Block(4,13,4,biomesoplenty:leaves_5:10)
Block(-8,14,-11,biomesoplenty:leaves_5:10)
Block(-7,14,-11,biomesoplenty:leaves_5:10)
Block(-8,14,-10,biomesoplenty:leaves_5:10)
Block(-7,14,-10,biomesoplenty:leaves_5:10)
Block(-6,14,-10,biomesoplenty:leaves_5:10)
Block(-5,14,-10,biomesoplenty:leaves_5:10)
Block(-4,14,-10,biomesoplenty:leaves_5:10)
Block(-8,14,-9,biomesoplenty:leaves_5:10)
Block(-7,14,-9,biomesoplenty:leaves_5:10)
Block(-6,14,-9,biomesoplenty:leaves_5:10)
Block(-5,14,-9,biomesoplenty:leaves_5:10)
Block(-4,14,-9,biomesoplenty:leaves_5:10)
Block(-2,14,-9,biomesoplenty:leaves_5:10)
Block(-1,14,-9,biomesoplenty:leaves_5:10)
Block(-6,14,-8,biomesoplenty:leaves_5:10)
Block(-5,14,-8,biomesoplenty:leaves_5:10)
Block(-4,14,-8,biomesoplenty:leaves_5:10)
Block(-3,14,-8,biomesoplenty:leaves_5:10)
Block(-2,14,-8,biomesoplenty:leaves_5:10)
Block(-1,14,-8,biomesoplenty:leaves_5:10)
Block(0,14,-8,biomesoplenty:leaves_5:10)
Block(1,14,-8,biomesoplenty:leaves_5:10)
Block(2,14,-8,biomesoplenty:leaves_5:10)
Block(-5,14,-7,biomesoplenty:leaves_5:10)
Block(-4,14,-7,biomesoplenty:leaves_5:10)
Block(-3,14,-7,biomesoplenty:leaves_5:10)
Block(-2,14,-7,biomesoplenty:leaves_5:10)
Block(-1,14,-7,biomesoplenty:leaves_5:10)
Block(0,14,-7,biomesoplenty:leaves_5:10)
Block(1,14,-7,biomesoplenty:leaves_5:10)
Block(2,14,-7,biomesoplenty:leaves_5:10)
Block(-6,14,-6,biomesoplenty:leaves_5:10)
Block(-5,14,-6,biomesoplenty:leaves_5:10)
Block(-4,14,-6,biomesoplenty:leaves_5:10)
Block(-3,14,-6,biomesoplenty:leaves_5:10)
Block(-2,14,-6,biomesoplenty:leaves_5:10)
Block(-1,14,-6,biomesoplenty:leaves_5:10)
Block(0,14,-6,biomesoplenty:leaves_5:10)
Block(1,14,-6,biomesoplenty:leaves_5:10)
Block(2,14,-6,biomesoplenty:leaves_5:10)
Block(3,14,-6,biomesoplenty:leaves_5:10)
Block(-6,14,-5,biomesoplenty:leaves_5:10)
Block(-5,14,-5,biomesoplenty:leaves_5:10)
Block(-4,14,-5,biomesoplenty:leaves_5:10)
Block(-3,14,-5,biomesoplenty:leaves_5:10)
Block(-2,14,-5,biomesoplenty:leaves_5:10)
Block(-1,14,-5,biomesoplenty:leaves_5:10)
Block(0,14,-5,biomesoplenty:leaves_5:10)
Block(1,14,-5,biomesoplenty:leaves_5:10)
Block(2,14,-5,biomesoplenty:leaves_5:10)
Block(3,14,-5,biomesoplenty:leaves_5:10)
Block(4,14,-5,biomesoplenty:leaves_5:10)
Block(-6,14,-4,biomesoplenty:leaves_5:10)
Block(-5,14,-4,biomesoplenty:leaves_5:10)
Block(-4,14,-4,biomesoplenty:leaves_5:10)
Block(-3,14,-4,biomesoplenty:leaves_5:10)
Block(-2,14,-4,biomesoplenty:leaves_5:10)
Block(-1,14,-4,biomesoplenty:leaves_5:10)
Block(0,14,-4,biomesoplenty:leaves_5:10)
Block(1,14,-4,biomesoplenty:leaves_5:10)
Block(2,14,-4,biomesoplenty:leaves_5:10)
Block(3,14,-4,biomesoplenty:leaves_5:10)
Block(4,14,-4,biomesoplenty:leaves_5:10)
Block(5,14,-4,biomesoplenty:leaves_5:10)
Block(6,14,-4,biomesoplenty:leaves_5:10)
Block(-6,14,-3,biomesoplenty:leaves_5:10)
Block(-5,14,-3,biomesoplenty:leaves_5:10)
Block(-4,14,-3,biomesoplenty:leaves_5:10)
Block(-3,14,-3,biomesoplenty:leaves_5:10)
Block(-2,14,-3,biomesoplenty:leaves_5:10)
Block(-1,14,-3,biomesoplenty:leaves_5:10)
Block(0,14,-3,biomesoplenty:leaves_5:10)
Block(1,14,-3,biomesoplenty:leaves_5:10)
Block(2,14,-3,biomesoplenty:leaves_5:10)
Block(3,14,-3,biomesoplenty:leaves_5:10)
Block(4,14,-3,biomesoplenty:leaves_5:10)
Block(5,14,-3,biomesoplenty:leaves_5:10)
Block(6,14,-3,biomesoplenty:leaves_5:10)
Block(-7,14,-2,biomesoplenty:leaves_5:10)
Block(-6,14,-2,biomesoplenty:leaves_5:10)
Block(-5,14,-2,biomesoplenty:leaves_5:10)
Block(-4,14,-2,biomesoplenty:leaves_5:10)
Block(-3,14,-2,biomesoplenty:leaves_5:10)
Block(-2,14,-2,biomesoplenty:leaves_5:10)
Block(-1,14,-2,biomesoplenty:leaves_5:10)
Block(0,14,-2,biomesoplenty:leaves_5:10)
Block(1,14,-2,biomesoplenty:leaves_5:10)
Block(2,14,-2,biomesoplenty:leaves_5:10)
Block(3,14,-2,biomesoplenty:leaves_5:10)
Block(4,14,-2,biomesoplenty:leaves_5:10)
Block(5,14,-2,biomesoplenty:leaves_5:10)
Block(6,14,-2,biomesoplenty:leaves_5:10)
Block(-9,14,-1,biomesoplenty:leaves_5:10)
Block(-8,14,-1,biomesoplenty:leaves_5:10)
Block(-6,14,-1,biomesoplenty:leaves_5:10)
Block(-5,14,-1,biomesoplenty:leaves_5:10)
Block(-4,14,-1,biomesoplenty:leaves_5:10)
Block(-3,14,-1,biomesoplenty:leaves_5:10)
Block(-2,14,-1,biomesoplenty:leaves_5:10)
Block(-1,14,-1,biomesoplenty:leaves_5:10)
Block(0,14,-1,biomesoplenty:leaves_5:10)
Block(1,14,-1,biomesoplenty:log_3:6)
Block(2,14,-1,biomesoplenty:log_3:6)
Block(3,14,-1,biomesoplenty:log_3:6)
Block(4,14,-1,biomesoplenty:leaves_5:10)
Block(5,14,-1,biomesoplenty:leaves_5:10)
Block(-10,14,0,biomesoplenty:leaves_5:10)
Block(-9,14,0,biomesoplenty:leaves_5:10)
Block(-8,14,0,biomesoplenty:leaves_5:10)
Block(-7,14,0,biomesoplenty:leaves_5:10)
Block(-6,14,0,biomesoplenty:leaves_5:10)
Block(-5,14,0,biomesoplenty:leaves_5:10)
Block(-4,14,0,biomesoplenty:leaves_5:10)
Block(-3,14,0,biomesoplenty:leaves_5:10)
Block(-2,14,0,biomesoplenty:leaves_5:10)
Block(-1,14,0,biomesoplenty:leaves_5:10)
Block(0,14,0,biomesoplenty:log_3:6)
Block(1,14,0,biomesoplenty:log_3:6)
Block(2,14,0,biomesoplenty:log_3:6)
Block(3,14,0,biomesoplenty:log_3:6)
Block(4,14,0,biomesoplenty:log_3:6)
Block(5,14,0,biomesoplenty:leaves_5:10)
Block(-9,14,1,biomesoplenty:leaves_5:10)
Block(-7,14,1,biomesoplenty:leaves_5:10)
Block(-5,14,1,biomesoplenty:leaves_5:10)
Block(-4,14,1,biomesoplenty:leaves_5:10)
Block(-2,14,1,biomesoplenty:leaves_5:10)
Block(-1,14,1,biomesoplenty:leaves_5:10)
Block(0,14,1,biomesoplenty:leaves_5:10)
Block(1,14,1,biomesoplenty:log_3:6)
Block(2,14,1,biomesoplenty:log_3:6)
Block(3,14,1,biomesoplenty:log_3:6)
Block(4,14,1,biomesoplenty:leaves_5:10)
Block(5,14,1,biomesoplenty:leaves_5:10)
Block(-7,14,2,biomesoplenty:leaves_5:10)
Block(-6,14,2,biomesoplenty:leaves_5:10)
Block(-5,14,2,biomesoplenty:leaves_5:10)
Block(-3,14,2,biomesoplenty:leaves_5:10)
Block(-1,14,2,biomesoplenty:leaves_5:10)
Block(0,14,2,biomesoplenty:leaves_5:10)
Block(1,14,2,biomesoplenty:leaves_5:10)
Block(2,14,2,biomesoplenty:log_3:6)
Block(3,14,2,biomesoplenty:leaves_5:10)
Block(4,14,2,biomesoplenty:leaves_5:10)
Block(5,14,2,biomesoplenty:leaves_5:10)
Block(-5,14,3,biomesoplenty:leaves_5:10)
Block(-4,14,3,biomesoplenty:leaves_5:10)
Block(-3,14,3,biomesoplenty:leaves_5:10)
Block(-2,14,3,biomesoplenty:leaves_5:10)
Block(-1,14,3,biomesoplenty:leaves_5:10)
Block(0,14,3,biomesoplenty:leaves_5:10)
Block(1,14,3,biomesoplenty:leaves_5:10)
Block(2,14,3,biomesoplenty:leaves_5:10)
Block(3,14,3,biomesoplenty:leaves_5:10)
Block(4,14,3,biomesoplenty:leaves_5:10)
Block(5,14,3,biomesoplenty:leaves_5:10)
Block(-3,14,4,biomesoplenty:leaves_5:10)
Block(-2,14,4,biomesoplenty:leaves_5:10)
Block(0,14,4,biomesoplenty:leaves_5:10)
Block(1,14,4,biomesoplenty:leaves_5:10)
Block(2,14,4,biomesoplenty:leaves_5:10)
Block(3,14,4,biomesoplenty:leaves_5:10)
Block(4,14,4,biomesoplenty:leaves_5:10)
Block(5,14,4,biomesoplenty:leaves_5:10)
Block(-3,14,5,biomesoplenty:leaves_5:10)
Block(-1,14,5,biomesoplenty:leaves_5:10)
Block(0,14,5,biomesoplenty:leaves_5:10)
Block(1,14,5,biomesoplenty:leaves_5:10)
Block(2,14,5,biomesoplenty:leaves_5:10)
Block(3,14,5,biomesoplenty:leaves_5:10)
Block(4,14,5,biomesoplenty:leaves_5:10)
Block(-3,14,6,biomesoplenty:leaves_5:10)
Block(-2,14,6,biomesoplenty:leaves_5:10)
Block(-1,14,6,biomesoplenty:leaves_5:10)
Block(0,14,6,biomesoplenty:leaves_5:10)
Block(1,14,6,biomesoplenty:leaves_5:10)
Block(2,14,6,biomesoplenty:leaves_5:10)
Block(-2,14,7,biomesoplenty:leaves_5:10)
Block(-1,14,7,biomesoplenty:leaves_5:10)
Block(1,14,7,biomesoplenty:leaves_5:10)
Block(2,14,7,biomesoplenty:leaves_5:10)
Block(-8,15,-12,biomesoplenty:leaves_5:10)
Block(-7,15,-12,biomesoplenty:leaves_5:10)
Block(-6,15,-12,biomesoplenty:leaves_5:10)
Block(-9,15,-11,biomesoplenty:leaves_5:10)
Block(-8,15,-11,biomesoplenty:leaves_5:10)
Block(-7,15,-11,biomesoplenty:leaves_5:10)
Block(-6,15,-11,biomesoplenty:leaves_5:10)
Block(-5,15,-11,biomesoplenty:leaves_5:10)
Block(-4,15,-11,biomesoplenty:leaves_5:10)
Block(2,15,-11,biomesoplenty:leaves_5:10)
Block(3,15,-11,biomesoplenty:leaves_5:10)
Block(-9,15,-10,biomesoplenty:leaves_5:10)
Block(-8,15,-10,biomesoplenty:leaves_5:10)
Block(-7,15,-10,biomesoplenty:leaves_5:10)
Block(-6,15,-10,biomesoplenty:leaves_5:10)
Block(-5,15,-10,biomesoplenty:leaves_5:10)
Block(-4,15,-10,biomesoplenty:leaves_5:10)
Block(-3,15,-10,biomesoplenty:leaves_5:10)
Block(-1,15,-10,biomesoplenty:leaves_5:10)
Block(2,15,-10,biomesoplenty:leaves_5:10)
Block(3,15,-10,biomesoplenty:leaves_5:10)
Block(4,15,-10,biomesoplenty:leaves_5:10)
Block(-9,15,-9,biomesoplenty:leaves_5:10)
Block(-8,15,-9,biomesoplenty:leaves_5:10)
Block(-7,15,-9,biomesoplenty:leaves_5:10)
Block(-6,15,-9,biomesoplenty:leaves_5:10)
Block(-5,15,-9,biomesoplenty:leaves_5:10)
Block(-4,15,-9,biomesoplenty:leaves_5:10)
Block(-3,15,-9,biomesoplenty:leaves_5:10)
Block(0,15,-9,biomesoplenty:leaves_5:10)
Block(1,15,-9,biomesoplenty:leaves_5:10)
Block(2,15,-9,biomesoplenty:leaves_5:10)
Block(3,15,-9,biomesoplenty:leaves_5:10)
Block(-10,15,-8,biomesoplenty:leaves_5:10)
Block(-9,15,-8,biomesoplenty:leaves_5:10)
Block(-8,15,-8,biomesoplenty:leaves_5:10)
Block(-7,15,-8,biomesoplenty:leaves_5:10)
Block(-6,15,-8,biomesoplenty:leaves_5:10)
Block(-5,15,-8,biomesoplenty:leaves_5:10)
Block(-4,15,-8,biomesoplenty:leaves_5:10)
Block(-3,15,-8,biomesoplenty:leaves_5:10)
Block(-2,15,-8,biomesoplenty:leaves_5:10)
Block(-1,15,-8,biomesoplenty:leaves_5:10)
Block(0,15,-8,biomesoplenty:leaves_5:10)
Block(1,15,-8,biomesoplenty:leaves_5:10)
Block(2,15,-8,biomesoplenty:leaves_5:10)
Block(3,15,-8,biomesoplenty:leaves_5:10)
Block(-10,15,-7,biomesoplenty:leaves_5:10)
Block(-9,15,-7,biomesoplenty:leaves_5:10)
Block(-8,15,-7,biomesoplenty:leaves_5:10)
Block(-7,15,-7,biomesoplenty:leaves_5:10)
Block(-6,15,-7,biomesoplenty:leaves_5:10)
Block(-5,15,-7,biomesoplenty:leaves_5:10)
Block(-4,15,-7,biomesoplenty:leaves_5:10)
Block(-3,15,-7,biomesoplenty:leaves_5:10)
Block(-2,15,-7,biomesoplenty:leaves_5:10)
Block(-1,15,-7,biomesoplenty:leaves_5:10)
Block(0,15,-7,biomesoplenty:leaves_5:10)
Block(1,15,-7,biomesoplenty:leaves_5:10)
Block(2,15,-7,biomesoplenty:leaves_5:10)
Block(3,15,-7,biomesoplenty:leaves_5:10)
Block(4,15,-7,biomesoplenty:leaves_5:10)
Block(5,15,-7,biomesoplenty:leaves_5:10)
Block(-10,15,-6,biomesoplenty:leaves_5:10)
Block(-9,15,-6,biomesoplenty:leaves_5:10)
Block(-7,15,-6,biomesoplenty:leaves_5:10)
Block(-6,15,-6,biomesoplenty:leaves_5:10)
Block(-5,15,-6,biomesoplenty:leaves_5:10)
Block(-4,15,-6,biomesoplenty:leaves_5:10)
Block(-3,15,-6,biomesoplenty:leaves_5:10)
Block(-2,15,-6,biomesoplenty:leaves_5:10)
Block(-1,15,-6,biomesoplenty:leaves_5:10)
Block(0,15,-6,biomesoplenty:leaves_5:10)
Block(1,15,-6,biomesoplenty:leaves_5:10)
Block(2,15,-6,biomesoplenty:leaves_5:10)
Block(3,15,-6,biomesoplenty:leaves_5:10)
Block(4,15,-6,biomesoplenty:leaves_5:10)
Block(5,15,-6,biomesoplenty:leaves_5:10)
Block(-7,15,-5,biomesoplenty:leaves_5:10)
Block(-6,15,-5,biomesoplenty:leaves_5:10)
Block(-5,15,-5,biomesoplenty:leaves_5:10)
Block(-4,15,-5,biomesoplenty:leaves_5:10)
Block(-3,15,-5,biomesoplenty:leaves_5:10)
Block(-2,15,-5,biomesoplenty:leaves_5:10)
Block(-1,15,-5,biomesoplenty:leaves_5:10)
Block(0,15,-5,biomesoplenty:leaves_5:10)
Block(1,15,-5,biomesoplenty:leaves_5:10)
Block(2,15,-5,biomesoplenty:leaves_5:10)
Block(3,15,-5,biomesoplenty:leaves_5:10)
Block(4,15,-5,biomesoplenty:leaves_5:10)
Block(6,15,-5,biomesoplenty:leaves_5:10)
Block(-10,15,-4,biomesoplenty:leaves_5:10)
Block(-9,15,-4,biomesoplenty:leaves_5:10)
Block(-8,15,-4,biomesoplenty:leaves_5:10)
Block(-7,15,-4,biomesoplenty:leaves_5:10)
Block(-6,15,-4,biomesoplenty:leaves_5:10)
Block(-5,15,-4,biomesoplenty:leaves_5:10)
Block(-4,15,-4,biomesoplenty:leaves_5:10)
Block(-3,15,-4,biomesoplenty:leaves_5:10)
Block(-2,15,-4,biomesoplenty:leaves_5:10)
Block(-1,15,-4,biomesoplenty:leaves_5:10)
Block(0,15,-4,biomesoplenty:leaves_5:10)
Block(1,15,-4,biomesoplenty:leaves_5:10)
Block(2,15,-4,biomesoplenty:log_3:6)
Block(3,15,-4,biomesoplenty:leaves_5:10)
Block(4,15,-4,biomesoplenty:leaves_5:10)
Block(5,15,-4,biomesoplenty:leaves_5:10)
Block(6,15,-4,biomesoplenty:leaves_5:10)
Block(-10,15,-3,biomesoplenty:leaves_5:10)
Block(-9,15,-3,biomesoplenty:leaves_5:10)
Block(-8,15,-3,biomesoplenty:leaves_5:10)
Block(-7,15,-3,biomesoplenty:leaves_5:10)
Block(-6,15,-3,biomesoplenty:leaves_5:10)
Block(-5,15,-3,biomesoplenty:leaves_5:10)
Block(-4,15,-3,biomesoplenty:leaves_5:10)
Block(-3,15,-3,biomesoplenty:leaves_5:10)
Block(-2,15,-3,biomesoplenty:leaves_5:10)
Block(-1,15,-3,biomesoplenty:leaves_5:10)
Block(0,15,-3,biomesoplenty:log_3:6)
Block(1,15,-3,biomesoplenty:log_3:6)
Block(2,15,-3,biomesoplenty:log_3:6)
Block(3,15,-3,biomesoplenty:log_3:6)
Block(4,15,-3,biomesoplenty:leaves_5:10)
Block(5,15,-3,biomesoplenty:leaves_5:10)
Block(6,15,-3,biomesoplenty:leaves_5:10)
Block(7,15,-3,biomesoplenty:leaves_5:10)
Block(8,15,-3,biomesoplenty:leaves_5:10)
Block(-11,15,-2,biomesoplenty:leaves_5:10)
Block(-10,15,-2,biomesoplenty:leaves_5:10)
Block(-9,15,-2,biomesoplenty:leaves_5:10)
Block(-8,15,-2,biomesoplenty:leaves_5:10)
Block(-7,15,-2,biomesoplenty:leaves_5:10)
Block(-6,15,-2,biomesoplenty:leaves_5:10)
Block(-5,15,-2,biomesoplenty:leaves_5:10)
Block(-4,15,-2,biomesoplenty:leaves_5:10)
Block(-3,15,-2,biomesoplenty:leaves_5:10)
Block(-2,15,-2,biomesoplenty:leaves_5:10)
Block(-1,15,-2,biomesoplenty:log_3:6)
Block(0,15,-2,biomesoplenty:log_3:6)
Block(1,15,-2,biomesoplenty:log_3:6)
Block(2,15,-2,biomesoplenty:log_3:6)
Block(3,15,-2,biomesoplenty:log_3:6)
Block(4,15,-2,biomesoplenty:leaves_5:10)
Block(5,15,-2,biomesoplenty:leaves_5:10)
Block(6,15,-2,biomesoplenty:leaves_5:10)
Block(7,15,-2,biomesoplenty:leaves_5:10)
Block(8,15,-2,biomesoplenty:leaves_5:10)
Block(-11,15,-1,biomesoplenty:leaves_5:10)
Block(-9,15,-1,biomesoplenty:leaves_5:10)
Block(-8,15,-1,biomesoplenty:leaves_5:10)
Block(-7,15,-1,biomesoplenty:leaves_5:10)
Block(-6,15,-1,biomesoplenty:leaves_5:10)
Block(-5,15,-1,biomesoplenty:leaves_5:10)
Block(-4,15,-1,biomesoplenty:leaves_5:10)
Block(-3,15,-1,biomesoplenty:leaves_5:10)
Block(-2,15,-1,biomesoplenty:leaves_5:10)
Block(-1,15,-1,biomesoplenty:leaves_5:10)
Block(0,15,-1,biomesoplenty:log_3:6)
Block(1,15,-1,biomesoplenty:log_3:6)
Block(2,15,-1,biomesoplenty:log_3:6)
Block(3,15,-1,biomesoplenty:log_3:6)
Block(4,15,-1,biomesoplenty:log_3:6)
Block(5,15,-1,biomesoplenty:leaves_5:10)
Block(6,15,-1,biomesoplenty:leaves_5:10)
Block(7,15,-1,biomesoplenty:leaves_5:10)
Block(8,15,-1,biomesoplenty:leaves_5:10)
Block(-11,15,0,biomesoplenty:leaves_5:10)
Block(-10,15,0,biomesoplenty:leaves_5:10)
Block(-8,15,0,biomesoplenty:leaves_5:10)
Block(-7,15,0,biomesoplenty:leaves_5:10)
Block(-6,15,0,biomesoplenty:leaves_5:10)
Block(-5,15,0,biomesoplenty:leaves_5:10)
Block(-4,15,0,biomesoplenty:leaves_5:10)
Block(-3,15,0,biomesoplenty:leaves_5:10)
Block(-2,15,0,biomesoplenty:leaves_5:10)
Block(-1,15,0,biomesoplenty:leaves_5:10)
Block(0,15,0,biomesoplenty:log_3:6)
Block(1,15,0,biomesoplenty:log_3:6)
Block(2,15,0,biomesoplenty:log_3:6)
Block(3,15,0,biomesoplenty:log_3:6)
Block(4,15,0,biomesoplenty:log_3:6)
Block(5,15,0,biomesoplenty:leaves_5:10)
Block(6,15,0,biomesoplenty:leaves_5:10)
Block(-11,15,1,biomesoplenty:leaves_5:10)
Block(-10,15,1,biomesoplenty:leaves_5:10)
Block(-9,15,1,biomesoplenty:leaves_5:10)
Block(-8,15,1,biomesoplenty:leaves_5:10)
Block(-7,15,1,biomesoplenty:leaves_5:10)
Block(-6,15,1,biomesoplenty:leaves_5:10)
Block(-5,15,1,biomesoplenty:leaves_5:10)
Block(-4,15,1,biomesoplenty:leaves_5:10)
Block(-3,15,1,biomesoplenty:leaves_5:10)
Block(-2,15,1,biomesoplenty:leaves_5:10)
Block(-1,15,1,biomesoplenty:leaves_5:10)
Block(0,15,1,biomesoplenty:log_3:6)
Block(1,15,1,biomesoplenty:log_3:6)
Block(2,15,1,biomesoplenty:log_3:6)
Block(3,15,1,biomesoplenty:log_3:6)
Block(4,15,1,biomesoplenty:log_3:6)
Block(5,15,1,biomesoplenty:leaves_5:10)
Block(6,15,1,biomesoplenty:leaves_5:10)
Block(9,15,1,biomesoplenty:leaves_5:10)
Block(10,15,1,biomesoplenty:leaves_5:10)
Block(11,15,1,biomesoplenty:leaves_5:10)
Block(-11,15,2,biomesoplenty:leaves_5:10)
Block(-10,15,2,biomesoplenty:leaves_5:10)
Block(-9,15,2,biomesoplenty:leaves_5:10)
Block(-8,15,2,biomesoplenty:leaves_5:10)
Block(-7,15,2,biomesoplenty:leaves_5:10)
Block(-6,15,2,biomesoplenty:leaves_5:10)
Block(-5,15,2,biomesoplenty:leaves_5:10)
Block(-4,15,2,biomesoplenty:leaves_5:10)
Block(-3,15,2,biomesoplenty:leaves_5:10)
Block(-2,15,2,biomesoplenty:leaves_5:10)
Block(-1,15,2,biomesoplenty:leaves_5:10)
Block(0,15,2,biomesoplenty:leaves_5:10)
Block(1,15,2,biomesoplenty:log_3:6)
Block(2,15,2,biomesoplenty:log_3:6)
Block(3,15,2,biomesoplenty:log_3:6)
Block(4,15,2,biomesoplenty:leaves_5:10)
Block(5,15,2,biomesoplenty:leaves_5:10)
Block(6,15,2,biomesoplenty:leaves_5:10)
Block(9,15,2,biomesoplenty:leaves_5:10)
Block(10,15,2,biomesoplenty:leaves_5:10)
Block(11,15,2,biomesoplenty:leaves_5:10)
Block(-9,15,3,biomesoplenty:leaves_5:10)
Block(-8,15,3,biomesoplenty:leaves_5:10)
Block(-7,15,3,biomesoplenty:leaves_5:10)
Block(-5,15,3,biomesoplenty:leaves_5:10)
Block(-3,15,3,biomesoplenty:leaves_5:10)
Block(-1,15,3,biomesoplenty:leaves_5:10)
Block(0,15,3,biomesoplenty:leaves_5:10)
Block(1,15,3,biomesoplenty:leaves_5:10)
Block(2,15,3,biomesoplenty:log_3:6)
Block(3,15,3,biomesoplenty:leaves_5:10)
Block(4,15,3,biomesoplenty:leaves_5:10)
Block(5,15,3,biomesoplenty:leaves_5:10)
Block(9,15,3,biomesoplenty:leaves_5:10)
Block(10,15,3,biomesoplenty:leaves_5:10)
Block(-8,15,4,biomesoplenty:leaves_5:10)
Block(-5,15,4,biomesoplenty:leaves_5:10)
Block(-3,15,4,biomesoplenty:leaves_5:10)
Block(-2,15,4,biomesoplenty:leaves_5:10)
Block(-1,15,4,biomesoplenty:leaves_5:10)
Block(0,15,4,biomesoplenty:leaves_5:10)
Block(1,15,4,biomesoplenty:leaves_5:10)
Block(2,15,4,biomesoplenty:leaves_5:10)
Block(3,15,4,biomesoplenty:leaves_5:10)
Block(4,15,4,biomesoplenty:leaves_5:10)
Block(5,15,4,biomesoplenty:leaves_5:10)
Block(8,15,4,biomesoplenty:leaves_5:10)
Block(9,15,4,biomesoplenty:leaves_5:10)
Block(-8,15,5,biomesoplenty:leaves_5:10)
Block(-7,15,5,biomesoplenty:leaves_5:10)
Block(-6,15,5,biomesoplenty:leaves_5:10)
Block(-5,15,5,biomesoplenty:leaves_5:10)
Block(-4,15,5,biomesoplenty:leaves_5:10)
Block(-3,15,5,biomesoplenty:leaves_5:10)
Block(-2,15,5,biomesoplenty:leaves_5:10)
Block(-1,15,5,biomesoplenty:leaves_5:10)
Block(0,15,5,biomesoplenty:leaves_5:10)
Block(1,15,5,biomesoplenty:leaves_5:10)
Block(2,15,5,biomesoplenty:leaves_5:10)
Block(3,15,5,biomesoplenty:leaves_5:10)
Block(4,15,5,biomesoplenty:leaves_5:10)
Block(8,15,5,biomesoplenty:leaves_5:10)
Block(9,15,5,biomesoplenty:leaves_5:10)
Block(-6,15,6,biomesoplenty:leaves_5:10)
Block(-5,15,6,biomesoplenty:leaves_5:10)
Block(-4,15,6,biomesoplenty:leaves_5:10)
Block(-3,15,6,biomesoplenty:leaves_5:10)
Block(-2,15,6,biomesoplenty:leaves_5:10)
Block(-1,15,6,biomesoplenty:leaves_5:10)
Block(0,15,6,biomesoplenty:leaves_5:10)
Block(1,15,6,biomesoplenty:leaves_5:10)
Block(2,15,6,biomesoplenty:leaves_5:10)
Block(3,15,6,biomesoplenty:leaves_5:10)
Block(4,15,6,biomesoplenty:leaves_5:10)
Block(5,15,6,biomesoplenty:leaves_5:10)
Block(6,15,6,biomesoplenty:leaves_5:10)
Block(7,15,6,biomesoplenty:leaves_5:10)
Block(9,15,6,biomesoplenty:leaves_5:10)
Block(10,15,6,biomesoplenty:leaves_5:10)
Block(-5,15,7,biomesoplenty:leaves_5:10)
Block(-4,15,7,biomesoplenty:leaves_5:10)
Block(-3,15,7,biomesoplenty:leaves_5:10)
Block(-2,15,7,biomesoplenty:leaves_5:10)
Block(0,15,7,biomesoplenty:leaves_5:10)
Block(1,15,7,biomesoplenty:leaves_5:10)
Block(2,15,7,biomesoplenty:leaves_5:10)
Block(3,15,7,biomesoplenty:leaves_5:10)
Block(5,15,7,biomesoplenty:leaves_5:10)
Block(6,15,7,biomesoplenty:leaves_5:10)
Block(7,15,7,biomesoplenty:leaves_5:10)
Block(-4,15,8,biomesoplenty:leaves_5:10)
Block(-3,15,8,biomesoplenty:leaves_5:10)
Block(-2,15,8,biomesoplenty:leaves_5:10)
Block(-1,15,8,biomesoplenty:leaves_5:10)
Block(0,15,8,biomesoplenty:leaves_5:10)
Block(1,15,8,biomesoplenty:leaves_5:10)
Block(2,15,8,biomesoplenty:leaves_5:10)
Block(3,15,8,biomesoplenty:leaves_5:10)
Block(4,15,8,biomesoplenty:leaves_5:10)
Block(5,15,8,biomesoplenty:leaves_5:10)
Block(6,15,8,biomesoplenty:leaves_5:10)
Block(-4,15,9,biomesoplenty:leaves_5:10)
Block(-3,15,9,biomesoplenty:leaves_5:10)
Block(-2,15,9,biomesoplenty:leaves_5:10)
Block(-1,15,9,biomesoplenty:leaves_5:10)
Block(0,15,9,biomesoplenty:leaves_5:10)
Block(1,15,9,biomesoplenty:leaves_5:10)
Block(2,15,9,biomesoplenty:leaves_5:10)
Block(3,15,9,biomesoplenty:leaves_5:10)
Block(4,15,9,biomesoplenty:leaves_5:10)
Block(-1,15,10,biomesoplenty:leaves_5:10)
Block(0,15,10,biomesoplenty:leaves_5:10)
Block(1,15,10,biomesoplenty:leaves_5:10)
Block(2,15,10,biomesoplenty:leaves_5:10)
Block(-8,16,-12,biomesoplenty:leaves_5:10)
Block(-7,16,-12,biomesoplenty:leaves_5:10)
Block(-6,16,-12,biomesoplenty:leaves_5:10)
Block(3,16,-12,biomesoplenty:leaves_5:10)
Block(4,16,-12,biomesoplenty:leaves_5:10)
Block(-9,16,-11,biomesoplenty:leaves_5:10)
Block(-8,16,-11,biomesoplenty:leaves_5:10)
Block(-7,16,-11,biomesoplenty:leaves_5:10)
Block(-6,16,-11,biomesoplenty:leaves_5:10)
Block(-5,16,-11,biomesoplenty:leaves_5:10)
Block(-4,16,-11,biomesoplenty:leaves_5:10)
Block(-2,16,-11,biomesoplenty:leaves_5:10)
Block(-1,16,-11,biomesoplenty:leaves_5:10)
Block(0,16,-11,biomesoplenty:leaves_5:10)
Block(1,16,-11,biomesoplenty:leaves_5:10)
Block(2,16,-11,biomesoplenty:leaves_5:10)
Block(3,16,-11,biomesoplenty:leaves_5:10)
Block(4,16,-11,biomesoplenty:leaves_5:10)
Block(5,16,-11,biomesoplenty:leaves_5:10)
Block(-9,16,-10,biomesoplenty:leaves_5:10)
Block(-8,16,-10,biomesoplenty:leaves_5:10)
Block(-7,16,-10,biomesoplenty:leaves_5:10)
Block(-6,16,-10,biomesoplenty:leaves_5:10)
Block(-5,16,-10,biomesoplenty:leaves_5:10)
Block(-4,16,-10,biomesoplenty:leaves_5:10)
Block(-3,16,-10,biomesoplenty:leaves_5:10)
Block(-2,16,-10,biomesoplenty:leaves_5:10)
Block(-1,16,-10,biomesoplenty:leaves_5:10)
Block(0,16,-10,biomesoplenty:leaves_5:10)
Block(1,16,-10,biomesoplenty:leaves_5:10)
Block(2,16,-10,biomesoplenty:leaves_5:10)
Block(3,16,-10,biomesoplenty:leaves_5:10)
Block(4,16,-10,biomesoplenty:leaves_5:10)
Block(5,16,-10,biomesoplenty:leaves_5:10)
Block(-11,16,-9,biomesoplenty:leaves_5:10)
Block(-8,16,-9,biomesoplenty:leaves_5:10)
Block(-7,16,-9,biomesoplenty:leaves_5:10)
Block(-6,16,-9,biomesoplenty:leaves_5:10)
Block(-5,16,-9,biomesoplenty:leaves_5:10)
Block(-4,16,-9,biomesoplenty:leaves_5:10)
Block(-3,16,-9,biomesoplenty:leaves_5:10)
Block(-2,16,-9,biomesoplenty:leaves_5:10)
Block(-1,16,-9,biomesoplenty:leaves_5:10)
Block(0,16,-9,biomesoplenty:leaves_5:10)
Block(1,16,-9,biomesoplenty:leaves_5:10)
Block(2,16,-9,biomesoplenty:leaves_5:10)
Block(3,16,-9,biomesoplenty:leaves_5:10)
Block(4,16,-9,biomesoplenty:leaves_5:10)
Block(5,16,-9,biomesoplenty:leaves_5:10)
Block(9,16,-9,biomesoplenty:leaves_5:10)
Block(-11,16,-8,biomesoplenty:leaves_5:10)
Block(-10,16,-8,biomesoplenty:leaves_5:10)
Block(-9,16,-8,biomesoplenty:leaves_5:10)
Block(-8,16,-8,biomesoplenty:leaves_5:10)
Block(-7,16,-8,biomesoplenty:leaves_5:10)
Block(-6,16,-8,biomesoplenty:leaves_5:10)
Block(-5,16,-8,biomesoplenty:leaves_5:10)
Block(-4,16,-8,biomesoplenty:leaves_5:10)
Block(-3,16,-8,biomesoplenty:leaves_5:10)
Block(-2,16,-8,biomesoplenty:leaves_5:10)
Block(-1,16,-8,biomesoplenty:leaves_5:10)
Block(0,16,-8,biomesoplenty:leaves_5:10)
Block(1,16,-8,biomesoplenty:leaves_5:10)
Block(2,16,-8,biomesoplenty:log_3:6)
Block(3,16,-8,biomesoplenty:leaves_5:10)
Block(4,16,-8,biomesoplenty:leaves_5:10)
Block(5,16,-8,biomesoplenty:leaves_5:10)
Block(9,16,-8,biomesoplenty:leaves_5:10)
Block(10,16,-8,biomesoplenty:leaves_5:10)
Block(-11,16,-7,biomesoplenty:leaves_5:10)
Block(-10,16,-7,biomesoplenty:leaves_5:10)
Block(-9,16,-7,biomesoplenty:leaves_5:10)
Block(-8,16,-7,biomesoplenty:leaves_5:10)
Block(-7,16,-7,biomesoplenty:leaves_5:10)
Block(-6,16,-7,biomesoplenty:leaves_5:10)
Block(-5,16,-7,biomesoplenty:leaves_5:10)
Block(-4,16,-7,biomesoplenty:log_3:6)
Block(-3,16,-7,biomesoplenty:leaves_5:10)
Block(-2,16,-7,biomesoplenty:leaves_5:10)
Block(-1,16,-7,biomesoplenty:leaves_5:10)
Block(0,16,-7,biomesoplenty:leaves_5:10)
Block(1,16,-7,biomesoplenty:log_3:6)
Block(2,16,-7,biomesoplenty:log_3:6)
Block(3,16,-7,biomesoplenty:log_3:6)
Block(4,16,-7,biomesoplenty:leaves_5:10)
Block(5,16,-7,biomesoplenty:leaves_5:10)
Block(6,16,-7,biomesoplenty:leaves_5:10)
Block(9,16,-7,biomesoplenty:leaves_5:10)
Block(10,16,-7,biomesoplenty:leaves_5:10)
Block(-9,16,-6,biomesoplenty:leaves_5:10)
Block(-8,16,-6,biomesoplenty:leaves_5:10)
Block(-7,16,-6,biomesoplenty:leaves_5:10)
Block(-6,16,-6,biomesoplenty:leaves_5:10)
Block(-5,16,-6,biomesoplenty:log_3:6)
Block(-4,16,-6,biomesoplenty:log_3:6)
Block(-3,16,-6,biomesoplenty:log_3:6)
Block(-2,16,-6,biomesoplenty:leaves_5:10)
Block(-1,16,-6,biomesoplenty:leaves_5:10)
Block(0,16,-6,biomesoplenty:leaves_5:10)
Block(1,16,-6,biomesoplenty:log_3:6)
Block(2,16,-6,biomesoplenty:log_3:6)
Block(3,16,-6,biomesoplenty:log_3:6)
Block(4,16,-6,biomesoplenty:leaves_5:10)
Block(5,16,-6,biomesoplenty:leaves_5:10)
Block(6,16,-6,biomesoplenty:leaves_5:10)
Block(7,16,-6,biomesoplenty:leaves_5:10)
Block(8,16,-6,biomesoplenty:leaves_5:10)
Block(-11,16,-5,biomesoplenty:leaves_5:10)
Block(-10,16,-5,biomesoplenty:leaves_5:10)
Block(-9,16,-5,biomesoplenty:leaves_5:10)
Block(-8,16,-5,biomesoplenty:leaves_5:10)
Block(-7,16,-5,biomesoplenty:leaves_5:10)
Block(-6,16,-5,biomesoplenty:leaves_5:10)
Block(-5,16,-5,biomesoplenty:leaves_5:10)
Block(-4,16,-5,biomesoplenty:log_3:6)
Block(-3,16,-5,biomesoplenty:log_3:6)
Block(-2,16,-5,biomesoplenty:log_3:6)
Block(-1,16,-5,biomesoplenty:leaves_5:10)
Block(0,16,-5,biomesoplenty:leaves_5:10)
Block(1,16,-5,biomesoplenty:log_3:6)
Block(2,16,-5,biomesoplenty:log_3:6)
Block(3,16,-5,biomesoplenty:log_3:6)
Block(4,16,-5,biomesoplenty:leaves_5:10)
Block(5,16,-5,biomesoplenty:leaves_5:10)
Block(6,16,-5,biomesoplenty:leaves_5:10)
Block(7,16,-5,biomesoplenty:leaves_5:10)
Block(8,16,-5,biomesoplenty:leaves_5:10)
Block(-9,16,-4,biomesoplenty:leaves_5:10)
Block(-8,16,-4,biomesoplenty:leaves_5:10)
Block(-7,16,-4,biomesoplenty:leaves_5:10)
Block(-6,16,-4,biomesoplenty:leaves_5:10)
Block(-5,16,-4,biomesoplenty:leaves_5:10)
Block(-4,16,-4,biomesoplenty:leaves_5:10)
Block(-3,16,-4,biomesoplenty:log_3:6)
Block(-2,16,-4,biomesoplenty:log_3:6)
Block(-1,16,-4,biomesoplenty:log_3:6)
Block(0,16,-4,biomesoplenty:leaves_5:10)
Block(1,16,-4,biomesoplenty:log_3:6)
Block(2,16,-4,biomesoplenty:log_3:6)
Block(3,16,-4,biomesoplenty:log_3:6)
Block(4,16,-4,biomesoplenty:leaves_5:10)
Block(5,16,-4,biomesoplenty:leaves_5:10)
Block(6,16,-4,biomesoplenty:leaves_5:10)
Block(7,16,-4,biomesoplenty:leaves_5:10)
Block(8,16,-4,biomesoplenty:leaves_5:10)
Block(-11,16,-3,biomesoplenty:leaves_5:10)
Block(-10,16,-3,biomesoplenty:leaves_5:10)
Block(-9,16,-3,biomesoplenty:leaves_5:10)
Block(-8,16,-3,biomesoplenty:leaves_5:10)
Block(-7,16,-3,biomesoplenty:leaves_5:10)
Block(-6,16,-3,biomesoplenty:leaves_5:10)
Block(-5,16,-3,biomesoplenty:leaves_5:10)
Block(-4,16,-3,biomesoplenty:leaves_5:10)
Block(-3,16,-3,biomesoplenty:leaves_5:10)
Block(-2,16,-3,biomesoplenty:log_3:6)
Block(-1,16,-3,biomesoplenty:log_3:6)
Block(0,16,-3,biomesoplenty:log_3:6)
Block(1,16,-3,biomesoplenty:log_3:6)
Block(2,16,-3,biomesoplenty:log_3:6)
Block(3,16,-3,biomesoplenty:log_3:6)
Block(4,16,-3,biomesoplenty:leaves_5:10)
Block(5,16,-3,biomesoplenty:log_3:6)
Block(6,16,-3,biomesoplenty:leaves_5:10)
Block(7,16,-3,biomesoplenty:leaves_5:10)
Block(8,16,-3,biomesoplenty:leaves_5:10)
Block(9,16,-3,biomesoplenty:leaves_5:10)
Block(-11,16,-2,biomesoplenty:leaves_5:10)
Block(-10,16,-2,biomesoplenty:leaves_5:10)
Block(-9,16,-2,biomesoplenty:leaves_5:10)
Block(-8,16,-2,biomesoplenty:leaves_5:10)
Block(-7,16,-2,biomesoplenty:leaves_5:10)
Block(-6,16,-2,biomesoplenty:leaves_5:10)
Block(-5,16,-2,biomesoplenty:leaves_5:10)
Block(-4,16,-2,biomesoplenty:leaves_5:10)
Block(-3,16,-2,biomesoplenty:leaves_5:10)
Block(-2,16,-2,biomesoplenty:log_3:6)
Block(-1,16,-2,biomesoplenty:log_3:6)
Block(0,16,-2,biomesoplenty:log_3:6)
Block(1,16,-2,biomesoplenty:log_3:6)
Block(2,16,-2,biomesoplenty:log_3:6)
Block(3,16,-2,biomesoplenty:log_3:6)
Block(4,16,-2,biomesoplenty:log_3:6)
Block(5,16,-2,biomesoplenty:log_3:6)
Block(6,16,-2,biomesoplenty:log_3:6)
Block(7,16,-2,biomesoplenty:leaves_5:10)
Block(8,16,-2,biomesoplenty:leaves_5:10)
Block(9,16,-2,biomesoplenty:leaves_5:10)
Block(-12,16,-1,biomesoplenty:leaves_5:10)
Block(-10,16,-1,biomesoplenty:leaves_5:10)
Block(-9,16,-1,biomesoplenty:leaves_5:10)
Block(-8,16,-1,biomesoplenty:leaves_5:10)
Block(-7,16,-1,biomesoplenty:leaves_5:10)
Block(-6,16,-1,biomesoplenty:leaves_5:10)
Block(-5,16,-1,biomesoplenty:leaves_5:10)
Block(-4,16,-1,biomesoplenty:leaves_5:10)
Block(-3,16,-1,biomesoplenty:leaves_5:10)
Block(-2,16,-1,biomesoplenty:leaves_5:10)
Block(-1,16,-1,biomesoplenty:log_3:6)
Block(0,16,-1,biomesoplenty:log_3:6)
Block(1,16,-1,biomesoplenty:log_3:6)
Block(2,16,-1,biomesoplenty:log_3:6)
Block(3,16,-1,biomesoplenty:log_3:6)
Block(4,16,-1,biomesoplenty:log_3:6)
Block(5,16,-1,biomesoplenty:log_3:6)
Block(6,16,-1,biomesoplenty:leaves_5:10)
Block(7,16,-1,biomesoplenty:leaves_5:10)
Block(8,16,-1,biomesoplenty:leaves_5:10)
Block(9,16,-1,biomesoplenty:leaves_5:10)
Block(-12,16,0,biomesoplenty:leaves_5:10)
Block(-11,16,0,biomesoplenty:leaves_5:10)
Block(-10,16,0,biomesoplenty:leaves_5:10)
Block(-9,16,0,biomesoplenty:leaves_5:10)
Block(-8,16,0,biomesoplenty:leaves_5:10)
Block(-7,16,0,biomesoplenty:leaves_5:10)
Block(-6,16,0,biomesoplenty:leaves_5:10)
Block(-5,16,0,biomesoplenty:leaves_5:10)
Block(-4,16,0,biomesoplenty:leaves_5:10)
Block(-3,16,0,biomesoplenty:leaves_5:10)
Block(-2,16,0,biomesoplenty:leaves_5:10)
Block(-1,16,0,biomesoplenty:leaves_5:10)
Block(0,16,0,biomesoplenty:log_3:6)
Block(1,16,0,biomesoplenty:log_3:6)
Block(2,16,0,biomesoplenty:log_3:6)
Block(3,16,0,biomesoplenty:log_3:6)
Block(4,16,0,biomesoplenty:log_3:6)
Block(5,16,0,biomesoplenty:leaves_5:10)
Block(6,16,0,biomesoplenty:leaves_5:10)
Block(7,16,0,biomesoplenty:leaves_5:10)
Block(9,16,0,biomesoplenty:leaves_5:10)
Block(10,16,0,biomesoplenty:leaves_5:10)
Block(11,16,0,biomesoplenty:leaves_5:10)
Block(-10,16,1,biomesoplenty:leaves_5:10)
Block(-9,16,1,biomesoplenty:leaves_5:10)
Block(-8,16,1,biomesoplenty:leaves_5:10)
Block(-7,16,1,biomesoplenty:leaves_5:10)
Block(-6,16,1,biomesoplenty:leaves_5:10)
Block(-5,16,1,biomesoplenty:leaves_5:10)
Block(-4,16,1,biomesoplenty:leaves_5:10)
Block(-3,16,1,biomesoplenty:leaves_5:10)
Block(-2,16,1,biomesoplenty:leaves_5:10)
Block(-1,16,1,biomesoplenty:leaves_5:10)
Block(0,16,1,biomesoplenty:leaves_5:10)
Block(1,16,1,biomesoplenty:log_3:6)
Block(2,16,1,biomesoplenty:log_3:6)
Block(3,16,1,biomesoplenty:log_3:6)
Block(4,16,1,biomesoplenty:log_3:6)
Block(5,16,1,biomesoplenty:leaves_5:10)
Block(6,16,1,biomesoplenty:leaves_5:10)
Block(7,16,1,biomesoplenty:leaves_5:10)
Block(8,16,1,biomesoplenty:leaves_5:10)
Block(9,16,1,biomesoplenty:leaves_5:10)
Block(10,16,1,biomesoplenty:leaves_5:10)
Block(11,16,1,biomesoplenty:leaves_5:10)
Block(12,16,1,biomesoplenty:leaves_5:10)
Block(-11,16,2,biomesoplenty:leaves_5:10)
Block(-10,16,2,biomesoplenty:leaves_5:10)
Block(-9,16,2,biomesoplenty:leaves_5:10)
Block(-8,16,2,biomesoplenty:leaves_5:10)
Block(-7,16,2,biomesoplenty:leaves_5:10)
Block(-6,16,2,biomesoplenty:leaves_5:10)
Block(-5,16,2,biomesoplenty:leaves_5:10)
Block(-4,16,2,biomesoplenty:leaves_5:10)
Block(-3,16,2,biomesoplenty:leaves_5:10)
Block(-2,16,2,biomesoplenty:leaves_5:10)
Block(-1,16,2,biomesoplenty:leaves_5:10)
Block(0,16,2,biomesoplenty:leaves_5:10)
Block(1,16,2,biomesoplenty:log_3:6)
Block(2,16,2,biomesoplenty:log_3:6)
Block(3,16,2,biomesoplenty:log_3:6)
Block(4,16,2,biomesoplenty:leaves_5:10)
Block(5,16,2,biomesoplenty:leaves_5:10)
Block(6,16,2,biomesoplenty:leaves_5:10)
Block(7,16,2,biomesoplenty:leaves_5:10)
Block(8,16,2,biomesoplenty:leaves_5:10)
Block(9,16,2,biomesoplenty:leaves_5:10)
Block(10,16,2,biomesoplenty:leaves_5:10)
Block(11,16,2,biomesoplenty:leaves_5:10)
Block(12,16,2,biomesoplenty:leaves_5:10)
Block(-10,16,3,biomesoplenty:leaves_5:10)
Block(-9,16,3,biomesoplenty:leaves_5:10)
Block(-8,16,3,biomesoplenty:leaves_5:10)
Block(-7,16,3,biomesoplenty:leaves_5:10)
Block(-6,16,3,biomesoplenty:leaves_5:10)
Block(-5,16,3,biomesoplenty:leaves_5:10)
Block(-4,16,3,biomesoplenty:leaves_5:10)
Block(-3,16,3,biomesoplenty:leaves_5:10)
Block(-2,16,3,biomesoplenty:leaves_5:10)
Block(-1,16,3,biomesoplenty:leaves_5:10)
Block(0,16,3,biomesoplenty:leaves_5:10)
Block(1,16,3,biomesoplenty:log_3:6)
Block(2,16,3,biomesoplenty:log_3:6)
Block(3,16,3,biomesoplenty:log_3:6)
Block(4,16,3,biomesoplenty:leaves_5:10)
Block(5,16,3,biomesoplenty:leaves_5:10)
Block(6,16,3,biomesoplenty:leaves_5:10)
Block(7,16,3,biomesoplenty:leaves_5:10)
Block(8,16,3,biomesoplenty:leaves_5:10)
Block(9,16,3,biomesoplenty:leaves_5:10)
Block(10,16,3,biomesoplenty:leaves_5:10)
Block(11,16,3,biomesoplenty:leaves_5:10)
Block(-10,16,4,biomesoplenty:leaves_5:10)
Block(-9,16,4,biomesoplenty:leaves_5:10)
Block(-8,16,4,biomesoplenty:leaves_5:10)
Block(-7,16,4,biomesoplenty:leaves_5:10)
Block(-6,16,4,biomesoplenty:leaves_5:10)
Block(-5,16,4,biomesoplenty:leaves_5:10)
Block(-4,16,4,biomesoplenty:leaves_5:10)
Block(-3,16,4,biomesoplenty:leaves_5:10)
Block(-2,16,4,biomesoplenty:leaves_5:10)
Block(-1,16,4,biomesoplenty:leaves_5:10)
Block(0,16,4,biomesoplenty:leaves_5:10)
Block(1,16,4,biomesoplenty:log_3:6)
Block(2,16,4,biomesoplenty:log_3:6)
Block(3,16,4,biomesoplenty:log_3:6)
Block(4,16,4,biomesoplenty:leaves_5:10)
Block(5,16,4,biomesoplenty:leaves_5:10)
Block(6,16,4,biomesoplenty:leaves_5:10)
Block(7,16,4,biomesoplenty:leaves_5:10)
Block(8,16,4,biomesoplenty:leaves_5:10)
Block(9,16,4,biomesoplenty:leaves_5:10)
Block(10,16,4,biomesoplenty:leaves_5:10)
Block(11,16,4,biomesoplenty:leaves_5:10)
Block(-9,16,5,biomesoplenty:leaves_5:10)
Block(-8,16,5,biomesoplenty:leaves_5:10)
Block(-7,16,5,biomesoplenty:leaves_5:10)
Block(-6,16,5,biomesoplenty:leaves_5:10)
Block(-5,16,5,biomesoplenty:leaves_5:10)
Block(-4,16,5,biomesoplenty:leaves_5:10)
Block(-3,16,5,biomesoplenty:leaves_5:10)
Block(-2,16,5,biomesoplenty:leaves_5:10)
Block(-1,16,5,biomesoplenty:leaves_5:10)
Block(0,16,5,biomesoplenty:leaves_5:10)
Block(1,16,5,biomesoplenty:leaves_5:10)
Block(2,16,5,biomesoplenty:log_3:6)
Block(3,16,5,biomesoplenty:leaves_5:10)
Block(4,16,5,biomesoplenty:leaves_5:10)
Block(5,16,5,biomesoplenty:leaves_5:10)
Block(6,16,5,biomesoplenty:leaves_5:10)
Block(7,16,5,biomesoplenty:leaves_5:10)
Block(8,16,5,biomesoplenty:leaves_5:10)
Block(9,16,5,biomesoplenty:leaves_5:10)
Block(10,16,5,biomesoplenty:leaves_5:10)
Block(11,16,5,biomesoplenty:leaves_5:10)
Block(-8,16,6,biomesoplenty:leaves_5:10)
Block(-7,16,6,biomesoplenty:leaves_5:10)
Block(-6,16,6,biomesoplenty:leaves_5:10)
Block(-5,16,6,biomesoplenty:leaves_5:10)
Block(-4,16,6,biomesoplenty:leaves_5:10)
Block(-3,16,6,biomesoplenty:leaves_5:10)
Block(-2,16,6,biomesoplenty:leaves_5:10)
Block(-1,16,6,biomesoplenty:leaves_5:10)
Block(0,16,6,biomesoplenty:leaves_5:10)
Block(1,16,6,biomesoplenty:leaves_5:10)
Block(2,16,6,biomesoplenty:leaves_5:10)
Block(3,16,6,biomesoplenty:leaves_5:10)
Block(4,16,6,biomesoplenty:leaves_5:10)
Block(5,16,6,biomesoplenty:leaves_5:10)
Block(6,16,6,biomesoplenty:leaves_5:10)
Block(7,16,6,biomesoplenty:leaves_5:10)
Block(8,16,6,biomesoplenty:leaves_5:10)
Block(9,16,6,biomesoplenty:leaves_5:10)
Block(10,16,6,biomesoplenty:leaves_5:10)
Block(11,16,6,biomesoplenty:leaves_5:10)
Block(-6,16,7,biomesoplenty:leaves_5:10)
Block(-5,16,7,biomesoplenty:leaves_5:10)
Block(-4,16,7,biomesoplenty:leaves_5:10)
Block(-3,16,7,biomesoplenty:leaves_5:10)
Block(-2,16,7,biomesoplenty:leaves_5:10)
Block(-1,16,7,biomesoplenty:leaves_5:10)
Block(0,16,7,biomesoplenty:leaves_5:10)
Block(1,16,7,biomesoplenty:leaves_5:10)
Block(2,16,7,biomesoplenty:leaves_5:10)
Block(3,16,7,biomesoplenty:leaves_5:10)
Block(4,16,7,biomesoplenty:leaves_5:10)
Block(5,16,7,biomesoplenty:leaves_5:10)
Block(6,16,7,biomesoplenty:leaves_5:10)
Block(7,16,7,biomesoplenty:leaves_5:10)
Block(8,16,7,biomesoplenty:leaves_5:10)
Block(9,16,7,biomesoplenty:leaves_5:10)
Block(10,16,7,biomesoplenty:leaves_5:10)
Block(-5,16,8,biomesoplenty:leaves_5:10)
Block(-4,16,8,biomesoplenty:leaves_5:10)
Block(-3,16,8,biomesoplenty:leaves_5:10)
Block(-2,16,8,biomesoplenty:leaves_5:10)
Block(-1,16,8,biomesoplenty:leaves_5:10)
Block(1,16,8,biomesoplenty:leaves_5:10)
Block(2,16,8,biomesoplenty:leaves_5:10)
Block(3,16,8,biomesoplenty:leaves_5:10)
Block(4,16,8,biomesoplenty:leaves_5:10)
Block(5,16,8,biomesoplenty:leaves_5:10)
Block(6,16,8,biomesoplenty:leaves_5:10)
Block(7,16,8,biomesoplenty:leaves_5:10)
Block(-5,16,9,biomesoplenty:leaves_5:10)
Block(-4,16,9,biomesoplenty:leaves_5:10)
Block(-3,16,9,biomesoplenty:leaves_5:10)
Block(-2,16,9,biomesoplenty:leaves_5:10)
Block(-1,16,9,biomesoplenty:leaves_5:10)
Block(0,16,9,biomesoplenty:leaves_5:10)
Block(1,16,9,biomesoplenty:leaves_5:10)
Block(2,16,9,biomesoplenty:leaves_5:10)
Block(3,16,9,biomesoplenty:leaves_5:10)
Block(4,16,9,biomesoplenty:leaves_5:10)
Block(5,16,9,biomesoplenty:leaves_5:10)
Block(6,16,9,biomesoplenty:leaves_5:10)
Block(7,16,9,biomesoplenty:leaves_5:10)
Block(-6,16,10,biomesoplenty:leaves_5:10)
Block(-5,16,10,biomesoplenty:leaves_5:10)
Block(-4,16,10,biomesoplenty:leaves_5:10)
Block(-3,16,10,biomesoplenty:leaves_5:10)
Block(-2,16,10,biomesoplenty:leaves_5:10)
Block(-1,16,10,biomesoplenty:leaves_5:10)
Block(0,16,10,biomesoplenty:leaves_5:10)
Block(1,16,10,biomesoplenty:leaves_5:10)
Block(2,16,10,biomesoplenty:leaves_5:10)
Block(3,16,10,biomesoplenty:leaves_5:10)
Block(4,16,10,biomesoplenty:leaves_5:10)
Block(5,16,10,biomesoplenty:leaves_5:10)
Block(0,16,11,biomesoplenty:leaves_5:10)
Block(2,16,11,biomesoplenty:leaves_5:10)
Block(3,16,11,biomesoplenty:leaves_5:10)
Block(4,16,11,biomesoplenty:leaves_5:10)
Block(-8,17,-12,biomesoplenty:leaves_5:10)
Block(-7,17,-12,biomesoplenty:leaves_5:10)
Block(-6,17,-12,biomesoplenty:leaves_5:10)
Block(-4,17,-12,biomesoplenty:leaves_5:10)
Block(-3,17,-12,biomesoplenty:leaves_5:10)
Block(-2,17,-12,biomesoplenty:leaves_5:10)
Block(-1,17,-12,biomesoplenty:leaves_5:10)
Block(0,17,-12,biomesoplenty:leaves_5:10)
Block(2,17,-12,biomesoplenty:leaves_5:10)
Block(3,17,-12,biomesoplenty:leaves_5:10)
Block(4,17,-12,biomesoplenty:leaves_5:10)
Block(-9,17,-11,biomesoplenty:leaves_5:10)
Block(-8,17,-11,biomesoplenty:leaves_5:10)
Block(-7,17,-11,biomesoplenty:leaves_5:10)
Block(-6,17,-11,biomesoplenty:log_3:6)
Block(-5,17,-11,biomesoplenty:leaves_5:10)
Block(-4,17,-11,biomesoplenty:leaves_5:10)
Block(-3,17,-11,biomesoplenty:leaves_5:10)
Block(-2,17,-11,biomesoplenty:leaves_5:10)
Block(-1,17,-11,biomesoplenty:leaves_5:10)
Block(0,17,-11,biomesoplenty:leaves_5:10)
Block(1,17,-11,biomesoplenty:leaves_5:10)
Block(2,17,-11,biomesoplenty:leaves_5:10)
Block(3,17,-11,biomesoplenty:leaves_5:10)
Block(5,17,-11,biomesoplenty:leaves_5:10)
Block(-9,17,-10,biomesoplenty:leaves_5:10)
Block(-8,17,-10,biomesoplenty:leaves_5:10)
Block(-7,17,-10,biomesoplenty:log_3:6)
Block(-6,17,-10,biomesoplenty:log_3:6)
Block(-5,17,-10,biomesoplenty:log_3:6)
Block(-4,17,-10,biomesoplenty:leaves_5:10)
Block(-3,17,-10,biomesoplenty:leaves_5:10)
Block(-2,17,-10,biomesoplenty:leaves_5:10)
Block(-1,17,-10,biomesoplenty:leaves_5:10)
Block(0,17,-10,biomesoplenty:leaves_5:10)
Block(1,17,-10,biomesoplenty:leaves_5:10)
Block(2,17,-10,biomesoplenty:leaves_5:10)
Block(3,17,-10,biomesoplenty:log_3:6)
Block(4,17,-10,biomesoplenty:leaves_5:10)
Block(5,17,-10,biomesoplenty:leaves_5:10)
Block(7,17,-10,biomesoplenty:leaves_5:10)
Block(8,17,-10,biomesoplenty:leaves_5:10)
Block(10,17,-10,biomesoplenty:leaves_5:10)
Block(11,17,-10,biomesoplenty:leaves_5:10)
Block(-11,17,-9,biomesoplenty:leaves_5:10)
Block(-9,17,-9,biomesoplenty:leaves_5:10)
Block(-8,17,-9,biomesoplenty:leaves_5:10)
Block(-7,17,-9,biomesoplenty:log_3:6)
Block(-6,17,-9,biomesoplenty:log_3:6)
Block(-5,17,-9,biomesoplenty:log_3:6)
Block(-4,17,-9,biomesoplenty:leaves_5:10)
Block(-3,17,-9,biomesoplenty:leaves_5:10)
Block(-2,17,-9,biomesoplenty:leaves_5:10)
Block(-1,17,-9,biomesoplenty:leaves_5:10)
Block(0,17,-9,biomesoplenty:leaves_5:10)
Block(1,17,-9,biomesoplenty:leaves_5:10)
Block(2,17,-9,biomesoplenty:log_3:6)
Block(3,17,-9,biomesoplenty:log_3:6)
Block(4,17,-9,biomesoplenty:log_3:6)
Block(5,17,-9,biomesoplenty:leaves_5:10)
Block(6,17,-9,biomesoplenty:leaves_5:10)
Block(7,17,-9,biomesoplenty:leaves_5:10)
Block(8,17,-9,biomesoplenty:leaves_5:10)
Block(9,17,-9,biomesoplenty:leaves_5:10)
Block(10,17,-9,biomesoplenty:leaves_5:10)
Block(11,17,-9,biomesoplenty:leaves_5:10)
Block(-11,17,-8,biomesoplenty:leaves_5:10)
Block(-9,17,-8,biomesoplenty:leaves_5:10)
Block(-8,17,-8,biomesoplenty:leaves_5:10)
Block(-7,17,-8,biomesoplenty:log_3:6)
Block(-6,17,-8,biomesoplenty:log_3:6)
Block(-5,17,-8,biomesoplenty:log_3:6)
Block(-4,17,-8,biomesoplenty:leaves_5:10)
Block(-3,17,-8,biomesoplenty:leaves_5:10)
Block(-2,17,-8,biomesoplenty:leaves_5:10)
Block(-1,17,-8,biomesoplenty:leaves_5:10)
Block(0,17,-8,biomesoplenty:leaves_5:10)
Block(1,17,-8,biomesoplenty:log_3:6)
Block(2,17,-8,biomesoplenty:log_3:6)
Block(3,17,-8,biomesoplenty:log_3:6)
Block(4,17,-8,biomesoplenty:leaves_5:10)
Block(5,17,-8,biomesoplenty:leaves_5:10)
Block(6,17,-8,biomesoplenty:leaves_5:10)
Block(7,17,-8,biomesoplenty:leaves_5:10)
Block(8,17,-8,biomesoplenty:leaves_5:10)
Block(9,17,-8,biomesoplenty:leaves_5:10)
Block(-10,17,-7,biomesoplenty:leaves_5:10)
Block(-9,17,-7,biomesoplenty:leaves_5:10)
Block(-8,17,-7,biomesoplenty:leaves_5:10)
Block(-7,17,-7,biomesoplenty:log_3:6)
Block(-6,17,-7,biomesoplenty:log_3:6)
Block(-5,17,-7,biomesoplenty:log_3:6)
Block(-4,17,-7,biomesoplenty:log_3:6)
Block(-3,17,-7,biomesoplenty:log_3:6)
Block(-2,17,-7,biomesoplenty:leaves_5:10)
Block(-1,17,-7,biomesoplenty:leaves_5:10)
Block(0,17,-7,biomesoplenty:leaves_5:10)
Block(1,17,-7,biomesoplenty:log_3:6)
Block(2,17,-7,biomesoplenty:log_3:6)
Block(3,17,-7,biomesoplenty:log_3:6)
Block(4,17,-7,biomesoplenty:leaves_5:10)
Block(5,17,-7,biomesoplenty:leaves_5:10)
Block(6,17,-7,biomesoplenty:leaves_5:10)
Block(7,17,-7,biomesoplenty:leaves_5:10)
Block(8,17,-7,biomesoplenty:leaves_5:10)
Block(9,17,-7,biomesoplenty:leaves_5:10)
Block(-12,17,-6,biomesoplenty:leaves_5:10)
Block(-9,17,-6,biomesoplenty:leaves_5:10)
Block(-8,17,-6,biomesoplenty:leaves_5:10)
Block(-7,17,-6,biomesoplenty:leaves_5:10)
Block(-6,17,-6,biomesoplenty:log_3:6)
Block(-5,17,-6,biomesoplenty:log_3:6)
Block(-4,17,-6,biomesoplenty:log_3:6)
Block(-3,17,-6,biomesoplenty:log_3:6)
Block(-2,17,-6,biomesoplenty:log_3:6)
Block(-1,17,-6,biomesoplenty:leaves_5:10)
Block(0,17,-6,biomesoplenty:leaves_5:10)
Block(1,17,-6,biomesoplenty:log_3:6)
Block(2,17,-6,biomesoplenty:log_3:6)
Block(3,17,-6,biomesoplenty:log_3:6)
Block(4,17,-6,biomesoplenty:leaves_5:10)
Block(5,17,-6,biomesoplenty:leaves_5:10)
Block(6,17,-6,biomesoplenty:leaves_5:10)
Block(7,17,-6,biomesoplenty:leaves_5:10)
Block(8,17,-6,biomesoplenty:leaves_5:10)
Block(9,17,-6,biomesoplenty:leaves_5:10)
Block(10,17,-6,biomesoplenty:leaves_5:10)
Block(11,17,-6,biomesoplenty:leaves_5:10)
Block(-10,17,-5,biomesoplenty:leaves_5:10)
Block(-9,17,-5,biomesoplenty:leaves_5:10)
Block(-8,17,-5,biomesoplenty:leaves_5:10)
Block(-7,17,-5,biomesoplenty:leaves_5:10)
Block(-6,17,-5,biomesoplenty:leaves_5:10)
Block(-5,17,-5,biomesoplenty:log_3:6)
Block(-4,17,-5,biomesoplenty:log_3:6)
Block(-3,17,-5,biomesoplenty:log_3:6)
Block(-2,17,-5,biomesoplenty:log_3:6)
Block(-1,17,-5,biomesoplenty:log_3:6)
Block(0,17,-5,biomesoplenty:leaves_5:10)
Block(1,17,-5,biomesoplenty:log_3:6)
Block(2,17,-5,biomesoplenty:log_3:6)
Block(3,17,-5,biomesoplenty:log_3:6)
Block(4,17,-5,biomesoplenty:leaves_5:10)
Block(5,17,-5,biomesoplenty:leaves_5:10)
Block(6,17,-5,biomesoplenty:leaves_5:10)
Block(7,17,-5,biomesoplenty:leaves_5:10)
Block(8,17,-5,biomesoplenty:leaves_5:10)
Block(9,17,-5,biomesoplenty:leaves_5:10)
Block(-11,17,-4,biomesoplenty:leaves_5:10)
Block(-10,17,-4,biomesoplenty:leaves_5:10)
Block(-9,17,-4,biomesoplenty:leaves_5:10)
Block(-8,17,-4,biomesoplenty:leaves_5:10)
Block(-7,17,-4,biomesoplenty:leaves_5:10)
Block(-6,17,-4,biomesoplenty:leaves_5:10)
Block(-5,17,-4,biomesoplenty:leaves_5:10)
Block(-4,17,-4,biomesoplenty:log_3:6)
Block(-3,17,-4,biomesoplenty:log_3:6)
Block(-2,17,-4,biomesoplenty:log_3:6)
Block(-1,17,-4,biomesoplenty:log_3:6)
Block(0,17,-4,biomesoplenty:log_3:6)
Block(1,17,-4,biomesoplenty:log_3:6)
Block(2,17,-4,biomesoplenty:log_3:6)
Block(3,17,-4,biomesoplenty:log_3:6)
Block(4,17,-4,biomesoplenty:leaves_5:10)
Block(5,17,-4,biomesoplenty:leaves_5:10)
Block(6,17,-4,biomesoplenty:leaves_5:10)
Block(7,17,-4,biomesoplenty:leaves_5:10)
Block(8,17,-4,biomesoplenty:leaves_5:10)
Block(9,17,-4,biomesoplenty:log_3:6)
Block(10,17,-4,biomesoplenty:leaves_5:10)
Block(11,17,-4,biomesoplenty:leaves_5:10)
Block(12,17,-4,biomesoplenty:leaves_5:10)
Block(-11,17,-3,biomesoplenty:leaves_5:10)
Block(-10,17,-3,biomesoplenty:leaves_5:10)
Block(-9,17,-3,biomesoplenty:leaves_5:10)
Block(-8,17,-3,biomesoplenty:leaves_5:10)
Block(-7,17,-3,biomesoplenty:leaves_5:10)
Block(-6,17,-3,biomesoplenty:leaves_5:10)
Block(-5,17,-3,biomesoplenty:leaves_5:10)
Block(-4,17,-3,biomesoplenty:leaves_5:10)
Block(-3,17,-3,biomesoplenty:log_3:6)
Block(-2,17,-3,biomesoplenty:log_3:6)
Block(-1,17,-3,biomesoplenty:log_3:6)
Block(0,17,-3,biomesoplenty:log_3:6)
Block(1,17,-3,biomesoplenty:log_3:6)
Block(2,17,-3,biomesoplenty:log_3:6)
Block(3,17,-3,biomesoplenty:log_3:6)
Block(4,17,-3,biomesoplenty:log_3:6)
Block(5,17,-3,biomesoplenty:log_3:6)
Block(6,17,-3,biomesoplenty:log_3:6)
Block(7,17,-3,biomesoplenty:log_3:6)
Block(8,17,-3,biomesoplenty:log_3:6)
Block(9,17,-3,biomesoplenty:log_3:6)
Block(10,17,-3,biomesoplenty:log_3:6)
Block(11,17,-3,biomesoplenty:leaves_5:10)
Block(12,17,-3,biomesoplenty:leaves_5:10)
Block(-11,17,-2,biomesoplenty:leaves_5:10)
Block(-10,17,-2,biomesoplenty:leaves_5:10)
Block(-9,17,-2,biomesoplenty:leaves_5:10)
Block(-8,17,-2,biomesoplenty:leaves_5:10)
Block(-7,17,-2,biomesoplenty:leaves_5:10)
Block(-6,17,-2,biomesoplenty:leaves_5:10)
Block(-5,17,-2,biomesoplenty:leaves_5:10)
Block(-4,17,-2,biomesoplenty:leaves_5:10)
Block(-3,17,-2,biomesoplenty:leaves_5:10)
Block(-2,17,-2,biomesoplenty:log_3:6)
Block(-1,17,-2,biomesoplenty:log_3:6)
Block(0,17,-2,biomesoplenty:log_3:6)
Block(1,17,-2,biomesoplenty:log_3:6)
Block(2,17,-2,biomesoplenty:log_3:6)
Block(3,17,-2,biomesoplenty:log_3:6)
Block(4,17,-2,biomesoplenty:log_3:6)
Block(5,17,-2,biomesoplenty:log_3:6)
Block(6,17,-2,biomesoplenty:log_3:6)
Block(7,17,-2,biomesoplenty:log_3:6)
Block(8,17,-2,biomesoplenty:log_3:6)
Block(9,17,-2,biomesoplenty:log_3:6)
Block(10,17,-2,biomesoplenty:leaves_5:10)
Block(11,17,-2,biomesoplenty:leaves_5:10)
Block(-12,17,-1,biomesoplenty:leaves_5:10)
Block(-11,17,-1,biomesoplenty:leaves_5:10)
Block(-10,17,-1,biomesoplenty:leaves_5:10)
Block(-9,17,-1,biomesoplenty:leaves_5:10)
Block(-8,17,-1,biomesoplenty:leaves_5:10)
Block(-7,17,-1,biomesoplenty:leaves_5:10)
Block(-6,17,-1,biomesoplenty:leaves_5:10)
Block(-5,17,-1,biomesoplenty:leaves_5:10)
Block(-4,17,-1,biomesoplenty:leaves_5:10)
Block(-3,17,-1,biomesoplenty:leaves_5:10)
Block(-2,17,-1,biomesoplenty:log_3:6)
Block(-1,17,-1,biomesoplenty:log_3:6)
Block(0,17,-1,biomesoplenty:log_3:6)
Block(1,17,-1,biomesoplenty:log_3:6)
Block(2,17,-1,biomesoplenty:log_3:6)
Block(3,17,-1,biomesoplenty:log_3:6)
Block(4,17,-1,biomesoplenty:log_3:6)
Block(5,17,-1,biomesoplenty:log_3:6)
Block(6,17,-1,biomesoplenty:log_3:6)
Block(7,17,-1,biomesoplenty:log_3:6)
Block(8,17,-1,biomesoplenty:log_3:6)
Block(9,17,-1,biomesoplenty:leaves_5:10)
Block(10,17,-1,biomesoplenty:leaves_5:10)
Block(11,17,-1,biomesoplenty:leaves_5:10)
Block(-12,17,0,biomesoplenty:leaves_5:10)
Block(-11,17,0,biomesoplenty:leaves_5:10)
Block(-10,17,0,biomesoplenty:leaves_5:10)
Block(-9,17,0,biomesoplenty:leaves_5:10)
Block(-8,17,0,biomesoplenty:leaves_5:10)
Block(-7,17,0,biomesoplenty:leaves_5:10)
Block(-6,17,0,biomesoplenty:leaves_5:10)
Block(-5,17,0,biomesoplenty:leaves_5:10)
Block(-4,17,0,biomesoplenty:leaves_5:10)
Block(-3,17,0,biomesoplenty:leaves_5:10)
Block(-2,17,0,biomesoplenty:leaves_5:10)
Block(-1,17,0,biomesoplenty:leaves_5:10)
Block(0,17,0,biomesoplenty:leaves_5:10)
Block(1,17,0,biomesoplenty:log_3:6)
Block(2,17,0,biomesoplenty:log_3:6)
Block(3,17,0,biomesoplenty:log_3:6)
Block(4,17,0,biomesoplenty:log_3:6)
Block(5,17,0,biomesoplenty:log_3:6)
Block(6,17,0,biomesoplenty:leaves_5:10)
Block(7,17,0,biomesoplenty:leaves_5:10)
Block(8,17,0,biomesoplenty:leaves_5:10)
Block(9,17,0,biomesoplenty:leaves_5:10)
Block(10,17,0,biomesoplenty:leaves_5:10)
Block(11,17,0,biomesoplenty:leaves_5:10)
Block(-11,17,1,biomesoplenty:leaves_5:10)
Block(-10,17,1,biomesoplenty:leaves_5:10)
Block(-9,17,1,biomesoplenty:leaves_5:10)
Block(-8,17,1,biomesoplenty:leaves_5:10)
Block(-7,17,1,biomesoplenty:leaves_5:10)
Block(-6,17,1,biomesoplenty:leaves_5:10)
Block(-5,17,1,biomesoplenty:leaves_5:10)
Block(-4,17,1,biomesoplenty:leaves_5:10)
Block(-3,17,1,biomesoplenty:leaves_5:10)
Block(-2,17,1,biomesoplenty:leaves_5:10)
Block(-1,17,1,biomesoplenty:leaves_5:10)
Block(0,17,1,biomesoplenty:leaves_5:10)
Block(1,17,1,biomesoplenty:log_3:6)
Block(2,17,1,biomesoplenty:log_3:6)
Block(3,17,1,biomesoplenty:log_3:6)
Block(4,17,1,biomesoplenty:leaves_5:10)
Block(5,17,1,biomesoplenty:leaves_5:10)
Block(6,17,1,biomesoplenty:leaves_5:10)
Block(7,17,1,biomesoplenty:leaves_5:10)
Block(8,17,1,biomesoplenty:leaves_5:10)
Block(9,17,1,biomesoplenty:leaves_5:10)
Block(10,17,1,biomesoplenty:leaves_5:10)
Block(11,17,1,biomesoplenty:leaves_5:10)
Block(12,17,1,biomesoplenty:leaves_5:10)
Block(-11,17,2,biomesoplenty:leaves_5:10)
Block(-10,17,2,biomesoplenty:leaves_5:10)
Block(-9,17,2,biomesoplenty:leaves_5:10)
Block(-8,17,2,biomesoplenty:leaves_5:10)
Block(-7,17,2,biomesoplenty:leaves_5:10)
Block(-6,17,2,biomesoplenty:leaves_5:10)
Block(-5,17,2,biomesoplenty:leaves_5:10)
Block(-4,17,2,biomesoplenty:leaves_5:10)
Block(-3,17,2,biomesoplenty:leaves_5:10)
Block(-2,17,2,biomesoplenty:leaves_5:10)
Block(-1,17,2,biomesoplenty:leaves_5:10)
Block(0,17,2,biomesoplenty:leaves_5:10)
Block(1,17,2,biomesoplenty:log_3:6)
Block(2,17,2,biomesoplenty:log_3:6)
Block(3,17,2,biomesoplenty:log_3:6)
Block(4,17,2,biomesoplenty:leaves_5:10)
Block(5,17,2,biomesoplenty:leaves_5:10)
Block(6,17,2,biomesoplenty:leaves_5:10)
Block(7,17,2,biomesoplenty:leaves_5:10)
Block(8,17,2,biomesoplenty:leaves_5:10)
Block(9,17,2,biomesoplenty:leaves_5:10)
Block(10,17,2,biomesoplenty:leaves_5:10)
Block(11,17,2,biomesoplenty:leaves_5:10)
Block(12,17,2,biomesoplenty:leaves_5:10)
Block(-10,17,3,biomesoplenty:leaves_5:10)
Block(-9,17,3,biomesoplenty:leaves_5:10)
Block(-8,17,3,biomesoplenty:leaves_5:10)
Block(-7,17,3,biomesoplenty:leaves_5:10)
Block(-6,17,3,biomesoplenty:leaves_5:10)
Block(-5,17,3,biomesoplenty:leaves_5:10)
Block(-4,17,3,biomesoplenty:leaves_5:10)
Block(-3,17,3,biomesoplenty:leaves_5:10)
Block(-2,17,3,biomesoplenty:leaves_5:10)
Block(-1,17,3,biomesoplenty:leaves_5:10)
Block(0,17,3,biomesoplenty:leaves_5:10)
Block(1,17,3,biomesoplenty:log_3:6)
Block(2,17,3,biomesoplenty:log_3:6)
Block(3,17,3,biomesoplenty:log_3:6)
Block(4,17,3,biomesoplenty:leaves_5:10)
Block(5,17,3,biomesoplenty:leaves_5:10)
Block(6,17,3,biomesoplenty:leaves_5:10)
Block(7,17,3,biomesoplenty:leaves_5:10)
Block(8,17,3,biomesoplenty:leaves_5:10)
Block(9,17,3,biomesoplenty:leaves_5:10)
Block(10,17,3,biomesoplenty:leaves_5:10)
Block(11,17,3,biomesoplenty:leaves_5:10)
Block(12,17,3,biomesoplenty:leaves_5:10)
Block(-10,17,4,biomesoplenty:leaves_5:10)
Block(-9,17,4,biomesoplenty:leaves_5:10)
Block(-8,17,4,biomesoplenty:leaves_5:10)
Block(-7,17,4,biomesoplenty:leaves_5:10)
Block(-6,17,4,biomesoplenty:leaves_5:10)
Block(-5,17,4,biomesoplenty:leaves_5:10)
Block(-4,17,4,biomesoplenty:leaves_5:10)
Block(-3,17,4,biomesoplenty:leaves_5:10)
Block(-2,17,4,biomesoplenty:leaves_5:10)
Block(-1,17,4,biomesoplenty:leaves_5:10)
Block(0,17,4,biomesoplenty:leaves_5:10)
Block(1,17,4,biomesoplenty:log_3:6)
Block(2,17,4,biomesoplenty:log_3:6)
Block(3,17,4,biomesoplenty:log_3:6)
Block(4,17,4,biomesoplenty:leaves_5:10)
Block(5,17,4,biomesoplenty:leaves_5:10)
Block(6,17,4,biomesoplenty:leaves_5:10)
Block(7,17,4,biomesoplenty:leaves_5:10)
Block(8,17,4,biomesoplenty:leaves_5:10)
Block(9,17,4,biomesoplenty:leaves_5:10)
Block(10,17,4,biomesoplenty:leaves_5:10)
Block(11,17,4,biomesoplenty:leaves_5:10)
Block(-10,17,5,biomesoplenty:leaves_5:10)
Block(-8,17,5,biomesoplenty:leaves_5:10)
Block(-7,17,5,biomesoplenty:leaves_5:10)
Block(-6,17,5,biomesoplenty:leaves_5:10)
Block(-5,17,5,biomesoplenty:leaves_5:10)
Block(-4,17,5,biomesoplenty:leaves_5:10)
Block(-3,17,5,biomesoplenty:leaves_5:10)
Block(-2,17,5,biomesoplenty:leaves_5:10)
Block(-1,17,5,biomesoplenty:leaves_5:10)
Block(0,17,5,biomesoplenty:leaves_5:10)
Block(1,17,5,biomesoplenty:log_3:6)
Block(2,17,5,biomesoplenty:log_3:6)
Block(3,17,5,biomesoplenty:log_3:6)
Block(4,17,5,biomesoplenty:leaves_5:10)
Block(5,17,5,biomesoplenty:leaves_5:10)
Block(6,17,5,biomesoplenty:leaves_5:10)
Block(7,17,5,biomesoplenty:leaves_5:10)
Block(8,17,5,biomesoplenty:leaves_5:10)
Block(9,17,5,biomesoplenty:leaves_5:10)
Block(10,17,5,biomesoplenty:leaves_5:10)
Block(11,17,5,biomesoplenty:leaves_5:10)
Block(-8,17,6,biomesoplenty:leaves_5:10)
Block(-7,17,6,biomesoplenty:leaves_5:10)
Block(-6,17,6,biomesoplenty:leaves_5:10)
Block(-5,17,6,biomesoplenty:leaves_5:10)
Block(-4,17,6,biomesoplenty:leaves_5:10)
Block(-3,17,6,biomesoplenty:leaves_5:10)
Block(-2,17,6,biomesoplenty:leaves_5:10)
Block(-1,17,6,biomesoplenty:leaves_5:10)
Block(0,17,6,biomesoplenty:leaves_5:10)
Block(1,17,6,biomesoplenty:leaves_5:10)
Block(2,17,6,biomesoplenty:log_3:6)
Block(3,17,6,biomesoplenty:log_3:6)
Block(4,17,6,biomesoplenty:log_3:6)
Block(5,17,6,biomesoplenty:leaves_5:10)
Block(6,17,6,biomesoplenty:leaves_5:10)
Block(7,17,6,biomesoplenty:leaves_5:10)
Block(8,17,6,biomesoplenty:leaves_5:10)
Block(9,17,6,biomesoplenty:leaves_5:10)
Block(10,17,6,biomesoplenty:leaves_5:10)
Block(11,17,6,biomesoplenty:leaves_5:10)
Block(-8,17,7,biomesoplenty:leaves_5:10)
Block(-7,17,7,biomesoplenty:leaves_5:10)
Block(-6,17,7,biomesoplenty:leaves_5:10)
Block(-5,17,7,biomesoplenty:leaves_5:10)
Block(-4,17,7,biomesoplenty:leaves_5:10)
Block(-3,17,7,biomesoplenty:leaves_5:10)
Block(-2,17,7,biomesoplenty:leaves_5:10)
Block(-1,17,7,biomesoplenty:leaves_5:10)
Block(0,17,7,biomesoplenty:leaves_5:10)
Block(1,17,7,biomesoplenty:leaves_5:10)
Block(2,17,7,biomesoplenty:leaves_5:10)
Block(3,17,7,biomesoplenty:log_3:6)
Block(4,17,7,biomesoplenty:log_3:6)
Block(5,17,7,biomesoplenty:leaves_5:10)
Block(6,17,7,biomesoplenty:leaves_5:10)
Block(7,17,7,biomesoplenty:leaves_5:10)
Block(8,17,7,biomesoplenty:leaves_5:10)
Block(9,17,7,biomesoplenty:leaves_5:10)
Block(10,17,7,biomesoplenty:leaves_5:10)
Block(-7,17,8,biomesoplenty:leaves_5:10)
Block(-6,17,8,biomesoplenty:leaves_5:10)
Block(-5,17,8,biomesoplenty:leaves_5:10)
Block(-4,17,8,biomesoplenty:leaves_5:10)
Block(-3,17,8,biomesoplenty:leaves_5:10)
Block(-2,17,8,biomesoplenty:leaves_5:10)
Block(-1,17,8,biomesoplenty:leaves_5:10)
Block(0,17,8,biomesoplenty:leaves_5:10)
Block(1,17,8,biomesoplenty:leaves_5:10)
Block(2,17,8,biomesoplenty:leaves_5:10)
Block(3,17,8,biomesoplenty:leaves_5:10)
Block(4,17,8,biomesoplenty:leaves_5:10)
Block(5,17,8,biomesoplenty:leaves_5:10)
Block(6,17,8,biomesoplenty:leaves_5:10)
Block(7,17,8,biomesoplenty:leaves_5:10)
Block(8,17,8,biomesoplenty:leaves_5:10)
Block(-6,17,9,biomesoplenty:leaves_5:10)
Block(-5,17,9,biomesoplenty:leaves_5:10)
Block(-4,17,9,biomesoplenty:leaves_5:10)
Block(-3,17,9,biomesoplenty:leaves_5:10)
Block(-2,17,9,biomesoplenty:leaves_5:10)
Block(-1,17,9,biomesoplenty:leaves_5:10)
Block(0,17,9,biomesoplenty:leaves_5:10)
Block(1,17,9,biomesoplenty:leaves_5:10)
Block(2,17,9,biomesoplenty:leaves_5:10)
Block(3,17,9,biomesoplenty:leaves_5:10)
Block(4,17,9,biomesoplenty:leaves_5:10)
Block(5,17,9,biomesoplenty:leaves_5:10)
Block(6,17,9,biomesoplenty:leaves_5:10)
Block(7,17,9,biomesoplenty:leaves_5:10)
Block(-6,17,10,biomesoplenty:leaves_5:10)
Block(-4,17,10,biomesoplenty:leaves_5:10)
Block(-3,17,10,biomesoplenty:leaves_5:10)
Block(-2,17,10,biomesoplenty:leaves_5:10)
Block(0,17,10,biomesoplenty:leaves_5:10)
Block(1,17,10,biomesoplenty:leaves_5:10)
Block(2,17,10,biomesoplenty:leaves_5:10)
Block(3,17,10,biomesoplenty:leaves_5:10)
Block(4,17,10,biomesoplenty:leaves_5:10)
Block(5,17,10,biomesoplenty:leaves_5:10)
Block(-4,17,11,biomesoplenty:leaves_5:10)
Block(-3,17,11,biomesoplenty:leaves_5:10)
Block(-1,17,11,biomesoplenty:leaves_5:10)
Block(0,17,11,biomesoplenty:leaves_5:10)
Block(2,17,11,biomesoplenty:leaves_5:10)
Block(3,17,11,biomesoplenty:leaves_5:10)
Block(4,17,11,biomesoplenty:leaves_5:10)
Block(-4,18,-13,biomesoplenty:leaves_5:10)
Block(-3,18,-13,biomesoplenty:leaves_5:10)
Block(-2,18,-13,biomesoplenty:leaves_5:10)
Block(2,18,-13,biomesoplenty:leaves_5:10)
Block(3,18,-13,biomesoplenty:leaves_5:10)
Block(4,18,-13,biomesoplenty:leaves_5:10)
Block(-6,18,-12,biomesoplenty:leaves_5:10)
Block(-5,18,-12,biomesoplenty:leaves_5:10)
Block(-4,18,-12,biomesoplenty:leaves_5:10)
Block(-3,18,-12,biomesoplenty:leaves_5:10)
Block(-2,18,-12,biomesoplenty:leaves_5:10)
Block(-1,18,-12,biomesoplenty:leaves_5:10)
Block(0,18,-12,biomesoplenty:leaves_5:10)
Block(2,18,-12,biomesoplenty:leaves_5:10)
Block(3,18,-12,biomesoplenty:leaves_5:10)
Block(4,18,-12,biomesoplenty:leaves_5:10)
Block(-8,18,-11,biomesoplenty:leaves_5:10)
Block(-7,18,-11,biomesoplenty:log_3:6)
Block(-6,18,-11,biomesoplenty:log_3:6)
Block(-5,18,-11,biomesoplenty:log_3:6)
Block(-4,18,-11,biomesoplenty:leaves_5:10)
Block(-3,18,-11,biomesoplenty:leaves_5:10)
Block(-2,18,-11,biomesoplenty:leaves_5:10)
Block(-1,18,-11,biomesoplenty:leaves_5:10)
Block(0,18,-11,biomesoplenty:leaves_5:10)
Block(1,18,-11,biomesoplenty:leaves_5:10)
Block(2,18,-11,biomesoplenty:leaves_5:10)
Block(3,18,-11,biomesoplenty:log_3:6)
Block(4,18,-11,biomesoplenty:leaves_5:10)
Block(5,18,-11,biomesoplenty:leaves_5:10)
Block(6,18,-11,biomesoplenty:leaves_5:10)
Block(7,18,-11,biomesoplenty:leaves_5:10)
Block(-10,18,-10,biomesoplenty:leaves_5:10)
Block(-9,18,-10,biomesoplenty:leaves_5:10)
Block(-8,18,-10,biomesoplenty:leaves_5:10)
Block(-7,18,-10,biomesoplenty:log_3:6)
Block(-6,18,-10,biomesoplenty:log_3:6)
Block(-5,18,-10,biomesoplenty:log_3:6)
Block(-4,18,-10,biomesoplenty:leaves_5:10)
Block(-3,18,-10,biomesoplenty:leaves_5:10)
Block(-2,18,-10,biomesoplenty:leaves_5:10)
Block(-1,18,-10,biomesoplenty:leaves_5:10)
Block(0,18,-10,biomesoplenty:leaves_5:10)
Block(1,18,-10,biomesoplenty:leaves_5:10)
Block(2,18,-10,biomesoplenty:log_3:6)
Block(3,18,-10,biomesoplenty:log_3:6)
Block(4,18,-10,biomesoplenty:log_3:6)
Block(5,18,-10,biomesoplenty:leaves_5:10)
Block(6,18,-10,biomesoplenty:leaves_5:10)
Block(7,18,-10,biomesoplenty:leaves_5:10)
Block(8,18,-10,biomesoplenty:leaves_5:10)
Block(9,18,-10,biomesoplenty:leaves_5:10)
Block(10,18,-10,biomesoplenty:leaves_5:10)
Block(11,18,-10,biomesoplenty:leaves_5:10)
Block(-11,18,-9,biomesoplenty:leaves_5:10)
Block(-9,18,-9,biomesoplenty:leaves_5:10)
Block(-8,18,-9,biomesoplenty:leaves_5:10)
Block(-7,18,-9,biomesoplenty:log_3:6)
Block(-6,18,-9,biomesoplenty:log_3:6)
Block(-5,18,-9,biomesoplenty:log_3:6)
Block(-4,18,-9,biomesoplenty:leaves_5:10)
Block(-3,18,-9,biomesoplenty:leaves_5:10)
Block(-2,18,-9,biomesoplenty:leaves_5:10)
Block(-1,18,-9,biomesoplenty:leaves_5:10)
Block(0,18,-9,biomesoplenty:leaves_5:10)
Block(1,18,-9,biomesoplenty:log_3:6)
Block(2,18,-9,biomesoplenty:log_3:6)
Block(3,18,-9,biomesoplenty:log_3:6)
Block(4,18,-9,biomesoplenty:log_3:6)
Block(5,18,-9,biomesoplenty:leaves_5:10)
Block(6,18,-9,biomesoplenty:leaves_5:10)
Block(7,18,-9,biomesoplenty:leaves_5:10)
Block(8,18,-9,biomesoplenty:leaves_5:10)
Block(9,18,-9,biomesoplenty:leaves_5:10)
Block(10,18,-9,biomesoplenty:leaves_5:10)
Block(11,18,-9,biomesoplenty:leaves_5:10)
Block(-11,18,-8,biomesoplenty:leaves_5:10)
Block(-9,18,-8,biomesoplenty:leaves_5:10)
Block(-8,18,-8,biomesoplenty:leaves_5:10)
Block(-7,18,-8,biomesoplenty:log_3:6)
Block(-6,18,-8,biomesoplenty:log_3:6)
Block(-5,18,-8,biomesoplenty:log_3:6)
Block(-4,18,-8,biomesoplenty:leaves_5:10)
Block(-2,18,-8,biomesoplenty:leaves_5:10)
Block(-1,18,-8,biomesoplenty:leaves_5:10)
Block(0,18,-8,biomesoplenty:leaves_5:10)
Block(1,18,-8,biomesoplenty:log_3:6)
Block(2,18,-8,biomesoplenty:log_3:6)
Block(3,18,-8,biomesoplenty:log_3:6)
Block(4,18,-8,biomesoplenty:log_3:6)
Block(5,18,-8,biomesoplenty:leaves_5:10)
Block(6,18,-8,biomesoplenty:leaves_5:10)
Block(7,18,-8,biomesoplenty:leaves_5:10)
Block(8,18,-8,biomesoplenty:leaves_5:10)
Block(9,18,-8,biomesoplenty:leaves_5:10)
Block(10,18,-8,biomesoplenty:leaves_5:10)
Block(12,18,-8,biomesoplenty:leaves_5:10)
Block(-12,18,-7,biomesoplenty:leaves_5:10)
Block(-11,18,-7,biomesoplenty:leaves_5:10)
Block(-10,18,-7,biomesoplenty:leaves_5:10)
Block(-9,18,-7,biomesoplenty:leaves_5:10)
Block(-8,18,-7,biomesoplenty:leaves_5:10)
Block(-7,18,-7,biomesoplenty:log_3:6)
Block(-6,18,-7,biomesoplenty:log_3:6)
Block(-5,18,-7,biomesoplenty:log_3:6)
Block(-4,18,-7,biomesoplenty:log_3:6)
Block(-3,18,-7,biomesoplenty:leaves_5:10)
Block(-2,18,-7,biomesoplenty:leaves_5:10)
Block(-1,18,-7,biomesoplenty:leaves_5:10)
Block(0,18,-7,biomesoplenty:leaves_5:10)
Block(1,18,-7,biomesoplenty:log_3:6)
Block(2,18,-7,biomesoplenty:log_3:6)
Block(3,18,-7,biomesoplenty:log_3:6)
Block(4,18,-7,biomesoplenty:leaves_5:10)
Block(6,18,-7,biomesoplenty:leaves_5:10)
Block(7,18,-7,biomesoplenty:leaves_5:10)
Block(8,18,-7,biomesoplenty:leaves_5:10)
Block(9,18,-7,biomesoplenty:leaves_5:10)
Block(10,18,-7,biomesoplenty:leaves_5:10)
Block(12,18,-7,biomesoplenty:leaves_5:10)
Block(-11,18,-6,biomesoplenty:leaves_5:10)
Block(-10,18,-6,biomesoplenty:leaves_5:10)
Block(-9,18,-6,biomesoplenty:leaves_5:10)
Block(-8,18,-6,biomesoplenty:leaves_5:10)
Block(-7,18,-6,biomesoplenty:log_3:6)
Block(-6,18,-6,biomesoplenty:log_3:6)
Block(-5,18,-6,biomesoplenty:log_3:6)
Block(-4,18,-6,biomesoplenty:log_3:6)
Block(-3,18,-6,biomesoplenty:log_3:6)
Block(-2,18,-6,biomesoplenty:leaves_5:10)
Block(-1,18,-6,biomesoplenty:leaves_5:10)
Block(0,18,-6,biomesoplenty:leaves_5:10)
Block(1,18,-6,biomesoplenty:log_3:6)
Block(2,18,-6,biomesoplenty:log_3:6)
Block(3,18,-6,biomesoplenty:log_3:6)
Block(4,18,-6,biomesoplenty:leaves_5:10)
Block(5,18,-6,biomesoplenty:leaves_5:10)
Block(6,18,-6,biomesoplenty:leaves_5:10)
Block(7,18,-6,biomesoplenty:leaves_5:10)
Block(8,18,-6,biomesoplenty:leaves_5:10)
Block(9,18,-6,biomesoplenty:leaves_5:10)
Block(10,18,-6,biomesoplenty:leaves_5:10)
Block(-11,18,-5,biomesoplenty:leaves_5:10)
Block(-10,18,-5,biomesoplenty:leaves_5:10)
Block(-9,18,-5,biomesoplenty:leaves_5:10)
Block(-8,18,-5,biomesoplenty:leaves_5:10)
Block(-7,18,-5,biomesoplenty:leaves_5:10)
Block(-6,18,-5,biomesoplenty:log_3:6)
Block(-5,18,-5,biomesoplenty:log_3:6)
Block(-4,18,-5,biomesoplenty:log_3:6)
Block(-3,18,-5,biomesoplenty:log_3:6)
Block(-2,18,-5,biomesoplenty:log_3:6)
Block(-1,18,-5,biomesoplenty:leaves_5:10)
Block(0,18,-5,biomesoplenty:leaves_5:10)
Block(1,18,-5,biomesoplenty:log_3:6)
Block(2,18,-5,biomesoplenty:log_3:6)
Block(3,18,-5,biomesoplenty:log_3:6)
Block(4,18,-5,biomesoplenty:leaves_5:10)
Block(5,18,-5,biomesoplenty:leaves_5:10)
Block(6,18,-5,biomesoplenty:leaves_5:10)
Block(7,18,-5,biomesoplenty:leaves_5:10)
Block(8,18,-5,biomesoplenty:leaves_5:10)
Block(9,18,-5,biomesoplenty:leaves_5:10)
Block(10,18,-5,biomesoplenty:leaves_5:10)
Block(11,18,-5,biomesoplenty:leaves_5:10)
Block(12,18,-5,biomesoplenty:leaves_5:10)
Block(-10,18,-4,biomesoplenty:leaves_5:10)
Block(-9,18,-4,biomesoplenty:leaves_5:10)
Block(-8,18,-4,biomesoplenty:leaves_5:10)
Block(-7,18,-4,biomesoplenty:leaves_5:10)
Block(-6,18,-4,biomesoplenty:leaves_5:10)
Block(-5,18,-4,biomesoplenty:leaves_5:10)
Block(-4,18,-4,biomesoplenty:leaves_5:10)
Block(-3,18,-4,biomesoplenty:log_3:6)
Block(-2,18,-4,biomesoplenty:log_3:6)
Block(-1,18,-4,biomesoplenty:log_3:6)
Block(0,18,-4,biomesoplenty:leaves_5:10)
Block(1,18,-4,biomesoplenty:log_3:6)
Block(2,18,-4,biomesoplenty:log_3:6)
Block(3,18,-4,biomesoplenty:log_3:6)
Block(4,18,-4,biomesoplenty:leaves_5:10)
Block(5,18,-4,biomesoplenty:leaves_5:10)
Block(6,18,-4,biomesoplenty:leaves_5:10)
Block(7,18,-4,biomesoplenty:leaves_5:10)
Block(8,18,-4,biomesoplenty:log_3:6)
Block(9,18,-4,biomesoplenty:log_3:6)
Block(10,18,-4,biomesoplenty:log_3:6)
Block(11,18,-4,biomesoplenty:leaves_5:10)
Block(12,18,-4,biomesoplenty:leaves_5:10)
Block(13,18,-4,biomesoplenty:leaves_5:10)
Block(-11,18,-3,biomesoplenty:leaves_5:10)
Block(-10,18,-3,biomesoplenty:leaves_5:10)
Block(-9,18,-3,biomesoplenty:leaves_5:10)
Block(-8,18,-3,biomesoplenty:leaves_5:10)
Block(-7,18,-3,biomesoplenty:leaves_5:10)
Block(-6,18,-3,biomesoplenty:leaves_5:10)
Block(-5,18,-3,biomesoplenty:leaves_5:10)
Block(-4,18,-3,biomesoplenty:leaves_5:10)
Block(-3,18,-3,biomesoplenty:leaves_5:10)
Block(-2,18,-3,biomesoplenty:log_3:6)
Block(-1,18,-3,biomesoplenty:log_3:6)
Block(0,18,-3,biomesoplenty:log_3:6)
Block(1,18,-3,biomesoplenty:log_3:6)
Block(2,18,-3,biomesoplenty:log_3:6)
Block(3,18,-3,biomesoplenty:log_3:6)
Block(4,18,-3,biomesoplenty:log_3:6)
Block(5,18,-3,biomesoplenty:log_3:6)
Block(6,18,-3,biomesoplenty:log_3:6)
Block(7,18,-3,biomesoplenty:log_3:6)
Block(8,18,-3,biomesoplenty:log_3:6)
Block(9,18,-3,biomesoplenty:log_3:6)
Block(10,18,-3,biomesoplenty:log_3:6)
Block(11,18,-3,biomesoplenty:log_3:6)
Block(12,18,-3,biomesoplenty:leaves_5:10)
Block(13,18,-3,biomesoplenty:leaves_5:10)
Block(-11,18,-2,biomesoplenty:leaves_5:10)
Block(-10,18,-2,biomesoplenty:leaves_5:10)
Block(-9,18,-2,biomesoplenty:leaves_5:10)
Block(-8,18,-2,biomesoplenty:leaves_5:10)
Block(-7,18,-2,biomesoplenty:leaves_5:10)
Block(-6,18,-2,biomesoplenty:leaves_5:10)
Block(-5,18,-2,biomesoplenty:leaves_5:10)
Block(-4,18,-2,biomesoplenty:leaves_5:10)
Block(-3,18,-2,biomesoplenty:leaves_5:10)
Block(-2,18,-2,biomesoplenty:log_3:6)
Block(-1,18,-2,biomesoplenty:log_3:6)
Block(0,18,-2,biomesoplenty:log_3:6)
Block(1,18,-2,biomesoplenty:log_3:6)
Block(2,18,-2,biomesoplenty:log_3:6)
Block(3,18,-2,biomesoplenty:log_3:6)
Block(4,18,-2,biomesoplenty:log_3:6)
Block(5,18,-2,biomesoplenty:log_3:6)
Block(6,18,-2,biomesoplenty:log_3:6)
Block(7,18,-2,biomesoplenty:log_3:6)
Block(8,18,-2,biomesoplenty:log_3:6)
Block(9,18,-2,biomesoplenty:log_3:6)
Block(10,18,-2,biomesoplenty:log_3:6)
Block(11,18,-2,biomesoplenty:leaves_5:10)
Block(12,18,-2,biomesoplenty:leaves_5:10)
Block(13,18,-2,biomesoplenty:leaves_5:10)
Block(-12,18,-1,biomesoplenty:leaves_5:10)
Block(-11,18,-1,biomesoplenty:leaves_5:10)
