{ 
    "registryname": "Industrial_Chiller", 
    "localizedname": "Industrial_Chiller", 
    "requires-blueprint": true, 
    "color": "7BFCE3", 
    "parts": [
        {
            "x": 1,
            "y": 2,
            "z": 1,
            "elements": [
                "quark:snow_bricks@0"
            ]
        },
        {
            "x": -1,
            "y": 0,
            "z": 0,
            "elements": [
                "quark:snow_bricks@0"
            ]
        },
        {
            "x": -1,
            "y": 0,
            "z": 1,
            "nbt": {"busSize":"0","casingColor":"15201527","id":"minecraft:tileitemoutputbus","inventory":{"inventoryArray":[{"holderEmpty":"1b","holderId":"0"}],"outSlots":,"miscSlots":,"inSlots":,"sides":}},
            "elements": [
                "modularmachinery:blockoutputbus@0"
            ]
        },
        {
            "x": 0,
            "y": 2,
            "z": 2,
            "elements": [
                "quark:snow_bricks@0"
            ]
        },
        {
            "x": 0,
            "y": 0,
            "z": 1,
            "elements": [
                "thermalfoundation:fluid_cryotheum@0"
            ]
        },
        {
            "x": 1,
            "y": 2,
            "z": 2,
            "elements": [
                "quark:snow_bricks@0"
            ]
        },
        {
            "x": 1,
            "y": 0,
            "z": 0,
            "elements": [
                "quark:snow_bricks@0"
            ]
        },
        {
            "x": -1,
            "y": 0,
            "z": 2,
            "elements": [
                "quark:snow_bricks@0"
            ]
        },
        {
            "x": 1,
            "y": 0,
            "z": 1,
            "nbt": {"busSize":"0","casingColor":"15201527","id":"minecraft:tileiteminputbus","inventory":{"inventoryArray":[{"holderEmpty":"1b","holderId":"0"}],"outSlots":,"miscSlots":,"inSlots":,"sides":}},
            "elements": [
                "modularmachinery:blockinputbus@0"
            ]
        },
        {
            "x": 0,
            "y": 0,
            "z": 2,
            "nbt": {"hatchSize":"0","casingColor":"15201527","ForgeCaps":{"ic2:capproviders":{"Data":[{"ic2.core.platform.capabilities.energy.SinkLimiterHandler":{},"IC2ProviderSide":"6"}]}},"id":"minecraft:tileenergyinputhatch","energy":"0L"},
            "elements": [
                "modularmachinery:blockenergyinputhatch@0"
            ]
        },
        {
            "x": 1,
            "y": 0,
            "z": 2,
            "elements": [
                "quark:snow_bricks@0"
            ]
        },
        {
            "x": 1,
            "y": -1,
            "z": 0,
            "elements": [
                "quark:snow_bricks@0"
            ]
        },
        {
            "x": 0,
            "y": -1,
            "z": 0,
            "elements": [
                "quark:snow_bricks@0"
            ]
        },
        {
            "x": -1,
            "y": 1,
            "z": 0,
            "elements": [
                "quark:snow_bricks@0"
            ]
        },
        {
            "x": -1,
            "y": -1,
            "z": 0,
            "elements": [
                "quark:snow_bricks@0"
            ]
        },
        {
            "x": 0,
            "y": 1,
            "z": 0,
            "nbt": {"casingColor":"15201527","id":"minecraft:tilecolorablemachinecomponent"},
            "elements": [
                "modularmachinery:blockcasing@1"
            ]
        },
        {
            "x": -1,
            "y": 1,
            "z": 1,
            "nbt": {"casingColor":"15201527","id":"minecraft:tilecolorablemachinecomponent"},
            "elements": [
                "modularmachinery:blockcasing@1"
            ]
        },
        {
            "x": 0,
            "y": 1,
            "z": 1,
            "elements": [
                "thermalfoundation:fluid_cryotheum@0"
            ]
        },
        {
            "x": 1,
            "y": 1,
            "z": 0,
            "elements": [
                "quark:snow_bricks@0"
            ]
        },
        {
            "x": -1,
            "y": 1,
            "z": 2,
            "elements": [
                "quark:snow_bricks@0"
            ]
        },
        {
            "x": 1,
            "y": 1,
            "z": 1,
            "nbt": {"casingColor":"15201527","id":"minecraft:tilecolorablemachinecomponent"},
            "elements": [
                "modularmachinery:blockcasing@1"
            ]
        },
        {
            "x": -1,
            "y": -1,
            "z": 1,
            "elements": [
                "quark:snow_bricks@0"
            ]
        },
        {
            "x": 0,
            "y": 1,
            "z": 2,
            "nbt": {"casingColor":"15201527","id":"minecraft:tilecolorablemachinecomponent"},
            "elements": [
                "modularmachinery:blockcasing@1"
            ]
        },
        {
            "x": 0,
            "y": -1,
            "z": 1,
            "nbt": {"casingColor":"15201527","id":"minecraft:tilecolorablemachinecomponent"},
            "elements": [
                "modularmachinery:blockcasing@1"
            ]
        },
        {
            "x": 1,
            "y": 1,
            "z": 2,
            "elements": [
                "quark:snow_bricks@0"
            ]
        },
        {
            "x": -1,
            "y": -1,
            "z": 2,
            "elements": [
                "quark:snow_bricks@0"
            ]
        },
        {
            "x": 1,
            "y": -1,
            "z": 1,
            "elements": [
                "quark:snow_bricks@0"
            ]
        },
        {
            "x": 0,
            "y": -1,
            "z": 2,
            "elements": [
                "quark:snow_bricks@0"
            ]
        },
        {
            "x": 1,
            "y": -1,
            "z": 2,
            "elements": [
                "quark:snow_bricks@0"
            ]
        },
        {
            "x": -1,
            "y": 2,
            "z": 0,
            "elements": [
                "quark:snow_bricks@0"
            ]
        },
        {
            "x": 0,
            "y": 2,
            "z": 0,
            "elements": [
                "quark:snow_bricks@0"
            ]
        },
        {
            "x": -1,
            "y": 2,
            "z": 1,
            "elements": [
                "quark:snow_bricks@0"
            ]
        },
        {
            "x": 1,
            "y": 2,
            "z": 0,
            "elements": [
                "quark:snow_bricks@0"
            ]
        },
        {
            "x": -1,
            "y": 2,
            "z": 2,
            "elements": [
                "quark:snow_bricks@0"
            ]
        },
        {
            "x": 0,
            "y": 2,
            "z": 1,
            "nbt": {"input":"1b","size":"0","casingColor":"15201527","id":"minecraft:tilefluidinputhatch","tank":{"Empty":""}},
            "elements": [
                "modularmachinery:blockfluidinputhatch@0"
            ]
        }
    ]}