#######################################################################
# +-----------------------------------------------------------------+ #
# |                            BO3 object                           | #
# +-----------------------------------------------------------------+ #
#######################################################################

# The descriptions in this file are accurate only for TerrainControl and OTG.
# For MCW and OTG+ these descriptions are only accurate if the BO3 is used as a CustomObject.
# MCW and OTG+ completely reimplemented CustomStructure, check the MCW/OTG+ documentation for more information.

# This is the config file of a custom object.
# If you add this object correctly to your BiomeConfigs, it will spawn in the world.

# This is the creator of this BO3 object
Author: Unknown

# A short description of this BO3 object
Description: This BO3 was converted from a schematic using OTGEdit. The author and description information of the schematic could not be found. If you know who the author of the schematic is then please add this information.

# The BO3 version, don't change this! It can be used by external applications to do a version check.
Version: 3

# The settings mode, WriteAll, WriteWithoutComments or WriteDisable. See WorldConfig.
SettingsMode: WriteDisable

#######################################################################
# +-----------------------------------------------------------------+ #
# |                          Main settings                          | #
# +-----------------------------------------------------------------+ #
#######################################################################

# This needs to be set to true to spawn the object in the Tree and Sapling resources.
Tree: true

# The frequency of the BO3 from 1 to 200. Tries this many times to spawn this BO3 when using the CustomObject(...) resource.
# Ignored by Tree(..), Sapling(..) and CustomStructure(..)
Frequency: 40

# The rarity of the BO3 from 0 to 100. Each spawn attempt has rarity% chance to succeed when using the CustomObject(...) resource.
# Ignored by Tree(..), Sapling(..) and CustomStructure(..)
Rarity: 100.0

# If you set this to true, the BO3 will be placed with a random rotation.
RotateRandomly: true

# The spawn height of the BO3 - randomY, highestBlock or highestSolidBlock.
SpawnHeight: randomY

# The height limits for the BO3.
MinHeight: 0

MaxHeight: 256

# Objects can have other objects attached to it: branches. Branches can also
# have branches attached to it, which can also have branches, etc. This is the
# maximum branch depth for this objects.
MaxBranchDepth: 10

# When spawned with the UseWorld keyword, this BO3 should NOT spawn in the following biomes.
# If you writer.write the BO3 name directly in the BiomeConfigs, this will be ignored.
ExcludedBiomes: All

# To optimise this BO3 for faster loading times you can use Notepad++ to find/replace comments and abbreviate things.
# Notepad++ find/replace with regex:
# Find: ^[#;].* replace to nothing removes all lines starting with # 
# Find: ^\s*$ replace to nothing removes most empty lines 
# Notepad++ find/replace without regex:
# *Warning: This will only work for OTG 1.10.2 v21 / OTG 1.11.2 v6 or higher. B( is not recognised by lower versions.
# Find: Block( replace to B(

#######################################################################
# +-----------------------------------------------------------------+ #
# |                      Source block settings                      | #
# +-----------------------------------------------------------------+ #
#######################################################################

# The block(s) the BO3 should spawn in.
SourceBlocks: AIR

# The maximum percentage of the BO3 that can be outside the SourceBlock.
# The BO3 won't be placed on a location with more blocks outside the SourceBlock than this percentage.
MaxPercentageOutsideSourceBlock: 100

# What to do when a block is about to be placed outside the SourceBlock? (dontPlace, placeAnyway)
OutsideSourceBlock: placeAnyway

#######################################################################
# +-----------------------------------------------------------------+ #
# |                              Blocks                             | #
# +-----------------------------------------------------------------+ #
#######################################################################

# All the blocks used in the BO3 are listed here. Possible blocks:
# Block(x,y,z,id[.data][,nbtfile.nbt) or B(x,y,z,id[.data][,nbtfile.nbt)
# RandomBlock(x,y,z,id[:data][,nbtfile.nbt],chance[,id[:data][,nbtfile.nbt],chance[,...]])
# So RandomBlock(0,0,0,CHEST,chest.nbt,50,CHEST,anotherchest.nbt,100) will spawn a chest at
# the BO3 origin, and give it a 50% chance to have the contents of chest.nbt, or, if that
# fails, a 100% percent chance to have the contents of anotherchest.nbt.

Block(-15,21,0,18:1)
Block(-15,22,0,18:1)
Block(-15,23,-1,18:1)
Block(-14,20,0,18:1)
Block(-14,21,0,18:1)
Block(-14,21,1,18:1)
Block(-14,21,2,18:1)
Block(-14,22,-1,18:1)
Block(-14,22,1,18:1)
Block(-14,23,-1,18:1)
Block(-14,23,2,18:1)
Block(-14,24,1,18:1)
Block(-13,20,-1,18:1)
Block(-13,20,0,18:1)
Block(-13,21,-7,18:1)
Block(-13,21,-6,18:1)
Block(-13,21,-5,18:1)
Block(-13,21,-4,18:1)
Block(-13,21,-3,18:1)
Block(-13,21,-2,18:1)
Block(-13,21,0,18:1)
Block(-13,21,1,18:1)
Block(-13,21,4,18:1)
Block(-13,21,6,18:1)
Block(-13,21,8,18:1)
Block(-13,22,-7,18:1)
Block(-13,22,-4,18:1)
Block(-13,22,-3,18:1)
Block(-13,22,-2,18:1)
Block(-13,22,-1,18:1)
Block(-13,22,0,17:4)
Block(-13,22,1,18:1)
Block(-13,22,2,18:1)
Block(-13,22,3,18:1)
Block(-13,22,4,18:1)
Block(-13,22,7,18:1)
Block(-13,23,-7,18:1)
Block(-13,23,-4,18:1)
Block(-13,23,-2,18:1)
Block(-13,23,-1,18:1)
Block(-13,23,0,18:1)
Block(-13,23,1,18:1)
Block(-13,23,3,18:1)
Block(-13,23,5,18:1)
Block(-13,23,6,18:1)
Block(-13,23,7,18:1)
Block(-13,24,0,18:1)
Block(-13,24,1,18:1)
Block(-12,20,-8,18:1)
Block(-12,20,-7,18:1)
Block(-12,20,-5,18:1)
Block(-12,20,-1,18:1)
Block(-12,20,0,18:1)
Block(-12,20,6,18:1)
Block(-12,20,7,18:1)
Block(-12,21,-10,18:1)
Block(-12,21,-6,18:1)
Block(-12,21,-4,18:1)
Block(-12,21,-3,18:1)
Block(-12,21,-2,18:1)
Block(-12,21,0,18:1)
Block(-12,21,2,18:1)
Block(-12,21,4,18:1)
Block(-12,21,5,18:1)
Block(-12,21,6,18:1)
Block(-12,21,7,18:1)
Block(-12,21,8,18:1)
Block(-12,21,9,18:1)
Block(-12,21,10,18:1)
Block(-12,22,-10,18:1)
Block(-12,22,-9,18:1)
Block(-12,22,-8,18:1)
Block(-12,22,-7,18:1)
Block(-12,22,-5,18:1)
Block(-12,22,-4,18:1)
Block(-12,22,-3,18:1)
Block(-12,22,-2,18:1)
Block(-12,22,-1,18:1)
Block(-12,22,0,17:4)
Block(-12,22,1,18:1)
Block(-12,22,2,18:1)
Block(-12,22,4,18:1)
Block(-12,22,5,18:1)
Block(-12,22,7,18:1)
Block(-12,22,8,18:1)
Block(-12,22,10,18:1)
Block(-12,22,11,18:1)
Block(-12,23,-11,18:1)
Block(-12,23,-9,18:1)
Block(-12,23,-8,18:1)
Block(-12,23,-7,18:1)
Block(-12,23,-6,18:1)
Block(-12,23,-5,18:1)
Block(-12,23,-3,18:1)
Block(-12,23,-2,18:1)
Block(-12,23,-1,18:1)
Block(-12,23,0,18:1)
Block(-12,23,1,18:1)
Block(-12,23,5,18:1)
Block(-12,23,6,18:1)
Block(-12,23,7,18:1)
Block(-12,23,8,18:1)
Block(-12,24,-7,18:1)
Block(-12,24,-1,18:1)
Block(-12,24,0,18:1)
Block(-12,24,1,18:1)
Block(-12,24,3,18:1)
Block(-12,24,4,18:1)
Block(-12,24,7,18:1)
Block(-12,24,8,18:1)
Block(-12,25,0,18:1)
Block(-11,20,-10,18:1)
Block(-11,20,-8,18:1)
Block(-11,20,-7,18:1)
Block(-11,20,-6,18:1)
Block(-11,20,-5,18:1)
Block(-11,20,-4,18:1)
Block(-11,20,-2,18:1)
Block(-11,20,0,18:1)
Block(-11,20,3,18:1)
Block(-11,20,4,18:1)
Block(-11,20,7,18:1)
Block(-11,20,8,18:1)
Block(-11,20,9,18:1)
Block(-11,21,-12,18:1)
Block(-11,21,-10,18:1)
Block(-11,21,-9,18:1)
Block(-11,21,-8,18:1)
Block(-11,21,-7,18:1)
Block(-11,21,-6,18:1)
Block(-11,21,-4,18:1)
Block(-11,21,-3,18:1)
Block(-11,21,-1,18:1)
Block(-11,21,0,18:1)
Block(-11,21,1,18:1)
Block(-11,21,2,18:1)
Block(-11,21,3,18:1)
Block(-11,21,4,18:1)
Block(-11,21,5,18:1)
Block(-11,21,6,18:1)
Block(-11,21,7,18:1)
Block(-11,21,8,18:1)
Block(-11,21,9,18:1)
Block(-11,21,10,18:1)
Block(-11,21,11,18:1)
Block(-11,22,-12,18:1)
Block(-11,22,-10,17:4)
Block(-11,22,-9,18:1)
Block(-11,22,-8,18:1)
Block(-11,22,-7,17:4)
Block(-11,22,-6,18:1)
Block(-11,22,-5,18:1)
Block(-11,22,-4,17:8)
Block(-11,22,-3,17:8)
Block(-11,22,-2,17:8)
Block(-11,22,-1,17:8)
Block(-11,22,0,17:4)
Block(-11,22,1,17:8)
Block(-11,22,2,17:8)
Block(-11,22,3,17:8)
Block(-11,22,4,17:8)
Block(-11,22,5,18:1)
Block(-11,22,6,18:1)
Block(-11,22,7,17:8)
Block(-11,22,8,18:1)
Block(-11,22,9,18:1)
Block(-11,22,10,17:4)
Block(-11,22,12,18:1)
Block(-11,23,-12,18:1)
Block(-11,23,-11,18:1)
Block(-11,23,-10,18:1)
Block(-11,23,-9,18:1)
Block(-11,23,-7,18:1)
Block(-11,23,-6,18:1)
Block(-11,23,-5,18:1)
Block(-11,23,-3,18:1)
Block(-11,23,-2,18:1)
Block(-11,23,-1,18:1)
Block(-11,23,0,18:1)
Block(-11,23,1,18:1)
Block(-11,23,2,18:1)
Block(-11,23,3,18:1)
Block(-11,23,4,18:1)
Block(-11,23,6,18:1)
Block(-11,23,7,18:1)
Block(-11,23,9,18:1)
Block(-11,24,-11,18:1)
Block(-11,24,-10,18:1)
Block(-11,24,-5,18:1)
Block(-11,24,-4,18:1)
Block(-11,24,-1,18:1)
Block(-11,24,0,18:1)
Block(-11,24,1,18:1)
Block(-11,24,2,18:1)
Block(-11,24,3,18:1)
Block(-11,24,4,18:1)
Block(-11,24,5,18:1)
Block(-11,24,7,18:1)
Block(-11,24,9,18:1)
Block(-11,24,10,18:1)
Block(-11,24,11,18:1)
Block(-11,25,2,18:1)
Block(-10,20,-11,18:1)
Block(-10,20,-10,18:1)
Block(-10,20,-8,18:1)
Block(-10,20,-7,18:1)
Block(-10,20,-2,18:1)
Block(-10,20,-1,18:1)
Block(-10,20,4,18:1)
Block(-10,20,6,18:1)
Block(-10,20,8,18:1)
Block(-10,20,9,18:1)
Block(-10,20,10,18:1)
Block(-10,20,11,18:1)
Block(-10,21,-10,18:1)
Block(-10,21,-9,18:1)
Block(-10,21,-8,18:1)
Block(-10,21,-7,18:1)
Block(-10,21,-6,18:1)
Block(-10,21,-5,18:1)
Block(-10,21,-4,18:1)
Block(-10,21,-3,18:1)
Block(-10,21,-1,18:1)
Block(-10,21,0,18:1)
Block(-10,21,1,18:1)
Block(-10,21,3,18:1)
Block(-10,21,4,18:1)
Block(-10,21,5,18:1)
Block(-10,21,6,18:1)
Block(-10,21,8,18:1)
Block(-10,21,9,18:1)
Block(-10,21,10,18:1)
Block(-10,21,11,18:1)
Block(-10,22,-12,18:1)
Block(-10,22,-11,17:8)
Block(-10,22,-10,17:4)
Block(-10,22,-9,18:1)
Block(-10,22,-8,17:4)
Block(-10,22,-7,18:1)
Block(-10,22,-6,18:1)
Block(-10,22,-5,18:1)
Block(-10,22,-4,18:1)
Block(-10,22,-3,18:1)
Block(-10,22,-2,18:1)
Block(-10,22,-1,18:1)
Block(-10,22,0,17:4)
Block(-10,22,1,18:1)
Block(-10,22,2,18:1)
Block(-10,22,3,18:1)
Block(-10,22,4,18:1)
Block(-10,22,5,18:1)
Block(-10,22,6,18:1)
Block(-10,22,8,17:8)
Block(-10,22,9,18:1)
Block(-10,22,10,17:8)
Block(-10,22,11,17:8)
Block(-10,22,12,18:1)
Block(-10,23,-11,18:1)
Block(-10,23,-10,18:1)
Block(-10,23,-9,18:1)
Block(-10,23,-8,18:1)
Block(-10,23,-7,18:1)
Block(-10,23,-6,18:1)
Block(-10,23,-5,18:1)
Block(-10,23,-4,18:1)
Block(-10,23,-3,18:1)
Block(-10,23,-2,18:1)
Block(-10,23,-1,18:1)
Block(-10,23,0,18:1)
Block(-10,23,1,18:1)
Block(-10,23,3,18:1)
Block(-10,23,4,18:1)
Block(-10,23,5,18:1)
Block(-10,23,7,18:1)
Block(-10,23,8,18:1)
Block(-10,23,9,18:1)
Block(-10,23,10,18:1)
Block(-10,23,12,18:1)
Block(-10,24,-11,18:1)
Block(-10,24,-10,18:1)
Block(-10,24,-2,18:1)
Block(-10,24,-1,18:1)
Block(-10,24,0,18:1)
Block(-10,24,2,18:1)
Block(-10,24,3,18:1)
Block(-10,24,4,18:1)
Block(-10,24,5,18:1)
Block(-10,24,7,18:1)
Block(-10,24,8,18:1)
Block(-10,24,9,18:1)
Block(-10,24,10,18:1)
Block(-10,24,11,18:1)
Block(-9,19,-4,18:1)
Block(-9,19,0,18:1)
Block(-9,19,6,18:1)
Block(-9,20,-11,18:1)
Block(-9,20,-10,18:1)
Block(-9,20,-8,18:1)
Block(-9,20,-7,18:1)
Block(-9,20,-3,18:1)
Block(-9,20,-1,18:1)
Block(-9,20,0,18:1)
Block(-9,20,1,18:1)
Block(-9,20,2,18:1)
Block(-9,20,5,18:1)
Block(-9,20,7,18:1)
Block(-9,20,8,18:1)
Block(-9,20,9,18:1)
Block(-9,20,10,18:1)
Block(-9,20,11,18:1)
Block(-9,21,-12,18:1)
Block(-9,21,-10,18:1)
Block(-9,21,-9,18:1)
Block(-9,21,-8,18:1)
Block(-9,21,-7,18:1)
Block(-9,21,-6,18:1)
Block(-9,21,-5,18:1)
Block(-9,21,-3,18:1)
Block(-9,21,-2,18:1)
Block(-9,21,-1,18:1)
Block(-9,21,0,17:4)
Block(-9,21,1,18:1)
Block(-9,21,2,18:1)
Block(-9,21,3,18:1)
Block(-9,21,4,18:1)
Block(-9,21,5,18:1)
Block(-9,21,7,18:1)
Block(-9,21,10,18:1)
Block(-9,22,-12,18:1)
Block(-9,22,-11,18:1)
Block(-9,22,-10,18:1)
Block(-9,22,-9,17:4)
Block(-9,22,-8,18:1)
Block(-9,22,-7,18:1)
Block(-9,22,-4,18:1)
Block(-9,22,-3,18:1)
Block(-9,22,-2,18:1)
Block(-9,22,-1,18:1)
Block(-9,22,0,18:1)
Block(-9,22,1,18:1)
Block(-9,22,2,18:1)
Block(-9,22,3,18:1)
Block(-9,22,4,18:1)
Block(-9,22,5,18:1)
Block(-9,22,6,18:1)
Block(-9,22,8,18:1)
Block(-9,22,9,17:8)
Block(-9,22,10,18:1)
Block(-9,23,-12,18:1)
Block(-9,23,-11,18:1)
Block(-9,23,-10,18:1)
Block(-9,23,-8,18:1)
Block(-9,23,-7,18:1)
Block(-9,23,-4,18:1)
Block(-9,23,-3,18:1)
Block(-9,23,-1,18:1)
Block(-9,23,0,18:1)
Block(-9,23,1,18:1)
Block(-9,23,2,18:1)
Block(-9,23,3,18:1)
Block(-9,23,4,18:1)
Block(-9,23,5,18:1)
Block(-9,23,6,18:1)
Block(-9,23,7,18:1)
Block(-9,23,11,18:1)
Block(-9,23,12,18:1)
Block(-9,24,-10,18:1)
Block(-9,24,-9,18:1)
Block(-9,24,-4,18:1)
Block(-9,24,-3,18:1)
Block(-9,24,-2,18:1)
Block(-9,24,-1,18:1)
Block(-9,24,0,18:1)
Block(-9,24,1,18:1)
Block(-9,24,2,18:1)
Block(-9,24,8,18:1)
Block(-9,24,9,18:1)
Block(-9,24,10,18:1)
Block(-9,25,2,18:1)
Block(-9,25,3,18:1)
Block(-8,19,-6,18:1)
Block(-8,19,-5,18:1)
Block(-8,19,-4,18:1)
Block(-8,19,3,18:1)
Block(-8,19,4,18:1)
Block(-8,19,6,18:1)
Block(-8,19,7,18:1)
Block(-8,19,8,18:1)
Block(-8,20,-12,18:1)
Block(-8,20,-9,18:1)
Block(-8,20,-8,18:1)
Block(-8,20,-7,18:1)
Block(-8,20,-6,18:1)
Block(-8,20,-5,18:1)
Block(-8,20,-3,18:1)
Block(-8,20,-2,18:1)
Block(-8,20,-1,18:1)
Block(-8,20,1,18:1)
Block(-8,20,2,18:1)
Block(-8,20,3,18:1)
Block(-8,20,6,18:1)
Block(-8,20,7,18:1)
Block(-8,20,8,18:1)
Block(-8,20,9,18:1)
Block(-8,20,11,18:1)
Block(-8,21,-13,18:1)
Block(-8,21,-12,18:1)
Block(-8,21,-10,18:1)
Block(-8,21,-9,18:1)
Block(-8,21,-7,18:1)
Block(-8,21,-6,17:8)
Block(-8,21,-5,17:8)
Block(-8,21,-4,18:1)
Block(-8,21,-3,17:8)
Block(-8,21,-2,17:8)
Block(-8,21,-1,17:8)
Block(-8,21,0,17:4)
Block(-8,21,1,17:8)
Block(-8,21,2,17:8)
Block(-8,21,3,17:8)
Block(-8,21,4,18:1)
Block(-8,21,5,17:8)
Block(-8,21,6,17:8)
Block(-8,21,7,18:1)
Block(-8,21,8,18:1)
Block(-8,21,9,18:1)
Block(-8,21,10,18:1)
Block(-8,21,11,18:1)
Block(-8,22,-12,18:1)
Block(-8,22,-11,18:1)
Block(-8,22,-10,17:4)
Block(-8,22,-9,18:1)
Block(-8,22,-8,17:4)
Block(-8,22,-7,18:1)
Block(-8,22,-6,18:1)
Block(-8,22,-5,18:1)
Block(-8,22,-4,18:1)
Block(-8,22,-3,18:1)
Block(-8,22,-1,18:1)
Block(-8,22,0,18:1)
Block(-8,22,1,18:1)
Block(-8,22,2,18:1)
Block(-8,22,3,18:1)
Block(-8,22,4,18:1)
Block(-8,22,6,18:1)
Block(-8,22,7,18:1)
Block(-8,22,8,17:8)
Block(-8,22,9,18:1)
Block(-8,22,10,17:8)
Block(-8,22,11,18:1)
Block(-8,22,12,18:1)
Block(-8,22,13,18:1)
Block(-8,23,-12,18:1)
Block(-8,23,-10,18:1)
Block(-8,23,-7,18:1)
Block(-8,23,-6,18:1)
Block(-8,23,-5,18:1)
Block(-8,23,-4,18:1)
Block(-8,23,-3,18:1)
Block(-8,23,-2,17:4)
Block(-8,23,-1,18:1)
Block(-8,23,0,18:1)
Block(-8,23,1,18:1)
Block(-8,23,2,17:4)
Block(-8,23,3,18:1)
Block(-8,23,4,18:1)
Block(-8,23,5,18:1)
Block(-8,23,6,18:1)
Block(-8,23,7,18:1)
Block(-8,23,8,18:1)
Block(-8,23,9,18:1)
Block(-8,23,10,18:1)
Block(-8,23,11,18:1)
Block(-8,23,13,18:1)
Block(-8,24,-9,18:1)
Block(-8,24,-8,18:1)
Block(-8,24,-2,18:1)
Block(-8,24,-1,18:1)
Block(-8,24,0,18:1)
Block(-8,24,1,18:1)
Block(-8,24,2,18:1)
Block(-8,24,3,18:1)
Block(-8,24,5,18:1)
Block(-8,24,7,18:1)
Block(-8,24,8,18:1)
Block(-8,24,10,18:1)
Block(-8,24,11,18:1)
Block(-8,25,-3,18:1)
Block(-8,25,-2,18:1)
Block(-8,25,1,18:1)
Block(-8,25,2,18:1)
Block(-8,25,3,18:1)
Block(-7,18,8,18:1)
Block(-7,18,9,18:1)
Block(-7,19,-7,18:1)
Block(-7,19,-6,18:1)
Block(-7,19,-4,18:1)
Block(-7,19,-1,18:1)
Block(-7,19,0,18:1)
Block(-7,19,1,18:1)
Block(-7,19,6,18:1)
Block(-7,19,8,18:1)
Block(-7,19,10,18:1)
Block(-7,20,-12,18:1)
Block(-7,20,-11,18:1)
Block(-7,20,-10,18:1)
Block(-7,20,-9,18:1)
Block(-7,20,-8,18:1)
Block(-7,20,-7,18:1)
Block(-7,20,-6,18:1)
Block(-7,20,-1,18:1)
Block(-7,20,0,18:1)
Block(-7,20,1,18:1)
Block(-7,20,2,18:1)
Block(-7,20,3,18:1)
Block(-7,20,4,18:1)
Block(-7,20,5,18:1)
Block(-7,20,6,18:1)
Block(-7,20,7,18:1)
Block(-7,20,8,18:1)
Block(-7,20,9,18:1)
Block(-7,20,10,18:1)
Block(-7,20,11,18:1)
Block(-7,20,12,18:1)
Block(-7,21,-13,18:1)
Block(-7,21,-12,18:1)
Block(-7,21,-11,18:1)
Block(-7,21,-10,18:1)
Block(-7,21,-9,18:1)
Block(-7,21,-8,18:1)
Block(-7,21,-7,17:4)
Block(-7,21,-6,18:1)
Block(-7,21,-5,18:1)
Block(-7,21,-4,18:1)
Block(-7,21,-3,18:1)
Block(-7,21,-2,18:1)
Block(-7,21,-1,18:1)
Block(-7,21,0,17:4)
Block(-7,21,1,18:1)
Block(-7,21,2,18:1)
Block(-7,21,3,18:1)
Block(-7,21,4,18:1)
Block(-7,21,6,18:1)
Block(-7,21,7,17:8)
Block(-7,21,8,18:1)
Block(-7,21,9,18:1)
Block(-7,21,10,18:1)
Block(-7,21,11,18:1)
Block(-7,22,-12,18:1)
Block(-7,22,-11,17:4)
Block(-7,22,-10,18:1)
Block(-7,22,-9,18:1)
Block(-7,22,-8,18:1)
Block(-7,22,-7,18:1)
Block(-7,22,-6,18:1)
Block(-7,22,-5,18:1)
Block(-7,22,-4,18:1)
Block(-7,22,-3,18:1)
Block(-7,22,-2,18:1)
Block(-7,22,-1,18:1)
Block(-7,22,0,18:1)
Block(-7,22,1,18:1)
Block(-7,22,2,18:1)
Block(-7,22,3,18:1)
Block(-7,22,4,18:1)
Block(-7,22,5,18:1)
Block(-7,22,6,18:1)
Block(-7,22,7,18:1)
Block(-7,22,8,18:1)
Block(-7,22,9,18:1)
Block(-7,22,10,18:1)
Block(-7,22,11,17:8)
Block(-7,22,12,18:1)
Block(-7,22,13,18:1)
Block(-7,23,-12,18:1)
Block(-7,23,-11,18:1)
Block(-7,23,-9,18:1)
Block(-7,23,-6,18:1)
Block(-7,23,-5,18:1)
Block(-7,23,-4,18:1)
Block(-7,23,-2,17:4)
Block(-7,23,0,18:1)
Block(-7,23,1,18:1)
Block(-7,23,2,17:4)
Block(-7,23,3,18:1)
Block(-7,23,4,18:1)
Block(-7,23,5,18:1)
Block(-7,23,6,18:1)
Block(-7,23,8,18:1)
Block(-7,23,9,18:1)
Block(-7,23,10,18:1)
Block(-7,23,11,18:1)
Block(-7,24,-10,18:1)
Block(-7,24,-8,18:1)
Block(-7,24,-3,18:1)
Block(-7,24,-2,18:1)
Block(-7,24,0,18:1)
Block(-7,24,2,18:1)
Block(-7,24,4,18:1)
Block(-7,24,5,18:1)
Block(-7,24,6,18:1)
Block(-7,24,7,18:1)
Block(-7,24,8,18:1)
Block(-7,24,10,18:1)
Block(-7,24,11,18:1)
Block(-7,25,-4,18:1)
Block(-7,25,-3,18:1)
Block(-7,25,-2,18:1)
Block(-7,25,1,18:1)
Block(-7,25,2,18:1)
Block(-7,25,3,18:1)
Block(-6,18,0,18:1)
Block(-6,18,7,18:1)
Block(-6,18,8,18:1)
Block(-6,18,9,18:1)
Block(-6,19,-7,18:1)
Block(-6,19,-6,18:1)
Block(-6,19,-5,18:1)
Block(-6,19,-2,18:1)
Block(-6,19,2,18:1)
Block(-6,19,5,18:1)
Block(-6,19,6,18:1)
Block(-6,19,7,18:1)
Block(-6,20,-12,18:1)
Block(-6,20,-11,18:1)
Block(-6,20,-10,18:1)
Block(-6,20,-8,18:1)
Block(-6,20,-6,18:1)
Block(-6,20,-5,18:1)
Block(-6,20,-4,18:1)
Block(-6,20,-1,18:1)
Block(-6,20,0,17:4)
Block(-6,20,1,18:1)
Block(-6,20,4,18:1)
Block(-6,20,5,18:1)
Block(-6,20,6,18:1)
Block(-6,20,7,18:1)
Block(-6,20,8,18:1)
Block(-6,20,9,18:1)
Block(-6,20,10,18:1)
Block(-6,21,-12,18:1)
Block(-6,21,-11,18:1)
Block(-6,21,-10,18:1)
Block(-6,21,-9,18:1)
Block(-6,21,-8,17:4)
Block(-6,21,-7,18:1)
Block(-6,21,-6,17:4)
Block(-6,21,-5,18:1)
Block(-6,21,-4,18:1)
Block(-6,21,-2,18:1)
Block(-6,21,-1,18:1)
Block(-6,21,1,18:1)
Block(-6,21,2,18:1)
Block(-6,21,3,18:1)
Block(-6,21,4,18:1)
Block(-6,21,5,18:1)
Block(-6,21,6,17:8)
Block(-6,21,8,17:4)
Block(-6,21,9,18:1)
Block(-6,21,10,18:1)
Block(-6,21,11,18:1)
Block(-6,22,-13,18:1)
Block(-6,22,-12,18:1)
Block(-6,22,-11,18:1)
Block(-6,22,-10,18:1)
Block(-6,22,-9,18:1)
Block(-6,22,-8,18:1)
Block(-6,22,-7,18:1)
Block(-6,22,-6,18:1)
Block(-6,22,-5,18:1)
Block(-6,22,-4,18:1)
Block(-6,22,-3,18:1)
Block(-6,22,-1,18:1)
Block(-6,22,0,18:1)
Block(-6,22,1,18:1)
Block(-6,22,2,18:1)
Block(-6,22,3,18:1)
Block(-6,22,4,18:1)
Block(-6,22,5,18:1)
Block(-6,22,6,18:1)
Block(-6,22,7,18:1)
Block(-6,22,8,18:1)
Block(-6,22,9,18:1)
Block(-6,22,10,18:1)
Block(-6,22,11,18:1)
Block(-6,22,12,18:1)
Block(-6,23,-8,18:1)
Block(-6,23,-7,18:1)
Block(-6,23,-6,18:1)
Block(-6,23,-5,18:1)
Block(-6,23,-4,17:8)
Block(-6,23,-3,17:8)
Block(-6,23,-2,17:4)
Block(-6,23,-1,18:1)
Block(-6,23,0,18:1)
Block(-6,23,1,18:1)
Block(-6,23,2,17:4)
Block(-6,23,3,17:8)
Block(-6,23,4,17:8)
Block(-6,23,5,18:1)
Block(-6,23,6,18:1)
Block(-6,23,7,18:1)
Block(-6,23,10,18:1)
Block(-6,23,11,18:1)
Block(-6,24,-11,18:1)
Block(-6,24,-6,18:1)
Block(-6,24,-3,18:1)
Block(-6,24,-2,18:1)
Block(-6,24,0,18:1)
Block(-6,24,1,18:1)
Block(-6,24,2,18:1)
Block(-6,24,3,18:1)
Block(-6,24,4,18:1)
Block(-6,24,5,18:1)
Block(-6,24,6,18:1)
Block(-6,25,-5,18:1)
Block(-6,25,-4,18:1)
Block(-6,25,-3,18:1)
Block(-6,25,-2,18:1)
Block(-6,25,3,18:1)
Block(-6,25,4,18:1)
Block(-6,25,5,18:1)
Block(-5,18,0,18:1)
Block(-5,18,1,18:1)
Block(-5,18,8,18:1)
Block(-5,19,-5,18:1)
Block(-5,19,-4,18:1)
Block(-5,19,-2,18:1)
Block(-5,19,-1,18:1)
Block(-5,19,2,18:1)
Block(-5,19,3,18:1)
Block(-5,19,6,18:1)
Block(-5,19,7,18:1)
Block(-5,19,9,18:1)
Block(-5,19,10,18:1)
Block(-5,20,-12,18:1)
Block(-5,20,-11,18:1)
Block(-5,20,-10,18:1)
Block(-5,20,-8,18:1)
Block(-5,20,-5,17:4)
Block(-5,20,-3,18:1)
Block(-5,20,-2,18:1)
Block(-5,20,0,17:4)
Block(-5,20,1,18:1)
Block(-5,20,2,18:1)
Block(-5,20,3,18:1)
Block(-5,20,4,18:1)
Block(-5,20,5,17:8)
Block(-5,20,6,18:1)
Block(-5,20,7,18:1)
Block(-5,20,8,18:1)
Block(-5,20,9,18:1)
Block(-5,20,10,18:1)
Block(-5,21,-12,18:1)
Block(-5,21,-10,18:1)
Block(-5,21,-8,17:4)
Block(-5,21,-7,18:1)
Block(-5,21,-6,18:1)
Block(-5,21,-5,18:1)
Block(-5,21,-4,18:1)
Block(-5,21,-3,18:1)
Block(-5,21,-2,18:1)
Block(-5,21,-1,18:1)
Block(-5,21,0,18:1)
Block(-5,21,1,18:1)
Block(-5,21,2,18:1)
Block(-5,21,3,18:1)
Block(-5,21,4,18:1)
Block(-5,21,5,18:1)
Block(-5,21,6,18:1)
Block(-5,21,7,18:1)
Block(-5,21,8,17:4)
Block(-5,21,9,18:1)
Block(-5,21,10,18:1)
Block(-5,21,11,18:1)
Block(-5,22,-13,18:1)
Block(-5,22,-12,18:1)
Block(-5,22,-11,18:1)
Block(-5,22,-10,18:1)
Block(-5,22,-9,18:1)
Block(-5,22,-8,18:1)
Block(-5,22,-7,18:1)
Block(-5,22,-5,18:1)
Block(-5,22,-4,18:1)
Block(-5,22,-3,18:1)
Block(-5,22,-2,18:1)
Block(-5,22,-1,18:1)
Block(-5,22,0,18:1)
Block(-5,22,1,18:1)
Block(-5,22,2,18:1)
Block(-5,22,4,18:1)
Block(-5,22,5,18:1)
Block(-5,22,6,18:1)
Block(-5,22,7,18:1)
Block(-5,22,8,18:1)
Block(-5,22,9,18:1)
Block(-5,22,10,18:1)
Block(-5,22,11,18:1)
Block(-5,22,12,18:1)
Block(-5,23,-11,18:1)
Block(-5,23,-9,18:1)
Block(-5,23,-8,18:1)
Block(-5,23,-7,18:1)
Block(-5,23,-6,18:1)
Block(-5,23,-5,18:1)
Block(-5,23,-4,18:1)
Block(-5,23,-3,18:1)
Block(-5,23,-2,17:4)
Block(-5,23,-1,18:1)
Block(-5,23,0,18:1)
Block(-5,23,1,18:1)
Block(-5,23,2,17:4)
Block(-5,23,4,18:1)
Block(-5,23,5,18:1)
Block(-5,23,6,18:1)
Block(-5,23,7,18:1)
Block(-5,23,8,18:1)
Block(-5,23,9,18:1)
Block(-5,23,11,18:1)
Block(-5,24,-12,18:1)
Block(-5,24,-11,18:1)
Block(-5,24,-10,18:1)
Block(-5,24,-7,18:1)
Block(-5,24,-4,18:1)
Block(-5,24,-3,18:1)
Block(-5,24,-2,18:1)
Block(-5,24,-1,18:1)
Block(-5,24,0,18:1)
Block(-5,24,2,18:1)
Block(-5,24,3,18:1)
Block(-5,24,4,18:1)
Block(-5,24,5,18:1)
Block(-5,24,12,18:1)
Block(-5,25,-4,18:1)
Block(-5,25,-2,18:1)
Block(-5,25,1,18:1)
Block(-5,25,3,18:1)
Block(-5,25,4,18:1)
Block(-5,25,6,18:1)
Block(-5,25,7,18:1)
Block(-4,0,0,17)
Block(-4,17,3,18:1)
Block(-4,18,0,18:1)
Block(-4,18,3,18:1)
Block(-4,18,4,18:1)
Block(-4,19,-8,18:1)
Block(-4,19,-7,18:1)
Block(-4,19,-4,18:1)
Block(-4,19,-3,18:1)
Block(-4,19,0,17:4)
Block(-4,19,2,18:1)
Block(-4,19,3,18:1)
Block(-4,19,4,18:1)
Block(-4,19,5,18:1)
Block(-4,19,8,18:1)
Block(-4,19,9,18:1)
Block(-4,20,-12,18:1)
Block(-4,20,-11,18:1)
Block(-4,20,-6,18:1)
Block(-4,20,-4,17:4)
Block(-4,20,-3,18:1)
Block(-4,20,-2,18:1)
Block(-4,20,0,17:4)
Block(-4,20,1,18:1)
Block(-4,20,2,18:1)
Block(-4,20,4,17:8)
Block(-4,20,6,18:1)
Block(-4,20,7,18:1)
Block(-4,20,8,18:1)
Block(-4,20,11,18:1)
Block(-4,20,12,18:1)
Block(-4,21,-12,18:1)
Block(-4,21,-11,18:1)
Block(-4,21,-10,18:1)
Block(-4,21,-9,18:1)
Block(-4,21,-8,18:1)
Block(-4,21,-7,18:1)
Block(-4,21,-6,18:1)
Block(-4,21,-5,18:1)
Block(-4,21,-4,18:1)
Block(-4,21,-3,18:1)
Block(-4,21,-2,18:1)
Block(-4,21,-1,18:1)
Block(-4,21,0,18:1)
Block(-4,21,1,18:1)
Block(-4,21,2,18:1)
Block(-4,21,3,18:1)
Block(-4,21,4,18:1)
Block(-4,21,5,18:1)
Block(-4,21,6,18:1)
Block(-4,21,9,18:1)
Block(-4,21,10,18:1)
Block(-4,21,11,18:1)
Block(-4,21,12,18:1)
Block(-4,22,-13,18:1)
Block(-4,22,-12,18:1)
Block(-4,22,-11,17:4)
Block(-4,22,-10,18:1)
Block(-4,22,-9,18:1)
Block(-4,22,-8,18:1)
Block(-4,22,-7,18:1)
Block(-4,22,-6,18:1)
Block(-4,22,-5,18:1)
Block(-4,22,-4,18:1)
Block(-4,22,-3,18:1)
Block(-4,22,-2,18:1)
Block(-4,22,0,18:1)
Block(-4,22,1,18:1)
Block(-4,22,2,18:1)
Block(-4,22,3,18:1)
Block(-4,22,4,18:1)
Block(-4,22,5,18:1)
Block(-4,22,6,18:1)
Block(-4,22,8,18:1)
Block(-4,22,9,18:1)
Block(-4,22,10,18:1)
Block(-4,22,11,17:4)
Block(-4,22,12,18:1)
Block(-4,22,13,18:1)
Block(-4,23,-13,18:1)
Block(-4,23,-12,18:1)
Block(-4,23,-11,18:1)
Block(-4,23,-10,18:1)
Block(-4,23,-9,18:1)
Block(-4,23,-8,18:1)
Block(-4,23,-7,18:1)
Block(-4,23,-6,17:4)
Block(-4,23,-5,18:1)
Block(-4,23,-4,18:1)
Block(-4,23,-3,18:1)
Block(-4,23,-2,17:4)
Block(-4,23,-1,18:1)
Block(-4,23,0,18:1)
Block(-4,23,2,17:4)
Block(-4,23,3,18:1)
Block(-4,23,4,18:1)
Block(-4,23,5,18:1)
Block(-4,23,6,17:4)
Block(-4,23,7,18:1)
Block(-4,23,8,18:1)
Block(-4,23,9,18:1)
Block(-4,23,10,18:1)
Block(-4,23,11,18:1)
Block(-4,23,12,18:1)
Block(-4,23,13,18:1)
Block(-4,24,-12,18:1)
Block(-4,24,-8,18:1)
Block(-4,24,-7,18:1)
Block(-4,24,-6,18:1)
Block(-4,24,-5,18:1)
Block(-4,24,-4,18:1)
Block(-4,24,-3,18:1)
Block(-4,24,-2,18:1)
Block(-4,24,0,18:1)
Block(-4,24,2,18:1)
Block(-4,24,3,18:1)
Block(-4,24,4,18:1)
Block(-4,24,5,18:1)
Block(-4,24,7,18:1)
Block(-4,24,8,18:1)
Block(-4,24,10,18:1)
Block(-4,24,11,18:1)
Block(-4,24,12,18:1)
Block(-4,25,-7,18:1)
Block(-4,25,-5,18:1)
Block(-4,25,-2,18:1)
Block(-4,25,-1,18:1)
Block(-4,25,1,18:1)
Block(-4,25,2,18:1)
Block(-4,25,6,18:1)
Block(-4,25,7,18:1)
Block(-3,0,-1,17)
Block(-3,0,0,17)
Block(-3,0,1,17)
Block(-3,1,0,17)
Block(-3,2,0,17)
Block(-3,18,-5,18:1)
Block(-3,18,-4,18:1)
Block(-3,18,0,17)
Block(-3,18,2,18:1)
Block(-3,18,4,18:1)
Block(-3,18,5,18:1)
Block(-3,19,-8,18:1)
Block(-3,19,-7,18:1)
Block(-3,19,-4,18:1)
Block(-3,19,-3,17:4)
Block(-3,19,0,17)
Block(-3,19,1,18:1)
Block(-3,19,2,18:1)
Block(-3,19,3,17:8)
Block(-3,19,4,18:1)
Block(-3,19,5,18:1)
Block(-3,19,7,18:1)
Block(-3,19,8,18:1)
Block(-3,20,-10,18:1)
Block(-3,20,-9,18:1)
Block(-3,20,-8,18:1)
Block(-3,20,-6,18:1)
Block(-3,20,-5,18:1)
Block(-3,20,-4,18:1)
Block(-3,20,-3,18:1)
Block(-3,20,-2,18:1)
Block(-3,20,-1,18:1)
Block(-3,20,0,17:4)
Block(-3,20,1,18:1)
Block(-3,20,2,18:1)
Block(-3,20,3,18:1)
Block(-3,20,4,18:1)
Block(-3,20,5,18:1)
Block(-3,20,6,18:1)
Block(-3,20,7,18:1)
Block(-3,20,8,18:1)
Block(-3,20,10,18:1)
Block(-3,20,11,18:1)
Block(-3,20,12,18:1)
Block(-3,21,-9,18:1)
Block(-3,21,-8,17:4)
Block(-3,21,-7,18:1)
Block(-3,21,-6,18:1)
Block(-3,21,-5,18:1)
Block(-3,21,-4,18:1)
Block(-3,21,-3,18:1)
Block(-3,21,-2,18:1)
Block(-3,21,-1,18:1)
Block(-3,21,0,18:1)
Block(-3,21,1,18:1)
Block(-3,21,2,18:1)
Block(-3,21,3,18:1)
Block(-3,21,4,18:1)
Block(-3,21,5,18:1)
Block(-3,21,6,18:1)
Block(-3,21,7,18:1)
Block(-3,21,8,17:4)
Block(-3,21,9,18:1)
Block(-3,21,10,18:1)
Block(-3,21,12,18:1)
Block(-3,22,-12,18:1)
Block(-3,22,-11,17:4)
Block(-3,22,-10,18:1)
Block(-3,22,-9,18:1)
Block(-3,22,-8,18:1)
Block(-3,22,-7,18:1)
Block(-3,22,-6,18:1)
Block(-3,22,-5,18:1)
Block(-3,22,-3,18:1)
Block(-3,22,-2,18:1)
Block(-3,22,-1,18:1)
Block(-3,22,0,18:1)
Block(-3,22,1,18:1)
Block(-3,22,2,18:1)
Block(-3,22,3,18:1)
Block(-3,22,4,18:1)
Block(-3,22,5,18:1)
Block(-3,22,7,18:1)
Block(-3,22,8,18:1)
Block(-3,22,9,18:1)
Block(-3,22,10,18:1)
Block(-3,22,11,17:4)
Block(-3,23,-11,18:1)
Block(-3,23,-10,18:1)
Block(-3,23,-9,18:1)
Block(-3,23,-8,18:1)
Block(-3,23,-7,18:1)
Block(-3,23,-6,17:4)
Block(-3,23,-5,18:1)
Block(-3,23,-4,18:1)
Block(-3,23,-3,18:1)
Block(-3,23,-2,17:4)
Block(-3,23,-1,18:1)
Block(-3,23,0,18:1)
Block(-3,23,1,18:1)
Block(-3,23,2,17:4)
Block(-3,23,3,18:1)
Block(-3,23,4,18:1)
Block(-3,23,6,17:4)
Block(-3,23,7,18:1)
Block(-3,23,8,18:1)
Block(-3,23,9,18:1)
Block(-3,23,10,18:1)
Block(-3,23,11,18:1)
Block(-3,23,12,18:1)
Block(-3,24,-11,18:1)
Block(-3,24,-8,18:1)
Block(-3,24,-7,18:1)
Block(-3,24,-6,18:1)
Block(-3,24,-4,18:1)
Block(-3,24,-3,18:1)
Block(-3,24,-2,18:1)
Block(-3,24,-1,18:1)
Block(-3,24,1,18:1)
Block(-3,24,2,18:1)
Block(-3,24,3,18:1)
Block(-3,24,4,18:1)
Block(-3,24,5,18:1)
Block(-3,24,6,18:1)
Block(-3,24,8,18:1)
Block(-3,24,10,18:1)
Block(-3,24,12,18:1)
Block(-3,25,-8,18:1)
Block(-3,25,-7,18:1)
Block(-3,25,-6,18:1)
Block(-3,25,-5,18:1)
Block(-3,25,-2,18:1)
Block(-3,25,1,18:1)
Block(-3,25,4,18:1)
Block(-3,25,5,18:1)
Block(-3,25,6,18:1)
Block(-3,25,8,18:1)
Block(-2,0,-2,17)
Block(-2,0,-1,17)
Block(-2,0,0,17)
Block(-2,0,1,17)
Block(-2,0,2,17)
Block(-2,1,-2,17)
Block(-2,1,-1,17)
Block(-2,1,0,17)
Block(-2,1,1,17)
Block(-2,1,2,17)
Block(-2,2,-1,17)
Block(-2,2,0,17)
Block(-2,2,1,17)
Block(-2,3,0,17)
Block(-2,4,0,17)
Block(-2,16,0,17)
Block(-2,17,0,17)
Block(-2,17,4,18:1)
Block(-2,18,-4,18:1)
Block(-2,18,-3,18:1)
Block(-2,18,-2,17)
Block(-2,18,-1,17)
Block(-2,18,0,17)
Block(-2,18,1,17)
Block(-2,18,2,17)
Block(-2,18,3,18:1)
Block(-2,18,4,18:1)
Block(-2,19,-8,18:1)
Block(-2,19,-5,18:1)
Block(-2,19,-4,18:1)
Block(-2,19,-2,17)
Block(-2,19,-1,17)
Block(-2,19,0,17)
Block(-2,19,1,17)
Block(-2,19,2,17)
Block(-2,19,4,18:1)
Block(-2,19,6,18:1)
Block(-2,20,-9,18:1)
Block(-2,20,-8,18:1)
Block(-2,20,-7,18:1)
Block(-2,20,-4,18:1)
Block(-2,20,-3,18:1)
Block(-2,20,-2,17)
Block(-2,20,0,17:4)
Block(-2,20,2,17)
Block(-2,20,3,18:1)
Block(-2,20,5,18:1)
Block(-2,20,6,18:1)
Block(-2,20,8,18:1)
Block(-2,20,9,18:1)
Block(-2,21,-13,18:1)
Block(-2,21,-12,18:1)
Block(-2,21,-11,18:1)
Block(-2,21,-10,18:1)
Block(-2,21,-9,18:1)
Block(-2,21,-8,17:4)
Block(-2,21,-7,18:1)
Block(-2,21,-4,18:1)
Block(-2,21,-3,18:1)
Block(-2,21,-2,17)
Block(-2,21,-1,18:1)
Block(-2,21,0,18:1)
Block(-2,21,1,18:1)
Block(-2,21,2,17)
Block(-2,21,3,18:1)
Block(-2,21,4,18:1)
Block(-2,21,5,18:1)
Block(-2,21,6,18:1)
Block(-2,21,7,18:1)
Block(-2,21,8,17:4)
Block(-2,21,9,18:1)
Block(-2,21,10,18:1)
Block(-2,21,11,18:1)
Block(-2,21,12,18:1)
Block(-2,22,-13,18:1)
Block(-2,22,-12,18:1)
Block(-2,22,-11,17:4)
Block(-2,22,-10,18:1)
Block(-2,22,-9,18:1)
Block(-2,22,-8,18:1)
Block(-2,22,-7,18:1)
Block(-2,22,-6,18:1)
Block(-2,22,-5,18:1)
Block(-2,22,-4,18:1)
Block(-2,22,-3,18:1)
Block(-2,22,-2,17)
Block(-2,22,-1,18:1)
Block(-2,22,0,18:1)
Block(-2,22,1,18:1)
Block(-2,22,2,17)
Block(-2,22,3,18:1)
Block(-2,22,4,18:1)
Block(-2,22,5,18:1)
Block(-2,22,6,18:1)
Block(-2,22,7,18:1)
Block(-2,22,8,18:1)
Block(-2,22,9,18:1)
Block(-2,22,10,18:1)
Block(-2,22,11,17:4)
Block(-2,22,12,18:1)
Block(-2,22,13,18:1)
Block(-2,22,14,18:1)
Block(-2,23,-14,18:1)
Block(-2,23,-13,18:1)
Block(-2,23,-12,18:1)
Block(-2,23,-10,18:1)
Block(-2,23,-9,18:1)
Block(-2,23,-8,17:8)
Block(-2,23,-7,17:8)
Block(-2,23,-6,17:8)
Block(-2,23,-5,17:8)
Block(-2,23,-4,17:8)
Block(-2,23,-3,17:8)
Block(-2,23,-2,18:1)
Block(-2,23,-1,18:1)
Block(-2,23,0,18:1)
Block(-2,23,1,18:1)
Block(-2,23,2,18:1)
Block(-2,23,3,17:8)
Block(-2,23,4,17:8)
Block(-2,23,5,17:8)
Block(-2,23,6,17:8)
Block(-2,23,7,17:8)
Block(-2,23,8,17:8)
Block(-2,23,9,18:1)
Block(-2,23,10,18:1)
Block(-2,23,11,18:1)
Block(-2,23,12,18:1)
Block(-2,24,-10,18:1)
Block(-2,24,-9,18:1)
Block(-2,24,-8,18:1)
Block(-2,24,-7,18:1)
Block(-2,24,-6,18:1)
Block(-2,24,-5,18:1)
Block(-2,24,-4,18:1)
Block(-2,24,-3,18:1)
Block(-2,24,-2,18:1)
Block(-2,24,0,18:1)
Block(-2,24,1,18:1)
Block(-2,24,2,18:1)
Block(-2,24,4,18:1)
Block(-2,24,5,18:1)
Block(-2,24,6,18:1)
Block(-2,24,7,18:1)
Block(-2,24,8,18:1)
Block(-2,24,10,18:1)
Block(-2,25,-8,18:1)
Block(-2,25,-7,18:1)
Block(-2,25,-4,18:1)
Block(-2,25,2,18:1)
Block(-2,25,3,18:1)
Block(-2,25,4,18:1)
Block(-2,25,6,18:1)
Block(-2,25,7,18:1)
Block(-2,25,8,18:1)
Block(-2,25,9,18:1)
Block(-2,26,4,18:1)
Block(-2,26,5,18:1)
Block(-2,26,6,18:1)
Block(-1,0,-3,17)
Block(-1,0,-2,17)
Block(-1,0,-1,17)
Block(-1,0,0,17)
Block(-1,0,1,17)
Block(-1,0,2,17)
Block(-1,0,3,17)
Block(-1,1,-2,17)
Block(-1,1,-1,17)
Block(-1,1,0,17)
Block(-1,1,1,17)
Block(-1,1,2,17)
Block(-1,2,-2,17)
Block(-1,2,-1,17)
Block(-1,2,0,17)
Block(-1,2,1,17)
Block(-1,2,2,17)
Block(-1,3,-1,17)
Block(-1,3,0,17)
Block(-1,3,1,17)
Block(-1,4,-1,17)
Block(-1,4,0,17)
Block(-1,4,1,17)
Block(-1,5,-1,17)
Block(-1,5,0,17)
Block(-1,5,1,17)
Block(-1,6,-1,17)
Block(-1,6,0,17)
Block(-1,6,1,17)
Block(-1,7,-1,17)
Block(-1,7,0,17)
Block(-1,7,1,17)
Block(-1,8,-1,17)
Block(-1,8,0,17)
Block(-1,8,1,17)
Block(-1,9,-1,17)
Block(-1,9,0,17)
Block(-1,9,1,17)
Block(-1,10,-1,17)
Block(-1,10,0,17)
Block(-1,10,1,17)
Block(-1,11,0,17)
Block(-1,12,0,17)
Block(-1,13,0,17)
Block(-1,14,0,17)
Block(-1,15,0,17)
Block(-1,16,-1,17)
Block(-1,16,0,17)
Block(-1,16,1,17)
Block(-1,17,-1,17)
Block(-1,17,0,17)
Block(-1,17,1,17)
Block(-1,18,-5,18:1)
Block(-1,18,-4,18:1)
Block(-1,18,-3,18:1)
Block(-1,18,-2,17)
Block(-1,18,-1,17)
Block(-1,18,0,17)
Block(-1,18,1,17)
Block(-1,18,2,17)
Block(-1,19,-7,18:1)
Block(-1,19,-6,18:1)
Block(-1,19,-5,18:1)
Block(-1,19,-4,18:1)
Block(-1,19,-3,18:1)
Block(-1,19,-2,17)
Block(-1,19,-1,17)
Block(-1,19,0,17)
Block(-1,19,1,17)
Block(-1,19,2,17)
Block(-1,19,3,18:1)
Block(-1,19,4,18:1)
Block(-1,19,6,18:1)
Block(-1,19,8,18:1)
Block(-1,19,9,18:1)
Block(-1,19,10,18:1)
Block(-1,20,-13,18:1)
Block(-1,20,-6,18:1)
Block(-1,20,-5,18:1)
Block(-1,20,-4,18:1)
Block(-1,20,-3,18:1)
Block(-1,20,-2,18:1)
Block(-1,20,-1,17)
Block(-1,20,0,17:4)
Block(-1,20,1,17)
Block(-1,20,3,18:1)
Block(-1,20,4,18:1)
Block(-1,20,6,18:1)
Block(-1,20,7,18:1)
Block(-1,20,8,18:1)
Block(-1,20,9,18:1)
Block(-1,20,10,18:1)
Block(-1,20,11,18:1)
Block(-1,20,12,18:1)
Block(-1,20,13,18:1)
Block(-1,21,-15,18:1)
Block(-1,21,-14,18:1)
Block(-1,21,-13,18:1)
Block(-1,21,-12,18:1)
Block(-1,21,-10,18:1)
Block(-1,21,-9,18:1)
Block(-1,21,-8,17:4)
Block(-1,21,-7,18:1)
Block(-1,21,-6,18:1)
Block(-1,21,-5,18:1)
Block(-1,21,-4,18:1)
Block(-1,21,-3,18:1)
Block(-1,21,-2,18:1)
Block(-1,21,0,18:1)
Block(-1,21,1,18:1)
Block(-1,21,3,18:1)
Block(-1,21,4,18:1)
Block(-1,21,5,18:1)
Block(-1,21,6,18:1)
Block(-1,21,7,18:1)
Block(-1,21,8,17:4)
Block(-1,21,9,18:1)
Block(-1,21,10,18:1)
Block(-1,21,11,18:1)
Block(-1,21,13,18:1)
Block(-1,22,-15,18:1)
Block(-1,22,-14,18:1)
Block(-1,22,-13,18:1)
Block(-1,22,-12,18:1)
Block(-1,22,-11,17:4)
Block(-1,22,-10,18:1)
Block(-1,22,-9,18:1)
Block(-1,22,-8,18:1)
Block(-1,22,-7,18:1)
Block(-1,22,-6,18:1)
Block(-1,22,-5,18:1)
Block(-1,22,-4,18:1)
Block(-1,22,-3,18:1)
Block(-1,22,-2,18:1)
Block(-1,22,-1,18:1)
Block(-1,22,0,18:1)
Block(-1,22,1,18:1)
Block(-1,22,2,18:1)
Block(-1,22,3,18:1)
Block(-1,22,4,18:1)
Block(-1,22,5,18:1)
Block(-1,22,6,18:1)
Block(-1,22,7,18:1)
Block(-1,22,8,18:1)
Block(-1,22,9,18:1)
Block(-1,22,10,18:1)
Block(-1,22,11,17:4)
Block(-1,22,12,18:1)
Block(-1,22,13,18:1)
Block(-1,22,14,18:1)
Block(-1,22,15,18:1)
Block(-1,23,-15,18:1)
Block(-1,23,-14,18:1)
Block(-1,23,-13,18:1)
Block(-1,23,-12,18:1)
Block(-1,23,-11,18:1)
Block(-1,23,-10,18:1)
Block(-1,23,-9,18:1)
Block(-1,23,-8,18:1)
Block(-1,23,-7,18:1)
Block(-1,23,-6,18:1)
Block(-1,23,-5,18:1)
Block(-1,23,-4,18:1)
Block(-1,23,-2,18:1)
Block(-1,23,0,18:1)
Block(-1,23,1,18:1)
Block(-1,23,2,18:1)
Block(-1,23,4,18:1)
Block(-1,23,6,18:1)
Block(-1,23,7,18:1)
Block(-1,23,8,18:1)
Block(-1,23,10,18:1)
Block(-1,23,11,18:1)
Block(-1,23,13,18:1)
Block(-1,23,14,18:1)
Block(-1,24,-13,18:1)
Block(-1,24,-12,18:1)
Block(-1,24,-10,18:1)
Block(-1,24,-9,18:1)
Block(-1,24,-8,18:1)
Block(-1,24,-7,18:1)
Block(-1,24,-6,18:1)
Block(-1,24,-4,18:1)
Block(-1,24,-1,18:1)
Block(-1,24,0,18:1)
Block(-1,24,1,18:1)
Block(-1,24,2,18:1)
Block(-1,24,3,18:1)
Block(-1,24,4,18:1)
Block(-1,24,5,18:1)
Block(-1,24,6,18:1)
Block(-1,24,7,18:1)
Block(-1,24,8,18:1)
Block(-1,24,9,18:1)
Block(-1,24,10,18:1)
Block(-1,24,11,18:1)
Block(-1,25,-9,18:1)
Block(-1,25,-8,18:1)
Block(-1,25,-7,18:1)
Block(-1,25,-1,18:1)
Block(-1,25,4,18:1)
Block(-1,25,8,18:1)
Block(-1,26,4,18:1)
Block(-1,26,5,18:1)
Block(-1,26,6,18:1)
Block(0,0,-3,17)
Block(0,0,-2,17)
Block(0,0,-1,17)
Block(0,0,0,17)
Block(0,0,1,17)
Block(0,0,2,17)
Block(0,0,3,17)
Block(0,1,-3,17)
Block(0,1,-2,17)
Block(0,1,-1,17)
Block(0,1,0,17)
Block(0,1,1,17)
Block(0,1,2,17)
Block(0,1,3,17)
Block(0,2,-2,17)
Block(0,2,-1,17)
Block(0,2,0,17)
Block(0,2,1,17)
Block(0,2,2,17)
Block(0,3,-2,17)
Block(0,3,-1,17)
Block(0,3,0,17)
Block(0,3,1,17)
Block(0,3,2,17)
Block(0,4,-2,17)
Block(0,4,-1,17)
Block(0,4,0,17)
Block(0,4,1,17)
Block(0,4,2,17)
Block(0,5,-1,17)
Block(0,5,0,17)
Block(0,5,1,17)
Block(0,6,-1,17)
Block(0,6,0,17)
Block(0,6,1,17)
Block(0,7,-1,17)
Block(0,7,0,17)
Block(0,7,1,17)
Block(0,8,-1,17)
Block(0,8,0,17)
Block(0,8,1,17)
Block(0,9,-1,17)
Block(0,9,0,17)
Block(0,9,1,17)
Block(0,10,-1,17)
Block(0,10,0,17)
Block(0,10,1,17)
Block(0,11,-1,17)
Block(0,11,0,17)
Block(0,11,1,17)
Block(0,12,-1,17)
Block(0,12,0,17)
Block(0,12,1,17)
Block(0,13,-1,17)
Block(0,13,0,17)
Block(0,13,1,17)
Block(0,14,-1,17)
Block(0,14,0,17)
Block(0,14,1,17)
Block(0,15,-1,17)
Block(0,15,0,17)
Block(0,15,1,17)
Block(0,16,-2,17)
Block(0,16,-1,17)
Block(0,16,0,17)
Block(0,16,1,17)
Block(0,16,2,17)
Block(0,17,-2,17)
Block(0,17,-1,17)
Block(0,17,0,17)
Block(0,17,1,17)
Block(0,17,2,17)
Block(0,18,-4,18:1)
Block(0,18,-3,17)
Block(0,18,-2,17)
Block(0,18,-1,17)
Block(0,18,0,17)
Block(0,18,1,17)
Block(0,18,2,17)
Block(0,18,3,17)
Block(0,18,4,18:1)
Block(0,18,5,18:1)
Block(0,18,6,18:1)
Block(0,18,9,18:1)
Block(0,19,-8,18:1)
Block(0,19,-6,18:1)
Block(0,19,-5,18:1)
Block(0,19,-4,17:8)
Block(0,19,-3,17)
Block(0,19,-2,17)
Block(0,19,-1,17)
Block(0,19,0,17)
Block(0,19,1,17)
Block(0,19,2,17)
Block(0,19,3,17)
Block(0,19,4,17:8)
Block(0,19,6,18:1)
Block(0,19,7,18:1)
Block(0,19,8,18:1)
Block(0,19,9,18:1)
Block(0,19,10,18:1)
Block(0,19,11,18:1)
Block(0,20,-13,18:1)
Block(0,20,-12,18:1)
Block(0,20,-11,18:1)
Block(0,20,-10,18:1)
Block(0,20,-8,18:1)
Block(0,20,-7,18:1)
Block(0,20,-6,17:8)
Block(0,20,-5,17:8)
Block(0,20,-4,17:8)
Block(0,20,-3,17:8)
Block(0,20,-2,17:8)
Block(0,20,-1,17:8)
Block(0,20,0,17)
Block(0,20,1,17:8)
Block(0,20,2,17:8)
Block(0,20,3,17:8)
Block(0,20,4,17:8)
Block(0,20,5,17:8)
Block(0,20,6,17:8)
Block(0,20,7,18:1)
Block(0,20,8,18:1)
Block(0,20,9,18:1)
Block(0,20,10,18:1)
Block(0,20,11,18:1)
Block(0,20,12,18:1)
Block(0,20,13,18:1)
Block(0,21,-15,18:1)
Block(0,21,-14,18:1)
Block(0,21,-13,18:1)
Block(0,21,-12,18:1)
Block(0,21,-11,18:1)
Block(0,21,-10,18:1)
Block(0,21,-9,17:8)
Block(0,21,-8,17:8)
Block(0,21,-7,17:8)
Block(0,21,-4,18:1)
Block(0,21,-3,18:1)
Block(0,21,-2,18:1)
Block(0,21,-1,18:1)
Block(0,21,0,17)
Block(0,21,1,18:1)
Block(0,21,2,18:1)
Block(0,21,3,18:1)
Block(0,21,4,18:1)
Block(0,21,5,18:1)
Block(0,21,6,18:1)
Block(0,21,7,17:8)
Block(0,21,8,17:8)
Block(0,21,9,17:8)
Block(0,21,10,18:1)
Block(0,21,11,18:1)
Block(0,21,12,18:1)
Block(0,21,13,18:1)
Block(0,21,14,18:1)
Block(0,21,15,18:1)
Block(0,22,-15,18:1)
Block(0,22,-14,18:1)
Block(0,22,-13,17:8)
Block(0,22,-12,17:8)
Block(0,22,-11,17:8)
Block(0,22,-10,17:8)
Block(0,22,-9,18:1)
Block(0,22,-8,18:1)
Block(0,22,-7,18:1)
Block(0,22,-6,18:1)
Block(0,22,-5,18:1)
Block(0,22,-4,18:1)
Block(0,22,-3,18:1)
Block(0,22,-2,18:1)
Block(0,22,-1,18:1)
Block(0,22,0,17)
Block(0,22,2,18:1)
Block(0,22,3,18:1)
Block(0,22,5,18:1)
Block(0,22,6,18:1)
Block(0,22,7,18:1)
Block(0,22,8,18:1)
Block(0,22,9,18:1)
Block(0,22,10,17:8)
Block(0,22,11,17:8)
Block(0,22,12,17:8)
Block(0,22,13,17:8)
Block(0,23,-15,18:1)
Block(0,23,-13,18:1)
Block(0,23,-12,18:1)
Block(0,23,-11,18:1)
Block(0,23,-10,18:1)
Block(0,23,-9,18:1)
Block(0,23,-8,18:1)
Block(0,23,-7,18:1)
Block(0,23,-6,18:1)
Block(0,23,-5,18:1)
Block(0,23,-4,18:1)
Block(0,23,-3,18:1)
Block(0,23,-2,18:1)
Block(0,23,-1,18:1)
Block(0,23,0,17)
Block(0,23,2,18:1)
Block(0,23,3,18:1)
Block(0,23,4,18:1)
Block(0,23,5,18:1)
Block(0,23,6,18:1)
Block(0,23,7,18:1)
Block(0,23,8,18:1)
Block(0,23,9,18:1)
Block(0,23,10,18:1)
Block(0,23,13,18:1)
Block(0,23,14,18:1)
Block(0,23,15,18:1)
Block(0,24,-14,18:1)
Block(0,24,-13,18:1)
Block(0,24,-12,18:1)
Block(0,24,-11,18:1)
Block(0,24,-10,18:1)
Block(0,24,-9,18:1)
Block(0,24,-8,18:1)
Block(0,24,-7,18:1)
Block(0,24,-6,18:1)
Block(0,24,-5,18:1)
Block(0,24,-4,18:1)
Block(0,24,-3,18:1)
Block(0,24,-1,18:1)
Block(0,24,0,18:1)
Block(0,24,2,18:1)
Block(0,24,3,18:1)
Block(0,24,4,18:1)
Block(0,24,5,18:1)
Block(0,24,6,18:1)
Block(0,24,8,18:1)
Block(0,24,10,18:1)
Block(0,24,11,18:1)
Block(0,24,14,18:1)
Block(0,25,-1,18:1)
Block(0,25,0,18:1)
Block(0,25,3,18:1)
Block(0,26,5,18:1)
Block(0,26,6,18:1)
Block(1,0,-3,17)
Block(1,0,-2,17)
Block(1,0,-1,17)
Block(1,0,0,17)
Block(1,0,1,17)
Block(1,0,2,17)
Block(1,0,3,17)
Block(1,1,-2,17)
Block(1,1,-1,17)
Block(1,1,0,17)
Block(1,1,1,17)
Block(1,1,2,17)
Block(1,2,-2,17)
Block(1,2,-1,17)
Block(1,2,0,17)
Block(1,2,1,17)
Block(1,2,2,17)
Block(1,3,-1,17)
Block(1,3,0,17)
Block(1,3,1,17)
Block(1,4,-1,17)
Block(1,4,0,17)
Block(1,4,1,17)
Block(1,5,-1,17)
Block(1,5,0,17)
Block(1,5,1,17)
Block(1,6,-1,17)
Block(1,6,0,17)
Block(1,6,1,17)
Block(1,7,-1,17)
Block(1,7,0,17)
Block(1,7,1,17)
Block(1,8,-1,17)
Block(1,8,0,17)
Block(1,8,1,17)
Block(1,9,-1,17)
Block(1,9,0,17)
Block(1,9,1,17)
Block(1,10,-1,17)
Block(1,10,0,17)
Block(1,10,1,17)
Block(1,11,0,17)
Block(1,12,0,17)
Block(1,13,0,17)
Block(1,14,0,17)
Block(1,15,0,17)
Block(1,16,-1,17)
Block(1,16,0,17)
Block(1,16,1,17)
Block(1,17,-1,17)
Block(1,17,0,17)
Block(1,17,1,17)
Block(1,18,-3,18:1)
Block(1,18,-2,17)
Block(1,18,-1,17)
Block(1,18,0,17)
Block(1,18,1,17)
Block(1,18,2,17)
Block(1,18,4,18:1)
Block(1,18,5,18:1)
Block(1,18,6,18:1)
Block(1,18,8,18:1)
Block(1,18,9,18:1)
Block(1,18,10,18:1)
Block(1,19,-9,18:1)
Block(1,19,-6,18:1)
Block(1,19,-5,18:1)
Block(1,19,-4,18:1)
Block(1,19,-2,17)
Block(1,19,-1,17)
Block(1,19,0,17)
Block(1,19,1,17)
Block(1,19,2,17)
Block(1,19,7,18:1)
Block(1,19,8,18:1)
Block(1,19,9,18:1)
Block(1,20,-13,18:1)
Block(1,20,-12,18:1)
Block(1,20,-11,18:1)
Block(1,20,-10,18:1)
Block(1,20,-9,18:1)
Block(1,20,-7,18:1)
Block(1,20,-6,18:1)
Block(1,20,-5,18:1)
Block(1,20,-2,18:1)
Block(1,20,-1,17)
Block(1,20,0,17:4)
Block(1,20,1,17)
Block(1,20,2,18:1)
Block(1,20,3,18:1)
Block(1,20,4,18:1)
Block(1,20,5,18:1)
Block(1,20,6,18:1)
Block(1,20,7,18:1)
Block(1,20,8,18:1)
Block(1,20,9,18:1)
Block(1,20,10,18:1)
Block(1,20,11,18:1)
Block(1,20,13,18:1)
Block(1,21,-14,18:1)
Block(1,21,-13,18:1)
Block(1,21,-12,18:1)
Block(1,21,-11,18:1)
Block(1,21,-10,18:1)
Block(1,21,-9,18:1)
Block(1,21,-8,17:4)
Block(1,21,-7,18:1)
Block(1,21,-4,18:1)
Block(1,21,-2,18:1)
Block(1,21,-1,18:1)
Block(1,21,0,18:1)
Block(1,21,1,18:1)
Block(1,21,4,18:1)
Block(1,21,6,18:1)
Block(1,21,7,18:1)
Block(1,21,8,17:4)
Block(1,21,11,18:1)
Block(1,21,12,18:1)
Block(1,21,13,18:1)
Block(1,22,-15,18:1)
Block(1,22,-13,18:1)
Block(1,22,-12,18:1)
Block(1,22,-11,17:4)
Block(1,22,-10,18:1)
Block(1,22,-9,18:1)
Block(1,22,-8,18:1)
Block(1,22,-7,18:1)
Block(1,22,-6,18:1)
Block(1,22,-5,18:1)
Block(1,22,-4,18:1)
Block(1,22,-3,18:1)
Block(1,22,-2,18:1)
Block(1,22,-1,18:1)
Block(1,22,0,18:1)
Block(1,22,1,18:1)
Block(1,22,2,18:1)
Block(1,22,3,18:1)
Block(1,22,6,18:1)
Block(1,22,7,18:1)
Block(1,22,8,18:1)
Block(1,22,9,18:1)
Block(1,22,10,18:1)
Block(1,22,11,17:4)
Block(1,22,12,18:1)
Block(1,22,13,18:1)
Block(1,22,14,18:1)
Block(1,23,-13,18:1)
Block(1,23,-11,18:1)
Block(1,23,-10,18:1)
Block(1,23,-9,18:1)
Block(1,23,-8,18:1)
Block(1,23,-7,18:1)
Block(1,23,-6,18:1)
Block(1,23,-5,18:1)
Block(1,23,-4,18:1)
Block(1,23,-3,18:1)
Block(1,23,-2,18:1)
Block(1,23,-1,18:1)
Block(1,23,0,18:1)
Block(1,23,1,18:1)
Block(1,23,2,18:1)
Block(1,23,3,18:1)
Block(1,23,5,18:1)
Block(1,23,6,18:1)
Block(1,23,7,18:1)
Block(1,23,8,18:1)
Block(1,23,10,18:1)
Block(1,23,11,18:1)
Block(1,23,12,18:1)
Block(1,24,-14,18:1)
Block(1,24,-13,18:1)
Block(1,24,-12,18:1)
Block(1,24,-10,18:1)
Block(1,24,-9,18:1)
Block(1,24,-8,18:1)
Block(1,24,-6,18:1)
Block(1,24,-5,18:1)
Block(1,24,-3,18:1)
Block(1,24,-2,18:1)
Block(1,24,-1,18:1)
Block(1,24,0,18:1)
Block(1,24,1,18:1)
Block(1,24,2,18:1)
Block(1,24,4,18:1)
Block(1,24,6,18:1)
Block(1,24,7,18:1)
Block(1,24,10,18:1)
Block(1,24,12,18:1)
Block(1,24,14,18:1)
Block(1,25,-9,18:1)
Block(1,25,-8,18:1)
Block(1,25,-7,18:1)
Block(1,25,-5,18:1)
Block(1,25,-4,18:1)
Block(1,25,-1,18:1)
Block(1,25,0,18:1)
Block(1,25,1,18:1)
Block(1,25,3,18:1)
Block(1,25,6,18:1)
Block(1,25,8,18:1)
Block(1,25,9,18:1)
Block(2,0,-2,17)
Block(2,0,-1,17)
Block(2,0,0,17)
Block(2,0,1,17)
Block(2,0,2,17)
Block(2,1,-2,17)
Block(2,1,-1,17)
Block(2,1,0,17)
Block(2,1,1,17)
Block(2,1,2,17)
Block(2,2,-1,17)
Block(2,2,0,17)
Block(2,2,1,17)
Block(2,3,0,17)
Block(2,4,0,17)
Block(2,16,0,17)
Block(2,17,0,17)
Block(2,18,-2,17)
Block(2,18,-1,17)
Block(2,18,0,17)
Block(2,18,1,17)
Block(2,18,2,17)
Block(2,18,10,18:1)
Block(2,19,-5,18:1)
Block(2,19,-4,18:1)
Block(2,19,-3,18:1)
Block(2,19,-2,17)
Block(2,19,-1,17)
Block(2,19,0,17)
Block(2,19,1,17)
Block(2,19,2,17)
Block(2,19,6,18:1)
Block(2,19,7,18:1)
Block(2,19,9,18:1)
Block(2,20,-12,18:1)
Block(2,20,-11,18:1)
Block(2,20,-10,18:1)
Block(2,20,-5,18:1)
Block(2,20,-4,18:1)
Block(2,20,-3,18:1)
Block(2,20,-2,17)
Block(2,20,-1,18:1)
Block(2,20,0,17:4)
Block(2,20,2,17)
Block(2,20,3,18:1)
Block(2,20,4,18:1)
Block(2,20,5,18:1)
Block(2,20,6,18:1)
Block(2,20,7,18:1)
Block(2,20,8,18:1)
Block(2,20,9,18:1)
Block(2,20,11,18:1)
Block(2,21,-13,18:1)
Block(2,21,-12,18:1)
Block(2,21,-11,18:1)
Block(2,21,-10,18:1)
Block(2,21,-9,18:1)
Block(2,21,-8,17:4)
Block(2,21,-7,18:1)
Block(2,21,-6,18:1)
Block(2,21,-5,18:1)
Block(2,21,-4,18:1)
Block(2,21,-3,18:1)
Block(2,21,-2,17)
Block(2,21,-1,18:1)
Block(2,21,0,18:1)
Block(2,21,1,18:1)
Block(2,21,2,17)
Block(2,21,4,18:1)
Block(2,21,5,18:1)
Block(2,21,6,18:1)
Block(2,21,7,18:1)
Block(2,21,8,17:4)
Block(2,21,9,18:1)
Block(2,21,10,18:1)
Block(2,21,11,18:1)
Block(2,21,12,18:1)
Block(2,21,13,18:1)
Block(2,21,14,18:1)
Block(2,22,-14,18:1)
Block(2,22,-13,18:1)
Block(2,22,-11,17:4)
Block(2,22,-10,18:1)
Block(2,22,-9,18:1)
Block(2,22,-8,18:1)
Block(2,22,-7,18:1)
Block(2,22,-6,18:1)
Block(2,22,-5,18:1)
Block(2,22,-4,18:1)
Block(2,22,-3,18:1)
Block(2,22,-2,17)
Block(2,22,-1,18:1)
Block(2,22,0,18:1)
Block(2,22,1,18:1)
Block(2,22,2,17)
Block(2,22,3,18:1)
Block(2,22,4,18:1)
Block(2,22,5,18:1)
Block(2,22,6,18:1)
Block(2,22,7,18:1)
Block(2,22,8,18:1)
Block(2,22,9,18:1)
Block(2,22,10,18:1)
Block(2,22,11,17:4)
Block(2,22,12,18:1)
Block(2,22,13,18:1)
Block(2,22,14,18:1)
Block(2,23,-12,18:1)
Block(2,23,-11,18:1)
Block(2,23,-10,18:1)
Block(2,23,-9,18:1)
Block(2,23,-8,17:8)
Block(2,23,-7,17:8)
Block(2,23,-6,17:8)
Block(2,23,-5,17:8)
Block(2,23,-4,17:8)
Block(2,23,-3,17:8)
Block(2,23,-2,18:1)
Block(2,23,-1,18:1)
Block(2,23,0,18:1)
Block(2,23,2,18:1)
Block(2,23,3,17:8)
Block(2,23,4,17:8)
Block(2,23,5,17:8)
Block(2,23,6,17:8)
Block(2,23,7,17:8)
Block(2,23,8,17:8)
Block(2,23,9,18:1)
Block(2,23,10,18:1)
Block(2,23,11,18:1)
Block(2,23,12,18:1)
Block(2,24,-10,18:1)
Block(2,24,-9,18:1)
Block(2,24,-8,18:1)
Block(2,24,-7,18:1)
Block(2,24,-6,18:1)
Block(2,24,-5,18:1)
Block(2,24,-4,18:1)
Block(2,24,-3,18:1)
Block(2,24,-2,18:1)
Block(2,24,-1,18:1)
Block(2,24,0,18:1)
Block(2,24,1,18:1)
Block(2,24,2,18:1)
Block(2,24,3,18:1)
Block(2,24,5,18:1)
Block(2,24,6,18:1)
Block(2,24,7,18:1)
Block(2,24,8,18:1)
Block(2,24,9,18:1)
Block(2,25,-9,18:1)
Block(2,25,-8,18:1)
Block(2,25,-7,18:1)
Block(2,25,-4,18:1)
Block(2,25,-2,18:1)
Block(2,25,-1,18:1)
Block(2,25,2,18:1)
Block(2,25,3,18:1)
Block(2,25,5,18:1)
Block(2,25,7,18:1)
Block(2,25,8,18:1)
Block(3,0,-1,17)
Block(3,0,0,17)
Block(3,0,1,17)
Block(3,1,0,17)
Block(3,18,0,17)
Block(3,18,1,18:1)
Block(3,18,6,18:1)
Block(3,18,7,18:1)
Block(3,19,-3,17:8)
Block(3,19,-1,18:1)
Block(3,19,0,17)
Block(3,19,2,18:1)
Block(3,19,3,17:4)
Block(3,19,5,18:1)
Block(3,19,6,18:1)
Block(3,19,8,18:1)
Block(3,20,-11,18:1)
Block(3,20,-8,18:1)
Block(3,20,-6,18:1)
Block(3,20,-4,18:1)
Block(3,20,-2,18:1)
Block(3,20,-1,18:1)
Block(3,20,0,17:4)
Block(3,20,1,18:1)
Block(3,20,2,18:1)
Block(3,20,3,18:1)
Block(3,20,5,18:1)
Block(3,20,6,18:1)
Block(3,20,7,18:1)
Block(3,20,8,18:1)
Block(3,20,9,18:1)
Block(3,20,10,18:1)
Block(3,20,11,18:1)
Block(3,21,-13,18:1)
Block(3,21,-12,18:1)
Block(3,21,-10,18:1)
Block(3,21,-9,18:1)
Block(3,21,-8,17:4)
Block(3,21,-7,18:1)
Block(3,21,-6,18:1)
Block(3,21,-5,18:1)
Block(3,21,-4,18:1)
Block(3,21,-3,18:1)
Block(3,21,-2,18:1)
Block(3,21,-1,18:1)
Block(3,21,0,18:1)
Block(3,21,2,18:1)
Block(3,21,3,18:1)
Block(3,21,4,18:1)
Block(3,21,5,18:1)
Block(3,21,6,18:1)
Block(3,21,7,18:1)
Block(3,21,8,17:4)
Block(3,21,9,18:1)
Block(3,21,10,18:1)
Block(3,21,13,18:1)
Block(3,22,-13,18:1)
Block(3,22,-12,18:1)
Block(3,22,-11,17:4)
Block(3,22,-10,18:1)
Block(3,22,-8,18:1)
Block(3,22,-7,18:1)
Block(3,22,-6,18:1)
Block(3,22,-5,18:1)
Block(3,22,-4,18:1)
Block(3,22,-3,18:1)
Block(3,22,-2,18:1)
Block(3,22,-1,18:1)
Block(3,22,0,18:1)
Block(3,22,1,18:1)
Block(3,22,2,18:1)
Block(3,22,3,18:1)
Block(3,22,5,18:1)
Block(3,22,6,18:1)
Block(3,22,7,18:1)
Block(3,22,8,18:1)
Block(3,22,11,17:4)
Block(3,22,12,18:1)
Block(3,23,-11,18:1)
Block(3,23,-10,18:1)
Block(3,23,-8,18:1)
Block(3,23,-6,17:4)
Block(3,23,-5,18:1)
Block(3,23,-2,17:4)
Block(3,23,-1,18:1)
Block(3,23,0,18:1)
Block(3,23,1,18:1)
Block(3,23,2,17:4)
Block(3,23,3,18:1)
Block(3,23,4,18:1)
Block(3,23,5,18:1)
Block(3,23,6,17:4)
Block(3,23,7,18:1)
Block(3,23,8,18:1)
Block(3,23,9,18:1)
Block(3,23,10,18:1)
Block(3,24,-11,18:1)
Block(3,24,-10,18:1)
Block(3,24,-9,18:1)
Block(3,24,-7,18:1)
Block(3,24,-6,18:1)
Block(3,24,-5,18:1)
Block(3,24,-4,18:1)
Block(3,24,-3,18:1)
Block(3,24,-2,18:1)
Block(3,24,-1,18:1)
Block(3,24,0,18:1)
Block(3,24,1,18:1)
Block(3,24,2,18:1)
Block(3,24,3,18:1)
Block(3,24,4,18:1)
Block(3,24,6,18:1)
Block(3,24,7,18:1)
Block(3,24,8,18:1)
Block(3,24,9,18:1)
Block(3,24,10,18:1)
Block(3,24,12,18:1)
Block(3,25,-9,18:1)
Block(3,25,-8,18:1)
Block(3,25,-6,18:1)
Block(3,25,-5,18:1)
Block(3,25,-4,18:1)
Block(3,25,-3,18:1)
Block(3,25,-2,18:1)
Block(3,25,0,18:1)
Block(3,25,1,18:1)
Block(3,25,2,18:1)
Block(3,25,5,18:1)
Block(3,25,6,18:1)
Block(3,25,7,18:1)
Block(4,18,-4,18:1)
Block(4,18,-3,18:1)
Block(4,18,-1,18:1)
Block(4,18,0,18:1)
Block(4,18,1,18:1)
Block(4,18,3,18:1)
Block(4,18,4,18:1)
Block(4,18,6,18:1)
Block(4,18,7,18:1)
Block(4,18,8,18:1)
Block(4,19,-8,18:1)
Block(4,19,-7,18:1)
Block(4,19,-6,18:1)
Block(4,19,-4,18:1)
Block(4,19,-3,18:1)
Block(4,19,-2,18:1)
Block(4,19,-1,18:1)
Block(4,19,0,17:4)
Block(4,19,1,18:1)
Block(4,19,2,18:1)
Block(4,19,3,18:1)
Block(4,19,4,18:1)
Block(4,19,5,18:1)
Block(4,19,6,18:1)
Block(4,19,8,18:1)
Block(4,20,-11,18:1)
Block(4,20,-10,18:1)
Block(4,20,-9,18:1)
Block(4,20,-8,18:1)
Block(4,20,-6,18:1)
Block(4,20,-5,18:1)
Block(4,20,-4,17:8)
Block(4,20,-3,18:1)
Block(4,20,-2,18:1)
Block(4,20,-1,18:1)
Block(4,20,0,17:4)
Block(4,20,2,18:1)
Block(4,20,4,17:4)
Block(4,20,5,18:1)
Block(4,20,6,18:1)
Block(4,20,7,18:1)
Block(4,20,8,18:1)
Block(4,20,9,18:1)
Block(4,20,10,18:1)
Block(4,20,11,18:1)
Block(4,21,-12,18:1)
Block(4,21,-11,18:1)
Block(4,21,-10,18:1)
Block(4,21,-9,18:1)
Block(4,21,-8,18:1)
Block(4,21,-7,18:1)
Block(4,21,-6,18:1)
Block(4,21,-5,18:1)
Block(4,21,-3,18:1)
Block(4,21,-2,18:1)
Block(4,21,-1,18:1)
Block(4,21,0,18:1)
Block(4,21,1,18:1)
Block(4,21,3,18:1)
Block(4,21,4,18:1)
Block(4,21,5,18:1)
Block(4,21,6,18:1)
Block(4,21,7,18:1)
Block(4,21,8,18:1)
Block(4,21,9,18:1)
Block(4,21,11,18:1)
Block(4,21,12,18:1)
Block(4,21,13,18:1)
Block(4,22,-11,17:4)
Block(4,22,-9,18:1)
Block(4,22,-8,18:1)
Block(4,22,-7,18:1)
Block(4,22,-6,18:1)
Block(4,22,-5,18:1)
Block(4,22,-4,18:1)
Block(4,22,-3,18:1)
Block(4,22,-2,18:1)
Block(4,22,-1,18:1)
Block(4,22,0,18:1)
Block(4,22,1,18:1)
Block(4,22,2,18:1)
Block(4,22,3,18:1)
Block(4,22,4,18:1)
Block(4,22,5,18:1)
Block(4,22,6,18:1)
Block(4,22,7,18:1)
Block(4,22,8,18:1)
Block(4,22,9,18:1)
Block(4,22,10,18:1)
Block(4,22,11,17:4)
Block(4,22,12,18:1)
Block(4,22,13,18:1)
Block(4,23,-13,18:1)
Block(4,23,-11,18:1)
Block(4,23,-10,18:1)
Block(4,23,-8,18:1)
Block(4,23,-7,18:1)
Block(4,23,-6,17:4)
Block(4,23,-5,18:1)
Block(4,23,-4,18:1)
Block(4,23,-3,18:1)
Block(4,23,-2,17:4)
Block(4,23,-1,18:1)
Block(4,23,0,18:1)
Block(4,23,1,18:1)
Block(4,23,2,17:4)
Block(4,23,3,18:1)
Block(4,23,4,18:1)
Block(4,23,5,18:1)
Block(4,23,6,17:4)
Block(4,23,7,18:1)
Block(4,23,8,18:1)
Block(4,23,9,18:1)
Block(4,23,11,18:1)
Block(4,24,-11,18:1)
Block(4,24,-10,18:1)
Block(4,24,-9,18:1)
Block(4,24,-8,18:1)
Block(4,24,-7,18:1)
Block(4,24,-6,18:1)
Block(4,24,-4,18:1)
Block(4,24,-3,18:1)
Block(4,24,0,18:1)
Block(4,24,1,18:1)
Block(4,24,2,18:1)
Block(4,24,3,18:1)
Block(4,24,4,18:1)
Block(4,24,5,18:1)
Block(4,24,6,18:1)
Block(4,24,7,18:1)
Block(4,24,8,18:1)
Block(4,24,9,18:1)
Block(4,24,10,18:1)
Block(4,25,-3,18:1)
Block(4,25,-2,18:1)
Block(4,25,0,18:1)
Block(4,25,1,18:1)
Block(4,25,4,18:1)
Block(4,25,5,18:1)
Block(4,25,7,18:1)
Block(5,17,-1,18:1)
Block(5,18,-4,18:1)
Block(5,18,0,18:1)
Block(5,18,4,18:1)
Block(5,18,6,18:1)
Block(5,18,7,18:1)
Block(5,18,8,18:1)
Block(5,19,-8,18:1)
Block(5,19,-6,18:1)
Block(5,19,-5,18:1)
Block(5,19,-4,18:1)
Block(5,19,-2,18:1)
Block(5,19,-1,18:1)
Block(5,19,0,18:1)
Block(5,19,1,18:1)
Block(5,19,2,18:1)
Block(5,19,4,18:1)
Block(5,19,5,18:1)
Block(5,19,7,18:1)
Block(5,19,8,18:1)
Block(5,20,-10,18:1)
Block(5,20,-9,18:1)
Block(5,20,-7,18:1)
Block(5,20,-6,18:1)
Block(5,20,-5,17:8)
Block(5,20,-4,18:1)
Block(5,20,-3,18:1)
Block(5,20,-2,18:1)
Block(5,20,0,17:4)
Block(5,20,1,18:1)
Block(5,20,2,18:1)
Block(5,20,3,18:1)
Block(5,20,4,18:1)
Block(5,20,5,17:4)
Block(5,20,7,18:1)
Block(5,20,8,18:1)
Block(5,20,9,18:1)
Block(5,20,10,18:1)
Block(5,20,11,18:1)
Block(5,20,12,18:1)
Block(5,21,-12,18:1)
Block(5,21,-11,18:1)
Block(5,21,-9,18:1)
Block(5,21,-8,17:4)
Block(5,21,-7,18:1)
Block(5,21,-6,18:1)
Block(5,21,-5,18:1)
Block(5,21,-4,18:1)
Block(5,21,-3,18:1)
Block(5,21,-2,18:1)
Block(5,21,-1,18:1)
Block(5,21,0,18:1)
Block(5,21,2,18:1)
Block(5,21,3,18:1)
Block(5,21,4,18:1)
Block(5,21,5,18:1)
Block(5,21,6,18:1)
Block(5,21,7,18:1)
Block(5,21,8,17:4)
Block(5,21,9,18:1)
Block(5,21,10,18:1)
Block(5,21,12,18:1)
Block(5,22,-13,18:1)
Block(5,22,-12,18:1)
Block(5,22,-11,18:1)
Block(5,22,-10,18:1)
Block(5,22,-8,18:1)
Block(5,22,-7,18:1)
Block(5,22,-6,18:1)
Block(5,22,-5,18:1)
Block(5,22,-3,18:1)
Block(5,22,-2,18:1)
Block(5,22,-1,18:1)
Block(5,22,0,18:1)
Block(5,22,4,18:1)
Block(5,22,5,18:1)
Block(5,22,6,18:1)
Block(5,22,7,18:1)
Block(5,22,8,18:1)
Block(5,22,9,18:1)
Block(5,22,10,18:1)
Block(5,22,11,18:1)
Block(5,22,12,18:1)
Block(5,22,13,18:1)
Block(5,23,-13,18:1)
Block(5,23,-12,18:1)
Block(5,23,-11,18:1)
Block(5,23,-9,18:1)
Block(5,23,-8,18:1)
Block(5,23,-7,18:1)
Block(5,23,-6,18:1)
Block(5,23,-5,18:1)
Block(5,23,-4,18:1)
Block(5,23,-3,18:1)
Block(5,23,-2,17:4)
Block(5,23,-1,18:1)
Block(5,23,0,18:1)
Block(5,23,1,18:1)
Block(5,23,2,17:4)
Block(5,23,3,18:1)
Block(5,23,4,18:1)
Block(5,23,5,18:1)
Block(5,23,6,18:1)
Block(5,23,7,18:1)
Block(5,23,8,18:1)
Block(5,23,9,18:1)
Block(5,23,10,18:1)
Block(5,23,11,18:1)
Block(5,23,12,18:1)
Block(5,24,-11,18:1)
Block(5,24,-8,18:1)
Block(5,24,-6,18:1)
Block(5,24,-5,18:1)
Block(5,24,-3,18:1)
Block(5,24,-2,18:1)
Block(5,24,-1,18:1)
Block(5,24,1,18:1)
Block(5,24,2,18:1)
Block(5,24,3,18:1)
Block(5,24,5,18:1)
Block(5,24,6,18:1)
Block(5,24,7,18:1)
Block(5,24,10,18:1)
Block(5,24,11,18:1)
Block(5,24,12,18:1)
Block(5,25,-4,18:1)
Block(5,25,-2,18:1)
Block(5,25,0,18:1)
Block(5,25,2,18:1)
Block(5,25,3,18:1)
Block(5,25,5,18:1)
Block(5,25,6,18:1)
Block(6,17,0,18:1)
Block(6,18,-2,18:1)
Block(6,18,-1,18:1)
Block(6,18,0,18:1)
Block(6,18,1,18:1)
Block(6,18,2,18:1)
Block(6,19,-8,18:1)
Block(6,19,-6,18:1)
Block(6,19,-5,18:1)
Block(6,19,-4,18:1)
Block(6,19,-3,18:1)
Block(6,19,-2,18:1)
Block(6,19,-1,18:1)
Block(6,19,0,18:1)
Block(6,19,1,18:1)
Block(6,19,2,18:1)
Block(6,19,6,18:1)
Block(6,19,7,18:1)
Block(6,19,8,18:1)
Block(6,19,9,18:1)
Block(6,20,-11,18:1)
Block(6,20,-7,18:1)
Block(6,20,-5,18:1)
Block(6,20,-4,18:1)
Block(6,20,-2,18:1)
Block(6,20,0,17:4)
Block(6,20,1,18:1)
Block(6,20,4,18:1)
Block(6,20,5,18:1)
Block(6,20,6,18:1)
Block(6,20,7,18:1)
Block(6,20,9,18:1)
Block(6,20,10,18:1)
Block(6,20,11,18:1)
Block(6,20,12,18:1)
Block(6,21,-12,18:1)
Block(6,21,-11,18:1)
Block(6,21,-10,18:1)
Block(6,21,-9,18:1)
Block(6,21,-8,17:4)
Block(6,21,-7,18:1)
Block(6,21,-6,17:8)
Block(6,21,-5,18:1)
Block(6,21,-4,18:1)
Block(6,21,-3,18:1)
Block(6,21,-1,18:1)
Block(6,21,0,18:1)
Block(6,21,1,18:1)
Block(6,21,4,18:1)
Block(6,21,5,18:1)
Block(6,21,6,17:4)
Block(6,21,7,18:1)
Block(6,21,8,17:4)
Block(6,21,9,18:1)
Block(6,21,10,18:1)
Block(6,21,11,18:1)
Block(6,22,-13,18:1)
Block(6,22,-12,18:1)
Block(6,22,-11,18:1)
Block(6,22,-10,18:1)
Block(6,22,-9,18:1)
Block(6,22,-8,18:1)
Block(6,22,-7,18:1)
Block(6,22,-6,18:1)
Block(6,22,-5,18:1)
Block(6,22,-4,18:1)
Block(6,22,-3,18:1)
Block(6,22,-2,18:1)
Block(6,22,-1,18:1)
Block(6,22,0,18:1)
Block(6,22,1,18:1)
Block(6,22,2,18:1)
Block(6,22,3,18:1)
Block(6,22,4,18:1)
Block(6,22,6,18:1)
Block(6,22,7,18:1)
Block(6,22,8,18:1)
Block(6,22,9,18:1)
Block(6,22,10,18:1)
Block(6,22,11,18:1)
Block(6,22,13,18:1)
Block(6,23,-12,18:1)
Block(6,23,-11,18:1)
Block(6,23,-10,18:1)
Block(6,23,-9,18:1)
Block(6,23,-8,18:1)
Block(6,23,-7,18:1)
Block(6,23,-6,18:1)
Block(6,23,-5,18:1)
Block(6,23,-4,17:8)
Block(6,23,-3,17:8)
Block(6,23,-2,17:4)
Block(6,23,-1,18:1)
Block(6,23,0,18:1)
Block(6,23,1,18:1)
Block(6,23,2,17:4)
Block(6,23,3,17:8)
Block(6,23,4,17:8)
Block(6,23,5,18:1)
Block(6,23,6,18:1)
Block(6,23,7,18:1)
Block(6,23,8,18:1)
Block(6,23,9,18:1)
Block(6,23,10,18:1)
Block(6,23,11,18:1)
Block(6,23,12,18:1)
Block(6,24,-12,18:1)
Block(6,24,-9,18:1)
Block(6,24,-8,18:1)
Block(6,24,-7,18:1)
Block(6,24,-5,18:1)
Block(6,24,-4,18:1)
Block(6,24,-3,18:1)
Block(6,24,0,18:1)
Block(6,24,2,18:1)
Block(6,24,4,18:1)
Block(6,24,5,18:1)
Block(6,24,6,18:1)
Block(6,24,10,18:1)
Block(6,24,11,18:1)
Block(6,25,-5,18:1)
Block(6,25,-1,18:1)
Block(6,25,0,18:1)
Block(6,25,3,18:1)
Block(6,25,4,18:1)
Block(6,25,5,18:1)
Block(7,17,1,18:1)
Block(7,18,0,18:1)
Block(7,18,1,18:1)
Block(7,19,-7,18:1)
Block(7,19,-6,18:1)
Block(7,19,-2,18:1)
Block(7,19,0,18:1)
Block(7,19,1,18:1)
Block(7,19,2,18:1)
Block(7,19,5,18:1)
Block(7,19,6,18:1)
Block(7,19,7,18:1)
Block(7,19,8,18:1)
Block(7,20,-12,18:1)
Block(7,20,-8,18:1)
Block(7,20,-7,18:1)
Block(7,20,-6,18:1)
Block(7,20,-3,18:1)
Block(7,20,0,18:1)
Block(7,20,3,18:1)
Block(7,20,4,18:1)
Block(7,20,5,18:1)
Block(7,20,6,18:1)
Block(7,20,7,18:1)
Block(7,20,9,18:1)
Block(7,20,11,18:1)
Block(7,20,12,18:1)
Block(7,21,-13,18:1)
Block(7,21,-11,18:1)
Block(7,21,-10,18:1)
Block(7,21,-9,18:1)
Block(7,21,-8,18:1)
Block(7,21,-7,17:8)
Block(7,21,-6,18:1)
Block(7,21,-5,18:1)
Block(7,21,-4,18:1)
Block(7,21,-3,18:1)
Block(7,21,-2,18:1)
Block(7,21,0,17:4)
Block(7,21,2,18:1)
Block(7,21,4,18:1)
Block(7,21,5,18:1)
Block(7,21,6,18:1)
Block(7,21,7,17:4)
Block(7,21,8,18:1)
Block(7,21,9,18:1)
Block(7,21,10,18:1)
Block(7,21,11,18:1)
Block(7,21,12,18:1)
Block(7,21,13,18:1)
Block(7,22,-13,18:1)
Block(7,22,-12,18:1)
Block(7,22,-11,17:8)
Block(7,22,-10,18:1)
Block(7,22,-9,18:1)
Block(7,22,-8,18:1)
Block(7,22,-7,18:1)
Block(7,22,-6,18:1)
Block(7,22,-5,18:1)
Block(7,22,-4,18:1)
Block(7,22,-3,18:1)
Block(7,22,-1,18:1)
Block(7,22,0,18:1)
Block(7,22,1,18:1)
Block(7,22,3,18:1)
Block(7,22,5,18:1)
Block(7,22,6,18:1)
Block(7,22,7,18:1)
Block(7,22,8,18:1)
Block(7,22,9,18:1)
Block(7,22,10,18:1)
Block(7,22,11,17:4)
Block(7,22,12,18:1)
Block(7,22,13,18:1)
Block(7,23,-12,18:1)
Block(7,23,-11,18:1)
Block(7,23,-10,18:1)
Block(7,23,-9,18:1)
Block(7,23,-8,18:1)
Block(7,23,-7,18:1)
Block(7,23,-5,18:1)
Block(7,23,-4,18:1)
Block(7,23,-3,18:1)
Block(7,23,-2,17:4)
Block(7,23,-1,18:1)
Block(7,23,0,18:1)
Block(7,23,1,18:1)
Block(7,23,2,17:4)
Block(7,23,3,18:1)
Block(7,23,4,18:1)
Block(7,23,5,18:1)
Block(7,23,6,18:1)
Block(7,23,7,18:1)
Block(7,23,8,18:1)
Block(7,23,9,18:1)
Block(7,23,10,18:1)
Block(7,23,11,18:1)
Block(7,23,12,18:1)
Block(7,24,-11,18:1)
Block(7,24,-9,18:1)
Block(7,24,-8,18:1)
Block(7,24,-6,18:1)
Block(7,24,-4,18:1)
Block(7,24,-3,18:1)
Block(7,24,-2,18:1)
Block(7,24,-1,18:1)
Block(7,24,0,18:1)
Block(7,24,1,18:1)
Block(7,24,2,18:1)
Block(7,24,3,18:1)
Block(7,24,4,18:1)
Block(7,24,10,18:1)
Block(7,24,11,18:1)
Block(7,24,12,18:1)
Block(7,25,-8,18:1)
Block(7,25,-2,18:1)
Block(7,25,-1,18:1)
Block(7,25,0,18:1)
Block(7,25,1,18:1)
Block(8,18,0,18:1)
Block(8,18,1,18:1)
Block(8,19,-6,18:1)
Block(8,19,-5,18:1)
Block(8,19,-4,18:1)
Block(8,19,-2,18:1)
Block(8,19,-1,18:1)
Block(8,19,0,18:1)
Block(8,19,1,18:1)
Block(8,19,4,18:1)
Block(8,19,5,18:1)
Block(8,20,-11,18:1)
Block(8,20,-10,18:1)
Block(8,20,-8,18:1)
Block(8,20,-6,18:1)
Block(8,20,-4,18:1)
Block(8,20,-3,18:1)
Block(8,20,-2,18:1)
Block(8,20,-1,18:1)
Block(8,20,1,18:1)
Block(8,20,2,18:1)
Block(8,20,3,18:1)
Block(8,20,5,18:1)
Block(8,20,6,18:1)
Block(8,20,7,18:1)
Block(8,20,8,18:1)
Block(8,20,12,18:1)
Block(8,21,-12,18:1)
Block(8,21,-11,18:1)
Block(8,21,-10,18:1)
Block(8,21,-9,18:1)
Block(8,21,-8,18:1)
Block(8,21,-7,18:1)
Block(8,21,-6,17:8)
Block(8,21,-5,17:8)
Block(8,21,-4,18:1)
Block(8,21,-3,17:8)
Block(8,21,-2,17:8)
Block(8,21,-1,17:8)
Block(8,21,0,17:4)
Block(8,21,1,17:8)
Block(8,21,2,17:8)
Block(8,21,3,17:8)
Block(8,21,4,18:1)
Block(8,21,5,17:8)
Block(8,21,6,17:8)
Block(8,21,7,18:1)
Block(8,21,9,18:1)
Block(8,21,10,18:1)
Block(8,22,-11,18:1)
Block(8,22,-10,17:8)
Block(8,22,-9,18:1)
Block(8,22,-8,17:8)
Block(8,22,-7,18:1)
Block(8,22,-6,18:1)
Block(8,22,-5,18:1)
Block(8,22,-4,18:1)
Block(8,22,-3,18:1)
Block(8,22,-2,18:1)
Block(8,22,-1,18:1)
Block(8,22,0,18:1)
Block(8,22,3,18:1)
Block(8,22,4,18:1)
Block(8,22,6,18:1)
Block(8,22,7,18:1)
Block(8,22,8,17:4)
Block(8,22,9,18:1)
Block(8,22,10,17:4)
Block(8,22,11,18:1)
Block(8,22,13,18:1)
Block(8,23,-12,18:1)
Block(8,23,-11,18:1)
Block(8,23,-10,18:1)
Block(8,23,-9,18:1)
Block(8,23,-8,18:1)
Block(8,23,-7,18:1)
Block(8,23,-6,18:1)
Block(8,23,-4,18:1)
Block(8,23,-3,18:1)
Block(8,23,-2,17:4)
Block(8,23,-1,18:1)
Block(8,23,0,18:1)
Block(8,23,1,18:1)
Block(8,23,2,17:4)
Block(8,23,3,18:1)
Block(8,23,5,18:1)
Block(8,23,6,18:1)
Block(8,23,7,18:1)
Block(8,23,8,18:1)
Block(8,23,9,18:1)
Block(8,23,10,18:1)
Block(8,23,13,18:1)
Block(8,24,-11,18:1)
Block(8,24,-9,18:1)
Block(8,24,-8,18:1)
Block(8,24,-5,18:1)
Block(8,24,-4,18:1)
Block(8,24,-2,18:1)
Block(8,24,-1,18:1)
Block(8,24,0,18:1)
Block(8,24,1,18:1)
Block(8,24,3,18:1)
Block(8,24,4,18:1)
Block(8,24,6,18:1)
Block(8,24,7,18:1)
Block(8,24,10,18:1)
Block(8,24,11,18:1)
Block(8,25,-9,18:1)
Block(8,25,-8,18:1)
Block(8,25,-3,18:1)
Block(8,25,-2,18:1)
Block(8,25,-1,18:1)
Block(8,25,1,18:1)
Block(9,19,-7,18:1)
Block(9,19,-6,18:1)
Block(9,19,-5,18:1)
Block(9,19,-4,18:1)
Block(9,19,-1,18:1)
Block(9,19,5,18:1)
Block(9,20,-10,18:1)
Block(9,20,-8,18:1)
Block(9,20,-6,18:1)
Block(9,20,-5,18:1)
Block(9,20,-2,18:1)
Block(9,20,-1,18:1)
Block(9,20,1,18:1)
Block(9,20,3,18:1)
Block(9,20,6,18:1)
Block(9,20,7,18:1)
Block(9,20,10,18:1)
Block(9,20,11,18:1)
Block(9,21,-11,18:1)
Block(9,21,-8,18:1)
Block(9,21,-7,18:1)
Block(9,21,-6,18:1)
Block(9,21,-4,18:1)
Block(9,21,-3,18:1)
Block(9,21,-2,18:1)
Block(9,21,-1,18:1)
Block(9,21,0,17:4)
Block(9,21,1,18:1)
Block(9,21,2,18:1)
Block(9,21,3,18:1)
Block(9,21,5,18:1)
Block(9,21,6,18:1)
Block(9,21,7,18:1)
Block(9,21,9,18:1)
Block(9,21,10,18:1)
Block(9,21,11,18:1)
Block(9,21,12,18:1)
Block(9,22,-12,18:1)
Block(9,22,-11,18:1)
Block(9,22,-10,18:1)
Block(9,22,-9,17:8)
Block(9,22,-8,18:1)
Block(9,22,-7,18:1)
Block(9,22,-6,18:1)
Block(9,22,-4,18:1)
Block(9,22,-3,18:1)
Block(9,22,-2,18:1)
Block(9,22,-1,18:1)
Block(9,22,0,18:1)
Block(9,22,1,18:1)
Block(9,22,3,18:1)
Block(9,22,4,18:1)
Block(9,22,5,18:1)
Block(9,22,6,18:1)
Block(9,22,7,18:1)
Block(9,22,8,18:1)
Block(9,22,9,17:4)
Block(9,22,10,18:1)
Block(9,22,11,18:1)
Block(9,22,12,18:1)
Block(9,23,-10,18:1)
Block(9,23,-9,18:1)
Block(9,23,-8,18:1)
Block(9,23,-7,18:1)
Block(9,23,-6,18:1)
Block(9,23,-5,18:1)
Block(9,23,-4,18:1)
Block(9,23,-3,18:1)
Block(9,23,-2,18:1)
Block(9,23,-1,18:1)
Block(9,23,0,18:1)
Block(9,23,1,18:1)
Block(9,23,2,18:1)
Block(9,23,3,18:1)
Block(9,23,4,18:1)
Block(9,23,5,18:1)
Block(9,23,6,18:1)
Block(9,23,7,18:1)
Block(9,23,8,18:1)
Block(9,23,9,18:1)
Block(9,23,10,18:1)
Block(9,23,12,18:1)
Block(9,24,-10,18:1)
Block(9,24,-9,18:1)
Block(9,24,-4,18:1)
Block(9,24,-2,18:1)
Block(9,24,-1,18:1)
Block(9,24,0,18:1)
Block(9,24,1,18:1)
Block(9,24,3,18:1)
Block(9,24,7,18:1)
Block(9,24,8,18:1)
Block(9,24,11,18:1)
Block(9,25,-10,18:1)
Block(9,25,-9,18:1)
Block(9,25,-2,18:1)
Block(9,25,-1,18:1)
Block(9,25,0,18:1)
Block(9,25,1,18:1)
Block(9,25,2,18:1)
Block(10,19,1,18:1)
Block(10,20,-11,18:1)
Block(10,20,-10,18:1)
Block(10,20,-9,18:1)
Block(10,20,-7,18:1)
Block(10,20,-6,18:1)
Block(10,20,-5,18:1)
Block(10,20,-4,18:1)
Block(10,20,-3,18:1)
Block(10,20,0,18:1)
Block(10,20,1,18:1)
Block(10,20,2,18:1)
Block(10,20,3,18:1)
Block(10,20,4,18:1)
Block(10,20,7,18:1)
Block(10,20,9,18:1)
Block(10,20,10,18:1)
Block(10,20,11,18:1)
Block(10,21,-12,18:1)
Block(10,21,-11,18:1)
Block(10,21,-10,18:1)
Block(10,21,-9,18:1)
Block(10,21,-7,18:1)
Block(10,21,-6,18:1)
Block(10,21,-5,18:1)
Block(10,21,-4,18:1)
Block(10,21,-3,18:1)
Block(10,21,-2,18:1)
Block(10,21,-1,18:1)
Block(10,21,0,18:1)
Block(10,21,1,18:1)
Block(10,21,2,18:1)
Block(10,21,4,18:1)
Block(10,21,5,18:1)
Block(10,21,6,18:1)
Block(10,21,7,18:1)
Block(10,21,9,18:1)
Block(10,21,10,18:1)
Block(10,21,11,18:1)
Block(10,22,-12,18:1)
Block(10,22,-11,17:8)
Block(10,22,-10,17:8)
Block(10,22,-9,18:1)
Block(10,22,-8,17:8)
Block(10,22,-7,18:1)
Block(10,22,-6,18:1)
Block(10,22,-5,18:1)
Block(10,22,-4,18:1)
Block(10,22,-3,18:1)
Block(10,22,-2,18:1)
Block(10,22,-1,18:1)
Block(10,22,0,17:4)
Block(10,22,1,18:1)
Block(10,22,2,18:1)
Block(10,22,3,18:1)
Block(10,22,4,18:1)
Block(10,22,5,18:1)
Block(10,22,6,18:1)
Block(10,22,8,17:4)
Block(10,22,9,18:1)
Block(10,22,10,17:4)
Block(10,22,11,17:8)
Block(10,22,12,18:1)
Block(10,23,-12,18:1)
Block(10,23,-10,18:1)
Block(10,23,-9,18:1)
Block(10,23,-8,18:1)
Block(10,23,-7,18:1)
Block(10,23,-6,18:1)
Block(10,23,-5,18:1)
Block(10,23,-3,18:1)
Block(10,23,-2,18:1)
Block(10,23,-1,18:1)
Block(10,23,0,18:1)
Block(10,23,1,18:1)
Block(10,23,2,18:1)
Block(10,23,3,18:1)
Block(10,23,4,18:1)
Block(10,23,5,18:1)
Block(10,23,6,18:1)
Block(10,23,7,18:1)
Block(10,23,8,18:1)
Block(10,23,9,18:1)
Block(10,23,10,18:1)
Block(10,24,-10,18:1)
Block(10,24,-9,18:1)
Block(10,24,-8,18:1)
Block(10,24,-7,18:1)
Block(10,24,-4,18:1)
Block(10,24,-3,18:1)
Block(10,24,-2,18:1)
Block(10,24,-1,18:1)
Block(10,24,0,18:1)
Block(10,24,2,18:1)
Block(10,24,3,18:1)
Block(10,24,4,18:1)
Block(10,24,5,18:1)
Block(10,24,6,18:1)
Block(10,24,7,18:1)
Block(10,24,8,18:1)
Block(10,24,11,18:1)
Block(10,25,1,18:1)
Block(11,19,0,18:1)
Block(11,20,-11,18:1)
Block(11,20,-7,18:1)
Block(11,20,-5,18:1)
Block(11,20,-4,18:1)
Block(11,20,-2,18:1)
Block(11,20,-1,18:1)
Block(11,20,0,18:1)
Block(11,20,3,18:1)
Block(11,20,4,18:1)
Block(11,20,6,18:1)
Block(11,20,7,18:1)
Block(11,20,11,18:1)
Block(11,21,-11,18:1)
Block(11,21,-9,18:1)
Block(11,21,-8,18:1)
Block(11,21,-7,18:1)
Block(11,21,-6,18:1)
Block(11,21,-5,18:1)
Block(11,21,-4,18:1)
Block(11,21,-3,18:1)
Block(11,21,-2,18:1)
Block(11,21,-1,18:1)
Block(11,21,0,18:1)
Block(11,21,1,18:1)
Block(11,21,2,18:1)
Block(11,21,3,18:1)
Block(11,21,4,18:1)
Block(11,21,5,18:1)
Block(11,21,6,18:1)
Block(11,21,7,18:1)
Block(11,21,9,18:1)
Block(11,21,10,18:1)
Block(11,22,-12,18:1)
Block(11,22,-11,18:1)
Block(11,22,-10,17:4)
Block(11,22,-9,18:1)
Block(11,22,-8,18:1)
Block(11,22,-7,17:8)
Block(11,22,-6,18:1)
Block(11,22,-5,18:1)
Block(11,22,-4,17:8)
Block(11,22,-3,17:8)
Block(11,22,-2,17:8)
Block(11,22,-1,17:8)
Block(11,22,0,17:4)
Block(11,22,1,17:8)
Block(11,22,2,17:8)
Block(11,22,3,17:8)
Block(11,22,4,17:8)
Block(11,22,5,18:1)
Block(11,22,6,18:1)
Block(11,22,7,17:4)
Block(11,22,8,18:1)
Block(11,22,9,18:1)
Block(11,22,10,17:4)
Block(11,22,11,18:1)
Block(11,22,12,18:1)
Block(11,23,-9,18:1)
Block(11,23,-8,18:1)
Block(11,23,-7,18:1)
Block(11,23,-6,18:1)
Block(11,23,-5,18:1)
Block(11,23,-4,18:1)
Block(11,23,-3,18:1)
Block(11,23,-2,18:1)
Block(11,23,0,18:1)
Block(11,23,1,18:1)
Block(11,23,2,18:1)
Block(11,23,4,18:1)
Block(11,23,5,18:1)
Block(11,23,6,18:1)
Block(11,23,7,18:1)
Block(11,23,8,18:1)
Block(11,23,9,18:1)
Block(11,23,10,18:1)
Block(11,24,-11,18:1)
Block(11,24,-8,18:1)
Block(11,24,-6,18:1)
Block(11,24,-5,18:1)
Block(11,24,-2,18:1)
Block(11,24,-1,18:1)
Block(11,24,0,18:1)
Block(11,24,1,18:1)
Block(11,24,3,18:1)
Block(11,24,4,18:1)
Block(11,24,5,18:1)
Block(11,24,6,18:1)
Block(11,24,7,18:1)
Block(11,24,8,18:1)
Block(11,24,10,18:1)
Block(11,24,11,18:1)
Block(12,19,0,18:1)
Block(12,19,1,18:1)
Block(12,19,2,18:1)
Block(12,20,-7,18:1)
Block(12,20,-4,18:1)
Block(12,20,-3,18:1)
Block(12,20,-2,18:1)
Block(12,20,-1,18:1)
Block(12,20,0,18:1)
Block(12,20,1,18:1)
Block(12,20,3,18:1)
Block(12,20,6,18:1)
Block(12,20,7,18:1)
Block(12,20,8,18:1)
Block(12,21,-9,18:1)
Block(12,21,-7,18:1)
Block(12,21,-4,18:1)
Block(12,21,-3,18:1)
Block(12,21,-2,18:1)
Block(12,21,0,18:1)
Block(12,21,1,18:1)
Block(12,21,2,18:1)
Block(12,21,3,18:1)
Block(12,21,4,18:1)
Block(12,21,10,18:1)
Block(12,22,-10,18:1)
Block(12,22,-9,18:1)
Block(12,22,-7,18:1)
Block(12,22,-5,18:1)
Block(12,22,-4,18:1)
Block(12,22,-3,18:1)
Block(12,22,-2,18:1)
Block(12,22,-1,18:1)
Block(12,22,0,17:4)
Block(12,22,2,18:1)
Block(12,22,3,18:1)
Block(12,22,4,18:1)
Block(12,22,5,18:1)
Block(12,22,6,18:1)
Block(12,22,7,18:1)
Block(12,22,9,18:1)
Block(12,22,10,18:1)
Block(12,22,11,18:1)
Block(12,23,-11,18:1)
Block(12,23,-9,18:1)
Block(12,23,-8,18:1)
Block(12,23,-7,18:1)
Block(12,23,-4,18:1)
Block(12,23,-3,18:1)
Block(12,23,-2,18:1)
Block(12,23,0,18:1)
Block(12,23,1,18:1)
Block(12,23,2,18:1)
Block(12,23,5,18:1)
Block(12,23,6,18:1)
Block(12,23,7,18:1)
Block(12,23,10,18:1)
Block(12,24,-7,18:1)
Block(12,24,-2,18:1)
Block(12,24,1,18:1)
Block(12,24,4,18:1)
Block(12,24,6,18:1)
Block(12,24,7,18:1)
Block(12,24,8,18:1)
Block(13,20,-1,18:1)
Block(13,20,0,18:1)
Block(13,21,-7,18:1)
Block(13,21,-6,18:1)
Block(13,21,-5,18:1)
Block(13,21,-4,18:1)
Block(13,21,-1,18:1)
Block(13,21,0,18:1)
Block(13,21,2,18:1)
Block(13,21,3,18:1)
Block(13,21,4,18:1)
Block(13,21,6,18:1)
Block(13,22,-8,18:1)
Block(13,22,-5,18:1)
Block(13,22,-4,18:1)
Block(13,22,-3,18:1)
Block(13,22,-2,18:1)
Block(13,22,-1,18:1)
Block(13,22,0,17:4)
Block(13,22,1,18:1)
Block(13,22,2,18:1)
Block(13,22,3,18:1)
Block(13,22,6,18:1)
Block(13,22,7,18:1)
Block(13,23,-8,18:1)
Block(13,23,-7,18:1)
Block(13,23,-6,18:1)
Block(13,23,-4,18:1)
Block(13,23,-2,18:1)
Block(13,23,3,18:1)
Block(13,23,4,18:1)
Block(13,23,7,18:1)
Block(13,24,0,18:1)
Block(14,20,0,18:1)
Block(14,21,-1,18:1)
Block(14,21,0,18:1)
Block(14,21,2,18:1)
Block(14,22,-2,18:1)
Block(14,22,-1,18:1)
Block(14,22,0,18:1)
Block(14,22,2,18:1)
Block(14,24,0,18:1)
Block(15,21,0,18:1)
Block(15,21,1,18:1)
Block(15,22,-1,18:1)
Block(15,22,0,18:1)


#######################################################################
# +-----------------------------------------------------------------+ #
# |                             Entities                            | #
# +-----------------------------------------------------------------+ #
#######################################################################

# Entity() spawns an entity instead of a block. The entity is spawned only once when the BO3 is spawned.
# Entities are persistent by default so they don't de-spawn when no player is near, they are only unloaded.
# Usage: Entity(x,y,z,mobName,groupSize,NameTagOrNBTFileName) or Entity(x,y,z,mobName,groupSize)
# Use /tc entities or /otg entities to get a list of entities that can be used as mobName, this includes entities added by other mods.
# NameTagOrNBTFileName can be either a nametag for the mob or an nbt file (such as mymobinfo.nbt or mymobinfo.txt).
# When using a text file you can use the same mob spawning parameters used with the /summon command to equip the
# entity and give it custom attributes etc. You can copy the DATA part of a summon command including surrounding
# curly braces to a .txt file, for instance for: "/summon Skeleton x y z {DATA}"

#######################################################################
# +-----------------------------------------------------------------+ #
# |                            BO3 checks                           | #
# +-----------------------------------------------------------------+ #
#######################################################################

# Require a condition at a certain location in order for the BO3 to be spawned.
# BlockCheck(x,y,z,BlockName[,BlockName[,...]]) - one of the blocks must be at the location
# BlockCheckNot(x,y,z,BlockName[,BlockName[,...]]) - all the blocks must not be at the location
# LightCheck(x,y,z,minLightLevel,maxLightLevel) - light must be between min and max (inclusive)

# You can use "Solid" as a BlockName for matching all solid blocks or "All" to match all blocks that aren't air.

# Examples:
#   BlockCheck(0,-1,0,GRASS,DIRT)  Require grass or dirt just below the object
#   BlockCheck(0,-1,0,Solid)       Require any solid block just below the object
#   BlockCheck(0,-1,0,WOOL)        Require any type of wool just below the object
#   BlockCheck(0,-1,0,WOOL:0)      Require white wool just below the object
#   BlockCheckNot(0,-1,0,WOOL:0)   Require that there is no white wool below the object
#   LightCheck(0,0,0,0,1)          Require almost complete darkness just below the object
BlockCheck(0,10,0,AIR)
BlockCheck(0,5,0,AIR)
BlockCheck(0,2,0,AIR)
BlockCheck(-4,0,-4,Solid)
BlockCheck(-3,0,-4,Solid)
BlockCheck(-2,0,-4,Solid)
BlockCheck(-1,0,-4,Solid)
BlockCheck(0,0,-4,Solid)
BlockCheck(1,0,-4,Solid)
BlockCheck(2,0,-4,Solid)
BlockCheck(3,0,-4,Solid)
BlockCheck(4,0,-4,Solid)
BlockCheck(-4,0,-3,Solid)
BlockCheck(-3,0,-3,Solid)
BlockCheck(-2,0,-3,Solid)
BlockCheck(-1,0,-3,Solid)
BlockCheck(0,0,-3,Solid)
BlockCheck(1,0,-3,Solid)
BlockCheck(2,0,-3,Solid)
BlockCheck(3,0,-3,Solid)
BlockCheck(4,0,-3,Solid)
BlockCheck(-4,0,-2,Solid)
BlockCheck(-3,0,-2,Solid)
BlockCheck(-2,0,-2,Solid)
BlockCheck(-1,0,-2,Solid)
BlockCheck(0,0,-2,Solid)
BlockCheck(1,0,-2,Solid)
BlockCheck(2,0,-2,Solid)
BlockCheck(3,0,-2,Solid)
BlockCheck(4,0,-2,Solid)
BlockCheck(-4,0,-1,Solid)
BlockCheck(-3,0,-1,Solid)
BlockCheck(-2,0,-1,Solid)
BlockCheck(-1,0,-1,Solid)
BlockCheck(0,0,-1,Solid)
BlockCheck(1,0,-1,Solid)
BlockCheck(2,0,-1,Solid)
BlockCheck(3,0,-1,Solid)
BlockCheck(4,0,-1,Solid)
BlockCheck(-4,0,0,Solid)
BlockCheck(-3,0,0,Solid)
BlockCheck(-2,0,0,Solid)
BlockCheck(-1,0,0,Solid)
BlockCheck(0,0,0,Solid)
BlockCheck(1,0,0,Solid)
BlockCheck(2,0,0,Solid)
BlockCheck(3,0,0,Solid)
BlockCheck(4,0,0,Solid)
BlockCheck(-4,0,1,Solid)
BlockCheck(-3,0,1,Solid)
BlockCheck(-2,0,1,Solid)
BlockCheck(-1,0,1,Solid)
BlockCheck(0,0,1,Solid)
BlockCheck(1,0,1,Solid)
BlockCheck(2,0,1,Solid)
BlockCheck(3,0,1,Solid)
BlockCheck(4,0,1,Solid)
BlockCheck(-4,0,2,Solid)
BlockCheck(-3,0,2,Solid)
BlockCheck(-2,0,2,Solid)
BlockCheck(-1,0,2,Solid)
BlockCheck(0,0,2,Solid)
BlockCheck(1,0,2,Solid)
BlockCheck(2,0,2,Solid)
BlockCheck(3,0,2,Solid)
BlockCheck(4,0,2,Solid)
BlockCheck(-4,0,3,Solid)
BlockCheck(-3,0,3,Solid)
BlockCheck(-2,0,3,Solid)
BlockCheck(-1,0,3,Solid)
BlockCheck(0,0,3,Solid)
BlockCheck(1,0,3,Solid)
BlockCheck(2,0,3,Solid)
BlockCheck(3,0,3,Solid)
BlockCheck(4,0,3,Solid)
BlockCheck(-4,0,4,Solid)
BlockCheck(-3,0,4,Solid)
BlockCheck(-2,0,4,Solid)
BlockCheck(-1,0,4,Solid)
BlockCheck(0,0,4,Solid)
BlockCheck(1,0,4,Solid)
BlockCheck(2,0,4,Solid)
BlockCheck(3,0,4,Solid)
BlockCheck(4,0,4,Solid)

