#######################################################################
# +-----------------------------------------------------------------+ #
# |                            BO3 object                           | #
# +-----------------------------------------------------------------+ #
#######################################################################

# The descriptions in this file are accurate only for TerrainControl and OTG.
# For MCW and OTG+ these descriptions are only accurate if the BO3 is used as a CustomObject.
# MCW and OTG+ completely reimplemented CustomStructure, check the MCW/OTG+ documentation for more information.

# This is the config file of a custom object.
# If you add this object correctly to your BiomeConfigs, it will spawn in the world.

# This is the creator of this BO3 object
Author: Unknown

# A short description of this BO3 object
Description: This BO3 was converted from a schematic using OTGEdit. The author and description information of the schematic could not be found. If you know who the author of the schematic is then please add this information.

# The BO3 version, don't change this! It can be used by external applications to do a version check.
Version: 3

# The settings mode, WriteAll, WriteWithoutComments or WriteDisable. See WorldConfig.
SettingsMode: WriteDisable

#######################################################################
# +-----------------------------------------------------------------+ #
# |                          Main settings                          | #
# +-----------------------------------------------------------------+ #
#######################################################################

# This needs to be set to true to spawn the object in the Tree and Sapling resources.
Tree: false

# The frequency of the BO3 from 1 to 200. Tries this many times to spawn this BO3 when using the CustomObject(...) resource.
# Ignored by Tree(..), Sapling(..) and CustomStructure(..)
Frequency: 40

# The rarity of the BO3 from 0 to 100. Each spawn attempt has rarity% chance to succeed when using the CustomObject(...) resource.
# Ignored by Tree(..), Sapling(..) and CustomStructure(..)
Rarity: 100.0

# If you set this to true, the BO3 will be placed with a random rotation.
RotateRandomly: true

# The spawn height of the BO3 - randomY, highestBlock or highestSolidBlock.
SpawnHeight: randomY

# The height limits for the BO3.
MinHeight: 0

MaxHeight: 256

# Objects can have other objects attached to it: branches. Branches can also
# have branches attached to it, which can also have branches, etc. This is the
# maximum branch depth for this objects.
MaxBranchDepth: 10

# When spawned with the UseWorld keyword, this BO3 should NOT spawn in the following biomes.
# If you writer.write the BO3 name directly in the BiomeConfigs, this will be ignored.
ExcludedBiomes: All

# To optimise this BO3 for faster loading times you can use Notepad++ to find/replace comments and abbreviate things.
# Notepad++ find/replace with regex:
# Find: ^[#;].* replace to nothing removes all lines starting with # 
# Find: ^\s*$ replace to nothing removes most empty lines 
# Notepad++ find/replace without regex:
# *Warning: This will only work for OTG 1.10.2 v21 / OTG 1.11.2 v6 or higher. B( is not recognised by lower versions.
# Find: Block( replace to B(

#######################################################################
# +-----------------------------------------------------------------+ #
# |                      Source block settings                      | #
# +-----------------------------------------------------------------+ #
#######################################################################

# The block(s) the BO3 should spawn in.
SourceBlocks: AIR

# The maximum percentage of the BO3 that can be outside the SourceBlock.
# The BO3 won't be placed on a location with more blocks outside the SourceBlock than this percentage.
MaxPercentageOutsideSourceBlock: 100

# What to do when a block is about to be placed outside the SourceBlock? (dontPlace, placeAnyway)
OutsideSourceBlock: placeAnyway

#######################################################################
# +-----------------------------------------------------------------+ #
# |                              Blocks                             | #
# +-----------------------------------------------------------------+ #
#######################################################################

# All the blocks used in the BO3 are listed here. Possible blocks:
# Block(x,y,z,id[.data][,nbtfile.nbt) or B(x,y,z,id[.data][,nbtfile.nbt)
# RandomBlock(x,y,z,id[:data][,nbtfile.nbt],chance[,id[:data][,nbtfile.nbt],chance[,...]])
# So RandomBlock(0,0,0,CHEST,chest.nbt,50,CHEST,anotherchest.nbt,100) will spawn a chest at
# the BO3 origin, and give it a 50% chance to have the contents of chest.nbt, or, if that
# fails, a 100% percent chance to have the contents of anotherchest.nbt.

Block(-62,21,-1,18:1)
Block(-62,21,0,18:1)
Block(-62,22,0,18:1)
Block(-62,22,1,18:1)
Block(-62,23,0,18:1)
Block(-62,23,1,18:1)
Block(-61,20,1,18:1)
Block(-61,21,-2,18:1)
Block(-61,21,0,18:1)
Block(-61,22,-2,18:1)
Block(-61,22,-1,18:1)
Block(-61,22,0,18:1)
Block(-61,22,2,18:1)
Block(-61,23,-1,18:1)
Block(-61,23,0,18:1)
Block(-61,24,0,18:1)
Block(-61,24,2,18:1)
Block(-60,19,1,18:1)
Block(-60,20,1,18:1)
Block(-60,20,2,18:1)
Block(-60,21,-6,18:1)
Block(-60,21,-3,18:1)
Block(-60,21,-2,18:1)
Block(-60,21,0,17:5)
Block(-60,21,2,18:1)
Block(-60,21,4,18:1)
Block(-60,22,-6,18:1)
Block(-60,22,-5,18:1)
Block(-60,22,-4,18:1)
Block(-60,22,-2,18:1)
Block(-60,22,0,18:1)
Block(-60,22,3,18:1)
Block(-60,22,4,18:1)
Block(-60,23,-1,18:1)
Block(-60,23,0,18:1)
Block(-60,24,-2,18:1)
Block(-60,24,0,18:1)
Block(-60,25,-1,18:1)
Block(-60,25,0,18:1)
Block(-59,19,-1,18:1)
Block(-59,19,0,18:1)
Block(-59,19,1,18:1)
Block(-59,20,-6,18:1)
Block(-59,20,-5,18:1)
Block(-59,20,0,17:5)
Block(-59,20,1,18:1)
Block(-59,20,3,18:1)
Block(-59,20,4,18:1)
Block(-59,20,5,18:1)
Block(-59,21,-5,18:1)
Block(-59,21,-3,18:1)
Block(-59,21,-1,17:5)
Block(-59,21,0,17:5)
Block(-59,21,1,17:5)
Block(-59,21,2,18:1)
Block(-59,21,3,18:1)
Block(-59,21,4,18:1)
Block(-59,21,5,18:1)
Block(-59,22,-6,18:1)
Block(-59,22,-5,18:1)
Block(-59,22,-3,18:1)
Block(-59,22,-2,18:1)
Block(-59,22,-1,18:1)
Block(-59,22,0,17:5)
Block(-59,22,1,18:1)
Block(-59,22,2,18:1)
Block(-59,22,3,18:1)
Block(-59,22,5,18:1)
Block(-59,23,-5,18:1)
Block(-59,23,-4,18:1)
Block(-59,23,-3,18:1)
Block(-59,23,-1,18:1)
Block(-59,23,0,18:1)
Block(-59,23,1,18:1)
Block(-59,23,2,18:1)
Block(-59,23,3,18:1)
Block(-59,24,-6,18:1)
Block(-59,24,-5,18:1)
Block(-59,24,-4,18:1)
Block(-59,24,-1,18:1)
Block(-59,24,0,18:1)
Block(-59,24,1,18:1)
Block(-59,24,3,18:1)
Block(-59,25,-1,18:1)
Block(-59,25,0,18:1)
Block(-59,25,1,18:1)
Block(-58,19,-5,18:1)
Block(-58,19,2,18:1)
Block(-58,19,3,18:1)
Block(-58,20,-5,18:1)
Block(-58,20,-3,18:1)
Block(-58,20,0,17:5)
Block(-58,20,1,18:1)
Block(-58,20,2,18:1)
Block(-58,20,3,18:1)
Block(-58,20,5,18:1)
Block(-58,21,-8,18:1)
Block(-58,21,-5,18:1)
Block(-58,21,-4,18:1)
Block(-58,21,-3,18:1)
Block(-58,21,-2,18:1)
Block(-58,21,-1,17:5)
Block(-58,21,0,17:5)
Block(-58,21,1,17:5)
Block(-58,21,2,18:1)
Block(-58,21,6,18:1)
Block(-58,22,-8,18:1)
Block(-58,22,-7,18:1)
Block(-58,22,-5,18:1)
Block(-58,22,-4,17:5)
Block(-58,22,-3,18:1)
Block(-58,22,-2,18:1)
Block(-58,22,-1,17:5)
Block(-58,22,0,17:5)
Block(-58,22,1,17:5)
Block(-58,22,2,18:1)
Block(-58,22,3,18:1)
Block(-58,22,4,17:5)
Block(-58,22,6,18:1)
Block(-58,22,8,18:1)
Block(-58,23,-7,18:1)
Block(-58,23,-5,18:1)
Block(-58,23,-4,18:1)
Block(-58,23,-1,18:1)
Block(-58,23,0,17:5)
Block(-58,23,1,18:1)
Block(-58,23,2,18:1)
Block(-58,23,3,18:1)
Block(-58,23,5,18:1)
Block(-58,23,6,18:1)
Block(-58,23,7,18:1)
Block(-58,23,8,18:1)
Block(-58,24,-6,18:1)
Block(-58,24,-5,18:1)
Block(-58,24,-2,18:1)
Block(-58,24,0,18:1)
Block(-58,24,1,18:1)
Block(-58,24,2,18:1)
Block(-58,24,7,18:1)
Block(-58,24,11,18:1)
Block(-58,24,12,18:1)
Block(-58,24,13,18:1)
Block(-58,25,-6,18:1)
Block(-58,25,-4,18:1)
Block(-58,25,0,18:1)
Block(-58,25,1,18:1)
Block(-58,25,3,18:1)
Block(-58,26,-1,18:1)
Block(-58,26,0,18:1)
Block(-57,19,-5,18:1)
Block(-57,19,-4,18:1)
Block(-57,19,2,18:1)
Block(-57,19,3,18:1)
Block(-57,19,4,18:1)
Block(-57,20,-7,18:1)
Block(-57,20,-6,18:1)
Block(-57,20,-5,18:1)
Block(-57,20,-3,18:1)
Block(-57,20,0,18:1)
Block(-57,20,1,18:1)
Block(-57,20,2,18:1)
Block(-57,20,3,18:1)
Block(-57,20,4,18:1)
Block(-57,20,5,18:1)
Block(-57,21,-7,18:1)
Block(-57,21,-4,17:9)
Block(-57,21,-3,17:9)
Block(-57,21,-2,17:9)
Block(-57,21,-1,17:5)
Block(-57,21,0,17:5)
Block(-57,21,1,17:5)
Block(-57,21,2,17:9)
Block(-57,21,3,17:9)
Block(-57,21,4,18:1)
Block(-57,21,5,18:1)
Block(-57,21,6,18:1)
Block(-57,21,7,18:1)
Block(-57,21,8,18:1)
Block(-57,21,9,18:1)
Block(-57,22,-7,17:9)
Block(-57,22,-6,17:9)
Block(-57,22,-5,17:9)
Block(-57,22,-4,17:9)
Block(-57,22,-3,17:9)
Block(-57,22,-2,17:9)
Block(-57,22,-1,17:5)
Block(-57,22,0,17:5)
Block(-57,22,1,17:5)
Block(-57,22,2,17:9)
Block(-57,22,3,17:9)
Block(-57,22,4,17:9)
Block(-57,22,5,17:9)
Block(-57,22,6,17:9)
Block(-57,22,10,18:1)
Block(-57,22,12,18:1)
Block(-57,23,-5,18:1)
Block(-57,23,-2,18:1)
Block(-57,23,-1,17:5)
Block(-57,23,0,17:5)
Block(-57,23,1,17:5)
Block(-57,23,2,18:1)
Block(-57,23,5,18:1)
Block(-57,23,7,18:1)
Block(-57,23,8,18:1)
Block(-57,23,9,18:1)
Block(-57,23,10,18:1)
Block(-57,23,12,17:5)
Block(-57,23,13,18:1)
Block(-57,24,-10,18:1)
Block(-57,24,-9,18:1)
Block(-57,24,-8,18:1)
Block(-57,24,-7,18:1)
Block(-57,24,-5,18:1)
Block(-57,24,-4,18:1)
Block(-57,24,-2,18:1)
Block(-57,24,0,18:1)
Block(-57,24,1,18:1)
Block(-57,24,2,18:1)
Block(-57,24,3,18:1)
Block(-57,24,4,18:1)
Block(-57,24,5,18:1)
Block(-57,24,9,18:1)
Block(-57,24,12,18:1)
Block(-57,25,-10,18:1)
Block(-57,25,-8,18:1)
Block(-57,25,-5,18:1)
Block(-57,25,-4,18:1)
Block(-57,25,-2,18:1)
Block(-57,25,1,18:1)
Block(-57,25,3,18:1)
Block(-57,25,4,18:1)
Block(-57,25,6,18:1)
Block(-57,25,7,18:1)
Block(-57,25,8,18:1)
Block(-57,25,11,18:1)
Block(-57,25,13,18:1)
Block(-57,26,-2,18:1)
Block(-57,26,2,18:1)
Block(-57,27,0,18:1)
Block(-57,27,1,18:1)
Block(-56,19,-5,18:1)
Block(-56,19,-4,18:1)
Block(-56,19,3,18:1)
Block(-56,19,4,18:1)
Block(-56,20,-6,18:1)
Block(-56,20,-3,18:1)
Block(-56,20,3,18:1)
Block(-56,20,4,18:1)
Block(-56,20,6,18:1)
Block(-56,20,7,18:1)
Block(-56,20,13,18:1)
Block(-56,21,-8,18:1)
Block(-56,21,-7,18:1)
Block(-56,21,-5,18:1)
Block(-56,21,-4,18:1)
Block(-56,21,-1,18:1)
Block(-56,21,0,17:5)
Block(-56,21,1,18:1)
Block(-56,21,2,18:1)
Block(-56,21,5,18:1)
Block(-56,21,6,18:1)
Block(-56,21,7,18:1)
Block(-56,21,12,18:1)
Block(-56,21,13,18:1)
Block(-56,21,14,18:1)
Block(-56,22,-8,18:1)
Block(-56,22,-7,18:1)
Block(-56,22,-5,17:5)
Block(-56,22,-4,18:1)
Block(-56,22,-3,18:1)
Block(-56,22,-1,17:5)
Block(-56,22,0,17:5)
Block(-56,22,1,17:5)
Block(-56,22,2,18:1)
Block(-56,22,3,18:1)
Block(-56,22,4,18:1)
Block(-56,22,5,18:1)
Block(-56,22,6,18:1)
Block(-56,22,10,18:1)
Block(-56,22,12,18:1)
Block(-56,22,15,18:1)
Block(-56,23,-11,18:1)
Block(-56,23,-10,18:1)
Block(-56,23,-9,18:1)
Block(-56,23,-6,18:1)
Block(-56,23,-5,18:1)
Block(-56,23,-4,18:1)
Block(-56,23,-3,18:1)
Block(-56,23,-2,18:1)
Block(-56,23,-1,17:5)
Block(-56,23,0,17:5)
Block(-56,23,1,17:5)
Block(-56,23,2,18:1)
Block(-56,23,6,18:1)
Block(-56,23,7,18:1)
Block(-56,23,8,18:1)
Block(-56,23,9,17:5)
Block(-56,23,10,18:1)
Block(-56,23,11,18:1)
Block(-56,23,12,17:5)
Block(-56,23,13,18:1)
Block(-56,23,15,18:1)
Block(-56,24,-11,18:1)
Block(-56,24,-10,18:1)
Block(-56,24,-9,18:1)
Block(-56,24,-8,18:1)
Block(-56,24,-7,18:1)
Block(-56,24,-2,18:1)
Block(-56,24,0,17:5)
Block(-56,24,1,18:1)
Block(-56,24,2,18:1)
Block(-56,24,3,18:1)
Block(-56,24,5,18:1)
Block(-56,24,7,18:1)
Block(-56,24,9,18:1)
Block(-56,24,10,18:1)
Block(-56,24,12,18:1)
Block(-56,24,13,18:1)
Block(-56,25,-10,18:1)
Block(-56,25,-8,18:1)
Block(-56,25,-7,18:1)
Block(-56,25,-5,18:1)
Block(-56,25,-3,18:1)
Block(-56,25,-2,18:1)
Block(-56,25,-1,18:1)
Block(-56,25,1,18:1)
Block(-56,25,2,18:1)
Block(-56,25,7,18:1)
Block(-56,25,8,18:1)
Block(-56,25,9,18:1)
Block(-56,25,11,18:1)
Block(-56,25,12,18:1)
Block(-56,25,14,18:1)
Block(-56,26,-10,18:1)
Block(-56,26,-9,18:1)
Block(-56,26,-2,18:1)
Block(-56,26,0,18:1)
Block(-56,26,1,18:1)
Block(-56,26,2,18:1)
Block(-56,26,6,18:1)
Block(-56,26,7,18:1)
Block(-56,26,11,18:1)
Block(-56,26,12,18:1)
Block(-56,26,13,18:1)
Block(-56,27,-1,18:1)
Block(-55,20,-5,18:1)
Block(-55,20,6,18:1)
Block(-55,20,7,18:1)
Block(-55,20,8,18:1)
Block(-55,20,12,18:1)
Block(-55,21,-9,18:1)
Block(-55,21,-8,18:1)
Block(-55,21,0,18:1)
Block(-55,21,3,18:1)
Block(-55,21,6,18:1)
Block(-55,21,7,18:1)
Block(-55,21,8,18:1)
Block(-55,21,9,18:1)
Block(-55,21,10,18:1)
Block(-55,21,11,18:1)
Block(-55,21,12,18:1)
Block(-55,22,-11,18:1)
Block(-55,22,-9,18:1)
Block(-55,22,-7,18:1)
Block(-55,22,-5,17:5)
Block(-55,22,-4,18:1)
Block(-55,22,-1,17:5)
Block(-55,22,0,17:5)
Block(-55,22,1,17:5)
Block(-55,22,2,17:9)
Block(-55,22,3,17:9)
Block(-55,22,4,17:9)
Block(-55,22,5,17:9)
Block(-55,22,6,18:1)
Block(-55,22,7,18:1)
Block(-55,22,8,18:1)
Block(-55,22,9,18:1)
Block(-55,22,10,18:1)
Block(-55,22,11,18:1)
Block(-55,22,12,18:1)
Block(-55,22,13,18:1)
Block(-55,22,14,18:1)
Block(-55,23,-17,18:1)
Block(-55,23,-15,18:1)
Block(-55,23,-13,18:1)
Block(-55,23,-12,18:1)
Block(-55,23,-8,18:1)
Block(-55,23,-6,18:1)
Block(-55,23,-5,18:1)
Block(-55,23,-3,18:1)
Block(-55,23,-2,18:1)
Block(-55,23,-1,17:5)
Block(-55,23,0,17:5)
Block(-55,23,1,17:5)
Block(-55,23,2,17:9)
Block(-55,23,3,17:9)
Block(-55,23,4,17:9)
Block(-55,23,5,17:9)
Block(-55,23,6,17:9)
Block(-55,23,7,17:9)
Block(-55,23,8,17:9)
Block(-55,23,9,17:9)
Block(-55,23,10,17:9)
Block(-55,23,11,17:9)
Block(-55,23,12,17:9)
Block(-55,23,13,17:9)
Block(-55,23,14,17:9)
Block(-55,23,15,18:1)
Block(-55,24,-18,18:1)
Block(-55,24,-17,18:1)
Block(-55,24,-16,18:1)
Block(-55,24,-15,18:1)
Block(-55,24,-14,18:1)
Block(-55,24,-12,18:1)
Block(-55,24,-9,18:1)
Block(-55,24,-8,18:1)
Block(-55,24,-6,17:5)
Block(-55,24,-4,18:1)
Block(-55,24,-2,18:1)
Block(-55,24,-1,17:5)
Block(-55,24,0,17:5)
Block(-55,24,1,17:5)
Block(-55,24,3,18:1)
Block(-55,24,4,18:1)
Block(-55,24,6,18:1)
Block(-55,24,8,18:1)
Block(-55,24,9,18:1)
Block(-55,24,10,18:1)
Block(-55,24,11,18:1)
Block(-55,24,13,18:1)
Block(-55,24,15,18:1)
Block(-55,24,16,18:1)
Block(-55,25,-16,18:1)
Block(-55,25,-15,18:1)
Block(-55,25,-14,18:1)
Block(-55,25,-13,18:1)
Block(-55,25,-12,18:1)
Block(-55,25,-11,18:1)
Block(-55,25,-10,18:1)
Block(-55,25,-9,18:1)
Block(-55,25,-8,18:1)
Block(-55,25,-6,18:1)
Block(-55,25,-5,18:1)
Block(-55,25,-3,18:1)
Block(-55,25,0,18:1)
Block(-55,25,1,18:1)
Block(-55,25,3,18:1)
Block(-55,25,7,18:1)
Block(-55,25,8,18:1)
Block(-55,25,10,18:1)
Block(-55,25,11,18:1)
Block(-55,25,12,18:1)
Block(-55,25,13,18:1)
Block(-55,26,-9,18:1)
Block(-55,26,-1,18:1)
Block(-55,26,1,18:1)
Block(-55,26,8,18:1)
Block(-55,26,11,18:1)
Block(-55,26,12,18:1)
Block(-55,26,13,18:1)
Block(-54,20,6,18:1)
Block(-54,20,7,18:1)
Block(-54,20,12,18:1)
Block(-54,20,13,18:1)
Block(-54,21,-9,18:1)
Block(-54,21,-5,18:1)
Block(-54,21,0,18:1)
Block(-54,21,1,18:1)
Block(-54,21,2,18:1)
Block(-54,21,3,18:1)
Block(-54,21,4,18:1)
Block(-54,21,5,18:1)
Block(-54,21,12,18:1)
Block(-54,22,-18,18:1)
Block(-54,22,-15,18:1)
Block(-54,22,-14,18:1)
Block(-54,22,-12,18:1)
Block(-54,22,-11,18:1)
Block(-54,22,-10,18:1)
Block(-54,22,-9,18:1)
Block(-54,22,-7,18:1)
Block(-54,22,-6,18:1)
Block(-54,22,-5,18:1)
Block(-54,22,-2,18:1)
Block(-54,22,-1,18:1)
Block(-54,22,0,17:5)
Block(-54,22,1,18:1)
Block(-54,22,2,18:1)
Block(-54,22,3,18:1)
Block(-54,22,4,18:1)
Block(-54,22,5,18:1)
Block(-54,22,7,18:1)
Block(-54,22,8,18:1)
Block(-54,22,9,18:1)
Block(-54,22,10,18:1)
Block(-54,22,11,18:1)
Block(-54,22,13,18:1)
Block(-54,22,17,18:1)
Block(-54,23,-18,18:1)
Block(-54,23,-16,18:1)
Block(-54,23,-15,18:1)
Block(-54,23,-14,18:1)
Block(-54,23,-13,18:1)
Block(-54,23,-12,18:1)
Block(-54,23,-11,18:1)
Block(-54,23,-10,18:1)
Block(-54,23,-9,18:1)
Block(-54,23,-8,18:1)
Block(-54,23,-7,18:1)
Block(-54,23,-6,18:1)
Block(-54,23,-5,18:1)
Block(-54,23,-2,18:1)
Block(-54,23,-1,17:5)
Block(-54,23,0,17:5)
Block(-54,23,1,17:5)
Block(-54,23,2,18:1)
Block(-54,23,3,18:1)
Block(-54,23,4,18:1)
Block(-54,23,6,18:1)
Block(-54,23,7,18:1)
Block(-54,23,9,18:1)
Block(-54,23,10,18:1)
Block(-54,23,11,18:1)
Block(-54,23,12,18:1)
Block(-54,23,13,18:1)
Block(-54,23,14,18:1)
Block(-54,23,15,18:1)
Block(-54,23,16,18:1)
Block(-54,24,-19,18:1)
Block(-54,24,-17,18:1)
Block(-54,24,-15,18:1)
Block(-54,24,-14,18:1)
Block(-54,24,-13,18:1)
Block(-54,24,-12,18:1)
Block(-54,24,-11,18:1)
Block(-54,24,-10,18:1)
Block(-54,24,-9,17:5)
Block(-54,24,-8,18:1)
Block(-54,24,-7,18:1)
Block(-54,24,-6,17:5)
Block(-54,24,-3,17:5)
Block(-54,24,-1,17:5)
Block(-54,24,0,17:5)
Block(-54,24,1,17:5)
Block(-54,24,2,18:1)
Block(-54,24,3,18:1)
Block(-54,24,4,18:1)
Block(-54,24,5,18:1)
Block(-54,24,6,18:1)
Block(-54,24,7,17:5)
Block(-54,24,8,18:1)
Block(-54,24,10,18:1)
Block(-54,24,11,18:1)
Block(-54,24,12,18:1)
Block(-54,24,13,18:1)
Block(-54,24,14,18:1)
Block(-54,24,15,18:1)
Block(-54,24,17,18:1)
Block(-54,25,-18,18:1)
Block(-54,25,-16,18:1)
Block(-54,25,-15,18:1)
Block(-54,25,-13,18:1)
Block(-54,25,-12,18:1)
Block(-54,25,-9,18:1)
Block(-54,25,-8,18:1)
Block(-54,25,-7,18:1)
Block(-54,25,-6,18:1)
Block(-54,25,-4,18:1)
Block(-54,25,-2,18:1)
Block(-54,25,0,18:1)
Block(-54,25,5,18:1)
Block(-54,25,6,18:1)
Block(-54,25,7,18:1)
Block(-54,25,9,18:1)
Block(-54,25,10,18:1)
Block(-54,25,13,18:1)
Block(-54,25,15,18:1)
Block(-54,25,16,18:1)
Block(-54,26,-19,18:1)
Block(-54,26,-17,18:1)
Block(-54,26,-15,18:1)
Block(-54,26,-14,18:1)
Block(-54,26,-13,18:1)
Block(-54,26,-12,18:1)
Block(-54,26,-11,18:1)
Block(-54,26,-10,18:1)
Block(-54,26,-9,18:1)
Block(-54,26,-8,18:1)
Block(-54,26,-7,18:1)
Block(-54,26,-6,18:1)
Block(-54,26,-5,18:1)
Block(-54,26,-2,18:1)
Block(-54,26,-1,18:1)
Block(-54,26,0,18:1)
Block(-54,26,7,18:1)
Block(-54,26,9,18:1)
Block(-54,26,10,18:1)
Block(-54,26,11,18:1)
Block(-54,26,12,18:1)
Block(-54,26,13,18:1)
Block(-54,26,14,18:1)
Block(-54,26,15,18:1)
Block(-54,26,16,18:1)
Block(-54,27,-10,18:1)
Block(-54,27,-9,18:1)
Block(-54,27,-8,18:1)
Block(-54,27,0,18:1)
Block(-54,27,2,18:1)
Block(-53,20,1,18:1)
Block(-53,21,-18,18:1)
Block(-53,21,-16,18:1)
Block(-53,21,-12,18:1)
Block(-53,21,-7,18:1)
Block(-53,21,1,18:1)
Block(-53,21,2,18:1)
Block(-53,21,5,18:1)
Block(-53,21,7,18:1)
Block(-53,21,10,18:1)
Block(-53,21,12,18:1)
Block(-53,21,13,18:1)
Block(-53,22,-19,18:1)
Block(-53,22,-17,18:1)
Block(-53,22,-16,18:1)
Block(-53,22,-15,18:1)
Block(-53,22,-13,18:1)
Block(-53,22,-12,18:1)
Block(-53,22,-11,18:1)
Block(-53,22,-9,18:1)
Block(-53,22,-1,18:1)
Block(-53,22,0,18:1)
Block(-53,22,1,18:1)
Block(-53,22,2,18:1)
Block(-53,22,3,18:1)
Block(-53,22,5,18:1)
Block(-53,22,6,18:1)
Block(-53,22,7,18:1)
Block(-53,22,8,18:1)
Block(-53,22,9,18:1)
Block(-53,22,10,18:1)
Block(-53,22,11,18:1)
Block(-53,22,12,18:1)
Block(-53,22,14,18:1)
Block(-53,22,15,18:1)
Block(-53,23,-19,18:1)
Block(-53,23,-18,18:1)
Block(-53,23,-17,18:1)
Block(-53,23,-15,18:1)
Block(-53,23,-14,18:1)
Block(-53,23,-12,18:1)
Block(-53,23,-11,18:1)
Block(-53,23,-9,18:1)
Block(-53,23,-6,18:1)
Block(-53,23,-2,18:1)
Block(-53,23,-1,17:5)
Block(-53,23,0,17:5)
Block(-53,23,1,17:5)
Block(-53,23,2,18:1)
Block(-53,23,4,18:1)
Block(-53,23,5,18:1)
Block(-53,23,6,18:1)
Block(-53,23,7,18:1)
Block(-53,23,8,18:1)
Block(-53,23,9,18:1)
Block(-53,23,11,18:1)
Block(-53,23,12,18:1)
Block(-53,23,13,18:1)
Block(-53,23,14,18:1)
Block(-53,24,-18,18:1)
Block(-53,24,-16,18:1)
Block(-53,24,-15,18:1)
Block(-53,24,-14,18:1)
Block(-53,24,-13,18:1)
Block(-53,24,-12,17:5)
Block(-53,24,-11,18:1)
Block(-53,24,-10,18:1)
Block(-53,24,-9,17:5)
Block(-53,24,-8,18:1)
Block(-53,24,-6,17:5)
Block(-53,24,-5,18:1)
Block(-53,24,-4,18:1)
Block(-53,24,-3,17:5)
Block(-53,24,-1,17:5)
Block(-53,24,0,17:5)
Block(-53,24,1,17:5)
Block(-53,24,2,18:1)
Block(-53,24,3,18:1)
Block(-53,24,4,18:1)
Block(-53,24,5,18:1)
Block(-53,24,6,18:1)
Block(-53,24,7,17:5)
Block(-53,24,8,18:1)
Block(-53,24,10,18:1)
Block(-53,24,11,18:1)
Block(-53,24,12,18:1)
Block(-53,24,13,18:1)
Block(-53,24,14,18:1)
Block(-53,24,15,18:1)
Block(-53,24,16,18:1)
Block(-53,25,-16,18:1)
Block(-53,25,-15,18:1)
Block(-53,25,-12,18:1)
Block(-53,25,-11,18:1)
Block(-53,25,-10,18:1)
Block(-53,25,-9,18:1)
Block(-53,25,-8,18:1)
Block(-53,25,-7,18:1)
Block(-53,25,-6,18:1)
Block(-53,25,-3,18:1)
Block(-53,25,0,17:5)
Block(-53,25,2,18:1)
Block(-53,25,5,18:1)
Block(-53,25,6,18:1)
Block(-53,25,8,18:1)
Block(-53,25,10,18:1)
Block(-53,25,11,18:1)
Block(-53,25,12,18:1)
Block(-53,25,14,18:1)
Block(-53,25,16,18:1)
Block(-53,26,-19,18:1)
Block(-53,26,-15,18:1)
Block(-53,26,-14,18:1)
Block(-53,26,-13,18:1)
Block(-53,26,-12,18:1)
Block(-53,26,-10,18:1)
Block(-53,26,-9,18:1)
Block(-53,26,-8,18:1)
Block(-53,26,-7,18:1)
Block(-53,26,-6,18:1)
Block(-53,26,-3,18:1)
Block(-53,26,2,18:1)
Block(-53,26,4,18:1)
Block(-53,26,5,18:1)
Block(-53,26,6,18:1)
Block(-53,26,12,18:1)
Block(-53,26,14,18:1)
Block(-53,27,-16,18:1)
Block(-53,27,-13,18:1)
Block(-53,27,-10,18:1)
Block(-53,27,0,18:1)
Block(-53,27,1,18:1)
Block(-53,27,2,18:1)
Block(-53,27,5,18:1)
Block(-53,27,6,18:1)
Block(-53,27,9,18:1)
Block(-53,27,14,18:1)
Block(-53,27,15,18:1)
Block(-53,27,16,18:1)
Block(-53,28,0,18:1)
Block(-52,19,0,18:1)
Block(-52,20,-1,18:1)
Block(-52,20,1,18:1)
Block(-52,20,2,18:1)
Block(-52,21,-17,18:1)
Block(-52,21,-16,18:1)
Block(-52,21,-15,18:1)
Block(-52,21,-14,18:1)
Block(-52,21,-13,18:1)
Block(-52,21,-7,18:1)
Block(-52,21,-6,18:1)
Block(-52,21,-2,18:1)
Block(-52,21,1,18:1)
Block(-52,21,3,18:1)
Block(-52,21,9,18:1)
Block(-52,21,10,18:1)
Block(-52,21,11,18:1)
Block(-52,21,15,18:1)
Block(-52,22,-18,18:1)
Block(-52,22,-17,18:1)
Block(-52,22,-16,18:1)
Block(-52,22,-15,18:1)
Block(-52,22,-13,18:1)
Block(-52,22,-12,18:1)
Block(-52,22,-11,18:1)
Block(-52,22,-10,18:1)
Block(-52,22,-9,18:1)
Block(-52,22,-8,18:1)
Block(-52,22,-7,18:1)
Block(-52,22,-6,18:1)
Block(-52,22,-5,18:1)
Block(-52,22,-1,18:1)
Block(-52,22,0,18:1)
Block(-52,22,1,18:1)
Block(-52,22,2,18:1)
Block(-52,22,3,18:1)
Block(-52,22,4,18:1)
Block(-52,22,5,18:1)
Block(-52,22,6,18:1)
Block(-52,22,7,18:1)
Block(-52,22,8,18:1)
Block(-52,22,9,18:1)
Block(-52,22,10,18:1)
Block(-52,22,12,18:1)
Block(-52,22,13,18:1)
Block(-52,22,14,18:1)
Block(-52,22,15,18:1)
Block(-52,23,-18,18:1)
Block(-52,23,-17,18:1)
Block(-52,23,-16,18:1)
Block(-52,23,-15,18:1)
Block(-52,23,-14,18:1)
Block(-52,23,-13,18:1)
Block(-52,23,-12,18:1)
Block(-52,23,-11,18:1)
Block(-52,23,-10,18:1)
Block(-52,23,-9,18:1)
Block(-52,23,-8,18:1)
Block(-52,23,-6,17:9)
Block(-52,23,-5,17:9)
Block(-52,23,-4,17:9)
Block(-52,23,-3,17:9)
Block(-52,23,-2,17:9)
Block(-52,23,-1,17:5)
Block(-52,23,0,17:5)
Block(-52,23,1,17:5)
Block(-52,23,2,17:9)
Block(-52,23,3,17:9)
Block(-52,23,4,17:9)
Block(-52,23,5,17:9)
Block(-52,23,6,18:1)
Block(-52,23,7,18:1)
Block(-52,23,8,18:1)
Block(-52,23,10,18:1)
Block(-52,23,11,18:1)
Block(-52,23,12,18:1)
Block(-52,23,13,18:1)
Block(-52,23,14,18:1)
Block(-52,23,15,18:1)
Block(-52,23,18,18:1)
Block(-52,24,-20,18:1)
Block(-52,24,-19,18:1)
Block(-52,24,-18,18:1)
Block(-52,24,-17,17:9)
Block(-52,24,-16,17:9)
Block(-52,24,-15,17:9)
Block(-52,24,-14,17:9)
Block(-52,24,-13,17:9)
Block(-52,24,-12,17:9)
Block(-52,24,-11,17:9)
Block(-52,24,-10,17:9)
Block(-52,24,-9,17:9)
Block(-52,24,-8,17:9)
Block(-52,24,-7,17:9)
Block(-52,24,-6,17:9)
Block(-52,24,-5,17:9)
Block(-52,24,-4,17:9)
Block(-52,24,-3,17:9)
Block(-52,24,-2,17:9)
Block(-52,24,-1,17:5)
Block(-52,24,0,17:5)
Block(-52,24,1,17:5)
Block(-52,24,2,17:9)
Block(-52,24,3,17:9)
Block(-52,24,4,17:9)
Block(-52,24,5,17:9)
Block(-52,24,6,17:9)
Block(-52,24,7,17:9)
Block(-52,24,8,17:9)
Block(-52,24,9,17:9)
Block(-52,24,10,17:9)
Block(-52,24,11,17:9)
Block(-52,24,12,17:9)
Block(-52,24,13,17:9)
Block(-52,24,14,17:9)
Block(-52,24,15,17:9)
Block(-52,24,16,17:9)
Block(-52,24,17,18:1)
Block(-52,24,18,18:1)
Block(-52,25,-19,18:1)
Block(-52,25,-18,18:1)
Block(-52,25,-17,18:1)
Block(-52,25,-16,18:1)
Block(-52,25,-15,18:1)
Block(-52,25,-14,18:1)
Block(-52,25,-8,18:1)
Block(-52,25,-7,18:1)
Block(-52,25,-6,18:1)
Block(-52,25,-4,18:1)
Block(-52,25,-3,18:1)
Block(-52,25,-1,17:5)
Block(-52,25,0,17:5)
Block(-52,25,1,17:5)
Block(-52,25,2,18:1)
Block(-52,25,3,18:1)
Block(-52,25,4,18:1)
Block(-52,25,5,18:1)
Block(-52,25,6,18:1)
Block(-52,25,7,18:1)
Block(-52,25,9,18:1)
Block(-52,25,10,18:1)
Block(-52,25,11,18:1)
Block(-52,25,12,18:1)
Block(-52,25,15,18:1)
Block(-52,25,16,18:1)
Block(-52,26,-19,18:1)
Block(-52,26,-17,18:1)
Block(-52,26,-16,18:1)
Block(-52,26,-15,18:1)
Block(-52,26,-14,18:1)
Block(-52,26,-13,18:1)
Block(-52,26,-11,18:1)
Block(-52,26,-10,18:1)
Block(-52,26,-9,18:1)
Block(-52,26,-8,18:1)
Block(-52,26,-7,18:1)
Block(-52,26,-5,18:1)
Block(-52,26,-4,18:1)
Block(-52,26,-3,18:1)
Block(-52,26,-2,18:1)
Block(-52,26,-1,18:1)
Block(-52,26,0,18:1)
Block(-52,26,1,18:1)
Block(-52,26,3,18:1)
Block(-52,26,4,18:1)
Block(-52,26,5,18:1)
Block(-52,26,6,18:1)
Block(-52,26,7,18:1)
Block(-52,26,8,18:1)
Block(-52,26,10,18:1)
Block(-52,26,15,18:1)
Block(-52,26,16,18:1)
Block(-52,26,17,18:1)
Block(-52,27,-18,18:1)
Block(-52,27,-16,18:1)
Block(-52,27,-15,18:1)
Block(-52,27,-13,18:1)
Block(-52,27,-6,18:1)
Block(-52,27,0,18:1)
Block(-52,27,4,18:1)
Block(-52,27,5,18:1)
Block(-52,27,6,18:1)
Block(-52,27,9,18:1)
Block(-52,27,10,18:1)
Block(-52,27,11,18:1)
Block(-52,27,14,18:1)
Block(-52,27,15,18:1)
Block(-52,28,-1,18:1)
Block(-51,19,1,18:1)
Block(-51,19,2,18:1)
Block(-51,20,-1,18:1)
Block(-51,20,0,18:1)
Block(-51,20,1,18:1)
Block(-51,20,3,18:1)
Block(-51,21,-15,18:1)
Block(-51,21,-14,18:1)
Block(-51,21,-13,18:1)
Block(-51,21,-2,18:1)
Block(-51,21,1,18:1)
Block(-51,21,2,18:1)
Block(-51,21,3,18:1)
Block(-51,21,4,18:1)
Block(-51,22,-19,18:1)
Block(-51,22,-18,18:1)
Block(-51,22,-17,18:1)
Block(-51,22,-16,18:1)
Block(-51,22,-15,18:1)
Block(-51,22,-13,18:1)
Block(-51,22,-12,18:1)
Block(-51,22,-11,18:1)
Block(-51,22,-8,18:1)
Block(-51,22,-6,18:1)
Block(-51,22,-1,18:1)
Block(-51,22,0,18:1)
Block(-51,22,1,18:1)
Block(-51,22,2,18:1)
Block(-51,22,3,18:1)
Block(-51,22,4,18:1)
Block(-51,22,5,18:1)
Block(-51,22,13,18:1)
Block(-51,22,15,18:1)
Block(-51,22,17,18:1)
Block(-51,23,-18,18:1)
Block(-51,23,-17,18:1)
Block(-51,23,-15,18:1)
Block(-51,23,-14,18:1)
Block(-51,23,-13,18:1)
Block(-51,23,-12,18:1)
Block(-51,23,-10,18:1)
Block(-51,23,-9,18:1)
Block(-51,23,-3,18:1)
Block(-51,23,-2,18:1)
Block(-51,23,0,17:5)
Block(-51,23,1,18:1)
Block(-51,23,2,18:1)
Block(-51,23,3,18:1)
Block(-51,23,4,18:1)
Block(-51,23,7,18:1)
Block(-51,23,10,18:1)
Block(-51,23,15,18:1)
Block(-51,23,16,18:1)
Block(-51,24,-18,18:1)
Block(-51,24,-17,18:1)
Block(-51,24,-15,18:1)
Block(-51,24,-14,17:5)
Block(-51,24,-13,18:1)
Block(-51,24,-12,18:1)
Block(-51,24,-11,18:1)
Block(-51,24,-10,18:1)
Block(-51,24,-9,18:1)
Block(-51,24,-7,18:1)
Block(-51,24,-6,17:5)
Block(-51,24,-5,18:1)
Block(-51,24,-4,18:1)
Block(-51,24,-3,17:5)
Block(-51,24,-1,17:5)
Block(-51,24,0,17:5)
Block(-51,24,1,17:5)
Block(-51,24,2,18:1)
Block(-51,24,3,18:1)
Block(-51,24,5,18:1)
Block(-51,24,6,18:1)
Block(-51,24,7,18:1)
Block(-51,24,8,18:1)
Block(-51,24,9,18:1)
Block(-51,24,10,17:5)
Block(-51,24,12,18:1)
Block(-51,24,13,18:1)
Block(-51,24,14,18:1)
Block(-51,24,15,18:1)
Block(-51,24,16,18:1)
Block(-51,24,17,18:1)
Block(-51,25,-17,18:1)
Block(-51,25,-16,18:1)
Block(-51,25,-14,18:1)
Block(-51,25,-13,18:1)
Block(-51,25,-12,18:1)
Block(-51,25,-11,17:5)
Block(-51,25,-10,18:1)
Block(-51,25,-9,18:1)
Block(-51,25,-8,18:1)
Block(-51,25,-7,18:1)
Block(-51,25,-6,18:1)
Block(-51,25,-5,18:1)
Block(-51,25,-3,18:1)
Block(-51,25,-2,18:1)
Block(-51,25,-1,17:5)
Block(-51,25,0,17:5)
Block(-51,25,1,17:5)
Block(-51,25,2,18:1)
Block(-51,25,3,18:1)
Block(-51,25,4,18:1)
Block(-51,25,5,18:1)
Block(-51,25,6,18:1)
Block(-51,25,7,18:1)
Block(-51,25,8,18:1)
Block(-51,25,9,18:1)
Block(-51,25,10,18:1)
Block(-51,25,11,18:1)
Block(-51,25,12,18:1)
Block(-51,25,13,18:1)
Block(-51,25,15,18:1)
Block(-51,25,17,18:1)
Block(-51,25,18,18:1)
Block(-51,26,-19,18:1)
Block(-51,26,-17,18:1)
Block(-51,26,-15,18:1)
Block(-51,26,-14,18:1)
Block(-51,26,-13,18:1)
Block(-51,26,-12,18:1)
Block(-51,26,-11,18:1)
Block(-51,26,-10,18:1)
Block(-51,26,-8,18:1)
Block(-51,26,-7,18:1)
Block(-51,26,-6,18:1)
Block(-51,26,-3,18:1)
Block(-51,26,-2,18:1)
Block(-51,26,-1,18:1)
Block(-51,26,0,18:1)
Block(-51,26,1,18:1)
Block(-51,26,2,18:1)
Block(-51,26,3,18:1)
Block(-51,26,4,18:1)
Block(-51,26,5,18:1)
Block(-51,26,6,18:1)
Block(-51,26,7,18:1)
Block(-51,26,8,18:1)
Block(-51,26,9,18:1)
Block(-51,26,10,18:1)
Block(-51,26,11,18:1)
Block(-51,26,12,18:1)
Block(-51,26,15,18:1)
Block(-51,26,16,18:1)
Block(-51,26,17,18:1)
Block(-51,27,-15,18:1)
Block(-51,27,-14,18:1)
Block(-51,27,-12,18:1)
Block(-51,27,-11,18:1)
Block(-51,27,-6,18:1)
Block(-51,27,-2,18:1)
Block(-51,27,0,18:1)
Block(-51,27,1,18:1)
Block(-51,27,5,18:1)
Block(-51,27,6,18:1)
Block(-51,27,10,18:1)
Block(-51,27,14,18:1)
Block(-51,27,15,18:1)
Block(-50,19,0,18:1)
Block(-50,19,1,18:1)
Block(-50,20,1,18:1)
Block(-50,20,2,18:1)
Block(-50,21,0,18:1)
Block(-50,21,2,18:1)
Block(-50,22,-16,18:1)
Block(-50,22,-15,18:1)
Block(-50,22,-14,18:1)
Block(-50,22,-8,18:1)
Block(-50,22,-2,18:1)
Block(-50,22,1,18:1)
Block(-50,22,2,18:1)
Block(-50,22,3,18:1)
Block(-50,22,4,18:1)
Block(-50,22,5,18:1)
Block(-50,22,7,18:1)
Block(-50,22,9,18:1)
Block(-50,22,10,18:1)
Block(-50,22,11,18:1)
Block(-50,22,12,18:1)
Block(-50,22,16,18:1)
Block(-50,22,17,18:1)
Block(-50,23,-16,18:1)
Block(-50,23,-15,18:1)
Block(-50,23,-14,18:1)
Block(-50,23,-13,18:1)
Block(-50,23,-12,18:1)
Block(-50,23,-10,18:1)
Block(-50,23,-8,18:1)
Block(-50,23,-7,18:1)
Block(-50,23,-6,18:1)
Block(-50,23,-5,18:1)
Block(-50,23,-1,18:1)
Block(-50,23,0,17:5)
Block(-50,23,1,18:1)
Block(-50,23,2,18:1)
Block(-50,23,3,18:1)
Block(-50,23,4,18:1)
Block(-50,23,5,18:1)
Block(-50,23,8,18:1)
Block(-50,23,9,18:1)
Block(-50,23,11,18:1)
Block(-50,23,12,18:1)
Block(-50,23,14,18:1)
Block(-50,23,15,18:1)
Block(-50,23,17,18:1)
Block(-50,24,-19,18:1)
Block(-50,24,-18,18:1)
Block(-50,24,-17,18:1)
Block(-50,24,-16,18:1)
Block(-50,24,-15,18:1)
Block(-50,24,-14,18:1)
Block(-50,24,-13,18:1)
Block(-50,24,-12,18:1)
Block(-50,24,-11,18:1)
Block(-50,24,-10,18:1)
Block(-50,24,-7,18:1)
Block(-50,24,-6,17:5)
Block(-50,24,-5,18:1)
Block(-50,24,-2,18:1)
Block(-50,24,-1,17:5)
Block(-50,24,0,17:5)
Block(-50,24,1,17:5)
Block(-50,24,2,18:1)
Block(-50,24,3,18:1)
Block(-50,24,4,18:1)
Block(-50,24,5,18:1)
Block(-50,24,6,18:1)
Block(-50,24,7,18:1)
Block(-50,24,8,18:1)
Block(-50,24,9,18:1)
Block(-50,24,10,18:1)
Block(-50,24,12,18:1)
Block(-50,24,13,18:1)
Block(-50,24,14,18:1)
Block(-50,24,15,18:1)
Block(-50,24,16,18:1)
Block(-50,24,17,18:1)
Block(-50,25,-19,18:1)
Block(-50,25,-18,18:1)
Block(-50,25,-17,18:1)
Block(-50,25,-16,18:1)
Block(-50,25,-15,18:1)
Block(-50,25,-14,18:1)
Block(-50,25,-13,18:1)
Block(-50,25,-11,17:5)
Block(-50,25,-10,18:1)
Block(-50,25,-9,18:1)
Block(-50,25,-8,18:1)
Block(-50,25,-7,18:1)
Block(-50,25,-6,18:1)
Block(-50,25,-5,18:1)
Block(-50,25,-4,18:1)
Block(-50,25,-2,18:1)
Block(-50,25,-1,17:5)
Block(-50,25,0,17:5)
Block(-50,25,1,17:5)
Block(-50,25,2,18:1)
Block(-50,25,5,17:5)
Block(-50,25,6,18:1)
Block(-50,25,7,18:1)
Block(-50,25,8,18:1)
Block(-50,25,10,18:1)
Block(-50,25,12,18:1)
Block(-50,25,14,18:1)
Block(-50,25,15,18:1)
Block(-50,25,16,17:5)
Block(-50,25,18,18:1)
Block(-50,26,-19,18:1)
Block(-50,26,-17,18:1)
Block(-50,26,-16,18:1)
Block(-50,26,-15,18:1)
Block(-50,26,-14,18:1)
Block(-50,26,-12,18:1)
Block(-50,26,-11,18:1)
Block(-50,26,-9,18:1)
Block(-50,26,-8,18:1)
Block(-50,26,-7,18:1)
Block(-50,26,-6,18:1)
Block(-50,26,-2,18:1)
Block(-50,26,-1,18:1)
Block(-50,26,0,17:5)
Block(-50,26,1,18:1)
Block(-50,26,2,18:1)
Block(-50,26,3,18:1)
Block(-50,26,4,18:1)
Block(-50,26,6,18:1)
Block(-50,26,8,18:1)
Block(-50,26,10,18:1)
Block(-50,26,11,18:1)
Block(-50,26,12,18:1)
Block(-50,26,13,18:1)
Block(-50,26,14,18:1)
Block(-50,26,15,18:1)
Block(-50,26,17,18:1)
Block(-50,26,18,18:1)
Block(-50,27,-18,18:1)
Block(-50,27,-16,18:1)
Block(-50,27,-15,18:1)
Block(-50,27,-14,18:1)
Block(-50,27,-13,18:1)
Block(-50,27,-10,18:1)
Block(-50,27,-9,18:1)
Block(-50,27,-8,18:1)
Block(-50,27,-6,18:1)
Block(-50,27,-1,18:1)
Block(-50,27,0,18:1)
Block(-50,27,2,18:1)
Block(-50,27,5,18:1)
Block(-50,27,9,18:1)
Block(-50,27,10,18:1)
Block(-50,27,13,18:1)
Block(-50,27,14,18:1)
Block(-50,27,15,18:1)
Block(-50,28,0,18:1)
Block(-49,20,1,18:1)
Block(-49,22,-15,18:1)
Block(-49,22,0,18:1)
Block(-49,22,1,18:1)
Block(-49,22,2,18:1)
Block(-49,22,5,18:1)
Block(-49,22,11,18:1)
Block(-49,22,13,18:1)
Block(-49,22,16,18:1)
Block(-49,23,-18,18:1)
Block(-49,23,-17,18:1)
Block(-49,23,-16,18:1)
Block(-49,23,-15,18:1)
Block(-49,23,-14,18:1)
Block(-49,23,-12,18:1)
Block(-49,23,-6,18:1)
Block(-49,23,-5,18:1)
Block(-49,23,-2,18:1)
Block(-49,23,-1,18:1)
Block(-49,23,0,18:1)
Block(-49,23,1,18:1)
Block(-49,23,2,18:1)
Block(-49,23,4,18:1)
Block(-49,23,5,18:1)
Block(-49,23,7,18:1)
Block(-49,23,9,18:1)
Block(-49,23,10,18:1)
Block(-49,23,11,18:1)
Block(-49,23,12,18:1)
Block(-49,23,13,18:1)
Block(-49,23,14,18:1)
Block(-49,23,16,18:1)
Block(-49,23,17,18:1)
Block(-49,23,18,18:1)
Block(-49,24,-18,18:1)
Block(-49,24,-17,18:1)
Block(-49,24,-16,18:1)
Block(-49,24,-15,18:1)
Block(-49,24,-13,18:1)
Block(-49,24,-12,18:1)
Block(-49,24,-11,18:1)
Block(-49,24,-8,18:1)
Block(-49,24,-7,18:1)
Block(-49,24,-6,18:1)
Block(-49,24,-5,18:1)
Block(-49,24,-2,18:1)
Block(-49,24,-1,17:5)
Block(-49,24,0,17:5)
Block(-49,24,1,17:5)
Block(-49,24,2,18:1)
Block(-49,24,3,18:1)
Block(-49,24,4,18:1)
Block(-49,24,5,18:1)
Block(-49,24,6,18:1)
Block(-49,24,8,18:1)
Block(-49,24,9,18:1)
Block(-49,24,10,18:1)
Block(-49,24,12,18:1)
Block(-49,24,13,18:1)
Block(-49,24,14,18:1)
Block(-49,24,15,18:1)
Block(-49,24,16,18:1)
Block(-49,25,-19,18:1)
Block(-49,25,-18,18:1)
Block(-49,25,-17,17:5)
Block(-49,25,-16,18:1)
Block(-49,25,-15,18:1)
Block(-49,25,-14,18:1)
Block(-49,25,-13,18:1)
Block(-49,25,-12,18:1)
Block(-49,25,-11,17:5)
Block(-49,25,-10,18:1)
Block(-49,25,-9,18:1)
Block(-49,25,-8,17:5)
Block(-49,25,-7,18:1)
Block(-49,25,-6,18:1)
Block(-49,25,-5,18:1)
Block(-49,25,-4,17:5)
Block(-49,25,-2,18:1)
Block(-49,25,-1,17:5)
Block(-49,25,0,17:5)
Block(-49,25,1,17:5)
Block(-49,25,2,18:1)
Block(-49,25,3,18:1)
Block(-49,25,4,18:1)
Block(-49,25,5,17:5)
Block(-49,25,6,18:1)
Block(-49,25,8,18:1)
Block(-49,25,9,17:5)
Block(-49,25,10,18:1)
Block(-49,25,11,17:5)
Block(-49,25,12,18:1)
Block(-49,25,13,18:1)
Block(-49,25,14,18:1)
Block(-49,25,15,18:1)
Block(-49,25,16,17:5)
Block(-49,25,17,18:1)
Block(-49,25,18,18:1)
Block(-49,26,-19,18:1)
Block(-49,26,-18,18:1)
Block(-49,26,-16,18:1)
Block(-49,26,-14,18:1)
Block(-49,26,-13,18:1)
Block(-49,26,-12,18:1)
Block(-49,26,-9,18:1)
Block(-49,26,-8,18:1)
Block(-49,26,-7,18:1)
Block(-49,26,-6,18:1)
Block(-49,26,-5,18:1)
Block(-49,26,-4,18:1)
Block(-49,26,-3,18:1)
Block(-49,26,-2,18:1)
Block(-49,26,-1,18:1)
Block(-49,26,0,17:5)
Block(-49,26,1,18:1)
Block(-49,26,2,18:1)
Block(-49,26,3,18:1)
Block(-49,26,4,18:1)
Block(-49,26,5,18:1)
Block(-49,26,10,18:1)
Block(-49,26,11,18:1)
Block(-49,26,13,18:1)
Block(-49,26,15,18:1)
Block(-49,26,18,18:1)
Block(-49,26,19,18:1)
Block(-49,27,-20,18:1)
Block(-49,27,-16,18:1)
Block(-49,27,-14,18:1)
Block(-49,27,-11,18:1)
Block(-49,27,-9,18:1)
Block(-49,27,-7,18:1)
Block(-49,27,-6,18:1)
Block(-49,27,-5,18:1)
Block(-49,27,-4,18:1)
Block(-49,27,-2,18:1)
Block(-49,27,1,18:1)
Block(-49,27,9,18:1)
Block(-49,27,10,18:1)
Block(-49,27,12,18:1)
Block(-49,27,13,18:1)
Block(-49,27,14,18:1)
Block(-49,27,15,18:1)
Block(-49,27,16,18:1)
Block(-49,28,-16,18:1)
Block(-49,28,-13,18:1)
Block(-49,28,-2,18:1)
Block(-49,28,5,18:1)
Block(-49,28,6,18:1)
Block(-49,28,12,18:1)
Block(-49,28,15,18:1)
Block(-49,29,0,18:1)
Block(-48,21,-1,18:1)
Block(-48,21,0,18:1)
Block(-48,21,1,18:1)
Block(-48,22,-16,18:1)
Block(-48,22,-13,18:1)
Block(-48,22,-12,18:1)
Block(-48,22,-8,18:1)
Block(-48,22,-7,18:1)
Block(-48,22,-6,18:1)
Block(-48,22,-1,18:1)
Block(-48,22,0,18:1)
Block(-48,22,1,18:1)
Block(-48,22,5,18:1)
Block(-48,22,6,18:1)
Block(-48,22,10,18:1)
Block(-48,22,11,18:1)
Block(-48,22,12,18:1)
Block(-48,22,13,18:1)
Block(-48,22,15,18:1)
Block(-48,22,16,18:1)
Block(-48,22,17,18:1)
Block(-48,23,-16,18:1)
Block(-48,23,-14,18:1)
Block(-48,23,-12,18:1)
Block(-48,23,-11,18:1)
Block(-48,23,-9,18:1)
Block(-48,23,-8,18:1)
Block(-48,23,-7,18:1)
Block(-48,23,-5,18:1)
Block(-48,23,-3,18:1)
Block(-48,23,-1,18:1)
Block(-48,23,0,18:1)
Block(-48,23,2,18:1)
Block(-48,23,4,18:1)
Block(-48,23,5,18:1)
Block(-48,23,8,18:1)
Block(-48,23,9,18:1)
Block(-48,23,10,18:1)
Block(-48,23,11,18:1)
Block(-48,23,12,18:1)
Block(-48,23,14,18:1)
Block(-48,23,18,18:1)
Block(-48,24,-19,18:1)
Block(-48,24,-18,18:1)
Block(-48,24,-16,18:1)
Block(-48,24,-14,18:1)
Block(-48,24,-13,18:1)
Block(-48,24,-12,18:1)
Block(-48,24,-11,18:1)
Block(-48,24,-10,18:1)
Block(-48,24,-9,18:1)
Block(-48,24,-8,18:1)
Block(-48,24,-7,17:9)
Block(-48,24,-6,17:9)
Block(-48,24,-5,17:9)
Block(-48,24,-4,17:9)
Block(-48,24,-3,17:9)
Block(-48,24,-2,17:9)
Block(-48,24,-1,17:5)
Block(-48,24,0,17:5)
Block(-48,24,1,17:5)
Block(-48,24,2,17:9)
Block(-48,24,3,17:9)
Block(-48,24,4,17:9)
Block(-48,24,5,17:9)
Block(-48,24,6,17:9)
Block(-48,24,7,17:9)
Block(-48,24,8,18:1)
Block(-48,24,9,18:1)
Block(-48,24,10,18:1)
Block(-48,24,11,18:1)
Block(-48,24,12,18:1)
Block(-48,24,13,18:1)
Block(-48,24,14,18:1)
Block(-48,24,16,18:1)
Block(-48,24,17,18:1)
Block(-48,25,-19,17:9)
Block(-48,25,-18,17:9)
Block(-48,25,-17,17:9)
Block(-48,25,-16,17:9)
Block(-48,25,-15,17:9)
Block(-48,25,-14,17:9)
Block(-48,25,-13,17:9)
Block(-48,25,-12,17:9)
Block(-48,25,-11,17:9)
Block(-48,25,-10,17:9)
Block(-48,25,-9,17:9)
Block(-48,25,-8,17:9)
Block(-48,25,-7,17:9)
Block(-48,25,-6,17:9)
Block(-48,25,-5,17:9)
Block(-48,25,-4,17:9)
Block(-48,25,-3,17:9)
Block(-48,25,-2,17:9)
Block(-48,25,-1,17:5)
Block(-48,25,0,17:5)
Block(-48,25,1,17:5)
Block(-48,25,2,17:9)
Block(-48,25,3,17:9)
Block(-48,25,4,17:9)
Block(-48,25,5,17:9)
Block(-48,25,6,17:9)
Block(-48,25,7,17:9)
Block(-48,25,8,17:9)
Block(-48,25,9,17:9)
Block(-48,25,10,17:9)
Block(-48,25,11,17:9)
Block(-48,25,12,17:9)
Block(-48,25,13,17:9)
Block(-48,25,14,17:9)
Block(-48,25,15,17:9)
Block(-48,25,16,17:9)
Block(-48,25,17,17:9)
Block(-48,25,18,17:9)
Block(-48,25,22,18:1)
Block(-48,26,-20,18:1)
Block(-48,26,-19,18:1)
Block(-48,26,-18,18:1)
Block(-48,26,-17,18:1)
Block(-48,26,-16,18:1)
Block(-48,26,-15,18:1)
Block(-48,26,-14,18:1)
Block(-48,26,-13,18:1)
Block(-48,26,-12,18:1)
Block(-48,26,-11,18:1)
Block(-48,26,-10,18:1)
Block(-48,26,-9,18:1)
Block(-48,26,-8,18:1)
Block(-48,26,-5,18:1)
Block(-48,26,-4,18:1)
Block(-48,26,-3,18:1)
Block(-48,26,-2,18:1)
Block(-48,26,-1,17:5)
Block(-48,26,0,17:5)
Block(-48,26,1,17:5)
Block(-48,26,2,18:1)
Block(-48,26,3,18:1)
Block(-48,26,5,18:1)
Block(-48,26,9,18:1)
Block(-48,26,10,18:1)
Block(-48,26,11,18:1)
Block(-48,26,12,18:1)
Block(-48,26,13,18:1)
Block(-48,26,14,18:1)
Block(-48,26,16,18:1)
Block(-48,26,17,18:1)
Block(-48,26,18,18:1)
Block(-48,26,19,18:1)
Block(-48,26,20,18:1)
Block(-48,26,21,18:1)
Block(-48,26,22,18:1)
Block(-48,27,-21,18:1)
Block(-48,27,-18,18:1)
Block(-48,27,-17,18:1)
Block(-48,27,-16,18:1)
Block(-48,27,-14,18:1)
Block(-48,27,-13,18:1)
Block(-48,27,-12,18:1)
Block(-48,27,-11,18:1)
Block(-48,27,-10,18:1)
Block(-48,27,-8,18:1)
Block(-48,27,-7,18:1)
Block(-48,27,-6,18:1)
Block(-48,27,-3,18:1)
Block(-48,27,-1,18:1)
Block(-48,27,2,18:1)
Block(-48,27,3,18:1)
Block(-48,27,6,18:1)
Block(-48,27,7,18:1)
Block(-48,27,9,18:1)
Block(-48,27,10,18:1)
Block(-48,27,11,18:1)
Block(-48,27,12,18:1)
Block(-48,27,13,18:1)
Block(-48,27,14,18:1)
Block(-48,27,15,18:1)
Block(-48,27,17,18:1)
Block(-48,27,18,18:1)
Block(-48,27,22,18:1)
Block(-48,28,-20,18:1)
Block(-48,28,-19,18:1)
Block(-48,28,-18,18:1)
Block(-48,28,-17,18:1)
Block(-48,28,-16,18:1)
Block(-48,28,-12,18:1)
Block(-48,28,-10,18:1)
Block(-48,28,-9,18:1)
Block(-48,28,-8,18:1)
Block(-48,28,-5,18:1)
Block(-48,28,-4,18:1)
Block(-48,28,-3,18:1)
Block(-48,28,-2,18:1)
Block(-48,28,-1,18:1)
Block(-48,28,0,18:1)
Block(-48,28,4,18:1)
Block(-48,28,5,18:1)
Block(-48,28,6,18:1)
Block(-48,28,9,18:1)
Block(-48,28,10,18:1)
Block(-48,28,12,18:1)
Block(-48,28,13,18:1)
Block(-48,28,16,18:1)
Block(-48,28,17,18:1)
Block(-48,29,-1,18:1)
Block(-48,29,0,18:1)
Block(-48,29,1,18:1)
Block(-47,21,-1,18:1)
Block(-47,21,0,18:1)
Block(-47,21,1,18:1)
Block(-47,22,-16,18:1)
Block(-47,22,-11,18:1)
Block(-47,22,-8,18:1)
Block(-47,22,-2,18:1)
Block(-47,22,-1,18:1)
Block(-47,22,0,18:1)
Block(-47,22,2,18:1)
Block(-47,22,5,18:1)
Block(-47,22,9,18:1)
Block(-47,22,10,18:1)
Block(-47,22,16,18:1)
Block(-47,22,17,18:1)
Block(-47,23,-19,18:1)
Block(-47,23,-18,18:1)
Block(-47,23,-16,18:1)
Block(-47,23,-14,18:1)
Block(-47,23,-12,18:1)
Block(-47,23,-10,18:1)
Block(-47,23,-9,18:1)
Block(-47,23,-8,18:1)
Block(-47,23,-1,18:1)
Block(-47,23,0,18:1)
Block(-47,23,1,18:1)
Block(-47,23,2,18:1)
Block(-47,23,3,18:1)
Block(-47,23,5,18:1)
Block(-47,23,7,18:1)
Block(-47,23,9,18:1)
Block(-47,23,10,18:1)
Block(-47,23,11,18:1)
Block(-47,23,12,18:1)
Block(-47,23,13,18:1)
Block(-47,23,14,18:1)
Block(-47,23,17,18:1)
Block(-47,24,-19,18:1)
Block(-47,24,-18,18:1)
Block(-47,24,-16,18:1)
Block(-47,24,-13,18:1)
Block(-47,24,-11,18:1)
Block(-47,24,-10,18:1)
Block(-47,24,-9,18:1)
Block(-47,24,-7,18:1)
Block(-47,24,-5,18:1)
Block(-47,24,-3,18:1)
Block(-47,24,-2,18:1)
Block(-47,24,-1,18:1)
Block(-47,24,0,17:5)
Block(-47,24,1,18:1)
Block(-47,24,2,18:1)
Block(-47,24,3,18:1)
Block(-47,24,4,18:1)
Block(-47,24,5,18:1)
Block(-47,24,6,18:1)
Block(-47,24,7,18:1)
Block(-47,24,8,18:1)
Block(-47,24,10,18:1)
Block(-47,24,15,18:1)
Block(-47,24,20,18:1)
Block(-47,24,21,18:1)
Block(-47,25,-22,18:1)
Block(-47,25,-18,18:1)
Block(-47,25,-17,18:1)
Block(-47,25,-16,18:1)
Block(-47,25,-15,18:1)
Block(-47,25,-14,18:1)
Block(-47,25,-13,18:1)
Block(-47,25,-12,18:1)
Block(-47,25,-11,18:1)
Block(-47,25,-10,18:1)
Block(-47,25,-9,18:1)
Block(-47,25,-8,18:1)
Block(-47,25,-7,18:1)
Block(-47,25,-6,18:1)
Block(-47,25,-4,18:1)
Block(-47,25,-3,18:1)
Block(-47,25,-2,18:1)
Block(-47,25,-1,17:5)
Block(-47,25,0,17:5)
Block(-47,25,1,17:5)
Block(-47,25,2,18:1)
Block(-47,25,3,18:1)
Block(-47,25,4,18:1)
Block(-47,25,5,18:1)
Block(-47,25,6,18:1)
Block(-47,25,7,18:1)
Block(-47,25,8,18:1)
Block(-47,25,9,17:5)
Block(-47,25,10,18:1)
Block(-47,25,11,18:1)
Block(-47,25,12,18:1)
Block(-47,25,13,18:1)
Block(-47,25,14,18:1)
Block(-47,25,16,18:1)
Block(-47,25,17,18:1)
Block(-47,25,18,18:1)
Block(-47,25,19,18:1)
Block(-47,25,22,18:1)
Block(-47,25,23,18:1)
Block(-47,26,-20,18:1)
Block(-47,26,-19,18:1)
Block(-47,26,-17,18:1)
Block(-47,26,-16,18:1)
Block(-47,26,-15,18:1)
Block(-47,26,-14,18:1)
Block(-47,26,-13,18:1)
Block(-47,26,-12,18:1)
Block(-47,26,-11,18:1)
Block(-47,26,-9,18:1)
Block(-47,26,-7,18:1)
Block(-47,26,-6,18:1)
Block(-47,26,-5,18:1)
Block(-47,26,-4,18:1)
Block(-47,26,-3,18:1)
Block(-47,26,-2,18:1)
Block(-47,26,-1,17:5)
Block(-47,26,0,17:5)
Block(-47,26,1,17:5)
Block(-47,26,2,18:1)
Block(-47,26,3,18:1)
Block(-47,26,4,18:1)
Block(-47,26,6,18:1)
Block(-47,26,7,18:1)
Block(-47,26,8,18:1)
Block(-47,26,9,18:1)
Block(-47,26,10,18:1)
Block(-47,26,11,18:1)
Block(-47,26,12,18:1)
Block(-47,26,13,18:1)
Block(-47,26,17,18:1)
Block(-47,26,19,18:1)
Block(-47,26,21,18:1)
Block(-47,27,-21,18:1)
Block(-47,27,-20,18:1)
Block(-47,27,-17,18:1)
Block(-47,27,-16,18:1)
Block(-47,27,-14,18:1)
Block(-47,27,-13,18:1)
Block(-47,27,-12,18:1)
Block(-47,27,-11,18:1)
Block(-47,27,-10,18:1)
Block(-47,27,-9,18:1)
Block(-47,27,-8,18:1)
Block(-47,27,-7,18:1)
Block(-47,27,-5,18:1)
Block(-47,27,-4,18:1)
Block(-47,27,-2,18:1)
Block(-47,27,-1,18:1)
Block(-47,27,0,18:1)
Block(-47,27,1,18:1)
Block(-47,27,3,18:1)
Block(-47,27,6,18:1)
Block(-47,27,8,18:1)
Block(-47,27,9,18:1)
Block(-47,27,11,18:1)
Block(-47,27,12,18:1)
Block(-47,27,13,18:1)
Block(-47,27,20,18:1)
Block(-47,28,-17,18:1)
Block(-47,28,-16,18:1)
Block(-47,28,-15,18:1)
Block(-47,28,-13,18:1)
Block(-47,28,-12,18:1)
Block(-47,28,-11,18:1)
Block(-47,28,-10,18:1)
Block(-47,28,-8,18:1)
Block(-47,28,-7,18:1)
Block(-47,28,-6,18:1)
Block(-47,28,-2,18:1)
Block(-47,28,-1,18:1)
Block(-47,28,0,18:1)
Block(-47,28,1,18:1)
Block(-47,28,2,18:1)
Block(-47,28,5,18:1)
Block(-47,28,10,18:1)
Block(-47,28,11,18:1)
Block(-47,28,13,18:1)
Block(-47,28,15,18:1)
Block(-47,28,19,18:1)
Block(-47,29,-10,18:1)
Block(-47,29,-4,18:1)
Block(-47,29,-1,18:1)
Block(-47,29,1,18:1)
Block(-46,21,-1,18:1)
Block(-46,21,0,18:1)
Block(-46,22,-2,18:1)
Block(-46,22,1,18:1)
Block(-46,23,-20,18:1)
Block(-46,23,-19,18:1)
Block(-46,23,-14,18:1)
Block(-46,23,-12,18:1)
Block(-46,23,-10,18:1)
Block(-46,23,-9,18:1)
Block(-46,23,-8,18:1)
Block(-46,23,-7,18:1)
Block(-46,23,-6,18:1)
Block(-46,23,-4,18:1)
Block(-46,23,-1,18:1)
Block(-46,23,0,18:1)
Block(-46,23,1,18:1)
Block(-46,23,2,18:1)
Block(-46,23,3,18:1)
Block(-46,23,4,18:1)
Block(-46,23,5,18:1)
Block(-46,23,6,18:1)
Block(-46,23,7,18:1)
Block(-46,23,10,18:1)
Block(-46,23,12,18:1)
Block(-46,23,14,18:1)
Block(-46,23,17,18:1)
Block(-46,23,20,18:1)
Block(-46,24,-27,18:1)
Block(-46,24,-20,18:1)
Block(-46,24,-19,18:1)
Block(-46,24,-18,18:1)
Block(-46,24,-17,18:1)
Block(-46,24,-15,18:1)
Block(-46,24,-14,18:1)
Block(-46,24,-13,18:1)
Block(-46,24,-12,18:1)
Block(-46,24,-11,18:1)
Block(-46,24,-10,18:1)
Block(-46,24,-9,18:1)
Block(-46,24,-7,18:1)
Block(-46,24,-5,18:1)
Block(-46,24,-4,18:1)
Block(-46,24,-1,18:1)
Block(-46,24,0,17:5)
Block(-46,24,2,18:1)
Block(-46,24,3,18:1)
Block(-46,24,4,18:1)
Block(-46,24,5,18:1)
Block(-46,24,6,18:1)
Block(-46,24,8,18:1)
Block(-46,24,9,18:1)
Block(-46,24,10,18:1)
Block(-46,24,12,18:1)
Block(-46,24,14,18:1)
Block(-46,24,16,18:1)
Block(-46,24,21,18:1)
Block(-46,24,23,18:1)
Block(-46,25,-26,18:1)
Block(-46,25,-21,18:1)
Block(-46,25,-20,18:1)
Block(-46,25,-19,18:1)
Block(-46,25,-18,18:1)
Block(-46,25,-17,18:1)
Block(-46,25,-16,18:1)
Block(-46,25,-15,18:1)
Block(-46,25,-11,18:1)
Block(-46,25,-10,18:1)
Block(-46,25,-9,18:1)
Block(-46,25,-8,18:1)
Block(-46,25,-7,18:1)
Block(-46,25,-6,18:1)
Block(-46,25,-5,18:1)
Block(-46,25,-4,18:1)
Block(-46,25,-3,18:1)
Block(-46,25,-2,18:1)
Block(-46,25,-1,17:5)
Block(-46,25,0,17:5)
Block(-46,25,1,17:5)
Block(-46,25,3,18:1)
Block(-46,25,4,18:1)
Block(-46,25,5,18:1)
Block(-46,25,6,18:1)
Block(-46,25,7,18:1)
Block(-46,25,8,18:1)
Block(-46,25,9,17:5)
Block(-46,25,10,18:1)
Block(-46,25,11,18:1)
Block(-46,25,12,18:1)
Block(-46,25,13,18:1)
Block(-46,25,14,18:1)
Block(-46,25,15,18:1)
Block(-46,25,16,18:1)
Block(-46,25,17,18:1)
Block(-46,25,18,18:1)
Block(-46,25,19,18:1)
Block(-46,25,20,18:1)
Block(-46,26,-27,18:1)
Block(-46,26,-26,18:1)
Block(-46,26,-22,18:1)
Block(-46,26,-21,18:1)
Block(-46,26,-20,18:1)
Block(-46,26,-19,17:5)
Block(-46,26,-18,18:1)
Block(-46,26,-17,18:1)
Block(-46,26,-16,18:1)
Block(-46,26,-15,18:1)
Block(-46,26,-14,18:1)
Block(-46,26,-13,18:1)
Block(-46,26,-12,18:1)
Block(-46,26,-11,18:1)
Block(-46,26,-10,18:1)
Block(-46,26,-9,17:5)
Block(-46,26,-8,18:1)
Block(-46,26,-7,18:1)
Block(-46,26,-6,18:1)
Block(-46,26,-5,17:5)
Block(-46,26,-4,18:1)
Block(-46,26,-3,18:1)
Block(-46,26,-2,17:9)
Block(-46,26,-1,17:5)
Block(-46,26,0,17:5)
Block(-46,26,1,17:5)
Block(-46,26,2,18:1)
Block(-46,26,3,18:1)
Block(-46,26,4,18:1)
Block(-46,26,5,18:1)
Block(-46,26,6,18:1)
Block(-46,26,7,17:5)
Block(-46,26,8,18:1)
Block(-46,26,10,18:1)
Block(-46,26,11,18:1)
Block(-46,26,12,17:5)
Block(-46,26,13,18:1)
Block(-46,26,14,18:1)
Block(-46,26,16,18:1)
Block(-46,26,17,18:1)
Block(-46,26,19,18:1)
Block(-46,26,20,18:1)
Block(-46,26,21,18:1)
Block(-46,26,22,18:1)
Block(-46,26,23,18:1)
Block(-46,27,-22,18:1)
Block(-46,27,-21,18:1)
Block(-46,27,-19,18:1)
Block(-46,27,-17,18:1)
Block(-46,27,-16,18:1)
Block(-46,27,-15,18:1)
Block(-46,27,-13,18:1)
Block(-46,27,-12,18:1)
Block(-46,27,-11,18:1)
Block(-46,27,-10,18:1)
Block(-46,27,-9,18:1)
Block(-46,27,-8,18:1)
Block(-46,27,-6,18:1)
Block(-46,27,-5,18:1)
Block(-46,27,-4,18:1)
Block(-46,27,-3,18:1)
Block(-46,27,-2,18:1)
Block(-46,27,-1,18:1)
Block(-46,27,0,17:5)
Block(-46,27,1,18:1)
Block(-46,27,3,18:1)
Block(-46,27,5,18:1)
Block(-46,27,7,18:1)
Block(-46,27,10,18:1)
Block(-46,27,12,18:1)
Block(-46,27,13,18:1)
Block(-46,27,14,18:1)
Block(-46,27,15,18:1)
Block(-46,27,16,18:1)
Block(-46,27,18,18:1)
Block(-46,27,19,18:1)
Block(-46,27,20,18:1)
Block(-46,27,23,18:1)
Block(-46,28,-21,18:1)
Block(-46,28,-20,18:1)
Block(-46,28,-19,18:1)
Block(-46,28,-18,18:1)
Block(-46,28,-17,18:1)
Block(-46,28,-16,18:1)
Block(-46,28,-15,18:1)
Block(-46,28,-14,18:1)
Block(-46,28,-9,18:1)
Block(-46,28,-8,18:1)
Block(-46,28,-7,18:1)
Block(-46,28,-6,18:1)
Block(-46,28,-5,18:1)
Block(-46,28,-4,18:1)
Block(-46,28,-3,18:1)
Block(-46,28,0,18:1)
Block(-46,28,1,18:1)
Block(-46,28,2,18:1)
Block(-46,28,20,18:1)
Block(-46,28,22,18:1)
Block(-46,29,-20,18:1)
Block(-46,29,-19,18:1)
Block(-46,29,-18,18:1)
Block(-46,29,-5,18:1)
Block(-46,29,-4,18:1)
Block(-46,29,0,18:1)
Block(-46,29,20,18:1)
Block(-45,22,-1,18:1)
Block(-45,22,0,18:1)
Block(-45,22,1,18:1)
Block(-45,22,2,18:1)
Block(-45,23,-26,18:1)
Block(-45,23,-25,18:1)
Block(-45,23,-19,18:1)
Block(-45,23,-15,18:1)
Block(-45,23,-14,18:1)
Block(-45,23,-13,18:1)
Block(-45,23,-9,18:1)
Block(-45,23,-6,18:1)
Block(-45,23,-5,18:1)
Block(-45,23,-4,18:1)
Block(-45,23,1,18:1)
Block(-45,23,3,18:1)
Block(-45,23,4,18:1)
Block(-45,23,21,18:1)
Block(-45,23,22,18:1)
Block(-45,24,-28,18:1)
Block(-45,24,-26,18:1)
Block(-45,24,-25,18:1)
Block(-45,24,-21,18:1)
Block(-45,24,-19,18:1)
Block(-45,24,-17,18:1)
Block(-45,24,-16,18:1)
Block(-45,24,-15,18:1)
Block(-45,24,-14,18:1)
Block(-45,24,-13,18:1)
Block(-45,24,-12,18:1)
Block(-45,24,-11,18:1)
Block(-45,24,-10,18:1)
Block(-45,24,-8,18:1)
Block(-45,24,-7,18:1)
Block(-45,24,-6,18:1)
Block(-45,24,-5,18:1)
Block(-45,24,-3,18:1)
Block(-45,24,-2,18:1)
Block(-45,24,-1,18:1)
Block(-45,24,0,17:5)
Block(-45,24,1,18:1)
Block(-45,24,5,18:1)
Block(-45,24,6,18:1)
Block(-45,24,7,18:1)
Block(-45,24,8,18:1)
Block(-45,24,9,18:1)
Block(-45,24,10,18:1)
Block(-45,24,12,18:1)
Block(-45,24,14,18:1)
Block(-45,24,15,18:1)
Block(-45,24,16,18:1)
Block(-45,24,17,18:1)
Block(-45,24,18,18:1)
Block(-45,24,19,18:1)
Block(-45,24,20,18:1)
Block(-45,24,21,18:1)
Block(-45,24,22,18:1)
Block(-45,24,23,18:1)
Block(-45,24,28,18:1)
Block(-45,25,-27,18:1)
Block(-45,25,-26,18:1)
Block(-45,25,-25,18:1)
Block(-45,25,-23,18:1)
Block(-45,25,-21,18:1)
Block(-45,25,-20,18:1)
Block(-45,25,-18,18:1)
Block(-45,25,-17,18:1)
Block(-45,25,-16,18:1)
Block(-45,25,-15,18:1)
Block(-45,25,-14,18:1)
Block(-45,25,-13,18:1)
Block(-45,25,-12,18:1)
Block(-45,25,-11,18:1)
Block(-45,25,-10,18:1)
Block(-45,25,-9,18:1)
Block(-45,25,-7,18:1)
Block(-45,25,-6,18:1)
Block(-45,25,-5,18:1)
Block(-45,25,-4,18:1)
Block(-45,25,-3,18:1)
Block(-45,25,-2,18:1)
Block(-45,25,-1,17:5)
Block(-45,25,0,17:5)
Block(-45,25,1,17:5)
Block(-45,25,4,18:1)
Block(-45,25,5,18:1)
Block(-45,25,7,18:1)
Block(-45,25,9,18:1)
Block(-45,25,10,18:1)
Block(-45,25,11,18:1)
Block(-45,25,12,18:1)
Block(-45,25,15,18:1)
Block(-45,25,16,18:1)
Block(-45,25,17,18:1)
Block(-45,25,18,18:1)
Block(-45,25,19,18:1)
Block(-45,25,21,18:1)
Block(-45,25,22,18:1)
Block(-45,25,23,18:1)
Block(-45,25,24,18:1)
Block(-45,25,27,18:1)
Block(-45,25,28,18:1)
Block(-45,25,29,18:1)
Block(-45,26,-27,18:1)
Block(-45,26,-24,18:1)
Block(-45,26,-23,18:1)
Block(-45,26,-22,18:1)
Block(-45,26,-21,18:1)
Block(-45,26,-20,18:1)
Block(-45,26,-19,17:5)
Block(-45,26,-17,18:1)
Block(-45,26,-16,18:1)
Block(-45,26,-15,18:1)
Block(-45,26,-14,17:5)
Block(-45,26,-13,18:1)
Block(-45,26,-12,18:1)
Block(-45,26,-11,18:1)
Block(-45,26,-10,18:1)
Block(-45,26,-9,17:5)
Block(-45,26,-8,18:1)
Block(-45,26,-7,18:1)
Block(-45,26,-5,17:5)
Block(-45,26,-4,18:1)
Block(-45,26,-3,18:1)
Block(-45,26,-2,18:1)
Block(-45,26,-1,17:5)
Block(-45,26,0,17:5)
Block(-45,26,1,17:5)
Block(-45,26,2,18:1)
Block(-45,26,3,18:1)
Block(-45,26,4,18:1)
Block(-45,26,5,18:1)
Block(-45,26,7,17:5)
Block(-45,26,10,18:1)
Block(-45,26,11,18:1)
Block(-45,26,12,17:5)
Block(-45,26,13,18:1)
Block(-45,26,14,18:1)
Block(-45,26,15,18:1)
Block(-45,26,16,17:5)
Block(-45,26,18,18:1)
Block(-45,26,19,18:1)
Block(-45,26,20,17:5)
Block(-45,26,21,17:9)
Block(-45,26,22,18:1)
Block(-45,26,23,18:1)
Block(-45,26,24,18:1)
Block(-45,26,27,18:1)
Block(-45,26,28,18:1)
Block(-45,27,-26,18:1)
Block(-45,27,-19,18:1)
Block(-45,27,-17,18:1)
Block(-45,27,-16,18:1)
Block(-45,27,-14,18:1)
Block(-45,27,-13,18:1)
Block(-45,27,-12,18:1)
Block(-45,27,-11,18:1)
Block(-45,27,-10,18:1)
Block(-45,27,-8,18:1)
Block(-45,27,-6,18:1)
Block(-45,27,-5,18:1)
Block(-45,27,-4,18:1)
Block(-45,27,-2,18:1)
Block(-45,27,-1,18:1)
Block(-45,27,0,17:5)
Block(-45,27,2,18:1)
Block(-45,27,3,18:1)
Block(-45,27,4,18:1)
Block(-45,27,5,18:1)
Block(-45,27,7,18:1)
Block(-45,27,9,18:1)
Block(-45,27,10,18:1)
Block(-45,27,12,18:1)
Block(-45,27,13,18:1)
Block(-45,27,14,18:1)
Block(-45,27,15,18:1)
Block(-45,27,16,18:1)
Block(-45,27,17,18:1)
Block(-45,27,18,18:1)
Block(-45,27,19,18:1)
Block(-45,27,20,18:1)
Block(-45,27,21,18:1)
Block(-45,27,22,18:1)
Block(-45,27,23,18:1)
Block(-45,27,24,18:1)
Block(-45,28,-23,18:1)
Block(-45,28,-22,18:1)
Block(-45,28,-20,18:1)
Block(-45,28,-17,18:1)
Block(-45,28,-16,18:1)
Block(-45,28,-15,18:1)
Block(-45,28,-14,18:1)
Block(-45,28,-13,18:1)
Block(-45,28,-12,18:1)
Block(-45,28,-11,18:1)
Block(-45,28,-10,18:1)
Block(-45,28,-9,18:1)
Block(-45,28,-8,18:1)
Block(-45,28,-7,18:1)
Block(-45,28,-5,18:1)
Block(-45,28,-3,18:1)
Block(-45,28,-2,18:1)
Block(-45,28,-1,18:1)
Block(-45,28,2,18:1)
Block(-45,28,3,18:1)
Block(-45,28,7,18:1)
Block(-45,28,12,18:1)
Block(-45,28,14,18:1)
Block(-45,28,15,18:1)
Block(-45,28,19,18:1)
Block(-45,28,20,18:1)
Block(-45,28,22,18:1)
Block(-45,29,-19,18:1)
Block(-45,29,-15,18:1)
Block(-45,29,-6,18:1)
Block(-45,29,-5,18:1)
Block(-45,29,-4,18:1)
Block(-45,29,0,18:1)
Block(-45,29,20,18:1)
Block(-45,29,21,18:1)
Block(-45,29,22,18:1)
Block(-45,30,-1,18:1)
Block(-45,30,0,18:1)
Block(-44,22,-26,18:1)
Block(-44,22,-25,18:1)
Block(-44,22,4,18:1)
Block(-44,23,-28,18:1)
Block(-44,23,-24,18:1)
Block(-44,23,-22,18:1)
Block(-44,23,-16,18:1)
Block(-44,23,-14,18:1)
Block(-44,23,-12,18:1)
Block(-44,23,-11,18:1)
Block(-44,23,0,18:1)
Block(-44,23,1,18:1)
Block(-44,23,2,18:1)
Block(-44,23,5,18:1)
Block(-44,23,6,18:1)
Block(-44,23,8,18:1)
Block(-44,23,16,18:1)
Block(-44,23,19,18:1)
Block(-44,23,20,18:1)
Block(-44,23,21,18:1)
Block(-44,23,27,18:1)
Block(-44,23,28,18:1)
Block(-44,23,29,18:1)
Block(-44,23,30,18:1)
Block(-44,24,-29,18:1)
Block(-44,24,-23,18:1)
Block(-44,24,-22,18:1)
Block(-44,24,-21,18:1)
Block(-44,24,-20,18:1)
Block(-44,24,-19,18:1)
Block(-44,24,-17,18:1)
Block(-44,24,-16,18:1)
Block(-44,24,-14,18:1)
Block(-44,24,-13,18:1)
Block(-44,24,-12,18:1)
Block(-44,24,-11,18:1)
Block(-44,24,-10,18:1)
Block(-44,24,-9,18:1)
Block(-44,24,-7,18:1)
Block(-44,24,-6,18:1)
Block(-44,24,-4,18:1)
Block(-44,24,-1,18:1)
Block(-44,24,0,18:1)
Block(-44,24,1,18:1)
Block(-44,24,4,18:1)
Block(-44,24,5,18:1)
Block(-44,24,7,18:1)
Block(-44,24,9,18:1)
Block(-44,24,14,18:1)
Block(-44,24,16,18:1)
Block(-44,24,18,18:1)
Block(-44,24,19,18:1)
Block(-44,24,23,18:1)
Block(-44,24,29,18:1)
Block(-44,24,30,18:1)
Block(-44,25,-29,18:1)
Block(-44,25,-28,18:1)
Block(-44,25,-26,18:1)
Block(-44,25,-25,18:1)
Block(-44,25,-23,18:1)
Block(-44,25,-22,18:1)
Block(-44,25,-21,18:1)
Block(-44,25,-20,18:1)
Block(-44,25,-19,18:1)
Block(-44,25,-18,18:1)
Block(-44,25,-17,18:1)
Block(-44,25,-15,18:1)
Block(-44,25,-13,18:1)
Block(-44,25,-12,18:1)
Block(-44,25,-11,18:1)
Block(-44,25,-10,18:1)
Block(-44,25,-9,18:1)
Block(-44,25,-8,18:1)
Block(-44,25,-7,18:1)
Block(-44,25,-6,18:1)
Block(-44,25,-5,18:1)
Block(-44,25,-4,18:1)
Block(-44,25,-3,18:1)
Block(-44,25,-2,18:1)
Block(-44,25,-1,17:5)
Block(-44,25,0,17:5)
Block(-44,25,1,17:5)
Block(-44,25,2,18:1)
Block(-44,25,4,18:1)
Block(-44,25,5,18:1)
Block(-44,25,7,18:1)
Block(-44,25,8,18:1)
Block(-44,25,10,18:1)
Block(-44,25,15,18:1)
Block(-44,25,17,18:1)
Block(-44,25,19,18:1)
Block(-44,25,20,18:1)
Block(-44,25,21,18:1)
Block(-44,25,24,18:1)
Block(-44,25,26,18:1)
Block(-44,25,27,18:1)
Block(-44,25,28,18:1)
Block(-44,25,30,18:1)
Block(-44,26,-29,18:1)
Block(-44,26,-26,18:1)
Block(-44,26,-24,18:1)
Block(-44,26,-23,18:1)
Block(-44,26,-22,18:1)
Block(-44,26,-21,18:1)
Block(-44,26,-19,17:5)
Block(-44,26,-18,18:1)
Block(-44,26,-17,18:1)
Block(-44,26,-16,18:1)
Block(-44,26,-15,18:1)
Block(-44,26,-14,17:5)
Block(-44,26,-13,18:1)
Block(-44,26,-12,18:1)
Block(-44,26,-11,17:5)
Block(-44,26,-10,18:1)
Block(-44,26,-9,17:5)
Block(-44,26,-8,18:1)
Block(-44,26,-7,18:1)
Block(-44,26,-6,18:1)
Block(-44,26,-5,17:5)
Block(-44,26,-4,18:1)
Block(-44,26,-3,18:1)
Block(-44,26,-2,18:1)
Block(-44,26,-1,17:5)
Block(-44,26,0,17:5)
Block(-44,26,1,17:5)
Block(-44,26,2,18:1)
Block(-44,26,4,18:1)
Block(-44,26,5,17:5)
Block(-44,26,6,18:1)
Block(-44,26,7,17:5)
Block(-44,26,10,18:1)
Block(-44,26,12,17:5)
Block(-44,26,13,18:1)
Block(-44,26,14,18:1)
Block(-44,26,15,18:1)
Block(-44,26,16,17:5)
Block(-44,26,17,18:1)
Block(-44,26,18,18:1)
Block(-44,26,19,18:1)
Block(-44,26,20,17:5)
Block(-44,26,21,18:1)
Block(-44,26,23,18:1)
Block(-44,26,24,18:1)
Block(-44,26,28,18:1)
Block(-44,26,29,18:1)
Block(-44,27,-26,18:1)
Block(-44,27,-22,18:1)
Block(-44,27,-21,18:1)
Block(-44,27,-20,18:1)
Block(-44,27,-18,18:1)
Block(-44,27,-17,18:1)
Block(-44,27,-16,18:1)
Block(-44,27,-15,18:1)
Block(-44,27,-14,18:1)
Block(-44,27,-12,18:1)
Block(-44,27,-11,18:1)
Block(-44,27,-10,18:1)
Block(-44,27,-9,18:1)
Block(-44,27,-8,18:1)
Block(-44,27,-7,18:1)
Block(-44,27,-6,18:1)
Block(-44,27,-5,18:1)
Block(-44,27,-3,18:1)
Block(-44,27,-1,18:1)
Block(-44,27,0,17:5)
Block(-44,27,1,18:1)
Block(-44,27,2,18:1)
Block(-44,27,3,18:1)
Block(-44,27,5,18:1)
Block(-44,27,6,18:1)
Block(-44,27,7,18:1)
Block(-44,27,10,18:1)
Block(-44,27,13,18:1)
Block(-44,27,15,18:1)
Block(-44,27,16,18:1)
Block(-44,27,17,18:1)
Block(-44,27,18,18:1)
Block(-44,27,19,18:1)
Block(-44,27,20,18:1)
Block(-44,27,21,18:1)
Block(-44,27,22,18:1)
Block(-44,27,29,18:1)
Block(-44,28,-22,18:1)
Block(-44,28,-20,18:1)
Block(-44,28,-19,18:1)
Block(-44,28,-18,18:1)
Block(-44,28,-17,18:1)
Block(-44,28,-13,18:1)
Block(-44,28,-11,18:1)
Block(-44,28,-10,18:1)
Block(-44,28,-8,18:1)
Block(-44,28,-7,18:1)
Block(-44,28,-6,18:1)
Block(-44,28,-5,18:1)
Block(-44,28,-4,18:1)
Block(-44,28,-3,18:1)
Block(-44,28,2,18:1)
Block(-44,28,3,18:1)
Block(-44,28,5,18:1)
Block(-44,28,6,18:1)
Block(-44,28,11,18:1)
Block(-44,28,14,18:1)
Block(-44,28,15,18:1)
Block(-44,28,16,18:1)
Block(-44,28,17,18:1)
Block(-44,28,18,18:1)
Block(-44,28,19,18:1)
Block(-44,28,20,18:1)
Block(-44,28,21,18:1)
Block(-44,28,22,18:1)
Block(-44,28,23,18:1)
Block(-44,29,-21,18:1)
Block(-44,29,-12,18:1)
Block(-44,29,-2,18:1)
Block(-44,29,-1,18:1)
Block(-44,29,0,18:1)
Block(-44,29,1,18:1)
Block(-44,29,8,18:1)
Block(-44,29,12,18:1)
Block(-44,29,16,18:1)
Block(-44,29,20,18:1)
Block(-44,29,21,18:1)
Block(-44,30,-1,18:1)
Block(-44,30,0,18:1)
Block(-43,22,-27,18:1)
Block(-43,22,-26,18:1)
Block(-43,22,-25,18:1)
Block(-43,22,28,18:1)
Block(-43,22,29,18:1)
Block(-43,23,-27,18:1)
Block(-43,23,-26,18:1)
Block(-43,23,-24,18:1)
Block(-43,23,-22,18:1)
Block(-43,23,-21,18:1)
Block(-43,23,-16,18:1)
Block(-43,23,-15,18:1)
Block(-43,23,-14,18:1)
Block(-43,23,-11,18:1)
Block(-43,23,-10,18:1)
Block(-43,23,-3,18:1)
Block(-43,23,1,18:1)
Block(-43,23,3,18:1)
Block(-43,23,4,18:1)
Block(-43,23,5,18:1)
Block(-43,23,6,18:1)
Block(-43,23,7,18:1)
Block(-43,23,8,18:1)
Block(-43,23,11,18:1)
Block(-43,23,12,18:1)
Block(-43,23,13,18:1)
Block(-43,23,16,18:1)
Block(-43,23,17,18:1)
Block(-43,23,19,18:1)
Block(-43,23,20,18:1)
Block(-43,24,-32,18:1)
Block(-43,24,-31,18:1)
Block(-43,24,-28,18:1)
Block(-43,24,-27,18:1)
Block(-43,24,-26,18:1)
Block(-43,24,-25,18:1)
Block(-43,24,-21,18:1)
Block(-43,24,-20,18:1)
Block(-43,24,-19,18:1)
Block(-43,24,-17,18:1)
Block(-43,24,-16,18:1)
Block(-43,24,-14,18:1)
Block(-43,24,-13,18:1)
Block(-43,24,-12,18:1)
Block(-43,24,-10,18:1)
Block(-43,24,-8,18:1)
Block(-43,24,-5,18:1)
Block(-43,24,-4,18:1)
Block(-43,24,-3,18:1)
Block(-43,24,-2,18:1)
Block(-43,24,-1,18:1)
Block(-43,24,0,18:1)
Block(-43,24,1,18:1)
Block(-43,24,3,18:1)
Block(-43,24,4,18:1)
Block(-43,24,5,18:1)
Block(-43,24,6,18:1)
Block(-43,24,7,18:1)
Block(-43,24,11,18:1)
Block(-43,24,12,18:1)
Block(-43,24,13,18:1)
Block(-43,24,14,18:1)
Block(-43,24,15,18:1)
Block(-43,24,16,18:1)
Block(-43,24,17,18:1)
Block(-43,24,18,18:1)
Block(-43,24,19,18:1)
Block(-43,24,20,18:1)
Block(-43,24,21,18:1)
Block(-43,24,22,18:1)
Block(-43,24,23,18:1)
Block(-43,24,25,18:1)
Block(-43,24,26,18:1)
Block(-43,24,27,18:1)
Block(-43,24,28,18:1)
Block(-43,24,30,18:1)
Block(-43,25,-32,18:1)
Block(-43,25,-31,18:1)
Block(-43,25,-30,18:1)
Block(-43,25,-29,18:1)
Block(-43,25,-28,18:1)
Block(-43,25,-27,18:1)
Block(-43,25,-26,17:5)
Block(-43,25,-25,18:1)
Block(-43,25,-24,18:1)
Block(-43,25,-23,18:1)
Block(-43,25,-22,18:1)
Block(-43,25,-20,18:1)
Block(-43,25,-19,18:1)
Block(-43,25,-18,18:1)
Block(-43,25,-17,18:1)
Block(-43,25,-15,18:1)
Block(-43,25,-14,18:1)
Block(-43,25,-13,18:1)
Block(-43,25,-12,18:1)
Block(-43,25,-11,18:1)
Block(-43,25,-10,18:1)
Block(-43,25,-9,18:1)
Block(-43,25,-8,18:1)
Block(-43,25,-7,17:9)
Block(-43,25,-6,17:9)
Block(-43,25,-5,17:9)
Block(-43,25,-4,17:9)
Block(-43,25,-3,17:9)
Block(-43,25,-2,17:9)
Block(-43,25,-1,17:5)
Block(-43,25,0,17:5)
Block(-43,25,1,17:5)
Block(-43,25,2,17:9)
Block(-43,25,3,17:9)
Block(-43,25,4,17:9)
Block(-43,25,5,17:9)
Block(-43,25,6,17:9)
Block(-43,25,7,17:9)
Block(-43,25,9,18:1)
Block(-43,25,10,18:1)
Block(-43,25,13,18:1)
Block(-43,25,14,18:1)
Block(-43,25,15,18:1)
Block(-43,25,16,18:1)
Block(-43,25,17,18:1)
Block(-43,25,18,18:1)
Block(-43,25,19,18:1)
Block(-43,25,20,18:1)
Block(-43,25,21,18:1)
Block(-43,25,22,18:1)
Block(-43,25,23,18:1)
Block(-43,25,24,18:1)
Block(-43,25,25,17:5)
Block(-43,25,26,18:1)
Block(-43,25,28,18:1)
Block(-43,25,31,18:1)
Block(-43,26,-31,18:1)
Block(-43,26,-27,18:1)
Block(-43,26,-26,18:1)
Block(-43,26,-24,18:1)
Block(-43,26,-23,18:1)
Block(-43,26,-21,17:9)
Block(-43,26,-20,17:9)
Block(-43,26,-19,17:9)
Block(-43,26,-18,17:9)
Block(-43,26,-17,17:9)
Block(-43,26,-16,17:9)
Block(-43,26,-15,17:9)
Block(-43,26,-14,17:9)
Block(-43,26,-13,17:9)
Block(-43,26,-12,17:9)
Block(-43,26,-11,17:9)
Block(-43,26,-10,17:9)
Block(-43,26,-9,17:9)
Block(-43,26,-8,17:9)
Block(-43,26,-7,17:9)
Block(-43,26,-6,17:9)
Block(-43,26,-5,17:9)
Block(-43,26,-4,17:9)
Block(-43,26,-3,17:9)
Block(-43,26,-2,17:9)
Block(-43,26,-1,17:5)
Block(-43,26,0,17:5)
Block(-43,26,1,17:5)
Block(-43,26,2,17:9)
Block(-43,26,3,17:9)
Block(-43,26,4,17:9)
Block(-43,26,5,17:9)
Block(-43,26,6,17:9)
Block(-43,26,7,17:9)
Block(-43,26,8,17:9)
Block(-43,26,9,17:9)
Block(-43,26,10,17:9)
Block(-43,26,11,17:9)
Block(-43,26,12,17:9)
Block(-43,26,13,17:9)
Block(-43,26,14,17:9)
Block(-43,26,15,17:9)
Block(-43,26,16,17:9)
Block(-43,26,17,17:9)
Block(-43,26,18,17:9)
Block(-43,26,19,17:9)
Block(-43,26,20,17:9)
Block(-43,26,21,18:1)
Block(-43,26,22,18:1)
Block(-43,26,23,18:1)
Block(-43,26,25,18:1)
Block(-43,26,26,18:1)
Block(-43,26,29,18:1)
Block(-43,27,-24,18:1)
Block(-43,27,-22,18:1)
Block(-43,27,-21,18:1)
Block(-43,27,-20,18:1)
Block(-43,27,-19,18:1)
Block(-43,27,-18,18:1)
Block(-43,27,-17,18:1)
Block(-43,27,-16,18:1)
Block(-43,27,-15,18:1)
Block(-43,27,-14,18:1)
Block(-43,27,-13,18:1)
Block(-43,27,-12,18:1)
Block(-43,27,-11,18:1)
Block(-43,27,-10,18:1)
Block(-43,27,-9,18:1)
Block(-43,27,-8,18:1)
Block(-43,27,-6,18:1)
Block(-43,27,-5,18:1)
Block(-43,27,-4,18:1)
Block(-43,27,-3,18:1)
Block(-43,27,-2,18:1)
Block(-43,27,-1,17:5)
Block(-43,27,0,17:5)
Block(-43,27,1,17:5)
Block(-43,27,2,18:1)
Block(-43,27,3,18:1)
Block(-43,27,4,18:1)
Block(-43,27,5,18:1)
Block(-43,27,6,18:1)
Block(-43,27,7,18:1)
Block(-43,27,9,18:1)
Block(-43,27,11,18:1)
Block(-43,27,12,18:1)
Block(-43,27,13,18:1)
Block(-43,27,14,18:1)
Block(-43,27,15,18:1)
Block(-43,27,17,18:1)
Block(-43,27,18,18:1)
Block(-43,27,19,18:1)
Block(-43,27,21,18:1)
Block(-43,27,27,18:1)
Block(-43,27,29,18:1)
Block(-43,28,-26,18:1)
Block(-43,28,-25,18:1)
Block(-43,28,-23,18:1)
Block(-43,28,-22,18:1)
Block(-43,28,-19,18:1)
Block(-43,28,-18,18:1)
Block(-43,28,-17,18:1)
Block(-43,28,-14,18:1)
Block(-43,28,-13,18:1)
Block(-43,28,-11,18:1)
Block(-43,28,-9,18:1)
Block(-43,28,-8,18:1)
Block(-43,28,-6,18:1)
Block(-43,28,-4,18:1)
Block(-43,28,-3,18:1)
Block(-43,28,-2,18:1)
Block(-43,28,-1,18:1)
Block(-43,28,0,18:1)
Block(-43,28,2,18:1)
Block(-43,28,3,18:1)
Block(-43,28,4,18:1)
Block(-43,28,5,18:1)
Block(-43,28,7,18:1)
Block(-43,28,8,18:1)
Block(-43,28,12,18:1)
Block(-43,28,14,18:1)
Block(-43,28,16,18:1)
Block(-43,28,17,18:1)
Block(-43,28,18,18:1)
Block(-43,28,19,18:1)
Block(-43,28,20,18:1)
Block(-43,28,22,18:1)
Block(-43,28,28,18:1)
Block(-43,29,-22,18:1)
Block(-43,29,-20,18:1)
Block(-43,29,-16,18:1)
Block(-43,29,-15,18:1)
Block(-43,29,-11,18:1)
Block(-43,29,-3,18:1)
Block(-43,29,-2,18:1)
Block(-43,29,6,18:1)
Block(-43,29,7,18:1)
Block(-43,29,12,18:1)
Block(-43,29,15,18:1)
Block(-43,29,16,18:1)
Block(-43,29,17,18:1)
Block(-43,29,19,18:1)
Block(-43,30,-2,18:1)
Block(-43,30,-1,18:1)
Block(-42,22,-36,18:1)
Block(-42,22,-34,18:1)
Block(-42,22,-33,18:1)
Block(-42,22,28,18:1)
Block(-42,22,29,18:1)
Block(-42,22,32,18:1)
Block(-42,22,33,18:1)
Block(-42,23,-35,18:1)
Block(-42,23,-34,18:1)
Block(-42,23,-33,18:1)
Block(-42,23,-31,18:1)
Block(-42,23,-27,18:1)
Block(-42,23,-26,18:1)
Block(-42,23,-25,18:1)
Block(-42,23,-21,18:1)
Block(-42,23,-19,18:1)
Block(-42,23,-17,18:1)
Block(-42,23,-11,18:1)
Block(-42,23,-9,18:1)
Block(-42,23,-8,18:1)
Block(-42,23,-3,18:1)
Block(-42,23,3,18:1)
Block(-42,23,7,18:1)
Block(-42,23,8,18:1)
Block(-42,23,11,18:1)
Block(-42,23,13,18:1)
Block(-42,23,16,18:1)
Block(-42,23,17,18:1)
Block(-42,23,20,18:1)
Block(-42,23,23,18:1)
Block(-42,23,25,18:1)
Block(-42,23,26,18:1)
Block(-42,23,27,18:1)
Block(-42,23,28,18:1)
Block(-42,23,29,18:1)
Block(-42,23,30,18:1)
Block(-42,23,31,18:1)
Block(-42,23,32,18:1)
Block(-42,23,33,18:1)
Block(-42,23,34,18:1)
Block(-42,24,-36,18:1)
Block(-42,24,-35,18:1)
Block(-42,24,-33,18:1)
Block(-42,24,-32,18:1)
Block(-42,24,-31,18:1)
Block(-42,24,-29,18:1)
Block(-42,24,-28,18:1)
Block(-42,24,-27,18:1)
Block(-42,24,-26,18:1)
Block(-42,24,-25,18:1)
Block(-42,24,-24,18:1)
Block(-42,24,-23,18:1)
Block(-42,24,-21,18:1)
Block(-42,24,-18,18:1)
Block(-42,24,-17,18:1)
Block(-42,24,-16,18:1)
Block(-42,24,-15,18:1)
Block(-42,24,-13,18:1)
Block(-42,24,-11,18:1)
Block(-42,24,-9,18:1)
Block(-42,24,-5,18:1)
Block(-42,24,-4,18:1)
Block(-42,24,-2,18:1)
Block(-42,24,0,18:1)
Block(-42,24,5,18:1)
Block(-42,24,8,18:1)
Block(-42,24,13,18:1)
Block(-42,24,14,18:1)
Block(-42,24,20,18:1)
Block(-42,24,21,18:1)
Block(-42,24,22,18:1)
Block(-42,24,24,18:1)
Block(-42,24,25,18:1)
Block(-42,24,26,18:1)
Block(-42,24,27,18:1)
Block(-42,24,29,18:1)
Block(-42,24,30,18:1)
Block(-42,24,31,18:1)
Block(-42,24,32,18:1)
Block(-42,24,33,18:1)
Block(-42,25,-33,18:1)
Block(-42,25,-31,18:1)
Block(-42,25,-30,18:1)
Block(-42,25,-29,17:5)
Block(-42,25,-28,18:1)
Block(-42,25,-27,18:1)
Block(-42,25,-26,17:5)
Block(-42,25,-25,18:1)
Block(-42,25,-24,18:1)
Block(-42,25,-21,18:1)
Block(-42,25,-20,18:1)
Block(-42,25,-18,18:1)
Block(-42,25,-17,18:1)
Block(-42,25,-16,18:1)
Block(-42,25,-15,18:1)
Block(-42,25,-14,18:1)
Block(-42,25,-13,18:1)
Block(-42,25,-11,18:1)
Block(-42,25,-8,18:1)
Block(-42,25,-7,18:1)
Block(-42,25,-6,18:1)
Block(-42,25,-5,18:1)
Block(-42,25,-4,18:1)
Block(-42,25,-3,18:1)
Block(-42,25,-2,18:1)
Block(-42,25,-1,18:1)
Block(-42,25,0,17:5)
Block(-42,25,1,18:1)
Block(-42,25,2,18:1)
Block(-42,25,3,18:1)
Block(-42,25,4,18:1)
Block(-42,25,5,18:1)
Block(-42,25,6,18:1)
Block(-42,25,7,18:1)
Block(-42,25,8,18:1)
Block(-42,25,9,18:1)
Block(-42,25,10,18:1)
Block(-42,25,16,18:1)
Block(-42,25,17,18:1)
Block(-42,25,18,18:1)
Block(-42,25,19,18:1)
Block(-42,25,20,18:1)
Block(-42,25,21,18:1)
Block(-42,25,23,18:1)
Block(-42,25,25,17:5)
Block(-42,25,26,18:1)
Block(-42,25,27,18:1)
Block(-42,25,28,17:5)
Block(-42,25,29,18:1)
Block(-42,25,30,18:1)
Block(-42,25,31,18:1)
Block(-42,26,-31,18:1)
Block(-42,26,-29,18:1)
Block(-42,26,-27,18:1)
Block(-42,26,-25,18:1)
Block(-42,26,-24,18:1)
Block(-42,26,-21,18:1)
Block(-42,26,-20,18:1)
Block(-42,26,-19,18:1)
Block(-42,26,-18,17:5)
Block(-42,26,-17,18:1)
Block(-42,26,-16,18:1)
Block(-42,26,-15,18:1)
Block(-42,26,-14,17:5)
Block(-42,26,-13,18:1)
Block(-42,26,-12,18:1)
Block(-42,26,-11,17:5)
Block(-42,26,-8,17:5)
Block(-42,26,-7,18:1)
Block(-42,26,-6,18:1)
Block(-42,26,-5,18:1)
Block(-42,26,-4,17:5)
Block(-42,26,-3,17:5)
Block(-42,26,-2,18:1)
Block(-42,26,-1,17:5)
Block(-42,26,0,17:5)
Block(-42,26,1,17:5)
Block(-42,26,2,18:1)
Block(-42,26,4,18:1)
Block(-42,26,5,18:1)
Block(-42,26,6,18:1)
Block(-42,26,7,18:1)
Block(-42,26,9,18:1)
Block(-42,26,10,18:1)
Block(-42,26,11,18:1)
Block(-42,26,12,18:1)
Block(-42,26,13,18:1)
Block(-42,26,14,18:1)
Block(-42,26,15,17:5)
Block(-42,26,16,18:1)
Block(-42,26,17,18:1)
Block(-42,26,18,18:1)
Block(-42,26,19,18:1)
Block(-42,26,20,18:1)
Block(-42,26,21,18:1)
Block(-42,26,22,18:1)
Block(-42,26,23,18:1)
Block(-42,26,24,18:1)
Block(-42,26,26,18:1)
Block(-42,26,27,18:1)
Block(-42,26,28,18:1)
Block(-42,26,30,18:1)
Block(-42,26,31,18:1)
Block(-42,27,-31,18:1)
Block(-42,27,-30,18:1)
Block(-42,27,-29,18:1)
Block(-42,27,-27,18:1)
Block(-42,27,-25,18:1)
Block(-42,27,-23,18:1)
Block(-42,27,-21,18:1)
Block(-42,27,-18,18:1)
Block(-42,27,-17,18:1)
Block(-42,27,-16,18:1)
Block(-42,27,-15,18:1)
Block(-42,27,-14,18:1)
Block(-42,27,-13,18:1)
Block(-42,27,-12,18:1)
Block(-42,27,-11,18:1)
Block(-42,27,-9,18:1)
Block(-42,27,-8,18:1)
Block(-42,27,-7,18:1)
Block(-42,27,-6,18:1)
Block(-42,27,-5,18:1)
Block(-42,27,-4,18:1)
Block(-42,27,-3,18:1)
Block(-42,27,-2,18:1)
Block(-42,27,-1,17:5)
Block(-42,27,0,17:5)
Block(-42,27,1,17:5)
Block(-42,27,2,18:1)
Block(-42,27,4,18:1)
Block(-42,27,5,18:1)
Block(-42,27,6,18:1)
Block(-42,27,7,18:1)
Block(-42,27,9,18:1)
Block(-42,27,10,18:1)
Block(-42,27,11,18:1)
Block(-42,27,12,18:1)
Block(-42,27,13,18:1)
Block(-42,27,14,18:1)
Block(-42,27,15,18:1)
Block(-42,27,16,18:1)
Block(-42,27,17,18:1)
Block(-42,27,18,18:1)
Block(-42,27,19,18:1)
Block(-42,27,20,18:1)
Block(-42,27,21,18:1)
Block(-42,27,22,18:1)
Block(-42,27,23,18:1)
Block(-42,27,25,18:1)
Block(-42,27,26,18:1)
Block(-42,27,27,18:1)
Block(-42,27,28,18:1)
Block(-42,27,30,18:1)
Block(-42,28,-26,18:1)
Block(-42,28,-25,18:1)
Block(-42,28,-19,18:1)
Block(-42,28,-18,18:1)
Block(-42,28,-17,18:1)
Block(-42,28,-16,18:1)
Block(-42,28,-14,18:1)
Block(-42,28,-13,18:1)
Block(-42,28,-9,18:1)
Block(-42,28,-7,18:1)
Block(-42,28,-4,18:1)
Block(-42,28,-3,18:1)
Block(-42,28,-2,18:1)
Block(-42,28,-1,18:1)
Block(-42,28,0,18:1)
Block(-42,28,1,18:1)
Block(-42,28,3,18:1)
Block(-42,28,4,18:1)
Block(-42,28,7,18:1)
Block(-42,28,8,18:1)
Block(-42,28,11,18:1)
Block(-42,28,12,18:1)
Block(-42,28,13,18:1)
Block(-42,28,14,18:1)
Block(-42,28,16,18:1)
Block(-42,28,20,18:1)
Block(-42,28,21,18:1)
Block(-42,28,28,18:1)
Block(-42,28,29,18:1)
Block(-42,29,-22,18:1)
Block(-42,29,-21,18:1)
Block(-42,29,-19,18:1)
Block(-42,29,-18,18:1)
Block(-42,29,-16,18:1)
Block(-42,29,-14,18:1)
Block(-42,29,-11,18:1)
Block(-42,29,-9,18:1)
Block(-42,29,-7,18:1)
Block(-42,29,-5,18:1)
Block(-42,29,-4,18:1)
Block(-42,29,-3,18:1)
Block(-42,29,-2,18:1)
Block(-42,29,-1,18:1)
Block(-42,29,1,18:1)
Block(-42,29,2,18:1)
Block(-42,29,6,18:1)
Block(-42,29,16,18:1)
Block(-42,29,17,18:1)
Block(-42,29,21,18:1)
Block(-42,30,-2,18:1)
Block(-42,30,0,18:1)
Block(-41,21,-36,18:1)
Block(-41,21,-35,18:1)
Block(-41,21,-34,18:1)
Block(-41,21,-33,18:1)
Block(-41,21,-31,18:1)
Block(-41,21,30,18:1)
Block(-41,21,31,18:1)
Block(-41,21,32,18:1)
Block(-41,21,33,18:1)
Block(-41,22,-37,18:1)
Block(-41,22,-35,18:1)
Block(-41,22,-33,18:1)
Block(-41,22,-31,18:1)
Block(-41,22,-27,18:1)
Block(-41,22,28,18:1)
Block(-41,22,29,18:1)
Block(-41,22,32,18:1)
Block(-41,22,33,18:1)
Block(-41,22,35,18:1)
Block(-41,23,-36,18:1)
Block(-41,23,-35,18:1)
Block(-41,23,-33,17:5)
Block(-41,23,-31,18:1)
Block(-41,23,-30,18:1)
Block(-41,23,-29,18:1)
Block(-41,23,-28,18:1)
Block(-41,23,-27,18:1)
Block(-41,23,-26,18:1)
Block(-41,23,-25,18:1)
Block(-41,23,-19,18:1)
Block(-41,23,-17,18:1)
Block(-41,23,-14,18:1)
Block(-41,23,-9,18:1)
Block(-41,23,-8,18:1)
Block(-41,23,-7,18:1)
Block(-41,23,-4,18:1)
Block(-41,23,2,18:1)
Block(-41,23,3,18:1)
Block(-41,23,5,18:1)
Block(-41,23,26,18:1)
Block(-41,23,28,18:1)
Block(-41,23,29,18:1)
Block(-41,23,31,18:1)
Block(-41,23,32,18:1)
Block(-41,23,33,18:1)
Block(-41,23,35,18:1)
Block(-41,24,-35,18:1)
Block(-41,24,-33,18:1)
Block(-41,24,-32,18:1)
Block(-41,24,-31,18:1)
Block(-41,24,-30,18:1)
Block(-41,24,-28,18:1)
Block(-41,24,-27,18:1)
Block(-41,24,-26,18:1)
Block(-41,24,-25,18:1)
Block(-41,24,-24,18:1)
Block(-41,24,-23,18:1)
Block(-41,24,-22,18:1)
Block(-41,24,-21,18:1)
Block(-41,24,-19,18:1)
Block(-41,24,-18,18:1)
Block(-41,24,-15,18:1)
Block(-41,24,-14,18:1)
Block(-41,24,-12,18:1)
Block(-41,24,-9,18:1)
Block(-41,24,-6,18:1)
Block(-41,24,-1,18:1)
Block(-41,24,1,18:1)
Block(-41,24,3,18:1)
Block(-41,24,4,18:1)
Block(-41,24,5,18:1)
Block(-41,24,9,18:1)
Block(-41,24,11,18:1)
Block(-41,24,12,18:1)
Block(-41,24,15,18:1)
Block(-41,24,18,18:1)
Block(-41,24,19,18:1)
Block(-41,24,21,18:1)
Block(-41,24,22,18:1)
Block(-41,24,23,18:1)
Block(-41,24,24,18:1)
Block(-41,24,25,18:1)
Block(-41,24,26,18:1)
Block(-41,24,28,18:1)
Block(-41,24,31,18:1)
Block(-41,24,32,18:1)
Block(-41,24,33,18:1)
Block(-41,24,34,18:1)
Block(-41,24,35,18:1)
Block(-41,25,-37,18:1)
Block(-41,25,-33,18:1)
Block(-41,25,-32,18:1)
Block(-41,25,-31,18:1)
Block(-41,25,-30,18:1)
Block(-41,25,-29,17:5)
Block(-41,25,-28,18:1)
Block(-41,25,-27,18:1)
Block(-41,25,-26,17:5)
Block(-41,25,-25,18:1)
Block(-41,25,-24,18:1)
Block(-41,25,-23,18:1)
Block(-41,25,-22,18:1)
Block(-41,25,-21,18:1)
Block(-41,25,-20,18:1)
Block(-41,25,-19,18:1)
Block(-41,25,-18,18:1)
Block(-41,25,-16,18:1)
Block(-41,25,-15,18:1)
Block(-41,25,-14,18:1)
Block(-41,25,-13,18:1)
Block(-41,25,-12,18:1)
Block(-41,25,-11,18:1)
Block(-41,25,-9,18:1)
Block(-41,25,-8,18:1)
Block(-41,25,-7,18:1)
Block(-41,25,-6,18:1)
Block(-41,25,-5,18:1)
Block(-41,25,-4,18:1)
Block(-41,25,-3,18:1)
Block(-41,25,-2,18:1)
Block(-41,25,-1,18:1)
Block(-41,25,0,17:5)
Block(-41,25,1,18:1)
Block(-41,25,2,18:1)
Block(-41,25,3,18:1)
Block(-41,25,4,18:1)
Block(-41,25,5,18:1)
Block(-41,25,7,18:1)
Block(-41,25,8,18:1)
Block(-41,25,9,18:1)
Block(-41,25,10,18:1)
Block(-41,25,11,18:1)
Block(-41,25,13,18:1)
Block(-41,25,15,18:1)
Block(-41,25,16,18:1)
Block(-41,25,18,18:1)
Block(-41,25,20,18:1)
Block(-41,25,21,18:1)
Block(-41,25,22,18:1)
Block(-41,25,23,18:1)
Block(-41,25,25,17:5)
Block(-41,25,26,18:1)
Block(-41,25,27,18:1)
Block(-41,25,28,17:5)
Block(-41,25,29,17:9)
Block(-41,25,30,17:9)
Block(-41,25,31,18:1)
Block(-41,25,32,18:1)
Block(-41,25,33,18:1)
Block(-41,25,35,18:1)
Block(-41,26,-30,18:1)
Block(-41,26,-29,18:1)
Block(-41,26,-28,18:1)
Block(-41,26,-27,18:1)
Block(-41,26,-26,18:1)
Block(-41,26,-25,18:1)
Block(-41,26,-24,18:1)
Block(-41,26,-21,18:1)
Block(-41,26,-20,18:1)
Block(-41,26,-19,18:1)
Block(-41,26,-18,17:5)
Block(-41,26,-17,18:1)
Block(-41,26,-16,18:1)
Block(-41,26,-15,18:1)
Block(-41,26,-14,17:5)
Block(-41,26,-13,18:1)
Block(-41,26,-12,18:1)
Block(-41,26,-11,17:5)
Block(-41,26,-10,18:1)
Block(-41,26,-9,18:1)
Block(-41,26,-8,17:5)
Block(-41,26,-7,18:1)
Block(-41,26,-6,18:1)
Block(-41,26,-5,18:1)
Block(-41,26,-4,17:5)
Block(-41,26,-2,18:1)
Block(-41,26,-1,17:5)
Block(-41,26,0,17:5)
Block(-41,26,1,17:5)
Block(-41,26,2,18:1)
Block(-41,26,3,18:1)
Block(-41,26,4,18:1)
Block(-41,26,5,18:1)
Block(-41,26,6,18:1)
Block(-41,26,7,18:1)
Block(-41,26,8,18:1)
Block(-41,26,9,18:1)
Block(-41,26,10,18:1)
Block(-41,26,12,18:1)
Block(-41,26,13,18:1)
Block(-41,26,14,18:1)
Block(-41,26,15,17:5)
Block(-41,26,16,18:1)
Block(-41,26,17,18:1)
Block(-41,26,18,18:1)
Block(-41,26,19,18:1)
Block(-41,26,20,18:1)
Block(-41,26,21,18:1)
Block(-41,26,25,18:1)
Block(-41,26,28,18:1)
Block(-41,27,-28,18:1)
Block(-41,27,-27,18:1)
Block(-41,27,-26,18:1)
Block(-41,27,-24,18:1)
Block(-41,27,-22,18:1)
Block(-41,27,-21,18:1)
Block(-41,27,-20,18:1)
Block(-41,27,-18,18:1)
Block(-41,27,-15,18:1)
Block(-41,27,-14,18:1)
Block(-41,27,-13,18:1)
Block(-41,27,-12,18:1)
Block(-41,27,-11,18:1)
Block(-41,27,-10,18:1)
Block(-41,27,-9,18:1)
Block(-41,27,-8,18:1)
Block(-41,27,-6,18:1)
Block(-41,27,-5,18:1)
Block(-41,27,-4,18:1)
Block(-41,27,-2,18:1)
Block(-41,27,-1,17:5)
Block(-41,27,0,17:5)
Block(-41,27,1,17:5)
Block(-41,27,2,18:1)
Block(-41,27,3,18:1)
Block(-41,27,4,18:1)
Block(-41,27,6,18:1)
Block(-41,27,7,18:1)
Block(-41,27,8,17:5)
Block(-41,27,9,18:1)
Block(-41,27,11,18:1)
Block(-41,27,12,18:1)
Block(-41,27,14,18:1)
Block(-41,27,15,18:1)
Block(-41,27,16,18:1)
Block(-41,27,17,18:1)
Block(-41,27,18,18:1)
Block(-41,27,19,18:1)
Block(-41,27,20,18:1)
Block(-41,27,21,18:1)
Block(-41,27,22,18:1)
Block(-41,27,23,18:1)
Block(-41,27,24,18:1)
Block(-41,27,25,18:1)
Block(-41,27,26,18:1)
Block(-41,27,27,18:1)
Block(-41,27,28,18:1)
Block(-41,27,29,18:1)
Block(-41,27,30,18:1)
Block(-41,28,-32,18:1)
Block(-41,28,-30,18:1)
Block(-41,28,-21,18:1)
Block(-41,28,-20,18:1)
Block(-41,28,-19,18:1)
Block(-41,28,-18,18:1)
Block(-41,28,-17,18:1)
Block(-41,28,-16,18:1)
Block(-41,28,-15,18:1)
Block(-41,28,-14,18:1)
Block(-41,28,-10,18:1)
Block(-41,28,-9,18:1)
Block(-41,28,-8,18:1)
Block(-41,28,-5,18:1)
Block(-41,28,-2,18:1)
Block(-41,28,-1,18:1)
Block(-41,28,0,18:1)
Block(-41,28,1,18:1)
Block(-41,28,5,18:1)
Block(-41,28,7,18:1)
Block(-41,28,8,18:1)
Block(-41,28,9,18:1)
Block(-41,28,11,18:1)
Block(-41,28,13,18:1)
Block(-41,28,14,18:1)
Block(-41,28,15,18:1)
Block(-41,28,16,18:1)
Block(-41,28,18,18:1)
Block(-41,28,19,18:1)
Block(-41,28,20,18:1)
Block(-41,28,21,18:1)
Block(-41,28,22,18:1)
Block(-41,28,24,18:1)
Block(-41,28,25,18:1)
Block(-41,28,27,18:1)
Block(-41,28,28,18:1)
Block(-41,29,-19,18:1)
Block(-41,29,-17,18:1)
Block(-41,29,-14,18:1)
Block(-41,29,-13,18:1)
Block(-41,29,-8,18:1)
Block(-41,29,-5,18:1)
Block(-41,29,-2,18:1)
Block(-41,29,-1,18:1)
Block(-41,29,1,18:1)
Block(-41,29,2,18:1)
Block(-41,29,3,18:1)
Block(-41,29,4,18:1)
Block(-41,29,5,18:1)
Block(-41,29,8,18:1)
Block(-41,29,11,18:1)
Block(-41,29,12,18:1)
Block(-41,29,13,18:1)
Block(-41,29,14,18:1)
Block(-41,29,19,18:1)
Block(-41,29,23,18:1)
Block(-41,30,-2,18:1)
Block(-41,30,-1,18:1)
Block(-41,30,17,18:1)
Block(-40,20,-36,18:1)
Block(-40,20,-34,18:1)
Block(-40,20,-33,18:1)
Block(-40,20,-32,18:1)
Block(-40,20,31,18:1)
Block(-40,20,33,18:1)
Block(-40,21,-38,18:1)
Block(-40,21,-37,18:1)
Block(-40,21,-36,18:1)
Block(-40,21,-34,18:1)
Block(-40,21,-32,18:1)
Block(-40,21,32,18:1)
Block(-40,21,33,18:1)
Block(-40,21,34,18:1)
Block(-40,21,35,18:1)
Block(-40,22,-39,18:1)
Block(-40,22,-37,18:1)
Block(-40,22,-35,18:1)
Block(-40,22,-34,18:1)
Block(-40,22,-33,18:1)
Block(-40,22,-32,18:1)
Block(-40,22,-31,18:1)
Block(-40,22,-30,18:1)
Block(-40,22,-27,18:1)
Block(-40,22,24,18:1)
Block(-40,22,25,18:1)
Block(-40,22,29,18:1)
Block(-40,22,30,18:1)
Block(-40,22,33,18:1)
Block(-40,22,37,18:1)
Block(-40,23,-39,18:1)
Block(-40,23,-38,18:1)
Block(-40,23,-37,18:1)
Block(-40,23,-36,18:1)
Block(-40,23,-34,18:1)
Block(-40,23,-33,17:5)
Block(-40,23,-32,18:1)
Block(-40,23,-31,18:1)
Block(-40,23,-29,18:1)
Block(-40,23,-28,18:1)
Block(-40,23,-27,18:1)
Block(-40,23,-26,18:1)
Block(-40,23,-25,18:1)
Block(-40,23,-24,18:1)
Block(-40,23,-23,18:1)
Block(-40,23,-22,18:1)
Block(-40,23,-21,18:1)
Block(-40,23,-19,18:1)
Block(-40,23,-18,18:1)
Block(-40,23,-17,18:1)
Block(-40,23,-15,18:1)
Block(-40,23,-14,18:1)
Block(-40,23,-9,18:1)
Block(-40,23,-7,18:1)
Block(-40,23,23,18:1)
Block(-40,23,25,18:1)
Block(-40,23,26,18:1)
Block(-40,23,27,18:1)
Block(-40,23,29,18:1)
Block(-40,23,30,18:1)
Block(-40,23,31,18:1)
Block(-40,23,32,17:5)
Block(-40,23,33,18:1)
Block(-40,23,34,18:1)
Block(-40,23,35,18:1)
Block(-40,23,36,18:1)
Block(-40,23,38,18:1)
Block(-40,24,-37,18:1)
Block(-40,24,-36,18:1)
Block(-40,24,-35,18:1)
Block(-40,24,-34,18:1)
Block(-40,24,-33,18:1)
Block(-40,24,-30,18:1)
Block(-40,24,-28,18:1)
Block(-40,24,-27,18:1)
Block(-40,24,-25,18:1)
Block(-40,24,-21,18:1)
Block(-40,24,-18,18:1)
Block(-40,24,-16,18:1)
Block(-40,24,-14,18:1)
Block(-40,24,-13,18:1)
Block(-40,24,-12,18:1)
Block(-40,24,-9,18:1)
Block(-40,24,-8,18:1)
Block(-40,24,-4,18:1)
Block(-40,24,3,18:1)
Block(-40,24,4,18:1)
Block(-40,24,5,18:1)
Block(-40,24,8,18:1)
Block(-40,24,9,18:1)
Block(-40,24,12,18:1)
Block(-40,24,13,18:1)
Block(-40,24,14,18:1)
Block(-40,24,17,18:1)
Block(-40,24,18,18:1)
Block(-40,24,21,18:1)
Block(-40,24,24,18:1)
Block(-40,24,25,18:1)
Block(-40,24,26,18:1)
Block(-40,24,27,18:1)
Block(-40,24,28,18:1)
Block(-40,24,29,18:1)
Block(-40,24,31,18:1)
Block(-40,24,32,18:1)
Block(-40,24,33,18:1)
Block(-40,24,34,18:1)
Block(-40,24,35,18:1)
Block(-40,24,36,18:1)
Block(-40,24,37,18:1)
Block(-40,25,-36,18:1)
Block(-40,25,-35,18:1)
Block(-40,25,-34,18:1)
Block(-40,25,-33,18:1)
Block(-40,25,-32,17:9)
Block(-40,25,-31,17:9)
Block(-40,25,-30,17:9)
Block(-40,25,-29,17:5)
Block(-40,25,-28,17:9)
Block(-40,25,-27,17:9)
Block(-40,25,-26,17:9)
Block(-40,25,-25,17:9)
Block(-40,25,-24,17:9)
Block(-40,25,-23,17:9)
Block(-40,25,-22,18:1)
Block(-40,25,-21,18:1)
Block(-40,25,-19,18:1)
Block(-40,25,-17,18:1)
Block(-40,25,-16,18:1)
Block(-40,25,-15,18:1)
Block(-40,25,-14,18:1)
Block(-40,25,-13,18:1)
Block(-40,25,-12,18:1)
Block(-40,25,-8,18:1)
Block(-40,25,-7,18:1)
Block(-40,25,-6,18:1)
Block(-40,25,-5,18:1)
Block(-40,25,-4,18:1)
Block(-40,25,-3,18:1)
Block(-40,25,-2,18:1)
Block(-40,25,-1,18:1)
Block(-40,25,0,17:5)
Block(-40,25,1,18:1)
Block(-40,25,2,18:1)
Block(-40,25,3,18:1)
Block(-40,25,4,18:1)
Block(-40,25,6,18:1)
Block(-40,25,7,18:1)
Block(-40,25,10,18:1)
Block(-40,25,11,18:1)
Block(-40,25,12,18:1)
Block(-40,25,13,18:1)
Block(-40,25,14,18:1)
Block(-40,25,15,18:1)
Block(-40,25,18,18:1)
Block(-40,25,19,18:1)
Block(-40,25,22,18:1)
Block(-40,25,23,18:1)
Block(-40,25,24,18:1)
Block(-40,25,25,17:9)
Block(-40,25,26,17:9)
Block(-40,25,27,17:9)
Block(-40,25,28,17:5)
Block(-40,25,31,18:1)
Block(-40,25,32,18:1)
Block(-40,25,33,18:1)
Block(-40,25,34,18:1)
Block(-40,26,-36,18:1)
Block(-40,26,-35,18:1)
Block(-40,26,-34,18:1)
Block(-40,26,-33,18:1)
Block(-40,26,-32,18:1)
Block(-40,26,-31,18:1)
Block(-40,26,-30,18:1)
Block(-40,26,-29,18:1)
Block(-40,26,-28,18:1)
Block(-40,26,-27,18:1)
Block(-40,26,-26,18:1)
Block(-40,26,-25,18:1)
Block(-40,26,-24,18:1)
Block(-40,26,-22,18:1)
Block(-40,26,-21,18:1)
Block(-40,26,-20,18:1)
Block(-40,26,-18,18:1)
Block(-40,26,-17,18:1)
Block(-40,26,-16,18:1)
Block(-40,26,-15,18:1)
Block(-40,26,-14,17:5)
Block(-40,26,-13,18:1)
Block(-40,26,-12,18:1)
Block(-40,26,-11,18:1)
Block(-40,26,-10,18:1)
Block(-40,26,-8,18:1)
Block(-40,26,-7,18:1)
Block(-40,26,-5,18:1)
Block(-40,26,-4,17:5)
Block(-40,26,-3,18:1)
Block(-40,26,-2,18:1)
Block(-40,26,-1,17:5)
Block(-40,26,0,17:5)
Block(-40,26,1,17:5)
Block(-40,26,2,18:1)
Block(-40,26,4,18:1)
Block(-40,26,5,18:1)
Block(-40,26,6,18:1)
Block(-40,26,7,18:1)
Block(-40,26,8,18:1)
Block(-40,26,12,18:1)
Block(-40,26,13,18:1)
Block(-40,26,15,18:1)
Block(-40,26,16,18:1)
Block(-40,26,18,18:1)
Block(-40,26,19,18:1)
Block(-40,26,20,18:1)
Block(-40,26,21,18:1)
Block(-40,26,22,18:1)
Block(-40,26,23,18:1)
Block(-40,26,26,18:1)
Block(-40,26,28,18:1)
Block(-40,26,29,18:1)
Block(-40,26,31,18:1)
Block(-40,26,33,18:1)
Block(-40,27,-33,18:1)
Block(-40,27,-31,18:1)
Block(-40,27,-30,18:1)
Block(-40,27,-29,18:1)
Block(-40,27,-28,18:1)
Block(-40,27,-27,18:1)
Block(-40,27,-21,18:1)
Block(-40,27,-20,18:1)
Block(-40,27,-18,18:1)
Block(-40,27,-17,18:1)
Block(-40,27,-16,18:1)
Block(-40,27,-14,18:1)
Block(-40,27,-13,18:1)
Block(-40,27,-12,18:1)
Block(-40,27,-11,18:1)
Block(-40,27,-10,18:1)
Block(-40,27,-9,18:1)
Block(-40,27,-8,18:1)
Block(-40,27,-5,18:1)
Block(-40,27,-4,18:1)
Block(-40,27,-3,18:1)
Block(-40,27,-1,17:5)
Block(-40,27,0,17:5)
Block(-40,27,1,17:5)
Block(-40,27,2,17:9)
Block(-40,27,3,17:9)
Block(-40,27,4,17:9)
Block(-40,27,5,18:1)
Block(-40,27,6,18:1)
Block(-40,27,7,18:1)
Block(-40,27,8,17:5)
Block(-40,27,10,18:1)
Block(-40,27,11,18:1)
Block(-40,27,12,18:1)
Block(-40,27,13,18:1)
Block(-40,27,15,18:1)
Block(-40,27,16,18:1)
Block(-40,27,17,18:1)
Block(-40,27,18,18:1)
Block(-40,27,19,18:1)
Block(-40,27,20,18:1)
Block(-40,27,21,18:1)
Block(-40,27,23,18:1)
Block(-40,27,24,18:1)
Block(-40,27,25,18:1)
Block(-40,27,27,18:1)
Block(-40,27,28,18:1)
Block(-40,27,29,18:1)
Block(-40,27,30,18:1)
Block(-40,28,-32,18:1)
Block(-40,28,-31,18:1)
Block(-40,28,-27,18:1)
Block(-40,28,-19,18:1)
Block(-40,28,-18,18:1)
Block(-40,28,-16,18:1)
Block(-40,28,-15,18:1)
Block(-40,28,-14,18:1)
Block(-40,28,-13,18:1)
Block(-40,28,-12,18:1)
Block(-40,28,-10,18:1)
Block(-40,28,-7,18:1)
Block(-40,28,-6,18:1)
Block(-40,28,-4,18:1)
Block(-40,28,-3,18:1)
Block(-40,28,-1,18:1)
Block(-40,28,0,18:1)
Block(-40,28,1,18:1)
Block(-40,28,3,18:1)
Block(-40,28,4,18:1)
Block(-40,28,7,18:1)
Block(-40,28,11,18:1)
Block(-40,28,13,18:1)
Block(-40,28,14,18:1)
Block(-40,28,16,18:1)
Block(-40,28,18,18:1)
Block(-40,28,25,18:1)
Block(-40,29,-19,18:1)
Block(-40,29,-18,18:1)
Block(-40,29,-14,18:1)
Block(-40,29,-13,18:1)
Block(-40,29,-9,18:1)
Block(-40,29,-7,18:1)
Block(-40,29,-3,18:1)
Block(-40,29,-2,18:1)
Block(-40,29,-1,18:1)
Block(-40,29,0,18:1)
Block(-40,29,1,18:1)
Block(-40,29,2,18:1)
Block(-40,29,4,18:1)
Block(-40,29,6,18:1)
Block(-40,29,11,18:1)
Block(-40,29,12,18:1)
Block(-40,29,13,18:1)
Block(-40,29,18,18:1)
Block(-40,29,19,18:1)
Block(-40,29,22,18:1)
Block(-40,30,-1,18:1)
Block(-40,30,1,18:1)
Block(-40,30,4,18:1)
Block(-40,30,5,18:1)
Block(-40,30,8,18:1)
Block(-40,30,13,18:1)
Block(-40,30,14,18:1)
Block(-40,30,17,18:1)
Block(-40,30,18,18:1)
Block(-39,20,-40,18:1)
Block(-39,20,-37,18:1)
Block(-39,20,-36,18:1)
Block(-39,20,-34,18:1)
Block(-39,20,-33,18:1)
Block(-39,20,-32,18:1)
Block(-39,20,32,18:1)
Block(-39,21,-38,18:1)
Block(-39,21,-37,18:1)
Block(-39,21,-35,18:1)
Block(-39,21,-34,18:1)
Block(-39,21,-33,18:1)
Block(-39,21,-32,18:1)
Block(-39,21,-31,18:1)
Block(-39,21,31,18:1)
Block(-39,21,32,18:1)
Block(-39,21,33,18:1)
Block(-39,21,34,18:1)
Block(-39,21,35,18:1)
Block(-39,21,37,18:1)
Block(-39,22,-38,18:1)
Block(-39,22,-37,18:1)
Block(-39,22,-36,18:1)
Block(-39,22,-35,18:1)
Block(-39,22,-34,18:1)
Block(-39,22,-33,18:1)
Block(-39,22,-31,18:1)
Block(-39,22,-30,18:1)
Block(-39,22,-26,18:1)
Block(-39,22,-23,18:1)
Block(-39,22,24,18:1)
Block(-39,22,25,18:1)
Block(-39,22,30,18:1)
Block(-39,22,31,18:1)
Block(-39,22,32,18:1)
Block(-39,22,33,18:1)
Block(-39,22,34,18:1)
Block(-39,22,35,18:1)
Block(-39,22,36,18:1)
Block(-39,22,38,18:1)
Block(-39,23,-39,18:1)
Block(-39,23,-38,18:1)
Block(-39,23,-37,18:1)
Block(-39,23,-36,18:1)
Block(-39,23,-35,17:9)
Block(-39,23,-34,17:9)
Block(-39,23,-33,17:5)
Block(-39,23,-32,18:1)
Block(-39,23,-31,18:1)
Block(-39,23,-30,18:1)
Block(-39,23,-29,18:1)
Block(-39,23,-28,18:1)
Block(-39,23,-24,18:1)
Block(-39,23,-23,18:1)
Block(-39,23,-14,18:1)
Block(-39,23,23,18:1)
Block(-39,23,25,18:1)
Block(-39,23,26,18:1)
Block(-39,23,29,18:1)
Block(-39,23,30,18:1)
Block(-39,23,31,18:1)
Block(-39,23,32,17:5)
Block(-39,23,33,17:9)
Block(-39,23,34,18:1)
Block(-39,23,35,18:1)
Block(-39,23,36,18:1)
Block(-39,23,38,18:1)
Block(-39,23,39,18:1)
Block(-39,24,-40,18:1)
Block(-39,24,-39,18:1)
Block(-39,24,-37,18:1)
Block(-39,24,-36,18:1)
Block(-39,24,-35,18:1)
Block(-39,24,-34,18:1)
Block(-39,24,-32,18:1)
Block(-39,24,-31,18:1)
Block(-39,24,-30,18:1)
Block(-39,24,-29,18:1)
Block(-39,24,-27,18:1)
Block(-39,24,-25,18:1)
Block(-39,24,-23,18:1)
Block(-39,24,-20,18:1)
Block(-39,24,-19,18:1)
Block(-39,24,-8,18:1)
Block(-39,24,-1,18:1)
Block(-39,24,0,18:1)
Block(-39,24,1,18:1)
Block(-39,24,7,18:1)
Block(-39,24,8,18:1)
Block(-39,24,9,18:1)
Block(-39,24,18,18:1)
Block(-39,24,19,18:1)
Block(-39,24,21,18:1)
Block(-39,24,22,18:1)
Block(-39,24,28,18:1)
Block(-39,24,29,18:1)
Block(-39,24,30,18:1)
Block(-39,24,31,18:1)
Block(-39,24,32,18:1)
Block(-39,24,33,18:1)
Block(-39,24,34,18:1)
Block(-39,24,35,18:1)
Block(-39,24,36,18:1)
Block(-39,24,38,18:1)
Block(-39,25,-37,18:1)
Block(-39,25,-36,18:1)
Block(-39,25,-35,18:1)
Block(-39,25,-34,18:1)
Block(-39,25,-33,18:1)
Block(-39,25,-32,18:1)
Block(-39,25,-31,18:1)
Block(-39,25,-30,18:1)
Block(-39,25,-29,17:5)
Block(-39,25,-28,18:1)
Block(-39,25,-27,18:1)
Block(-39,25,-26,18:1)
Block(-39,25,-25,18:1)
Block(-39,25,-24,17:5)
Block(-39,25,-23,18:1)
Block(-39,25,-22,18:1)
Block(-39,25,-21,18:1)
Block(-39,25,-20,18:1)
Block(-39,25,-17,18:1)
Block(-39,25,-14,18:1)
Block(-39,25,-13,18:1)
Block(-39,25,-10,18:1)
Block(-39,25,-7,18:1)
Block(-39,25,-4,18:1)
Block(-39,25,-3,18:1)
Block(-39,25,-1,18:1)
Block(-39,25,0,17:5)
Block(-39,25,1,18:1)
Block(-39,25,2,18:1)
Block(-39,25,5,18:1)
Block(-39,25,6,18:1)
Block(-39,25,7,18:1)
Block(-39,25,8,18:1)
Block(-39,25,9,18:1)
Block(-39,25,10,18:1)
Block(-39,25,11,18:1)
Block(-39,25,12,18:1)
Block(-39,25,13,18:1)
Block(-39,25,15,18:1)
Block(-39,25,16,18:1)
Block(-39,25,20,18:1)
Block(-39,25,21,18:1)
Block(-39,25,22,18:1)
Block(-39,25,24,18:1)
Block(-39,25,25,18:1)
Block(-39,25,27,18:1)
Block(-39,25,28,17:5)
Block(-39,25,29,17:9)
Block(-39,25,30,18:1)
Block(-39,25,31,18:1)
Block(-39,25,32,18:1)
Block(-39,25,33,18:1)
Block(-39,25,34,18:1)
Block(-39,25,35,18:1)
Block(-39,25,36,18:1)
Block(-39,26,-35,18:1)
Block(-39,26,-34,18:1)
Block(-39,26,-33,18:1)
Block(-39,26,-32,18:1)
Block(-39,26,-31,18:1)
Block(-39,26,-30,18:1)
Block(-39,26,-29,18:1)
Block(-39,26,-28,18:1)
Block(-39,26,-27,18:1)
Block(-39,26,-25,18:1)
Block(-39,26,-24,18:1)
Block(-39,26,-20,18:1)
Block(-39,26,-19,18:1)
Block(-39,26,-18,18:1)
Block(-39,26,-17,18:1)
Block(-39,26,-16,18:1)
Block(-39,26,-15,18:1)
Block(-39,26,-14,17:5)
Block(-39,26,-11,18:1)
Block(-39,26,-10,18:1)
Block(-39,26,-9,18:1)
Block(-39,26,-8,18:1)
Block(-39,26,-6,18:1)
Block(-39,26,-5,18:1)
Block(-39,26,-4,18:1)
Block(-39,26,-3,18:1)
Block(-39,26,-2,18:1)
Block(-39,26,-1,17:5)
Block(-39,26,0,17:5)
Block(-39,26,1,17:5)
Block(-39,26,4,18:1)
Block(-39,26,5,18:1)
Block(-39,26,6,18:1)
Block(-39,26,7,18:1)
Block(-39,26,8,18:1)
Block(-39,26,9,18:1)
Block(-39,26,10,18:1)
Block(-39,26,11,18:1)
Block(-39,26,12,18:1)
Block(-39,26,13,18:1)
Block(-39,26,15,18:1)
Block(-39,26,16,18:1)
Block(-39,26,18,18:1)
Block(-39,26,19,18:1)
Block(-39,26,20,18:1)
Block(-39,26,21,18:1)
Block(-39,26,22,18:1)
Block(-39,26,23,18:1)
Block(-39,26,24,18:1)
Block(-39,26,25,18:1)
Block(-39,26,28,18:1)
Block(-39,26,29,18:1)
Block(-39,26,31,18:1)
Block(-39,26,33,18:1)
Block(-39,27,-32,18:1)
Block(-39,27,-29,18:1)
Block(-39,27,-27,18:1)
Block(-39,27,-22,18:1)
Block(-39,27,-21,18:1)
Block(-39,27,-20,18:1)
Block(-39,27,-19,18:1)
Block(-39,27,-18,18:1)
Block(-39,27,-17,18:1)
Block(-39,27,-16,18:1)
Block(-39,27,-15,18:1)
Block(-39,27,-14,18:1)
Block(-39,27,-13,18:1)
Block(-39,27,-10,18:1)
Block(-39,27,-9,18:1)
Block(-39,27,-7,18:1)
Block(-39,27,-6,17:5)
Block(-39,27,-4,18:1)
Block(-39,27,-3,18:1)
Block(-39,27,-2,18:1)
Block(-39,27,-1,17:5)
Block(-39,27,0,17:5)
Block(-39,27,1,17:5)
Block(-39,27,2,18:1)
Block(-39,27,3,18:1)
Block(-39,27,4,18:1)
Block(-39,27,5,18:1)
Block(-39,27,6,18:1)
Block(-39,27,7,17:5)
Block(-39,27,8,17:9)
Block(-39,27,10,18:1)
Block(-39,27,11,18:1)
Block(-39,27,13,17:5)
Block(-39,27,14,18:1)
Block(-39,27,15,18:1)
Block(-39,27,16,18:1)
Block(-39,27,17,18:1)
Block(-39,27,18,17:5)
Block(-39,27,19,17:9)
Block(-39,27,20,17:9)
Block(-39,27,21,17:9)
Block(-39,27,22,18:1)
Block(-39,27,23,18:1)
Block(-39,27,24,18:1)
Block(-39,27,25,18:1)
Block(-39,28,-30,18:1)
Block(-39,28,-28,18:1)
Block(-39,28,-27,18:1)
Block(-39,28,-26,18:1)
Block(-39,28,-23,18:1)
Block(-39,28,-21,18:1)
Block(-39,28,-20,18:1)
Block(-39,28,-17,18:1)
Block(-39,28,-16,18:1)
Block(-39,28,-15,18:1)
Block(-39,28,-14,18:1)
Block(-39,28,-13,18:1)
Block(-39,28,-12,18:1)
Block(-39,28,-11,18:1)
Block(-39,28,-10,18:1)
Block(-39,28,-9,18:1)
Block(-39,28,-6,18:1)
Block(-39,28,-3,18:1)
Block(-39,28,-2,18:1)
Block(-39,28,-1,18:1)
Block(-39,28,1,18:1)
Block(-39,28,3,18:1)
Block(-39,28,4,18:1)
Block(-39,28,5,18:1)
Block(-39,28,6,18:1)
Block(-39,28,7,18:1)
Block(-39,28,8,18:1)
Block(-39,28,10,18:1)
Block(-39,28,13,18:1)
Block(-39,28,14,18:1)
Block(-39,28,16,18:1)
Block(-39,28,17,18:1)
Block(-39,28,18,18:1)
Block(-39,28,19,18:1)
Block(-39,28,20,18:1)
Block(-39,28,21,18:1)
Block(-39,28,23,18:1)
Block(-39,28,25,18:1)
Block(-39,29,-15,18:1)
Block(-39,29,-14,18:1)
Block(-39,29,-2,18:1)
Block(-39,29,0,18:1)
Block(-39,29,2,18:1)
Block(-39,29,4,18:1)
Block(-39,29,5,18:1)
Block(-39,29,7,18:1)
Block(-39,29,8,18:1)
Block(-39,29,9,18:1)
Block(-39,29,10,18:1)
Block(-39,29,11,18:1)
Block(-39,29,13,18:1)
Block(-39,29,14,18:1)
Block(-39,29,15,18:1)
Block(-39,29,16,18:1)
Block(-39,29,20,18:1)
Block(-39,29,21,18:1)
Block(-39,29,22,18:1)
Block(-39,30,-1,18:1)
Block(-39,30,1,18:1)
Block(-39,30,3,18:1)
Block(-39,30,7,18:1)
Block(-39,30,13,18:1)
Block(-39,30,18,18:1)
Block(-39,30,20,18:1)
Block(-39,30,22,18:1)
Block(-38,19,-38,18:1)
Block(-38,20,-40,18:1)
Block(-38,20,-38,18:1)
Block(-38,20,-36,18:1)
Block(-38,20,-34,18:1)
Block(-38,20,-33,18:1)
Block(-38,20,32,18:1)
Block(-38,20,33,18:1)
Block(-38,20,37,18:1)
Block(-38,21,-40,18:1)
Block(-38,21,-37,17:5)
Block(-38,21,-36,18:1)
Block(-38,21,-35,18:1)
Block(-38,21,-33,18:1)
Block(-38,21,-31,18:1)
Block(-38,21,32,18:1)
Block(-38,21,33,18:1)
Block(-38,21,35,18:1)
Block(-38,21,37,17:1)
Block(-38,21,39,18:1)
Block(-38,22,-41,18:1)
Block(-38,22,-40,18:1)
Block(-38,22,-38,18:1)
Block(-38,22,-37,17:5)
Block(-38,22,-36,18:1)
Block(-38,22,-35,18:1)
Block(-38,22,-33,18:1)
Block(-38,22,-24,18:1)
Block(-38,22,30,18:1)
Block(-38,22,32,18:1)
Block(-38,22,35,18:1)
Block(-38,22,36,18:1)
Block(-38,22,37,17:1)
Block(-38,22,39,18:1)
Block(-38,23,-41,18:1)
Block(-38,23,-39,18:1)
Block(-38,23,-38,18:1)
Block(-38,23,-37,18:1)
Block(-38,23,-36,18:1)
Block(-38,23,-35,18:1)
Block(-38,23,-34,18:1)
Block(-38,23,-33,17:5)
Block(-38,23,-32,18:1)
Block(-38,23,-31,18:1)
Block(-38,23,-29,18:1)
Block(-38,23,-28,18:1)
Block(-38,23,-27,18:1)
Block(-38,23,-26,18:1)
Block(-38,23,-25,18:1)
Block(-38,23,-24,18:1)
Block(-38,23,-21,18:1)
Block(-38,23,26,18:1)
Block(-38,23,27,18:1)
Block(-38,23,29,18:1)
Block(-38,23,30,18:1)
Block(-38,23,31,18:1)
Block(-38,23,32,17:5)
Block(-38,23,33,18:1)
Block(-38,23,34,18:1)
Block(-38,23,35,18:1)
Block(-38,23,40,18:1)
Block(-38,24,-40,18:1)
Block(-38,24,-39,18:1)
Block(-38,24,-37,18:1)
Block(-38,24,-36,18:1)
Block(-38,24,-34,18:1)
Block(-38,24,-33,17:5)
Block(-38,24,-31,18:1)
Block(-38,24,-30,18:1)
Block(-38,24,-29,18:1)
Block(-38,24,-28,18:1)
Block(-38,24,-27,18:1)
Block(-38,24,-23,18:1)
Block(-38,24,-22,18:1)
Block(-38,24,-20,18:1)
Block(-38,24,-14,18:1)
Block(-38,24,-12,18:1)
Block(-38,24,-2,18:1)
Block(-38,24,0,18:1)
Block(-38,24,1,18:1)
Block(-38,24,12,18:1)
Block(-38,24,13,18:1)
Block(-38,24,21,18:1)
Block(-38,24,24,18:1)
Block(-38,24,25,18:1)
Block(-38,24,26,18:1)
Block(-38,24,27,18:1)
Block(-38,24,29,18:1)
Block(-38,24,30,18:1)
Block(-38,24,31,18:1)
Block(-38,24,32,18:1)
Block(-38,24,33,18:1)
Block(-38,24,34,18:1)
Block(-38,24,35,18:1)
Block(-38,24,37,18:1)
Block(-38,24,40,18:1)
Block(-38,25,-37,18:1)
Block(-38,25,-35,18:1)
Block(-38,25,-34,18:1)
Block(-38,25,-33,18:1)
Block(-38,25,-31,18:1)
Block(-38,25,-30,17:9)
Block(-38,25,-29,17:5)
Block(-38,25,-28,18:1)
Block(-38,25,-27,18:1)
Block(-38,25,-26,18:1)
Block(-38,25,-25,18:1)
Block(-38,25,-24,17:5)
Block(-38,25,-23,17:9)
Block(-38,25,-22,18:1)
Block(-38,25,-20,18:1)
Block(-38,25,-19,18:1)
Block(-38,25,-18,18:1)
Block(-38,25,-15,18:1)
Block(-38,25,-14,18:1)
Block(-38,25,-12,18:1)
Block(-38,25,-10,18:1)
Block(-38,25,-8,18:1)
Block(-38,25,-6,18:1)
Block(-38,25,-1,18:1)
Block(-38,25,0,18:1)
Block(-38,25,2,18:1)
Block(-38,25,5,18:1)
Block(-38,25,6,18:1)
Block(-38,25,7,18:1)
Block(-38,25,9,18:1)
Block(-38,25,10,18:1)
Block(-38,25,11,18:1)
Block(-38,25,12,18:1)
Block(-38,25,13,18:1)
Block(-38,25,14,18:1)
Block(-38,25,17,18:1)
Block(-38,25,18,18:1)
Block(-38,25,19,18:1)
Block(-38,25,21,18:1)
Block(-38,25,23,18:1)
Block(-38,25,24,18:1)
Block(-38,25,26,18:1)
Block(-38,25,27,18:1)
Block(-38,25,28,17:5)
Block(-38,25,29,18:1)
Block(-38,25,30,18:1)
Block(-38,25,32,18:1)
Block(-38,25,33,18:1)
Block(-38,25,34,18:1)
Block(-38,25,37,18:1)
Block(-38,25,38,18:1)
Block(-38,26,-35,18:1)
Block(-38,26,-34,18:1)
Block(-38,26,-33,18:1)
Block(-38,26,-32,18:1)
Block(-38,26,-31,18:1)
Block(-38,26,-30,18:1)
Block(-38,26,-28,18:1)
Block(-38,26,-27,18:1)
Block(-38,26,-26,18:1)
Block(-38,26,-25,18:1)
Block(-38,26,-24,18:1)
Block(-38,26,-23,18:1)
Block(-38,26,-22,18:1)
Block(-38,26,-21,18:1)
Block(-38,26,-20,18:1)
Block(-38,26,-19,18:1)
Block(-38,26,-18,18:1)
Block(-38,26,-17,18:1)
Block(-38,26,-16,18:1)
Block(-38,26,-15,18:1)
Block(-38,26,-14,18:1)
Block(-38,26,-13,18:1)
Block(-38,26,-12,18:1)
Block(-38,26,-9,18:1)
Block(-38,26,-8,18:1)
Block(-38,26,-7,18:1)
Block(-38,26,-6,18:1)
Block(-38,26,-1,17:5)
Block(-38,26,0,17:5)
Block(-38,26,1,17:5)
Block(-38,26,2,18:1)
Block(-38,26,3,18:1)
Block(-38,26,4,18:1)
Block(-38,26,5,18:1)
Block(-38,26,7,18:1)
Block(-38,26,9,18:1)
Block(-38,26,11,18:1)
Block(-38,26,12,18:1)
Block(-38,26,13,18:1)
Block(-38,26,16,18:1)
Block(-38,26,18,18:1)
Block(-38,26,19,18:1)
Block(-38,26,20,18:1)
Block(-38,26,22,18:1)
Block(-38,26,24,18:1)
Block(-38,26,25,18:1)
Block(-38,26,26,18:1)
Block(-38,26,27,18:1)
Block(-38,26,28,18:1)
Block(-38,26,30,18:1)
Block(-38,26,32,18:1)
Block(-38,26,33,18:1)
Block(-38,27,-31,18:1)
Block(-38,27,-30,18:1)
Block(-38,27,-29,18:1)
Block(-38,27,-28,18:1)
Block(-38,27,-27,18:1)
Block(-38,27,-26,18:1)
Block(-38,27,-25,18:1)
Block(-38,27,-23,18:1)
Block(-38,27,-22,18:1)
Block(-38,27,-21,18:1)
Block(-38,27,-20,18:1)
Block(-38,27,-19,17:5)
Block(-38,27,-18,18:1)
Block(-38,27,-16,18:1)
Block(-38,27,-15,18:1)
Block(-38,27,-14,18:1)
Block(-38,27,-13,18:1)
Block(-38,27,-12,18:1)
Block(-38,27,-10,17:5)
Block(-38,27,-9,18:1)
Block(-38,27,-8,18:1)
Block(-38,27,-7,18:1)
Block(-38,27,-6,17:5)
Block(-38,27,-4,18:1)
Block(-38,27,-3,18:1)
Block(-38,27,-2,18:1)
Block(-38,27,-1,17:5)
Block(-38,27,0,17:5)
Block(-38,27,1,17:5)
Block(-38,27,2,18:1)
Block(-38,27,3,18:1)
Block(-38,27,4,18:1)
Block(-38,27,5,18:1)
Block(-38,27,7,17:5)
Block(-38,27,9,18:1)
Block(-38,27,10,18:1)
Block(-38,27,11,18:1)
Block(-38,27,12,18:1)
Block(-38,27,13,17:5)
Block(-38,27,14,18:1)
Block(-38,27,15,18:1)
Block(-38,27,16,18:1)
Block(-38,27,17,18:1)
Block(-38,27,18,17:5)
Block(-38,27,19,18:1)
Block(-38,27,20,18:1)
Block(-38,27,21,18:1)
Block(-38,27,22,18:1)
Block(-38,27,23,18:1)
Block(-38,27,24,18:1)
Block(-38,27,25,18:1)
Block(-38,27,28,18:1)
Block(-38,27,30,18:1)
Block(-38,27,33,18:1)
Block(-38,28,-24,18:1)
Block(-38,28,-23,18:1)
Block(-38,28,-22,18:1)
Block(-38,28,-20,18:1)
Block(-38,28,-16,18:1)
Block(-38,28,-15,18:1)
Block(-38,28,-13,18:1)
Block(-38,28,-12,18:1)
Block(-38,28,-11,18:1)
Block(-38,28,-6,18:1)
Block(-38,28,-5,18:1)
Block(-38,28,-4,18:1)
Block(-38,28,-3,18:1)
Block(-38,28,-2,18:1)
Block(-38,28,-1,18:1)
Block(-38,28,0,17:5)
Block(-38,28,1,18:1)
Block(-38,28,2,18:1)
Block(-38,28,3,18:1)
Block(-38,28,5,18:1)
Block(-38,28,6,18:1)
Block(-38,28,8,18:1)
Block(-38,28,10,18:1)
Block(-38,28,11,18:1)
Block(-38,28,12,18:1)
Block(-38,28,13,18:1)
Block(-38,28,15,18:1)
Block(-38,28,17,18:1)
Block(-38,28,18,18:1)
Block(-38,28,19,18:1)
Block(-38,28,21,18:1)
Block(-38,28,22,18:1)
Block(-38,28,24,18:1)
Block(-38,29,-19,18:1)
Block(-38,29,-15,18:1)
Block(-38,29,-13,18:1)
Block(-38,29,-12,18:1)
Block(-38,29,-10,18:1)
Block(-38,29,-7,18:1)
Block(-38,29,-6,18:1)
Block(-38,29,-5,18:1)
Block(-38,29,-4,18:1)
Block(-38,29,-3,18:1)
Block(-38,29,-2,18:1)
Block(-38,29,-1,18:1)
Block(-38,29,0,18:1)
Block(-38,29,1,18:1)
Block(-38,29,2,18:1)
Block(-38,29,4,18:1)
Block(-38,29,7,18:1)
Block(-38,29,11,18:1)
Block(-38,29,12,18:1)
Block(-38,29,13,18:1)
Block(-38,29,14,18:1)
Block(-38,29,15,18:1)
Block(-38,29,16,18:1)
Block(-38,29,18,18:1)
Block(-38,29,19,18:1)
Block(-38,29,20,18:1)
Block(-38,29,22,18:1)
Block(-38,30,-1,18:1)
Block(-38,30,0,18:1)
Block(-38,30,7,18:1)
Block(-38,30,9,18:1)
Block(-38,30,14,18:1)
Block(-38,30,20,18:1)
Block(-37,19,-39,18:1)
Block(-37,19,-38,18:1)
Block(-37,19,-37,18:1)
Block(-37,20,36,18:1)
Block(-37,20,37,18:1)
Block(-37,20,38,18:1)
Block(-37,21,-38,17:1)
Block(-37,21,-37,17:5)
Block(-37,21,-36,18:1)
Block(-37,21,-35,18:1)
Block(-37,21,-34,18:1)
Block(-37,21,-33,18:1)
Block(-37,21,-32,18:1)
Block(-37,21,-31,18:1)
Block(-37,21,31,18:1)
Block(-37,21,32,18:1)
Block(-37,21,33,18:1)
Block(-37,21,36,17:9)
Block(-37,21,37,17:9)
Block(-37,21,38,17:9)
Block(-37,21,39,18:1)
Block(-37,22,-41,18:1)
Block(-37,22,-40,18:1)
Block(-37,22,-39,18:1)
Block(-37,22,-38,17:1)
Block(-37,22,-37,17:5)
Block(-37,22,-36,17:5)
Block(-37,22,-35,18:1)
