#######################################################################
# +-----------------------------------------------------------------+ #
# |                            BO3 object                           | #
# +-----------------------------------------------------------------+ #
#######################################################################

# The descriptions in this file are accurate only for TerrainControl and OTG.
# For MCW and OTG+ these descriptions are only accurate if the BO3 is used as a CustomObject.
# MCW and OTG+ completely reimplemented CustomStructure, check the MCW/OTG+ documentation for more information.

# This is the config file of a custom object.
# If you add this object correctly to your BiomeConfigs, it will spawn in the world.

# This is the creator of this BO3 object
Author: Unknown

# A short description of this BO3 object
Description: This BO3 was converted from a schematic using OTGEdit. The author and description information of the schematic could not be found. If you know who the author of the schematic is then please add this information.

# The BO3 version, don't change this! It can be used by external applications to do a version check.
Version: 3

# The settings mode, WriteAll, WriteWithoutComments or WriteDisable. See WorldConfig.
SettingsMode: WriteDisable

#######################################################################
# +-----------------------------------------------------------------+ #
# |                          Main settings                          | #
# +-----------------------------------------------------------------+ #
#######################################################################

# This needs to be set to true to spawn the object in the Tree and Sapling resources.
Tree: false

# The frequency of the BO3 from 1 to 200. Tries this many times to spawn this BO3 when using the CustomObject(...) resource.
# Ignored by Tree(..), Sapling(..) and CustomStructure(..)
Frequency: 40

# The rarity of the BO3 from 0 to 100. Each spawn attempt has rarity% chance to succeed when using the CustomObject(...) resource.
# Ignored by Tree(..), Sapling(..) and CustomStructure(..)
Rarity: 100.0

# If you set this to true, the BO3 will be placed with a random rotation.
RotateRandomly: true

# The spawn height of the BO3 - randomY, highestBlock or highestSolidBlock.
SpawnHeight: randomY

# The height limits for the BO3.
MinHeight: 0

MaxHeight: 256

# Objects can have other objects attached to it: branches. Branches can also
# have branches attached to it, which can also have branches, etc. This is the
# maximum branch depth for this objects.
MaxBranchDepth: 10

# When spawned with the UseWorld keyword, this BO3 should NOT spawn in the following biomes.
# If you writer.write the BO3 name directly in the BiomeConfigs, this will be ignored.
ExcludedBiomes: All

# To optimise this BO3 for faster loading times you can use Notepad++ to find/replace comments and abbreviate things.
# Notepad++ find/replace with regex:
# Find: ^[#;].* replace to nothing removes all lines starting with # 
# Find: ^\s*$ replace to nothing removes most empty lines 
# Notepad++ find/replace without regex:
# *Warning: This will only work for OTG 1.10.2 v21 / OTG 1.11.2 v6 or higher. B( is not recognised by lower versions.
# Find: Block( replace to B(

#######################################################################
# +-----------------------------------------------------------------+ #
# |                      Source block settings                      | #
# +-----------------------------------------------------------------+ #
#######################################################################

# The block(s) the BO3 should spawn in.
SourceBlocks: AIR

# The maximum percentage of the BO3 that can be outside the SourceBlock.
# The BO3 won't be placed on a location with more blocks outside the SourceBlock than this percentage.
MaxPercentageOutsideSourceBlock: 100

# What to do when a block is about to be placed outside the SourceBlock? (dontPlace, placeAnyway)
OutsideSourceBlock: placeAnyway

#######################################################################
# +-----------------------------------------------------------------+ #
# |                              Blocks                             | #
# +-----------------------------------------------------------------+ #
#######################################################################

# All the blocks used in the BO3 are listed here. Possible blocks:
# Block(x,y,z,id[.data][,nbtfile.nbt) or B(x,y,z,id[.data][,nbtfile.nbt)
# RandomBlock(x,y,z,id[:data][,nbtfile.nbt],chance[,id[:data][,nbtfile.nbt],chance[,...]])
# So RandomBlock(0,0,0,CHEST,chest.nbt,50,CHEST,anotherchest.nbt,100) will spawn a chest at
# the BO3 origin, and give it a 50% chance to have the contents of chest.nbt, or, if that
# fails, a 100% percent chance to have the contents of anotherchest.nbt.

Block(-6,44,0,18:3)
Block(-6,45,0,18:3)
Block(-6,45,1,18:3)
Block(-6,45,2,18:3)
Block(-6,46,-2,18:3)
Block(-6,46,-1,18:3)
Block(-6,50,1,18:3)
Block(-6,51,1,18:3)
Block(-5,43,-1,18:3)
Block(-5,44,-2,18:3)
Block(-5,44,-1,18:3)
Block(-5,44,0,18:3)
Block(-5,44,1,18:3)
Block(-5,44,3,18:3)
Block(-5,45,-3,18:3)
Block(-5,45,-2,18:3)
Block(-5,45,-1,18:3)
Block(-5,45,0,17:7)
Block(-5,46,-1,18:3)
Block(-5,46,0,18:3)
Block(-5,46,1,18:3)
Block(-5,47,-1,18:3)
Block(-5,49,0,18:3)
Block(-5,49,1,18:3)
Block(-5,50,2,18:3)
Block(-5,51,-1,18:3)
Block(-5,51,2,18:3)
Block(-5,51,3,18:3)
Block(-5,53,1,18:3)
Block(-5,53,2,18:3)
Block(-4,43,-1,18:3)
Block(-4,43,0,18:3)
Block(-4,43,1,18:3)
Block(-4,43,2,18:3)
Block(-4,44,-3,18:3)
Block(-4,44,-2,18:3)
Block(-4,44,-1,18:3)
Block(-4,44,1,18:3)
Block(-4,44,3,18:3)
Block(-4,45,-5,18:3)
Block(-4,45,-4,18:3)
Block(-4,45,-3,18:3)
Block(-4,45,-2,18:3)
Block(-4,45,-1,17:11)
Block(-4,45,0,17:7)
Block(-4,45,1,17:11)
Block(-4,45,2,18:3)
Block(-4,45,3,18:3)
Block(-4,46,-5,18:3)
Block(-4,46,-1,18:3)
Block(-4,46,0,18:3)
Block(-4,46,1,18:3)
Block(-4,46,2,18:3)
Block(-4,46,3,18:3)
Block(-4,47,-2,18:3)
Block(-4,47,-1,18:3)
Block(-4,47,1,18:3)
Block(-4,47,2,18:3)
Block(-4,49,0,18:3)
Block(-4,49,1,18:3)
Block(-4,50,-1,18:3)
Block(-4,50,1,18:3)
Block(-4,50,2,18:3)
Block(-4,50,3,18:3)
Block(-4,51,-3,18:3)
Block(-4,51,-2,18:3)
Block(-4,51,-1,18:3)
Block(-4,51,0,18:3)
Block(-4,51,1,17:7)
Block(-4,51,2,18:3)
Block(-4,51,3,18:3)
Block(-4,52,-2,18:3)
Block(-4,52,-1,18:3)
Block(-4,52,0,18:3)
Block(-4,52,1,18:3)
Block(-4,52,3,18:3)
Block(-4,53,0,18:3)
Block(-4,53,1,18:3)
Block(-4,53,2,18:3)
Block(-4,54,1,18:3)
Block(-4,55,-1,18:3)
Block(-4,55,0,18:3)
Block(-4,55,1,18:3)
Block(-4,56,0,18:3)
Block(-3,17,-2,18:3)
Block(-3,18,-3,18:3)
Block(-3,18,-1,18:3)
Block(-3,19,-2,18:3)
Block(-3,38,-2,18:3)
Block(-3,38,-1,18:3)
Block(-3,39,-2,18:3)
Block(-3,40,-1,18:3)
Block(-3,43,-4,18:3)
Block(-3,43,-1,18:3)
Block(-3,43,0,18:3)
Block(-3,43,1,18:3)
Block(-3,44,-6,18:3)
Block(-3,44,-5,18:3)
Block(-3,44,-4,18:3)
Block(-3,44,-3,18:3)
Block(-3,44,-1,18:3)
Block(-3,44,0,18:3)
Block(-3,44,1,18:3)
Block(-3,44,2,18:3)
Block(-3,44,3,18:3)
Block(-3,44,4,18:3)
Block(-3,45,-5,18:3)
Block(-3,45,-3,18:3)
Block(-3,45,-2,18:3)
Block(-3,45,0,17:7)
Block(-3,45,1,18:3)
Block(-3,45,2,18:3)
Block(-3,45,3,18:3)
Block(-3,46,1,18:3)
Block(-3,46,2,18:3)
Block(-3,46,3,18:3)
Block(-3,47,-4,18:3)
Block(-3,47,-2,18:3)
Block(-3,47,-1,18:3)
Block(-3,47,0,18:3)
Block(-3,47,1,18:3)
Block(-3,47,2,18:3)
Block(-3,48,0,18:3)
Block(-3,48,1,18:3)
Block(-3,49,-3,18:3)
Block(-3,49,-2,18:3)
Block(-3,49,-1,18:3)
Block(-3,49,1,18:3)
Block(-3,50,-2,18:3)
Block(-3,50,1,18:3)
Block(-3,51,-4,18:3)
Block(-3,51,-1,18:3)
Block(-3,51,0,18:3)
Block(-3,51,1,17:7)
Block(-3,51,2,18:3)
Block(-3,51,3,18:3)
Block(-3,51,4,18:3)
Block(-3,52,2,18:3)
Block(-3,52,3,18:3)
Block(-3,53,-1,18:3)
Block(-3,53,2,18:3)
Block(-3,54,-1,18:3)
Block(-3,54,0,18:3)
Block(-3,55,-2,18:3)
Block(-3,55,-1,18:3)
Block(-3,55,0,18:3)
Block(-3,55,1,18:3)
Block(-3,55,2,18:3)
Block(-3,56,-2,18:3)
Block(-3,56,-1,18:3)
Block(-3,56,0,18:3)
Block(-3,56,2,18:3)
Block(-3,57,-1,18:3)
Block(-3,57,0,18:3)
Block(-3,57,1,18:3)
Block(-2,0,-2,17:3)
Block(-2,0,-1,17:3)
Block(-2,0,0,17:3)
Block(-2,0,1,17:3)
Block(-2,1,-2,17:3)
Block(-2,1,-1,17:3)
Block(-2,1,0,17:3)
Block(-2,1,1,17:3)
Block(-2,2,-2,17:3)
Block(-2,2,-1,17:3)
Block(-2,2,0,17:3)
Block(-2,2,1,17:3)
Block(-2,3,-1,17:3)
Block(-2,3,0,17:3)
Block(-2,4,-1,17:3)
Block(-2,4,0,17:3)
Block(-2,16,-2,18:3)
Block(-2,17,-3,18:3)
Block(-2,17,-2,18:3)
Block(-2,17,-1,18:3)
Block(-2,18,-4,18:3)
Block(-2,18,-2,18:3)
Block(-2,18,-1,18:3)
Block(-2,18,0,18:3)
Block(-2,19,-4,18:3)
Block(-2,20,-3,18:3)
Block(-2,20,-2,18:3)
Block(-2,24,-2,18:3)
Block(-2,25,-4,18:3)
Block(-2,33,-2,18:3)
Block(-2,33,-1,18:3)
Block(-2,33,1,18:3)
Block(-2,34,-1,18:3)
Block(-2,35,-1,106:8)
Block(-2,37,-1,18:3)
Block(-2,38,-1,18:3)
Block(-2,39,-3,18:3)
Block(-2,39,-1,18:3)
Block(-2,39,0,18:3)
Block(-2,39,1,18:3)
Block(-2,41,-1,18:3)
Block(-2,43,-5,18:3)
Block(-2,43,-4,18:3)
Block(-2,43,2,18:3)
Block(-2,44,-5,18:3)
Block(-2,44,-4,18:3)
Block(-2,44,-3,18:3)
Block(-2,44,-2,18:3)
Block(-2,44,-1,18:3)
Block(-2,44,0,18:3)
Block(-2,44,1,18:3)
Block(-2,44,2,18:3)
Block(-2,44,3,18:3)
Block(-2,44,4,18:3)
Block(-2,45,-5,18:3)
Block(-2,45,-4,17:7)
Block(-2,45,-3,18:3)
Block(-2,45,-2,18:3)
Block(-2,45,-1,18:3)
Block(-2,45,0,17:7)
Block(-2,45,1,18:3)
Block(-2,45,2,18:3)
Block(-2,45,3,18:3)
Block(-2,46,-6,18:3)
Block(-2,46,-4,18:3)
Block(-2,46,-3,18:3)
Block(-2,46,-2,18:3)
Block(-2,46,-1,18:3)
Block(-2,46,0,18:3)
Block(-2,46,1,18:3)
Block(-2,46,2,18:3)
Block(-2,47,-5,18:3)
Block(-2,47,-4,18:3)
Block(-2,47,-2,18:3)
Block(-2,47,-1,18:3)
Block(-2,47,0,18:3)
Block(-2,47,1,18:3)
Block(-2,47,2,18:3)
Block(-2,47,3,18:3)
Block(-2,48,-2,18:3)
Block(-2,48,-1,18:3)
Block(-2,48,0,17:3)
Block(-2,48,1,17:3)
Block(-2,48,2,18:3)
Block(-2,48,3,18:3)
Block(-2,49,-3,18:3)
Block(-2,49,-1,18:3)
Block(-2,49,0,17:3)
Block(-2,49,1,17:3)
Block(-2,49,3,18:3)
Block(-2,50,-2,18:3)
Block(-2,50,0,17:3)
Block(-2,50,1,17:3)
Block(-2,50,2,18:3)
Block(-2,50,3,18:3)
Block(-2,51,-3,18:3)
Block(-2,51,-2,17:11)
Block(-2,51,-1,17:11)
Block(-2,51,0,17:3)
Block(-2,51,1,17:3)
Block(-2,51,2,18:3)
Block(-2,51,3,18:3)
Block(-2,51,4,18:3)
Block(-2,52,-4,18:3)
Block(-2,52,-3,18:3)
Block(-2,52,0,17:3)
Block(-2,52,1,17:3)
Block(-2,52,2,18:3)
Block(-2,52,4,18:3)
Block(-2,53,-3,18:3)
Block(-2,53,-2,18:3)
Block(-2,53,-1,18:3)
Block(-2,53,0,17:3)
Block(-2,53,1,17:3)
Block(-2,53,3,18:3)
Block(-2,54,-1,18:3)
Block(-2,54,0,17:3)
Block(-2,54,1,17:3)
Block(-2,54,2,18:3)
Block(-2,55,-2,18:3)
Block(-2,55,-1,18:3)
Block(-2,55,0,17:3)
Block(-2,55,1,17:3)
Block(-2,55,2,18:3)
Block(-2,55,3,18:3)
Block(-2,56,-2,18:3)
Block(-2,56,0,18:3)
Block(-2,56,2,18:3)
Block(-2,57,0,18:3)
Block(-1,0,-3,17:3)
Block(-1,0,-2,17:3)
Block(-1,0,-1,17:3)
Block(-1,0,0,17:3)
Block(-1,0,1,17:3)
Block(-1,0,2,17:3)
Block(-1,1,-3,17:3)
Block(-1,1,-2,17:3)
Block(-1,1,-1,17:3)
Block(-1,1,0,17:3)
Block(-1,1,1,17:3)
Block(-1,1,2,17:3)
Block(-1,2,-3,17:3)
Block(-1,2,-2,17:3)
Block(-1,2,-1,17:3)
Block(-1,2,0,17:3)
Block(-1,2,1,17:3)
Block(-1,2,2,17:3)
Block(-1,3,-2,17:3)
Block(-1,3,-1,17:3)
Block(-1,3,0,17:3)
Block(-1,3,1,17:3)
Block(-1,4,-2,17:3)
Block(-1,4,-1,17:3)
Block(-1,4,0,17:3)
Block(-1,4,1,17:3)
Block(-1,5,-2,17:3)
Block(-1,5,-1,17:3)
Block(-1,5,0,17:3)
Block(-1,5,1,17:3)
Block(-1,6,-2,17:3)
Block(-1,6,-1,17:3)
Block(-1,6,0,17:3)
Block(-1,6,1,17:3)
Block(-1,7,-1,17:3)
Block(-1,7,0,17:3)
Block(-1,7,1,106:4)
Block(-1,8,-1,17:3)
Block(-1,8,0,17:3)
Block(-1,8,1,106:8)
Block(-1,9,-1,17:3)
Block(-1,9,0,17:3)
Block(-1,10,-1,17:3)
Block(-1,10,0,17:3)
Block(-1,11,-1,106:8)
Block(-1,11,0,106:8)
Block(-1,12,0,106:8)
Block(-1,15,-2,17:3)
Block(-1,15,-1,17:3)
Block(-1,16,-2,17:3)
Block(-1,16,-1,17:3)
Block(-1,16,0,18:3)
Block(-1,17,-3,18:3)
Block(-1,17,-2,17:3)
Block(-1,17,-1,17:3)
Block(-1,17,0,18:3)
Block(-1,18,-3,18:3)
Block(-1,18,-2,17:3)
Block(-1,18,-1,17:3)
Block(-1,18,0,18:3)
Block(-1,18,1,18:3)
Block(-1,19,-4,18:3)
Block(-1,19,-3,18:3)
Block(-1,19,-2,17:3)
Block(-1,19,-1,17:3)
Block(-1,19,0,18:3)
Block(-1,20,-3,18:3)
Block(-1,20,-2,17:3)
Block(-1,20,-1,17:3)
Block(-1,20,0,18:3)
Block(-1,21,-2,17:3)
Block(-1,21,-1,17:3)
Block(-1,21,0,106:4)
Block(-1,22,-2,17:3)
Block(-1,22,-1,17:3)
Block(-1,23,-2,17:3)
Block(-1,23,-1,17:3)
Block(-1,24,-4,18:3)
Block(-1,24,-3,18:3)
Block(-1,24,-2,18:3)
Block(-1,24,-1,18:3)
Block(-1,24,0,18:3)
Block(-1,25,-4,18:3)
Block(-1,25,-3,18:3)
Block(-1,25,-2,18:3)
Block(-1,25,0,18:3)
Block(-1,26,-4,18:3)
Block(-1,26,-3,18:3)
Block(-1,26,-2,106:8)
Block(-1,26,-1,18:3)
Block(-1,27,-2,106:8)
Block(-1,27,-1,106:8)
Block(-1,31,-1,18:3)
Block(-1,32,-3,18:3)
Block(-1,32,-2,18:3)
Block(-1,32,-1,18:3)
Block(-1,32,0,18:3)
Block(-1,32,1,18:3)
Block(-1,33,-3,18:3)
Block(-1,33,-2,18:3)
Block(-1,33,-1,18:3)
Block(-1,33,1,18:3)
Block(-1,33,2,18:3)
Block(-1,34,-1,17:3)
Block(-1,34,0,17:3)
Block(-1,34,1,18:3)
Block(-1,35,-2,18:3)
Block(-1,35,-1,17:3)
Block(-1,35,0,17:3)
Block(-1,36,-1,17:3)
Block(-1,36,0,17:3)
Block(-1,37,-2,18:3)
Block(-1,37,-1,17:3)
Block(-1,37,0,17:3)
Block(-1,38,-1,17:3)
Block(-1,38,0,17:3)
Block(-1,38,1,18:3)
Block(-1,39,-3,18:3)
Block(-1,39,-2,18:3)
Block(-1,39,-1,17:3)
Block(-1,39,0,17:3)
Block(-1,40,-3,18:3)
Block(-1,40,-2,18:3)
Block(-1,40,-1,17:3)
Block(-1,40,0,17:3)
Block(-1,40,1,18:3)
Block(-1,41,-2,18:3)
Block(-1,41,-1,17:3)
Block(-1,41,0,17:3)
Block(-1,42,-1,17:3)
Block(-1,42,0,17:3)
Block(-1,43,-4,18:3)
Block(-1,43,-3,18:3)
Block(-1,43,-1,17:3)
Block(-1,43,0,17:3)
Block(-1,43,3,18:3)
Block(-1,43,4,18:3)
Block(-1,44,-6,18:3)
Block(-1,44,-5,18:3)
Block(-1,44,-4,18:3)
Block(-1,44,-3,18:3)
Block(-1,44,-1,17:3)
Block(-1,44,0,17:3)
Block(-1,44,1,18:3)
Block(-1,44,2,18:3)
Block(-1,44,3,18:3)
Block(-1,44,5,18:3)
Block(-1,45,-6,18:3)
Block(-1,45,-5,17:11)
Block(-1,45,-4,17:11)
Block(-1,45,-3,17:11)
Block(-1,45,-2,17:11)
Block(-1,45,-1,17:3)
Block(-1,45,0,17:3)
Block(-1,45,1,18:3)
Block(-1,45,2,18:3)
Block(-1,45,3,17:7)
Block(-1,45,4,18:3)
Block(-1,45,5,18:3)
Block(-1,46,-6,18:3)
Block(-1,46,-4,18:3)
Block(-1,46,-3,18:3)
Block(-1,46,-2,18:3)
Block(-1,46,-1,17:3)
Block(-1,46,0,17:3)
Block(-1,46,1,18:3)
Block(-1,46,3,18:3)
Block(-1,46,4,18:3)
Block(-1,47,-5,18:3)
Block(-1,47,-4,18:3)
Block(-1,47,-3,18:3)
Block(-1,47,-2,18:3)
Block(-1,47,-1,17:3)
Block(-1,47,0,17:3)
Block(-1,47,3,18:3)
Block(-1,48,-3,18:3)
Block(-1,48,-2,18:3)
Block(-1,48,-1,17:3)
Block(-1,48,0,17:3)
Block(-1,48,1,17:3)
Block(-1,48,2,18:3)
Block(-1,48,3,18:3)
Block(-1,49,-3,18:3)
Block(-1,49,-1,18:3)
Block(-1,49,0,17:3)
Block(-1,49,1,17:3)
Block(-1,49,3,18:3)
Block(-1,50,-4,18:3)
Block(-1,50,-1,18:3)
Block(-1,50,0,17:3)
Block(-1,50,1,17:3)
Block(-1,50,2,18:3)
Block(-1,50,5,18:3)
Block(-1,51,-4,18:3)
Block(-1,51,-2,18:3)
Block(-1,51,-1,18:3)
Block(-1,51,0,17:3)
Block(-1,51,1,17:3)
Block(-1,51,2,17:11)
Block(-1,51,3,17:11)
Block(-1,51,5,18:3)
Block(-1,52,-2,18:3)
Block(-1,52,-1,18:3)
Block(-1,52,0,17:3)
Block(-1,52,1,17:3)
Block(-1,52,2,18:3)
Block(-1,52,3,18:3)
Block(-1,52,4,18:3)
Block(-1,53,-2,18:3)
Block(-1,53,-1,18:3)
Block(-1,53,0,17:3)
Block(-1,53,1,17:3)
Block(-1,53,2,18:3)
Block(-1,53,3,18:3)
Block(-1,54,-1,18:3)
Block(-1,54,0,17:3)
Block(-1,54,1,17:3)
Block(-1,54,2,18:3)
Block(-1,54,3,18:3)
Block(-1,55,-1,18:3)
Block(-1,55,0,17:3)
Block(-1,55,1,17:3)
Block(-1,55,2,18:3)
Block(-1,55,3,18:3)
Block(-1,56,-2,18:3)
Block(-1,56,-1,18:3)
Block(-1,56,0,18:3)
Block(-1,56,1,18:3)
Block(-1,57,0,18:3)
Block(-1,57,1,18:3)
Block(-1,57,2,18:3)
Block(0,0,-3,17:3)
Block(0,0,-2,17:3)
Block(0,0,-1,17:3)
Block(0,0,0,17:3)
Block(0,0,1,17:3)
Block(0,0,2,17:3)
Block(0,1,-3,17:3)
Block(0,1,-2,17:3)
Block(0,1,-1,17:3)
Block(0,1,0,17:3)
Block(0,1,1,17:3)
Block(0,1,2,17:3)
Block(0,2,-3,17:3)
Block(0,2,-2,17:3)
Block(0,2,-1,17:3)
Block(0,2,0,17:3)
Block(0,2,1,17:3)
Block(0,2,2,17:3)
Block(0,3,-3,17:3)
Block(0,3,-2,17:3)
Block(0,3,-1,17:3)
Block(0,3,0,17:3)
Block(0,3,1,17:3)
Block(0,3,2,17:3)
Block(0,4,-3,17:3)
Block(0,4,-2,17:3)
Block(0,4,-1,17:3)
Block(0,4,0,17:3)
Block(0,4,1,17:3)
Block(0,4,2,17:3)
Block(0,5,-2,17:3)
Block(0,5,-1,17:3)
Block(0,5,0,17:3)
Block(0,5,1,17:3)
Block(0,6,-2,17:3)
Block(0,6,-1,17:3)
Block(0,6,0,17:3)
Block(0,6,1,17:3)
Block(0,7,-2,17:3)
Block(0,7,-1,17:3)
Block(0,7,0,17:3)
Block(0,7,1,17:3)
Block(0,8,-2,17:3)
Block(0,8,-1,17:3)
Block(0,8,0,17:3)
Block(0,8,1,17:3)
Block(0,9,-2,17:3)
Block(0,9,-1,17:3)
Block(0,9,0,17:3)
Block(0,9,1,17:3)
Block(0,10,-2,17:3)
Block(0,10,-1,17:3)
Block(0,10,0,17:3)
Block(0,10,1,17:3)
Block(0,11,-1,17:3)
Block(0,11,0,17:3)
Block(0,11,1,106:4)
Block(0,12,-1,17:3)
Block(0,12,0,17:3)
Block(0,13,-1,17:3)
Block(0,13,0,17:3)
Block(0,14,-1,17:3)
Block(0,14,0,17:3)
Block(0,15,-2,17:3)
Block(0,15,-1,17:3)
Block(0,15,0,17:3)
Block(0,16,-2,17:3)
Block(0,16,-1,17:3)
Block(0,16,0,18:3)
Block(0,17,-4,18:3)
Block(0,17,-3,18:3)
Block(0,17,-2,17:3)
Block(0,17,-1,17:3)
Block(0,17,0,18:3)
Block(0,17,1,18:3)
Block(0,18,-3,18:3)
Block(0,18,-2,17:3)
Block(0,18,-1,17:3)
Block(0,18,0,18:3)
Block(0,19,-3,18:3)
Block(0,19,-2,17:3)
Block(0,19,-1,17:3)
Block(0,19,0,18:3)
Block(0,20,-3,18:3)
Block(0,20,-2,17:3)
Block(0,20,-1,17:3)
Block(0,20,0,106:4)
Block(0,21,-2,17:3)
Block(0,21,-1,17:3)
Block(0,21,0,106:4)
Block(0,22,-2,17:3)
Block(0,22,-1,17:3)
Block(0,23,-4,18:3)
Block(0,23,-3,18:3)
Block(0,23,-2,17:3)
Block(0,23,-1,17:3)
Block(0,24,-3,18:3)
Block(0,24,-2,17:3)
Block(0,24,-1,17:3)
Block(0,25,-5,18:3)
Block(0,25,-4,18:3)
Block(0,25,-3,18:3)
Block(0,25,-2,17:3)
Block(0,25,-1,17:3)
Block(0,25,1,18:3)
Block(0,26,-5,18:3)
Block(0,26,-4,18:3)
Block(0,26,-3,18:3)
Block(0,26,-2,17:3)
Block(0,26,-1,17:3)
Block(0,27,-4,18:3)
Block(0,27,-3,18:3)
Block(0,27,-2,17:3)
Block(0,27,-1,17:3)
Block(0,28,-3,106:1)
Block(0,28,-2,17:3)
Block(0,28,-1,17:3)
Block(0,29,-2,17:3)
Block(0,29,-1,17:3)
Block(0,30,-2,17:3)
Block(0,30,-1,17:3)
Block(0,31,-3,18:3)
Block(0,31,-2,17:3)
Block(0,31,-1,17:3)
Block(0,32,-4,18:3)
Block(0,32,-3,18:3)
Block(0,32,-2,17:3)
Block(0,32,-1,17:3)
Block(0,32,0,18:3)
Block(0,32,1,18:3)
Block(0,32,2,18:3)
Block(0,33,-3,18:3)
Block(0,33,-2,17:3)
Block(0,33,-1,17:3)
Block(0,33,0,18:3)
Block(0,33,1,18:3)
Block(0,34,-3,18:3)
Block(0,34,-2,17:3)
Block(0,34,-1,17:3)
Block(0,34,0,17:3)
Block(0,34,1,18:3)
Block(0,35,-2,18:3)
Block(0,35,-1,17:3)
Block(0,35,0,17:3)
Block(0,35,1,106:4)
Block(0,36,-2,106:1)
Block(0,36,-1,17:3)
Block(0,36,0,17:3)
Block(0,37,-2,18:3)
Block(0,37,-1,17:3)
Block(0,37,0,17:3)
Block(0,38,-2,18:3)
Block(0,38,-1,17:3)
Block(0,38,0,17:3)
Block(0,38,1,18:3)
Block(0,39,-2,18:3)
Block(0,39,-1,17:3)
Block(0,39,0,17:3)
Block(0,40,-3,18:3)
Block(0,40,-1,17:3)
Block(0,40,0,17:3)
Block(0,41,-2,18:3)
Block(0,41,-1,17:3)
Block(0,41,0,17:3)
Block(0,42,-1,17:3)
Block(0,42,0,17:3)
Block(0,43,-5,18:3)
Block(0,43,-4,18:3)
Block(0,43,-3,18:3)
Block(0,43,-1,17:3)
Block(0,43,0,17:3)
Block(0,43,4,18:3)
Block(0,44,-6,18:3)
Block(0,44,-4,18:3)
Block(0,44,-2,18:3)
Block(0,44,-1,17:3)
Block(0,44,0,17:3)
Block(0,44,1,18:3)
Block(0,44,2,18:3)
Block(0,44,4,18:3)
Block(0,44,5,18:3)
Block(0,45,-5,18:3)
Block(0,45,-4,17:7)
Block(0,45,-3,18:3)
Block(0,45,-2,18:3)
Block(0,45,-1,17:3)
Block(0,45,0,17:3)
Block(0,45,1,17:11)
Block(0,45,2,17:11)
Block(0,45,3,17:11)
Block(0,45,4,17:11)
Block(0,45,5,18:3)
Block(0,46,-5,18:3)
Block(0,46,-4,18:3)
Block(0,46,-2,18:3)
Block(0,46,-1,17:3)
Block(0,46,0,17:3)
Block(0,46,1,18:3)
Block(0,46,3,18:3)
Block(0,46,4,18:3)
Block(0,47,-3,18:3)
Block(0,47,-1,17:3)
Block(0,47,0,17:3)
Block(0,47,1,18:3)
Block(0,47,2,18:3)
Block(0,47,3,18:3)
Block(0,47,4,18:3)
Block(0,48,-3,18:3)
Block(0,48,-2,18:3)
Block(0,48,-1,17:3)
Block(0,48,0,17:3)
Block(0,48,1,18:3)
Block(0,48,2,18:3)
Block(0,49,-2,18:3)
Block(0,49,-1,18:3)
Block(0,49,0,18:3)
Block(0,49,1,18:3)
Block(0,49,3,18:3)
Block(0,50,-1,18:3)
Block(0,50,0,18:3)
Block(0,50,1,18:3)
Block(0,50,2,18:3)
Block(0,50,3,18:3)
Block(0,50,5,18:3)
Block(0,51,-3,18:3)
Block(0,51,-2,18:3)
Block(0,51,-1,18:3)
Block(0,51,0,17:7)
Block(0,51,1,18:3)
Block(0,51,2,18:3)
Block(0,51,3,18:3)
Block(0,51,4,18:3)
Block(0,51,5,18:3)
Block(0,52,-2,18:3)
Block(0,52,1,18:3)
Block(0,52,2,18:3)
Block(0,52,3,18:3)
Block(0,53,0,18:3)
Block(0,53,3,18:3)
Block(0,53,4,18:3)
Block(0,54,-1,18:3)
Block(0,55,-1,18:3)
Block(0,55,0,18:3)
Block(0,55,2,18:3)
Block(0,56,1,18:3)
Block(0,56,2,18:3)
Block(0,56,3,18:3)
Block(0,57,2,18:3)
Block(1,0,-3,17:3)
Block(1,0,-2,17:3)
Block(1,0,-1,17:3)
Block(1,0,0,17:3)
Block(1,0,1,17:3)
Block(1,0,2,17:3)
Block(1,1,-3,17:3)
Block(1,1,-2,17:3)
Block(1,1,-1,17:3)
Block(1,1,0,17:3)
Block(1,1,1,17:3)
Block(1,1,2,17:3)
Block(1,2,-3,17:3)
Block(1,2,-2,17:3)
Block(1,2,-1,17:3)
Block(1,2,0,17:3)
Block(1,2,1,17:3)
Block(1,2,2,17:3)
Block(1,3,-3,17:3)
Block(1,3,-2,17:3)
Block(1,3,-1,17:3)
Block(1,3,0,17:3)
Block(1,3,1,17:3)
Block(1,3,2,17:3)
Block(1,4,-3,17:3)
Block(1,4,-2,17:3)
Block(1,4,-1,17:3)
Block(1,4,0,17:3)
Block(1,4,1,17:3)
Block(1,4,2,17:3)
Block(1,5,-2,17:3)
Block(1,5,-1,17:3)
Block(1,5,0,17:3)
Block(1,5,1,17:3)
Block(1,6,-2,17:3)
Block(1,6,-1,17:3)
Block(1,6,0,17:3)
Block(1,6,1,17:3)
Block(1,7,-2,17:3)
Block(1,7,-1,17:3)
Block(1,7,0,17:3)
Block(1,7,1,17:3)
Block(1,8,-2,17:3)
Block(1,8,-1,17:3)
Block(1,8,0,17:3)
Block(1,8,1,17:3)
Block(1,9,-2,17:3)
Block(1,9,-1,17:3)
Block(1,9,0,17:3)
Block(1,9,1,17:3)
Block(1,10,-2,17:3)
Block(1,10,-1,17:3)
Block(1,10,0,17:3)
Block(1,10,1,17:3)
Block(1,11,-2,106:1)
Block(1,11,-1,17:3)
Block(1,11,0,17:3)
Block(1,12,-1,17:3)
Block(1,12,0,17:3)
Block(1,13,-1,17:3)
Block(1,13,0,17:3)
Block(1,14,-1,17:3)
Block(1,14,0,17:3)
Block(1,15,-1,17:3)
Block(1,15,0,17:3)
Block(1,16,-2,18:3)
Block(1,17,-2,18:3)
Block(1,17,-1,18:3)
Block(1,18,-3,18:3)
Block(1,18,-2,18:3)
Block(1,18,-1,18:3)
Block(1,18,1,18:3)
Block(1,19,-3,18:3)
Block(1,19,-2,18:3)
Block(1,19,-1,18:3)
Block(1,19,0,18:3)
Block(1,19,1,18:3)
Block(1,20,-2,18:3)
Block(1,20,-1,106:2)
Block(1,23,-3,18:3)
Block(1,23,-2,17:3)
Block(1,23,-1,17:3)
Block(1,24,-2,17:3)
Block(1,24,-1,17:3)
Block(1,24,0,18:3)
Block(1,25,-4,18:3)
Block(1,25,-3,18:3)
Block(1,25,-2,17:3)
Block(1,25,-1,17:3)
Block(1,25,0,18:3)
Block(1,25,1,18:3)
Block(1,26,-5,18:3)
Block(1,26,-4,18:3)
Block(1,26,-3,18:3)
Block(1,26,-2,17:3)
Block(1,26,-1,17:3)
Block(1,26,0,18:3)
Block(1,27,-3,18:3)
Block(1,27,-2,17:3)
Block(1,27,-1,17:3)
Block(1,27,0,18:3)
Block(1,28,-3,106:1)
Block(1,28,-2,17:3)
Block(1,28,-1,17:3)
Block(1,28,0,106:4)
Block(1,29,-2,17:3)
Block(1,29,-1,17:3)
Block(1,30,-2,17:3)
Block(1,30,-1,17:3)
Block(1,31,-4,18:3)
Block(1,31,-2,17:3)
Block(1,31,-1,17:3)
Block(1,31,0,18:3)
Block(1,32,-2,17:3)
Block(1,32,-1,17:3)
Block(1,32,0,18:3)
Block(1,33,-3,18:3)
Block(1,33,-2,17:3)
Block(1,33,-1,17:3)
Block(1,34,-3,18:3)
Block(1,34,-2,17:3)
Block(1,34,-1,17:3)
Block(1,34,0,18:3)
Block(1,34,1,18:3)
Block(1,35,-2,18:3)
Block(1,35,-1,18:3)
Block(1,36,-1,106:2)
Block(1,38,-1,18:3)
Block(1,38,0,18:3)
Block(1,39,-2,18:3)
Block(1,39,-1,18:3)
Block(1,39,0,18:3)
Block(1,40,-2,18:3)
Block(1,40,-1,18:3)
Block(1,43,-5,18:3)
Block(1,43,-4,18:3)
Block(1,43,3,18:3)
Block(1,44,-4,18:3)
Block(1,44,-2,18:3)
Block(1,44,-1,18:3)
Block(1,44,0,18:3)
Block(1,44,3,18:3)
Block(1,45,-5,18:3)
Block(1,45,-4,18:3)
Block(1,45,-3,18:3)
Block(1,45,-2,18:3)
Block(1,45,-1,17:7)
Block(1,45,1,18:3)
Block(1,45,2,18:3)
Block(1,45,3,17:7)
Block(1,45,4,18:3)
Block(1,45,5,18:3)
Block(1,46,-5,18:3)
Block(1,46,-4,18:3)
Block(1,46,-3,18:3)
Block(1,46,-2,18:3)
Block(1,46,3,18:3)
Block(1,46,4,18:3)
Block(1,47,-5,18:3)
Block(1,47,-4,18:3)
Block(1,47,-1,18:3)
Block(1,47,0,18:3)
Block(1,47,1,18:3)
Block(1,47,2,18:3)
Block(1,47,3,18:3)
Block(1,47,4,18:3)
Block(1,48,-2,18:3)
Block(1,48,-1,18:3)
Block(1,48,0,18:3)
Block(1,48,1,18:3)
Block(1,48,2,18:3)
Block(1,49,-3,18:3)
Block(1,49,-1,18:3)
Block(1,49,0,18:3)
Block(1,49,1,18:3)
Block(1,50,-2,18:3)
Block(1,50,-1,18:3)
Block(1,50,0,18:3)
Block(1,50,1,18:3)
Block(1,50,2,18:3)
Block(1,50,4,18:3)
Block(1,51,-1,18:3)
Block(1,51,0,17:7)
Block(1,51,1,18:3)
Block(1,51,2,18:3)
Block(1,51,3,18:3)
Block(1,52,-2,18:3)
Block(1,52,1,18:3)
Block(1,53,1,18:3)
Block(1,54,0,18:3)
Block(1,54,2,18:3)
Block(1,55,1,18:3)
Block(1,55,2,18:3)
Block(1,56,0,18:3)
Block(1,56,1,18:3)
Block(2,0,-3,17:3)
Block(2,0,-2,17:3)
Block(2,0,-1,17:3)
Block(2,0,0,17:3)
Block(2,0,1,17:3)
Block(2,0,2,17:3)
Block(2,1,-3,17:3)
Block(2,1,-2,17:3)
Block(2,1,-1,17:3)
Block(2,1,0,17:3)
Block(2,1,1,17:3)
Block(2,1,2,17:3)
Block(2,2,-3,17:3)
Block(2,2,-2,17:3)
Block(2,2,-1,17:3)
Block(2,2,0,17:3)
Block(2,2,1,17:3)
Block(2,2,2,17:3)
Block(2,3,-2,17:3)
Block(2,3,-1,17:3)
Block(2,3,0,17:3)
Block(2,3,1,17:3)
Block(2,4,-2,17:3)
Block(2,4,-1,17:3)
Block(2,4,0,17:3)
Block(2,4,1,17:3)
Block(2,5,-2,17:3)
Block(2,5,-1,17:3)
Block(2,5,0,17:3)
Block(2,5,1,17:3)
Block(2,6,-2,17:3)
Block(2,6,-1,17:3)
Block(2,6,0,17:3)
Block(2,6,1,17:3)
Block(2,7,-2,106:2)
Block(2,7,-1,17:3)
Block(2,7,0,17:3)
Block(2,7,1,106:4)
Block(2,8,-2,106:2)
Block(2,8,-1,17:3)
Block(2,8,0,17:3)
Block(2,8,1,106:4)
Block(2,9,-1,17:3)
Block(2,9,0,17:3)
Block(2,9,1,106:4)
Block(2,10,-1,17:3)
Block(2,10,0,17:3)
Block(2,11,-1,106:2)
Block(2,17,-2,18:3)
Block(2,17,-1,18:3)
Block(2,17,0,18:3)
Block(2,18,-2,18:3)
Block(2,18,-1,18:3)
Block(2,18,0,18:3)
Block(2,19,-1,18:3)
Block(2,23,-2,18:3)
Block(2,23,-1,18:3)
Block(2,24,-4,18:3)
Block(2,24,-3,18:3)
Block(2,24,-1,18:3)
Block(2,25,-5,18:3)
Block(2,25,-4,18:3)
Block(2,25,-3,18:3)
Block(2,25,-2,18:3)
Block(2,25,-1,18:3)
Block(2,25,0,18:3)
Block(2,26,-5,18:3)
Block(2,26,-2,106:2)
Block(2,26,-1,18:3)
Block(2,27,-1,18:3)
Block(2,27,0,18:3)
Block(2,28,-1,106:2)
Block(2,31,-3,18:3)
Block(2,31,-2,18:3)
Block(2,32,-4,18:3)
Block(2,32,-3,18:3)
Block(2,32,-2,18:3)
Block(2,32,-1,18:3)
Block(2,33,-3,18:3)
Block(2,33,-2,18:3)
Block(2,33,-1,18:3)
Block(2,33,0,18:3)
Block(2,34,-2,18:3)
Block(2,34,-1,18:3)
Block(2,43,-2,18:3)
Block(2,43,-1,18:3)
Block(2,43,0,18:3)
Block(2,43,1,18:3)
Block(2,43,3,18:3)
Block(2,43,4,18:3)
Block(2,44,-4,18:3)
Block(2,44,-3,18:3)
Block(2,44,-2,18:3)
Block(2,44,2,18:3)
Block(2,44,3,18:3)
Block(2,44,5,18:3)
Block(2,45,-4,18:3)
Block(2,45,-3,18:3)
Block(2,45,-2,18:3)
Block(2,45,-1,17:7)
Block(2,45,0,18:3)
Block(2,45,2,18:3)
Block(2,45,5,18:3)
Block(2,46,-4,18:3)
Block(2,46,-1,18:3)
Block(2,46,1,18:3)
Block(2,46,2,18:3)
Block(2,46,3,18:3)
Block(2,47,-2,18:3)
Block(2,47,-1,18:3)
Block(2,48,-2,18:3)
Block(2,48,-1,18:3)
Block(2,48,0,18:3)
Block(2,49,-1,18:3)
Block(2,49,1,18:3)
Block(2,50,-1,18:3)
Block(2,50,0,18:3)
Block(2,50,2,18:3)
Block(2,51,-2,18:3)
Block(2,51,-1,18:3)
Block(2,51,0,18:3)
Block(2,51,1,18:3)
Block(2,51,2,18:3)
Block(2,52,0,18:3)
Block(2,53,0,18:3)
Block(2,53,1,18:3)
Block(3,0,-2,17:3)
Block(3,0,-1,17:3)
Block(3,0,0,17:3)
Block(3,0,1,17:3)
Block(3,1,-2,17:3)
Block(3,1,-1,17:3)
Block(3,1,0,17:3)
Block(3,1,1,17:3)
Block(3,2,-2,17:3)
Block(3,2,-1,17:3)
Block(3,2,0,17:3)
Block(3,2,1,17:3)
Block(3,3,-1,17:3)
Block(3,3,0,17:3)
Block(3,4,-1,17:3)
Block(3,4,0,17:3)
Block(3,24,-3,18:3)
Block(3,24,-1,18:3)
Block(3,24,0,18:3)
Block(3,25,-4,18:3)
Block(3,25,-2,18:3)
Block(3,25,-1,18:3)
Block(3,26,-2,18:3)
Block(3,26,-1,18:3)
Block(3,26,0,18:3)
Block(3,31,-2,18:3)
Block(3,32,-4,18:3)
Block(3,32,-1,18:3)
Block(3,32,0,18:3)
Block(3,33,-3,18:3)
Block(3,33,-2,18:3)
Block(3,43,-2,18:3)
Block(3,43,-1,18:3)
Block(3,43,0,18:3)
Block(3,44,-3,18:3)
Block(3,44,-2,18:3)
Block(3,44,-1,18:3)
Block(3,44,0,18:3)
Block(3,44,1,18:3)
Block(3,44,2,18:3)
Block(3,45,-3,18:3)
Block(3,45,-2,17:11)
Block(3,45,-1,17:7)
Block(3,45,0,17:11)
Block(3,45,1,18:3)
Block(3,45,2,18:3)
Block(3,45,3,18:3)
Block(3,45,4,18:3)
Block(3,46,-3,18:3)
Block(3,46,-2,18:3)
Block(3,46,-1,18:3)
Block(3,46,0,18:3)
Block(3,46,1,18:3)
Block(3,46,2,18:3)
Block(3,47,-3,18:3)
Block(3,47,-2,18:3)
Block(3,47,0,18:3)
Block(3,47,1,18:3)
Block(3,50,0,18:3)
Block(3,50,1,18:3)
Block(3,51,0,18:3)
Block(3,52,0,18:3)
Block(4,43,-3,18:3)
Block(4,43,-2,18:3)
Block(4,43,-1,18:3)
Block(4,44,1,18:3)
Block(4,45,-2,18:3)
Block(4,45,-1,17:7)
Block(4,45,0,18:3)
Block(4,45,1,18:3)
Block(4,46,-4,18:3)
Block(4,46,-2,18:3)
Block(4,46,1,18:3)
Block(4,46,2,18:3)
Block(4,47,-2,18:3)
Block(5,44,0,18:3)
Block(5,45,-3,18:3)
Block(5,45,-2,18:3)
Block(5,45,-1,18:3)
Block(5,45,0,18:3)
Block(5,45,1,18:3)
Block(5,46,-3,18:3)
Block(5,46,-1,18:3)
Block(5,46,0,18:3)
Block(5,46,1,18:3)


#######################################################################
# +-----------------------------------------------------------------+ #
# |                             Entities                            | #
# +-----------------------------------------------------------------+ #
#######################################################################

# Entity() spawns an entity instead of a block. The entity is spawned only once when the BO3 is spawned.
# Entities are persistent by default so they don't de-spawn when no player is near, they are only unloaded.
# Usage: Entity(x,y,z,mobName,groupSize,NameTagOrNBTFileName) or Entity(x,y,z,mobName,groupSize)
# Use /tc entities or /otg entities to get a list of entities that can be used as mobName, this includes entities added by other mods.
# NameTagOrNBTFileName can be either a nametag for the mob or an nbt file (such as mymobinfo.nbt or mymobinfo.txt).
# When using a text file you can use the same mob spawning parameters used with the /summon command to equip the
# entity and give it custom attributes etc. You can copy the DATA part of a summon command including surrounding
# curly braces to a .txt file, for instance for: "/summon Skeleton x y z {DATA}"

#######################################################################
# +-----------------------------------------------------------------+ #
# |                            BO3 checks                           | #
# +-----------------------------------------------------------------+ #
#######################################################################

# Require a condition at a certain location in order for the BO3 to be spawned.
# BlockCheck(x,y,z,BlockName[,BlockName[,...]]) - one of the blocks must be at the location
# BlockCheckNot(x,y,z,BlockName[,BlockName[,...]]) - all the blocks must not be at the location
# LightCheck(x,y,z,minLightLevel,maxLightLevel) - light must be between min and max (inclusive)

# You can use "Solid" as a BlockName for matching all solid blocks or "All" to match all blocks that aren't air.

# Examples:
#   BlockCheck(0,-1,0,GRASS,DIRT)  Require grass or dirt just below the object
#   BlockCheck(0,-1,0,Solid)       Require any solid block just below the object
#   BlockCheck(0,-1,0,WOOL)        Require any type of wool just below the object
#   BlockCheck(0,-1,0,WOOL:0)      Require white wool just below the object
#   BlockCheckNot(0,-1,0,WOOL:0)   Require that there is no white wool below the object
#   LightCheck(0,0,0,0,1)          Require almost complete darkness just below the object
BlockCheck(0,10,0,AIR)
BlockCheck(0,5,0,AIR)
BlockCheck(0,2,0,AIR)
BlockCheck(-4,0,-4,Solid)
BlockCheck(-3,0,-4,Solid)
BlockCheck(-2,0,-4,Solid)
BlockCheck(-1,0,-4,Solid)
BlockCheck(0,0,-4,Solid)
BlockCheck(1,0,-4,Solid)
BlockCheck(2,0,-4,Solid)
BlockCheck(3,0,-4,Solid)
BlockCheck(4,0,-4,Solid)
BlockCheck(-4,0,-3,Solid)
BlockCheck(-3,0,-3,Solid)
BlockCheck(-2,0,-3,Solid)
BlockCheck(-1,0,-3,Solid)
BlockCheck(0,0,-3,Solid)
BlockCheck(1,0,-3,Solid)
BlockCheck(2,0,-3,Solid)
BlockCheck(3,0,-3,Solid)
BlockCheck(4,0,-3,Solid)
BlockCheck(-4,0,-2,Solid)
BlockCheck(-3,0,-2,Solid)
BlockCheck(-2,0,-2,Solid)
BlockCheck(-1,0,-2,Solid)
BlockCheck(0,0,-2,Solid)
BlockCheck(1,0,-2,Solid)
BlockCheck(2,0,-2,Solid)
BlockCheck(3,0,-2,Solid)
BlockCheck(4,0,-2,Solid)
BlockCheck(-4,0,-1,Solid)
BlockCheck(-3,0,-1,Solid)
BlockCheck(-2,0,-1,Solid)
BlockCheck(-1,0,-1,Solid)
BlockCheck(0,0,-1,Solid)
BlockCheck(1,0,-1,Solid)
BlockCheck(2,0,-1,Solid)
BlockCheck(3,0,-1,Solid)
BlockCheck(4,0,-1,Solid)
BlockCheck(-4,0,0,Solid)
BlockCheck(-3,0,0,Solid)
BlockCheck(-2,0,0,Solid)
BlockCheck(-1,0,0,Solid)
BlockCheck(0,0,0,Solid)
BlockCheck(1,0,0,Solid)
BlockCheck(2,0,0,Solid)
BlockCheck(3,0,0,Solid)
BlockCheck(4,0,0,Solid)
BlockCheck(-4,0,1,Solid)
BlockCheck(-3,0,1,Solid)
BlockCheck(-2,0,1,Solid)
BlockCheck(-1,0,1,Solid)
BlockCheck(0,0,1,Solid)
BlockCheck(1,0,1,Solid)
BlockCheck(2,0,1,Solid)
BlockCheck(3,0,1,Solid)
BlockCheck(4,0,1,Solid)
BlockCheck(-4,0,2,Solid)
BlockCheck(-3,0,2,Solid)
BlockCheck(-2,0,2,Solid)
BlockCheck(-1,0,2,Solid)
BlockCheck(0,0,2,Solid)
BlockCheck(1,0,2,Solid)
BlockCheck(2,0,2,Solid)
BlockCheck(3,0,2,Solid)
BlockCheck(4,0,2,Solid)
BlockCheck(-4,0,3,Solid)
BlockCheck(-3,0,3,Solid)
BlockCheck(-2,0,3,Solid)
BlockCheck(-1,0,3,Solid)
BlockCheck(0,0,3,Solid)
BlockCheck(1,0,3,Solid)
BlockCheck(2,0,3,Solid)
BlockCheck(3,0,3,Solid)
BlockCheck(4,0,3,Solid)
BlockCheck(-4,0,4,Solid)
BlockCheck(-3,0,4,Solid)
BlockCheck(-2,0,4,Solid)
BlockCheck(-1,0,4,Solid)
BlockCheck(0,0,4,Solid)
BlockCheck(1,0,4,Solid)
BlockCheck(2,0,4,Solid)
BlockCheck(3,0,4,Solid)
BlockCheck(4,0,4,Solid)

