#######################################################################
# +-----------------------------------------------------------------+ #
# |                            BO3 object                           | #
# +-----------------------------------------------------------------+ #
#######################################################################

# The descriptions in this file are accurate only for TerrainControl and OTG.
# For MCW and OTG+ these descriptions are only accurate if the BO3 is used as a CustomObject.
# MCW and OTG+ completely reimplemented CustomStructure, check the MCW/OTG+ documentation for more information.

# This is the config file of a custom object.
# If you add this object correctly to your BiomeConfigs, it will spawn in the world.

# This is the creator of this BO3 object
Author: Unknown

# A short description of this BO3 object
Description: This BO3 was converted from a schematic using OTGEdit. The author and description information of the schematic could not be found. If you know who the author of the schematic is then please add this information.

# The BO3 version, don't change this! It can be used by external applications to do a version check.
Version: 3

# The settings mode, WriteAll, WriteWithoutComments or WriteDisable. See WorldConfig.
SettingsMode: WriteDisable

#######################################################################
# +-----------------------------------------------------------------+ #
# |                          Main settings                          | #
# +-----------------------------------------------------------------+ #
#######################################################################

# This needs to be set to true to spawn the object in the Tree and Sapling resources.
Tree: false

# The frequency of the BO3 from 1 to 200. Tries this many times to spawn this BO3 when using the CustomObject(...) resource.
# Ignored by Tree(..), Sapling(..) and CustomStructure(..)
Frequency: 40

# The rarity of the BO3 from 0 to 100. Each spawn attempt has rarity% chance to succeed when using the CustomObject(...) resource.
# Ignored by Tree(..), Sapling(..) and CustomStructure(..)
Rarity: 100.0

# If you set this to true, the BO3 will be placed with a random rotation.
RotateRandomly: true

# The spawn height of the BO3 - randomY, highestBlock or highestSolidBlock.
SpawnHeight: randomY

# The height limits for the BO3.
MinHeight: 0

MaxHeight: 256

# Objects can have other objects attached to it: branches. Branches can also
# have branches attached to it, which can also have branches, etc. This is the
# maximum branch depth for this objects.
MaxBranchDepth: 10

# When spawned with the UseWorld keyword, this BO3 should NOT spawn in the following biomes.
# If you writer.write the BO3 name directly in the BiomeConfigs, this will be ignored.
ExcludedBiomes: All

# To optimise this BO3 for faster loading times you can use Notepad++ to find/replace comments and abbreviate things.
# Notepad++ find/replace with regex:
# Find: ^[#;].* replace to nothing removes all lines starting with # 
# Find: ^\s*$ replace to nothing removes most empty lines 
# Notepad++ find/replace without regex:
# *Warning: This will only work for OTG 1.10.2 v21 / OTG 1.11.2 v6 or higher. B( is not recognised by lower versions.
# Find: Block( replace to B(

#######################################################################
# +-----------------------------------------------------------------+ #
# |                      Source block settings                      | #
# +-----------------------------------------------------------------+ #
#######################################################################

# The block(s) the BO3 should spawn in.
SourceBlocks: AIR

# The maximum percentage of the BO3 that can be outside the SourceBlock.
# The BO3 won't be placed on a location with more blocks outside the SourceBlock than this percentage.
MaxPercentageOutsideSourceBlock: 100

# What to do when a block is about to be placed outside the SourceBlock? (dontPlace, placeAnyway)
OutsideSourceBlock: placeAnyway

#######################################################################
# +-----------------------------------------------------------------+ #
# |                              Blocks                             | #
# +-----------------------------------------------------------------+ #
#######################################################################

# All the blocks used in the BO3 are listed here. Possible blocks:
# Block(x,y,z,id[.data][,nbtfile.nbt) or B(x,y,z,id[.data][,nbtfile.nbt)
# RandomBlock(x,y,z,id[:data][,nbtfile.nbt],chance[,id[:data][,nbtfile.nbt],chance[,...]])
# So RandomBlock(0,0,0,CHEST,chest.nbt,50,CHEST,anotherchest.nbt,100) will spawn a chest at
# the BO3 origin, and give it a 50% chance to have the contents of chest.nbt, or, if that
# fails, a 100% percent chance to have the contents of anotherchest.nbt.

Block(-12,14,-1,106:8)
Block(-12,14,0,106:8)
Block(-12,15,-1,106:8)
Block(-12,15,0,106:8)
Block(-11,13,-2,106:8)
Block(-11,14,-2,106:8)
Block(-11,15,-2,106:8)
Block(-11,15,-1,18:3)
Block(-11,15,0,18:3)
Block(-11,16,-2,18:3)
Block(-11,16,-1,18:3)
Block(-11,16,1,18:3)
Block(-11,16,3,18:3)
Block(-11,17,0,18:3)
Block(-11,17,1,18:3)
Block(-10,14,-1,18:3)
Block(-10,14,1,18:3)
Block(-10,15,-2,18:3)
Block(-10,15,-1,18:3)
Block(-10,15,0,18:3)
Block(-10,15,1,106:4)
Block(-10,15,3,106:8)
Block(-10,16,-1,18:3)
Block(-10,16,0,18:3)
Block(-10,16,1,18:3)
Block(-10,16,2,18:3)
Block(-10,16,3,18:3)
Block(-10,16,4,18:3)
Block(-10,17,-1,18:3)
Block(-10,17,1,18:3)
Block(-10,18,1,18:3)
Block(-10,18,2,18:3)
Block(-9,10,4,106:8)
Block(-9,11,4,106:8)
Block(-9,12,2,106:4)
Block(-9,12,4,106:8)
Block(-9,13,-5,106:1)
Block(-9,13,2,106:4)
Block(-9,13,4,106:8)
Block(-9,14,-5,106:1)
Block(-9,14,0,18:3)
Block(-9,14,1,18:3)
Block(-9,14,2,106:4)
Block(-9,14,4,106:8)
Block(-9,15,-5,106:1)
Block(-9,15,-4,18:3)
Block(-9,15,-1,18:3)
Block(-9,15,0,17:3)
Block(-9,15,1,18:3)
Block(-9,15,2,106:4)
Block(-9,15,3,18:3)
Block(-9,15,4,106:8)
Block(-9,16,-3,18:3)
Block(-9,16,-2,18:3)
Block(-9,16,-1,17:11)
Block(-9,16,0,17:3)
Block(-9,16,1,17:11)
Block(-9,16,2,18:3)
Block(-9,16,3,18:3)
Block(-9,16,5,18:3)
Block(-9,17,-3,18:3)
Block(-9,17,-1,18:3)
Block(-9,17,0,18:3)
Block(-9,18,0,18:3)
Block(-9,18,1,18:3)
Block(-9,18,2,18:3)
Block(-9,18,3,18:3)
Block(-9,19,1,18:3)
Block(-8,9,-6,106:1)
Block(-8,10,-6,106:1)
Block(-8,11,-6,106:1)
Block(-8,11,7,106:4)
Block(-8,12,-6,106:1)
Block(-8,12,7,106:4)
Block(-8,13,-6,106:1)
Block(-8,13,7,106:4)
Block(-8,14,-7,18:3)
Block(-8,14,-6,106:1)
Block(-8,14,0,18:3)
Block(-8,14,7,106:4)
Block(-8,15,-6,106:1)
Block(-8,15,-5,18:3)
Block(-8,15,-4,18:3)
Block(-8,15,-3,18:3)
Block(-8,15,-1,18:3)
Block(-8,15,2,18:3)
Block(-8,15,4,18:3)
Block(-8,15,6,18:3)
Block(-8,15,7,106:4)
Block(-8,16,-6,18:3)
Block(-8,16,-5,18:3)
Block(-8,16,-3,18:3)
Block(-8,16,-1,18:3)
Block(-8,16,0,18:3)
Block(-8,16,1,18:3)
Block(-8,16,3,18:3)
Block(-8,16,4,18:3)
Block(-8,16,5,18:3)
Block(-8,16,7,18:3)
Block(-8,17,-3,18:3)
Block(-8,17,-2,18:3)
Block(-8,17,-1,18:3)
Block(-8,17,0,17:3)
Block(-8,17,1,18:3)
Block(-8,17,2,18:3)
Block(-8,17,6,18:3)
Block(-8,18,-1,18:3)
Block(-8,18,0,18:3)
Block(-8,18,1,18:3)
Block(-8,18,2,18:3)
Block(-8,19,2,18:3)
Block(-7,11,8,106:8)
Block(-7,12,8,106:8)
Block(-7,13,8,106:8)
Block(-7,14,-7,18:3)
Block(-7,14,-6,18:3)
Block(-7,14,-5,18:3)
Block(-7,14,5,18:3)
Block(-7,14,6,18:3)
Block(-7,14,8,106:8)
Block(-7,15,-7,106:1)
Block(-7,15,-6,18:3)
Block(-7,15,-5,18:3)
Block(-7,15,-4,18:3)
Block(-7,15,-3,18:3)
Block(-7,15,-2,18:3)
Block(-7,15,-1,18:3)
Block(-7,15,0,18:3)
Block(-7,15,4,18:3)
Block(-7,15,5,18:3)
Block(-7,15,6,18:3)
Block(-7,15,7,18:3)
Block(-7,15,8,106:8)
Block(-7,16,-7,18:3)
Block(-7,16,-6,18:3)
Block(-7,16,-5,18:3)
Block(-7,16,-4,18:3)
Block(-7,16,-1,18:3)
Block(-7,16,0,18:3)
Block(-7,16,1,18:3)
Block(-7,16,4,18:3)
Block(-7,16,5,18:3)
Block(-7,16,6,18:3)
Block(-7,16,7,18:3)
Block(-7,16,8,18:3)
Block(-7,17,-6,18:3)
Block(-7,17,-5,18:3)
Block(-7,17,-1,18:3)
Block(-7,17,0,18:3)
Block(-7,17,1,18:3)
Block(-7,17,3,18:3)
Block(-7,17,4,18:3)
Block(-7,17,5,18:3)
Block(-7,17,7,18:3)
Block(-7,18,-2,18:3)
Block(-7,18,0,17:7)
Block(-7,18,2,18:3)
Block(-7,18,4,18:3)
Block(-7,19,-2,18:3)
Block(-7,19,0,18:3)
Block(-7,19,1,18:3)
Block(-7,20,-1,18:3)
Block(-6,13,-9,106:1)
Block(-6,14,-9,106:1)
Block(-6,14,-6,18:3)
Block(-6,14,-5,18:3)
Block(-6,14,4,18:3)
Block(-6,14,5,18:3)
Block(-6,14,6,18:3)
Block(-6,14,7,18:3)
Block(-6,15,-9,106:1)
Block(-6,15,-8,18:3)
Block(-6,15,-6,17:3)
Block(-6,15,-4,18:3)
Block(-6,15,4,18:3)
Block(-6,15,5,18:3)
Block(-6,15,6,17:3)
Block(-6,15,7,18:3)
Block(-6,15,8,18:3)
Block(-6,16,-8,18:3)
Block(-6,16,-6,17:3)
Block(-6,16,-5,17:11)
Block(-6,16,-4,18:3)
Block(-6,16,-1,18:3)
Block(-6,16,1,18:3)
Block(-6,16,4,18:3)
Block(-6,16,5,17:11)
Block(-6,16,6,17:3)
Block(-6,16,7,18:3)
Block(-6,17,-7,18:3)
Block(-6,17,-6,17:3)
Block(-6,17,-5,18:3)
Block(-6,17,-4,18:3)
Block(-6,17,-3,18:3)
Block(-6,17,0,18:3)
Block(-6,17,1,18:3)
Block(-6,17,2,18:3)
Block(-6,17,3,18:3)
Block(-6,17,4,18:3)
Block(-6,17,5,18:3)
Block(-6,17,6,17:3)
Block(-6,18,-6,18:3)
Block(-6,18,-5,18:3)
Block(-6,18,-2,18:3)
Block(-6,18,-1,17:11)
Block(-6,18,0,17:7)
Block(-6,18,1,17:11)
Block(-6,18,2,18:3)
Block(-6,18,3,18:3)
Block(-6,18,4,18:3)
Block(-6,18,5,18:3)
Block(-6,18,6,18:3)
Block(-6,19,-4,18:3)
Block(-6,19,-2,18:3)
Block(-6,19,-1,18:3)
Block(-6,19,0,18:3)
Block(-6,19,1,18:3)
Block(-6,19,4,18:3)
Block(-6,19,5,18:3)
Block(-6,20,-1,18:3)
Block(-6,20,0,18:3)
Block(-5,13,-10,106:1)
Block(-5,13,8,106:4)
Block(-5,14,-10,106:1)
Block(-5,14,-7,18:3)
Block(-5,14,-6,18:3)
Block(-5,14,-5,18:3)
Block(-5,14,5,18:3)
Block(-5,14,6,18:3)
Block(-5,14,7,18:3)
Block(-5,14,8,106:4)
Block(-5,15,-10,106:1)
Block(-5,15,-9,18:3)
Block(-5,15,-8,18:3)
Block(-5,15,-7,18:3)
Block(-5,15,-6,18:3)
Block(-5,15,-5,18:3)
Block(-5,15,-4,18:3)
Block(-5,15,6,18:3)
Block(-5,15,7,18:3)
Block(-5,15,8,106:4)
Block(-5,16,-8,18:3)
Block(-5,16,-7,18:3)
Block(-5,16,-6,17:7)
Block(-5,16,-5,18:3)
Block(-5,16,-4,18:3)
Block(-5,16,-3,18:3)
Block(-5,16,-1,18:3)
Block(-5,16,0,18:3)
Block(-5,16,3,18:3)
Block(-5,16,4,18:3)
Block(-5,16,5,18:3)
Block(-5,16,6,17:7)
Block(-5,17,-6,18:3)
Block(-5,17,-5,18:3)
Block(-5,17,-4,18:3)
Block(-5,17,2,18:3)
Block(-5,17,4,18:3)
Block(-5,17,5,18:3)
Block(-5,17,6,18:3)
Block(-5,17,7,18:3)
Block(-5,18,-6,18:3)
Block(-5,18,-5,17:11)
Block(-5,18,-4,18:3)
Block(-5,18,-3,18:3)
Block(-5,18,-2,18:3)
Block(-5,18,-1,18:3)
Block(-5,18,0,17:7)
Block(-5,18,1,18:3)
Block(-5,18,4,18:3)
Block(-5,18,5,17:7)
Block(-5,18,6,18:3)
Block(-5,19,-3,18:3)
Block(-5,19,-1,18:3)
Block(-5,19,1,18:3)
Block(-5,19,2,18:3)
Block(-5,19,4,18:3)
Block(-5,19,6,18:3)
Block(-5,19,7,18:3)
Block(-5,20,-3,18:3)
Block(-5,20,-1,18:3)
Block(-5,20,0,18:3)
Block(-5,20,3,18:3)
Block(-4,14,-9,106:8)
Block(-4,14,-7,18:3)
Block(-4,14,-6,18:3)
Block(-4,14,6,18:3)
Block(-4,14,7,18:3)
Block(-4,14,8,18:3)
Block(-4,15,-9,106:8)
Block(-4,15,-8,18:3)
Block(-4,15,-7,18:3)
Block(-4,15,-6,18:3)
Block(-4,15,-5,18:3)
Block(-4,15,4,18:3)
Block(-4,15,6,18:3)
Block(-4,15,8,106:8)
Block(-4,16,-10,18:3)
Block(-4,16,-9,18:3)
Block(-4,16,-8,18:3)
Block(-4,16,-6,18:3)
Block(-4,16,-5,18:3)
Block(-4,16,-4,18:3)
Block(-4,16,-3,18:3)
Block(-4,16,3,18:3)
Block(-4,16,4,18:3)
Block(-4,16,5,18:3)
Block(-4,16,6,18:3)
Block(-4,16,10,18:3)
Block(-4,17,-8,18:3)
Block(-4,17,-7,18:3)
Block(-4,17,-6,18:3)
Block(-4,17,-5,18:3)
Block(-4,17,-4,18:3)
Block(-4,17,-3,18:3)
Block(-4,17,0,18:3)
Block(-4,17,1,18:3)
Block(-4,17,4,18:3)
Block(-4,17,5,18:3)
Block(-4,17,6,18:3)
Block(-4,18,-5,18:3)
Block(-4,18,-4,17:11)
Block(-4,18,-3,18:3)
Block(-4,18,-2,18:3)
Block(-4,18,-1,18:3)
Block(-4,18,0,18:3)
Block(-4,18,1,18:3)
Block(-4,18,2,18:3)
Block(-4,18,3,18:3)
Block(-4,18,4,17:7)
Block(-4,18,5,18:3)
Block(-4,18,6,18:3)
Block(-4,19,-6,18:3)
Block(-4,19,-4,18:3)
Block(-4,19,-2,18:3)
Block(-4,19,-1,18:3)
Block(-4,19,0,17:7)
Block(-4,19,1,18:3)
Block(-4,19,2,18:3)
Block(-4,19,4,18:3)
Block(-4,19,6,18:3)
Block(-4,20,-3,18:3)
Block(-4,20,0,18:3)
Block(-4,20,2,18:3)
Block(-4,20,3,18:3)
Block(-4,21,-1,18:3)
Block(-3,0,-1,17:3)
Block(-3,0,0,17:3)
Block(-3,0,1,17:3)
Block(-3,1,0,17:3)
Block(-3,2,0,17:3)
Block(-3,3,-1,106:8)
Block(-3,3,0,106:8)
Block(-3,4,0,106:8)
Block(-3,5,0,106:8)
Block(-3,14,10,18:3)
Block(-3,15,-9,18:3)
Block(-3,15,-6,18:3)
Block(-3,15,5,18:3)
Block(-3,15,6,18:3)
Block(-3,15,8,18:3)
Block(-3,15,9,106:4)
Block(-3,16,-6,18:3)
Block(-3,16,-5,18:3)
Block(-3,16,4,18:3)
Block(-3,16,5,18:3)
Block(-3,16,6,18:3)
Block(-3,16,10,18:3)
Block(-3,17,-9,18:3)
Block(-3,17,-7,18:3)
Block(-3,17,-6,18:3)
Block(-3,17,-4,18:3)
Block(-3,17,-3,18:3)
Block(-3,17,-1,18:3)
Block(-3,17,0,18:3)
Block(-3,17,3,18:3)
Block(-3,17,6,18:3)
Block(-3,17,7,18:3)
Block(-3,17,10,18:3)
Block(-3,18,-6,18:3)
Block(-3,18,-4,18:3)
Block(-3,18,-3,18:3)
Block(-3,18,0,18:3)
Block(-3,18,1,18:3)
Block(-3,18,2,18:3)
Block(-3,18,3,18:3)
Block(-3,18,5,18:3)
Block(-3,18,6,18:3)
Block(-3,19,-5,18:3)
Block(-3,19,-4,18:3)
Block(-3,19,-3,17:11)
Block(-3,19,-2,18:3)
Block(-3,19,-1,18:3)
Block(-3,19,0,17:7)
Block(-3,19,2,18:3)
Block(-3,19,3,17:7)
Block(-3,19,4,18:3)
Block(-3,20,-4,18:3)
Block(-3,20,-3,18:3)
Block(-3,20,-2,18:3)
Block(-3,20,-1,18:3)
Block(-3,20,0,18:3)
Block(-3,20,1,18:3)
Block(-3,20,2,18:3)
Block(-3,20,3,18:3)
Block(-3,21,1,18:3)
Block(-2,0,-2,17:3)
Block(-2,0,-1,17:3)
Block(-2,0,0,17:3)
Block(-2,0,1,17:3)
Block(-2,0,2,17:3)
Block(-2,1,-2,17:3)
Block(-2,1,-1,17:3)
Block(-2,1,0,17:3)
Block(-2,1,1,17:3)
Block(-2,1,2,17:3)
Block(-2,2,-2,17:3)
Block(-2,2,-1,17:3)
Block(-2,2,0,17:3)
Block(-2,2,1,17:3)
Block(-2,2,2,17:3)
Block(-2,3,-1,17:3)
Block(-2,3,0,17:3)
Block(-2,3,1,17:3)
Block(-2,4,-1,17:3)
Block(-2,4,0,17:3)
Block(-2,4,1,17:3)
Block(-2,5,-1,106:8)
Block(-2,5,0,17:3)
Block(-2,5,1,106:8)
Block(-2,6,-1,106:8)
Block(-2,6,0,17:3)
Block(-2,6,1,106:8)
Block(-2,7,-1,106:8)
Block(-2,7,1,106:8)
Block(-2,8,-1,106:8)
Block(-2,8,1,106:8)
Block(-2,12,-11,106:1)
Block(-2,13,-11,106:1)
Block(-2,14,-11,106:1)
Block(-2,14,-9,18:3)
Block(-2,14,9,18:3)
Block(-2,14,10,18:3)
Block(-2,15,-11,106:1)
Block(-2,15,-10,18:3)
Block(-2,15,-7,18:3)
Block(-2,15,7,18:3)
Block(-2,15,8,18:3)
Block(-2,15,9,18:3)
Block(-2,16,-9,18:3)
Block(-2,16,-8,18:3)
Block(-2,16,7,18:3)
Block(-2,16,9,18:3)
Block(-2,16,10,18:3)
Block(-2,16,11,18:3)
Block(-2,17,-9,18:3)
Block(-2,17,-7,18:3)
Block(-2,17,-6,18:3)
Block(-2,17,-5,18:3)
Block(-2,17,-4,18:3)
Block(-2,17,0,18:3)
Block(-2,17,1,18:3)
Block(-2,17,4,18:3)
Block(-2,17,6,18:3)
Block(-2,18,-10,18:3)
Block(-2,18,-6,18:3)
Block(-2,18,-5,18:3)
Block(-2,18,-4,18:3)
Block(-2,18,-3,18:3)
Block(-2,18,-2,18:3)
Block(-2,18,-1,18:3)
Block(-2,18,3,18:3)
Block(-2,18,4,18:3)
Block(-2,18,5,18:3)
Block(-2,18,6,18:3)
Block(-2,18,7,18:3)
Block(-2,18,9,18:3)
Block(-2,18,10,18:3)
Block(-2,19,-6,18:3)
Block(-2,19,-5,18:3)
Block(-2,19,-4,18:3)
Block(-2,19,-3,18:3)
Block(-2,19,-2,17:11)
Block(-2,19,0,17:7)
Block(-2,19,1,18:3)
Block(-2,19,2,17:7)
Block(-2,19,4,18:3)
Block(-2,19,5,18:3)
Block(-2,19,9,18:3)
Block(-2,20,-1,18:3)
Block(-2,20,0,18:3)
Block(-2,20,1,18:3)
Block(-2,20,2,18:3)
Block(-2,20,3,18:3)
Block(-2,21,0,18:3)
Block(-2,21,1,18:3)
Block(-2,22,0,18:3)
Block(-1,0,-3,17:3)
Block(-1,0,-2,17:3)
Block(-1,0,-1,17:3)
Block(-1,0,0,17:3)
Block(-1,0,1,17:3)
Block(-1,0,2,17:3)
Block(-1,0,3,17:3)
Block(-1,1,-2,17:3)
Block(-1,1,-1,17:3)
Block(-1,1,0,17:3)
Block(-1,1,1,17:3)
Block(-1,1,2,17:3)
Block(-1,2,-2,17:3)
Block(-1,2,-1,17:3)
Block(-1,2,0,17:3)
Block(-1,2,1,17:3)
Block(-1,2,2,17:3)
Block(-1,3,-2,17:3)
Block(-1,3,-1,17:3)
Block(-1,3,0,17:3)
Block(-1,3,1,17:3)
Block(-1,3,2,17:3)
Block(-1,4,-2,17:3)
Block(-1,4,-1,17:3)
Block(-1,4,0,17:3)
Block(-1,4,1,17:3)
Block(-1,4,2,17:3)
Block(-1,5,-1,17:3)
Block(-1,5,0,17:3)
Block(-1,5,1,17:3)
Block(-1,5,2,106:4)
Block(-1,6,-1,17:3)
Block(-1,6,0,17:3)
Block(-1,6,1,17:3)
Block(-1,6,2,106:4)
Block(-1,7,-1,17:3)
Block(-1,7,0,17:3)
Block(-1,7,1,17:3)
Block(-1,7,2,106:4)
Block(-1,8,-1,17:3)
Block(-1,8,0,17:3)
Block(-1,8,1,17:3)
Block(-1,8,2,106:4)
Block(-1,9,-11,106:1)
Block(-1,9,-1,17:3)
Block(-1,9,0,17:3)
Block(-1,9,1,17:3)
Block(-1,10,-11,106:1)
Block(-1,10,-1,17:3)
Block(-1,10,0,17:3)
Block(-1,10,1,17:3)
Block(-1,11,-11,106:1)
Block(-1,11,-1,17:3)
Block(-1,11,0,17:3)
Block(-1,11,1,17:3)
Block(-1,12,-11,106:1)
Block(-1,12,-1,17:3)
Block(-1,12,0,17:3)
Block(-1,12,1,17:3)
Block(-1,13,-11,106:1)
Block(-1,13,0,17:3)
Block(-1,13,1,106:12)
Block(-1,14,-11,106:1)
Block(-1,14,-9,18:3)
Block(-1,14,0,17:3)
Block(-1,14,1,106:12)
Block(-1,14,8,18:3)
Block(-1,14,9,18:3)
Block(-1,14,10,18:3)
Block(-1,15,-11,106:1)
Block(-1,15,-10,18:3)
Block(-1,15,-9,18:3)
Block(-1,15,-8,18:3)
Block(-1,15,-7,18:3)
Block(-1,15,0,17:3)
Block(-1,15,1,106:4)
Block(-1,15,7,18:3)
Block(-1,15,8,18:3)
Block(-1,15,9,18:3)
Block(-1,15,10,106:4)
Block(-1,16,-11,18:3)
Block(-1,16,-10,18:3)
Block(-1,16,-9,17:7)
Block(-1,16,-8,18:3)
Block(-1,16,-7,18:3)
Block(-1,16,-6,18:3)
Block(-1,16,0,17:3)
Block(-1,16,6,18:3)
Block(-1,16,7,18:3)
Block(-1,16,8,18:3)
Block(-1,16,9,17:7)
Block(-1,16,10,18:3)
Block(-1,16,11,18:3)
Block(-1,17,-11,18:3)
Block(-1,17,-10,18:3)
Block(-1,17,-9,18:3)
Block(-1,17,-8,18:3)
Block(-1,17,-7,18:3)
Block(-1,17,-6,18:3)
Block(-1,17,-5,18:3)
Block(-1,17,-3,18:3)
Block(-1,17,-2,18:3)
Block(-1,17,0,17:3)
Block(-1,17,2,18:3)
Block(-1,17,3,18:3)
Block(-1,17,6,18:3)
Block(-1,17,7,18:3)
Block(-1,17,8,18:3)
Block(-1,17,10,18:3)
Block(-1,17,11,18:3)
Block(-1,18,-9,18:3)
Block(-1,18,-6,17:7)
Block(-1,18,-4,18:3)
Block(-1,18,-3,18:3)
Block(-1,18,0,17:3)
Block(-1,18,1,18:3)
Block(-1,18,3,18:3)
Block(-1,18,4,18:3)
Block(-1,18,5,18:3)
Block(-1,18,6,17:7)
Block(-1,18,8,18:3)
Block(-1,18,9,18:3)
Block(-1,18,10,18:3)
Block(-1,19,-7,18:3)
Block(-1,19,-6,18:3)
Block(-1,19,-5,18:3)
Block(-1,19,-4,18:3)
Block(-1,19,-3,18:3)
Block(-1,19,-2,18:3)
Block(-1,19,-1,17:11)
Block(-1,19,0,17:3)
Block(-1,19,1,17:7)
Block(-1,19,2,18:3)
Block(-1,19,3,18:3)
Block(-1,19,4,18:3)
Block(-1,20,-6,18:3)
Block(-1,20,-5,18:3)
Block(-1,20,-4,18:3)
Block(-1,20,-2,18:3)
Block(-1,20,-1,18:3)
Block(-1,20,0,17:3)
Block(-1,20,1,18:3)
Block(-1,20,5,18:3)
Block(-1,20,6,18:3)
Block(-1,21,-4,18:3)
Block(-1,21,-2,18:3)
Block(-1,21,-1,18:3)
Block(-1,21,0,18:3)
Block(-1,21,2,18:3)
Block(-1,21,4,18:3)
Block(-1,22,0,18:3)
Block(-1,22,1,18:3)
Block(0,0,-3,17:3)
Block(0,0,-2,17:3)
Block(0,0,-1,17:3)
Block(0,0,0,17:3)
Block(0,0,1,17:3)
Block(0,0,2,17:3)
Block(0,0,3,17:3)
Block(0,1,-3,17:3)
Block(0,1,-2,17:3)
Block(0,1,-1,17:3)
Block(0,1,0,17:3)
Block(0,1,1,17:3)
Block(0,1,2,17:3)
Block(0,1,3,17:3)
Block(0,2,-3,17:3)
Block(0,2,-2,17:3)
Block(0,2,-1,17:3)
Block(0,2,0,17:3)
Block(0,2,1,17:3)
Block(0,2,2,17:3)
Block(0,2,3,17:3)
Block(0,3,-2,17:3)
Block(0,3,-1,17:3)
Block(0,3,0,17:3)
Block(0,3,1,17:3)
Block(0,3,2,17:3)
Block(0,3,3,106:4)
Block(0,4,-2,17:3)
Block(0,4,-1,17:3)
Block(0,4,0,17:3)
Block(0,4,1,17:3)
Block(0,4,2,17:3)
Block(0,4,3,106:4)
Block(0,5,-2,17:3)
Block(0,5,-1,17:3)
Block(0,5,0,17:3)
Block(0,5,1,17:3)
Block(0,5,2,17:3)
Block(0,5,3,106:4)
Block(0,6,-2,17:3)
Block(0,6,-1,17:3)
Block(0,6,0,17:3)
Block(0,6,1,17:3)
Block(0,6,2,17:3)
Block(0,7,-2,106:1)
Block(0,7,-1,17:3)
Block(0,7,0,17:3)
Block(0,7,1,17:3)
Block(0,8,-2,106:1)
Block(0,8,-1,17:3)
Block(0,8,0,17:3)
Block(0,8,1,17:3)
Block(0,9,-2,106:1)
Block(0,9,-1,17:3)
Block(0,9,0,17:3)
Block(0,9,1,17:3)
Block(0,10,-2,106:1)
Block(0,10,-1,17:3)
Block(0,10,0,17:3)
Block(0,10,1,17:3)
Block(0,11,-2,106:1)
Block(0,11,-1,17:3)
Block(0,11,0,17:3)
Block(0,11,1,17:3)
Block(0,12,-2,106:1)
Block(0,12,-1,17:3)
Block(0,12,0,17:3)
Block(0,12,1,17:3)
Block(0,12,11,106:4)
Block(0,13,-12,106:1)
Block(0,13,-2,106:1)
Block(0,13,-1,17:3)
Block(0,13,0,17:3)
Block(0,13,1,17:3)
Block(0,13,11,106:4)
Block(0,14,-12,106:1)
Block(0,14,-9,18:3)
Block(0,14,-8,18:3)
Block(0,14,-2,106:1)
Block(0,14,-1,17:3)
Block(0,14,0,17:3)
Block(0,14,1,17:3)
Block(0,14,8,18:3)
Block(0,14,9,18:3)
Block(0,14,11,106:4)
Block(0,15,-12,106:1)
Block(0,15,-11,18:3)
Block(0,15,-10,18:3)
Block(0,15,-9,17:3)
Block(0,15,-7,18:3)
Block(0,15,-1,17:3)
Block(0,15,0,17:3)
Block(0,15,1,17:3)
Block(0,15,9,17:3)
Block(0,15,10,18:3)
Block(0,15,11,106:4)
Block(0,16,-9,17:3)
Block(0,16,-8,18:3)
Block(0,16,-7,18:3)
Block(0,16,-5,18:3)
Block(0,16,-1,17:3)
Block(0,16,0,17:3)
Block(0,16,1,17:3)
Block(0,16,6,18:3)
Block(0,16,7,18:3)
Block(0,16,8,18:3)
Block(0,16,9,17:3)
Block(0,16,10,18:3)
Block(0,16,11,18:3)
Block(0,17,-11,18:3)
Block(0,17,-9,18:3)
Block(0,17,-8,17:3)
Block(0,17,-7,18:3)
Block(0,17,-6,18:3)
Block(0,17,-3,18:3)
Block(0,17,-1,17:3)
Block(0,17,0,17:3)
Block(0,17,1,17:3)
Block(0,17,2,18:3)
Block(0,17,3,18:3)
Block(0,17,4,18:3)
Block(0,17,5,18:3)
Block(0,17,6,18:3)
Block(0,17,7,18:3)
Block(0,17,8,17:3)
Block(0,17,9,18:3)
Block(0,17,10,18:3)
Block(0,18,-10,18:3)
Block(0,18,-9,18:3)
Block(0,18,-8,18:3)
Block(0,18,-7,17:11)
Block(0,18,-6,17:11)
Block(0,18,-5,17:11)
Block(0,18,-4,18:3)
Block(0,18,-3,18:3)
Block(0,18,-1,17:3)
Block(0,18,0,17:3)
Block(0,18,1,17:3)
Block(0,18,2,18:3)
Block(0,18,3,18:3)
Block(0,18,4,18:3)
Block(0,18,5,17:11)
Block(0,18,6,17:11)
Block(0,18,7,17:11)
Block(0,18,8,18:3)
Block(0,18,10,18:3)
Block(0,19,-8,18:3)
Block(0,19,-7,18:3)
Block(0,19,-5,18:3)
Block(0,19,-4,17:11)
Block(0,19,-3,17:11)
Block(0,19,-2,17:11)
Block(0,19,-1,17:3)
Block(0,19,0,17:3)
Block(0,19,1,17:3)
Block(0,19,2,17:11)
Block(0,19,3,17:11)
Block(0,19,4,17:11)
Block(0,19,5,18:3)
Block(0,19,6,18:3)
Block(0,19,8,18:3)
Block(0,20,-7,18:3)
Block(0,20,-6,18:3)
Block(0,20,-4,18:3)
Block(0,20,-2,18:3)
Block(0,20,-1,17:3)
Block(0,20,0,17:3)
Block(0,20,1,17:3)
Block(0,20,2,18:3)
Block(0,20,3,18:3)
Block(0,20,4,18:3)
Block(0,20,6,18:3)
Block(0,21,-3,18:3)
Block(0,21,-2,18:3)
Block(0,21,-1,18:3)
Block(0,21,0,17:3)
Block(0,21,1,18:3)
Block(0,21,2,18:3)
Block(0,21,4,18:3)
Block(0,22,-2,18:3)
Block(0,22,-1,18:3)
Block(0,22,0,18:3)
Block(0,22,2,18:3)
Block(1,0,-3,17:3)
Block(1,0,-2,17:3)
Block(1,0,-1,17:3)
Block(1,0,0,17:3)
Block(1,0,1,17:3)
Block(1,0,2,17:3)
Block(1,0,3,17:3)
Block(1,1,-2,17:3)
Block(1,1,-1,17:3)
Block(1,1,0,17:3)
Block(1,1,1,17:3)
Block(1,1,2,17:3)
Block(1,2,-2,17:3)
Block(1,2,-1,17:3)
Block(1,2,0,17:3)
Block(1,2,1,17:3)
Block(1,2,2,17:3)
Block(1,3,-2,17:3)
Block(1,3,-1,17:3)
Block(1,3,0,17:3)
Block(1,3,1,17:3)
Block(1,3,2,17:3)
Block(1,4,-2,17:3)
Block(1,4,-1,17:3)
Block(1,4,0,17:3)
Block(1,4,1,17:3)
Block(1,4,2,17:3)
Block(1,5,-2,106:1)
Block(1,5,-1,17:3)
Block(1,5,0,17:3)
Block(1,5,1,17:3)
Block(1,6,-2,106:1)
Block(1,6,-1,17:3)
Block(1,6,0,17:3)
Block(1,6,1,17:3)
Block(1,7,-1,17:3)
Block(1,7,0,17:3)
Block(1,7,1,17:3)
Block(1,8,-1,17:3)
Block(1,8,0,17:3)
Block(1,8,1,17:3)
Block(1,9,-1,17:3)
Block(1,9,0,17:3)
Block(1,9,1,17:3)
Block(1,10,-1,17:3)
Block(1,10,0,17:3)
Block(1,10,1,17:3)
Block(1,11,-2,106:1)
Block(1,11,-1,17:3)
Block(1,11,0,17:3)
Block(1,11,1,17:3)
Block(1,12,-2,106:1)
Block(1,12,-1,17:3)
Block(1,12,0,17:3)
Block(1,12,1,17:3)
Block(1,13,-11,106:1)
Block(1,13,0,17:3)
Block(1,13,1,106:4)
Block(1,14,-11,106:1)
Block(1,14,-10,18:3)
Block(1,14,-9,18:3)
Block(1,14,0,17:3)
Block(1,14,8,18:3)
Block(1,14,9,18:3)
Block(1,14,10,18:3)
Block(1,15,-11,106:1)
Block(1,15,-10,18:3)
Block(1,15,-9,18:3)
Block(1,15,0,17:3)
Block(1,15,7,18:3)
Block(1,15,8,18:3)
Block(1,15,9,18:3)
Block(1,15,10,106:4)
Block(1,16,-11,18:3)
Block(1,16,-10,18:3)
Block(1,16,-9,17:7)
Block(1,16,-8,18:3)
Block(1,16,-7,18:3)
Block(1,16,-5,18:3)
Block(1,16,0,17:3)
Block(1,16,7,18:3)
Block(1,16,8,18:3)
Block(1,16,9,17:7)
Block(1,16,10,18:3)
Block(1,17,-10,18:3)
Block(1,17,-9,18:3)
Block(1,17,-8,18:3)
Block(1,17,-7,18:3)
Block(1,17,-6,18:3)
Block(1,17,0,17:3)
Block(1,17,6,18:3)
Block(1,17,8,18:3)
Block(1,17,10,18:3)
Block(1,18,-10,18:3)
Block(1,18,-7,18:3)
Block(1,18,-6,17:7)
Block(1,18,-5,18:3)
Block(1,18,-4,18:3)
Block(1,18,-3,18:3)
Block(1,18,0,17:3)
Block(1,18,1,18:3)
Block(1,18,5,18:3)
Block(1,18,6,17:7)
Block(1,18,7,18:3)
Block(1,18,8,18:3)
Block(1,19,-8,18:3)
Block(1,19,-4,18:3)
Block(1,19,-3,18:3)
Block(1,19,-2,18:3)
Block(1,19,-1,17:7)
Block(1,19,0,17:3)
Block(1,19,1,17:11)
Block(1,19,5,18:3)
Block(1,19,6,18:3)
Block(1,20,-5,18:3)
Block(1,20,-4,18:3)
Block(1,20,-3,18:3)
Block(1,20,-1,18:3)
Block(1,20,0,17:3)
Block(1,20,1,18:3)
Block(1,20,2,18:3)
Block(1,20,3,18:3)
Block(1,20,5,18:3)
Block(1,21,-4,18:3)
Block(1,21,-3,18:3)
Block(1,21,-2,18:3)
Block(1,21,0,18:3)
Block(1,21,1,18:3)
Block(1,21,2,18:3)
Block(1,21,3,18:3)
Block(1,22,-2,18:3)
Block(2,0,-2,17:3)
Block(2,0,-1,17:3)
Block(2,0,0,17:3)
Block(2,0,1,17:3)
Block(2,0,2,17:3)
Block(2,1,-2,17:3)
Block(2,1,-1,17:3)
Block(2,1,0,17:3)
Block(2,1,1,17:3)
Block(2,1,2,17:3)
Block(2,2,-2,17:3)
Block(2,2,-1,17:3)
Block(2,2,0,17:3)
Block(2,2,1,17:3)
Block(2,2,2,17:3)
Block(2,3,-1,17:3)
Block(2,3,0,17:3)
Block(2,3,1,17:3)
Block(2,4,-1,17:3)
Block(2,4,0,17:3)
Block(2,4,1,17:3)
Block(2,5,0,17:3)
Block(2,5,1,106:2)
Block(2,6,-1,106:2)
Block(2,6,0,17:3)
Block(2,6,1,106:2)
Block(2,7,-1,106:2)
Block(2,7,0,106:2)
Block(2,7,1,106:2)
Block(2,8,-1,106:2)
Block(2,8,0,106:2)
Block(2,9,-1,106:2)
Block(2,10,0,106:2)
Block(2,10,1,106:2)
Block(2,11,0,106:2)
Block(2,11,1,106:2)
Block(2,12,0,106:2)
Block(2,13,0,106:2)
Block(2,14,-10,18:3)
Block(2,14,8,18:3)
Block(2,15,8,18:3)
Block(2,15,9,18:3)
Block(2,16,-11,18:3)
Block(2,16,-10,18:3)
Block(2,16,-9,18:3)
Block(2,16,-8,18:3)
Block(2,16,8,18:3)
Block(2,17,-11,18:3)
Block(2,17,-10,18:3)
Block(2,17,-9,18:3)
Block(2,17,-8,18:3)
Block(2,17,-7,18:3)
Block(2,17,-6,18:3)
Block(2,17,-5,18:3)
Block(2,17,0,18:3)
Block(2,17,3,18:3)
Block(2,17,4,18:3)
Block(2,17,5,18:3)
Block(2,17,6,18:3)
Block(2,18,-9,18:3)
Block(2,18,-8,18:3)
Block(2,18,-6,18:3)
Block(2,18,-5,18:3)
Block(2,18,-4,18:3)
Block(2,18,-3,18:3)
Block(2,18,-2,18:3)
Block(2,18,0,18:3)
Block(2,18,3,18:3)
Block(2,18,4,18:3)
Block(2,18,5,18:3)
Block(2,18,6,18:3)
Block(2,18,7,18:3)
Block(2,18,8,18:3)
Block(2,18,9,18:3)
Block(2,19,-7,18:3)
Block(2,19,-5,18:3)
Block(2,19,-4,18:3)
Block(2,19,-3,18:3)
Block(2,19,-2,17:7)
Block(2,19,-1,18:3)
Block(2,19,0,17:7)
Block(2,19,1,18:3)
Block(2,19,2,17:11)
Block(2,19,3,18:3)
Block(2,19,4,18:3)
Block(2,20,-2,18:3)
Block(2,20,-1,18:3)
Block(2,20,2,18:3)
Block(2,20,3,18:3)
Block(2,20,4,18:3)
Block(2,21,-1,18:3)
Block(2,21,1,18:3)
Block(2,22,1,18:3)
Block(3,0,-1,17:3)
Block(3,0,0,17:3)
Block(3,0,1,17:3)
Block(3,1,0,17:3)
Block(3,2,0,17:3)
Block(3,10,-11,106:1)
Block(3,10,9,106:2)
Block(3,11,-11,106:1)
Block(3,11,9,106:2)
Block(3,12,-11,106:1)
Block(3,12,9,106:2)
Block(3,13,-11,106:1)
Block(3,13,9,106:2)
Block(3,14,-11,106:1)
Block(3,14,9,106:2)
Block(3,15,-11,106:1)
Block(3,15,-10,18:3)
Block(3,15,-9,18:3)
Block(3,15,-7,18:3)
Block(3,15,-5,18:3)
Block(3,15,6,18:3)
Block(3,15,8,18:3)
Block(3,15,9,106:2)
Block(3,16,-10,18:3)
Block(3,16,-8,18:3)
Block(3,16,-7,18:3)
Block(3,16,-6,18:3)
Block(3,16,-5,18:3)
Block(3,16,3,18:3)
Block(3,16,4,18:3)
Block(3,16,5,18:3)
Block(3,16,7,18:3)
Block(3,16,8,18:3)
Block(3,16,9,18:3)
Block(3,17,-8,18:3)
Block(3,17,-6,18:3)
Block(3,17,-5,18:3)
Block(3,17,-3,18:3)
Block(3,17,-2,18:3)
Block(3,17,-1,18:3)
Block(3,17,0,18:3)
Block(3,17,1,18:3)
Block(3,17,5,18:3)
Block(3,17,8,18:3)
Block(3,18,-6,18:3)
Block(3,18,-4,18:3)
Block(3,18,-2,18:3)
Block(3,18,-1,18:3)
Block(3,18,0,18:3)
Block(3,18,1,18:3)
Block(3,18,2,18:3)
Block(3,18,4,18:3)
Block(3,18,6,18:3)
Block(3,19,-3,17:7)
Block(3,19,-1,18:3)
Block(3,19,0,17:7)
Block(3,19,1,18:3)
Block(3,19,3,17:11)
Block(3,19,6,18:3)
Block(3,20,-5,18:3)
Block(3,20,-4,18:3)
Block(3,20,-1,18:3)
Block(3,20,0,18:3)
Block(3,20,2,18:3)
Block(3,20,4,18:3)
Block(3,21,-1,18:3)
Block(3,21,0,18:3)
Block(4,11,8,106:2)
Block(4,12,-9,106:2)
Block(4,12,8,106:2)
Block(4,13,-9,106:2)
Block(4,13,8,106:2)
Block(4,14,-9,106:2)
Block(4,14,-5,18:3)
Block(4,14,5,18:3)
Block(4,14,6,18:3)
Block(4,14,8,106:2)
Block(4,15,-9,106:2)
Block(4,15,-8,18:3)
Block(4,15,-6,18:3)
Block(4,15,-5,18:3)
Block(4,15,-4,18:3)
Block(4,15,4,18:3)
Block(4,15,5,18:3)
Block(4,15,6,18:3)
Block(4,15,7,18:3)
Block(4,15,8,106:2)
Block(4,16,-7,18:3)
Block(4,16,-6,18:3)
Block(4,16,-5,18:3)
Block(4,16,-4,18:3)
Block(4,16,-3,18:3)
Block(4,16,3,18:3)
Block(4,16,4,18:3)
Block(4,16,5,18:3)
Block(4,16,6,18:3)
Block(4,16,7,18:3)
Block(4,17,-6,18:3)
Block(4,17,-5,18:3)
Block(4,17,-4,18:3)
Block(4,17,-2,18:3)
Block(4,17,-1,18:3)
Block(4,17,2,18:3)
Block(4,17,3,18:3)
Block(4,17,4,18:3)
Block(4,17,5,18:3)
Block(4,17,6,18:3)
Block(4,17,8,18:3)
Block(4,18,-6,18:3)
Block(4,18,-5,18:3)
Block(4,18,-4,17:7)
Block(4,18,-2,18:3)
Block(4,18,-1,18:3)
Block(4,18,0,18:3)
Block(4,18,1,18:3)
Block(4,18,2,18:3)
Block(4,18,3,18:3)
Block(4,18,4,17:11)
Block(4,18,5,18:3)
Block(4,18,6,18:3)
Block(4,18,7,18:3)
Block(4,19,-6,18:3)
Block(4,19,-5,18:3)
Block(4,19,-4,18:3)
Block(4,19,-3,18:3)
Block(4,19,0,17:7)
Block(4,19,1,18:3)
Block(4,19,2,18:3)
Block(4,19,3,18:3)
Block(4,19,4,18:3)
Block(4,20,-2,18:3)
Block(4,20,0,18:3)
Block(4,20,1,18:3)
Block(4,20,2,18:3)
Block(4,20,4,18:3)
Block(4,20,5,18:3)
Block(4,21,0,18:3)
Block(5,14,-7,18:3)
Block(5,14,-6,18:3)
Block(5,14,-4,18:3)
Block(5,14,5,18:3)
Block(5,14,7,18:3)
Block(5,15,-9,18:3)
Block(5,15,-8,18:3)
Block(5,15,-7,18:3)
Block(5,15,-6,18:3)
Block(5,15,-5,18:3)
Block(5,15,-4,18:3)
Block(5,15,3,18:3)
Block(5,15,4,18:3)
Block(5,15,5,18:3)
Block(5,15,6,18:3)
Block(5,15,7,18:3)
Block(5,16,-8,18:3)
Block(5,16,-7,18:3)
Block(5,16,-6,17:7)
Block(5,16,-5,18:3)
Block(5,16,-4,18:3)
Block(5,16,0,18:3)
Block(5,16,3,18:3)
Block(5,16,4,18:3)
Block(5,16,5,18:3)
Block(5,16,6,17:7)
Block(5,16,7,18:3)
Block(5,16,8,18:3)
Block(5,17,-8,18:3)
Block(5,17,-6,18:3)
Block(5,17,-5,18:3)
Block(5,17,-4,18:3)
Block(5,17,-2,18:3)
Block(5,17,4,18:3)
Block(5,17,5,18:3)
Block(5,17,6,18:3)
Block(5,17,8,18:3)
Block(5,17,9,18:3)
Block(5,18,-7,18:3)
Block(5,18,-6,18:3)
Block(5,18,-5,17:7)
Block(5,18,-4,18:3)
Block(5,18,-3,18:3)
Block(5,18,-2,18:3)
Block(5,18,-1,18:3)
Block(5,18,0,17:7)
Block(5,18,1,18:3)
Block(5,18,2,18:3)
Block(5,18,4,18:3)
Block(5,18,5,17:11)
Block(5,18,6,18:3)
Block(5,18,7,18:3)
Block(5,19,-6,18:3)
Block(5,19,-5,18:3)
Block(5,19,-2,18:3)
Block(5,19,0,18:3)
Block(5,19,1,18:3)
Block(5,19,4,18:3)
Block(5,19,6,18:3)
Block(5,20,-4,18:3)
Block(5,20,-3,18:3)
Block(5,20,-1,18:3)
Block(5,20,0,18:3)
Block(5,20,1,18:3)
Block(5,20,4,18:3)
Block(6,13,-10,106:1)
Block(6,14,-10,106:1)
Block(6,14,-7,18:3)
Block(6,14,-6,18:3)
Block(6,14,-5,18:3)
Block(6,14,4,18:3)
Block(6,14,5,18:3)
Block(6,14,6,18:3)
Block(6,14,7,18:3)
Block(6,15,-10,106:1)
Block(6,15,-9,18:3)
Block(6,15,-6,17:3)
Block(6,15,-5,18:3)
Block(6,15,-4,18:3)
Block(6,15,3,18:3)
Block(6,15,4,18:3)
Block(6,15,6,17:3)
Block(6,15,7,18:3)
Block(6,15,8,18:3)
Block(6,15,9,106:4)
Block(6,16,-7,18:3)
Block(6,16,-6,17:3)
Block(6,16,-5,17:11)
Block(6,16,-4,18:3)
Block(6,16,-3,18:3)
Block(6,16,0,18:3)
Block(6,16,3,18:3)
Block(6,16,4,18:3)
Block(6,16,5,17:11)
Block(6,16,6,17:3)
Block(6,16,7,18:3)
Block(6,17,-7,18:3)
Block(6,17,-6,17:3)
Block(6,17,-5,18:3)
Block(6,17,-4,18:3)
Block(6,17,-2,18:3)
Block(6,17,0,18:3)
Block(6,17,3,18:3)
Block(6,17,4,18:3)
Block(6,17,5,18:3)
Block(6,17,6,17:3)
Block(6,17,7,18:3)
Block(6,17,8,18:3)
Block(6,18,-7,18:3)
Block(6,18,-6,18:3)
Block(6,18,-5,18:3)
Block(6,18,-4,18:3)
Block(6,18,-3,18:3)
Block(6,18,-2,18:3)
Block(6,18,-1,17:11)
Block(6,18,0,17:7)
Block(6,18,1,17:11)
Block(6,18,2,18:3)
Block(6,18,3,18:3)
Block(6,18,4,18:3)
Block(6,18,5,18:3)
Block(6,18,7,18:3)
Block(6,19,-1,18:3)
Block(6,19,0,18:3)
Block(6,19,1,18:3)
Block(6,19,4,18:3)
Block(6,20,-1,18:3)
Block(6,20,0,18:3)
Block(6,20,1,18:3)
Block(7,10,-7,106:1)
Block(7,11,-7,106:1)
Block(7,12,-7,106:1)
Block(7,13,-7,106:1)
Block(7,14,-7,106:1)
Block(7,14,-5,18:3)
Block(7,14,4,18:3)
Block(7,14,5,18:3)
Block(7,14,7,18:3)
Block(7,14,8,18:3)
Block(7,15,-7,106:1)
Block(7,15,-6,18:3)
Block(7,15,-5,18:3)
Block(7,15,-3,18:3)
Block(7,15,-2,18:3)
Block(7,15,-1,18:3)
Block(7,15,0,18:3)
Block(7,15,1,18:3)
Block(7,15,6,18:3)
Block(7,15,7,18:3)
Block(7,16,-7,18:3)
Block(7,16,-6,18:3)
Block(7,16,-4,18:3)
Block(7,16,-3,18:3)
Block(7,16,-2,18:3)
Block(7,16,-1,18:3)
Block(7,16,0,18:3)
Block(7,16,1,18:3)
Block(7,16,2,18:3)
Block(7,16,4,18:3)
Block(7,16,5,18:3)
Block(7,16,7,18:3)
Block(7,16,8,18:3)
Block(7,17,-6,18:3)
Block(7,17,-2,18:3)
Block(7,17,-1,18:3)
Block(7,17,0,18:3)
Block(7,17,1,18:3)
Block(7,17,2,18:3)
Block(7,17,5,18:3)
Block(7,17,6,18:3)
Block(7,17,7,18:3)
Block(7,18,-4,18:3)
Block(7,18,0,17:7)
Block(7,18,2,18:3)
Block(7,20,0,18:3)
Block(7,20,1,18:3)
Block(8,14,-2,18:3)
Block(8,14,2,18:3)
Block(8,14,4,18:3)
Block(8,15,-5,18:3)
Block(8,15,-4,106:4)
Block(8,15,-3,18:3)
Block(8,15,-1,18:3)
Block(8,15,1,18:3)
Block(8,15,5,18:3)
Block(8,15,6,18:3)
Block(8,15,7,106:2)
Block(8,16,-6,18:3)
Block(8,16,-3,18:3)
Block(8,16,-2,18:3)
Block(8,16,-1,18:3)
Block(8,16,0,18:3)
Block(8,16,1,18:3)
Block(8,16,2,18:3)
Block(8,16,4,18:3)
Block(8,16,5,18:3)
Block(8,17,-5,18:3)
Block(8,17,-3,18:3)
Block(8,17,-2,18:3)
Block(8,17,-1,18:3)
Block(8,17,0,17:3)
Block(8,17,1,18:3)
Block(8,17,4,18:3)
Block(8,17,5,18:3)
Block(8,18,-2,18:3)
Block(8,18,-1,18:3)
Block(8,18,0,18:3)
Block(8,18,1,18:3)
Block(8,19,-1,18:3)
Block(8,19,0,18:3)
Block(9,11,6,106:2)
Block(9,12,-5,106:2)
Block(9,12,6,106:2)
Block(9,13,-5,106:2)
Block(9,13,6,106:2)
Block(9,14,-5,106:2)
Block(9,14,-3,18:3)
Block(9,14,-2,18:3)
Block(9,14,-1,18:3)
Block(9,14,0,18:3)
Block(9,14,1,18:3)
Block(9,14,2,18:3)
Block(9,14,3,18:3)
Block(9,14,6,106:2)
Block(9,15,-5,106:2)
Block(9,15,-3,106:2)
Block(9,15,-1,18:3)
Block(9,15,0,17:3)
Block(9,15,1,18:3)
Block(9,15,6,106:2)
Block(9,16,-3,18:3)
Block(9,16,-2,18:3)
Block(9,16,-1,17:11)
Block(9,16,0,17:3)
Block(9,16,1,17:11)
Block(9,16,2,18:3)
Block(9,16,3,18:3)
Block(9,17,-3,18:3)
Block(9,17,-2,18:3)
Block(9,17,-1,18:3)
Block(9,17,0,18:3)
Block(9,17,1,18:3)
Block(9,17,4,18:3)
Block(9,18,-2,18:3)
Block(9,18,-1,18:3)
Block(9,18,0,18:3)
Block(10,11,4,106:4)
Block(10,12,4,106:4)
Block(10,13,4,106:4)
Block(10,14,-2,18:3)
Block(10,14,0,18:3)
Block(10,14,4,106:4)
Block(10,15,0,18:3)
Block(10,15,1,18:3)
Block(10,15,2,18:3)
Block(10,15,3,18:3)
Block(10,15,4,106:4)
Block(10,16,-2,18:3)
Block(10,16,-1,18:3)
Block(10,16,0,18:3)
Block(10,16,1,18:3)
Block(10,17,-1,18:3)
Block(10,17,0,18:3)
Block(10,18,-1,18:3)
Block(11,12,1,106:2)
Block(11,13,0,106:2)
Block(11,13,1,106:2)
Block(11,14,0,106:2)
Block(11,14,1,106:2)
Block(11,15,-2,18:3)
Block(11,15,0,106:2)
Block(11,15,1,106:2)
Block(11,15,2,18:3)
Block(11,15,3,106:4)
Block(11,16,-3,18:3)
Block(11,16,-2,18:3)
Block(11,16,0,18:3)
Block(11,17,-2,18:3)
Block(11,17,-1,18:3)
Block(12,9,-2,106:2)
Block(12,10,-2,106:2)
Block(12,11,-2,106:2)
Block(12,12,-2,106:2)
Block(12,13,-2,106:2)
Block(12,14,-2,106:2)
Block(12,15,-2,106:2)
Block(12,15,2,106:2)


#######################################################################
# +-----------------------------------------------------------------+ #
# |                             Entities                            | #
# +-----------------------------------------------------------------+ #
#######################################################################

# Entity() spawns an entity instead of a block. The entity is spawned only once when the BO3 is spawned.
# Entities are persistent by default so they don't de-spawn when no player is near, they are only unloaded.
# Usage: Entity(x,y,z,mobName,groupSize,NameTagOrNBTFileName) or Entity(x,y,z,mobName,groupSize)
# Use /tc entities or /otg entities to get a list of entities that can be used as mobName, this includes entities added by other mods.
# NameTagOrNBTFileName can be either a nametag for the mob or an nbt file (such as mymobinfo.nbt or mymobinfo.txt).
# When using a text file you can use the same mob spawning parameters used with the /summon command to equip the
# entity and give it custom attributes etc. You can copy the DATA part of a summon command including surrounding
# curly braces to a .txt file, for instance for: "/summon Skeleton x y z {DATA}"

#######################################################################
# +-----------------------------------------------------------------+ #
# |                            BO3 checks                           | #
# +-----------------------------------------------------------------+ #
#######################################################################

# Require a condition at a certain location in order for the BO3 to be spawned.
# BlockCheck(x,y,z,BlockName[,BlockName[,...]]) - one of the blocks must be at the location
# BlockCheckNot(x,y,z,BlockName[,BlockName[,...]]) - all the blocks must not be at the location
# LightCheck(x,y,z,minLightLevel,maxLightLevel) - light must be between min and max (inclusive)

# You can use "Solid" as a BlockName for matching all solid blocks or "All" to match all blocks that aren't air.

# Examples:
#   BlockCheck(0,-1,0,GRASS,DIRT)  Require grass or dirt just below the object
#   BlockCheck(0,-1,0,Solid)       Require any solid block just below the object
#   BlockCheck(0,-1,0,WOOL)        Require any type of wool just below the object
#   BlockCheck(0,-1,0,WOOL:0)      Require white wool just below the object
#   BlockCheckNot(0,-1,0,WOOL:0)   Require that there is no white wool below the object
#   LightCheck(0,0,0,0,1)          Require almost complete darkness just below the object
BlockCheck(0,10,0,AIR)
BlockCheck(0,5,0,AIR)
BlockCheck(0,2,0,AIR)
BlockCheck(-4,0,-4,Solid)
BlockCheck(-3,0,-4,Solid)
BlockCheck(-2,0,-4,Solid)
BlockCheck(-1,0,-4,Solid)
BlockCheck(0,0,-4,Solid)
BlockCheck(1,0,-4,Solid)
BlockCheck(2,0,-4,Solid)
BlockCheck(3,0,-4,Solid)
BlockCheck(4,0,-4,Solid)
BlockCheck(-4,0,-3,Solid)
BlockCheck(-3,0,-3,Solid)
BlockCheck(-2,0,-3,Solid)
BlockCheck(-1,0,-3,Solid)
BlockCheck(0,0,-3,Solid)
BlockCheck(1,0,-3,Solid)
BlockCheck(2,0,-3,Solid)
BlockCheck(3,0,-3,Solid)
BlockCheck(4,0,-3,Solid)
BlockCheck(-4,0,-2,Solid)
BlockCheck(-3,0,-2,Solid)
BlockCheck(-2,0,-2,Solid)
BlockCheck(-1,0,-2,Solid)
BlockCheck(0,0,-2,Solid)
BlockCheck(1,0,-2,Solid)
BlockCheck(2,0,-2,Solid)
BlockCheck(3,0,-2,Solid)
BlockCheck(4,0,-2,Solid)
BlockCheck(-4,0,-1,Solid)
BlockCheck(-3,0,-1,Solid)
BlockCheck(-2,0,-1,Solid)
BlockCheck(-1,0,-1,Solid)
BlockCheck(0,0,-1,Solid)
BlockCheck(1,0,-1,Solid)
BlockCheck(2,0,-1,Solid)
BlockCheck(3,0,-1,Solid)
BlockCheck(4,0,-1,Solid)
BlockCheck(-4,0,0,Solid)
BlockCheck(-3,0,0,Solid)
BlockCheck(-2,0,0,Solid)
BlockCheck(-1,0,0,Solid)
BlockCheck(0,0,0,Solid)
BlockCheck(1,0,0,Solid)
BlockCheck(2,0,0,Solid)
BlockCheck(3,0,0,Solid)
BlockCheck(4,0,0,Solid)
BlockCheck(-4,0,1,Solid)
BlockCheck(-3,0,1,Solid)
BlockCheck(-2,0,1,Solid)
BlockCheck(-1,0,1,Solid)
BlockCheck(0,0,1,Solid)
BlockCheck(1,0,1,Solid)
BlockCheck(2,0,1,Solid)
BlockCheck(3,0,1,Solid)
BlockCheck(4,0,1,Solid)
BlockCheck(-4,0,2,Solid)
BlockCheck(-3,0,2,Solid)
BlockCheck(-2,0,2,Solid)
BlockCheck(-1,0,2,Solid)
BlockCheck(0,0,2,Solid)
BlockCheck(1,0,2,Solid)
BlockCheck(2,0,2,Solid)
BlockCheck(3,0,2,Solid)
BlockCheck(4,0,2,Solid)
BlockCheck(-4,0,3,Solid)
BlockCheck(-3,0,3,Solid)
BlockCheck(-2,0,3,Solid)
BlockCheck(-1,0,3,Solid)
BlockCheck(0,0,3,Solid)
BlockCheck(1,0,3,Solid)
BlockCheck(2,0,3,Solid)
BlockCheck(3,0,3,Solid)
BlockCheck(4,0,3,Solid)
BlockCheck(-4,0,4,Solid)
BlockCheck(-3,0,4,Solid)
BlockCheck(-2,0,4,Solid)
BlockCheck(-1,0,4,Solid)
BlockCheck(0,0,4,Solid)
BlockCheck(1,0,4,Solid)
BlockCheck(2,0,4,Solid)
BlockCheck(3,0,4,Solid)
BlockCheck(4,0,4,Solid)

