#######################################################################
# +-----------------------------------------------------------------+ #
# |                            BO3 object                           | #
# +-----------------------------------------------------------------+ #
#######################################################################

# The descriptions in this file are accurate only for TerrainControl and OTG.
# For MCW and OTG+ these descriptions are only accurate if the BO3 is used as a CustomObject.
# MCW and OTG+ completely reimplemented CustomStructure, check the MCW/OTG+ documentation for more information.

# This is the config file of a custom object.
# If you add this object correctly to your BiomeConfigs, it will spawn in the world.

# This is the creator of this BO3 object
Author: Unknown

# A short description of this BO3 object
Description: This BO3 was converted from a schematic using OTGEdit. The author and description information of the schematic could not be found. If you know who the author of the schematic is then please add this information.

# The BO3 version, don't change this! It can be used by external applications to do a version check.
Version: 3

# The settings mode, WriteAll, WriteWithoutComments or WriteDisable. See WorldConfig.
SettingsMode: WriteDisable

#######################################################################
# +-----------------------------------------------------------------+ #
# |                          Main settings                          | #
# +-----------------------------------------------------------------+ #
#######################################################################

# This needs to be set to true to spawn the object in the Tree and Sapling resources.
Tree: false

# The frequency of the BO3 from 1 to 200. Tries this many times to spawn this BO3 when using the CustomObject(...) resource.
# Ignored by Tree(..), Sapling(..) and CustomStructure(..)
Frequency: 40

# The rarity of the BO3 from 0 to 100. Each spawn attempt has rarity% chance to succeed when using the CustomObject(...) resource.
# Ignored by Tree(..), Sapling(..) and CustomStructure(..)
Rarity: 100.0

# If you set this to true, the BO3 will be placed with a random rotation.
RotateRandomly: true

# The spawn height of the BO3 - randomY, highestBlock or highestSolidBlock.
SpawnHeight: randomY

# The height limits for the BO3.
MinHeight: 0

MaxHeight: 256

# Objects can have other objects attached to it: branches. Branches can also
# have branches attached to it, which can also have branches, etc. This is the
# maximum branch depth for this objects.
MaxBranchDepth: 10

# When spawned with the UseWorld keyword, this BO3 should NOT spawn in the following biomes.
# If you writer.write the BO3 name directly in the BiomeConfigs, this will be ignored.
ExcludedBiomes: All

# To optimise this BO3 for faster loading times you can use Notepad++ to find/replace comments and abbreviate things.
# Notepad++ find/replace with regex:
# Find: ^[#;].* replace to nothing removes all lines starting with # 
# Find: ^\s*$ replace to nothing removes most empty lines 
# Notepad++ find/replace without regex:
# *Warning: This will only work for OTG 1.10.2 v21 / OTG 1.11.2 v6 or higher. B( is not recognised by lower versions.
# Find: Block( replace to B(

#######################################################################
# +-----------------------------------------------------------------+ #
# |                      Source block settings                      | #
# +-----------------------------------------------------------------+ #
#######################################################################

# The block(s) the BO3 should spawn in.
SourceBlocks: AIR

# The maximum percentage of the BO3 that can be outside the SourceBlock.
# The BO3 won't be placed on a location with more blocks outside the SourceBlock than this percentage.
MaxPercentageOutsideSourceBlock: 100

# What to do when a block is about to be placed outside the SourceBlock? (dontPlace, placeAnyway)
OutsideSourceBlock: placeAnyway

#######################################################################
# +-----------------------------------------------------------------+ #
# |                              Blocks                             | #
# +-----------------------------------------------------------------+ #
#######################################################################

# All the blocks used in the BO3 are listed here. Possible blocks:
# Block(x,y,z,id[.data][,nbtfile.nbt) or B(x,y,z,id[.data][,nbtfile.nbt)
# RandomBlock(x,y,z,id[:data][,nbtfile.nbt],chance[,id[:data][,nbtfile.nbt],chance[,...]])
# So RandomBlock(0,0,0,CHEST,chest.nbt,50,CHEST,anotherchest.nbt,100) will spawn a chest at
# the BO3 origin, and give it a 50% chance to have the contents of chest.nbt, or, if that
# fails, a 100% percent chance to have the contents of anotherchest.nbt.

Block(-14,18,-2,106:8)
Block(-14,19,-2,106:8)
Block(-14,20,-2,106:8)
Block(-14,20,-1,18:3)
Block(-14,21,-2,106:8)
Block(-14,21,-1,106:8)
Block(-14,22,-2,18:3)
Block(-14,22,1,18:3)
Block(-14,23,-3,18:3)
Block(-13,19,-3,106:8)
Block(-13,19,2,106:8)
Block(-13,20,-3,106:8)
Block(-13,20,-2,18:3)
Block(-13,20,-1,18:3)
Block(-13,20,0,18:3)
Block(-13,20,2,106:8)
Block(-13,21,-3,106:8)
Block(-13,21,-2,18:3)
Block(-13,21,-1,18:3)
Block(-13,21,0,106:8)
Block(-13,21,2,106:8)
Block(-13,22,-4,18:3)
Block(-13,22,-3,18:3)
Block(-13,22,-2,18:3)
Block(-13,22,-1,18:3)
Block(-13,22,0,18:3)
Block(-13,22,1,18:3)
Block(-13,23,-3,18:3)
Block(-13,23,-2,18:3)
Block(-13,23,1,18:3)
Block(-13,24,-4,18:3)
Block(-13,24,-3,18:3)
Block(-13,24,-1,18:3)
Block(-13,24,2,18:3)
Block(-12,18,-5,106:1)
Block(-12,19,-5,106:1)
Block(-12,19,-1,18:3)
Block(-12,19,0,18:3)
Block(-12,20,-5,106:1)
Block(-12,20,-3,18:3)
Block(-12,20,-1,18:3)
Block(-12,21,-5,106:1)
Block(-12,21,-4,18:3)
Block(-12,21,-3,18:3)
Block(-12,21,-1,18:3)
Block(-12,21,0,18:3)
Block(-12,21,1,18:3)
Block(-12,21,2,18:3)
Block(-12,22,-5,18:3)
Block(-12,22,-4,18:3)
Block(-12,22,-2,18:3)
Block(-12,22,-1,18:3)
Block(-12,22,2,18:3)
Block(-12,22,3,18:3)
Block(-12,23,-5,18:3)
Block(-12,23,-3,18:3)
Block(-12,23,-1,18:3)
Block(-12,23,1,18:3)
Block(-12,23,2,18:3)
Block(-12,24,-2,18:3)
Block(-12,24,-1,18:3)
Block(-12,24,1,18:3)
Block(-12,25,-3,18:3)
Block(-12,25,-2,18:3)
Block(-12,25,2,18:3)
Block(-12,26,0,18:3)
Block(-12,27,-1,18:3)
Block(-11,19,-2,18:3)
Block(-11,19,-1,18:3)
Block(-11,20,-3,18:3)
Block(-11,20,-2,18:3)
Block(-11,20,-1,18:3)
Block(-11,20,0,18:3)
Block(-11,21,-5,106:1)
Block(-11,21,-4,18:3)
Block(-11,21,-3,18:3)
Block(-11,21,-2,18:3)
Block(-11,21,-1,17:3)
Block(-11,21,0,18:3)
Block(-11,21,1,18:3)
Block(-11,22,-8,18:3)
Block(-11,22,-4,18:3)
Block(-11,22,-3,18:3)
Block(-11,22,-2,18:3)
Block(-11,22,-1,17:3)
Block(-11,22,0,18:3)
Block(-11,22,1,18:3)
Block(-11,22,2,18:3)
Block(-11,23,-5,18:3)
Block(-11,23,-3,17:11)
Block(-11,23,-2,17:11)
Block(-11,23,-1,17:3)
Block(-11,23,0,17:11)
Block(-11,23,1,17:11)
Block(-11,23,2,18:3)
Block(-11,23,3,18:3)
Block(-11,24,-5,18:3)
Block(-11,24,-4,18:3)
Block(-11,24,-3,18:3)
Block(-11,24,-1,17:3)
Block(-11,24,0,18:3)
Block(-11,24,1,18:3)
Block(-11,24,3,18:3)
Block(-11,25,-4,18:3)
Block(-11,25,-3,18:3)
Block(-11,25,-2,18:3)
Block(-11,25,-1,18:3)
Block(-11,25,0,18:3)
Block(-11,25,1,18:3)
Block(-11,26,-2,18:3)
Block(-11,26,-1,18:3)
Block(-11,26,0,18:3)
Block(-11,27,-2,18:3)
Block(-11,27,-1,18:3)
Block(-11,27,0,18:3)
Block(-10,16,-9,106:8)
Block(-10,17,-9,106:8)
Block(-10,18,-9,106:8)
Block(-10,19,-9,106:8)
Block(-10,19,-2,18:3)
Block(-10,19,1,106)
Block(-10,19,7,106:8)
Block(-10,20,-9,106:8)
Block(-10,20,-3,18:3)
Block(-10,20,-2,18:3)
Block(-10,20,0,18:3)
Block(-10,20,1,18:3)
Block(-10,20,7,106:8)
Block(-10,21,-9,106:8)
Block(-10,21,-3,18:3)
Block(-10,21,-2,18:3)
Block(-10,21,0,18:3)
Block(-10,21,1,18:3)
Block(-10,21,7,106:8)
Block(-10,22,-10,18:3)
Block(-10,22,-9,18:3)
Block(-10,22,-8,18:3)
Block(-10,22,-3,18:3)
Block(-10,22,-2,18:3)
Block(-10,22,-1,18:3)
Block(-10,22,1,18:3)
Block(-10,22,7,18:3)
Block(-10,22,8,18:3)
Block(-10,23,-9,18:3)
Block(-10,23,-8,18:3)
Block(-10,23,-5,18:3)
Block(-10,23,-3,18:3)
Block(-10,23,-2,18:3)
Block(-10,23,-1,17:7)
Block(-10,23,0,18:3)
Block(-10,23,1,18:3)
Block(-10,23,2,18:3)
Block(-10,23,6,18:3)
Block(-10,23,7,18:3)
Block(-10,24,-10,18:3)
Block(-10,24,-8,18:3)
Block(-10,24,-3,18:3)
Block(-10,24,-2,18:3)
Block(-10,24,-1,18:3)
Block(-10,24,0,18:3)
Block(-10,24,1,18:3)
Block(-10,24,6,18:3)
Block(-10,25,-4,18:3)
Block(-10,25,-3,18:3)
Block(-10,25,-2,18:3)
Block(-10,25,-1,17:3)
Block(-10,25,0,18:3)
Block(-10,25,1,18:3)
Block(-10,25,2,18:3)
Block(-10,25,3,18:3)
Block(-10,26,-3,18:3)
Block(-10,26,-2,18:3)
Block(-10,26,-1,18:3)
Block(-10,26,0,18:3)
Block(-10,26,1,18:3)
Block(-10,27,-3,18:3)
Block(-10,27,-2,18:3)
Block(-10,28,-2,18:3)
Block(-10,28,2,18:3)
Block(-9,17,1,106:4)
Block(-9,18,-3,106:2)
Block(-9,18,1,106:4)
Block(-9,19,-3,106:2)
Block(-9,19,1,106:4)
Block(-9,20,-10,18:3)
Block(-9,20,-9,18:3)
Block(-9,20,-8,106:8)
Block(-9,20,-3,106:2)
Block(-9,20,-2,18:3)
Block(-9,20,-1,18:3)
Block(-9,20,1,106:4)
Block(-9,20,7,18:3)
Block(-9,21,-9,18:3)
Block(-9,21,-8,106:8)
Block(-9,21,-3,106:2)
Block(-9,21,-2,18:3)
Block(-9,21,-1,18:3)
Block(-9,21,0,18:3)
Block(-9,21,1,106:4)
Block(-9,21,7,18:3)
Block(-9,21,8,18:3)
Block(-9,21,9,106:4)
Block(-9,22,-10,18:3)
Block(-9,22,-9,18:3)
Block(-9,22,-8,18:3)
Block(-9,22,-7,18:3)
Block(-9,22,-6,18:3)
Block(-9,22,-4,18:3)
Block(-9,22,-3,18:3)
Block(-9,22,-2,18:3)
Block(-9,22,-1,18:3)
Block(-9,22,0,18:3)
Block(-9,22,1,18:3)
Block(-9,22,2,18:3)
Block(-9,22,5,18:3)
Block(-9,22,6,18:3)
Block(-9,23,-11,18:3)
Block(-9,23,-10,18:3)
Block(-9,23,-9,18:3)
Block(-9,23,-8,18:3)
Block(-9,23,-7,18:3)
Block(-9,23,-4,18:3)
Block(-9,23,-3,18:3)
Block(-9,23,-2,18:3)
Block(-9,23,-1,17:7)
Block(-9,23,0,18:3)
Block(-9,23,1,18:3)
Block(-9,23,2,18:3)
Block(-9,23,4,18:3)
Block(-9,23,5,18:3)
Block(-9,23,6,18:3)
Block(-9,23,7,18:3)
Block(-9,23,8,18:3)
Block(-9,24,-9,18:3)
Block(-9,24,-3,18:3)
Block(-9,24,-2,18:3)
Block(-9,24,-1,18:3)
Block(-9,24,1,18:3)
Block(-9,24,5,18:3)
Block(-9,24,6,18:3)
Block(-9,24,7,18:3)
Block(-9,25,-10,18:3)
Block(-9,25,-9,18:3)
Block(-9,25,-7,18:3)
Block(-9,25,-2,18:3)
Block(-9,25,-1,18:3)
Block(-9,25,0,18:3)
Block(-9,25,6,18:3)
Block(-9,25,8,18:3)
Block(-9,26,-3,18:3)
Block(-9,26,-2,18:3)
Block(-9,26,-1,17:3)
Block(-9,26,1,18:3)
Block(-9,27,-4,18:3)
Block(-9,27,-3,18:3)
Block(-9,27,-2,18:3)
Block(-9,27,-1,18:3)
Block(-9,27,0,18:3)
Block(-9,27,1,18:3)
Block(-9,27,3,18:3)
Block(-9,27,5,18:3)
Block(-9,28,-3,18:3)
Block(-9,28,-2,18:3)
Block(-9,28,-1,18:3)
Block(-9,28,0,18:3)
Block(-9,28,1,18:3)
Block(-9,28,2,18:3)
Block(-8,18,-11,106:1)
Block(-8,19,-11,106:1)
Block(-8,19,-9,18:3)
Block(-8,19,0,106:2)
Block(-8,19,6,18:3)
Block(-8,20,-11,106:1)
Block(-8,20,-10,18:3)
Block(-8,20,-9,18:3)
Block(-8,20,0,106:2)
Block(-8,20,7,18:3)
Block(-8,20,8,18:3)
Block(-8,21,-11,106:1)
Block(-8,21,-10,18:3)
Block(-8,21,-9,18:3)
Block(-8,21,-8,18:3)
Block(-8,21,-7,18:3)
Block(-8,21,-1,18:3)
Block(-8,21,0,106:2)
Block(-8,21,5,18:3)
Block(-8,21,6,18:3)
Block(-8,21,7,18:3)
Block(-8,21,8,18:3)
Block(-8,21,9,18:3)
Block(-8,21,10,106:4)
Block(-8,22,-11,18:3)
Block(-8,22,-10,18:3)
Block(-8,22,-9,18:3)
Block(-8,22,-8,18:3)
Block(-8,22,-7,18:3)
Block(-8,22,-1,18:3)
Block(-8,22,0,18:3)
Block(-8,22,3,18:3)
Block(-8,22,5,18:3)
Block(-8,22,6,18:3)
Block(-8,22,7,18:3)
Block(-8,22,8,18:3)
Block(-8,22,9,18:3)
Block(-8,23,-10,18:3)
Block(-8,23,-9,17:7)
Block(-8,23,-8,18:3)
Block(-8,23,-7,18:3)
Block(-8,23,-5,18:3)
Block(-8,23,-3,18:3)
Block(-8,23,-1,18:3)
Block(-8,23,0,18:3)
Block(-8,23,3,18:3)
Block(-8,23,5,18:3)
Block(-8,23,6,18:3)
Block(-8,23,7,17:7)
Block(-8,23,8,18:3)
Block(-8,24,-9,18:3)
Block(-8,24,-8,18:3)
Block(-8,24,-7,18:3)
Block(-8,24,-2,18:3)
Block(-8,24,0,18:3)
Block(-8,24,5,18:3)
Block(-8,24,6,18:3)
Block(-8,24,7,18:3)
Block(-8,24,8,18:3)
Block(-8,24,9,18:3)
Block(-8,25,-11,18:3)
Block(-8,25,-10,18:3)
Block(-8,25,-8,18:3)
Block(-8,25,-7,18:3)
Block(-8,25,-4,18:3)
Block(-8,25,-1,18:3)
Block(-8,25,0,18:3)
Block(-8,25,1,18:3)
Block(-8,25,6,18:3)
Block(-8,25,7,18:3)
Block(-8,26,-7,18:3)
Block(-8,26,-5,18:3)
Block(-8,26,-4,18:3)
Block(-8,26,-2,18:3)
Block(-8,26,-1,18:3)
Block(-8,26,0,18:3)
Block(-8,26,1,18:3)
Block(-8,26,5,18:3)
Block(-8,26,6,18:3)
Block(-8,26,7,18:3)
Block(-8,27,-7,18:3)
Block(-8,27,-5,18:3)
Block(-8,27,-4,18:3)
Block(-8,27,-3,18:3)
Block(-8,27,-1,17:7)
Block(-8,27,0,18:3)
Block(-8,27,1,18:3)
Block(-8,27,3,18:3)
Block(-8,27,5,18:3)
Block(-8,27,6,18:3)
Block(-8,28,-4,18:3)
Block(-8,28,-3,18:3)
Block(-8,28,-1,18:3)
Block(-8,28,0,18:3)
Block(-8,28,1,18:3)
Block(-8,28,3,18:3)
Block(-8,29,-4,18:3)
Block(-8,29,1,18:3)
Block(-7,19,-10,18:3)
Block(-7,19,-9,18:3)
Block(-7,19,-5,106:4)
Block(-7,19,7,18:3)
Block(-7,20,-11,18:3)
Block(-7,20,-5,106:4)
Block(-7,20,7,18:3)
Block(-7,20,9,18:3)
Block(-7,21,-11,106:8)
Block(-7,21,-9,17:3)
Block(-7,21,-8,18:3)
Block(-7,21,-7,18:3)
Block(-7,21,-6,18:3)
Block(-7,21,-5,106:4)
Block(-7,21,5,18:3)
Block(-7,21,6,18:3)
Block(-7,21,7,17:3)
Block(-7,21,8,18:3)
Block(-7,22,-11,18:3)
Block(-7,22,-10,18:3)
Block(-7,22,-9,17:3)
Block(-7,22,-8,18:3)
Block(-7,22,-7,18:3)
Block(-7,22,-6,18:3)
Block(-7,22,-5,18:3)
Block(-7,22,-1,18:3)
Block(-7,22,3,18:3)
Block(-7,22,4,18:3)
Block(-7,22,5,18:3)
Block(-7,22,6,18:3)
Block(-7,22,7,17:3)
Block(-7,22,8,18:3)
Block(-7,23,-12,18:3)
Block(-7,23,-11,18:3)
Block(-7,23,-10,17:11)
Block(-7,23,-9,17:3)
Block(-7,23,-8,17:11)
Block(-7,23,-7,17:11)
Block(-7,23,-6,18:3)
Block(-7,23,0,18:3)
Block(-7,23,3,18:3)
Block(-7,23,4,18:3)
Block(-7,23,5,17:11)
Block(-7,23,6,17:11)
Block(-7,23,7,17:3)
Block(-7,23,8,17:11)
Block(-7,23,9,18:3)
Block(-7,24,-10,18:3)
Block(-7,24,-9,17:3)
Block(-7,24,-8,18:3)
Block(-7,24,-7,18:3)
Block(-7,24,-6,18:3)
Block(-7,24,-2,18:3)
Block(-7,24,4,18:3)
Block(-7,24,5,18:3)
Block(-7,24,6,18:3)
Block(-7,24,7,17:3)
Block(-7,25,-10,18:3)
Block(-7,25,-9,17:3)
Block(-7,25,-8,18:3)
Block(-7,25,-7,18:3)
Block(-7,25,-6,18:3)
Block(-7,25,-2,18:3)
Block(-7,25,0,18:3)
Block(-7,25,1,18:3)
Block(-7,25,2,18:3)
Block(-7,25,4,18:3)
Block(-7,25,5,18:3)
Block(-7,25,6,18:3)
Block(-7,25,7,17:3)
Block(-7,25,8,18:3)
Block(-7,26,-9,18:3)
Block(-7,26,-8,18:3)
Block(-7,26,-7,18:3)
Block(-7,26,-4,18:3)
Block(-7,26,-3,18:3)
Block(-7,26,-2,18:3)
Block(-7,26,1,18:3)
Block(-7,26,5,18:3)
Block(-7,26,6,18:3)
Block(-7,26,7,18:3)
Block(-7,27,-8,18:3)
Block(-7,27,-7,18:3)
Block(-7,27,-6,18:3)
Block(-7,27,-5,18:3)
Block(-7,27,-4,18:3)
Block(-7,27,-3,17:11)
Block(-7,27,-2,17:11)
Block(-7,27,-1,17:7)
Block(-7,27,0,17:11)
Block(-7,27,1,17:11)
Block(-7,27,2,18:3)
Block(-7,27,3,18:3)
Block(-7,27,4,18:3)
Block(-7,27,5,18:3)
Block(-7,28,-7,18:3)
Block(-7,28,-6,18:3)
Block(-7,28,-5,18:3)
Block(-7,28,-4,18:3)
Block(-7,28,-3,18:3)
Block(-7,28,-2,18:3)
Block(-7,28,-1,18:3)
Block(-7,28,1,18:3)
Block(-7,28,5,18:3)
Block(-7,28,6,18:3)
Block(-7,29,-4,18:3)
Block(-7,29,-3,18:3)
Block(-7,29,1,18:3)
Block(-7,29,2,18:3)
Block(-6,18,-12,106:1)
Block(-6,19,-12,106:1)
Block(-6,19,7,18:3)
Block(-6,20,-12,106:1)
Block(-6,20,-9,18:3)
Block(-6,20,4,106:1)
Block(-6,20,6,18:3)
Block(-6,20,7,18:3)
Block(-6,20,8,18:3)
Block(-6,20,9,106:4)
Block(-6,21,-12,106:1)
Block(-6,21,-11,18:3)
Block(-6,21,-10,18:3)
Block(-6,21,-9,18:3)
Block(-6,21,-8,18:3)
Block(-6,21,-7,18:3)
Block(-6,21,4,106:1)
Block(-6,21,5,18:3)
Block(-6,21,6,18:3)
Block(-6,21,7,18:3)
Block(-6,21,8,18:3)
Block(-6,21,9,106:4)
Block(-6,22,-10,18:3)
Block(-6,22,-9,18:3)
Block(-6,22,-8,18:3)
Block(-6,22,-7,18:3)
Block(-6,22,5,18:3)
Block(-6,22,6,18:3)
Block(-6,22,7,18:3)
Block(-6,22,8,18:3)
Block(-6,22,9,18:3)
Block(-6,22,10,18:3)
Block(-6,23,-11,18:3)
Block(-6,23,-10,18:3)
Block(-6,23,-9,17:7)
Block(-6,23,-8,18:3)
Block(-6,23,-7,18:3)
Block(-6,23,3,18:3)
Block(-6,23,5,18:3)
Block(-6,23,6,18:3)
Block(-6,23,7,17:7)
Block(-6,23,8,18:3)
Block(-6,23,9,18:3)
Block(-6,24,-9,18:3)
Block(-6,24,-8,18:3)
Block(-6,24,-7,18:3)
Block(-6,24,3,18:3)
Block(-6,24,4,18:3)
Block(-6,24,5,18:3)
Block(-6,24,6,18:3)
Block(-6,24,7,18:3)
Block(-6,24,8,18:3)
Block(-6,25,-10,18:3)
Block(-6,25,-9,18:3)
Block(-6,25,-7,18:3)
Block(-6,25,-6,18:3)
Block(-6,25,-4,18:3)
Block(-6,25,-3,18:3)
Block(-6,25,1,18:3)
Block(-6,25,4,18:3)
Block(-6,25,5,18:3)
Block(-6,25,6,18:3)
Block(-6,25,7,18:3)
Block(-6,25,8,18:3)
Block(-6,25,9,18:3)
Block(-6,26,-10,18:3)
Block(-6,26,-9,18:3)
Block(-6,26,-8,17:3)
Block(-6,26,-7,18:3)
Block(-6,26,-6,18:3)
Block(-6,26,-5,18:3)
Block(-6,26,-4,18:3)
Block(-6,26,-3,18:3)
Block(-6,26,-2,18:3)
Block(-6,26,2,18:3)
Block(-6,26,3,18:3)
Block(-6,26,4,18:3)
Block(-6,26,5,18:3)
Block(-6,26,6,17:3)
Block(-6,26,7,18:3)
Block(-6,27,-9,18:3)
Block(-6,27,-8,18:3)
Block(-6,27,-7,18:3)
Block(-6,27,-6,18:3)
Block(-6,27,-3,18:3)
Block(-6,27,-1,17:7)
Block(-6,27,0,18:3)
Block(-6,27,1,18:3)
Block(-6,27,2,18:3)
Block(-6,27,3,18:3)
Block(-6,27,4,18:3)
Block(-6,27,5,18:3)
Block(-6,27,6,18:3)
Block(-6,27,7,18:3)
Block(-6,27,8,18:3)
Block(-6,28,-8,18:3)
Block(-6,28,-7,18:3)
Block(-6,28,-5,18:3)
Block(-6,28,-1,18:3)
Block(-6,28,0,18:3)
Block(-6,28,1,18:3)
Block(-6,28,3,18:3)
Block(-6,28,6,18:3)
Block(-6,28,7,18:3)
Block(-6,29,-6,18:3)
Block(-6,29,-4,18:3)
Block(-6,29,-3,18:3)
Block(-6,29,-2,18:3)
Block(-6,29,-1,18:3)
Block(-6,29,1,18:3)
Block(-6,29,4,18:3)
Block(-6,29,5,18:3)
Block(-5,18,5,106:2)
Block(-5,19,-7,106:4)
Block(-5,19,5,106:2)
Block(-5,20,-11,106:1)
Block(-5,20,-8,18:3)
Block(-5,20,-7,106:4)
Block(-5,20,5,106:2)
Block(-5,20,6,18:3)
Block(-5,21,-11,106:1)
Block(-5,21,-10,18:3)
Block(-5,21,-9,18:3)
Block(-5,21,-8,18:3)
Block(-5,21,-7,106:4)
Block(-5,21,5,106:2)
Block(-5,21,6,18:3)
Block(-5,21,7,18:3)
Block(-5,22,-10,18:3)
Block(-5,22,-9,18:3)
Block(-5,22,-8,18:3)
Block(-5,22,-7,18:3)
Block(-5,22,5,18:3)
Block(-5,22,6,18:3)
Block(-5,22,7,18:3)
Block(-5,22,8,18:3)
Block(-5,22,9,18:3)
Block(-5,23,-11,18:3)
Block(-5,23,-10,18:3)
Block(-5,23,-9,17:7)
Block(-5,23,-8,18:3)
Block(-5,23,-7,18:3)
Block(-5,23,-6,18:3)
Block(-5,23,4,18:3)
Block(-5,23,5,18:3)
Block(-5,23,6,18:3)
Block(-5,23,7,17:7)
Block(-5,24,-12,18:3)
Block(-5,24,-11,18:3)
Block(-5,24,-10,18:3)
Block(-5,24,-8,18:3)
Block(-5,24,-7,18:3)
Block(-5,24,5,18:3)
Block(-5,24,6,18:3)
Block(-5,24,7,18:3)
Block(-5,24,8,18:3)
Block(-5,24,9,18:3)
Block(-5,25,-10,18:3)
Block(-5,25,-9,18:3)
Block(-5,25,-8,18:3)
Block(-5,25,-7,18:3)
Block(-5,25,4,18:3)
Block(-5,25,6,18:3)
Block(-5,25,8,18:3)
Block(-5,26,-11,18:3)
Block(-5,26,-10,18:3)
Block(-5,26,-9,18:3)
Block(-5,26,-8,18:3)
Block(-5,26,-6,18:3)
Block(-5,26,-4,18:3)
Block(-5,26,-3,18:3)
Block(-5,26,-2,18:3)
Block(-5,26,0,18:3)
Block(-5,26,1,18:3)
Block(-5,26,4,18:3)
Block(-5,26,5,18:3)
Block(-5,26,6,18:3)
Block(-5,26,8,18:3)
Block(-5,27,-9,18:3)
Block(-5,27,-8,18:3)
Block(-5,27,-7,17:11)
Block(-5,27,-6,18:3)
Block(-5,27,-4,18:3)
Block(-5,27,-3,18:3)
Block(-5,27,-1,18:3)
Block(-5,27,0,18:3)
Block(-5,27,1,18:3)
Block(-5,27,2,18:3)
Block(-5,27,4,18:3)
Block(-5,27,5,17:7)
Block(-5,28,-9,18:3)
Block(-5,28,-1,17:7)
Block(-5,28,0,18:3)
Block(-5,28,1,18:3)
Block(-5,28,2,18:3)
Block(-5,28,5,18:3)
Block(-5,28,6,18:3)
Block(-5,28,7,18:3)
Block(-5,29,-7,18:3)
Block(-5,29,-3,18:3)
Block(-5,29,4,18:3)
Block(-5,29,6,18:3)
Block(-4,0,-2,17:3)
Block(-4,0,-1,17:3)
Block(-4,0,0,17:3)
Block(-4,0,1,17:3)
Block(-4,0,2,17:3)
Block(-4,1,-1,17:3)
Block(-4,1,0,17:3)
Block(-4,1,1,17:3)
Block(-4,2,-1,17:3)
Block(-4,2,0,17:3)
Block(-4,2,1,17:3)
Block(-4,21,6,106:1)
Block(-4,21,7,18:3)
Block(-4,22,-11,18:3)
Block(-4,22,-10,18:3)
Block(-4,22,-8,18:3)
Block(-4,23,-11,18:3)
Block(-4,23,-10,18:3)
Block(-4,23,-9,18:3)
Block(-4,23,-8,18:3)
Block(-4,23,-7,18:3)
Block(-4,23,5,18:3)
Block(-4,23,6,18:3)
Block(-4,23,7,18:3)
Block(-4,23,9,18:3)
Block(-4,24,-13,18:3)
Block(-4,24,-11,18:3)
Block(-4,24,-10,18:3)
Block(-4,24,-9,18:3)
Block(-4,24,-8,18:3)
Block(-4,24,5,18:3)
Block(-4,24,6,18:3)
Block(-4,24,7,18:3)
Block(-4,25,-9,18:3)
Block(-4,25,-8,18:3)
Block(-4,25,-7,18:3)
Block(-4,25,5,18:3)
Block(-4,25,6,18:3)
Block(-4,25,7,18:3)
Block(-4,26,-9,18:3)
Block(-4,26,-8,18:3)
Block(-4,26,-7,18:3)
Block(-4,26,-2,18:3)
Block(-4,26,-1,18:3)
Block(-4,26,0,18:3)
Block(-4,26,5,18:3)
Block(-4,26,6,18:3)
Block(-4,26,7,18:3)
Block(-4,27,-9,18:3)
Block(-4,27,-8,18:3)
Block(-4,27,-7,18:3)
Block(-4,27,-6,17:11)
Block(-4,27,-5,18:3)
Block(-4,27,-4,18:3)
Block(-4,27,-2,18:3)
Block(-4,27,4,17:7)
Block(-4,27,5,18:3)
Block(-4,27,6,18:3)
Block(-4,27,7,18:3)
Block(-4,28,-7,18:3)
Block(-4,28,-4,18:3)
Block(-4,28,-3,18:3)
Block(-4,28,-2,17:11)
Block(-4,28,-1,17:7)
Block(-4,28,0,17:11)
Block(-4,28,1,18:3)
Block(-4,28,2,18:3)
Block(-4,28,3,18:3)
Block(-4,28,4,18:3)
Block(-4,28,5,18:3)
Block(-4,28,6,18:3)
Block(-4,29,-7,18:3)
Block(-4,29,-6,18:3)
Block(-4,29,-4,18:3)
Block(-4,29,-3,18:3)
Block(-4,29,-1,18:3)
Block(-4,29,1,18:3)
Block(-4,29,4,18:3)
Block(-4,29,5,18:3)
Block(-4,29,6,18:3)
Block(-4,30,-2,18:3)
Block(-4,30,0,18:3)
Block(-3,0,-6,17:3)
Block(-3,0,-5,17:3)
Block(-3,0,-4,17:3)
Block(-3,0,-3,17:3)
Block(-3,0,-2,17:3)
Block(-3,0,-1,17:3)
Block(-3,0,0,17:3)
Block(-3,0,1,17:3)
Block(-3,0,2,17:3)
Block(-3,0,3,17:3)
Block(-3,1,-6,17:3)
Block(-3,1,-5,17:3)
Block(-3,1,-3,17:3)
Block(-3,1,-2,17:3)
Block(-3,1,-1,17:3)
Block(-3,1,0,17:3)
Block(-3,1,1,17:3)
Block(-3,1,2,17:3)
Block(-3,2,-1,17:3)
Block(-3,2,0,17:3)
Block(-3,2,1,17:3)
Block(-3,3,-1,17:3)
Block(-3,3,0,17:3)
Block(-3,4,-1,17:3)
Block(-3,4,0,17:3)
Block(-3,18,-14,106:8)
Block(-3,18,10,106:8)
Block(-3,19,-14,106:8)
Block(-3,19,7,106:2)
Block(-3,19,10,106:8)
Block(-3,20,-14,106:8)
Block(-3,20,7,106:2)
Block(-3,20,10,106:8)
Block(-3,21,-14,106:8)
Block(-3,21,7,106:2)
Block(-3,21,10,106:8)
Block(-3,22,-14,18:3)
Block(-3,22,7,18:3)
Block(-3,22,8,18:3)
Block(-3,22,10,18:3)
Block(-3,23,-13,18:3)
Block(-3,23,-12,18:3)
Block(-3,23,-10,18:3)
Block(-3,23,-9,18:3)
Block(-3,23,-8,18:3)
Block(-3,23,5,18:3)
Block(-3,23,7,18:3)
Block(-3,23,10,18:3)
Block(-3,23,11,18:3)
Block(-3,24,-13,18:3)
Block(-3,24,-12,18:3)
Block(-3,24,-10,18:3)
Block(-3,24,-9,18:3)
Block(-3,24,6,18:3)
Block(-3,24,8,18:3)
Block(-3,24,11,18:3)
Block(-3,24,12,18:3)
Block(-3,26,-8,18:3)
Block(-3,26,-7,18:3)
Block(-3,26,-6,18:3)
Block(-3,26,-5,18:3)
Block(-3,26,-4,18:3)
Block(-3,26,-3,18:3)
Block(-3,26,-1,18:3)
Block(-3,26,0,18:3)
Block(-3,26,2,18:3)
Block(-3,26,5,18:3)
Block(-3,26,6,18:3)
Block(-3,26,7,18:3)
Block(-3,26,8,18:3)
Block(-3,27,-10,18:3)
Block(-3,27,-7,18:3)
Block(-3,27,-4,18:3)
Block(-3,27,-3,18:3)
Block(-3,27,-2,18:3)
Block(-3,27,0,18:3)
Block(-3,27,4,18:3)
Block(-3,27,5,18:3)
Block(-3,27,7,18:3)
Block(-3,28,-5,17:11)
Block(-3,28,-4,18:3)
Block(-3,28,-2,18:3)
Block(-3,28,-1,17:7)
Block(-3,28,0,18:3)
Block(-3,28,1,18:3)
Block(-3,28,2,18:3)
Block(-3,28,3,17:7)
Block(-3,28,4,18:3)
Block(-3,28,5,18:3)
Block(-3,28,7,18:3)
Block(-3,29,-2,18:3)
Block(-3,29,-1,18:3)
Block(-3,29,0,18:3)
Block(-3,29,1,18:3)
Block(-3,29,2,18:3)
Block(-3,30,-5,18:3)
Block(-3,30,-2,18:3)
Block(-3,30,-1,18:3)
Block(-2,0,-6,17:3)
Block(-2,0,-5,17:3)
Block(-2,0,-4,17:3)
Block(-2,0,-3,17:3)
Block(-2,0,-2,17:3)
Block(-2,0,-1,17:3)
Block(-2,0,0,17:3)
Block(-2,0,1,17:3)
Block(-2,0,2,17:3)
Block(-2,0,3,17:3)
Block(-2,0,4,17:3)
Block(-2,1,-6,17:3)
Block(-2,1,-5,17:3)
Block(-2,1,-4,17:3)
Block(-2,1,-3,17:3)
Block(-2,1,-2,17:3)
Block(-2,1,-1,17:3)
Block(-2,1,0,17:3)
Block(-2,1,1,17:3)
Block(-2,1,2,17:3)
Block(-2,1,3,17:3)
Block(-2,1,4,17:3)
Block(-2,2,-5,17:3)
Block(-2,2,-4,17:3)
Block(-2,2,-2,17:3)
Block(-2,2,-1,17:3)
Block(-2,2,0,17:3)
Block(-2,2,1,17:3)
Block(-2,2,2,17:3)
Block(-2,3,-2,17:3)
Block(-2,3,-1,17:3)
Block(-2,3,0,17:3)
Block(-2,3,1,17:3)
Block(-2,3,2,17:3)
Block(-2,4,-1,17:3)
Block(-2,4,0,17:3)
Block(-2,4,1,17:3)
Block(-2,5,-2,106:8)
Block(-2,5,-1,17:3)
Block(-2,5,0,17:3)
Block(-2,6,-1,17:3)
Block(-2,6,0,17:3)
Block(-2,7,-2,106:8)
Block(-2,7,-1,106:8)
Block(-2,8,-1,106:8)
Block(-2,9,-1,106:8)
Block(-2,9,0,106:8)
Block(-2,10,-1,106:8)
Block(-2,10,0,106:8)
Block(-2,11,-1,106:8)
Block(-2,12,-1,106:8)
Block(-2,13,-1,106:8)
Block(-2,17,12,106:8)
Block(-2,18,12,106:8)
Block(-2,19,-15,106:1)
Block(-2,19,12,106:8)
Block(-2,20,-15,106:1)
Block(-2,20,9,106:1)
Block(-2,20,11,18:3)
Block(-2,20,12,106:8)
Block(-2,21,-15,106:1)
Block(-2,21,-14,18:3)
Block(-2,21,9,106:1)
Block(-2,21,10,18:3)
Block(-2,21,11,106:8)
Block(-2,21,12,106:8)
Block(-2,22,-14,18:3)
Block(-2,22,-13,18:3)
Block(-2,22,-12,18:3)
Block(-2,22,11,18:3)
Block(-2,23,-15,18:3)
Block(-2,23,-14,18:3)
Block(-2,23,-13,18:3)
Block(-2,23,-11,18:3)
Block(-2,23,-10,18:3)
Block(-2,23,-8,18:3)
Block(-2,23,9,18:3)
Block(-2,23,10,18:3)
Block(-2,23,11,18:3)
Block(-2,23,12,18:3)
Block(-2,24,-13,18:3)
Block(-2,24,-12,18:3)
Block(-2,24,-11,18:3)
Block(-2,24,9,18:3)
Block(-2,24,10,18:3)
Block(-2,24,11,18:3)
Block(-2,24,12,18:3)
Block(-2,24,13,18:3)
Block(-2,25,-13,18:3)
Block(-2,25,-10,18:3)
Block(-2,25,-9,18:3)
Block(-2,25,7,18:3)
Block(-2,25,11,18:3)
Block(-2,25,12,18:3)
Block(-2,26,-3,18:3)
Block(-2,26,-1,18:3)
Block(-2,26,0,18:3)
Block(-2,26,2,18:3)
Block(-2,26,3,18:3)
Block(-2,27,-11,18:3)
Block(-2,27,-10,18:3)
Block(-2,27,-8,18:3)
Block(-2,27,-5,18:3)
Block(-2,27,-4,18:3)
Block(-2,27,-3,18:3)
Block(-2,27,-2,18:3)
Block(-2,27,-1,18:3)
Block(-2,27,0,18:3)
Block(-2,27,1,18:3)
Block(-2,27,2,18:3)
Block(-2,27,3,18:3)
Block(-2,27,4,18:3)
Block(-2,27,5,18:3)
Block(-2,27,7,18:3)
Block(-2,27,10,18:3)
Block(-2,28,-10,18:3)
Block(-2,28,-9,18:3)
Block(-2,28,-7,18:3)
Block(-2,28,-6,18:3)
Block(-2,28,-5,18:3)
Block(-2,28,-4,17:11)
Block(-2,28,-3,18:3)
Block(-2,28,-2,18:3)
Block(-2,28,-1,17:7)
Block(-2,28,0,18:3)
Block(-2,28,1,18:3)
Block(-2,28,2,17:7)
Block(-2,28,3,18:3)
Block(-2,28,4,18:3)
Block(-2,28,6,18:3)
Block(-2,29,-10,18:3)
Block(-2,29,-8,18:3)
Block(-2,29,-6,18:3)
Block(-2,29,-4,18:3)
Block(-2,29,-3,18:3)
Block(-2,29,-2,18:3)
Block(-2,29,0,18:3)
Block(-2,29,1,18:3)
Block(-2,29,2,18:3)
Block(-2,29,3,18:3)
Block(-2,29,7,18:3)
Block(-2,29,8,18:3)
Block(-2,30,-1,18:3)
Block(-2,30,0,18:3)
Block(-1,0,-6,17:3)
Block(-1,0,-5,17:3)
Block(-1,0,-4,17:3)
Block(-1,0,-3,17:3)
Block(-1,0,-2,17:3)
Block(-1,0,-1,17:3)
Block(-1,0,0,17:3)
Block(-1,0,1,17:3)
Block(-1,0,2,17:3)
Block(-1,0,3,17:3)
Block(-1,0,4,17:3)
Block(-1,1,-6,17:3)
Block(-1,1,-5,17:3)
Block(-1,1,-4,17:3)
Block(-1,1,-3,17:3)
Block(-1,1,-2,17:3)
Block(-1,1,-1,17:3)
Block(-1,1,0,17:3)
Block(-1,1,1,17:3)
Block(-1,1,2,17:3)
Block(-1,1,3,17:3)
Block(-1,1,4,17:3)
Block(-1,2,-6,17:3)
Block(-1,2,-5,17:3)
Block(-1,2,-4,17:3)
Block(-1,2,-3,17:3)
Block(-1,2,-2,17:3)
Block(-1,2,-1,17:3)
Block(-1,2,0,17:3)
Block(-1,2,1,17:3)
Block(-1,2,2,17:3)
Block(-1,2,3,17:3)
Block(-1,3,-5,17:3)
Block(-1,3,-4,17:3)
Block(-1,3,-3,17:3)
Block(-1,3,-2,17:3)
Block(-1,3,-1,17:3)
Block(-1,3,0,17:3)
Block(-1,3,1,17:3)
Block(-1,3,2,17:3)
Block(-1,3,3,17:3)
Block(-1,4,-4,106:8)
Block(-1,4,-3,17:3)
Block(-1,4,-2,17:3)
Block(-1,4,-1,17:3)
Block(-1,4,0,17:3)
Block(-1,4,1,17:3)
Block(-1,4,2,17:3)
Block(-1,5,-4,106:8)
Block(-1,5,-3,106:9)
Block(-1,5,-2,17:3)
Block(-1,5,-1,17:3)
Block(-1,5,0,17:3)
Block(-1,5,1,17:3)
Block(-1,6,-3,106:9)
Block(-1,6,-2,17:3)
Block(-1,6,-1,17:3)
Block(-1,6,0,17:3)
Block(-1,7,-3,106:9)
Block(-1,7,-2,17:3)
Block(-1,7,-1,17:3)
Block(-1,7,0,17:3)
Block(-1,7,1,106:8)
Block(-1,8,-3,106:1)
Block(-1,8,-2,17:3)
Block(-1,8,-1,17:3)
Block(-1,8,0,17:3)
Block(-1,8,1,106:8)
Block(-1,9,-3,106:1)
Block(-1,9,-2,17:3)
Block(-1,9,-1,17:3)
Block(-1,9,0,17:3)
Block(-1,10,-3,106:1)
Block(-1,10,-2,17:3)
Block(-1,10,-1,17:3)
Block(-1,10,0,17:3)
Block(-1,11,-2,106:1)
Block(-1,11,-1,17:3)
Block(-1,12,-1,17:3)
Block(-1,13,-1,17:3)
Block(-1,14,-1,17:3)
Block(-1,15,-1,17:3)
Block(-1,19,8,106:8)
Block(-1,20,-13,18:3)
Block(-1,20,-12,18:3)
Block(-1,20,8,106:8)
Block(-1,20,11,18:3)
Block(-1,20,12,18:3)
Block(-1,21,-13,18:3)
Block(-1,21,-12,18:3)
Block(-1,21,8,106:8)
Block(-1,21,10,18:3)
Block(-1,21,11,18:3)
Block(-1,21,12,18:3)
Block(-1,22,-12,18:3)
Block(-1,22,-11,18:3)
Block(-1,22,9,18:3)
Block(-1,22,10,18:3)
Block(-1,22,12,18:3)
Block(-1,22,13,18:3)
Block(-1,22,14,18:3)
Block(-1,23,-14,18:3)
Block(-1,23,-13,17:7)
Block(-1,23,-12,18:3)
Block(-1,23,-11,18:3)
Block(-1,23,-10,18:3)
Block(-1,23,-9,18:3)
Block(-1,23,8,18:3)
Block(-1,23,9,18:3)
Block(-1,23,10,18:3)
Block(-1,23,11,17:7)
Block(-1,23,12,18:3)
Block(-1,23,13,18:3)
Block(-1,24,-15,18:3)
Block(-1,24,-14,18:3)
Block(-1,24,-13,18:3)
Block(-1,24,-12,18:3)
Block(-1,24,-11,18:3)
Block(-1,24,9,18:3)
Block(-1,24,10,18:3)
Block(-1,24,11,18:3)
Block(-1,24,12,18:3)
Block(-1,24,13,18:3)
Block(-1,24,14,18:3)
Block(-1,25,-14,18:3)
Block(-1,25,-13,18:3)
Block(-1,25,-10,18:3)
Block(-1,25,-9,18:3)
Block(-1,25,-8,18:3)
Block(-1,25,7,18:3)
Block(-1,25,8,18:3)
Block(-1,25,9,18:3)
Block(-1,25,10,18:3)
Block(-1,25,11,18:3)
Block(-1,26,-12,18:3)
Block(-1,26,-11,18:3)
Block(-1,26,-10,18:3)
Block(-1,26,-9,18:3)
Block(-1,26,-8,18:3)
Block(-1,26,-3,18:3)
Block(-1,26,-2,18:3)
Block(-1,26,-1,18:3)
Block(-1,26,3,18:3)
Block(-1,26,7,18:3)
Block(-1,26,8,18:3)
Block(-1,26,9,18:3)
Block(-1,26,10,18:3)
Block(-1,27,-11,18:3)
Block(-1,27,-10,18:3)
Block(-1,27,-9,17:7)
Block(-1,27,-8,18:3)
Block(-1,27,-7,18:3)
Block(-1,27,-4,18:3)
Block(-1,27,-3,18:3)
Block(-1,27,-2,18:3)
Block(-1,27,-1,18:3)
Block(-1,27,0,18:3)
Block(-1,27,1,18:3)
Block(-1,27,5,18:3)
Block(-1,27,6,18:3)
Block(-1,27,7,17:7)
Block(-1,27,8,18:3)
Block(-1,27,9,18:3)
Block(-1,27,10,18:3)
Block(-1,28,-11,18:3)
Block(-1,28,-9,18:3)
Block(-1,28,-5,18:3)
Block(-1,28,-4,18:3)
Block(-1,28,-3,17:11)
Block(-1,28,-2,18:3)
Block(-1,28,-1,17:7)
Block(-1,28,0,18:3)
Block(-1,28,1,17:7)
Block(-1,28,2,18:3)
Block(-1,28,4,18:3)
Block(-1,28,5,18:3)
Block(-1,28,7,18:3)
Block(-1,28,8,18:3)
Block(-1,29,-10,18:3)
Block(-1,29,-5,18:3)
Block(-1,29,-4,18:3)
Block(-1,29,-3,18:3)
Block(-1,29,-2,18:3)
Block(-1,29,-1,18:3)
Block(-1,29,0,18:3)
Block(-1,29,1,18:3)
Block(-1,29,2,18:3)
Block(-1,29,3,18:3)
Block(-1,29,4,18:3)
Block(-1,29,6,18:3)
Block(-1,29,7,18:3)
Block(-1,30,-4,18:3)
Block(-1,30,-1,18:3)
Block(-1,30,0,18:3)
Block(-1,30,2,18:3)
Block(-1,31,-2,18:3)
Block(-1,31,-1,18:3)
Block(0,0,-6,17:3)
Block(0,0,-5,17:3)
Block(0,0,-4,17:3)
Block(0,0,-3,17:3)
Block(0,0,-2,17:3)
Block(0,0,-1,17:3)
Block(0,0,0,17:3)
Block(0,0,1,17:3)
Block(0,0,2,17:3)
Block(0,0,3,17:3)
Block(0,0,4,17:3)
Block(0,1,-6,17:3)
Block(0,1,-5,17:3)
Block(0,1,-4,17:3)
Block(0,1,-3,17:3)
Block(0,1,-2,17:3)
Block(0,1,-1,17:3)
Block(0,1,0,17:3)
Block(0,1,1,17:3)
Block(0,1,2,17:3)
Block(0,1,3,17:3)
Block(0,1,4,17:3)
Block(0,2,-6,17:3)
Block(0,2,-5,17:3)
Block(0,2,-4,17:3)
Block(0,2,-3,17:3)
Block(0,2,-2,17:3)
Block(0,2,-1,17:3)
Block(0,2,0,17:3)
Block(0,2,1,17:3)
Block(0,2,2,17:3)
Block(0,2,3,17:3)
Block(0,2,4,17:3)
Block(0,3,-5,17:3)
Block(0,3,-4,17:3)
Block(0,3,-3,17:3)
Block(0,3,-2,17:3)
Block(0,3,-1,17:3)
Block(0,3,0,17:3)
Block(0,3,1,17:3)
Block(0,3,2,17:3)
Block(0,3,3,17:3)
Block(0,3,4,17:3)
Block(0,4,-5,17:3)
Block(0,4,-4,17:3)
Block(0,4,-3,17:3)
Block(0,4,-2,17:3)
Block(0,4,-1,17:3)
Block(0,4,0,17:3)
Block(0,4,1,17:3)
Block(0,4,2,17:3)
Block(0,4,3,17:3)
Block(0,5,-4,17:3)
Block(0,5,-3,17:3)
Block(0,5,-2,17:3)
Block(0,5,-1,17:3)
Block(0,5,0,17:3)
Block(0,5,1,17:3)
Block(0,5,2,17:3)
Block(0,6,-3,17:3)
Block(0,6,-2,17:3)
Block(0,6,-1,17:3)
Block(0,6,0,17:3)
Block(0,6,1,17:3)
Block(0,6,2,17:3)
Block(0,7,-3,17:3)
Block(0,7,-2,17:3)
Block(0,7,-1,17:3)
Block(0,7,0,17:3)
Block(0,7,1,17:3)
Block(0,7,2,106:4)
Block(0,8,-3,17:3)
Block(0,8,-2,17:3)
Block(0,8,-1,17:3)
Block(0,8,0,17:3)
Block(0,8,1,17:3)
Block(0,8,2,106:4)
Block(0,9,-4,106:1)
Block(0,9,-3,17:3)
Block(0,9,-2,17:3)
Block(0,9,-1,17:3)
Block(0,9,0,17:3)
Block(0,9,1,17:3)
Block(0,9,2,106:4)
Block(0,10,-4,106:1)
Block(0,10,-3,17:3)
Block(0,10,-2,17:3)
Block(0,10,-1,17:3)
Block(0,10,0,17:3)
Block(0,10,1,17:3)
Block(0,10,2,106:4)
Block(0,11,-2,17:3)
Block(0,11,-1,17:3)
Block(0,11,0,17:3)
Block(0,11,1,106:8)
Block(0,12,-2,17:3)
Block(0,12,-1,17:3)
Block(0,12,0,17:3)
Block(0,12,1,106:8)
Block(0,13,-2,17:3)
Block(0,13,-1,17:3)
Block(0,13,0,17:3)
Block(0,13,1,106:8)
Block(0,14,-2,17:3)
Block(0,14,-1,17:3)
Block(0,14,0,17:3)
Block(0,15,-2,17:3)
Block(0,15,-1,17:3)
Block(0,15,0,17:3)
Block(0,16,-16,106:1)
Block(0,16,-2,17:3)
Block(0,16,-1,17:3)
Block(0,16,0,17:3)
Block(0,17,-16,106:1)
Block(0,17,-2,17:3)
Block(0,17,-1,17:3)
Block(0,17,0,17:3)
Block(0,17,14,106:4)
Block(0,18,-16,106:1)
Block(0,18,-2,17:3)
Block(0,18,-1,17:3)
Block(0,18,0,17:3)
Block(0,18,14,106:4)
Block(0,19,-16,106:1)
Block(0,19,-13,18:3)
Block(0,19,-2,17:3)
Block(0,19,-1,17:3)
Block(0,19,0,17:3)
Block(0,19,11,18:3)
Block(0,19,14,106:4)
Block(0,20,-16,106:1)
Block(0,20,-14,18:3)
Block(0,20,-13,18:3)
Block(0,20,-2,17:3)
Block(0,20,-1,17:3)
Block(0,20,0,17:3)
Block(0,20,9,18:3)
Block(0,20,12,18:3)
Block(0,20,14,106:4)
Block(0,21,-16,106:1)
Block(0,21,-15,18:3)
Block(0,21,-14,18:3)
Block(0,21,-13,18:3)
Block(0,21,-12,18:3)
Block(0,21,-11,18:3)
Block(0,21,-2,17:3)
Block(0,21,-1,17:3)
Block(0,21,0,17:3)
Block(0,21,8,18:3)
Block(0,21,9,18:3)
Block(0,21,11,18:3)
Block(0,21,12,18:3)
Block(0,21,13,18:3)
Block(0,21,14,106:4)
Block(0,22,-14,18:3)
Block(0,22,-13,18:3)
Block(0,22,-11,18:3)
Block(0,22,-10,18:3)
Block(0,22,-9,18:3)
Block(0,22,-1,17:3)
Block(0,22,9,18:3)
Block(0,22,11,18:3)
Block(0,23,-15,18:3)
Block(0,23,-14,18:3)
Block(0,23,-13,17:7)
Block(0,23,-12,18:3)
Block(0,23,-11,18:3)
Block(0,23,-10,18:3)
Block(0,23,-9,18:3)
Block(0,23,-8,18:3)
Block(0,23,-1,17:3)
Block(0,23,9,18:3)
Block(0,23,10,18:3)
Block(0,23,11,17:7)
Block(0,23,12,18:3)
Block(0,24,-14,18:3)
Block(0,24,-13,18:3)
Block(0,24,-12,18:3)
Block(0,24,-11,18:3)
Block(0,24,-9,18:3)
Block(0,24,-8,18:3)
Block(0,24,-1,17:3)
Block(0,24,7,18:3)
Block(0,24,8,18:3)
Block(0,24,9,18:3)
Block(0,24,10,18:3)
Block(0,24,11,18:3)
Block(0,24,12,18:3)
Block(0,24,13,18:3)
Block(0,25,-13,18:3)
Block(0,25,-12,18:3)
Block(0,25,-11,18:3)
Block(0,25,-10,18:3)
Block(0,25,-9,18:3)
Block(0,25,-8,18:3)
Block(0,25,-1,17:3)
Block(0,25,6,18:3)
Block(0,25,7,18:3)
Block(0,25,9,18:3)
Block(0,25,11,18:3)
Block(0,26,-11,18:3)
Block(0,26,-10,18:3)
Block(0,26,-9,18:3)
Block(0,26,-8,18:3)
Block(0,26,-4,18:3)
Block(0,26,-3,18:3)
Block(0,26,-1,17:3)
Block(0,26,0,18:3)
Block(0,26,4,18:3)
Block(0,26,5,18:3)
Block(0,26,7,18:3)
Block(0,26,8,18:3)
Block(0,26,9,18:3)
Block(0,26,10,18:3)
Block(0,26,11,18:3)
Block(0,26,12,18:3)
Block(0,27,-12,18:3)
Block(0,27,-11,18:3)
Block(0,27,-10,18:3)
Block(0,27,-9,17:7)
Block(0,27,-7,18:3)
Block(0,27,-6,18:3)
Block(0,27,-5,18:3)
Block(0,27,-4,18:3)
Block(0,27,-3,18:3)
Block(0,27,-2,18:3)
Block(0,27,-1,17:3)
Block(0,27,1,18:3)
Block(0,27,2,18:3)
Block(0,27,5,18:3)
Block(0,27,6,18:3)
Block(0,27,7,17:7)
Block(0,27,8,18:3)
Block(0,27,9,18:3)
Block(0,27,11,18:3)
Block(0,28,-10,18:3)
Block(0,28,-9,18:3)
Block(0,28,-8,18:3)
Block(0,28,-6,17:7)
Block(0,28,-5,18:3)
Block(0,28,-4,18:3)
Block(0,28,-3,18:3)
Block(0,28,-2,17:11)
Block(0,28,-1,17:3)
Block(0,28,0,17:7)
Block(0,28,1,18:3)
Block(0,28,2,18:3)
Block(0,28,3,18:3)
Block(0,28,4,17:7)
Block(0,28,6,18:3)
Block(0,28,7,18:3)
Block(0,28,9,18:3)
Block(0,29,-7,18:3)
Block(0,29,-5,18:3)
Block(0,29,-4,18:3)
Block(0,29,-3,18:3)
Block(0,29,-2,18:3)
Block(0,29,-1,17:3)
Block(0,29,0,18:3)
Block(0,29,1,18:3)
Block(0,29,2,18:3)
Block(0,29,3,18:3)
Block(0,29,4,18:3)
Block(0,29,5,18:3)
Block(0,29,6,18:3)
Block(0,29,7,18:3)
Block(0,30,-6,18:3)
Block(0,30,-4,18:3)
Block(0,30,-3,18:3)
Block(0,30,-2,18:3)
Block(0,30,-1,18:3)
Block(0,30,0,18:3)
Block(0,30,1,18:3)
Block(0,30,2,18:3)
Block(0,30,3,18:3)
Block(0,30,4,18:3)
Block(0,31,-3,18:3)
Block(0,31,-1,18:3)
Block(0,31,1,18:3)
Block(0,32,-1,18:3)
Block(1,0,-6,17:3)
Block(1,0,-5,17:3)
Block(1,0,-4,17:3)
Block(1,0,-3,17:3)
Block(1,0,-2,17:3)
Block(1,0,-1,17:3)
Block(1,0,0,17:3)
Block(1,0,1,17:3)
Block(1,0,2,17:3)
Block(1,0,3,17:3)
Block(1,0,4,17:3)
Block(1,1,-6,17:3)
Block(1,1,-5,17:3)
Block(1,1,-4,17:3)
Block(1,1,-3,17:3)
Block(1,1,-2,17:3)
Block(1,1,-1,17:3)
Block(1,1,0,17:3)
Block(1,1,1,17:3)
Block(1,1,2,17:3)
Block(1,1,3,17:3)
Block(1,1,4,17:3)
Block(1,2,-5,17:3)
Block(1,2,-4,17:3)
Block(1,2,-3,17:3)
Block(1,2,-2,17:3)
Block(1,2,-1,17:3)
Block(1,2,0,17:3)
Block(1,2,1,17:3)
Block(1,2,2,17:3)
Block(1,2,3,17:3)
Block(1,3,-5,17:3)
Block(1,3,-4,17:3)
Block(1,3,-3,17:3)
Block(1,3,-2,17:3)
Block(1,3,-1,17:3)
Block(1,3,0,17:3)
Block(1,3,1,17:3)
Block(1,3,2,17:3)
Block(1,3,3,17:3)
Block(1,4,-5,17:3)
Block(1,4,-4,17:3)
Block(1,4,-3,17:3)
Block(1,4,-2,17:3)
Block(1,4,-1,17:3)
Block(1,4,0,17:3)
Block(1,4,1,17:3)
Block(1,4,2,17:3)
Block(1,4,3,17:3)
Block(1,5,-5,17:3)
Block(1,5,-4,17:3)
Block(1,5,-3,17:3)
Block(1,5,-2,17:3)
Block(1,5,-1,17:3)
Block(1,5,0,17:3)
Block(1,5,1,17:3)
Block(1,5,2,17:3)
Block(1,6,-4,17:3)
Block(1,6,-3,17:3)
Block(1,6,-2,17:3)
Block(1,6,-1,17:3)
Block(1,6,0,17:3)
Block(1,6,1,17:3)
Block(1,6,2,17:3)
Block(1,7,-4,17:3)
Block(1,7,-3,17:3)
Block(1,7,-2,17:3)
Block(1,7,-1,17:3)
Block(1,7,0,17:3)
Block(1,7,1,17:3)
Block(1,8,-4,106:1)
Block(1,8,-3,17:3)
Block(1,8,-2,17:3)
Block(1,8,-1,17:3)
Block(1,8,0,17:3)
Block(1,8,1,17:3)
Block(1,8,2,106:4)
Block(1,9,-4,106:1)
Block(1,9,-3,17:3)
Block(1,9,-2,17:3)
Block(1,9,-1,17:3)
Block(1,9,0,17:3)
Block(1,9,1,17:3)
Block(1,10,-4,106:1)
Block(1,10,-3,17:3)
Block(1,10,-2,17:3)
Block(1,10,-1,17:3)
Block(1,10,0,17:3)
Block(1,10,1,17:3)
Block(1,11,-4,106:1)
Block(1,11,-3,17:3)
Block(1,11,-2,17:3)
Block(1,11,-1,17:3)
Block(1,11,0,17:3)
Block(1,11,1,17:3)
Block(1,12,-4,106:1)
Block(1,12,-3,17:3)
Block(1,12,-2,17:3)
Block(1,12,-1,17:3)
Block(1,12,0,17:3)
Block(1,12,1,17:3)
Block(1,12,2,106:4)
Block(1,13,-3,17:3)
Block(1,13,-2,17:3)
Block(1,13,-1,17:3)
Block(1,13,0,17:3)
Block(1,13,1,17:3)
Block(1,14,-3,17:3)
Block(1,14,-2,17:3)
Block(1,14,-1,17:3)
Block(1,14,0,17:3)
Block(1,14,1,17:3)
Block(1,15,-3,17:3)
Block(1,15,-2,17:3)
Block(1,15,-1,17:3)
Block(1,15,0,17:3)
Block(1,15,1,17:3)
Block(1,16,-2,17:3)
Block(1,16,-1,17:3)
Block(1,16,0,17:3)
Block(1,17,-15,106:8)
Block(1,17,-2,17:3)
Block(1,17,-1,17:3)
Block(1,17,0,17:3)
Block(1,18,-15,106:8)
Block(1,18,-2,17:3)
Block(1,18,-1,17:3)
Block(1,18,0,17:3)
Block(1,19,-15,106:8)
Block(1,19,-13,18:3)
Block(1,19,-12,18:3)
Block(1,19,-2,17:3)
Block(1,19,-1,17:3)
Block(1,19,0,17:3)
Block(1,19,10,18:3)
Block(1,19,11,18:3)
Block(1,20,-15,106:8)
Block(1,20,-14,18:3)
Block(1,20,-13,18:3)
Block(1,20,-12,18:3)
Block(1,20,-2,17:3)
Block(1,20,-1,17:3)
Block(1,20,0,17:3)
Block(1,20,9,18:3)
Block(1,20,13,18:3)
Block(1,21,-15,106:8)
Block(1,21,-14,18:3)
Block(1,21,-13,17:3)
Block(1,21,-12,18:3)
Block(1,21,-11,18:3)
Block(1,21,-10,18:3)
Block(1,21,-2,17:3)
Block(1,21,-1,17:3)
Block(1,21,0,17:3)
Block(1,21,8,18:3)
Block(1,21,9,18:3)
Block(1,21,10,18:3)
Block(1,21,11,17:3)
Block(1,21,12,18:3)
Block(1,21,13,18:3)
Block(1,21,14,18:3)
Block(1,21,15,106:4)
Block(1,22,-15,18:3)
Block(1,22,-14,18:3)
Block(1,22,-13,17:3)
Block(1,22,-12,18:3)
Block(1,22,-11,18:3)
Block(1,22,-9,18:3)
Block(1,22,-2,17:3)
Block(1,22,-1,17:3)
Block(1,22,0,17:3)
Block(1,22,7,18:3)
Block(1,22,8,18:3)
Block(1,22,9,18:3)
Block(1,22,10,18:3)
Block(1,22,11,17:3)
Block(1,22,12,18:3)
Block(1,22,13,18:3)
Block(1,23,-14,18:3)
Block(1,23,-13,17:3)
Block(1,23,-12,17:11)
Block(1,23,-11,17:11)
Block(1,23,-10,18:3)
Block(1,23,-9,18:3)
Block(1,23,-2,17:3)
Block(1,23,-1,17:3)
Block(1,23,0,17:3)
Block(1,23,6,18:3)
Block(1,23,7,18:3)
Block(1,23,8,18:3)
Block(1,23,9,17:11)
Block(1,23,10,17:11)
Block(1,23,11,17:3)
Block(1,23,12,18:3)
Block(1,24,-14,18:3)
Block(1,24,-13,17:3)
Block(1,24,-12,18:3)
Block(1,24,-11,18:3)
Block(1,24,-10,18:3)
Block(1,24,-2,17:3)
Block(1,24,-1,17:3)
Block(1,24,0,17:3)
Block(1,24,7,18:3)
Block(1,24,8,18:3)
Block(1,24,9,18:3)
Block(1,24,10,18:3)
Block(1,24,11,17:3)
Block(1,24,12,18:3)
Block(1,25,-12,17:3)
Block(1,25,-11,18:3)
Block(1,25,-10,18:3)
Block(1,25,-2,17:3)
Block(1,25,-1,17:3)
Block(1,25,0,17:3)
Block(1,25,7,18:3)
Block(1,25,9,18:3)
Block(1,25,10,17:3)
Block(1,26,-13,18:3)
Block(1,26,-12,18:3)
Block(1,26,-11,17:3)
Block(1,26,-10,18:3)
Block(1,26,-9,18:3)
Block(1,26,-8,18:3)
Block(1,26,-6,18:3)
Block(1,26,-3,18:3)
Block(1,26,-2,17:3)
Block(1,26,-1,17:3)
Block(1,26,0,17:3)
Block(1,26,1,18:3)
Block(1,26,3,18:3)
Block(1,26,4,18:3)
Block(1,26,5,18:3)
Block(1,26,6,18:3)
Block(1,26,7,18:3)
Block(1,26,8,18:3)
Block(1,26,9,17:3)
Block(1,26,10,18:3)
Block(1,26,11,18:3)
Block(1,27,-11,18:3)
Block(1,27,-10,17:11)
Block(1,27,-9,17:11)
Block(1,27,-8,17:11)
Block(1,27,-7,18:3)
Block(1,27,-6,18:3)
Block(1,27,-4,18:3)
Block(1,27,-3,18:3)
Block(1,27,-2,17:3)
Block(1,27,-1,17:3)
Block(1,27,0,17:3)
Block(1,27,1,18:3)
Block(1,27,2,18:3)
Block(1,27,4,18:3)
Block(1,27,5,18:3)
Block(1,27,6,17:11)
Block(1,27,7,17:11)
Block(1,27,8,17:11)
Block(1,27,9,18:3)
Block(1,27,10,18:3)
Block(1,28,-11,18:3)
Block(1,28,-10,18:3)
Block(1,28,-9,18:3)
Block(1,28,-8,18:3)
Block(1,28,-7,17:11)
Block(1,28,-6,17:11)
Block(1,28,-5,17:11)
Block(1,28,-4,17:11)
Block(1,28,-3,17:11)
Block(1,28,-2,17:3)
Block(1,28,-1,17:3)
Block(1,28,0,17:3)
Block(1,28,1,17:11)
Block(1,28,2,17:11)
Block(1,28,3,17:11)
Block(1,28,4,17:11)
Block(1,28,5,17:11)
Block(1,28,6,18:3)
Block(1,28,9,18:3)
Block(1,28,10,18:3)
Block(1,29,-8,18:3)
Block(1,29,-7,18:3)
Block(1,29,-5,18:3)
Block(1,29,-4,18:3)
Block(1,29,-3,18:3)
Block(1,29,-2,17:3)
Block(1,29,-1,17:3)
Block(1,29,0,17:3)
Block(1,29,1,18:3)
Block(1,29,2,18:3)
Block(1,29,3,18:3)
Block(1,29,4,18:3)
Block(1,29,6,18:3)
Block(1,30,-5,18:3)
Block(1,30,-4,18:3)
Block(1,30,-3,18:3)
Block(1,30,-2,18:3)
Block(1,30,-1,17:3)
Block(1,30,0,18:3)
Block(1,30,1,18:3)
Block(1,30,2,18:3)
Block(1,30,3,18:3)
Block(1,30,5,18:3)
Block(1,31,-3,18:3)
Block(1,31,-1,18:3)
Block(1,31,0,18:3)
Block(1,31,1,18:3)
Block(1,32,-1,18:3)
Block(1,32,0,18:3)
Block(2,0,-6,17:3)
Block(2,0,-5,17:3)
Block(2,0,-4,17:3)
Block(2,0,-3,17:3)
Block(2,0,-2,17:3)
Block(2,0,-1,17:3)
Block(2,0,0,17:3)
Block(2,0,1,17:3)
Block(2,0,2,17:3)
Block(2,0,3,17:3)
Block(2,0,4,17:3)
Block(2,1,-5,17:3)
Block(2,1,-4,17:3)
Block(2,1,-3,17:3)
Block(2,1,-2,17:3)
Block(2,1,-1,17:3)
Block(2,1,0,17:3)
Block(2,1,1,17:3)
Block(2,1,2,17:3)
Block(2,1,3,17:3)
Block(2,2,-5,17:3)
Block(2,2,-4,17:3)
Block(2,2,-3,17:3)
Block(2,2,-2,17:3)
Block(2,2,-1,17:3)
Block(2,2,0,17:3)
Block(2,2,1,17:3)
Block(2,2,2,17:3)
Block(2,2,3,17:3)
Block(2,3,-5,17:3)
Block(2,3,-4,17:3)
Block(2,3,-3,17:3)
Block(2,3,-2,17:3)
Block(2,3,-1,17:3)
Block(2,3,0,17:3)
Block(2,3,1,17:3)
Block(2,3,2,17:3)
Block(2,4,-5,17:3)
Block(2,4,-4,17:3)
Block(2,4,-3,17:3)
Block(2,4,-2,17:3)
Block(2,4,-1,17:3)
Block(2,4,0,17:3)
Block(2,4,1,17:3)
Block(2,4,2,17:3)
Block(2,5,-5,17:3)
Block(2,5,-4,17:3)
Block(2,5,-3,17:3)
Block(2,5,-2,17:3)
Block(2,5,-1,17:3)
Block(2,5,0,17:3)
Block(2,5,1,17:3)
Block(2,5,2,17:3)
Block(2,6,-4,17:3)
Block(2,6,-3,17:3)
Block(2,6,-2,17:3)
Block(2,6,-1,17:3)
Block(2,6,0,17:3)
Block(2,6,1,17:3)
Block(2,7,-4,17:3)
Block(2,7,-3,17:3)
Block(2,7,-2,17:3)
Block(2,7,-1,17:3)
Block(2,7,0,17:3)
Block(2,7,1,17:3)
Block(2,8,-3,17:3)
Block(2,8,-2,17:3)
Block(2,8,-1,17:3)
Block(2,8,0,17:3)
Block(2,8,1,17:3)
Block(2,9,-3,17:3)
Block(2,9,-2,17:3)
Block(2,9,-1,17:3)
Block(2,9,0,17:3)
Block(2,9,1,17:3)
Block(2,10,-3,17:3)
Block(2,10,-2,17:3)
Block(2,10,-1,17:3)
Block(2,10,0,17:3)
Block(2,10,1,17:3)
Block(2,11,-3,106:1)
Block(2,11,-2,17:3)
Block(2,11,-1,17:3)
Block(2,11,0,17:3)
Block(2,12,-3,106:1)
Block(2,12,-2,17:3)
Block(2,12,-1,17:3)
Block(2,12,0,17:3)
Block(2,13,-3,106:1)
Block(2,13,-2,17:3)
Block(2,13,-1,17:3)
Block(2,13,0,17:3)
Block(2,14,-2,17:3)
Block(2,14,-1,17:3)
Block(2,14,0,17:3)
Block(2,14,1,106:4)
Block(2,15,-2,17:3)
Block(2,15,-1,17:3)
Block(2,15,0,17:3)
Block(2,16,-2,17:3)
Block(2,16,-1,17:3)
Block(2,16,0,17:3)
Block(2,17,-2,17:3)
Block(2,17,-1,17:3)
Block(2,17,0,17:3)
Block(2,18,-2,17:3)
Block(2,18,-1,17:3)
Block(2,18,0,17:3)
Block(2,18,14,106:4)
Block(2,19,-13,18:3)
Block(2,19,-2,17:3)
Block(2,19,-1,17:3)
Block(2,19,0,17:3)
Block(2,19,10,18:3)
Block(2,19,11,18:3)
Block(2,19,14,106:4)
Block(2,20,-13,18:3)
Block(2,20,-11,18:3)
Block(2,20,-2,17:3)
Block(2,20,-1,17:3)
Block(2,20,0,17:3)
Block(2,20,7,106:1)
Block(2,20,9,18:3)
Block(2,20,13,18:3)
Block(2,20,14,106:4)
Block(2,21,-15,18:3)
Block(2,21,-14,18:3)
Block(2,21,-13,18:3)
Block(2,21,-12,18:3)
Block(2,21,-11,18:3)
Block(2,21,-10,106:4)
Block(2,21,-2,17:3)
Block(2,21,-1,17:3)
Block(2,21,0,17:3)
Block(2,21,7,106:1)
Block(2,21,8,18:3)
Block(2,21,9,18:3)
Block(2,21,10,18:3)
Block(2,21,11,18:3)
Block(2,21,13,18:3)
Block(2,21,14,106:4)
Block(2,22,-14,18:3)
Block(2,22,-12,18:3)
Block(2,22,-11,18:3)
Block(2,22,-9,18:3)
Block(2,22,-1,17:3)
Block(2,22,9,18:3)
Block(2,22,10,18:3)
Block(2,22,11,18:3)
Block(2,22,13,18:3)
Block(2,22,14,18:3)
Block(2,23,-15,18:3)
Block(2,23,-13,17:7)
Block(2,23,-12,18:3)
Block(2,23,-10,18:3)
Block(2,23,-9,18:3)
Block(2,23,-1,17:3)
Block(2,23,8,18:3)
Block(2,23,9,18:3)
Block(2,23,10,18:3)
Block(2,23,11,17:7)
Block(2,23,12,18:3)
Block(2,24,-13,18:3)
Block(2,24,-12,18:3)
Block(2,24,-11,18:3)
Block(2,24,-10,18:3)
Block(2,24,-9,18:3)
Block(2,24,-1,17:3)
Block(2,24,9,18:3)
Block(2,25,-13,18:3)
Block(2,25,-12,18:3)
Block(2,25,-11,18:3)
Block(2,25,-8,18:3)
Block(2,25,-1,17:3)
Block(2,25,7,18:3)
Block(2,25,8,18:3)
Block(2,25,9,18:3)
Block(2,25,10,18:3)
Block(2,25,11,18:3)
Block(2,25,12,18:3)
Block(2,26,-13,18:3)
Block(2,26,-12,18:3)
Block(2,26,-11,18:3)
Block(2,26,-10,18:3)
Block(2,26,-9,18:3)
Block(2,26,-8,18:3)
Block(2,26,-7,18:3)
Block(2,26,-6,18:3)
Block(2,26,-5,18:3)
Block(2,26,-4,18:3)
Block(2,26,-1,17:3)
Block(2,26,0,18:3)
Block(2,26,1,18:3)
Block(2,26,7,18:3)
Block(2,26,8,18:3)
Block(2,26,9,18:3)
Block(2,26,11,18:3)
Block(2,27,-10,18:3)
Block(2,27,-9,17:7)
Block(2,27,-8,18:3)
Block(2,27,-6,18:3)
Block(2,27,-5,18:3)
Block(2,27,-4,18:3)
Block(2,27,-1,17:3)
Block(2,27,0,18:3)
Block(2,27,1,18:3)
Block(2,27,3,18:3)
Block(2,27,4,18:3)
Block(2,27,6,18:3)
Block(2,27,7,17:7)
Block(2,27,8,18:3)
Block(2,27,9,18:3)
Block(2,27,11,18:3)
Block(2,28,-10,18:3)
Block(2,28,-9,18:3)
Block(2,28,-8,18:3)
Block(2,28,-7,18:3)
Block(2,28,-6,17:7)
Block(2,28,-5,18:3)
Block(2,28,-4,18:3)
Block(2,28,-3,18:3)
Block(2,28,-2,17:7)
Block(2,28,-1,17:3)
Block(2,28,0,17:11)
Block(2,28,1,18:3)
Block(2,28,2,18:3)
Block(2,28,3,18:3)
Block(2,28,4,17:7)
Block(2,28,6,18:3)
Block(2,28,7,18:3)
Block(2,29,-9,18:3)
Block(2,29,-7,18:3)
Block(2,29,-6,18:3)
Block(2,29,-5,18:3)
Block(2,29,-4,18:3)
Block(2,29,-3,18:3)
Block(2,29,-1,17:3)
Block(2,29,0,18:3)
Block(2,29,1,18:3)
Block(2,29,4,18:3)
Block(2,29,7,18:3)
Block(2,29,8,18:3)
Block(2,30,-6,18:3)
Block(2,30,-2,18:3)
Block(2,30,-1,18:3)
Block(2,30,0,18:3)
Block(2,30,1,18:3)
Block(2,30,3,18:3)
Block(2,30,4,18:3)
Block(2,30,5,18:3)
Block(2,31,-2,18:3)
Block(2,31,-1,18:3)
Block(2,31,0,18:3)
Block(2,32,-2,18:3)
Block(2,32,-1,18:3)
Block(3,0,-5,17:3)
Block(3,0,-4,17:3)
Block(3,0,-3,17:3)
Block(3,0,-2,17:3)
Block(3,0,-1,17:3)
Block(3,0,0,17:3)
Block(3,0,1,17:3)
Block(3,0,2,17:3)
Block(3,0,3,17:3)
Block(3,0,4,17:3)
Block(3,1,-5,17:3)
Block(3,1,-4,17:3)
Block(3,1,-3,17:3)
Block(3,1,-2,17:3)
Block(3,1,-1,17:3)
Block(3,1,0,17:3)
Block(3,1,1,17:3)
Block(3,1,2,17:3)
Block(3,1,3,17:3)
Block(3,2,-5,17:3)
Block(3,2,-4,17:3)
Block(3,2,-3,17:3)
Block(3,2,-2,17:3)
Block(3,2,-1,17:3)
Block(3,2,0,17:3)
Block(3,2,1,17:3)
Block(3,2,2,17:3)
Block(3,2,3,17:3)
Block(3,3,-4,17:3)
Block(3,3,-3,17:3)
Block(3,3,-2,17:3)
Block(3,3,-1,17:3)
Block(3,3,0,17:3)
Block(3,3,1,17:3)
Block(3,3,2,17:3)
Block(3,4,-3,17:3)
Block(3,4,-2,17:3)
Block(3,4,-1,17:3)
Block(3,4,0,17:3)
Block(3,4,1,17:3)
Block(3,5,-2,17:3)
Block(3,5,-1,17:3)
Block(3,5,0,17:3)
Block(3,5,1,17:3)
Block(3,6,-2,17:3)
Block(3,6,-1,17:3)
Block(3,6,0,17:3)
Block(3,7,-2,17:3)
Block(3,7,-1,17:3)
Block(3,7,0,17:3)
Block(3,8,-2,17:3)
Block(3,8,-1,17:3)
Block(3,8,0,17:3)
Block(3,9,-3,106:2)
Block(3,9,-2,17:3)
Block(3,9,-1,17:3)
Block(3,9,0,17:3)
Block(3,10,-3,106:2)
Block(3,10,-2,17:3)
Block(3,10,-1,17:3)
Block(3,10,0,17:3)
Block(3,11,-1,17:3)
Block(3,11,0,106:6)
Block(3,12,-1,17:3)
Block(3,12,0,106:6)
Block(3,13,-1,17:3)
Block(3,13,0,106:6)
Block(3,14,-1,17:3)
Block(3,14,0,106:2)
Block(3,15,-1,17:3)
Block(3,16,-15,106:1)
Block(3,17,-15,106:1)
Block(3,18,-15,106:1)
Block(3,19,-15,106:1)
Block(3,20,-15,106:1)
Block(3,20,-13,18:3)
Block(3,20,11,18:3)
Block(3,20,13,106:2)
Block(3,21,-15,106:1)
Block(3,21,-14,18:3)
Block(3,21,-13,18:3)
Block(3,21,-12,18:3)
Block(3,21,-11,106:2)
Block(3,21,10,18:3)
Block(3,21,11,18:3)
Block(3,21,12,18:3)
Block(3,21,13,106:2)
Block(3,22,-15,18:3)
Block(3,22,-13,18:3)
Block(3,22,-12,18:3)
Block(3,22,-11,18:3)
Block(3,22,9,18:3)
Block(3,22,11,18:3)
Block(3,22,12,18:3)
Block(3,23,-14,18:3)
Block(3,23,-13,17:7)
Block(3,23,-12,18:3)
Block(3,23,-11,18:3)
Block(3,23,8,18:3)
Block(3,23,9,18:3)
Block(3,23,10,18:3)
Block(3,23,11,17:7)
Block(3,23,12,18:3)
Block(3,23,13,18:3)
Block(3,23,14,18:3)
Block(3,24,-15,18:3)
Block(3,24,-14,18:3)
Block(3,24,-13,18:3)
Block(3,24,-12,18:3)
Block(3,24,-11,18:3)
Block(3,24,9,18:3)
Block(3,24,11,18:3)
Block(3,25,-14,18:3)
Block(3,25,-13,18:3)
Block(3,25,-11,18:3)
Block(3,25,-10,18:3)
Block(3,25,-9,18:3)
Block(3,25,6,18:3)
Block(3,25,7,18:3)
Block(3,25,8,18:3)
Block(3,25,11,18:3)
Block(3,25,12,18:3)
Block(3,25,13,18:3)
Block(3,26,-12,18:3)
Block(3,26,-11,18:3)
Block(3,26,-10,18:3)
Block(3,26,-9,18:3)
Block(3,26,-8,18:3)
Block(3,26,-5,18:3)
Block(3,26,-3,18:3)
Block(3,26,0,18:3)
Block(3,26,3,18:3)
Block(3,26,7,18:3)
Block(3,26,8,18:3)
Block(3,26,9,18:3)
Block(3,26,10,18:3)
Block(3,27,-11,18:3)
Block(3,27,-10,18:3)
Block(3,27,-9,17:7)
Block(3,27,-8,18:3)
Block(3,27,-7,18:3)
Block(3,27,-4,18:3)
Block(3,27,-3,18:3)
Block(3,27,-2,18:3)
Block(3,27,-1,18:3)
Block(3,27,0,18:3)
Block(3,27,1,18:3)
Block(3,27,2,18:3)
Block(3,27,3,18:3)
Block(3,27,4,18:3)
Block(3,27,5,18:3)
Block(3,27,7,17:7)
Block(3,27,8,18:3)
Block(3,27,9,18:3)
Block(3,27,10,18:3)
Block(3,28,-11,18:3)
Block(3,28,-9,18:3)
Block(3,28,-8,18:3)
Block(3,28,-7,18:3)
Block(3,28,-6,18:3)
Block(3,28,-5,18:3)
Block(3,28,-3,17:7)
Block(3,28,-2,18:3)
Block(3,28,-1,17:7)
Block(3,28,0,18:3)
Block(3,28,1,17:11)
Block(3,28,2,18:3)
Block(3,28,3,18:3)
Block(3,28,5,18:3)
Block(3,28,8,18:3)
Block(3,28,9,18:3)
Block(3,29,-9,18:3)
Block(3,29,-8,18:3)
Block(3,29,-7,18:3)
Block(3,29,-6,18:3)
Block(3,29,-5,18:3)
Block(3,29,-4,18:3)
Block(3,29,-3,18:3)
Block(3,29,-2,18:3)
Block(3,29,2,18:3)
Block(3,29,7,18:3)
Block(3,30,-5,18:3)
Block(3,30,-3,18:3)
Block(3,30,-2,18:3)
Block(3,30,-1,18:3)
Block(3,30,2,18:3)
Block(3,31,-2,18:3)
Block(3,31,0,18:3)
Block(4,0,-5,17:3)
Block(4,0,-4,17:3)
Block(4,0,-3,17:3)
Block(4,0,-2,17:3)
Block(4,0,-1,17:3)
Block(4,0,0,17:3)
Block(4,0,1,17:3)
Block(4,0,2,17:3)
Block(4,0,3,17:3)
Block(4,1,-4,17:3)
Block(4,1,-3,17:3)
Block(4,1,-2,17:3)
Block(4,1,-1,17:3)
Block(4,1,0,17:3)
Block(4,1,1,17:3)
Block(4,1,2,17:3)
Block(4,2,-4,17:3)
Block(4,2,-3,17:3)
Block(4,2,-2,17:3)
Block(4,2,-1,17:3)
Block(4,2,0,17:3)
Block(4,2,1,17:3)
Block(4,3,-3,17:3)
Block(4,3,-2,17:3)
Block(4,3,-1,17:3)
Block(4,3,0,17:3)
Block(4,3,1,17:3)
Block(4,4,-3,17:3)
Block(4,4,-2,17:3)
Block(4,4,-1,17:3)
Block(4,4,0,17:3)
Block(4,5,-2,17:3)
Block(4,5,-1,17:3)
Block(4,6,-2,17:3)
Block(4,6,-1,17:3)
Block(4,9,-2,106:2)
Block(4,10,-2,106:2)
Block(4,10,-1,106:2)
Block(4,11,-1,106:2)
Block(4,12,-1,106:2)
Block(4,15,13,106:4)
Block(4,16,13,106:4)
Block(4,17,13,106:4)
Block(4,18,-15,106:1)
Block(4,18,13,106:4)
Block(4,19,-15,106:1)
Block(4,19,13,106:4)
Block(4,20,-15,106:1)
Block(4,20,13,106:4)
Block(4,21,-15,106:1)
Block(4,21,-14,18:3)
Block(4,21,-13,18:3)
Block(4,21,-12,18:3)
Block(4,21,10,18:3)
Block(4,21,11,18:3)
Block(4,21,12,18:3)
Block(4,21,13,106:4)
Block(4,22,-15,18:3)
Block(4,22,-13,18:3)
Block(4,22,9,18:3)
Block(4,22,12,18:3)
Block(4,22,13,18:3)
Block(4,23,-13,18:3)
Block(4,23,-12,18:3)
Block(4,23,-11,18:3)
Block(4,23,9,18:3)
Block(4,23,12,18:3)
Block(4,23,13,18:3)
Block(4,24,-14,18:3)
Block(4,24,-13,18:3)
Block(4,24,11,18:3)
Block(4,24,12,18:3)
Block(4,24,13,18:3)
Block(4,25,-10,18:3)
Block(4,25,6,18:3)
Block(4,25,11,18:3)
Block(4,25,12,18:3)
Block(4,26,-11,18:3)
Block(4,26,-7,18:3)
Block(4,26,-3,18:3)
Block(4,26,2,18:3)
Block(4,26,4,18:3)
Block(4,26,6,18:3)
Block(4,26,9,18:3)
Block(4,26,10,18:3)
Block(4,27,-8,18:3)
Block(4,27,-7,18:3)
Block(4,27,-6,18:3)
Block(4,27,-3,18:3)
Block(4,27,-2,18:3)
Block(4,27,0,18:3)
Block(4,27,3,18:3)
Block(4,27,4,18:3)
Block(4,27,5,18:3)
Block(4,27,6,18:3)
Block(4,27,7,18:3)
Block(4,27,9,18:3)
Block(4,28,-10,18:3)
Block(4,28,-9,18:3)
Block(4,28,-6,18:3)
Block(4,28,-4,17:7)
Block(4,28,-3,18:3)
Block(4,28,-2,18:3)
Block(4,28,-1,17:7)
Block(4,28,0,18:3)
Block(4,28,1,18:3)
Block(4,28,2,17:11)
Block(4,28,3,18:3)
Block(4,28,4,18:3)
Block(4,28,5,18:3)
Block(4,28,7,18:3)
Block(4,29,-10,18:3)
Block(4,29,-9,18:3)
Block(4,29,-8,18:3)
Block(4,29,-6,18:3)
Block(4,29,-5,18:3)
Block(4,29,-4,18:3)
Block(4,29,-3,18:3)
Block(4,29,-2,18:3)
Block(4,29,-1,18:3)
Block(4,29,0,18:3)
Block(4,29,1,18:3)
Block(4,29,2,18:3)
Block(4,29,3,18:3)
Block(4,29,4,18:3)
Block(4,29,7,18:3)
Block(4,29,8,18:3)
Block(4,30,-5,18:3)
Block(4,30,-4,18:3)
Block(4,30,-3,18:3)
Block(4,30,-2,18:3)
Block(4,30,-1,18:3)
Block(4,30,0,18:3)
Block(4,30,2,18:3)
Block(4,30,3,18:3)
Block(5,0,-5,17:3)
Block(5,0,-4,17:3)
Block(5,0,-3,17:3)
Block(5,0,-2,17:3)
Block(5,0,-1,17:3)
Block(5,0,0,17:3)
Block(5,0,1,17:3)
Block(5,0,2,17:3)
Block(5,1,-3,17:3)
Block(5,1,-2,17:3)
Block(5,1,-1,17:3)
Block(5,1,0,17:3)
Block(5,1,1,17:3)
Block(5,2,-3,17:3)
Block(5,2,-2,17:3)
Block(5,2,-1,17:3)
Block(5,2,0,17:3)
Block(5,2,1,17:3)
Block(5,3,-3,17:3)
Block(5,3,-2,17:3)
Block(5,3,-1,17:3)
Block(5,3,0,17:3)
Block(5,4,-2,17:3)
Block(5,4,-1,17:3)
Block(5,20,-9,106:8)
Block(5,21,-14,106:2)
Block(5,21,-9,106:8)
Block(5,21,11,18:3)
Block(5,22,-13,18:3)
Block(5,22,-12,18:3)
Block(5,22,5,18:3)
Block(5,22,7,18:3)
Block(5,22,8,18:3)
Block(5,22,12,18:3)
Block(5,23,-14,18:3)
Block(5,23,-13,18:3)
Block(5,23,-12,18:3)
Block(5,23,-9,18:3)
Block(5,23,-8,18:3)
Block(5,23,7,18:3)
Block(5,23,11,18:3)
Block(5,24,-14,18:3)
Block(5,24,-10,18:3)
Block(5,24,-9,18:3)
Block(5,24,6,18:3)
Block(5,24,7,18:3)
Block(5,24,8,18:3)
Block(5,24,10,18:3)
Block(5,24,12,18:3)
Block(5,25,4,18:3)
Block(5,25,11,18:3)
Block(5,26,-9,18:3)
Block(5,26,-8,18:3)
Block(5,26,-5,18:3)
Block(5,26,-4,18:3)
Block(5,26,-1,18:3)
Block(5,26,2,18:3)
Block(5,26,3,18:3)
Block(5,26,4,18:3)
Block(5,26,6,18:3)
Block(5,26,7,18:3)
Block(5,26,8,18:3)
Block(5,27,-9,18:3)
Block(5,27,-8,18:3)
Block(5,27,-7,18:3)
Block(5,27,-6,18:3)
Block(5,27,-4,18:3)
Block(5,27,-2,18:3)
Block(5,27,-1,18:3)
Block(5,27,0,18:3)
Block(5,27,1,18:3)
Block(5,27,2,18:3)
Block(5,27,3,18:3)
Block(5,27,4,18:3)
Block(5,27,5,18:3)
Block(5,27,6,18:3)
Block(5,27,7,18:3)
Block(5,28,-10,18:3)
Block(5,28,-8,18:3)
Block(5,28,-6,18:3)
Block(5,28,-5,17:7)
Block(5,28,-4,18:3)
Block(5,28,-3,18:3)
Block(5,28,-2,18:3)
Block(5,28,-1,17:7)
Block(5,28,0,18:3)
Block(5,28,2,18:3)
Block(5,28,3,17:11)
Block(5,28,4,18:3)
Block(5,28,5,18:3)
Block(5,28,6,18:3)
Block(5,29,-6,18:3)
Block(5,29,-5,18:3)
Block(5,29,-4,18:3)
Block(5,29,-2,18:3)
Block(5,29,-1,18:3)
Block(5,29,0,18:3)
Block(5,29,1,18:3)
Block(5,29,2,18:3)
Block(5,30,-4,18:3)
Block(6,0,-4,17:3)
Block(6,0,-3,17:3)
Block(6,0,-2,17:3)
Block(6,0,-1,17:3)
Block(6,0,0,17:3)
Block(6,0,1,17:3)
Block(6,1,-2,17:3)
Block(6,1,-1,17:3)
Block(6,1,0,17:3)
Block(6,2,-2,17:3)
Block(6,2,-1,17:3)
Block(6,17,6,106:8)
Block(6,18,6,106:8)
Block(6,19,6,106:8)
Block(6,20,-8,106:8)
Block(6,20,6,106:8)
Block(6,21,-9,18:3)
Block(6,21,-8,106:8)
Block(6,21,6,106:8)
Block(6,21,7,18:3)
Block(6,21,8,18:3)
Block(6,22,-11,18:3)
Block(6,22,-8,18:3)
Block(6,22,5,18:3)
Block(6,22,7,18:3)
Block(6,22,9,18:3)
Block(6,23,-13,18:3)
Block(6,23,-11,18:3)
Block(6,23,-9,18:3)
Block(6,23,-8,18:3)
Block(6,23,-7,18:3)
Block(6,23,5,18:3)
Block(6,23,6,18:3)
Block(6,23,7,18:3)
Block(6,23,8,18:3)
Block(6,24,-11,18:3)
Block(6,24,-9,18:3)
Block(6,24,5,18:3)
Block(6,24,8,18:3)
Block(6,25,-10,18:3)
Block(6,25,-7,18:3)
Block(6,25,4,18:3)
Block(6,25,5,18:3)
Block(6,25,6,18:3)
Block(6,25,7,18:3)
Block(6,26,-9,18:3)
Block(6,26,-8,18:3)
Block(6,26,-7,18:3)
Block(6,26,-1,18:3)
Block(6,26,0,18:3)
Block(6,26,2,18:3)
Block(6,26,4,18:3)
Block(6,26,5,18:3)
Block(6,26,6,18:3)
Block(6,26,7,18:3)
Block(6,27,-9,18:3)
Block(6,27,-8,18:3)
Block(6,27,-7,18:3)
Block(6,27,-6,17:7)
Block(6,27,-5,18:3)
Block(6,27,-4,18:3)
Block(6,27,-3,18:3)
Block(6,27,-1,18:3)
Block(6,27,2,18:3)
Block(6,27,3,18:3)
Block(6,27,4,17:11)
Block(6,27,5,18:3)
Block(6,27,6,18:3)
Block(6,28,-8,18:3)
Block(6,28,-4,18:3)
Block(6,28,-3,18:3)
Block(6,28,-2,17:11)
Block(6,28,-1,17:7)
Block(6,28,0,17:11)
Block(6,28,1,18:3)
Block(6,28,2,18:3)
Block(6,28,3,18:3)
Block(6,29,-8,18:3)
Block(6,29,-6,18:3)
Block(6,29,-5,18:3)
Block(6,29,-3,18:3)
Block(6,29,-2,18:3)
Block(6,29,-1,18:3)
Block(6,29,1,18:3)
Block(6,29,2,18:3)
Block(6,29,3,18:3)
Block(6,30,-1,18:3)
Block(6,30,0,18:3)
Block(7,0,-2,17:3)
Block(7,0,-1,17:3)
Block(7,0,0,17:3)
Block(7,16,-7,106:4)
Block(7,17,-7,106:4)
Block(7,18,-7,106:4)
Block(7,19,-7,106:4)
Block(7,20,-9,18:3)
Block(7,20,-7,106:4)
Block(7,20,5,106:1)
Block(7,20,6,18:3)
Block(7,21,-10,18:3)
Block(7,21,-9,18:3)
Block(7,21,-8,18:3)
Block(7,21,-7,106:4)
Block(7,21,5,106:1)
Block(7,21,6,18:3)
Block(7,21,7,18:3)
Block(7,21,8,18:3)
Block(7,22,-12,18:3)
Block(7,22,-11,18:3)
Block(7,22,-10,18:3)
Block(7,22,-9,18:3)
Block(7,22,-8,18:3)
Block(7,22,-7,18:3)
Block(7,22,5,18:3)
Block(7,22,6,18:3)
Block(7,22,7,18:3)
Block(7,22,9,18:3)
Block(7,23,-11,18:3)
Block(7,23,-10,18:3)
Block(7,23,-9,17:7)
Block(7,23,-8,18:3)
Block(7,23,4,18:3)
Block(7,23,5,18:3)
Block(7,23,6,18:3)
Block(7,23,7,17:7)
Block(7,23,8,18:3)
Block(7,23,9,18:3)
Block(7,23,10,18:3)
Block(7,24,-10,18:3)
Block(7,24,-9,18:3)
Block(7,24,-8,18:3)
Block(7,24,-7,18:3)
Block(7,24,5,18:3)
Block(7,24,6,18:3)
Block(7,24,7,18:3)
Block(7,24,9,18:3)
Block(7,25,-10,18:3)
Block(7,25,-9,18:3)
Block(7,25,-8,18:3)
Block(7,25,-7,18:3)
Block(7,25,-6,18:3)
Block(7,25,4,18:3)
Block(7,25,6,18:3)
Block(7,25,7,18:3)
Block(7,25,8,18:3)
Block(7,26,-10,18:3)
Block(7,26,-9,18:3)
Block(7,26,-8,18:3)
Block(7,26,-7,18:3)
Block(7,26,-3,18:3)
Block(7,26,-2,18:3)
Block(7,26,4,18:3)
Block(7,26,5,18:3)
Block(7,26,8,18:3)
Block(7,27,-9,18:3)
Block(7,27,-8,18:3)
Block(7,27,-7,17:7)
Block(7,27,-6,18:3)
Block(7,27,-5,18:3)
Block(7,27,-3,18:3)
Block(7,27,-2,18:3)
Block(7,27,-1,18:3)
Block(7,27,2,18:3)
Block(7,27,5,17:11)
Block(7,27,6,18:3)
Block(7,27,7,18:3)
Block(7,28,-9,18:3)
Block(7,28,-8,18:3)
Block(7,28,-7,18:3)
Block(7,28,-6,18:3)
Block(7,28,-5,18:3)
Block(7,28,-3,18:3)
Block(7,28,-1,17:7)
Block(7,28,0,18:3)
Block(7,28,1,18:3)
Block(7,28,2,18:3)
Block(7,28,3,18:3)
Block(7,28,4,18:3)
Block(7,28,5,18:3)
Block(7,28,7,18:3)
Block(7,29,-7,18:3)
Block(7,29,-1,18:3)
Block(7,29,5,18:3)
Block(7,30,-2,18:3)
Block(7,30,-1,18:3)
Block(8,16,4,106:1)
Block(8,17,4,106:1)
Block(8,18,-12,106:1)
Block(8,18,4,106:1)
Block(8,19,-12,106:1)
Block(8,19,-10,18:3)
Block(8,19,-9,18:3)
Block(8,19,-6,106:4)
Block(8,19,4,106:1)
Block(8,19,7,18:3)
Block(8,20,-12,106:1)
Block(8,20,-10,18:3)
Block(8,20,-6,106:4)
Block(8,20,4,106:1)
Block(8,20,7,18:3)
Block(8,20,9,18:3)
Block(8,20,10,18:3)
Block(8,21,-12,106:1)
Block(8,21,-11,18:3)
Block(8,21,-10,18:3)
Block(8,21,-9,18:3)
Block(8,21,-8,18:3)
Block(8,21,-7,18:3)
Block(8,21,-6,106:4)
Block(8,21,4,106:1)
Block(8,21,5,18:3)
Block(8,21,6,18:3)
Block(8,21,7,18:3)
Block(8,21,8,18:3)
Block(8,21,9,18:3)
Block(8,21,10,106:4)
Block(8,22,-11,18:3)
Block(8,22,-10,18:3)
Block(8,22,-9,18:3)
Block(8,22,-8,18:3)
Block(8,22,-7,18:3)
Block(8,22,5,18:3)
Block(8,22,6,18:3)
Block(8,22,7,18:3)
Block(8,22,8,18:3)
Block(8,23,-10,18:3)
Block(8,23,-9,17:7)
Block(8,23,-8,18:3)
Block(8,23,-7,18:3)
Block(8,23,-6,18:3)
Block(8,23,-5,18:3)
Block(8,23,3,18:3)
Block(8,23,6,18:3)
Block(8,23,7,17:7)
Block(8,23,8,18:3)
Block(8,23,9,18:3)
Block(8,24,-12,18:3)
Block(8,24,-11,18:3)
Block(8,24,-10,18:3)
Block(8,24,-9,18:3)
Block(8,24,-8,18:3)
Block(8,24,-7,18:3)
Block(8,24,5,18:3)
Block(8,24,6,18:3)
Block(8,24,8,18:3)
Block(8,25,-10,18:3)
Block(8,25,-9,18:3)
Block(8,25,-8,18:3)
Block(8,25,-7,18:3)
Block(8,25,-2,18:3)
Block(8,25,2,18:3)
Block(8,25,4,18:3)
Block(8,25,5,18:3)
Block(8,25,6,18:3)
Block(8,25,7,18:3)
Block(8,26,-10,18:3)
Block(8,26,-9,18:3)
Block(8,26,-8,17:3)
Block(8,26,-7,18:3)
Block(8,26,-6,18:3)
Block(8,26,-5,18:3)
Block(8,26,-3,18:3)
Block(8,26,1,18:3)
Block(8,26,4,18:3)
Block(8,26,5,18:3)
Block(8,26,6,17:3)
Block(8,26,7,18:3)
Block(8,26,8,18:3)
Block(8,27,-10,18:3)
Block(8,27,-8,18:3)
Block(8,27,-7,18:3)
Block(8,27,-6,18:3)
Block(8,27,-5,18:3)
Block(8,27,-3,18:3)
Block(8,27,-2,18:3)
Block(8,27,-1,17:7)
Block(8,27,0,18:3)
Block(8,27,1,18:3)
Block(8,27,3,18:3)
Block(8,27,4,18:3)
Block(8,27,5,18:3)
Block(8,27,6,18:3)
Block(8,27,7,18:3)
Block(8,27,8,18:3)
Block(8,28,-9,18:3)
Block(8,28,-8,18:3)
Block(8,28,-7,18:3)
Block(8,28,-6,18:3)
Block(8,28,-5,18:3)
Block(8,28,-3,18:3)
Block(8,28,-2,18:3)
Block(8,28,-1,18:3)
Block(8,28,0,18:3)
Block(8,28,1,18:3)
Block(8,28,2,18:3)
Block(8,28,3,18:3)
Block(8,28,6,18:3)
Block(8,29,-8,18:3)
Block(8,29,-5,18:3)
Block(8,29,-3,18:3)
Block(8,29,-1,18:3)
Block(8,29,0,18:3)
Block(8,29,1,18:3)
Block(9,17,-1,106:8)
Block(9,18,-1,106:8)
Block(9,19,-12,106:1)
Block(9,19,-10,18:3)
Block(9,19,-1,106:8)
Block(9,19,6,18:3)
Block(9,19,7,18:3)
Block(9,19,8,18:3)
Block(9,20,-12,106:1)
Block(9,20,-9,18:3)
Block(9,20,-8,18:3)
Block(9,20,-7,18:3)
Block(9,20,-1,106:8)
Block(9,20,5,18:3)
Block(9,20,6,18:3)
Block(9,20,7,18:3)
Block(9,20,9,18:3)
Block(9,21,-12,106:1)
Block(9,21,-11,18:3)
Block(9,21,-10,18:3)
Block(9,21,-9,17:3)
Block(9,21,-8,18:3)
Block(9,21,-7,18:3)
Block(9,21,-6,18:3)
Block(9,21,-1,106:8)
Block(9,21,5,18:3)
Block(9,21,6,18:3)
Block(9,21,7,17:3)
Block(9,21,8,18:3)
Block(9,21,9,18:3)
Block(9,22,-12,18:3)
Block(9,22,-11,18:3)
Block(9,22,-10,18:3)
Block(9,22,-9,17:3)
Block(9,22,-8,18:3)
Block(9,22,-7,18:3)
Block(9,22,-5,18:3)
Block(9,22,-2,18:3)
Block(9,22,-1,18:3)
Block(9,22,1,18:3)
Block(9,22,4,18:3)
Block(9,22,5,18:3)
Block(9,22,6,18:3)
Block(9,22,7,17:3)
Block(9,22,8,18:3)
Block(9,22,9,18:3)
Block(9,23,-11,18:3)
Block(9,23,-10,17:11)
Block(9,23,-9,17:3)
Block(9,23,-8,17:11)
Block(9,23,-7,17:11)
Block(9,23,-6,18:3)
Block(9,23,-2,18:3)
Block(9,23,-1,18:3)
Block(9,23,3,18:3)
Block(9,23,4,18:3)
Block(9,23,5,17:11)
Block(9,23,6,17:11)
Block(9,23,7,17:3)
Block(9,23,8,17:11)
Block(9,23,9,18:3)
Block(9,23,10,18:3)
Block(9,24,-12,18:3)
Block(9,24,-11,18:3)
Block(9,24,-10,18:3)
Block(9,24,-9,17:3)
Block(9,24,-8,18:3)
Block(9,24,-7,18:3)
Block(9,24,4,18:3)
Block(9,24,5,18:3)
Block(9,24,6,18:3)
Block(9,24,7,17:3)
Block(9,25,-11,18:3)
Block(9,25,-10,18:3)
Block(9,25,-9,17:3)
Block(9,25,-8,18:3)
Block(9,25,-7,18:3)
Block(9,25,-6,18:3)
Block(9,25,-2,18:3)
Block(9,25,-1,18:3)
Block(9,25,1,18:3)
Block(9,25,2,18:3)
Block(9,25,4,18:3)
Block(9,25,5,18:3)
Block(9,25,6,18:3)
Block(9,25,7,17:3)
Block(9,25,8,18:3)
Block(9,26,-9,18:3)
Block(9,26,-8,18:3)
Block(9,26,-7,18:3)
Block(9,26,-6,18:3)
Block(9,26,-5,18:3)
Block(9,26,-4,18:3)
Block(9,26,-3,18:3)
Block(9,26,-2,18:3)
Block(9,26,0,18:3)
Block(9,26,1,18:3)
Block(9,26,2,18:3)
Block(9,26,3,18:3)
Block(9,26,4,18:3)
Block(9,26,5,18:3)
Block(9,26,6,18:3)
Block(9,26,7,18:3)
Block(9,26,8,18:3)
Block(9,27,-7,18:3)
Block(9,27,-6,18:3)
Block(9,27,-5,18:3)
Block(9,27,-4,18:3)
Block(9,27,-3,17:11)
Block(9,27,-2,17:11)
Block(9,27,-1,17:7)
Block(9,27,0,17:11)
Block(9,27,1,17:11)
Block(9,27,2,18:3)
Block(9,27,3,18:3)
Block(9,27,5,18:3)
Block(9,27,6,18:3)
Block(9,27,7,18:3)
Block(9,28,-9,18:3)
Block(9,28,-8,18:3)
Block(9,28,-7,18:3)
Block(9,28,-6,18:3)
Block(9,28,-4,18:3)
Block(9,28,-3,18:3)
Block(9,28,-2,18:3)
Block(9,28,0,18:3)
Block(9,28,1,18:3)
Block(9,28,6,18:3)
Block(9,29,-3,18:3)
Block(9,29,-2,18:3)
Block(9,29,2,18:3)
Block(10,16,-12,106:1)
Block(10,17,-12,106:1)
Block(10,18,-12,106:1)
Block(10,18,0,106:4)
Block(10,18,4,106:1)
Block(10,19,-12,106:1)
Block(10,19,-2,106:8)
Block(10,19,0,106:4)
Block(10,19,4,106:1)
Block(10,19,7,18:3)
Block(10,20,-12,106:1)
Block(10,20,-11,18:3)
Block(10,20,-10,18:3)
Block(10,20,-9,18:3)
Block(10,20,-2,106:8)
Block(10,20,0,106:4)
Block(10,20,4,106:1)
Block(10,20,5,18:3)
Block(10,20,7,18:3)
Block(10,20,8,18:3)
Block(10,20,9,106:2)
Block(10,21,-12,106:1)
Block(10,21,-11,18:3)
Block(10,21,-8,18:3)
Block(10,21,-7,18:3)
Block(10,21,-2,106:8)
Block(10,21,-1,18:3)
Block(10,21,0,106:4)
Block(10,21,4,106:1)
Block(10,21,5,18:3)
Block(10,21,7,18:3)
Block(10,21,8,18:3)
Block(10,21,9,106:2)
Block(10,22,-12,18:3)
Block(10,22,-11,18:3)
Block(10,22,-10,18:3)
Block(10,22,-7,18:3)
Block(10,22,-6,18:3)
Block(10,22,-1,18:3)
Block(10,22,0,18:3)
Block(10,22,1,18:3)
Block(10,22,5,18:3)
Block(10,22,6,18:3)
Block(10,22,7,18:3)
Block(10,23,-12,18:3)
Block(10,23,-11,18:3)
Block(10,23,-10,18:3)
Block(10,23,-9,17:7)
Block(10,23,-8,18:3)
Block(10,23,-7,18:3)
Block(10,23,-6,18:3)
Block(10,23,-5,18:3)
Block(10,23,-2,18:3)
Block(10,23,-1,18:3)
Block(10,23,0,18:3)
Block(10,23,1,18:3)
Block(10,23,5,18:3)
Block(10,23,6,18:3)
Block(10,23,7,17:7)
Block(10,23,8,18:3)
Block(10,23,9,18:3)
Block(10,24,-11,18:3)
Block(10,24,-10,18:3)
Block(10,24,-1,18:3)
Block(10,24,0,18:3)
Block(10,24,5,18:3)
Block(10,24,6,18:3)
Block(10,24,7,18:3)
Block(10,24,8,18:3)
Block(10,25,-10,18:3)
Block(10,25,-8,18:3)
Block(10,25,-7,18:3)
Block(10,25,-6,18:3)
Block(10,25,-4,18:3)
Block(10,25,-3,18:3)
Block(10,25,-1,18:3)
Block(10,25,0,18:3)
Block(10,25,1,18:3)
Block(10,25,5,18:3)
Block(10,25,6,18:3)
Block(10,25,7,18:3)
Block(10,26,-8,18:3)
Block(10,26,-7,18:3)
Block(10,26,-1,18:3)
Block(10,26,0,18:3)
Block(10,26,1,18:3)
Block(10,26,4,18:3)
Block(10,26,6,18:3)
Block(10,26,7,18:3)
Block(10,27,-9,18:3)
Block(10,27,-7,18:3)
Block(10,27,-3,18:3)
Block(10,27,-2,18:3)
Block(10,27,-1,17:7)
Block(10,27,0,18:3)
Block(10,27,1,18:3)
Block(10,27,5,18:3)
Block(10,28,-3,18:3)
Block(10,28,-1,18:3)
Block(10,28,0,18:3)
Block(10,28,1,18:3)
Block(10,28,2,18:3)
Block(10,29,-4,18:3)
Block(10,29,-3,18:3)
Block(10,29,-2,18:3)
Block(10,29,0,18:3)
Block(10,29,2,18:3)
Block(11,16,-11,106:2)
Block(11,17,-11,106:2)
Block(11,18,-11,106:2)
Block(11,19,-11,106:2)
Block(11,19,-7,106:2)
Block(11,19,6,106:1)
Block(11,20,-11,106:2)
Block(11,20,-7,106:2)
Block(11,20,-2,18:3)
Block(11,20,-1,18:3)
Block(11,20,6,106:1)
Block(11,20,7,18:3)
Block(11,20,8,18:3)
Block(11,21,-11,106:2)
Block(11,21,-8,18:3)
Block(11,21,-7,106:2)
Block(11,21,-2,18:3)
Block(11,21,-1,18:3)
Block(11,21,0,18:3)
Block(11,21,6,106:1)
Block(11,21,7,18:3)
Block(11,21,8,106:2)
Block(11,22,-9,18:3)
Block(11,22,-8,18:3)
Block(11,22,-7,18:3)
Block(11,22,-6,18:3)
Block(11,22,-4,18:3)
Block(11,22,-3,18:3)
Block(11,22,-2,18:3)
Block(11,22,-1,18:3)
Block(11,22,0,18:3)
Block(11,22,1,18:3)
Block(11,22,4,18:3)
Block(11,22,5,18:3)
Block(11,22,6,18:3)
Block(11,22,7,18:3)
Block(11,23,-11,18:3)
Block(11,23,-10,18:3)
Block(11,23,-8,18:3)
Block(11,23,-6,18:3)
Block(11,23,-4,18:3)
Block(11,23,-3,18:3)
Block(11,23,-2,18:3)
Block(11,23,-1,17:7)
Block(11,23,0,18:3)
Block(11,23,1,18:3)
Block(11,23,2,18:3)
Block(11,23,4,18:3)
Block(11,23,5,18:3)
Block(11,23,7,18:3)
Block(11,23,8,18:3)
Block(11,24,-10,18:3)
Block(11,24,-9,18:3)
Block(11,24,-6,18:3)
Block(11,24,-3,18:3)
Block(11,24,-2,18:3)
Block(11,24,-1,18:3)
Block(11,24,0,18:3)
Block(11,24,1,18:3)
Block(11,24,2,18:3)
Block(11,24,8,18:3)
Block(11,24,9,18:3)
Block(11,25,-7,18:3)
Block(11,25,-2,18:3)
Block(11,25,-1,18:3)
Block(11,25,0,18:3)
Block(11,25,5,18:3)
Block(11,25,7,18:3)
Block(11,26,-5,18:3)
Block(11,26,-4,18:3)
Block(11,26,-3,18:3)
Block(11,26,-2,18:3)
Block(11,26,-1,17:3)
Block(11,26,0,18:3)
Block(11,26,1,18:3)
Block(11,26,2,18:3)
Block(11,26,4,18:3)
Block(11,27,-3,18:3)
Block(11,27,-2,18:3)
Block(11,27,-1,18:3)
Block(11,27,0,18:3)
Block(11,27,1,18:3)
Block(11,27,2,18:3)
Block(11,27,3,18:3)
Block(11,28,-1,18:3)
Block(11,28,1,18:3)
Block(11,28,2,18:3)
Block(12,16,-8,106:2)
Block(12,17,-8,106:2)
Block(12,18,-8,106:2)
Block(12,19,-8,106:2)
Block(12,19,7,106:2)
Block(12,20,-8,106:2)
Block(12,20,-2,18:3)
Block(12,20,-1,18:3)
Block(12,20,1,18:3)
Block(12,20,7,106:2)
Block(12,21,-8,106:2)
Block(12,21,-4,18:3)
Block(12,21,-3,18:3)
Block(12,21,-2,18:3)
Block(12,21,-1,18:3)
Block(12,21,0,18:3)
Block(12,21,1,18:3)
Block(12,21,7,106:2)
Block(12,22,-6,18:3)
Block(12,22,-3,18:3)
Block(12,22,-2,18:3)
Block(12,22,-1,18:3)
Block(12,22,0,18:3)
Block(12,22,1,18:3)
Block(12,22,8,18:3)
Block(12,23,-8,18:3)
Block(12,23,-5,18:3)
Block(12,23,-4,18:3)
Block(12,23,-3,18:3)
Block(12,23,-2,18:3)
Block(12,23,-1,17:7)
Block(12,23,0,18:3)
Block(12,23,1,18:3)
Block(12,23,3,18:3)
Block(12,23,5,18:3)
Block(12,23,7,18:3)
Block(12,23,8,18:3)
Block(12,24,-9,18:3)
Block(12,24,-4,18:3)
Block(12,24,-3,18:3)
Block(12,24,-2,18:3)
Block(12,24,0,18:3)
Block(12,24,3,18:3)
Block(12,24,8,18:3)
Block(12,25,-5,18:3)
Block(12,25,-4,18:3)
Block(12,25,-3,18:3)
Block(12,25,-2,18:3)
Block(12,25,-1,17:3)
Block(12,25,1,18:3)
Block(12,26,-3,18:3)
Block(12,26,-2,18:3)
Block(12,26,-1,18:3)
Block(12,26,1,18:3)
Block(12,27,-1,18:3)
Block(12,28,-1,18:3)
Block(13,19,-2,18:3)
Block(13,19,-1,18:3)
Block(13,19,3,106:4)
Block(13,20,-3,18:3)
Block(13,20,-1,18:3)
Block(13,20,0,18:3)
Block(13,20,1,18:3)
Block(13,20,3,106:4)
Block(13,21,-3,18:3)
Block(13,21,-2,18:3)
Block(13,21,-1,17:3)
Block(13,21,0,18:3)
Block(13,21,2,18:3)
Block(13,21,3,106:4)
Block(13,22,-5,18:3)
Block(13,22,-4,18:3)
Block(13,22,-3,18:3)
Block(13,22,-2,18:3)
Block(13,22,-1,17:3)
Block(13,22,0,18:3)
Block(13,22,1,18:3)
Block(13,22,3,18:3)
Block(13,23,-4,18:3)
Block(13,23,-3,17:11)
Block(13,23,-2,17:11)
Block(13,23,-1,17:3)
Block(13,23,0,17:11)
Block(13,23,1,17:11)
Block(13,23,2,18:3)
Block(13,23,3,18:3)
Block(13,23,4,18:3)
Block(13,24,-4,18:3)
Block(13,24,-3,18:3)
Block(13,24,-2,18:3)
Block(13,24,-1,17:3)
Block(13,24,0,18:3)
Block(13,24,1,18:3)
Block(13,24,3,18:3)
Block(13,25,-3,18:3)
Block(13,25,-2,18:3)
Block(13,25,0,18:3)
Block(13,25,1,18:3)
Block(13,25,2,18:3)
Block(13,26,-2,18:3)
Block(13,26,-1,18:3)
Block(13,26,0,18:3)
Block(13,27,-1,18:3)
Block(14,18,-5,106:1)
Block(14,19,-5,106:1)
Block(14,19,-1,18:3)
Block(14,20,-5,106:1)
Block(14,20,0,18:3)
Block(14,20,1,18:3)
Block(14,20,2,18:3)
Block(14,21,-5,106:1)
Block(14,21,-4,18:3)
Block(14,21,-3,18:3)
Block(14,21,-1,18:3)
Block(14,21,1,18:3)
Block(14,21,2,106:2)
Block(14,22,-3,18:3)
Block(14,22,-2,18:3)
Block(14,22,-1,18:3)
Block(14,22,1,18:3)
Block(14,23,-4,18:3)
Block(14,23,-3,18:3)
Block(14,23,-2,18:3)
Block(14,23,-1,18:3)
Block(14,23,0,18:3)
Block(14,23,1,18:3)
Block(14,23,3,18:3)
Block(14,24,-5,18:3)
Block(14,24,-3,18:3)
Block(14,24,-1,18:3)
Block(14,24,1,18:3)
Block(14,24,3,18:3)
Block(14,25,-4,18:3)
Block(14,25,-3,18:3)
Block(14,25,0,18:3)
Block(14,25,1,18:3)
Block(14,26,-2,18:3)
Block(15,16,1,106:2)
Block(15,17,1,106:2)
Block(15,18,1,106:2)
Block(15,19,-3,106:2)
Block(15,19,1,106:2)
Block(15,20,-3,106:2)
Block(15,20,0,18:3)
Block(15,20,1,106:2)
Block(15,21,-3,106:2)
Block(15,21,-1,18:3)
Block(15,21,1,106:2)
Block(15,22,-3,18:3)
Block(15,22,-1,18:3)
Block(15,22,0,18:3)
Block(15,22,1,18:3)
Block(15,23,-4,18:3)
Block(15,23,-2,18:3)
Block(15,23,0,18:3)
Block(15,24,-4,18:3)
Block(15,24,-3,18:3)
Block(15,24,1,18:3)
Block(15,25,0,18:3)
Block(16,15,-1,106:2)
Block(16,16,-1,106:2)
Block(16,17,-1,106:2)
Block(16,18,-1,106:2)
Block(16,19,-1,106:2)
Block(16,20,-1,106:2)
Block(16,21,-1,106:2)


#######################################################################
# +-----------------------------------------------------------------+ #
# |                             Entities                            | #
# +-----------------------------------------------------------------+ #
#######################################################################

# Entity() spawns an entity instead of a block. The entity is spawned only once when the BO3 is spawned.
# Entities are persistent by default so they don't de-spawn when no player is near, they are only unloaded.
# Usage: Entity(x,y,z,mobName,groupSize,NameTagOrNBTFileName) or Entity(x,y,z,mobName,groupSize)
# Use /tc entities or /otg entities to get a list of entities that can be used as mobName, this includes entities added by other mods.
# NameTagOrNBTFileName can be either a nametag for the mob or an nbt file (such as mymobinfo.nbt or mymobinfo.txt).
# When using a text file you can use the same mob spawning parameters used with the /summon command to equip the
# entity and give it custom attributes etc. You can copy the DATA part of a summon command including surrounding
# curly braces to a .txt file, for instance for: "/summon Skeleton x y z {DATA}"

#######################################################################
# +-----------------------------------------------------------------+ #
# |                            BO3 checks                           | #
# +-----------------------------------------------------------------+ #
#######################################################################

# Require a condition at a certain location in order for the BO3 to be spawned.
# BlockCheck(x,y,z,BlockName[,BlockName[,...]]) - one of the blocks must be at the location
# BlockCheckNot(x,y,z,BlockName[,BlockName[,...]]) - all the blocks must not be at the location
# LightCheck(x,y,z,minLightLevel,maxLightLevel) - light must be between min and max (inclusive)

# You can use "Solid" as a BlockName for matching all solid blocks or "All" to match all blocks that aren't air.

# Examples:
#   BlockCheck(0,-1,0,GRASS,DIRT)  Require grass or dirt just below the object
#   BlockCheck(0,-1,0,Solid)       Require any solid block just below the object
#   BlockCheck(0,-1,0,WOOL)        Require any type of wool just below the object
#   BlockCheck(0,-1,0,WOOL:0)      Require white wool just below the object
#   BlockCheckNot(0,-1,0,WOOL:0)   Require that there is no white wool below the object
#   LightCheck(0,0,0,0,1)          Require almost complete darkness just below the object
BlockCheck(0,10,0,AIR)
BlockCheck(0,5,0,AIR)
BlockCheck(0,2,0,AIR)
BlockCheck(-4,0,-4,Solid)
BlockCheck(-3,0,-4,Solid)
BlockCheck(-2,0,-4,Solid)
BlockCheck(-1,0,-4,Solid)
BlockCheck(0,0,-4,Solid)
BlockCheck(1,0,-4,Solid)
BlockCheck(2,0,-4,Solid)
BlockCheck(3,0,-4,Solid)
BlockCheck(4,0,-4,Solid)
BlockCheck(-4,0,-3,Solid)
BlockCheck(-3,0,-3,Solid)
BlockCheck(-2,0,-3,Solid)
BlockCheck(-1,0,-3,Solid)
BlockCheck(0,0,-3,Solid)
BlockCheck(1,0,-3,Solid)
BlockCheck(2,0,-3,Solid)
BlockCheck(3,0,-3,Solid)
BlockCheck(4,0,-3,Solid)
BlockCheck(-4,0,-2,Solid)
BlockCheck(-3,0,-2,Solid)
BlockCheck(-2,0,-2,Solid)
BlockCheck(-1,0,-2,Solid)
BlockCheck(0,0,-2,Solid)
BlockCheck(1,0,-2,Solid)
BlockCheck(2,0,-2,Solid)
BlockCheck(3,0,-2,Solid)
BlockCheck(4,0,-2,Solid)
BlockCheck(-4,0,-1,Solid)
BlockCheck(-3,0,-1,Solid)
BlockCheck(-2,0,-1,Solid)
BlockCheck(-1,0,-1,Solid)
BlockCheck(0,0,-1,Solid)
BlockCheck(1,0,-1,Solid)
BlockCheck(2,0,-1,Solid)
BlockCheck(3,0,-1,Solid)
BlockCheck(4,0,-1,Solid)
BlockCheck(-4,0,0,Solid)
BlockCheck(-3,0,0,Solid)
BlockCheck(-2,0,0,Solid)
BlockCheck(-1,0,0,Solid)
BlockCheck(0,0,0,Solid)
BlockCheck(1,0,0,Solid)
BlockCheck(2,0,0,Solid)
BlockCheck(3,0,0,Solid)
BlockCheck(4,0,0,Solid)
BlockCheck(-4,0,1,Solid)
BlockCheck(-3,0,1,Solid)
BlockCheck(-2,0,1,Solid)
BlockCheck(-1,0,1,Solid)
BlockCheck(0,0,1,Solid)
BlockCheck(1,0,1,Solid)
BlockCheck(2,0,1,Solid)
BlockCheck(3,0,1,Solid)
BlockCheck(4,0,1,Solid)
BlockCheck(-4,0,2,Solid)
BlockCheck(-3,0,2,Solid)
BlockCheck(-2,0,2,Solid)
BlockCheck(-1,0,2,Solid)
BlockCheck(0,0,2,Solid)
BlockCheck(1,0,2,Solid)
BlockCheck(2,0,2,Solid)
BlockCheck(3,0,2,Solid)
BlockCheck(4,0,2,Solid)
BlockCheck(-4,0,3,Solid)
BlockCheck(-3,0,3,Solid)
BlockCheck(-2,0,3,Solid)
BlockCheck(-1,0,3,Solid)
BlockCheck(0,0,3,Solid)
BlockCheck(1,0,3,Solid)
BlockCheck(2,0,3,Solid)
BlockCheck(3,0,3,Solid)
BlockCheck(4,0,3,Solid)
BlockCheck(-4,0,4,Solid)
BlockCheck(-3,0,4,Solid)
BlockCheck(-2,0,4,Solid)
BlockCheck(-1,0,4,Solid)
BlockCheck(0,0,4,Solid)
BlockCheck(1,0,4,Solid)
BlockCheck(2,0,4,Solid)
BlockCheck(3,0,4,Solid)
BlockCheck(4,0,4,Solid)

