#######################################################################
# +-----------------------------------------------------------------+ #
# |                            BO3 object                           | #
# +-----------------------------------------------------------------+ #
#######################################################################

# The descriptions in this file are accurate only for TerrainControl and OTG.
# For MCW and OTG+ these descriptions are only accurate if the BO3 is used as a CustomObject.
# MCW and OTG+ completely reimplemented CustomStructure, check the MCW/OTG+ documentation for more information.

# This is the config file of a custom object.
# If you add this object correctly to your BiomeConfigs, it will spawn in the world.

# This is the creator of this BO3 object
Author: Unknown

# A short description of this BO3 object
Description: This BO3 was converted from a schematic using OTGEdit. The author and description information of the schematic could not be found. If you know who the author of the schematic is then please add this information.

# The BO3 version, don't change this! It can be used by external applications to do a version check.
Version: 3

# The settings mode, WriteAll, WriteWithoutComments or WriteDisable. See WorldConfig.
SettingsMode: WriteDisable

#######################################################################
# +-----------------------------------------------------------------+ #
# |                          Main settings                          | #
# +-----------------------------------------------------------------+ #
#######################################################################

# This needs to be set to true to spawn the object in the Tree and Sapling resources.
Tree: false

# The frequency of the BO3 from 1 to 200. Tries this many times to spawn this BO3 when using the CustomObject(...) resource.
# Ignored by Tree(..), Sapling(..) and CustomStructure(..)
Frequency: 40

# The rarity of the BO3 from 0 to 100. Each spawn attempt has rarity% chance to succeed when using the CustomObject(...) resource.
# Ignored by Tree(..), Sapling(..) and CustomStructure(..)
Rarity: 100.0

# If you set this to true, the BO3 will be placed with a random rotation.
RotateRandomly: true

# The spawn height of the BO3 - randomY, highestBlock or highestSolidBlock.
SpawnHeight: randomY

# The height limits for the BO3.
MinHeight: 0

MaxHeight: 256

# Objects can have other objects attached to it: branches. Branches can also
# have branches attached to it, which can also have branches, etc. This is the
# maximum branch depth for this objects.
MaxBranchDepth: 10

# When spawned with the UseWorld keyword, this BO3 should NOT spawn in the following biomes.
# If you writer.write the BO3 name directly in the BiomeConfigs, this will be ignored.
ExcludedBiomes: All

# To optimise this BO3 for faster loading times you can use Notepad++ to find/replace comments and abbreviate things.
# Notepad++ find/replace with regex:
# Find: ^[#;].* replace to nothing removes all lines starting with # 
# Find: ^\s*$ replace to nothing removes most empty lines 
# Notepad++ find/replace without regex:
# *Warning: This will only work for OTG 1.10.2 v21 / OTG 1.11.2 v6 or higher. B( is not recognised by lower versions.
# Find: Block( replace to B(

#######################################################################
# +-----------------------------------------------------------------+ #
# |                      Source block settings                      | #
# +-----------------------------------------------------------------+ #
#######################################################################

# The block(s) the BO3 should spawn in.
SourceBlocks: AIR

# The maximum percentage of the BO3 that can be outside the SourceBlock.
# The BO3 won't be placed on a location with more blocks outside the SourceBlock than this percentage.
MaxPercentageOutsideSourceBlock: 100

# What to do when a block is about to be placed outside the SourceBlock? (dontPlace, placeAnyway)
OutsideSourceBlock: placeAnyway

#######################################################################
# +-----------------------------------------------------------------+ #
# |                              Blocks                             | #
# +-----------------------------------------------------------------+ #
#######################################################################

# All the blocks used in the BO3 are listed here. Possible blocks:
# Block(x,y,z,id[.data][,nbtfile.nbt) or B(x,y,z,id[.data][,nbtfile.nbt)
# RandomBlock(x,y,z,id[:data][,nbtfile.nbt],chance[,id[:data][,nbtfile.nbt],chance[,...]])
# So RandomBlock(0,0,0,CHEST,chest.nbt,50,CHEST,anotherchest.nbt,100) will spawn a chest at
# the BO3 origin, and give it a 50% chance to have the contents of chest.nbt, or, if that
# fails, a 100% percent chance to have the contents of anotherchest.nbt.

Block(-35,22,-1,106:8)
Block(-35,23,-1,106:8)
Block(-35,23,0,106:8)
Block(-35,24,-1,106:8)
Block(-35,24,0,106:8)
Block(-35,25,-1,106:8)
Block(-35,25,0,106:8)
Block(-34,23,3,106:8)
Block(-34,24,-2,106:8)
Block(-34,24,-1,18:3)
Block(-34,24,0,18:3)
Block(-34,24,3,106:8)
Block(-34,25,-2,106:8)
Block(-34,25,-1,18:3)
Block(-34,25,0,18:3)
Block(-34,25,3,106:8)
Block(-34,26,-2,106:8)
Block(-34,26,-1,106:8)
Block(-34,26,0,18:3)
Block(-34,26,1,18:3)
Block(-34,27,-1,106:8)
Block(-34,27,0,106:8)
Block(-33,19,-3,106:1)
Block(-33,19,0,18:3)
Block(-33,20,-3,106:1)
Block(-33,20,-1,18:3)
Block(-33,20,0,18:3)
Block(-33,20,1,18:3)
Block(-33,21,-3,106:1)
Block(-33,21,0,18:3)
Block(-33,22,-3,106:1)
Block(-33,23,-3,106:1)
Block(-33,23,-1,18:3)
Block(-33,24,-3,106:1)
Block(-33,24,-2,18:3)
Block(-33,24,1,18:3)
Block(-33,24,2,18:3)
Block(-33,25,-3,106:1)
Block(-33,25,-2,18:3)
Block(-33,25,-1,18:3)
Block(-33,25,0,18:3)
Block(-33,25,1,106:8)
Block(-33,25,3,18:3)
Block(-33,26,-3,106:1)
Block(-33,26,-2,18:3)
Block(-33,26,-1,18:3)
Block(-33,26,0,18:3)
Block(-33,26,1,18:3)
Block(-33,27,-1,18:3)
Block(-33,27,0,18:3)
Block(-33,27,3,18:3)
Block(-33,28,-1,18:3)
Block(-32,18,-3,106:1)
Block(-32,18,-1,18:3)
Block(-32,18,0,18:3)
Block(-32,19,-3,106:1)
Block(-32,19,1,18:3)
Block(-32,19,2,18:3)
Block(-32,20,-3,106:1)
Block(-32,20,-1,18:3)
Block(-32,20,0,18:3)
Block(-32,21,-3,106:1)
Block(-32,21,-2,18:3)
Block(-32,22,-3,106:1)
Block(-32,22,-1,18:3)
Block(-32,22,0,18:3)
Block(-32,22,1,18:3)
Block(-32,23,-3,106:1)
Block(-32,23,4,106:4)
Block(-32,23,5,106:8)
Block(-32,24,-3,106:1)
Block(-32,24,-1,18:3)
Block(-32,24,0,18:3)
Block(-32,24,2,18:3)
Block(-32,24,3,18:3)
Block(-32,24,4,106:4)
Block(-32,24,5,106:8)
Block(-32,25,-3,106:1)
Block(-32,25,-2,18:3)
Block(-32,25,-1,18:3)
Block(-32,25,0,18:3)
Block(-32,25,1,18:3)
Block(-32,25,2,18:3)
Block(-32,25,3,18:3)
Block(-32,25,4,106:4)
Block(-32,25,5,106:8)
Block(-32,26,-3,18:3)
Block(-32,26,-2,18:3)
Block(-32,26,-1,18:3)
Block(-32,26,0,18:3)
Block(-32,26,1,18:3)
Block(-32,26,2,18:3)
Block(-32,26,3,18:3)
Block(-32,26,4,18:3)
Block(-32,27,-1,18:3)
Block(-32,27,0,18:3)
Block(-32,27,1,18:3)
Block(-32,28,-2,18:3)
Block(-32,28,-1,18:3)
Block(-32,28,0,18:3)
Block(-32,28,1,18:3)
Block(-32,28,4,18:3)
Block(-32,29,-3,18:3)
Block(-31,18,-1,18:3)
Block(-31,18,0,18:3)
Block(-31,19,-2,18:3)
Block(-31,19,-1,18:3)
Block(-31,19,0,18:3)
Block(-31,19,2,18:3)
Block(-31,20,-1,18:3)
Block(-31,20,0,17:3)
Block(-31,20,1,18:3)
Block(-31,20,2,18:3)
Block(-31,21,-1,18:3)
Block(-31,21,0,17:3)
Block(-31,21,1,18:3)
Block(-31,21,6,106:4)
Block(-31,22,-4,106:1)
Block(-31,22,-1,18:3)
Block(-31,22,0,17:3)
Block(-31,22,1,18:3)
Block(-31,22,6,106:4)
Block(-31,23,-4,106:1)
Block(-31,23,-2,18:3)
Block(-31,23,0,17:3)
Block(-31,23,1,18:3)
Block(-31,23,2,18:3)
Block(-31,23,3,18:3)
Block(-31,23,6,106:4)
Block(-31,24,-4,106:1)
Block(-31,24,-2,18:3)
Block(-31,24,-1,18:3)
Block(-31,24,0,17:3)
Block(-31,24,1,18:3)
Block(-31,24,2,18:3)
Block(-31,24,6,106:4)
Block(-31,25,-4,106:1)
Block(-31,25,-3,18:3)
Block(-31,25,-1,18:3)
Block(-31,25,0,17:3)
Block(-31,25,1,18:3)
Block(-31,25,2,18:3)
Block(-31,25,3,18:3)
Block(-31,25,5,18:3)
Block(-31,25,6,106:4)
Block(-31,26,-2,18:3)
Block(-31,26,-1,18:3)
Block(-31,26,0,17:3)
Block(-31,26,1,18:3)
Block(-31,26,2,18:3)
Block(-31,26,4,18:3)
Block(-31,27,-3,18:3)
Block(-31,27,0,18:3)
Block(-31,27,1,18:3)
Block(-31,27,2,18:3)
Block(-31,28,-3,18:3)
Block(-31,28,-2,18:3)
Block(-31,28,-1,18:3)
Block(-31,28,0,18:3)
Block(-31,28,3,18:3)
Block(-31,28,4,18:3)
Block(-31,29,-5,18:3)
Block(-31,29,-1,18:3)
Block(-31,29,1,18:3)
Block(-31,29,2,18:3)
Block(-31,29,3,18:3)
Block(-31,30,-4,18:3)
Block(-31,30,-3,18:3)
Block(-31,30,0,18:3)
Block(-31,30,3,18:3)
Block(-31,30,4,18:3)
Block(-31,31,-4,18:3)
Block(-31,31,0,18:3)
Block(-31,32,0,18:3)
Block(-30,18,0,18:3)
Block(-30,19,6,106:4)
Block(-30,20,-2,18:3)
Block(-30,20,0,18:3)
Block(-30,20,2,18:3)
Block(-30,20,4,106:4)
Block(-30,20,6,106:4)
Block(-30,21,-2,18:3)
Block(-30,21,-1,18:3)
Block(-30,21,4,106:4)
Block(-30,21,6,106:4)
Block(-30,22,0,18:3)
Block(-30,22,1,18:3)
Block(-30,22,4,106:4)
Block(-30,22,6,106:4)
Block(-30,23,-1,18:3)
Block(-30,23,1,18:3)
Block(-30,23,2,18:3)
Block(-30,23,3,18:3)
Block(-30,23,4,106:4)
Block(-30,23,6,106:4)
Block(-30,24,-3,18:3)
Block(-30,24,-2,18:3)
Block(-30,24,-1,18:3)
Block(-30,24,0,18:3)
Block(-30,24,2,18:3)
Block(-30,24,3,18:3)
Block(-30,24,4,106:4)
Block(-30,24,6,106:4)
Block(-30,25,-4,106:1)
Block(-30,25,-3,18:3)
Block(-30,25,-2,18:3)
Block(-30,25,-1,18:3)
Block(-30,25,0,17:3)
Block(-30,25,1,18:3)
Block(-30,25,3,18:3)
Block(-30,25,4,106:4)
Block(-30,25,5,18:3)
Block(-30,25,6,106:4)
Block(-30,26,-3,18:3)
Block(-30,26,-1,18:3)
Block(-30,26,0,17:3)
Block(-30,26,1,17:11)
Block(-30,26,2,17:11)
Block(-30,26,3,18:3)
Block(-30,26,4,18:3)
Block(-30,26,5,18:3)
Block(-30,26,6,106:4)
Block(-30,27,-3,18:3)
Block(-30,27,-2,17:11)
Block(-30,27,-1,17:11)
Block(-30,27,0,17:3)
Block(-30,27,1,18:3)
Block(-30,27,2,18:3)
Block(-30,27,3,18:3)
Block(-30,27,4,18:3)
Block(-30,28,-5,18:3)
Block(-30,28,-4,18:3)
Block(-30,28,-3,18:3)
Block(-30,28,0,17:3)
Block(-30,28,1,18:3)
Block(-30,28,2,18:3)
Block(-30,28,3,18:3)
Block(-30,29,-5,18:3)
Block(-30,29,-3,18:3)
Block(-30,29,-2,18:3)
Block(-30,29,-1,18:3)
Block(-30,29,0,18:3)
Block(-30,29,1,18:3)
Block(-30,29,2,18:3)
Block(-30,29,3,18:3)
Block(-30,29,5,18:3)
Block(-30,30,-6,18:3)
Block(-30,30,-5,18:3)
Block(-30,30,-2,18:3)
Block(-30,30,-1,18:3)
Block(-30,30,0,18:3)
Block(-30,30,1,18:3)
Block(-30,30,3,18:3)
Block(-30,30,4,18:3)
Block(-30,30,5,18:3)
Block(-30,31,-5,18:3)
Block(-30,31,-1,18:3)
Block(-30,31,0,18:3)
Block(-30,31,1,18:3)
Block(-30,31,2,18:3)
Block(-30,32,-4,18:3)
Block(-30,32,-2,18:3)
Block(-30,32,1,18:3)
Block(-30,32,2,18:3)
Block(-29,17,5,106:2)
Block(-29,18,5,106:2)
Block(-29,19,0,18:3)
Block(-29,19,1,18:3)
Block(-29,19,5,106:2)
Block(-29,20,0,18:3)
Block(-29,20,1,18:3)
Block(-29,20,5,106:2)
Block(-29,21,0,18:3)
Block(-29,21,5,106:2)
Block(-29,22,5,106:2)
Block(-29,23,-2,18:3)
Block(-29,23,-1,18:3)
Block(-29,23,0,18:3)
Block(-29,23,1,18:3)
Block(-29,23,3,18:3)
Block(-29,23,5,106:2)
Block(-29,24,-2,18:3)
Block(-29,24,2,18:3)
Block(-29,24,5,106:2)
Block(-29,25,-3,18:3)
Block(-29,25,-2,18:3)
Block(-29,25,-1,18:3)
Block(-29,25,0,18:3)
Block(-29,25,1,18:3)
Block(-29,25,2,18:3)
Block(-29,25,3,106:4)
Block(-29,25,5,106:2)
Block(-29,26,-2,18:3)
Block(-29,26,-1,18:3)
Block(-29,26,0,18:3)
Block(-29,26,1,18:3)
Block(-29,26,2,18:3)
Block(-29,26,4,18:3)
Block(-29,27,-5,18:3)
Block(-29,27,-4,18:3)
Block(-29,27,-3,18:3)
Block(-29,27,-2,18:3)
Block(-29,27,-1,18:3)
Block(-29,27,0,17:3)
Block(-29,27,1,18:3)
Block(-29,27,3,18:3)
Block(-29,27,4,18:3)
Block(-29,27,5,18:3)
Block(-29,28,-3,18:3)
Block(-29,28,-2,18:3)
Block(-29,28,0,17:3)
Block(-29,28,1,18:3)
Block(-29,28,2,18:3)
Block(-29,28,3,18:3)
Block(-29,29,-3,18:3)
Block(-29,29,-2,18:3)
Block(-29,29,0,17:3)
Block(-29,29,1,18:3)
Block(-29,29,2,18:3)
Block(-29,29,3,18:3)
Block(-29,30,-4,18:3)
Block(-29,30,-2,18:3)
Block(-29,30,0,17:3)
Block(-29,30,1,18:3)
Block(-29,30,3,18:3)
Block(-29,30,5,18:3)
Block(-29,30,6,18:3)
Block(-29,31,-3,18:3)
Block(-29,31,-1,18:3)
Block(-29,31,0,18:3)
Block(-29,31,2,18:3)
Block(-29,31,3,18:3)
Block(-29,32,1,18:3)
Block(-29,32,2,18:3)
Block(-29,32,3,18:3)
Block(-29,32,4,18:3)
Block(-29,33,-4,18:3)
Block(-29,33,-2,18:3)
Block(-29,33,3,18:3)
Block(-28,19,-3,106:2)
Block(-28,20,-3,106:2)
Block(-28,21,-3,106:2)
Block(-28,22,-3,106:2)
Block(-28,23,-3,106:2)
Block(-28,24,-3,106:2)
Block(-28,24,0,18:3)
Block(-28,24,1,18:3)
Block(-28,24,2,18:3)
Block(-28,24,3,18:3)
Block(-28,25,-3,106:2)
Block(-28,25,-2,18:3)
Block(-28,25,-1,18:3)
Block(-28,25,0,18:3)
Block(-28,25,1,106:2)
Block(-28,26,-3,18:3)
Block(-28,26,-2,18:3)
Block(-28,26,0,18:3)
Block(-28,26,1,18:3)
Block(-28,26,2,18:3)
Block(-28,26,4,18:3)
Block(-28,27,-2,18:3)
Block(-28,27,-1,18:3)
Block(-28,27,0,18:3)
Block(-28,27,2,18:3)
Block(-28,27,3,18:3)
Block(-28,27,4,18:3)
Block(-28,28,-5,18:3)
Block(-28,28,-3,18:3)
Block(-28,28,-2,18:3)
Block(-28,28,-1,18:3)
Block(-28,28,0,18:3)
Block(-28,28,1,18:3)
Block(-28,28,3,18:3)
Block(-28,28,4,18:3)
Block(-28,28,5,18:3)
Block(-28,29,-6,18:3)
Block(-28,29,-5,18:3)
Block(-28,29,-3,18:3)
Block(-28,29,-2,18:3)
Block(-28,29,-1,18:3)
Block(-28,29,0,18:3)
Block(-28,29,1,18:3)
Block(-28,29,2,18:3)
Block(-28,29,5,18:3)
Block(-28,29,6,18:3)
Block(-28,30,-5,18:3)
Block(-28,30,-4,18:3)
Block(-28,30,-3,17:11)
Block(-28,30,-2,17:11)
Block(-28,30,-1,17:11)
Block(-28,30,0,17:3)
Block(-28,30,1,17:11)
Block(-28,30,2,17:11)
Block(-28,30,3,17:11)
Block(-28,30,4,18:3)
Block(-28,30,5,18:3)
Block(-28,31,-4,18:3)
Block(-28,31,-3,18:3)
Block(-28,31,0,17:3)
Block(-28,31,1,18:3)
Block(-28,31,2,18:3)
Block(-28,31,3,18:3)
Block(-28,31,4,18:3)
Block(-28,32,-4,18:3)
Block(-28,32,-3,18:3)
Block(-28,32,0,18:3)
Block(-28,32,1,18:3)
Block(-28,32,2,18:3)
Block(-28,32,3,18:3)
Block(-28,32,4,18:3)
Block(-28,32,5,18:3)
Block(-28,33,-4,18:3)
Block(-28,33,-3,18:3)
Block(-28,33,-1,18:3)
Block(-28,33,0,18:3)
Block(-28,33,1,18:3)
Block(-28,33,2,18:3)
Block(-28,33,3,18:3)
Block(-28,33,4,18:3)
Block(-28,33,5,18:3)
Block(-28,34,-5,18:3)
Block(-28,34,0,18:3)
Block(-28,34,1,18:3)
Block(-28,34,4,18:3)
Block(-28,35,-1,18:3)
Block(-27,20,-1,106:2)
Block(-27,21,-1,106:2)
Block(-27,21,0,106:2)
Block(-27,22,-1,106:2)
Block(-27,22,0,106:2)
Block(-27,23,-1,106:2)
Block(-27,23,0,106:2)
Block(-27,24,-1,106:2)
Block(-27,24,0,106:2)
Block(-27,25,-1,106:2)
Block(-27,25,0,106:2)
Block(-27,26,-2,18:3)
Block(-27,26,-1,18:3)
Block(-27,26,0,106:2)
Block(-27,26,2,18:3)
Block(-27,27,-4,18:3)
Block(-27,27,-3,18:3)
Block(-27,27,-1,18:3)
Block(-27,27,0,106:2)
Block(-27,27,1,18:3)
Block(-27,27,4,18:3)
Block(-27,28,-5,18:3)
Block(-27,28,-3,18:3)
Block(-27,28,-1,18:3)
Block(-27,28,0,18:3)
Block(-27,28,2,18:3)
Block(-27,28,3,18:3)
Block(-27,28,4,18:3)
Block(-27,29,-2,18:3)
Block(-27,29,-1,18:3)
Block(-27,29,0,18:3)
Block(-27,29,1,18:3)
Block(-27,29,2,18:3)
Block(-27,29,3,18:3)
Block(-27,30,-5,18:3)
Block(-27,30,-4,18:3)
Block(-27,30,-3,18:3)
Block(-27,30,-2,18:3)
Block(-27,30,-1,18:3)
Block(-27,30,0,18:3)
Block(-27,30,2,18:3)
Block(-27,30,3,18:3)
Block(-27,30,5,18:3)
Block(-27,30,6,18:3)
Block(-27,31,-5,18:3)
Block(-27,31,-3,18:3)
Block(-27,31,-2,18:3)
Block(-27,31,-1,18:3)
Block(-27,31,0,17:7)
Block(-27,31,1,18:3)
Block(-27,31,2,18:3)
Block(-27,31,3,18:3)
Block(-27,31,4,18:3)
Block(-27,31,5,18:3)
Block(-27,32,-4,18:3)
Block(-27,32,-3,18:3)
Block(-27,32,-1,18:3)
Block(-27,32,0,17:7)
Block(-27,32,1,18:3)
Block(-27,32,3,18:3)
Block(-27,32,4,18:3)
Block(-27,32,5,18:3)
Block(-27,33,-5,18:3)
Block(-27,33,-3,18:3)
Block(-27,33,-2,18:3)
Block(-27,33,-1,18:3)
Block(-27,33,0,18:3)
Block(-27,33,2,18:3)
Block(-27,33,3,18:3)
Block(-27,33,4,18:3)
Block(-27,33,6,18:3)
Block(-27,34,-2,18:3)
Block(-27,34,-1,18:3)
Block(-27,34,0,18:3)
Block(-27,34,1,18:3)
Block(-27,35,0,18:3)
Block(-27,35,2,18:3)
Block(-27,35,5,18:3)
Block(-27,35,6,18:3)
Block(-27,36,0,18:3)
Block(-27,36,2,18:3)
Block(-26,28,-3,18:3)
Block(-26,28,-1,18:3)
Block(-26,28,2,18:3)
Block(-26,29,-4,18:3)
Block(-26,29,-3,18:3)
Block(-26,29,-2,18:3)
Block(-26,29,1,18:3)
Block(-26,29,2,18:3)
Block(-26,29,5,18:3)
Block(-26,30,-5,18:3)
Block(-26,30,-4,18:3)
Block(-26,30,-3,18:3)
Block(-26,30,-2,18:3)
Block(-26,30,0,18:3)
Block(-26,30,1,18:3)
Block(-26,30,2,18:3)
Block(-26,30,3,18:3)
Block(-26,30,4,18:3)
Block(-26,31,-5,18:3)
Block(-26,31,-3,18:3)
Block(-26,31,-2,18:3)
Block(-26,31,-1,18:3)
Block(-26,31,0,18:3)
Block(-26,31,1,18:3)
Block(-26,31,2,18:3)
Block(-26,31,4,18:3)
Block(-26,31,5,18:3)
Block(-26,32,-5,18:3)
Block(-26,32,-4,18:3)
Block(-26,32,-3,18:3)
Block(-26,32,-2,18:3)
Block(-26,32,0,17:7)
Block(-26,32,1,18:3)
Block(-26,32,2,18:3)
Block(-26,32,3,18:3)
Block(-26,32,4,18:3)
Block(-26,32,5,18:3)
Block(-26,33,-6,18:3)
Block(-26,33,-5,18:3)
Block(-26,33,-4,18:3)
Block(-26,33,-1,18:3)
Block(-26,33,0,17:7)
Block(-26,33,2,18:3)
Block(-26,33,3,18:3)
Block(-26,33,4,18:3)
Block(-26,33,5,18:3)
Block(-26,33,6,18:3)
Block(-26,34,-5,18:3)
Block(-26,34,-1,18:3)
Block(-26,34,0,18:3)
Block(-26,34,1,18:3)
Block(-26,34,2,18:3)
Block(-26,34,4,18:3)
Block(-26,34,7,18:3)
Block(-26,35,-4,18:3)
Block(-26,35,-3,18:3)
Block(-26,35,2,18:3)
Block(-26,35,3,18:3)
Block(-26,35,6,18:3)
Block(-26,36,-2,18:3)
Block(-26,36,0,18:3)
Block(-26,36,1,18:3)
Block(-26,37,-1,18:3)
Block(-25,29,3,18:3)
Block(-25,29,4,18:3)
Block(-25,30,-5,18:3)
Block(-25,30,-4,18:3)
Block(-25,30,-3,18:3)
Block(-25,30,2,18:3)
Block(-25,30,3,18:3)
Block(-25,31,-4,18:3)
Block(-25,31,-3,18:3)
Block(-25,31,-1,18:3)
Block(-25,31,0,18:3)
Block(-25,31,1,18:3)
Block(-25,31,3,18:3)
Block(-25,31,4,18:3)
Block(-25,31,5,18:3)
Block(-25,31,6,18:3)
Block(-25,32,-7,18:3)
Block(-25,32,-4,18:3)
Block(-25,32,-2,18:3)
Block(-25,32,-1,18:3)
Block(-25,32,0,18:3)
Block(-25,32,1,18:3)
Block(-25,32,2,18:3)
Block(-25,32,4,18:3)
Block(-25,32,7,18:3)
Block(-25,33,-7,18:3)
Block(-25,33,-6,18:3)
Block(-25,33,-5,18:3)
Block(-25,33,-4,17:11)
Block(-25,33,-3,17:11)
Block(-25,33,-2,17:11)
Block(-25,33,-1,17:11)
Block(-25,33,0,17:7)
Block(-25,33,1,17:11)
Block(-25,33,2,17:11)
Block(-25,33,3,17:11)
Block(-25,33,4,17:11)
Block(-25,33,5,18:3)
Block(-25,33,6,18:3)
Block(-25,34,-7,18:3)
Block(-25,34,-6,18:3)
Block(-25,34,-5,18:3)
Block(-25,34,-3,18:3)
Block(-25,34,-2,18:3)
Block(-25,34,-1,18:3)
Block(-25,34,0,17:7)
Block(-25,34,1,18:3)
Block(-25,34,2,18:3)
Block(-25,34,3,18:3)
Block(-25,34,5,18:3)
Block(-25,34,7,18:3)
Block(-25,35,-5,18:3)
Block(-25,35,-4,18:3)
Block(-25,35,-3,18:3)
Block(-25,35,-2,18:3)
Block(-25,35,-1,18:3)
Block(-25,35,0,18:3)
Block(-25,35,1,18:3)
Block(-25,35,2,18:3)
Block(-25,35,3,18:3)
Block(-25,35,6,18:3)
Block(-25,36,-5,18:3)
Block(-25,36,-4,18:3)
Block(-25,36,-2,18:3)
Block(-25,36,-1,18:3)
Block(-25,36,0,18:3)
Block(-25,36,1,18:3)
Block(-25,36,3,18:3)
Block(-25,36,4,18:3)
Block(-25,36,5,18:3)
Block(-25,37,-1,18:3)
Block(-25,37,1,18:3)
Block(-24,19,19,106:8)
Block(-24,20,19,106:8)
Block(-24,21,19,106:8)
Block(-24,22,19,106:8)
Block(-24,23,19,106:8)
Block(-24,24,19,106:8)
Block(-24,25,19,106:8)
Block(-24,26,19,106:8)
Block(-24,27,-18,18:3)
Block(-24,27,19,106:8)
Block(-24,28,-19,18:3)
Block(-24,28,-18,18:3)
Block(-24,29,-17,18:3)
Block(-24,29,-16,18:3)
Block(-24,29,-15,18:3)
Block(-24,30,-16,18:3)
Block(-24,30,-4,18:3)
Block(-24,30,16,18:3)
Block(-24,31,-17,18:3)
Block(-24,31,-4,18:3)
Block(-24,31,-3,18:3)
Block(-24,31,-1,18:3)
Block(-24,31,0,18:3)
Block(-24,31,5,18:3)
Block(-24,32,-6,18:3)
Block(-24,32,0,18:3)
Block(-24,32,1,18:3)
Block(-24,32,2,18:3)
Block(-24,32,3,18:3)
Block(-24,32,5,18:3)
Block(-24,33,-7,18:3)
Block(-24,33,-6,18:3)
Block(-24,33,-3,18:3)
Block(-24,33,-2,18:3)
Block(-24,33,-1,18:3)
Block(-24,33,0,17:7)
Block(-24,33,1,18:3)
Block(-24,33,2,18:3)
Block(-24,33,3,18:3)
Block(-24,33,4,18:3)
Block(-24,33,5,18:3)
Block(-24,33,7,18:3)
Block(-24,34,-4,18:3)
Block(-24,34,-3,18:3)
Block(-24,34,-2,18:3)
Block(-24,34,0,17:7)
Block(-24,34,1,18:3)
Block(-24,34,2,18:3)
Block(-24,34,3,18:3)
Block(-24,34,6,18:3)
Block(-24,34,7,18:3)
Block(-24,35,-6,18:3)
Block(-24,35,-5,18:3)
Block(-24,35,-4,18:3)
Block(-24,35,-3,18:3)
Block(-24,35,-2,18:3)
Block(-24,35,0,18:3)
Block(-24,35,1,18:3)
Block(-24,35,2,18:3)
Block(-24,35,3,18:3)
Block(-24,35,4,18:3)
Block(-24,35,5,18:3)
Block(-24,35,6,18:3)
Block(-24,36,-5,18:3)
Block(-24,36,0,18:3)
Block(-24,36,1,18:3)
Block(-24,37,-1,18:3)
Block(-24,37,0,18:3)
Block(-24,37,1,18:3)
Block(-23,20,-20,18:3)
Block(-23,21,-20,106:1)
Block(-23,21,-17,106:8)
Block(-23,21,20,18:3)
Block(-23,22,-20,106:1)
Block(-23,22,-18,106:4)
Block(-23,22,-17,106:8)
Block(-23,23,-20,106:1)
Block(-23,23,-18,106:4)
Block(-23,23,-17,106:8)
Block(-23,23,18,106:1)
Block(-23,23,20,18:3)
Block(-23,24,-20,106:1)
Block(-23,24,-19,18:3)
Block(-23,24,-18,106:4)
Block(-23,24,-17,106:8)
Block(-23,24,-16,106:4)
Block(-23,24,18,106:1)
Block(-23,24,19,18:3)
Block(-23,24,20,18:3)
Block(-23,24,21,18:3)
Block(-23,25,-20,106:1)
Block(-23,25,-19,18:3)
Block(-23,25,-18,106:4)
Block(-23,25,-17,106:8)
Block(-23,25,-16,106:4)
Block(-23,25,18,106:1)
Block(-23,25,19,18:3)
Block(-23,26,-20,106:1)
Block(-23,26,-19,18:3)
Block(-23,26,-18,18:3)
Block(-23,26,-17,18:3)
Block(-23,26,-16,106:4)
Block(-23,26,18,106:1)
Block(-23,27,-20,18:3)
Block(-23,27,-18,18:3)
Block(-23,27,-16,18:3)
Block(-23,27,18,106:1)
Block(-23,27,19,18:3)
Block(-23,27,20,18:3)
Block(-23,28,-16,18:3)
Block(-23,28,20,18:3)
Block(-23,28,21,18:3)
Block(-23,29,-20,18:3)
Block(-23,29,-17,18:3)
Block(-23,29,-16,18:3)
Block(-23,29,-15,18:3)
Block(-23,29,15,18:3)
Block(-23,29,16,18:3)
Block(-23,29,17,18:3)
Block(-23,29,18,18:3)
Block(-23,30,-18,18:3)
Block(-23,30,-16,18:3)
Block(-23,30,14,18:3)
Block(-23,30,16,18:3)
Block(-23,31,-17,18:3)
Block(-23,31,-16,18:3)
Block(-23,31,-15,18:3)
Block(-23,31,-6,18:3)
Block(-23,31,-4,18:3)
Block(-23,31,4,18:3)
Block(-23,31,5,18:3)
Block(-23,31,16,18:3)
Block(-23,31,18,18:3)
Block(-23,32,-15,18:3)
Block(-23,32,-14,18:3)
Block(-23,32,-6,18:3)
Block(-23,32,-3,18:3)
Block(-23,32,-2,18:3)
Block(-23,32,0,18:3)
Block(-23,32,2,18:3)
Block(-23,32,16,18:3)
Block(-23,33,-13,18:3)
Block(-23,33,-5,18:3)
Block(-23,33,-4,18:3)
Block(-23,33,-2,18:3)
Block(-23,33,0,18:3)
Block(-23,33,2,18:3)
Block(-23,33,3,18:3)
Block(-23,33,4,18:3)
Block(-23,33,5,18:3)
Block(-23,33,6,18:3)
Block(-23,34,-14,18:3)
Block(-23,34,-13,18:3)
Block(-23,34,-6,18:3)
Block(-23,34,-5,18:3)
Block(-23,34,-4,18:3)
Block(-23,34,-1,18:3)
Block(-23,34,0,17:7)
Block(-23,34,1,18:3)
Block(-23,34,2,18:3)
Block(-23,34,4,18:3)
Block(-23,34,5,18:3)
Block(-23,35,-7,18:3)
Block(-23,35,-6,18:3)
Block(-23,35,-5,18:3)
Block(-23,35,-4,18:3)
Block(-23,35,-3,18:3)
Block(-23,35,-2,18:3)
Block(-23,35,-1,18:3)
Block(-23,35,0,17:7)
Block(-23,35,1,18:3)
Block(-23,35,2,18:3)
Block(-23,35,3,18:3)
Block(-23,35,4,18:3)
Block(-23,35,5,18:3)
Block(-23,35,6,18:3)
Block(-23,35,7,18:3)
Block(-23,36,-6,18:3)
Block(-23,36,-5,18:3)
Block(-23,36,-4,18:3)
Block(-23,36,-3,18:3)
Block(-23,36,-2,18:3)
Block(-23,36,-1,18:3)
Block(-23,36,0,18:3)
Block(-23,36,1,18:3)
Block(-23,36,4,18:3)
Block(-23,37,-6,18:3)
Block(-23,37,-2,18:3)
Block(-23,37,-1,18:3)
Block(-22,19,-20,18:3)
Block(-22,19,21,18:3)
Block(-22,19,22,106:8)
Block(-22,20,-21,18:3)
Block(-22,20,-20,18:3)
Block(-22,20,-19,18:3)
Block(-22,20,20,18:3)
Block(-22,20,22,106:8)
Block(-22,21,-21,18:3)
Block(-22,21,-20,18:3)
Block(-22,21,20,18:3)
Block(-22,21,22,106:8)
Block(-22,22,-20,18:3)
Block(-22,22,-16,106:4)
Block(-22,22,17,106:1)
Block(-22,22,20,18:3)
Block(-22,22,21,18:3)
Block(-22,22,22,106:8)
Block(-22,23,-19,18:3)
Block(-22,23,-16,106:4)
Block(-22,23,17,106:1)
Block(-22,23,21,18:3)
Block(-22,23,22,106:8)
Block(-22,24,-19,18:3)
Block(-22,24,-18,18:3)
Block(-22,24,-16,106:4)
Block(-22,24,17,106:1)
Block(-22,24,19,18:3)
Block(-22,24,20,18:3)
Block(-22,24,22,106:8)
Block(-22,25,-19,18:3)
Block(-22,25,-18,106:8)
Block(-22,25,-17,18:3)
Block(-22,25,-16,106:4)
Block(-22,25,17,106:1)
Block(-22,25,18,18:3)
Block(-22,25,19,18:3)
Block(-22,25,20,18:3)
Block(-22,25,22,106:8)
Block(-22,26,-17,18:3)
Block(-22,26,-16,106:4)
Block(-22,26,19,18:3)
Block(-22,26,22,18:3)
Block(-22,27,-20,18:3)
Block(-22,27,-18,18:3)
Block(-22,27,-17,18:3)
Block(-22,27,-16,18:3)
Block(-22,27,-15,18:3)
Block(-22,27,20,18:3)
Block(-22,28,-18,18:3)
Block(-22,28,-16,18:3)
Block(-22,28,-15,18:3)
Block(-22,28,18,18:3)
Block(-22,28,20,18:3)
Block(-22,29,-20,18:3)
Block(-22,29,-19,18:3)
Block(-22,29,-18,18:3)
Block(-22,29,-16,18:3)
Block(-22,29,-14,18:3)
Block(-22,29,14,18:3)
Block(-22,29,16,18:3)
Block(-22,29,18,18:3)
Block(-22,29,20,18:3)
Block(-22,30,-20,18:3)
Block(-22,30,-19,18:3)
Block(-22,30,-17,18:3)
Block(-22,30,-14,18:3)
Block(-22,30,-13,18:3)
Block(-22,30,13,18:3)
Block(-22,30,14,18:3)
Block(-22,30,16,18:3)
Block(-22,30,18,18:3)
Block(-22,30,19,18:3)
Block(-22,30,20,18:3)
Block(-22,31,-19,18:3)
Block(-22,31,-17,18:3)
Block(-22,31,-15,18:3)
Block(-22,31,-14,18:3)
Block(-22,31,-13,18:3)
Block(-22,31,14,18:3)
Block(-22,31,15,18:3)
Block(-22,31,16,18:3)
Block(-22,31,17,18:3)
Block(-22,32,-16,18:3)
Block(-22,32,-14,18:3)
Block(-22,32,-13,18:3)
Block(-22,32,-6,18:3)
Block(-22,32,-5,18:3)
Block(-22,32,4,18:3)
Block(-22,32,5,18:3)
Block(-22,32,15,18:3)
Block(-22,32,17,18:3)
Block(-22,32,18,18:3)
Block(-22,33,-17,18:3)
Block(-22,33,-15,18:3)
Block(-22,33,-13,18:3)
Block(-22,33,-7,18:3)
Block(-22,33,-5,18:3)
Block(-22,33,-4,18:3)
Block(-22,33,-3,18:3)
Block(-22,33,0,18:3)
Block(-22,33,1,18:3)
Block(-22,33,3,18:3)
Block(-22,33,4,18:3)
Block(-22,33,5,18:3)
Block(-22,33,11,18:3)
Block(-22,33,15,18:3)
Block(-22,33,16,18:3)
Block(-22,34,-14,18:3)
Block(-22,34,-13,18:3)
Block(-22,34,-8,18:3)
Block(-22,34,-5,18:3)
Block(-22,34,-3,18:3)
Block(-22,34,-2,18:3)
Block(-22,34,-1,18:3)
Block(-22,34,0,17:7)
Block(-22,34,2,18:3)
Block(-22,34,4,18:3)
Block(-22,34,5,18:3)
Block(-22,34,8,18:3)
Block(-22,35,-14,18:3)
Block(-22,35,-11,18:3)
Block(-22,35,-8,18:3)
Block(-22,35,-7,18:3)
Block(-22,35,-5,18:3)
Block(-22,35,-4,18:3)
Block(-22,35,-3,18:3)
Block(-22,35,-2,18:3)
Block(-22,35,-1,18:3)
Block(-22,35,0,17:7)
Block(-22,35,4,18:3)
Block(-22,35,5,18:3)
Block(-22,35,6,18:3)
Block(-22,35,13,18:3)
Block(-22,36,-6,18:3)
Block(-22,36,-3,18:3)
Block(-22,36,-2,18:3)
Block(-22,36,0,18:3)
Block(-22,36,1,18:3)
Block(-22,36,2,18:3)
Block(-22,36,3,18:3)
Block(-22,37,-7,18:3)
Block(-22,37,-2,18:3)
Block(-22,37,1,18:3)
Block(-22,37,2,18:3)
Block(-22,37,3,18:3)
Block(-22,37,4,18:3)
Block(-22,37,5,18:3)
Block(-22,38,-4,18:3)
Block(-22,38,-2,18:3)
Block(-22,38,0,18:3)
Block(-22,38,5,18:3)
Block(-21,0,-1,17:3)
Block(-21,18,-21,18:3)
Block(-21,19,-20,18:3)
Block(-21,19,20,18:3)
Block(-21,19,21,18:3)
Block(-21,19,22,18:3)
Block(-21,20,-20,18:3)
Block(-21,20,-19,18:3)
Block(-21,20,-18,18:3)
Block(-21,20,18,18:3)
Block(-21,20,21,18:3)
Block(-21,20,22,18:3)
Block(-21,20,23,18:3)
Block(-21,21,-22,18:3)
Block(-21,21,-20,18:3)
Block(-21,21,19,18:3)
Block(-21,21,20,18:3)
Block(-21,22,-21,18:3)
Block(-21,22,-20,18:3)
Block(-21,22,-19,18:3)
Block(-21,22,19,18:3)
Block(-21,22,20,18:3)
Block(-21,22,21,18:3)
Block(-21,22,22,18:3)
Block(-21,22,23,18:3)
Block(-21,23,-21,18:3)
Block(-21,23,-20,18:3)
Block(-21,23,-18,18:3)
Block(-21,23,20,18:3)
Block(-21,23,21,106:4)
Block(-21,23,22,18:3)
Block(-21,24,-21,106:1)
Block(-21,24,-20,18:3)
Block(-21,24,-19,18:3)
Block(-21,24,-18,18:3)
Block(-21,24,-17,18:3)
Block(-21,24,18,18:3)
Block(-21,24,19,18:3)
Block(-21,24,20,18:3)
Block(-21,24,21,106:4)
Block(-21,24,22,18:3)
Block(-21,24,23,18:3)
Block(-21,25,-20,18:3)
Block(-21,25,-19,18:3)
Block(-21,25,-18,18:3)
Block(-21,25,-17,18:3)
Block(-21,25,20,18:3)
Block(-21,25,21,106:4)
Block(-21,25,22,18:3)
Block(-21,25,23,106:4)
Block(-21,26,-22,18:3)
Block(-21,26,-21,18:3)
Block(-21,26,-20,18:3)
Block(-21,26,-19,18:3)
Block(-21,26,-18,18:3)
Block(-21,26,-15,18:3)
Block(-21,26,17,18:3)
Block(-21,26,18,18:3)
Block(-21,26,19,18:3)
Block(-21,26,20,18:3)
Block(-21,26,21,18:3)
Block(-21,26,22,18:3)
Block(-21,26,23,18:3)
Block(-21,27,-21,18:3)
Block(-21,27,-20,18:3)
Block(-21,27,-18,17:11)
Block(-21,27,-17,18:3)
Block(-21,27,-16,18:3)
Block(-21,27,-15,18:3)
Block(-21,27,16,18:3)
Block(-21,27,17,18:3)
Block(-21,27,18,17:11)
Block(-21,27,19,18:3)
Block(-21,27,20,18:3)
Block(-21,27,21,18:3)
Block(-21,27,22,18:3)
Block(-21,27,23,18:3)
Block(-21,28,-21,18:3)
Block(-21,28,-19,18:3)
Block(-21,28,-18,18:3)
Block(-21,28,-17,18:3)
Block(-21,28,-16,18:3)
Block(-21,28,-15,18:3)
Block(-21,28,-14,18:3)
Block(-21,28,14,18:3)
Block(-21,28,15,18:3)
Block(-21,28,18,18:3)
Block(-21,28,19,18:3)
Block(-21,28,20,18:3)
Block(-21,28,21,18:3)
Block(-21,29,-19,18:3)
Block(-21,29,-18,18:3)
Block(-21,29,-17,18:3)
Block(-21,29,-16,18:3)
Block(-21,29,-13,18:3)
Block(-21,29,15,18:3)
Block(-21,29,16,18:3)
Block(-21,29,18,18:3)
Block(-21,29,19,18:3)
Block(-21,29,20,18:3)
Block(-21,30,-21,18:3)
Block(-21,30,-20,18:3)
Block(-21,30,-19,18:3)
Block(-21,30,-17,18:3)
Block(-21,30,-16,17:11)
Block(-21,30,-13,18:3)
Block(-21,30,13,18:3)
Block(-21,30,14,18:3)
Block(-21,30,15,18:3)
Block(-21,30,16,17:11)
Block(-21,30,17,18:3)
Block(-21,30,18,18:3)
Block(-21,30,19,18:3)
Block(-21,30,20,18:3)
Block(-21,30,21,18:3)
Block(-21,31,-21,18:3)
Block(-21,31,-17,18:3)
Block(-21,31,-15,18:3)
Block(-21,31,-14,18:3)
Block(-21,31,-13,18:3)
Block(-21,31,12,18:3)
Block(-21,31,13,18:3)
Block(-21,31,14,18:3)
Block(-21,31,15,18:3)
Block(-21,31,16,18:3)
Block(-21,31,17,18:3)
Block(-21,31,18,18:3)
Block(-21,31,19,18:3)
Block(-21,31,21,18:3)
Block(-21,32,-19,18:3)
Block(-21,32,-18,18:3)
Block(-21,32,-17,18:3)
Block(-21,32,-16,18:3)
Block(-21,32,-14,18:3)
Block(-21,32,-6,18:3)
Block(-21,32,-4,18:3)
Block(-21,32,4,18:3)
Block(-21,32,5,18:3)
Block(-21,32,6,18:3)
Block(-21,32,15,18:3)
Block(-21,32,16,18:3)
Block(-21,32,17,18:3)
Block(-21,32,18,18:3)
Block(-21,32,19,18:3)
Block(-21,33,-16,18:3)
Block(-21,33,-15,18:3)
Block(-21,33,-14,18:3)
Block(-21,33,-13,18:3)
Block(-21,33,-12,18:3)
Block(-21,33,-6,18:3)
Block(-21,33,-5,18:3)
Block(-21,33,-4,18:3)
Block(-21,33,-3,18:3)
Block(-21,33,-1,18:3)
Block(-21,33,0,18:3)
Block(-21,33,3,18:3)
Block(-21,33,4,18:3)
Block(-21,33,5,18:3)
Block(-21,33,6,18:3)
Block(-21,33,10,18:3)
Block(-21,33,11,18:3)
Block(-21,33,12,18:3)
Block(-21,33,13,18:3)
Block(-21,33,15,18:3)
Block(-21,33,16,18:3)
Block(-21,33,17,18:3)
Block(-21,34,-15,18:3)
Block(-21,34,-13,18:3)
Block(-21,34,-11,18:3)
Block(-21,34,-8,18:3)
Block(-21,34,-7,18:3)
Block(-21,34,-6,18:3)
Block(-21,34,-5,18:3)
Block(-21,34,-4,18:3)
Block(-21,34,-3,18:3)
Block(-21,34,-2,18:3)
Block(-21,34,-1,18:3)
Block(-21,34,0,18:3)
Block(-21,34,1,18:3)
Block(-21,34,4,18:3)
Block(-21,34,5,18:3)
Block(-21,34,8,18:3)
Block(-21,35,-13,18:3)
Block(-21,35,-12,18:3)
Block(-21,35,-11,18:3)
Block(-21,35,-8,18:3)
Block(-21,35,-7,18:3)
Block(-21,35,-6,18:3)
Block(-21,35,-5,17:11)
Block(-21,35,-4,17:11)
Block(-21,35,-3,17:11)
Block(-21,35,-2,17:11)
Block(-21,35,-1,17:11)
Block(-21,35,0,17:7)
Block(-21,35,1,17:11)
Block(-21,35,2,17:11)
Block(-21,35,3,17:11)
Block(-21,35,4,17:11)
Block(-21,35,5,17:11)
Block(-21,35,6,18:3)
Block(-21,35,7,18:3)
Block(-21,35,8,18:3)
Block(-21,35,10,18:3)
Block(-21,35,12,18:3)
Block(-21,35,13,18:3)
Block(-21,36,-14,18:3)
Block(-21,36,-11,18:3)
Block(-21,36,-8,18:3)
Block(-21,36,-6,18:3)
Block(-21,36,-4,18:3)
Block(-21,36,-2,18:3)
Block(-21,36,-1,18:3)
Block(-21,36,0,17:7)
Block(-21,36,1,18:3)
Block(-21,36,3,18:3)
Block(-21,36,4,18:3)
Block(-21,36,5,18:3)
Block(-21,36,6,18:3)
Block(-21,36,7,18:3)
Block(-21,36,13,18:3)
Block(-21,37,-7,18:3)
Block(-21,37,-6,18:3)
Block(-21,37,-5,18:3)
Block(-21,37,-4,18:3)
Block(-21,37,-3,18:3)
Block(-21,37,-1,18:3)
Block(-21,37,0,18:3)
Block(-21,37,2,18:3)
Block(-21,37,3,18:3)
Block(-21,37,4,18:3)
Block(-21,37,5,18:3)
Block(-21,37,6,18:3)
Block(-21,37,7,18:3)
Block(-21,38,-5,18:3)
Block(-21,38,-4,18:3)
Block(-21,38,0,18:3)
Block(-21,38,4,18:3)
Block(-21,38,5,18:3)
Block(-21,38,6,18:3)
Block(-20,0,-2,17:3)
Block(-20,0,-1,17:3)
Block(-20,0,0,17:3)
Block(-20,0,3,17:3)
Block(-20,18,-21,18:3)
Block(-20,18,-20,18:3)
Block(-20,18,20,18:3)
Block(-20,18,21,18:3)
Block(-20,19,-21,18:3)
Block(-20,19,-19,18:3)
Block(-20,19,-18,18:3)
Block(-20,19,18,18:3)
Block(-20,19,19,18:3)
Block(-20,19,20,18:3)
Block(-20,19,21,18:3)
Block(-20,19,22,18:3)
Block(-20,20,-22,18:3)
Block(-20,20,-20,17:3)
Block(-20,20,-19,18:3)
Block(-20,20,-18,18:3)
Block(-20,20,-15,106:4)
Block(-20,20,18,18:3)
Block(-20,20,20,17:3)
Block(-20,20,21,18:3)
Block(-20,20,22,18:3)
Block(-20,21,-22,18:3)
Block(-20,21,-21,18:3)
Block(-20,21,-20,17:3)
Block(-20,21,-19,18:3)
Block(-20,21,-18,18:3)
Block(-20,21,-15,106:4)
Block(-20,21,18,18:3)
Block(-20,21,20,17:3)
Block(-20,21,22,18:3)
Block(-20,22,-22,18:3)
Block(-20,22,-21,18:3)
Block(-20,22,-20,17:3)
Block(-20,22,-18,18:3)
Block(-20,22,-15,106:4)
Block(-20,22,16,106:1)
Block(-20,22,18,18:3)
Block(-20,22,19,18:3)
Block(-20,22,20,17:3)
Block(-20,22,21,18:3)
Block(-20,22,22,18:3)
Block(-20,22,24,106:4)
Block(-20,23,-22,106:8)
Block(-20,23,-21,18:3)
Block(-20,23,-20,17:3)
Block(-20,23,-19,18:3)
Block(-20,23,-18,18:3)
Block(-20,23,-17,18:3)
Block(-20,23,-15,106:4)
Block(-20,23,16,106:1)
Block(-20,23,17,18:3)
Block(-20,23,20,17:3)
Block(-20,23,24,106:4)
Block(-20,24,-22,106:8)
Block(-20,24,-21,18:3)
Block(-20,24,-20,17:3)
Block(-20,24,-19,18:3)
Block(-20,24,-18,18:3)
Block(-20,24,-17,18:3)
Block(-20,24,-15,106:4)
Block(-20,24,16,106:1)
Block(-20,24,17,18:3)
Block(-20,24,18,18:3)
Block(-20,24,19,18:3)
Block(-20,24,20,17:3)
Block(-20,24,21,18:3)
Block(-20,24,22,18:3)
Block(-20,24,23,18:3)
Block(-20,24,24,106:4)
Block(-20,25,-21,106:1)
Block(-20,25,-20,17:3)
Block(-20,25,-19,18:3)
Block(-20,25,-17,18:3)
Block(-20,25,-16,18:3)
Block(-20,25,-15,106:4)
Block(-20,25,16,106:1)
Block(-20,25,17,18:3)
Block(-20,25,18,18:3)
Block(-20,25,19,18:3)
Block(-20,25,20,17:3)
Block(-20,25,21,18:3)
Block(-20,25,22,18:3)
Block(-20,25,23,18:3)
Block(-20,25,24,106:4)
Block(-20,26,-22,18:3)
Block(-20,26,-20,17:3)
Block(-20,26,-19,18:3)
Block(-20,26,-18,18:3)
Block(-20,26,-16,18:3)
Block(-20,26,-15,106:4)
Block(-20,26,15,18:3)
Block(-20,26,18,18:3)
Block(-20,26,20,17:3)
Block(-20,26,21,18:3)
Block(-20,26,22,18:3)
Block(-20,27,-21,18:3)
Block(-20,27,-20,17:3)
Block(-20,27,-19,17:11)
Block(-20,27,-18,18:3)
Block(-20,27,-17,18:3)
Block(-20,27,-16,18:3)
Block(-20,27,-15,18:3)
Block(-20,27,15,18:3)
Block(-20,27,16,18:3)
Block(-20,27,17,18:3)
Block(-20,27,18,18:3)
Block(-20,27,19,17:11)
Block(-20,27,20,17:3)
Block(-20,27,21,18:3)
Block(-20,27,22,18:3)
Block(-20,27,23,18:3)
Block(-20,28,-22,18:3)
Block(-20,28,-21,18:3)
Block(-20,28,-19,18:3)
Block(-20,28,-18,18:3)
Block(-20,28,-17,18:3)
Block(-20,28,-16,18:3)
Block(-20,28,16,18:3)
Block(-20,28,20,18:3)
Block(-20,28,21,18:3)
Block(-20,29,-21,18:3)
Block(-20,29,-18,18:3)
Block(-20,29,-15,18:3)
Block(-20,29,14,18:3)
Block(-20,29,15,18:3)
Block(-20,29,16,18:3)
Block(-20,29,18,18:3)
Block(-20,29,19,18:3)
Block(-20,29,20,18:3)
Block(-20,29,22,18:3)
Block(-20,30,-21,18:3)
Block(-20,30,-19,18:3)
Block(-20,30,-18,18:3)
Block(-20,30,-17,17:11)
Block(-20,30,-16,18:3)
Block(-20,30,-14,18:3)
Block(-20,30,-13,18:3)
Block(-20,30,-12,18:3)
Block(-20,30,12,18:3)
Block(-20,30,13,18:3)
Block(-20,30,14,18:3)
Block(-20,30,16,18:3)
Block(-20,30,17,17:11)
Block(-20,30,18,18:3)
Block(-20,30,19,18:3)
Block(-20,30,20,18:3)
Block(-20,31,-22,18:3)
Block(-20,31,-21,18:3)
Block(-20,31,-20,18:3)
Block(-20,31,-19,18:3)
Block(-20,31,-18,18:3)
Block(-20,31,-16,18:3)
Block(-20,31,-15,18:3)
Block(-20,31,-14,18:3)
Block(-20,31,-13,18:3)
Block(-20,31,11,18:3)
Block(-20,31,12,18:3)
Block(-20,31,13,18:3)
Block(-20,31,14,18:3)
Block(-20,31,15,18:3)
Block(-20,31,17,18:3)
Block(-20,31,18,18:3)
Block(-20,31,19,18:3)
Block(-20,31,21,18:3)
Block(-20,32,-21,18:3)
Block(-20,32,-20,18:3)
Block(-20,32,-19,18:3)
Block(-20,32,-18,18:3)
Block(-20,32,-17,18:3)
Block(-20,32,-16,18:3)
Block(-20,32,-15,18:3)
Block(-20,32,-14,18:3)
Block(-20,32,-13,18:3)
Block(-20,32,-12,18:3)
Block(-20,32,4,18:3)
Block(-20,32,5,18:3)
Block(-20,32,12,18:3)
Block(-20,32,15,18:3)
Block(-20,32,16,18:3)
Block(-20,32,18,18:3)
Block(-20,32,19,18:3)
Block(-20,32,20,18:3)
Block(-20,33,-20,18:3)
Block(-20,33,-18,18:3)
Block(-20,33,-16,18:3)
Block(-20,33,-15,18:3)
Block(-20,33,-13,17:11)
Block(-20,33,-11,18:3)
Block(-20,33,0,18:3)
Block(-20,33,1,18:3)
Block(-20,33,5,18:3)
Block(-20,33,11,18:3)
Block(-20,33,12,18:3)
Block(-20,33,13,17:11)
Block(-20,33,14,18:3)
Block(-20,33,15,18:3)
Block(-20,33,16,18:3)
Block(-20,33,18,18:3)
Block(-20,34,-17,18:3)
Block(-20,34,-15,18:3)
Block(-20,34,-13,18:3)
Block(-20,34,-12,18:3)
Block(-20,34,-11,18:3)
Block(-20,34,-10,18:3)
Block(-20,34,-7,18:3)
Block(-20,34,-5,18:3)
Block(-20,34,-3,18:3)
Block(-20,34,-2,18:3)
Block(-20,34,0,18:3)
Block(-20,34,2,18:3)
Block(-20,34,6,18:3)
Block(-20,34,10,18:3)
Block(-20,34,11,18:3)
Block(-20,34,12,18:3)
Block(-20,34,13,18:3)
Block(-20,34,14,18:3)
Block(-20,34,17,18:3)
Block(-20,35,-19,18:3)
Block(-20,35,-13,18:3)
Block(-20,35,-12,18:3)
Block(-20,35,-11,18:3)
Block(-20,35,-10,18:3)
Block(-20,35,-6,18:3)
Block(-20,35,-5,18:3)
Block(-20,35,-4,18:3)
Block(-20,35,-3,18:3)
Block(-20,35,-2,18:3)
Block(-20,35,-1,18:3)
Block(-20,35,0,17:7)
Block(-20,35,1,18:3)
Block(-20,35,2,18:3)
Block(-20,35,3,18:3)
Block(-20,35,4,18:3)
Block(-20,35,5,18:3)
Block(-20,35,6,18:3)
Block(-20,35,8,18:3)
Block(-20,35,11,18:3)
Block(-20,35,12,18:3)
Block(-20,35,13,18:3)
Block(-20,35,14,18:3)
Block(-20,35,15,18:3)
Block(-20,36,-15,18:3)
Block(-20,36,-14,18:3)
Block(-20,36,-13,18:3)
Block(-20,36,-12,18:3)
Block(-20,36,-10,18:3)
Block(-20,36,-8,18:3)
Block(-20,36,-4,18:3)
Block(-20,36,-3,18:3)
Block(-20,36,-2,18:3)
Block(-20,36,-1,18:3)
Block(-20,36,0,17:7)
Block(-20,36,1,18:3)
Block(-20,36,2,18:3)
Block(-20,36,4,18:3)
Block(-20,36,5,18:3)
Block(-20,36,6,18:3)
Block(-20,36,7,18:3)
Block(-20,36,8,18:3)
Block(-20,36,9,18:3)
Block(-20,36,14,18:3)
Block(-20,37,-13,18:3)
Block(-20,37,-10,18:3)
Block(-20,37,-5,18:3)
Block(-20,37,-4,18:3)
Block(-20,37,-3,18:3)
Block(-20,37,-2,18:3)
Block(-20,37,-1,18:3)
Block(-20,37,3,18:3)
Block(-20,37,5,18:3)
Block(-20,37,6,18:3)
Block(-20,37,7,18:3)
Block(-20,38,-6,18:3)
Block(-20,38,-5,18:3)
Block(-20,38,-4,18:3)
Block(-20,38,-2,18:3)
Block(-20,38,-1,18:3)
Block(-20,38,0,18:3)
Block(-20,38,5,18:3)
Block(-20,38,6,18:3)
Block(-20,39,-1,18:3)
Block(-20,39,0,18:3)
Block(-19,0,-1,17:3)
Block(-19,0,0,17:3)
Block(-19,0,1,17:3)
Block(-19,0,2,17:3)
Block(-19,0,3,17:3)
Block(-19,0,4,17:3)
Block(-19,18,-21,18:3)
Block(-19,18,-20,18:3)
Block(-19,18,19,18:3)
Block(-19,18,20,18:3)
Block(-19,19,-22,18:3)
Block(-19,19,-20,18:3)
Block(-19,19,-19,18:3)
Block(-19,20,-21,18:3)
Block(-19,20,-20,18:3)
Block(-19,20,-18,18:3)
Block(-19,20,-16,106:4)
Block(-19,20,19,18:3)
Block(-19,20,20,18:3)
Block(-19,20,21,18:3)
Block(-19,21,-21,18:3)
Block(-19,21,-20,18:3)
Block(-19,21,-18,18:3)
Block(-19,21,-16,106:4)
Block(-19,21,20,18:3)
Block(-19,21,21,18:3)
Block(-19,22,-21,18:3)
Block(-19,22,-16,106:4)
Block(-19,22,16,106:1)
Block(-19,22,20,18:3)
Block(-19,22,21,18:3)
Block(-19,23,-20,18:3)
Block(-19,23,-16,106:4)
Block(-19,23,16,106:1)
Block(-19,23,18,18:3)
Block(-19,23,20,18:3)
Block(-19,23,21,18:3)
Block(-19,23,22,18:3)
Block(-19,24,-23,18:3)
Block(-19,24,-22,18:3)
Block(-19,24,-21,18:3)
Block(-19,24,-20,18:3)
Block(-19,24,-19,17:3)
Block(-19,24,-16,106:4)
Block(-19,24,16,106:1)
Block(-19,24,17,18:3)
Block(-19,24,19,17:3)
Block(-19,24,20,18:3)
Block(-19,24,21,18:3)
Block(-19,24,22,18:3)
Block(-19,24,23,18:3)
Block(-19,25,-19,17:3)
Block(-19,25,-17,18:3)
Block(-19,25,-16,106:4)
Block(-19,25,16,106:1)
Block(-19,25,17,18:3)
Block(-19,25,19,17:3)
Block(-19,25,22,18:3)
Block(-19,25,23,106:4)
Block(-19,26,-21,18:3)
Block(-19,26,-20,18:3)
Block(-19,26,-19,17:3)
Block(-19,26,-18,18:3)
Block(-19,26,-16,18:3)
Block(-19,26,17,18:3)
Block(-19,26,18,18:3)
Block(-19,26,19,17:3)
Block(-19,26,23,106:4)
Block(-19,27,-21,18:3)
Block(-19,27,-20,17:7)
Block(-19,27,-19,17:3)
Block(-19,27,-18,18:3)
Block(-19,27,-17,18:3)
Block(-19,27,18,18:3)
Block(-19,27,19,17:3)
Block(-19,27,20,17:7)
Block(-19,27,22,18:3)
Block(-19,27,23,106:4)
Block(-19,28,-21,18:3)
Block(-19,28,-19,17:3)
Block(-19,28,-18,18:3)
Block(-19,28,-17,18:3)
Block(-19,28,-16,18:3)
Block(-19,28,-15,18:3)
Block(-19,28,16,18:3)
Block(-19,28,17,18:3)
Block(-19,28,19,17:3)
Block(-19,28,20,18:3)
Block(-19,28,21,18:3)
Block(-19,28,22,18:3)
Block(-19,28,23,106:4)
Block(-19,29,-22,18:3)
Block(-19,29,-21,18:3)
Block(-19,29,-20,18:3)
Block(-19,29,-19,17:3)
Block(-19,29,-18,18:3)
Block(-19,29,-17,18:3)
Block(-19,29,-16,18:3)
Block(-19,29,16,18:3)
Block(-19,29,17,18:3)
Block(-19,29,18,18:3)
Block(-19,29,19,17:3)
Block(-19,29,20,18:3)
Block(-19,29,21,18:3)
Block(-19,29,22,18:3)
Block(-19,29,23,106:4)
Block(-19,30,-22,18:3)
Block(-19,30,-21,18:3)
Block(-19,30,-20,18:3)
Block(-19,30,-19,17:3)
Block(-19,30,-18,17:11)
Block(-19,30,-16,18:3)
Block(-19,30,-15,18:3)
Block(-19,30,-14,18:3)
Block(-19,30,-13,18:3)
Block(-19,30,14,18:3)
Block(-19,30,15,18:3)
Block(-19,30,16,18:3)
Block(-19,30,17,18:3)
Block(-19,30,18,17:11)
Block(-19,30,19,17:3)
Block(-19,30,20,18:3)
Block(-19,30,21,18:3)
Block(-19,30,22,18:3)
Block(-19,31,-22,18:3)
Block(-19,31,-21,18:3)
Block(-19,31,-20,18:3)
Block(-19,31,-19,18:3)
Block(-19,31,-18,18:3)
Block(-19,31,-17,18:3)
Block(-19,31,-16,18:3)
Block(-19,31,-15,18:3)
Block(-19,31,-14,18:3)
Block(-19,31,15,18:3)
Block(-19,31,16,18:3)
Block(-19,31,17,18:3)
Block(-19,31,19,18:3)
Block(-19,31,21,18:3)
Block(-19,31,22,18:3)
Block(-19,32,-20,18:3)
Block(-19,32,-19,18:3)
Block(-19,32,-17,18:3)
Block(-19,32,-16,18:3)
Block(-19,32,-15,18:3)
Block(-19,32,-14,18:3)
Block(-19,32,-11,18:3)
Block(-19,32,11,18:3)
Block(-19,32,13,18:3)
Block(-19,32,16,18:3)
Block(-19,32,17,18:3)
Block(-19,32,18,18:3)
Block(-19,32,19,18:3)
Block(-19,32,21,18:3)
Block(-19,33,-20,18:3)
Block(-19,33,-18,18:3)
Block(-19,33,-17,18:3)
Block(-19,33,-16,18:3)
Block(-19,33,-14,17:11)
Block(-19,33,-13,18:3)
Block(-19,33,-12,18:3)
Block(-19,33,-11,18:3)
Block(-19,33,-10,18:3)
Block(-19,33,-5,18:3)
Block(-19,33,10,18:3)
Block(-19,33,11,18:3)
Block(-19,33,12,18:3)
Block(-19,33,13,18:3)
Block(-19,33,14,17:11)
Block(-19,33,16,18:3)
Block(-19,33,17,18:3)
Block(-19,33,18,18:3)
Block(-19,33,19,18:3)
Block(-19,33,20,18:3)
Block(-19,34,-19,18:3)
Block(-19,34,-17,18:3)
Block(-19,34,-14,18:3)
Block(-19,34,-13,18:3)
Block(-19,34,-12,18:3)
Block(-19,34,-11,18:3)
Block(-19,34,-10,18:3)
Block(-19,34,-9,18:3)
Block(-19,34,-6,18:3)
Block(-19,34,-5,18:3)
Block(-19,34,-2,18:3)
Block(-19,34,-1,18:3)
Block(-19,34,0,18:3)
Block(-19,34,5,18:3)
Block(-19,34,9,18:3)
Block(-19,34,10,18:3)
Block(-19,34,11,18:3)
Block(-19,34,12,18:3)
Block(-19,34,14,18:3)
Block(-19,34,15,18:3)
Block(-19,34,16,18:3)
Block(-19,34,17,18:3)
Block(-19,34,19,18:3)
Block(-19,35,-19,18:3)
Block(-19,35,-18,18:3)
Block(-19,35,-17,18:3)
Block(-19,35,-13,18:3)
Block(-19,35,-12,18:3)
Block(-19,35,-11,18:3)
Block(-19,35,-10,18:3)
Block(-19,35,-5,18:3)
Block(-19,35,-4,18:3)
Block(-19,35,-2,18:3)
Block(-19,35,-1,18:3)
Block(-19,35,0,17:7)
Block(-19,35,1,18:3)
Block(-19,35,3,18:3)
Block(-19,35,4,18:3)
Block(-19,35,5,18:3)
Block(-19,35,6,18:3)
Block(-19,35,7,18:3)
Block(-19,35,8,18:3)
Block(-19,35,9,18:3)
Block(-19,35,10,18:3)
Block(-19,35,11,18:3)
Block(-19,35,12,18:3)
Block(-19,35,13,18:3)
Block(-19,35,14,18:3)
Block(-19,35,15,18:3)
Block(-19,35,18,18:3)
Block(-19,36,-14,18:3)
Block(-19,36,-12,18:3)
Block(-19,36,-11,18:3)
Block(-19,36,-8,18:3)
Block(-19,36,-6,18:3)
Block(-19,36,-5,18:3)
Block(-19,36,-4,18:3)
Block(-19,36,-2,18:3)
Block(-19,36,0,17:7)
Block(-19,36,1,18:3)
Block(-19,36,2,18:3)
Block(-19,36,3,18:3)
Block(-19,36,5,18:3)
Block(-19,36,6,18:3)
Block(-19,36,7,18:3)
Block(-19,36,10,18:3)
Block(-19,36,13,18:3)
Block(-19,36,14,18:3)
Block(-19,37,-13,18:3)
Block(-19,37,-6,18:3)
Block(-19,37,-5,18:3)
Block(-19,37,-4,18:3)
Block(-19,37,-2,18:3)
Block(-19,37,-1,18:3)
Block(-19,37,0,18:3)
Block(-19,37,1,18:3)
Block(-19,37,2,18:3)
Block(-19,37,4,18:3)
Block(-19,37,5,18:3)
Block(-19,37,6,18:3)
Block(-19,37,7,18:3)
Block(-19,38,-11,18:3)
Block(-19,38,-4,18:3)
Block(-19,38,-2,18:3)
Block(-19,38,0,18:3)
Block(-19,38,5,18:3)
Block(-19,38,7,18:3)
Block(-19,39,-1,18:3)
Block(-18,0,0,17:3)
Block(-18,0,1,17:3)
Block(-18,0,2,17:3)
Block(-18,0,3,17:3)
Block(-18,19,-21,18:3)
Block(-18,19,-20,18:3)
Block(-18,19,20,18:3)
Block(-18,20,-21,18:3)
Block(-18,20,17,106:1)
Block(-18,20,19,18:3)
Block(-18,20,20,18:3)
Block(-18,20,21,18:3)
Block(-18,21,-20,18:3)
Block(-18,21,-19,18:3)
Block(-18,21,17,106:1)
Block(-18,21,21,18:3)
Block(-18,22,-20,18:3)
Block(-18,22,17,106:1)
Block(-18,22,18,18:3)
Block(-18,22,23,106:4)
Block(-18,23,-23,106:1)
Block(-18,23,-20,18:3)
Block(-18,23,17,106:1)
Block(-18,23,18,18:3)
Block(-18,23,19,18:3)
Block(-18,23,20,18:3)
Block(-18,23,23,106:4)
Block(-18,24,-23,106:1)
Block(-18,24,-21,18:3)
Block(-18,24,-19,18:3)
Block(-18,24,-18,18:3)
Block(-18,24,17,106:1)
Block(-18,24,18,18:3)
Block(-18,24,19,18:3)
Block(-18,24,23,106:4)
Block(-18,25,-23,106:1)
Block(-18,25,-21,106:1)
Block(-18,25,-20,18:3)
Block(-18,25,17,106:1)
Block(-18,25,18,18:3)
Block(-18,25,20,18:3)
Block(-18,25,22,18:3)
Block(-18,25,23,106:4)
Block(-18,26,-23,106:1)
Block(-18,26,-21,18:3)
Block(-18,26,-20,18:3)
Block(-18,26,-17,18:3)
Block(-18,26,17,106:1)
Block(-18,26,18,18:3)
Block(-18,26,19,18:3)
Block(-18,26,21,18:3)
Block(-18,26,22,18:3)
Block(-18,26,23,106:4)
Block(-18,27,-23,106:1)
Block(-18,27,-22,18:3)
Block(-18,27,-21,17:7)
Block(-18,27,-20,18:3)
Block(-18,27,-19,18:3)
Block(-18,27,-18,18:3)
Block(-18,27,-17,18:3)
Block(-18,27,17,106:1)
Block(-18,27,18,18:3)
Block(-18,27,19,18:3)
Block(-18,27,20,18:3)
Block(-18,27,21,17:7)
Block(-18,27,22,18:3)
Block(-18,27,23,106:4)
Block(-18,28,-21,18:3)
Block(-18,28,-20,18:3)
Block(-18,28,-19,18:3)
Block(-18,28,-18,17:3)
Block(-18,28,17,106:1)
Block(-18,28,18,17:3)
Block(-18,28,20,18:3)
Block(-18,28,23,106:4)
Block(-18,28,24,18:3)
Block(-18,29,-22,18:3)
Block(-18,29,-21,18:3)
Block(-18,29,-20,18:3)
Block(-18,29,-19,18:3)
Block(-18,29,-18,17:3)
Block(-18,29,16,18:3)
Block(-18,29,18,17:3)
Block(-18,29,19,18:3)
Block(-18,29,21,18:3)
Block(-18,29,22,18:3)
Block(-18,29,23,106:4)
Block(-18,30,-23,18:3)
Block(-18,30,-21,18:3)
Block(-18,30,-20,18:3)
Block(-18,30,-19,17:7)
Block(-18,30,-18,17:3)
Block(-18,30,-17,18:3)
Block(-18,30,-16,18:3)
Block(-18,30,16,18:3)
Block(-18,30,17,18:3)
Block(-18,30,18,17:3)
Block(-18,30,19,17:7)
Block(-18,30,20,18:3)
Block(-18,30,21,18:3)
Block(-18,30,22,18:3)
Block(-18,30,23,18:3)
Block(-18,31,-22,18:3)
Block(-18,31,-20,18:3)
Block(-18,31,-19,18:3)
Block(-18,31,-18,17:3)
Block(-18,31,-17,18:3)
Block(-18,31,-16,18:3)
Block(-18,31,-15,18:3)
Block(-18,31,13,18:3)
Block(-18,31,15,18:3)
Block(-18,31,16,18:3)
Block(-18,31,17,18:3)
Block(-18,31,18,17:3)
Block(-18,31,22,18:3)
Block(-18,32,-23,18:3)
Block(-18,32,-21,18:3)
Block(-18,32,-20,18:3)
Block(-18,32,-19,18:3)
Block(-18,32,-18,17:3)
Block(-18,32,-17,18:3)
Block(-18,32,-16,18:3)
Block(-18,32,-15,18:3)
Block(-18,32,-14,18:3)
Block(-18,32,11,18:3)
Block(-18,32,12,18:3)
Block(-18,32,13,18:3)
Block(-18,32,15,18:3)
Block(-18,32,17,18:3)
Block(-18,32,18,17:3)
Block(-18,32,19,18:3)
Block(-18,32,20,18:3)
Block(-18,32,21,18:3)
Block(-18,32,22,18:3)
Block(-18,32,23,18:3)
Block(-18,33,-20,18:3)
Block(-18,33,-18,18:3)
Block(-18,33,-17,18:3)
Block(-18,33,-16,18:3)
Block(-18,33,-15,17:11)
Block(-18,33,-14,18:3)
Block(-18,33,-13,18:3)
Block(-18,33,-12,18:3)
Block(-18,33,-11,18:3)
Block(-18,33,4,18:3)
Block(-18,33,5,18:3)
Block(-18,33,9,18:3)
Block(-18,33,11,18:3)
Block(-18,33,12,18:3)
Block(-18,33,13,18:3)
Block(-18,33,14,18:3)
Block(-18,33,15,17:11)
Block(-18,33,17,18:3)
Block(-18,33,19,18:3)
Block(-18,34,-18,18:3)
Block(-18,34,-17,18:3)
Block(-18,34,-16,18:3)
Block(-18,34,-14,18:3)
Block(-18,34,-13,18:3)
Block(-18,34,-12,18:3)
Block(-18,34,-10,18:3)
Block(-18,34,-8,18:3)
Block(-18,34,-5,18:3)
Block(-18,34,-4,18:3)
Block(-18,34,-1,18:3)
Block(-18,34,0,18:3)
Block(-18,34,5,18:3)
Block(-18,34,9,18:3)
Block(-18,34,10,18:3)
Block(-18,34,11,18:3)
Block(-18,34,12,18:3)
Block(-18,34,13,18:3)
Block(-18,34,15,18:3)
Block(-18,34,18,18:3)
Block(-18,35,-16,18:3)
Block(-18,35,-15,18:3)
Block(-18,35,-14,18:3)
Block(-18,35,-13,18:3)
Block(-18,35,-12,18:3)
Block(-18,35,-11,17:11)
Block(-18,35,-10,18:3)
Block(-18,35,-9,18:3)
Block(-18,35,-8,18:3)
Block(-18,35,-7,18:3)
Block(-18,35,-6,18:3)
Block(-18,35,-5,18:3)
Block(-18,35,-2,18:3)
Block(-18,35,-1,18:3)
Block(-18,35,0,17:7)
Block(-18,35,1,18:3)
Block(-18,35,2,18:3)
Block(-18,35,3,18:3)
Block(-18,35,4,18:3)
Block(-18,35,5,18:3)
Block(-18,35,8,18:3)
Block(-18,35,9,18:3)
Block(-18,35,10,18:3)
Block(-18,35,11,17:11)
Block(-18,35,12,18:3)
Block(-18,35,13,18:3)
Block(-18,35,14,18:3)
Block(-18,35,16,18:3)
Block(-18,36,-16,18:3)
Block(-18,36,-15,18:3)
Block(-18,36,-14,18:3)
Block(-18,36,-13,18:3)
Block(-18,36,-12,18:3)
Block(-18,36,-11,18:3)
Block(-18,36,-10,18:3)
Block(-18,36,-8,18:3)
Block(-18,36,-7,18:3)
Block(-18,36,-6,18:3)
Block(-18,36,-5,18:3)
Block(-18,36,-4,18:3)
Block(-18,36,-3,18:3)
Block(-18,36,-2,18:3)
Block(-18,36,-1,18:3)
Block(-18,36,0,17:7)
Block(-18,36,1,18:3)
Block(-18,36,2,18:3)
Block(-18,36,3,18:3)
Block(-18,36,4,18:3)
Block(-18,36,5,18:3)
Block(-18,36,6,18:3)
Block(-18,36,7,18:3)
Block(-18,36,8,18:3)
Block(-18,36,9,18:3)
Block(-18,36,11,18:3)
Block(-18,36,14,18:3)
Block(-18,36,15,18:3)
Block(-18,36,16,18:3)
Block(-18,36,17,18:3)
Block(-18,37,-11,18:3)
Block(-18,37,-10,18:3)
Block(-18,37,-9,18:3)
Block(-18,37,-5,18:3)
Block(-18,37,-3,18:3)
Block(-18,37,-2,18:3)
Block(-18,37,-1,18:3)
Block(-18,37,0,18:3)
Block(-18,37,1,18:3)
Block(-18,37,2,18:3)
Block(-18,37,3,18:3)
Block(-18,37,5,18:3)
Block(-18,37,9,18:3)
Block(-18,37,11,18:3)
Block(-18,37,12,18:3)
Block(-18,37,13,18:3)
Block(-18,38,-12,18:3)
Block(-18,38,-10,18:3)
Block(-18,38,-6,18:3)
Block(-18,38,-5,18:3)
Block(-18,38,-3,18:3)
Block(-18,38,-1,18:3)
Block(-18,38,5,18:3)
Block(-18,38,6,18:3)
Block(-18,38,7,18:3)
Block(-18,38,11,18:3)
Block(-18,39,-5,18:3)
Block(-18,39,-4,18:3)
Block(-18,39,0,18:3)
Block(-18,39,5,18:3)
Block(-18,39,6,18:3)
Block(-18,40,0,18:3)
Block(-17,0,1,17:3)
Block(-17,0,2,17:3)
Block(-17,19,18,106:2)
Block(-17,20,18,106:2)
Block(-17,21,-20,18:3)
Block(-17,21,18,106:2)
Block(-17,22,18,106:2)
Block(-17,23,18,106:2)
Block(-17,24,-19,18:3)
Block(-17,24,18,106:2)
Block(-17,24,19,18:3)
Block(-17,24,20,18:3)
Block(-17,24,21,18:3)
Block(-17,25,-20,18:3)
Block(-17,25,18,106:2)
Block(-17,25,19,106:1)
Block(-17,25,20,18:3)
Block(-17,26,19,18:3)
Block(-17,26,20,18:3)
Block(-17,26,21,18:3)
Block(-17,27,-22,18:3)
Block(-17,27,20,18:3)
Block(-17,27,21,18:3)
Block(-17,28,-23,18:3)
Block(-17,28,-22,18:3)
Block(-17,28,-21,18:3)
Block(-17,28,-20,18:3)
Block(-17,28,-19,18:3)
Block(-17,28,19,18:3)
Block(-17,28,20,18:3)
Block(-17,28,21,18:3)
Block(-17,28,22,18:3)
Block(-17,28,23,18:3)
Block(-17,29,-24,18:3)
Block(-17,29,-21,18:3)
Block(-17,29,-20,18:3)
Block(-17,29,-19,18:3)
Block(-17,29,17,18:3)
Block(-17,29,18,18:3)
Block(-17,29,19,18:3)
Block(-17,29,20,18:3)
Block(-17,29,21,18:3)
Block(-17,29,22,18:3)
Block(-17,29,23,106:4)
Block(-17,30,-24,18:3)
Block(-17,30,-23,18:3)
Block(-17,30,-22,18:3)
Block(-17,30,-21,18:3)
Block(-17,30,-20,17:7)
Block(-17,30,-19,18:3)
Block(-17,30,-18,18:3)
Block(-17,30,-16,18:3)
Block(-17,30,16,18:3)
Block(-17,30,17,18:3)
Block(-17,30,18,18:3)
Block(-17,30,19,18:3)
Block(-17,30,20,17:7)
Block(-17,31,-23,18:3)
Block(-17,31,-20,18:3)
Block(-17,31,-17,17:3)
Block(-17,31,-16,18:3)
Block(-17,31,-15,18:3)
Block(-17,31,15,18:3)
Block(-17,31,17,17:3)
Block(-17,31,18,18:3)
Block(-17,31,19,18:3)
Block(-17,32,-21,18:3)
Block(-17,32,-20,18:3)
Block(-17,32,-19,18:3)
Block(-17,32,-18,18:3)
Block(-17,32,-17,17:3)
Block(-17,32,-15,18:3)
Block(-17,32,-14,18:3)
Block(-17,32,-13,18:3)
Block(-17,32,11,18:3)
Block(-17,32,14,18:3)
Block(-17,32,17,17:3)
Block(-17,32,18,18:3)
Block(-17,32,19,18:3)
Block(-17,32,20,18:3)
Block(-17,32,21,18:3)
Block(-17,33,-22,18:3)
Block(-17,33,-20,18:3)
Block(-17,33,-18,18:3)
Block(-17,33,-17,17:3)
Block(-17,33,-16,17:11)
Block(-17,33,-15,18:3)
Block(-17,33,-14,18:3)
Block(-17,33,-12,18:3)
Block(-17,33,4,18:3)
Block(-17,33,5,18:3)
Block(-17,33,6,18:3)
Block(-17,33,11,18:3)
Block(-17,33,13,18:3)
Block(-17,33,14,18:3)
Block(-17,33,15,18:3)
Block(-17,33,16,17:11)
Block(-17,33,17,17:3)
Block(-17,33,18,18:3)
Block(-17,33,19,18:3)
Block(-17,33,21,18:3)
Block(-17,33,22,18:3)
Block(-17,34,-20,18:3)
Block(-17,34,-18,18:3)
Block(-17,34,-17,18:3)
Block(-17,34,-15,18:3)
Block(-17,34,-14,18:3)
Block(-17,34,-13,18:3)
Block(-17,34,-10,18:3)
Block(-17,34,-5,18:3)
Block(-17,34,0,18:3)
Block(-17,34,4,18:3)
Block(-17,34,5,18:3)
Block(-17,34,12,18:3)
Block(-17,34,13,18:3)
Block(-17,34,14,18:3)
Block(-17,34,15,18:3)
Block(-17,34,16,18:3)
Block(-17,34,17,18:3)
Block(-17,34,19,18:3)
Block(-17,35,-19,18:3)
Block(-17,35,-18,18:3)
Block(-17,35,-17,18:3)
Block(-17,35,-16,18:3)
Block(-17,35,-12,17:11)
Block(-17,35,-11,18:3)
Block(-17,35,-8,18:3)
Block(-17,35,-6,18:3)
Block(-17,35,-1,18:3)
Block(-17,35,2,18:3)
Block(-17,35,4,18:3)
Block(-17,35,5,18:3)
Block(-17,35,6,18:3)
Block(-17,35,10,18:3)
Block(-17,35,11,18:3)
Block(-17,35,12,17:11)
Block(-17,35,13,18:3)
Block(-17,35,14,18:3)
Block(-17,35,15,18:3)
Block(-17,35,16,18:3)
Block(-17,35,17,18:3)
Block(-17,35,18,18:3)
Block(-17,35,19,18:3)
Block(-17,36,-17,18:3)
Block(-17,36,-16,18:3)
Block(-17,36,-7,18:3)
Block(-17,36,-5,17:11)
Block(-17,36,-4,17:11)
Block(-17,36,-3,17:11)
Block(-17,36,-2,17:11)
Block(-17,36,-1,17:11)
Block(-17,36,0,17:7)
Block(-17,36,1,17:11)
Block(-17,36,2,17:11)
Block(-17,36,3,17:11)
Block(-17,36,4,17:11)
Block(-17,36,5,17:11)
Block(-17,36,6,18:3)
Block(-17,36,9,18:3)
Block(-17,36,13,18:3)
Block(-17,36,15,18:3)
Block(-17,36,17,18:3)
Block(-17,36,18,18:3)
Block(-17,37,-16,18:3)
Block(-17,37,-15,18:3)
Block(-17,37,-14,18:3)
Block(-17,37,-13,18:3)
Block(-17,37,-5,18:3)
Block(-17,37,-3,18:3)
Block(-17,37,-2,18:3)
Block(-17,37,-1,18:3)
Block(-17,37,0,17:7)
Block(-17,37,2,18:3)
Block(-17,37,3,18:3)
Block(-17,37,4,18:3)
Block(-17,37,5,18:3)
Block(-17,37,8,18:3)
Block(-17,37,11,18:3)
Block(-17,37,14,18:3)
Block(-17,37,15,18:3)
Block(-17,38,-11,18:3)
Block(-17,38,-10,18:3)
Block(-17,38,-7,18:3)
Block(-17,38,-6,18:3)
Block(-17,38,-5,18:3)
Block(-17,38,-3,18:3)
Block(-17,38,-1,18:3)
Block(-17,38,0,18:3)
Block(-17,38,2,18:3)
Block(-17,38,3,18:3)
Block(-17,38,4,18:3)
Block(-17,38,5,18:3)
Block(-17,38,6,18:3)
Block(-17,38,7,18:3)
Block(-17,38,11,18:3)
Block(-17,38,12,18:3)
Block(-17,39,-5,18:3)
Block(-17,39,-2,18:3)
Block(-17,39,-1,18:3)
Block(-17,39,0,18:3)
Block(-17,39,4,18:3)
Block(-17,39,6,18:3)
Block(-17,40,-1,18:3)
Block(-17,40,0,18:3)
Block(-17,40,1,18:3)
Block(-16,0,-6,17:3)
Block(-16,0,0,17:3)
Block(-16,0,1,17:3)
Block(-16,0,2,17:3)
Block(-16,0,3,17:3)
Block(-16,22,20,106:2)
Block(-16,23,20,106:2)
Block(-16,24,-20,106:2)
Block(-16,24,-19,106:2)
Block(-16,24,20,106:2)
Block(-16,25,-20,106:2)
Block(-16,25,20,106:2)
Block(-16,26,-20,106:2)
Block(-16,26,20,106:2)
Block(-16,27,-22,18:3)
Block(-16,27,-21,18:3)
Block(-16,27,-20,106:2)
Block(-16,28,-23,18:3)
Block(-16,28,-22,18:3)
Block(-16,28,-21,18:3)
Block(-16,28,-20,106:2)
Block(-16,28,-19,18:3)
Block(-16,28,19,18:3)
Block(-16,28,21,18:3)
Block(-16,28,23,18:3)
Block(-16,29,-24,18:3)
Block(-16,29,-21,18:3)
Block(-16,29,-20,18:3)
Block(-16,29,-19,18:3)
Block(-16,29,-18,18:3)
Block(-16,29,18,18:3)
Block(-16,29,19,18:3)
Block(-16,29,20,18:3)
Block(-16,29,21,18:3)
Block(-16,29,23,18:3)
Block(-16,30,-23,18:3)
Block(-16,30,-22,18:3)
Block(-16,30,-21,17:7)
Block(-16,30,-20,18:3)
Block(-16,30,-19,18:3)
Block(-16,30,-18,18:3)
Block(-16,30,16,18:3)
Block(-16,30,18,18:3)
Block(-16,30,19,18:3)
Block(-16,30,20,18:3)
Block(-16,30,21,17:7)
Block(-16,30,22,18:3)
Block(-16,30,23,18:3)
Block(-16,30,24,18:3)
Block(-16,31,-24,18:3)
Block(-16,31,-23,18:3)
Block(-16,31,-20,18:3)
Block(-16,31,-19,18:3)
Block(-16,31,-18,18:3)
Block(-16,31,-17,18:3)
Block(-16,31,17,18:3)
Block(-16,31,19,18:3)
Block(-16,31,21,18:3)
Block(-16,32,-23,18:3)
Block(-16,32,-21,18:3)
Block(-16,32,-20,18:3)
Block(-16,32,-19,18:3)
Block(-16,32,-18,18:3)
Block(-16,32,-17,18:3)
Block(-16,32,-16,18:3)
Block(-16,32,-15,18:3)
Block(-16,32,-14,18:3)
Block(-16,32,14,18:3)
Block(-16,32,15,18:3)
Block(-16,32,16,18:3)
Block(-16,32,18,18:3)
Block(-16,32,19,18:3)
Block(-16,32,20,18:3)
Block(-16,32,21,18:3)
Block(-16,32,23,18:3)
Block(-16,33,-21,18:3)
Block(-16,33,-20,18:3)
Block(-16,33,-19,18:3)
Block(-16,33,-18,18:3)
Block(-16,33,-17,17:7)
Block(-16,33,-16,17:3)
Block(-16,33,-15,18:3)
Block(-16,33,-14,18:3)
Block(-16,33,-5,18:3)
Block(-16,33,14,18:3)
Block(-16,33,15,18:3)
Block(-16,33,16,17:3)
Block(-16,33,17,17:7)
Block(-16,33,18,18:3)
Block(-16,33,19,18:3)
Block(-16,33,20,18:3)
Block(-16,33,21,18:3)
Block(-16,34,-20,18:3)
Block(-16,34,-18,18:3)
Block(-16,34,-16,17:3)
Block(-16,34,-13,18:3)
Block(-16,34,-5,18:3)
Block(-16,34,-1,18:3)
Block(-16,34,0,18:3)
Block(-16,34,3,18:3)
Block(-16,34,4,18:3)
Block(-16,34,5,18:3)
Block(-16,34,10,18:3)
Block(-16,34,11,18:3)
Block(-16,34,12,18:3)
Block(-16,34,13,18:3)
Block(-16,34,14,18:3)
Block(-16,34,16,17:3)
Block(-16,34,17,18:3)
Block(-16,34,19,18:3)
Block(-16,34,20,18:3)
Block(-16,35,-19,18:3)
Block(-16,35,-18,18:3)
Block(-16,35,-16,18:3)
Block(-16,35,-15,18:3)
Block(-16,35,-13,17:11)
Block(-16,35,-12,18:3)
Block(-16,35,-11,18:3)
Block(-16,35,-5,18:3)
Block(-16,35,-2,18:3)
Block(-16,35,2,18:3)
Block(-16,35,12,18:3)
Block(-16,35,13,17:11)
Block(-16,35,14,18:3)
Block(-16,35,15,18:3)
Block(-16,35,16,18:3)
Block(-16,35,17,18:3)
Block(-16,35,18,18:3)
Block(-16,36,-17,18:3)
Block(-16,36,-16,18:3)
Block(-16,36,-15,18:3)
Block(-16,36,-14,18:3)
Block(-16,36,-13,18:3)
Block(-16,36,-11,18:3)
Block(-16,36,-8,18:3)
Block(-16,36,-5,18:3)
Block(-16,36,-4,18:3)
Block(-16,36,-3,18:3)
Block(-16,36,-2,18:3)
Block(-16,36,-1,18:3)
Block(-16,36,0,17:7)
Block(-16,36,1,18:3)
Block(-16,36,3,18:3)
Block(-16,36,4,18:3)
Block(-16,36,5,18:3)
Block(-16,36,6,18:3)
Block(-16,36,7,18:3)
Block(-16,36,8,18:3)
Block(-16,36,10,18:3)
Block(-16,36,11,18:3)
Block(-16,36,12,18:3)
Block(-16,36,15,18:3)
Block(-16,36,18,18:3)
Block(-16,37,-14,18:3)
Block(-16,37,-12,18:3)
Block(-16,37,-11,18:3)
Block(-16,37,-9,18:3)
Block(-16,37,-8,18:3)
Block(-16,37,-7,18:3)
Block(-16,37,-6,18:3)
Block(-16,37,-5,18:3)
Block(-16,37,-4,18:3)
Block(-16,37,-2,18:3)
Block(-16,37,0,17:7)
Block(-16,37,1,18:3)
Block(-16,37,2,18:3)
Block(-16,37,3,18:3)
Block(-16,37,4,18:3)
Block(-16,37,5,18:3)
Block(-16,37,6,18:3)
Block(-16,37,7,18:3)
Block(-16,37,8,18:3)
Block(-16,37,9,18:3)
Block(-16,37,15,18:3)
Block(-16,38,-16,18:3)
Block(-16,38,-15,18:3)
Block(-16,38,-5,18:3)
Block(-16,38,-4,18:3)
Block(-16,38,-3,18:3)
Block(-16,38,-2,18:3)
Block(-16,38,-1,18:3)
Block(-16,38,0,18:3)
Block(-16,38,5,18:3)
Block(-16,38,16,18:3)
Block(-16,39,-6,18:3)
Block(-16,39,-5,18:3)
Block(-16,39,-4,18:3)
Block(-16,39,-1,18:3)
Block(-16,39,2,18:3)
Block(-16,39,5,18:3)
Block(-15,0,-12,17:3)
Block(-15,0,-7,17:3)
Block(-15,0,-6,17:3)
Block(-15,0,-5,17:3)
Block(-15,0,-1,17:3)
Block(-15,0,0,17:3)
Block(-15,0,1,17:3)
Block(-15,0,2,17:3)
Block(-15,0,3,17:3)
Block(-15,0,4,17:3)
Block(-15,27,-20,18:3)
Block(-15,27,21,18:3)
Block(-15,28,-23,18:3)
Block(-15,28,-21,18:3)
Block(-15,28,-20,18:3)
Block(-15,28,19,18:3)
Block(-15,28,21,18:3)
Block(-15,29,-21,18:3)
Block(-15,29,-19,18:3)
Block(-15,29,-18,18:3)
Block(-15,29,19,18:3)
Block(-15,29,20,18:3)
Block(-15,29,21,18:3)
Block(-15,29,23,18:3)
Block(-15,30,-23,18:3)
Block(-15,30,-22,18:3)
Block(-15,30,-21,18:3)
Block(-15,30,-18,18:3)
Block(-15,30,20,18:3)
Block(-15,30,21,18:3)
Block(-15,30,23,18:3)
Block(-15,30,24,18:3)
Block(-15,31,-21,18:3)
Block(-15,31,-20,18:3)
Block(-15,31,-18,18:3)
Block(-15,31,-17,18:3)
Block(-15,31,-15,18:3)
Block(-15,31,17,18:3)
Block(-15,31,20,18:3)
Block(-15,31,21,18:3)
Block(-15,31,23,18:3)
Block(-15,32,-23,18:3)
Block(-15,32,-21,18:3)
Block(-15,32,-20,18:3)
Block(-15,32,-19,18:3)
Block(-15,32,-18,18:3)
Block(-15,32,-16,18:3)
Block(-15,32,-15,18:3)
Block(-15,32,-14,18:3)
Block(-15,32,15,18:3)
Block(-15,32,16,18:3)
Block(-15,32,18,18:3)
Block(-15,32,19,18:3)
Block(-15,32,20,18:3)
Block(-15,32,21,18:3)
Block(-15,32,22,18:3)
Block(-15,33,-21,18:3)
Block(-15,33,-20,18:3)
Block(-15,33,-19,18:3)
Block(-15,33,-18,17:7)
Block(-15,33,-17,18:3)
Block(-15,33,-16,18:3)
Block(-15,33,-15,18:3)
Block(-15,33,-14,18:3)
Block(-15,33,13,18:3)
Block(-15,33,14,18:3)
Block(-15,33,15,18:3)
Block(-15,33,16,18:3)
Block(-15,33,17,18:3)
Block(-15,33,18,17:7)
Block(-15,33,19,18:3)
Block(-15,33,20,18:3)
Block(-15,33,21,18:3)
Block(-15,34,-19,18:3)
Block(-15,34,-18,18:3)
Block(-15,34,-17,18:3)
Block(-15,34,-16,18:3)
Block(-15,34,-15,17:3)
Block(-15,34,-13,18:3)
Block(-15,34,-12,18:3)
Block(-15,34,-11,18:3)
Block(-15,34,-3,18:3)
Block(-15,34,11,18:3)
Block(-15,34,12,18:3)
Block(-15,34,13,18:3)
Block(-15,34,14,18:3)
Block(-15,34,15,17:3)
Block(-15,34,17,18:3)
Block(-15,34,18,18:3)
Block(-15,34,20,18:3)
Block(-15,34,22,18:3)
Block(-15,35,-20,18:3)
Block(-15,35,-19,18:3)
Block(-15,35,-18,18:3)
Block(-15,35,-17,18:3)
Block(-15,35,-16,18:3)
Block(-15,35,-15,17:3)
Block(-15,35,-14,17:11)
Block(-15,35,-13,18:3)
Block(-15,35,-12,18:3)
Block(-15,35,-11,18:3)
Block(-15,35,-10,18:3)
Block(-15,35,-6,18:3)
Block(-15,35,-5,18:3)
Block(-15,35,-3,18:3)
Block(-15,35,0,18:3)
Block(-15,35,1,18:3)
Block(-15,35,4,18:3)
Block(-15,35,5,18:3)
Block(-15,35,6,18:3)
Block(-15,35,12,18:3)
Block(-15,35,14,17:11)
Block(-15,35,15,17:3)
Block(-15,35,16,18:3)
Block(-15,35,17,18:3)
Block(-15,35,18,18:3)
Block(-15,35,21,18:3)
Block(-15,36,-18,18:3)
Block(-15,36,-17,18:3)
Block(-15,36,-14,18:3)
Block(-15,36,-13,18:3)
Block(-15,36,-12,18:3)
Block(-15,36,-7,18:3)
Block(-15,36,-6,18:3)
Block(-15,36,-5,18:3)
Block(-15,36,-4,18:3)
Block(-15,36,-3,18:3)
Block(-15,36,-2,18:3)
Block(-15,36,-1,18:3)
Block(-15,36,0,17:7)
Block(-15,36,1,18:3)
Block(-15,36,2,18:3)
Block(-15,36,3,18:3)
Block(-15,36,5,18:3)
Block(-15,36,6,18:3)
Block(-15,36,7,18:3)
Block(-15,36,11,18:3)
Block(-15,36,13,18:3)
Block(-15,36,15,18:3)
Block(-15,36,16,18:3)
Block(-15,36,17,18:3)
Block(-15,36,18,18:3)
Block(-15,37,-17,18:3)
Block(-15,37,-15,18:3)
Block(-15,37,-14,18:3)
Block(-15,37,-13,18:3)
Block(-15,37,-10,18:3)
Block(-15,37,-9,18:3)
Block(-15,37,-8,18:3)
Block(-15,37,-7,18:3)
Block(-15,37,-6,18:3)
Block(-15,37,-5,18:3)
Block(-15,37,-4,18:3)
Block(-15,37,-3,18:3)
Block(-15,37,-2,18:3)
Block(-15,37,-1,18:3)
Block(-15,37,0,17:7)
Block(-15,37,1,18:3)
Block(-15,37,2,18:3)
Block(-15,37,3,18:3)
Block(-15,37,5,18:3)
Block(-15,37,6,18:3)
Block(-15,37,7,18:3)
Block(-15,37,8,18:3)
Block(-15,37,15,18:3)
Block(-15,37,16,18:3)
Block(-15,37,17,18:3)
Block(-15,38,-15,18:3)
Block(-15,38,-9,18:3)
Block(-15,38,-8,18:3)
Block(-15,38,-7,18:3)
Block(-15,38,-5,18:3)
Block(-15,38,-4,18:3)
Block(-15,38,-3,18:3)
Block(-15,38,-2,18:3)
Block(-15,38,3,18:3)
Block(-15,38,4,18:3)
Block(-15,38,5,18:3)
Block(-15,38,6,18:3)
Block(-15,38,16,18:3)
Block(-15,39,-10,18:3)
Block(-15,39,-6,18:3)
Block(-15,39,-5,18:3)
Block(-15,39,0,18:3)
Block(-15,39,1,18:3)
Block(-15,39,5,18:3)
Block(-15,39,7,18:3)
Block(-15,39,8,18:3)
Block(-14,0,-13,17:3)
Block(-14,0,-12,17:3)
Block(-14,0,-11,17:3)
Block(-14,0,-6,17:3)
Block(-14,0,-5,17:3)
Block(-14,0,-4,17:3)
Block(-14,0,-3,17:3)
Block(-14,0,-2,17:3)
Block(-14,0,-1,17:3)
Block(-14,0,0,17:3)
Block(-14,0,1,17:3)
Block(-14,0,2,17:3)
Block(-14,0,3,17:3)
Block(-14,0,4,17:3)
Block(-14,0,5,17:3)
Block(-14,0,11,17:3)
Block(-14,1,-2,17:3)
Block(-14,28,-22,18:3)
Block(-14,28,-20,18:3)
Block(-14,28,19,18:3)
Block(-14,28,21,18:3)
Block(-14,29,-23,18:3)
Block(-14,29,-22,18:3)
Block(-14,29,-21,18:3)
Block(-14,29,-20,18:3)
Block(-14,29,21,18:3)
Block(-14,30,-24,18:3)
Block(-14,30,-23,18:3)
Block(-14,30,-22,18:3)
Block(-14,30,-21,18:3)
Block(-14,30,-20,18:3)
Block(-14,30,-19,18:3)
Block(-14,30,20,18:3)
Block(-14,30,21,18:3)
Block(-14,31,-22,18:3)
Block(-14,31,-21,18:3)
Block(-14,31,-20,18:3)
Block(-14,31,-19,18:3)
Block(-14,31,19,18:3)
Block(-14,31,21,18:3)
Block(-14,31,22,18:3)
Block(-14,32,-23,18:3)
Block(-14,32,-22,18:3)
Block(-14,32,-18,18:3)
Block(-14,32,-16,18:3)
Block(-14,32,-15,18:3)
Block(-14,32,-14,18:3)
Block(-14,32,14,18:3)
Block(-14,32,15,18:3)
Block(-14,32,17,18:3)
Block(-14,32,18,18:3)
Block(-14,32,19,18:3)
Block(-14,32,20,18:3)
Block(-14,32,21,18:3)
Block(-14,32,22,18:3)
Block(-14,32,23,18:3)
Block(-14,33,-22,18:3)
Block(-14,33,-20,18:3)
Block(-14,33,-19,17:7)
Block(-14,33,-18,18:3)
Block(-14,33,-17,18:3)
Block(-14,33,-16,18:3)
Block(-14,33,-15,18:3)
Block(-14,33,-13,18:3)
Block(-14,33,16,18:3)
Block(-14,33,17,18:3)
Block(-14,33,18,18:3)
Block(-14,33,19,17:7)
Block(-14,33,20,18:3)
Block(-14,33,21,18:3)
Block(-14,33,22,18:3)
Block(-14,33,23,18:3)
Block(-14,34,-22,18:3)
Block(-14,34,-20,18:3)
Block(-14,34,-19,18:3)
Block(-14,34,-18,18:3)
Block(-14,34,-17,18:3)
Block(-14,34,-16,18:3)
Block(-14,34,-15,18:3)
Block(-14,34,-8,18:3)
Block(-14,34,-5,18:3)
Block(-14,34,-1,18:3)
Block(-14,34,12,18:3)
Block(-14,34,13,18:3)
Block(-14,34,17,18:3)
Block(-14,34,18,18:3)
Block(-14,34,23,18:3)
Block(-14,35,-19,18:3)
Block(-14,35,-18,18:3)
Block(-14,35,-17,18:3)
Block(-14,35,-16,18:3)
Block(-14,35,-15,17:7)
Block(-14,35,-14,17:11)
Block(-14,35,-13,18:3)
Block(-14,35,-8,18:3)
Block(-14,35,-7,18:3)
Block(-14,35,-5,18:3)
Block(-14,35,-1,18:3)
Block(-14,35,5,18:3)
Block(-14,35,7,18:3)
Block(-14,35,12,18:3)
Block(-14,35,14,17:7)
Block(-14,35,15,17:7)
Block(-14,35,17,18:3)
Block(-14,35,18,18:3)
Block(-14,35,19,18:3)
Block(-14,35,20,18:3)
Block(-14,36,-17,18:3)
Block(-14,36,-16,18:3)
Block(-14,36,-14,17:11)
Block(-14,36,-13,18:3)
Block(-14,36,-12,18:3)
Block(-14,36,-11,18:3)
Block(-14,36,-9,18:3)
Block(-14,36,-8,18:3)
Block(-14,36,-7,18:3)
Block(-14,36,-6,18:3)
Block(-14,36,-5,18:3)
Block(-14,36,-4,18:3)
Block(-14,36,-3,18:3)
Block(-14,36,-2,18:3)
Block(-14,36,-1,18:3)
Block(-14,36,0,17:7)
Block(-14,36,3,18:3)
Block(-14,36,4,18:3)
Block(-14,36,5,18:3)
Block(-14,36,6,18:3)
Block(-14,36,7,18:3)
Block(-14,36,10,18:3)
Block(-14,36,11,18:3)
Block(-14,36,12,18:3)
Block(-14,36,13,18:3)
Block(-14,36,14,17:7)
Block(-14,36,15,18:3)
Block(-14,36,17,18:3)
Block(-14,36,18,18:3)
Block(-14,36,19,18:3)
Block(-14,36,20,18:3)
Block(-14,37,-17,18:3)
Block(-14,37,-15,18:3)
Block(-14,37,-14,18:3)
Block(-14,37,-13,18:3)
Block(-14,37,-11,18:3)
Block(-14,37,-10,18:3)
Block(-14,37,-9,18:3)
Block(-14,37,-8,18:3)
Block(-14,37,-7,18:3)
Block(-14,37,-6,18:3)
Block(-14,37,-5,18:3)
Block(-14,37,-3,18:3)
Block(-14,37,-1,18:3)
Block(-14,37,0,17:7)
Block(-14,37,1,18:3)
Block(-14,37,2,18:3)
Block(-14,37,3,18:3)
Block(-14,37,4,18:3)
Block(-14,37,5,18:3)
Block(-14,37,6,18:3)
Block(-14,37,8,18:3)
Block(-14,37,10,18:3)
Block(-14,37,11,18:3)
Block(-14,37,12,18:3)
Block(-14,37,14,18:3)
Block(-14,37,16,18:3)
Block(-14,38,-15,18:3)
Block(-14,38,-14,18:3)
Block(-14,38,-12,18:3)
Block(-14,38,-10,18:3)
Block(-14,38,-9,18:3)
Block(-14,38,-8,18:3)
Block(-14,38,-7,18:3)
Block(-14,38,-6,18:3)
Block(-14,38,-5,18:3)
Block(-14,38,0,18:3)
Block(-14,38,1,18:3)
Block(-14,38,3,18:3)
Block(-14,38,5,18:3)
Block(-14,38,6,18:3)
Block(-14,38,8,18:3)
Block(-14,38,12,18:3)
Block(-14,38,16,18:3)
Block(-14,39,-10,18:3)
Block(-14,39,-6,18:3)
Block(-14,39,-5,18:3)
Block(-14,39,-2,18:3)
Block(-14,39,-1,18:3)
Block(-14,39,0,18:3)
Block(-14,39,3,18:3)
Block(-14,39,4,18:3)
Block(-14,39,6,18:3)
Block(-14,39,8,18:3)
Block(-14,39,9,18:3)
Block(-14,40,-8,18:3)
Block(-14,40,-7,18:3)
Block(-14,40,1,18:3)
Block(-14,40,4,18:3)
Block(-14,40,6,18:3)
Block(-14,40,7,18:3)
Block(-13,0,-12,17:3)
Block(-13,0,-11,17:3)
Block(-13,0,-10,17:3)
Block(-13,0,-5,17:3)
Block(-13,0,-4,17:3)
Block(-13,0,-3,17:3)
Block(-13,0,-2,17:3)
Block(-13,0,-1,17:3)
Block(-13,0,0,17:3)
Block(-13,0,1,17:3)
Block(-13,0,2,17:3)
Block(-13,0,3,17:3)
Block(-13,0,4,17:3)
Block(-13,0,5,17:3)
Block(-13,0,9,17:3)
Block(-13,0,10,17:3)
Block(-13,0,11,17:3)
Block(-13,0,12,17:3)
Block(-13,1,-3,17:3)
Block(-13,1,-2,17:3)
Block(-13,1,-1,17:3)
Block(-13,1,2,17:3)
Block(-13,29,-21,18:3)
Block(-13,29,-20,18:3)
Block(-13,29,21,18:3)
Block(-13,30,-22,18:3)
Block(-13,30,-21,18:3)
Block(-13,30,-20,18:3)
Block(-13,30,19,18:3)
Block(-13,30,20,18:3)
Block(-13,30,21,18:3)
Block(-13,30,22,18:3)
Block(-13,31,-22,18:3)
Block(-13,31,-21,18:3)
Block(-13,31,-20,18:3)
Block(-13,31,-18,18:3)
Block(-13,31,19,18:3)
Block(-13,31,20,18:3)
Block(-13,31,21,18:3)
Block(-13,32,-22,18:3)
Block(-13,32,-21,18:3)
Block(-13,32,-20,18:3)
Block(-13,32,-19,18:3)
Block(-13,32,-18,18:3)
Block(-13,32,-17,18:3)
Block(-13,32,17,18:3)
Block(-13,32,18,18:3)
Block(-13,32,19,18:3)
Block(-13,32,20,18:3)
Block(-13,32,21,18:3)
Block(-13,32,22,18:3)
Block(-13,33,-23,18:3)
Block(-13,33,-22,18:3)
Block(-13,33,-21,18:3)
Block(-13,33,-20,17:7)
Block(-13,33,-19,18:3)
Block(-13,33,-18,18:3)
Block(-13,33,-17,18:3)
Block(-13,33,-14,18:3)
Block(-13,33,15,18:3)
Block(-13,33,16,18:3)
Block(-13,33,17,18:3)
Block(-13,33,18,18:3)
Block(-13,33,19,18:3)
Block(-13,33,20,17:7)
Block(-13,33,21,18:3)
Block(-13,34,-23,18:3)
Block(-13,34,-22,18:3)
Block(-13,34,-21,18:3)
Block(-13,34,-20,18:3)
Block(-13,34,-18,18:3)
Block(-13,34,-17,18:3)
Block(-13,34,-16,18:3)
Block(-13,34,-15,18:3)
Block(-13,34,-9,18:3)
Block(-13,34,-8,18:3)
Block(-13,34,-6,18:3)
Block(-13,34,-4,18:3)
Block(-13,34,0,18:3)
Block(-13,34,7,18:3)
Block(-13,34,13,18:3)
Block(-13,34,15,18:3)
Block(-13,34,17,18:3)
Block(-13,34,18,18:3)
Block(-13,34,19,18:3)
Block(-13,34,20,18:3)
Block(-13,34,23,18:3)
Block(-13,35,-21,18:3)
Block(-13,35,-20,18:3)
Block(-13,35,-19,18:3)
Block(-13,35,-18,18:3)
Block(-13,35,-16,17:7)
Block(-13,35,-15,18:3)
Block(-13,35,-13,17:11)
Block(-13,35,-11,18:3)
Block(-13,35,-10,18:3)
Block(-13,35,-8,18:3)
Block(-13,35,-6,18:3)
Block(-13,35,-5,18:3)
Block(-13,35,-4,18:3)
Block(-13,35,-2,18:3)
Block(-13,35,0,18:3)
Block(-13,35,3,18:3)
Block(-13,35,6,18:3)
Block(-13,35,7,18:3)
Block(-13,35,10,18:3)
Block(-13,35,12,18:3)
Block(-13,35,13,17:7)
Block(-13,35,15,18:3)
Block(-13,35,16,17:7)
Block(-13,35,18,18:3)
Block(-13,35,19,18:3)
Block(-13,35,20,18:3)
Block(-13,35,21,18:3)
Block(-13,36,-20,18:3)
Block(-13,36,-17,18:3)
Block(-13,36,-16,18:3)
Block(-13,36,-13,17:11)
Block(-13,36,-12,18:3)
Block(-13,36,-11,18:3)
Block(-13,36,-10,18:3)
Block(-13,36,-9,18:3)
Block(-13,36,-8,18:3)
Block(-13,36,-6,18:3)
Block(-13,36,-5,18:3)
Block(-13,36,-3,18:3)
Block(-13,36,-2,18:3)
Block(-13,36,-1,18:3)
Block(-13,36,0,17:7)
Block(-13,36,3,18:3)
Block(-13,36,5,18:3)
Block(-13,36,6,18:3)
Block(-13,36,7,18:3)
Block(-13,36,8,18:3)
Block(-13,36,10,18:3)
Block(-13,36,11,18:3)
Block(-13,36,13,17:7)
Block(-13,36,15,18:3)
Block(-13,36,16,18:3)
Block(-13,36,17,18:3)
Block(-13,36,18,18:3)
Block(-13,36,19,18:3)
Block(-13,36,20,18:3)
Block(-13,36,21,18:3)
Block(-13,37,-20,18:3)
Block(-13,37,-18,18:3)
Block(-13,37,-14,18:3)
Block(-13,37,-13,18:3)
Block(-13,37,-12,18:3)
Block(-13,37,-11,18:3)
Block(-13,37,-10,18:3)
Block(-13,37,-8,17:11)
Block(-13,37,-7,18:3)
Block(-13,37,-6,18:3)
Block(-13,37,-5,17:11)
Block(-13,37,-4,17:11)
Block(-13,37,-3,17:11)
Block(-13,37,-2,17:11)
Block(-13,37,-1,17:11)
Block(-13,37,0,17:7)
Block(-13,37,1,17:11)
Block(-13,37,2,17:11)
Block(-13,37,3,17:11)
Block(-13,37,4,17:11)
Block(-13,37,5,17:11)
Block(-13,37,6,18:3)
Block(-13,37,7,18:3)
Block(-13,37,8,17:11)
Block(-13,37,9,18:3)
Block(-13,37,11,18:3)
Block(-13,37,13,18:3)
Block(-13,37,15,18:3)
Block(-13,37,17,18:3)
Block(-13,37,18,18:3)
Block(-13,37,20,18:3)
Block(-13,38,-12,18:3)
Block(-13,38,-11,18:3)
Block(-13,38,-10,18:3)
Block(-13,38,-8,18:3)
Block(-13,38,-7,18:3)
Block(-13,38,-6,18:3)
Block(-13,38,-4,18:3)
Block(-13,38,-3,18:3)
Block(-13,38,-2,18:3)
Block(-13,38,-1,18:3)
Block(-13,38,0,18:3)
Block(-13,38,1,18:3)
Block(-13,38,2,18:3)
Block(-13,38,3,18:3)
Block(-13,38,4,18:3)
Block(-13,38,5,18:3)
Block(-13,38,6,18:3)
Block(-13,38,7,18:3)
Block(-13,38,8,18:3)
Block(-13,38,9,18:3)
Block(-13,38,11,18:3)
Block(-13,38,13,18:3)
Block(-13,39,-13,18:3)
Block(-13,39,-11,18:3)
Block(-13,39,-9,18:3)
Block(-13,39,-7,18:3)
Block(-13,39,-5,18:3)
Block(-13,39,-4,18:3)
Block(-13,39,-3,18:3)
Block(-13,39,-1,18:3)
Block(-13,39,0,18:3)
Block(-13,39,2,18:3)
Block(-13,39,3,18:3)
Block(-13,39,4,18:3)
Block(-13,39,6,18:3)
Block(-13,39,7,18:3)
Block(-13,39,8,18:3)
Block(-13,39,9,18:3)
Block(-13,39,10,18:3)
Block(-13,39,11,18:3)
Block(-13,39,12,18:3)
Block(-13,39,13,18:3)
Block(-13,40,-9,18:3)
Block(-13,40,-8,18:3)
Block(-13,40,-6,18:3)
Block(-13,40,-5,18:3)
Block(-13,40,-4,18:3)
Block(-13,40,-1,18:3)
Block(-13,40,0,18:3)
Block(-13,40,4,18:3)
Block(-13,40,5,18:3)
Block(-13,40,6,18:3)
Block(-13,40,8,18:3)
Block(-12,0,-11,17:3)
Block(-12,0,-10,17:3)
Block(-12,0,-5,17:3)
Block(-12,0,-4,17:3)
Block(-12,0,-3,17:3)
Block(-12,0,-2,17:3)
Block(-12,0,-1,17:3)
Block(-12,0,0,17:3)
Block(-12,0,1,17:3)
Block(-12,0,2,17:3)
Block(-12,0,3,17:3)
Block(-12,0,4,17:3)
Block(-12,0,5,17:3)
Block(-12,0,6,17:3)
Block(-12,0,8,17:3)
Block(-12,0,9,17:3)
Block(-12,0,10,17:3)
Block(-12,0,11,17:3)
Block(-12,1,-2,17:3)
Block(-12,1,1,17:3)
Block(-12,1,2,17:3)
Block(-12,1,3,17:3)
Block(-12,30,-20,18:3)
Block(-12,30,19,18:3)
Block(-12,30,20,18:3)
Block(-12,30,21,18:3)
Block(-12,31,-22,18:3)
Block(-12,31,-20,18:3)
Block(-12,31,-19,18:3)
Block(-12,31,-18,18:3)
Block(-12,31,18,18:3)
Block(-12,31,20,18:3)
Block(-12,32,-20,18:3)
Block(-12,32,-18,18:3)
Block(-12,32,-2,106:1)
Block(-12,32,17,18:3)
Block(-12,32,20,18:3)
Block(-12,32,21,18:3)
Block(-12,32,22,18:3)
Block(-12,32,23,18:3)
Block(-12,33,-20,18:3)
Block(-12,33,-18,18:3)
Block(-12,33,-17,18:3)
Block(-12,33,-2,106:1)
Block(-12,33,17,18:3)
Block(-12,33,18,18:3)
Block(-12,33,19,18:3)
Block(-12,33,22,18:3)
Block(-12,34,-22,18:3)
Block(-12,34,-20,18:3)
Block(-12,34,-19,18:3)
Block(-12,34,-18,18:3)
Block(-12,34,-17,18:3)
Block(-12,34,-16,18:3)
Block(-12,34,-2,106:1)
Block(-12,34,-1,18:3)
Block(-12,34,4,18:3)
Block(-12,34,5,18:3)
Block(-12,34,10,18:3)
Block(-12,34,15,18:3)
Block(-12,34,16,18:3)
Block(-12,34,17,18:3)
Block(-12,34,18,18:3)
Block(-12,34,23,18:3)
Block(-12,35,-22,18:3)
Block(-12,35,-21,18:3)
Block(-12,35,-20,18:3)
Block(-12,35,-18,18:3)
Block(-12,35,-17,17:7)
Block(-12,35,-16,18:3)
Block(-12,35,-15,18:3)
Block(-12,35,-13,18:3)
Block(-12,35,-11,18:3)
Block(-12,35,-10,18:3)
Block(-12,35,-8,18:3)
Block(-12,35,-7,18:3)
Block(-12,35,-6,18:3)
Block(-12,35,-5,18:3)
Block(-12,35,-2,18:3)
Block(-12,35,0,18:3)
Block(-12,35,4,18:3)
Block(-12,35,5,18:3)
Block(-12,35,6,18:3)
Block(-12,35,7,18:3)
Block(-12,35,10,18:3)
Block(-12,35,13,18:3)
Block(-12,35,14,18:3)
Block(-12,35,15,18:3)
Block(-12,35,16,18:3)
Block(-12,35,17,17:7)
Block(-12,35,18,18:3)
Block(-12,35,19,18:3)
Block(-12,35,20,18:3)
Block(-12,35,21,18:3)
Block(-12,36,-20,18:3)
Block(-12,36,-16,18:3)
Block(-12,36,-15,18:3)
Block(-12,36,-14,18:3)
Block(-12,36,-12,17:11)
Block(-12,36,-10,18:3)
Block(-12,36,-9,18:3)
Block(-12,36,-7,18:3)
Block(-12,36,-6,18:3)
Block(-12,36,-5,106:2)
Block(-12,36,-2,18:3)
Block(-12,36,-1,18:3)
Block(-12,36,0,18:3)
Block(-12,36,4,18:3)
Block(-12,36,5,18:3)
Block(-12,36,7,18:3)
Block(-12,36,8,18:3)
Block(-12,36,9,18:3)
Block(-12,36,11,18:3)
Block(-12,36,12,17:7)
Block(-12,36,14,18:3)
Block(-12,36,15,18:3)
Block(-12,36,16,18:3)
Block(-12,36,17,18:3)
Block(-12,36,18,18:3)
Block(-12,36,20,18:3)
Block(-12,36,21,18:3)
Block(-12,36,22,18:3)
Block(-12,37,-18,18:3)
Block(-12,37,-17,18:3)
Block(-12,37,-14,18:3)
Block(-12,37,-13,18:3)
Block(-12,37,-12,17:11)
Block(-12,37,-11,18:3)
Block(-12,37,-10,18:3)
Block(-12,37,-9,17:11)
Block(-12,37,-8,18:3)
Block(-12,37,-6,18:3)
Block(-12,37,-5,18:3)
Block(-12,37,-4,18:3)
Block(-12,37,-3,18:3)
Block(-12,37,-2,18:3)
Block(-12,37,-1,18:3)
Block(-12,37,0,17:7)
Block(-12,37,1,18:3)
Block(-12,37,3,18:3)
Block(-12,37,4,18:3)
Block(-12,37,5,18:3)
Block(-12,37,6,18:3)
Block(-12,37,7,18:3)
Block(-12,37,8,18:3)
Block(-12,37,9,17:11)
Block(-12,37,10,18:3)
Block(-12,37,11,18:3)
Block(-12,37,12,17:7)
Block(-12,37,13,18:3)
Block(-12,37,17,18:3)
Block(-12,37,19,18:3)
Block(-12,38,-12,18:3)
Block(-12,38,-10,18:3)
Block(-12,38,-7,18:3)
Block(-12,38,-6,18:3)
Block(-12,38,-3,18:3)
Block(-12,38,-1,17:7)
Block(-12,38,0,17:7)
Block(-12,38,1,17:7)
Block(-12,38,3,18:3)
Block(-12,38,5,18:3)
Block(-12,38,6,18:3)
Block(-12,38,8,18:3)
Block(-12,38,9,18:3)
Block(-12,38,11,18:3)
Block(-12,38,12,18:3)
Block(-12,38,17,18:3)
Block(-12,39,-11,18:3)
Block(-12,39,-10,18:3)
Block(-12,39,-8,18:3)
Block(-12,39,-7,18:3)
Block(-12,39,-6,18:3)
Block(-12,39,-5,18:3)
Block(-12,39,-1,18:3)
Block(-12,39,2,18:3)
Block(-12,39,3,18:3)
Block(-12,39,6,18:3)
Block(-12,39,7,18:3)
Block(-12,39,10,18:3)
Block(-12,39,11,18:3)
Block(-12,39,13,18:3)
Block(-12,40,-8,18:3)
Block(-12,40,-6,18:3)
Block(-12,40,-5,18:3)
Block(-12,40,-4,18:3)
Block(-12,40,0,18:3)
Block(-12,40,4,18:3)
Block(-12,40,10,18:3)
Block(-12,40,12,18:3)
Block(-11,0,-12,17:3)
Block(-11,0,-11,17:3)
Block(-11,0,-10,17:3)
Block(-11,0,-9,17:3)
Block(-11,0,-4,17:3)
Block(-11,0,-2,17:3)
Block(-11,0,-1,17:3)
Block(-11,0,0,17:3)
Block(-11,0,1,17:3)
Block(-11,0,2,17:3)
Block(-11,0,3,17:3)
Block(-11,0,4,17:3)
Block(-11,0,5,17:3)
Block(-11,0,6,17:3)
Block(-11,0,8,17:3)
Block(-11,0,9,17:3)
Block(-11,0,10,17:3)
Block(-11,0,11,17:3)
Block(-11,1,-10,17:3)
Block(-11,1,1,17:3)
Block(-11,1,2,17:3)
Block(-11,1,3,17:3)
Block(-11,1,5,17:3)
Block(-11,1,9,17:3)
Block(-11,2,2,17:3)
Block(-11,31,-20,18:3)
Block(-11,31,-18,18:3)
Block(-11,31,-2,106:2)
Block(-11,31,20,18:3)
Block(-11,31,22,18:3)
Block(-11,32,-22,18:3)
Block(-11,32,-21,18:3)
Block(-11,32,-19,18:3)
Block(-11,32,-18,18:3)
Block(-11,32,-4,106:4)
Block(-11,32,-2,106:2)
Block(-11,32,4,106:2)
Block(-11,32,18,18:3)
Block(-11,33,-20,18:3)
Block(-11,33,-19,18:3)
Block(-11,33,-18,18:3)
Block(-11,33,-17,18:3)
Block(-11,33,-16,18:3)
Block(-11,33,-4,106:4)
Block(-11,33,-2,106:2)
Block(-11,33,4,106:2)
Block(-11,33,18,18:3)
Block(-11,33,19,18:3)
Block(-11,33,20,18:3)
Block(-11,34,-22,18:3)
Block(-11,34,-21,18:3)
Block(-11,34,-20,18:3)
Block(-11,34,-19,18:3)
Block(-11,34,-18,18:3)
Block(-11,34,-17,18:3)
Block(-11,34,-16,18:3)
Block(-11,34,-15,18:3)
Block(-11,34,-12,18:3)
Block(-11,34,-11,18:3)
Block(-11,34,-4,106:4)
Block(-11,34,-2,106:2)
Block(-11,34,4,106:2)
Block(-11,34,10,18:3)
Block(-11,34,15,18:3)
Block(-11,34,18,18:3)
Block(-11,34,19,18:3)
Block(-11,34,20,18:3)
Block(-11,34,21,18:3)
Block(-11,35,-22,18:3)
Block(-11,35,-21,18:3)
Block(-11,35,-19,18:3)
Block(-11,35,-18,17:7)
Block(-11,35,-17,18:3)
Block(-11,35,-16,18:3)
Block(-11,35,-15,18:3)
Block(-11,35,-13,18:3)
Block(-11,35,-12,18:3)
Block(-11,35,-11,18:3)
Block(-11,35,-10,18:3)
Block(-11,35,-9,18:3)
Block(-11,35,-5,18:3)
Block(-11,35,-4,106:4)
Block(-11,35,-2,106:2)
Block(-11,35,-1,18:3)
Block(-11,35,0,18:3)
Block(-11,35,5,18:3)
Block(-11,35,10,18:3)
Block(-11,35,11,18:3)
Block(-11,35,12,18:3)
Block(-11,35,15,18:3)
Block(-11,35,16,18:3)
Block(-11,35,18,17:7)
Block(-11,35,19,18:3)
Block(-11,35,20,18:3)
Block(-11,35,21,18:3)
Block(-11,36,-21,18:3)
Block(-11,36,-20,18:3)
Block(-11,36,-19,18:3)
Block(-11,36,-18,18:3)
Block(-11,36,-16,18:3)
Block(-11,36,-14,18:3)
Block(-11,36,-13,18:3)
Block(-11,36,-12,18:3)
Block(-11,36,-11,17:11)
Block(-11,36,-10,18:3)
Block(-11,36,-9,18:3)
Block(-11,36,-8,18:3)
Block(-11,36,0,18:3)
Block(-11,36,1,18:3)
Block(-11,36,5,18:3)
Block(-11,36,7,18:3)
Block(-11,36,11,17:7)
Block(-11,36,12,18:3)
Block(-11,36,13,18:3)
Block(-11,36,14,18:3)
Block(-11,36,16,18:3)
Block(-11,36,18,18:3)
Block(-11,36,19,18:3)
Block(-11,36,20,18:3)
Block(-11,36,21,18:3)
Block(-11,37,-19,18:3)
Block(-11,37,-18,18:3)
Block(-11,37,-14,18:3)
Block(-11,37,-13,18:3)
Block(-11,37,-12,18:3)
Block(-11,37,-11,17:11)
Block(-11,37,-10,17:11)
Block(-11,37,-9,18:3)
Block(-11,37,-8,18:3)
Block(-11,37,-7,18:3)
Block(-11,37,-5,18:3)
Block(-11,37,-4,18:3)
Block(-11,37,-3,18:3)
Block(-11,37,-2,18:3)
Block(-11,37,-1,18:3)
Block(-11,37,0,17:7)
Block(-11,37,1,18:3)
Block(-11,37,2,18:3)
Block(-11,37,4,18:3)
Block(-11,37,6,18:3)
Block(-11,37,7,18:3)
Block(-11,37,8,18:3)
Block(-11,37,9,18:3)
Block(-11,37,10,17:11)
Block(-11,37,11,17:7)
Block(-11,37,12,18:3)
Block(-11,37,13,18:3)
Block(-11,37,14,18:3)
Block(-11,37,16,18:3)
Block(-11,37,17,18:3)
Block(-11,37,18,18:3)
Block(-11,38,-18,18:3)
Block(-11,38,-14,18:3)
Block(-11,38,-13,18:3)
Block(-11,38,-12,18:3)
Block(-11,38,-10,18:3)
Block(-11,38,-9,18:3)
Block(-11,38,-8,18:3)
Block(-11,38,-7,18:3)
Block(-11,38,-5,18:3)
Block(-11,38,-4,18:3)
Block(-11,38,-2,18:3)
Block(-11,38,-1,17:7)
Block(-11,38,0,17:7)
Block(-11,38,1,17:7)
Block(-11,38,6,18:3)
Block(-11,38,8,18:3)
Block(-11,38,9,18:3)
Block(-11,38,10,18:3)
Block(-11,38,11,18:3)
Block(-11,38,12,18:3)
Block(-11,38,13,18:3)
Block(-11,38,14,18:3)
Block(-11,38,17,18:3)
Block(-11,38,18,18:3)
Block(-11,39,-13,18:3)
Block(-11,39,-11,18:3)
Block(-11,39,-10,18:3)
Block(-11,39,-9,18:3)
Block(-11,39,-6,18:3)
Block(-11,39,-5,18:3)
Block(-11,39,-1,18:3)
Block(-11,39,0,18:3)
Block(-11,39,7,18:3)
Block(-11,39,8,18:3)
Block(-11,39,9,18:3)
Block(-11,39,10,18:3)
Block(-11,39,11,18:3)
Block(-11,39,12,18:3)
Block(-11,40,-12,18:3)
Block(-11,40,-11,18:3)
Block(-11,40,-10,18:3)
Block(-11,40,10,18:3)
Block(-11,40,11,18:3)
Block(-10,0,-14,17:3)
Block(-10,0,-13,17:3)
Block(-10,0,-12,17:3)
Block(-10,0,-11,17:3)
Block(-10,0,-10,17:3)
Block(-10,0,-9,17:3)
Block(-10,0,-8,17:3)
Block(-10,0,-7,17:3)
Block(-10,0,-3,17:3)
Block(-10,0,-2,17:3)
Block(-10,0,-1,17:3)
Block(-10,0,0,17:3)
Block(-10,0,1,17:3)
Block(-10,0,2,17:3)
Block(-10,0,3,17:3)
Block(-10,0,4,17:3)
Block(-10,0,5,17:3)
Block(-10,0,6,17:3)
Block(-10,0,7,17:3)
Block(-10,0,8,17:3)
Block(-10,0,9,17:3)
Block(-10,0,10,17:3)
Block(-10,0,11,17:3)
Block(-10,0,12,17:3)
Block(-10,1,-11,17:3)
Block(-10,1,-10,17:3)
Block(-10,1,-9,17:3)
Block(-10,1,-2,17:3)
Block(-10,1,-1,17:3)
Block(-10,1,0,17:3)
Block(-10,1,1,17:3)
Block(-10,1,2,17:3)
Block(-10,1,3,17:3)
Block(-10,1,4,17:3)
Block(-10,1,5,17:3)
Block(-10,1,6,17:3)
Block(-10,1,8,17:3)
Block(-10,1,9,17:3)
Block(-10,1,10,17:3)
Block(-10,2,1,17:3)
Block(-10,2,2,17:3)
Block(-10,2,3,17:3)
Block(-10,14,-1,106:8)
Block(-10,15,-1,106:8)
Block(-10,16,-1,106:8)
Block(-10,16,1,106:8)
Block(-10,17,-1,106:8)
Block(-10,17,1,106:8)
Block(-10,18,-1,106:8)
Block(-10,18,1,106:8)
Block(-10,19,-1,106:8)
Block(-10,19,1,106:8)
Block(-10,20,-1,106:8)
Block(-10,20,1,106:8)
Block(-10,21,-1,106:8)
Block(-10,21,1,106:8)
Block(-10,22,1,106:8)
Block(-10,23,1,106:8)
Block(-10,32,-21,18:3)
Block(-10,32,-20,18:3)
Block(-10,32,5,106:2)
Block(-10,32,6,106:2)
Block(-10,32,18,18:3)
Block(-10,32,20,18:3)
Block(-10,33,-21,18:3)
Block(-10,33,-20,18:3)
Block(-10,33,-19,18:3)
Block(-10,33,-18,18:3)
Block(-10,33,-16,18:3)
Block(-10,33,5,106:2)
Block(-10,33,6,106:2)
Block(-10,33,16,18:3)
Block(-10,33,18,18:3)
Block(-10,33,19,18:3)
Block(-10,33,20,18:3)
Block(-10,33,21,18:3)
Block(-10,34,-21,18:3)
Block(-10,34,-20,18:3)
Block(-10,34,-19,18:3)
Block(-10,34,-18,18:3)
Block(-10,34,-12,18:3)
Block(-10,34,-10,18:3)
Block(-10,34,5,106:2)
Block(-10,34,6,106:2)
Block(-10,34,10,18:3)
Block(-10,34,11,18:3)
Block(-10,34,18,18:3)
Block(-10,34,19,18:3)
Block(-10,35,-21,18:3)
Block(-10,35,-18,18:3)
Block(-10,35,-15,18:3)
Block(-10,35,-13,18:3)
Block(-10,35,-12,18:3)
Block(-10,35,-11,18:3)
Block(-10,35,-10,18:3)
Block(-10,35,-9,18:3)
Block(-10,35,5,106:2)
Block(-10,35,6,106)
Block(-10,35,9,18:3)
Block(-10,35,11,18:3)
Block(-10,35,16,18:3)
Block(-10,35,17,18:3)
Block(-10,35,18,18:3)
Block(-10,36,-21,18:3)
Block(-10,36,-19,18:3)
Block(-10,36,-18,18:3)
Block(-10,36,-14,18:3)
Block(-10,36,-13,18:3)
Block(-10,36,-11,18:3)
Block(-10,36,-10,17:11)
Block(-10,36,-8,18:3)
Block(-10,36,-7,18:3)
Block(-10,36,0,18:3)
Block(-10,36,1,18:3)
Block(-10,36,5,18:3)
Block(-10,36,6,18:3)
Block(-10,36,7,18:3)
Block(-10,36,8,18:3)
Block(-10,36,9,18:3)
Block(-10,36,10,17:7)
Block(-10,36,13,18:3)
Block(-10,36,14,18:3)
Block(-10,36,18,18:3)
Block(-10,37,-19,18:3)
Block(-10,37,-18,18:3)
Block(-10,37,-14,18:3)
Block(-10,37,-13,18:3)
Block(-10,37,-12,18:3)
Block(-10,37,-11,17:7)
Block(-10,37,-10,17:11)
Block(-10,37,-8,18:3)
Block(-10,37,-7,18:3)
Block(-10,37,-6,18:3)
Block(-10,37,-5,18:3)
Block(-10,37,-4,18:3)
Block(-10,37,-1,18:3)
Block(-10,37,0,17:7)
Block(-10,37,4,18:3)
Block(-10,37,5,18:3)
Block(-10,37,7,18:3)
Block(-10,37,8,18:3)
Block(-10,37,9,18:3)
Block(-10,37,10,17:7)
Block(-10,37,11,17:7)
Block(-10,37,12,18:3)
Block(-10,37,13,18:3)
Block(-10,37,14,18:3)
Block(-10,37,15,18:3)
Block(-10,37,17,18:3)
Block(-10,37,18,18:3)
Block(-10,38,-19,18:3)
Block(-10,38,-17,18:3)
Block(-10,38,-11,18:3)
Block(-10,38,-8,18:3)
Block(-10,38,-7,18:3)
Block(-10,38,-6,18:3)
Block(-10,38,-5,18:3)
Block(-10,38,-4,18:3)
Block(-10,38,-2,18:3)
Block(-10,38,-1,17:7)
Block(-10,38,0,17:7)
Block(-10,38,1,17:7)
Block(-10,38,4,18:3)
Block(-10,38,6,18:3)
Block(-10,38,7,18:3)
Block(-10,38,8,18:3)
Block(-10,38,11,18:3)
Block(-10,38,14,18:3)
Block(-10,38,15,18:3)
Block(-10,38,17,18:3)
Block(-10,38,18,18:3)
Block(-10,38,19,18:3)
Block(-10,39,-14,18:3)
Block(-10,39,-13,18:3)
Block(-10,39,-12,18:3)
Block(-10,39,-7,18:3)
Block(-10,39,-1,18:3)
Block(-10,39,7,18:3)
Block(-10,39,11,18:3)
Block(-10,39,13,18:3)
Block(-10,40,1,18:3)
Block(-10,40,12,18:3)
Block(-9,0,-16,17:3)
Block(-9,0,-15,17:3)
Block(-9,0,-14,17:3)
Block(-9,0,-13,17:3)
Block(-9,0,-12,17:3)
Block(-9,0,-11,17:3)
Block(-9,0,-10,17:3)
Block(-9,0,-9,17:3)
Block(-9,0,-8,17:3)
Block(-9,0,-7,17:3)
Block(-9,0,-6,17:3)
Block(-9,0,-5,17:3)
Block(-9,0,-4,17:3)
Block(-9,0,-3,17:3)
Block(-9,0,-2,17:3)
Block(-9,0,-1,17:3)
Block(-9,0,0,17:3)
Block(-9,0,1,17:3)
Block(-9,0,2,17:3)
Block(-9,0,3,17:3)
Block(-9,0,4,17:3)
Block(-9,0,5,17:3)
Block(-9,0,6,17:3)
Block(-9,0,7,17:3)
Block(-9,0,8,17:3)
Block(-9,0,9,17:3)
Block(-9,0,10,17:3)
Block(-9,0,11,17:3)
Block(-9,0,16,17:3)
Block(-9,1,-10,17:3)
Block(-9,1,-9,17:3)
Block(-9,1,-8,17:3)
Block(-9,1,-7,17:3)
Block(-9,1,-3,17:3)
Block(-9,1,-2,17:3)
Block(-9,1,-1,17:3)
Block(-9,1,0,17:3)
Block(-9,1,1,17:3)
Block(-9,1,2,17:3)
Block(-9,1,3,17:3)
Block(-9,1,4,17:3)
Block(-9,1,5,17:3)
Block(-9,1,6,17:3)
Block(-9,1,7,17:3)
Block(-9,1,8,17:3)
Block(-9,1,9,17:3)
Block(-9,2,-2,17:3)
Block(-9,2,-1,17:3)
Block(-9,2,0,17:3)
Block(-9,2,1,17:3)
Block(-9,2,2,17:3)
Block(-9,2,5,17:3)
Block(-9,14,-2,106:1)
Block(-9,15,-2,106:1)
Block(-9,16,-2,106:1)
Block(-9,17,-2,106:1)
Block(-9,18,-2,106:1)
Block(-9,19,-2,106:1)
Block(-9,20,-2,106:1)
Block(-9,21,-2,106:1)
Block(-9,21,-1,18:3)
Block(-9,22,-1,106:8)
Block(-9,22,0,18:3)
Block(-9,22,1,18:3)
Block(-9,23,0,106:1)
Block(-9,23,1,18:3)
Block(-9,25,-12,106:4)
Block(-9,26,-12,106:4)
Block(-9,27,-12,106:4)
Block(-9,27,-7,18:1)
Block(-9,28,-12,106:4)
Block(-9,28,-7,106:8)
Block(-9,29,-12,106:4)
Block(-9,29,-7,106:8)
Block(-9,29,-1,106:1)
Block(-9,30,-12,106:4)
Block(-9,30,-7,106:8)
Block(-9,30,-1,106:1)
Block(-9,30,2,106:4)
Block(-9,31,-12,106:4)
Block(-9,31,-10,106:2)
Block(-9,31,-7,106:8)
Block(-9,31,-1,106:1)
Block(-9,31,2,106:4)
Block(-9,32,-12,106:4)
Block(-9,32,-10,106:2)
Block(-9,32,-7,106:8)
Block(-9,32,-1,106:1)
Block(-9,32,2,106:4)
Block(-9,33,-19,18:3)
Block(-9,33,-18,18:3)
Block(-9,33,-17,18:3)
Block(-9,33,-12,106:4)
Block(-9,33,-10,106:2)
Block(-9,33,-7,106:8)
Block(-9,33,-1,106:1)
Block(-9,33,2,106:4)
Block(-9,33,18,18:3)
Block(-9,34,-21,18:3)
Block(-9,34,-18,18:3)
Block(-9,34,-13,18:3)
Block(-9,34,-12,106:4)
Block(-9,34,-10,106:2)
Block(-9,34,-7,106:8)
Block(-9,34,-1,106:1)
Block(-9,34,2,106:4)
Block(-9,34,18,18:3)
Block(-9,34,20,18:3)
Block(-9,35,-19,18:3)
Block(-9,35,-18,18:3)
Block(-9,35,-17,18:3)
Block(-9,35,-16,18:3)
Block(-9,35,-15,18:3)
Block(-9,35,-12,18:3)
Block(-9,35,-10,18:3)
Block(-9,35,-7,106:8)
Block(-9,35,-1,106:1)
Block(-9,35,0,18:3)
Block(-9,35,2,106:4)
Block(-9,35,11,18:3)
Block(-9,35,16,18:3)
Block(-9,35,17,18:3)
Block(-9,35,20,18:3)
Block(-9,36,-19,18:3)
Block(-9,36,-16,18:3)
Block(-9,36,-12,18:3)
Block(-9,36,-10,18:3)
Block(-9,36,-9,17:11)
Block(-9,36,-7,18:3)
Block(-9,36,-2,18:3)
Block(-9,36,-1,106:1)
Block(-9,36,0,18:3)
Block(-9,36,1,18:3)
Block(-9,36,2,106:4)
Block(-9,36,7,18:3)
Block(-9,36,9,17:7)
Block(-9,36,10,18:3)
Block(-9,36,11,18:3)
Block(-9,36,12,18:3)
Block(-9,36,13,18:3)
Block(-9,36,18,18:3)
Block(-9,36,20,18:3)
Block(-9,37,-19,18:3)
Block(-9,37,-18,18:3)
Block(-9,37,-17,18:3)
Block(-9,37,-15,18:3)
Block(-9,37,-14,18:3)
Block(-9,37,-13,18:3)
Block(-9,37,-12,17:7)
Block(-9,37,-11,18:3)
Block(-9,37,-10,18:3)
Block(-9,37,-9,17:11)
Block(-9,37,-7,18:3)
Block(-9,37,-3,18:3)
Block(-9,37,0,17:7)
Block(-9,37,8,18:3)
Block(-9,37,9,17:7)
Block(-9,37,10,18:3)
Block(-9,37,11,18:3)
Block(-9,37,12,17:7)
Block(-9,37,13,18:3)
Block(-9,37,14,18:3)
Block(-9,37,15,18:3)
Block(-9,37,16,18:3)
Block(-9,37,19,18:3)
Block(-9,38,-13,18:3)
Block(-9,38,-12,18:3)
Block(-9,38,-11,18:3)
Block(-9,38,-8,18:3)
Block(-9,38,-7,18:3)
Block(-9,38,-3,18:3)
Block(-9,38,-2,18:3)
Block(-9,38,-1,17:7)
Block(-9,38,0,17:7)
Block(-9,38,1,17:7)
Block(-9,38,2,18:3)
Block(-9,38,3,18:3)
Block(-9,38,7,18:3)
Block(-9,38,8,18:3)
Block(-9,38,9,18:3)
Block(-9,38,10,18:3)
Block(-9,38,11,18:3)
Block(-9,38,12,18:3)
Block(-9,38,13,18:3)
Block(-9,38,16,18:3)
Block(-9,39,-15,18:3)
Block(-9,39,-13,18:3)
Block(-9,39,-12,18:3)
Block(-9,39,-11,18:3)
Block(-9,39,-9,18:3)
Block(-9,39,-7,18:3)
Block(-9,39,0,18:3)
Block(-9,39,1,18:3)
Block(-9,39,2,18:3)
Block(-9,39,3,18:3)
Block(-9,39,5,18:3)
Block(-9,39,6,18:3)
Block(-9,39,7,18:3)
Block(-9,39,9,18:3)
Block(-9,39,10,18:3)
Block(-9,39,13,18:3)
Block(-9,40,-14,18:3)
Block(-9,40,-6,18:3)
Block(-9,40,-5,18:3)
Block(-9,40,-2,18:3)
Block(-9,40,0,18:3)
Block(-9,40,2,18:3)
Block(-9,40,6,18:3)
Block(-9,40,13,18:3)
Block(-9,41,-1,18:3)
Block(-8,0,-17,17:3)
Block(-8,0,-16,17:3)
Block(-8,0,-15,17:3)
Block(-8,0,-14,17:3)
Block(-8,0,-13,17:3)
Block(-8,0,-12,17:3)
Block(-8,0,-11,17:3)
Block(-8,0,-10,17:3)
Block(-8,0,-9,17:3)
Block(-8,0,-8,17:3)
Block(-8,0,-7,17:3)
Block(-8,0,-6,17:3)
Block(-8,0,-5,17:3)
Block(-8,0,-4,17:3)
Block(-8,0,-3,17:3)
Block(-8,0,-2,17:3)
Block(-8,0,-1,17:3)
Block(-8,0,0,17:3)
Block(-8,0,1,17:3)
Block(-8,0,2,17:3)
Block(-8,0,3,17:3)
Block(-8,0,4,17:3)
Block(-8,0,5,17:3)
Block(-8,0,6,17:3)
Block(-8,0,7,17:3)
Block(-8,0,8,17:3)
Block(-8,0,9,17:3)
Block(-8,0,10,17:3)
Block(-8,0,15,17:3)
Block(-8,0,16,17:3)
Block(-8,0,17,17:3)
Block(-8,1,-9,17:3)
Block(-8,1,-8,17:3)
Block(-8,1,-7,17:3)
Block(-8,1,-6,17:3)
Block(-8,1,-5,17:3)
Block(-8,1,-4,17:3)
Block(-8,1,-3,17:3)
Block(-8,1,-2,17:3)
Block(-8,1,-1,17:3)
Block(-8,1,0,17:3)
Block(-8,1,1,17:3)
Block(-8,1,2,17:3)
Block(-8,1,3,17:3)
Block(-8,1,4,17:3)
Block(-8,1,5,17:3)
Block(-8,1,6,17:3)
Block(-8,1,7,17:3)
Block(-8,1,8,17:3)
Block(-8,1,9,17:3)
Block(-8,2,-8,17:3)
Block(-8,2,-7,17:3)
Block(-8,2,-2,17:3)
Block(-8,2,-1,17:3)
Block(-8,2,0,17:3)
Block(-8,2,1,17:3)
Block(-8,2,2,17:3)
Block(-8,2,4,17:3)
Block(-8,2,5,17:3)
Block(-8,2,6,17:3)
Block(-8,2,7,17:3)
Block(-8,2,8,17:3)
Block(-8,3,-1,17:3)
Block(-8,3,0,17:3)
Block(-8,3,1,17:3)
Block(-8,16,6,106:8)
Block(-8,17,6,106:8)
Block(-8,18,4,106:8)
Block(-8,18,6,106:8)
Block(-8,19,4,106:8)
Block(-8,19,6,106:8)
Block(-8,20,4,106:8)
Block(-8,20,6,106:8)
Block(-8,21,-2,18:3)
Block(-8,21,0,18:3)
Block(-8,21,4,106:8)
Block(-8,21,5,18:3)
Block(-8,21,6,106:8)
Block(-8,22,-4,106:8)
Block(-8,22,-2,18:3)
Block(-8,22,-1,18:3)
Block(-8,22,0,18:3)
Block(-8,22,2,18:3)
Block(-8,22,5,18:3)
Block(-8,23,-1,18:3)
Block(-8,23,0,18:3)
Block(-8,24,0,18:3)
Block(-8,24,1,18:3)
Block(-8,25,9,18:1)
Block(-8,26,-7,18:3)
Block(-8,26,9,106:8)
Block(-8,27,-8,18:1)
Block(-8,27,-7,17:3)
Block(-8,27,-6,18:1)
Block(-8,27,9,106:8)
Block(-8,28,-8,106:1)
Block(-8,28,-7,18:3)
Block(-8,28,-6,106:4)
Block(-8,28,9,106:8)
Block(-8,29,-6,106:4)
Block(-8,29,9,106:8)
Block(-8,30,-8,106:1)
Block(-8,30,-6,106:4)
Block(-8,30,9,106:8)
Block(-8,31,-8,106:1)
Block(-8,31,-6,106:4)
Block(-8,31,9,106:8)
Block(-8,32,-8,106:1)
Block(-8,32,-6,106:4)
Block(-8,32,6,106:8)
Block(-8,32,9,106:8)
Block(-8,33,-25,18:3)
Block(-8,33,-8,106:1)
Block(-8,33,-6,106:4)
Block(-8,33,6,106:8)
Block(-8,33,9,106:8)
Block(-8,34,-22,18:3)
Block(-8,34,-21,18:3)
Block(-8,34,-20,18:3)
Block(-8,34,-18,18:3)
Block(-8,34,-13,18:3)
Block(-8,34,-12,18:3)
Block(-8,34,-8,106:1)
Block(-8,34,-6,106:4)
Block(-8,34,6,106:8)
Block(-8,34,9,106:8)
Block(-8,34,12,18:3)
Block(-8,35,-22,18:3)
Block(-8,35,-21,18:3)
Block(-8,35,-20,18:3)
Block(-8,35,-19,18:3)
Block(-8,35,-18,18:3)
Block(-8,35,-17,18:3)
Block(-8,35,-15,18:3)
Block(-8,35,-14,18:3)
Block(-8,35,-13,18:3)
Block(-8,35,-8,106:1)
Block(-8,35,-7,18:3)
Block(-8,35,-6,106:4)
Block(-8,35,-1,18:3)
Block(-8,35,0,18:3)
Block(-8,35,6,106:8)
Block(-8,35,7,106:8)
Block(-8,35,9,106:8)
Block(-8,35,11,18:3)
Block(-8,35,12,18:3)
Block(-8,35,17,18:3)
Block(-8,35,18,18:3)
Block(-8,35,19,18:3)
Block(-8,35,20,18:3)
Block(-8,35,21,18:3)
Block(-8,36,-18,18:3)
Block(-8,36,-17,18:3)
Block(-8,36,-16,18:3)
Block(-8,36,-14,18:3)
Block(-8,36,-13,18:3)
Block(-8,36,-12,18:3)
Block(-8,36,-11,18:3)
Block(-8,36,-7,18:3)
Block(-8,36,-2,18:3)
Block(-8,36,-1,18:3)
Block(-8,36,0,17:7)
Block(-8,36,1,18:3)
Block(-8,36,2,18:3)
Block(-8,36,10,18:3)
Block(-8,36,11,18:3)
Block(-8,36,12,18:3)
Block(-8,36,13,18:3)
Block(-8,36,17,18:3)
Block(-8,36,18,18:3)
Block(-8,36,19,18:3)
Block(-8,36,21,18:3)
Block(-8,36,22,18:3)
Block(-8,37,-18,18:3)
Block(-8,37,-17,18:3)
Block(-8,37,-16,18:3)
Block(-8,37,-15,18:3)
Block(-8,37,-14,18:3)
Block(-8,37,-13,17:7)
Block(-8,37,-12,18:3)
Block(-8,37,-11,18:3)
Block(-8,37,-10,18:3)
Block(-8,37,-9,18:3)
Block(-8,37,-8,17:11)
Block(-8,37,-7,18:3)
Block(-8,37,-6,18:3)
Block(-8,37,-5,18:3)
Block(-8,37,-3,17:11)
Block(-8,37,-2,17:11)
Block(-8,37,-1,17:11)
Block(-8,37,0,17:7)
Block(-8,37,1,17:11)
Block(-8,37,2,17:11)
Block(-8,37,4,18:3)
Block(-8,37,5,18:3)
Block(-8,37,6,18:3)
Block(-8,37,7,18:3)
Block(-8,37,8,17:7)
Block(-8,37,10,18:3)
Block(-8,37,11,18:3)
Block(-8,37,12,18:3)
Block(-8,37,13,17:7)
Block(-8,37,14,18:3)
Block(-8,37,15,18:3)
Block(-8,37,16,18:3)
Block(-8,38,-16,18:3)
Block(-8,38,-13,18:3)
Block(-8,38,-11,18:3)
Block(-8,38,-10,18:3)
Block(-8,38,-9,18:3)
Block(-8,38,-8,17:11)
Block(-8,38,-7,17:11)
Block(-8,38,-6,18:3)
Block(-8,38,-2,18:3)
Block(-8,38,-1,17:7)
Block(-8,38,0,17:7)
Block(-8,38,1,17:7)
Block(-8,38,2,18:3)
Block(-8,38,3,18:3)
Block(-8,38,6,18:3)
Block(-8,38,7,17:7)
Block(-8,38,8,17:7)
Block(-8,38,10,18:3)
Block(-8,38,11,18:3)
Block(-8,38,12,18:3)
Block(-8,38,13,18:3)
Block(-8,38,15,18:3)
Block(-8,39,-13,18:3)
Block(-8,39,-12,18:3)
Block(-8,39,-9,18:3)
Block(-8,39,-5,18:3)
Block(-8,39,-3,18:3)
Block(-8,39,-2,18:3)
Block(-8,39,0,18:3)
Block(-8,39,2,18:3)
Block(-8,39,3,18:3)
Block(-8,39,7,18:3)
Block(-8,39,10,18:3)
Block(-8,39,11,18:3)
Block(-8,39,12,18:3)
Block(-8,39,13,18:3)
Block(-8,39,14,18:3)
Block(-8,40,-14,18:3)
Block(-8,40,-9,18:3)
Block(-8,40,-8,18:3)
Block(-8,40,-7,18:3)
Block(-8,40,-6,18:3)
Block(-8,40,-5,18:3)
Block(-8,40,1,18:3)
Block(-8,40,2,18:3)
Block(-8,40,7,18:3)
Block(-8,40,12,18:3)
Block(-8,40,13,18:3)
Block(-8,41,-7,18:3)
Block(-8,41,0,18:3)
Block(-8,41,6,18:3)
Block(-8,41,8,18:3)
Block(-7,0,-16,17:3)
Block(-7,0,-14,17:3)
Block(-7,0,-13,17:3)
Block(-7,0,-12,17:3)
Block(-7,0,-11,17:3)
Block(-7,0,-10,17:3)
Block(-7,0,-9,17:3)
Block(-7,0,-8,17:3)
Block(-7,0,-7,17:3)
Block(-7,0,-6,17:3)
Block(-7,0,-5,17:3)
Block(-7,0,-4,17:3)
Block(-7,0,-3,17:3)
Block(-7,0,-2,17:3)
Block(-7,0,-1,17:3)
Block(-7,0,0,17:3)
Block(-7,0,1,17:3)
Block(-7,0,2,17:3)
Block(-7,0,3,17:3)
Block(-7,0,4,17:3)
Block(-7,0,5,17:3)
Block(-7,0,6,17:3)
Block(-7,0,7,17:3)
Block(-7,0,8,17:3)
Block(-7,0,9,17:3)
Block(-7,0,10,17:3)
Block(-7,0,16,17:3)
Block(-7,0,17,17:3)
Block(-7,1,-9,17:3)
Block(-7,1,-8,17:3)
Block(-7,1,-7,17:3)
Block(-7,1,-6,17:3)
Block(-7,1,-5,17:3)
Block(-7,1,-4,17:3)
Block(-7,1,-3,17:3)
Block(-7,1,-2,17:3)
Block(-7,1,-1,17:3)
Block(-7,1,0,17:3)
Block(-7,1,1,17:3)
Block(-7,1,2,17:3)
Block(-7,1,3,17:3)
Block(-7,1,4,17:3)
Block(-7,1,5,17:3)
Block(-7,1,6,17:3)
Block(-7,1,7,17:3)
Block(-7,1,8,17:3)
Block(-7,1,9,17:3)
Block(-7,2,-8,17:3)
Block(-7,2,-7,17:3)
Block(-7,2,-6,17:3)
Block(-7,2,-5,17:3)
Block(-7,2,-4,17:3)
Block(-7,2,-3,17:3)
Block(-7,2,-2,17:3)
Block(-7,2,-1,17:3)
Block(-7,2,0,17:3)
Block(-7,2,1,17:3)
Block(-7,2,2,17:3)
Block(-7,2,3,17:3)
Block(-7,2,4,17:3)
Block(-7,2,5,17:3)
Block(-7,2,6,17:3)
Block(-7,2,7,17:3)
Block(-7,2,8,17:3)
Block(-7,3,-7,17:3)
Block(-7,3,-6,17:3)
Block(-7,3,-3,17:3)
Block(-7,3,-2,17:3)
Block(-7,3,-1,17:3)
Block(-7,3,0,17:3)
Block(-7,3,1,17:3)
Block(-7,3,2,17:3)
Block(-7,3,4,17:3)
Block(-7,3,6,17:3)
Block(-7,3,7,17:3)
Block(-7,4,-1,17:3)
Block(-7,4,0,17:3)
Block(-7,4,1,17:3)
Block(-7,5,0,17:3)
Block(-7,14,7,106:4)
Block(-7,15,7,106:4)
Block(-7,16,7,106:4)
Block(-7,17,7,106:4)
Block(-7,18,7,106:4)
Block(-7,19,7,106:4)
Block(-7,20,0,18:3)
Block(-7,20,7,106:4)
Block(-7,21,-3,18:3)
Block(-7,21,-1,18:3)
Block(-7,21,0,18:3)
Block(-7,21,4,18:3)
Block(-7,21,5,18:3)
Block(-7,21,6,18:3)
Block(-7,21,7,106:4)
Block(-7,22,-5,18:3)
Block(-7,22,-4,18:3)
Block(-7,22,-2,18:3)
Block(-7,22,-1,18:3)
Block(-7,22,0,17:7)
Block(-7,22,2,18:3)
Block(-7,22,4,18:3)
Block(-7,22,5,18:3)
Block(-7,22,6,18:3)
Block(-7,22,7,106:4)
Block(-7,23,-6,18:3)
Block(-7,23,-2,18:3)
Block(-7,23,-1,18:3)
Block(-7,23,1,18:3)
Block(-7,23,2,18:3)
Block(-7,23,4,18:3)
Block(-7,23,5,18:3)
Block(-7,24,9,18:3)
Block(-7,25,8,18:1)
Block(-7,25,9,17:3)
Block(-7,25,10,18:1)
Block(-7,26,8,106:1)
Block(-7,26,10,106:4)
Block(-7,27,-7,18:1)
Block(-7,27,8,106:1)
Block(-7,27,10,106:4)
Block(-7,28,-7,106:2)
Block(-7,28,8,106:1)
Block(-7,28,10,106:4)
Block(-7,29,-28,18:3)
Block(-7,29,-7,106:2)
Block(-7,29,8,106:1)
Block(-7,29,10,106:4)
Block(-7,30,-7,106:2)
Block(-7,30,8,106:1)
Block(-7,30,10,106:4)
Block(-7,31,-7,106:2)
Block(-7,31,8,106:1)
Block(-7,31,10,106:4)
Block(-7,32,-25,18:3)
Block(-7,32,-24,18:3)
Block(-7,32,-7,106:2)
Block(-7,32,8,106:1)
Block(-7,32,10,106:4)
Block(-7,32,24,18:3)
Block(-7,33,-26,18:3)
Block(-7,33,-25,18:3)
Block(-7,33,-24,18:3)
Block(-7,33,-23,18:3)
Block(-7,33,-21,18:3)
Block(-7,33,-20,18:3)
Block(-7,33,-7,106:2)
Block(-7,33,8,106:1)
Block(-7,33,10,106:4)
Block(-7,33,23,18:3)
Block(-7,33,25,18:3)
Block(-7,34,-26,18:3)
Block(-7,34,-25,18:3)
Block(-7,34,-22,18:3)
Block(-7,34,-20,18:3)
Block(-7,34,-19,18:3)
Block(-7,34,-7,106:2)
Block(-7,34,8,106:1)
Block(-7,34,10,106:4)
Block(-7,34,16,18:3)
Block(-7,34,17,18:3)
Block(-7,34,19,18:3)
Block(-7,34,21,18:3)
Block(-7,34,22,18:3)
Block(-7,34,24,18:3)
Block(-7,34,26,18:3)
Block(-7,35,-23,18:3)
Block(-7,35,-22,18:3)
Block(-7,35,-21,18:3)
Block(-7,35,-20,18:3)
Block(-7,35,-19,18:3)
Block(-7,35,-18,18:3)
Block(-7,35,-17,18:3)
Block(-7,35,-16,18:3)
Block(-7,35,-14,18:3)
Block(-7,35,-13,18:3)
Block(-7,35,-12,18:3)
Block(-7,35,-7,106:2)
Block(-7,35,-6,18:3)
Block(-7,35,6,18:3)
Block(-7,35,7,18:3)
Block(-7,35,8,106:1)
Block(-7,35,9,18:3)
Block(-7,35,10,106:4)
Block(-7,35,12,18:3)
Block(-7,35,13,18:3)
Block(-7,35,17,18:3)
Block(-7,35,18,18:3)
Block(-7,35,19,18:3)
Block(-7,35,20,18:3)
Block(-7,35,21,18:3)
Block(-7,35,22,18:3)
Block(-7,36,-23,18:3)
Block(-7,36,-19,18:3)
Block(-7,36,-17,18:3)
Block(-7,36,-14,18:3)
Block(-7,36,-13,18:3)
Block(-7,36,-12,18:3)
Block(-7,36,-11,18:3)
Block(-7,36,-8,18:3)
Block(-7,36,-7,18:3)
Block(-7,36,-6,18:3)
Block(-7,36,-5,18:3)
Block(-7,36,-1,18:3)
Block(-7,36,0,17:7)
Block(-7,36,1,18:3)
Block(-7,36,7,18:3)
Block(-7,36,8,18:3)
Block(-7,36,9,18:3)
Block(-7,36,11,18:3)
Block(-7,36,13,18:3)
Block(-7,36,17,18:3)
Block(-7,36,18,18:3)
Block(-7,36,19,18:3)
Block(-7,36,21,18:3)
Block(-7,36,22,18:3)
Block(-7,37,-23,18:3)
Block(-7,37,-22,18:3)
Block(-7,37,-21,18:3)
Block(-7,37,-19,18:3)
Block(-7,37,-17,18:3)
Block(-7,37,-16,18:3)
Block(-7,37,-15,18:3)
Block(-7,37,-14,18:3)
Block(-7,37,-13,18:3)
Block(-7,37,-12,18:3)
Block(-7,37,-11,18:3)
Block(-7,37,-10,18:3)
Block(-7,37,-7,17:11)
Block(-7,37,-6,18:3)
Block(-7,37,-5,18:3)
Block(-7,37,-4,18:3)
Block(-7,37,-2,18:3)
Block(-7,37,0,17:7)
Block(-7,37,1,18:3)
Block(-7,37,5,18:3)
Block(-7,37,7,17:7)
Block(-7,37,9,18:3)
Block(-7,37,10,18:3)
Block(-7,37,11,18:3)
Block(-7,37,12,18:3)
Block(-7,37,13,18:3)
Block(-7,37,14,18:3)
Block(-7,37,15,18:3)
Block(-7,37,16,18:3)
Block(-7,37,17,18:3)
Block(-7,37,19,18:3)
Block(-7,37,21,18:3)
Block(-7,37,23,18:3)
Block(-7,38,-18,18:3)
Block(-7,38,-16,18:3)
Block(-7,38,-14,18:3)
Block(-7,38,-13,18:3)
Block(-7,38,-12,18:3)
Block(-7,38,-10,18:3)
Block(-7,38,-9,18:3)
Block(-7,38,-8,17:11)
Block(-7,38,-7,17:11)
Block(-7,38,-6,17:11)
Block(-7,38,-4,18:3)
Block(-7,38,-2,18:3)
Block(-7,38,-1,17:7)
Block(-7,38,0,17:7)
Block(-7,38,1,17:7)
Block(-7,38,3,18:3)
Block(-7,38,4,18:3)
Block(-7,38,5,18:3)
Block(-7,38,6,17:7)
Block(-7,38,7,17:7)
Block(-7,38,8,17:7)
Block(-7,38,9,18:3)
Block(-7,38,10,18:3)
Block(-7,38,11,18:3)
Block(-7,38,13,18:3)
Block(-7,38,14,18:3)
Block(-7,38,15,18:3)
Block(-7,38,17,18:3)
Block(-7,39,-15,18:3)
