#######################################################################
# +-----------------------------------------------------------------+ #
# |                            BO3 object                           | #
# +-----------------------------------------------------------------+ #
#######################################################################

# The descriptions in this file are accurate only for TerrainControl and OTG.
# For MCW and OTG+ these descriptions are only accurate if the BO3 is used as a CustomObject.
# MCW and OTG+ completely reimplemented CustomStructure, check the MCW/OTG+ documentation for more information.

# This is the config file of a custom object.
# If you add this object correctly to your BiomeConfigs, it will spawn in the world.

# This is the creator of this BO3 object
Author: Unknown

# A short description of this BO3 object
Description: This BO3 was converted from a schematic using OTGEdit. The author and description information of the schematic could not be found. If you know who the author of the schematic is then please add this information.

# The BO3 version, don't change this! It can be used by external applications to do a version check.
Version: 3

# The settings mode, WriteAll, WriteWithoutComments or WriteDisable. See WorldConfig.
SettingsMode: WriteDisable

#######################################################################
# +-----------------------------------------------------------------+ #
# |                          Main settings                          | #
# +-----------------------------------------------------------------+ #
#######################################################################

# This needs to be set to true to spawn the object in the Tree and Sapling resources.
Tree: true

# The frequency of the BO3 from 1 to 200. Tries this many times to spawn this BO3 when using the CustomObject(...) resource.
# Ignored by Tree(..), Sapling(..) and CustomStructure(..)
Frequency: 40

# The rarity of the BO3 from 0 to 100. Each spawn attempt has rarity% chance to succeed when using the CustomObject(...) resource.
# Ignored by Tree(..), Sapling(..) and CustomStructure(..)
Rarity: 100.0

# If you set this to true, the BO3 will be placed with a random rotation.
RotateRandomly: true

# The spawn height of the BO3 - randomY, highestBlock or highestSolidBlock.
SpawnHeight: randomY

# The height limits for the BO3.
MinHeight: 0

MaxHeight: 256

# Objects can have other objects attached to it: branches. Branches can also
# have branches attached to it, which can also have branches, etc. This is the
# maximum branch depth for this objects.
MaxBranchDepth: 10

# When spawned with the UseWorld keyword, this BO3 should NOT spawn in the following biomes.
# If you writer.write the BO3 name directly in the BiomeConfigs, this will be ignored.
ExcludedBiomes: All

# To optimise this BO3 for faster loading times you can use Notepad++ to find/replace comments and abbreviate things.
# Notepad++ find/replace with regex:
# Find: ^[#;].* replace to nothing removes all lines starting with # 
# Find: ^\s*$ replace to nothing removes most empty lines 
# Notepad++ find/replace without regex:
# *Warning: This will only work for OTG 1.10.2 v21 / OTG 1.11.2 v6 or higher. B( is not recognised by lower versions.
# Find: Block( replace to B(

#######################################################################
# +-----------------------------------------------------------------+ #
# |                      Source block settings                      | #
# +-----------------------------------------------------------------+ #
#######################################################################

# The block(s) the BO3 should spawn in.
SourceBlocks: AIR

# The maximum percentage of the BO3 that can be outside the SourceBlock.
# The BO3 won't be placed on a location with more blocks outside the SourceBlock than this percentage.
MaxPercentageOutsideSourceBlock: 100

# What to do when a block is about to be placed outside the SourceBlock? (dontPlace, placeAnyway)
OutsideSourceBlock: placeAnyway

#######################################################################
# +-----------------------------------------------------------------+ #
# |                              Blocks                             | #
# +-----------------------------------------------------------------+ #
#######################################################################

# All the blocks used in the BO3 are listed here. Possible blocks:
# Block(x,y,z,id[.data][,nbtfile.nbt) or B(x,y,z,id[.data][,nbtfile.nbt)
# RandomBlock(x,y,z,id[:data][,nbtfile.nbt],chance[,id[:data][,nbtfile.nbt],chance[,...]])
# So RandomBlock(0,0,0,CHEST,chest.nbt,50,CHEST,anotherchest.nbt,100) will spawn a chest at
# the BO3 origin, and give it a 50% chance to have the contents of chest.nbt, or, if that
# fails, a 100% percent chance to have the contents of anotherchest.nbt.

Block(-14,17,11,biomesoplenty:hard_ice:0)
Block(-14,20,12,biomesoplenty:hard_ice:0)
Block(-13,9,2,biomesoplenty:hard_ice:0)
Block(-13,10,1,biomesoplenty:hard_ice:0)
Block(-13,10,2,biomesoplenty:hard_ice:0)
Block(-13,10,3,biomesoplenty:hard_ice:0)
Block(-13,11,2,biomesoplenty:hard_ice:0)
Block(-13,11,3,biomesoplenty:hard_ice:0)
Block(-13,11,4,biomesoplenty:hard_ice:0)
Block(-13,12,3,biomesoplenty:hard_ice:0)
Block(-13,12,4,biomesoplenty:hard_ice:0)
Block(-13,12,5,biomesoplenty:hard_ice:0)
Block(-13,13,4,biomesoplenty:hard_ice:0)
Block(-13,13,5,biomesoplenty:hard_ice:0)
Block(-13,13,6,biomesoplenty:hard_ice:0)
Block(-13,14,5,biomesoplenty:hard_ice:0)
Block(-13,14,6,biomesoplenty:hard_ice:0)
Block(-13,14,7,biomesoplenty:hard_ice:0)
Block(-13,14,8,biomesoplenty:hard_ice:0)
Block(-13,15,7,biomesoplenty:hard_ice:0)
Block(-13,15,8,biomesoplenty:hard_ice:0)
Block(-13,15,9,biomesoplenty:hard_ice:0)
Block(-13,15,10,biomesoplenty:hard_ice:0)
Block(-13,16,8,biomesoplenty:hard_ice:0)
Block(-13,16,9,biomesoplenty:hard_ice:0)
Block(-13,16,10,biomesoplenty:hard_ice:0)
Block(-13,16,11,biomesoplenty:hard_ice:0)
Block(-13,16,12,biomesoplenty:hard_ice:0)
Block(-13,17,8,biomesoplenty:hard_ice:0)
Block(-13,17,9,biomesoplenty:hard_ice:0)
Block(-13,17,10,biomesoplenty:hard_ice:0)
Block(-13,17,11,biomesoplenty:hard_ice:0)
Block(-13,17,12,biomesoplenty:hard_ice:0)
Block(-13,18,8,biomesoplenty:hard_ice:0)
Block(-13,18,9,biomesoplenty:hard_ice:0)
Block(-13,18,10,biomesoplenty:hard_ice:0)
Block(-13,18,11,biomesoplenty:hard_ice:0)
Block(-13,18,12,biomesoplenty:hard_ice:0)
Block(-13,19,8,biomesoplenty:hard_ice:0)
Block(-13,19,9,biomesoplenty:hard_ice:0)
Block(-13,19,10,biomesoplenty:hard_ice:0)
Block(-13,19,11,biomesoplenty:hard_ice:0)
Block(-13,19,12,biomesoplenty:hard_ice:0)
Block(-13,20,8,biomesoplenty:hard_ice:0)
Block(-13,20,9,biomesoplenty:hard_ice:0)
Block(-13,20,10,biomesoplenty:hard_ice:0)
Block(-13,20,11,biomesoplenty:hard_ice:0)
Block(-13,20,12,biomesoplenty:hard_ice:0)
Block(-13,20,13,biomesoplenty:hard_ice:0)
Block(-13,21,9,biomesoplenty:hard_ice:0)
Block(-13,21,10,biomesoplenty:hard_ice:0)
Block(-13,21,11,biomesoplenty:hard_ice:0)
Block(-13,21,12,biomesoplenty:hard_ice:0)
Block(-13,21,13,biomesoplenty:hard_ice:0)
Block(-13,22,9,biomesoplenty:hard_ice:0)
Block(-13,22,10,biomesoplenty:hard_ice:0)
Block(-13,22,11,biomesoplenty:hard_ice:0)
Block(-13,22,12,biomesoplenty:hard_ice:0)
Block(-13,22,13,biomesoplenty:hard_ice:0)
Block(-13,23,10,biomesoplenty:hard_ice:0)
Block(-13,23,11,biomesoplenty:hard_ice:0)
Block(-13,23,12,biomesoplenty:hard_ice:0)
Block(-13,24,10,biomesoplenty:hard_ice:0)
Block(-13,24,11,biomesoplenty:hard_ice:0)
Block(-13,25,11,biomesoplenty:hard_ice:0)
Block(-12,9,0,biomesoplenty:hard_ice:0)
Block(-12,9,1,biomesoplenty:hard_ice:0)
Block(-12,9,2,biomesoplenty:hard_ice:0)
Block(-12,9,3,biomesoplenty:hard_ice:0)
Block(-12,10,-2,biomesoplenty:hard_ice:0)
Block(-12,10,-1,biomesoplenty:hard_ice:0)
Block(-12,10,0,biomesoplenty:hard_ice:0)
Block(-12,10,1,biomesoplenty:hard_ice:0)
Block(-12,10,2,biomesoplenty:hard_ice:0)
Block(-12,10,3,biomesoplenty:hard_ice:0)
Block(-12,10,4,biomesoplenty:hard_ice:0)
Block(-12,11,-1,biomesoplenty:hard_ice:0)
Block(-12,11,0,biomesoplenty:hard_ice:0)
Block(-12,11,1,biomesoplenty:hard_ice:0)
Block(-12,11,2,biomesoplenty:hard_ice:0)
Block(-12,11,3,biomesoplenty:hard_ice:0)
Block(-12,11,4,biomesoplenty:hard_ice:0)
Block(-12,11,5,biomesoplenty:hard_ice:0)
Block(-12,12,-1,biomesoplenty:hard_ice:0)
Block(-12,12,0,biomesoplenty:hard_ice:0)
Block(-12,12,1,biomesoplenty:hard_ice:0)
Block(-12,12,2,biomesoplenty:hard_ice:0)
Block(-12,12,3,biomesoplenty:hard_ice:0)
Block(-12,12,4,biomesoplenty:hard_ice:0)
Block(-12,12,5,biomesoplenty:hard_ice:0)
Block(-12,12,6,biomesoplenty:hard_ice:0)
Block(-12,13,0,biomesoplenty:hard_ice:0)
Block(-12,13,1,biomesoplenty:hard_ice:0)
Block(-12,13,2,biomesoplenty:hard_ice:0)
Block(-12,13,3,biomesoplenty:hard_ice:0)
Block(-12,13,4,biomesoplenty:hard_ice:0)
Block(-12,13,5,biomesoplenty:hard_ice:0)
Block(-12,13,6,biomesoplenty:hard_ice:0)
Block(-12,13,7,biomesoplenty:hard_ice:0)
Block(-12,13,8,biomesoplenty:hard_ice:0)
Block(-12,14,0,biomesoplenty:hard_ice:0)
Block(-12,14,1,biomesoplenty:hard_ice:0)
Block(-12,14,2,biomesoplenty:hard_ice:0)
Block(-12,14,3,biomesoplenty:hard_ice:0)
Block(-12,14,4,biomesoplenty:hard_ice:0)
Block(-12,14,5,biomesoplenty:hard_ice:0)
Block(-12,14,6,biomesoplenty:hard_ice:0)
Block(-12,14,7,biomesoplenty:hard_ice:0)
Block(-12,14,8,biomesoplenty:hard_ice:0)
Block(-12,14,9,biomesoplenty:hard_ice:0)
Block(-12,15,1,biomesoplenty:hard_ice:0)
Block(-12,15,2,biomesoplenty:hard_ice:0)
Block(-12,15,3,biomesoplenty:hard_ice:0)
Block(-12,15,4,biomesoplenty:hard_ice:0)
Block(-12,15,5,biomesoplenty:hard_ice:0)
Block(-12,15,6,biomesoplenty:hard_ice:0)
Block(-12,15,7,biomesoplenty:hard_ice:0)
Block(-12,15,8,biomesoplenty:hard_ice:0)
Block(-12,15,9,biomesoplenty:hard_ice:0)
Block(-12,15,10,biomesoplenty:hard_ice:0)
Block(-12,15,11,biomesoplenty:hard_ice:0)
Block(-12,16,2,biomesoplenty:hard_ice:0)
Block(-12,16,3,biomesoplenty:hard_ice:0)
Block(-12,16,4,biomesoplenty:hard_ice:0)
Block(-12,16,5,biomesoplenty:hard_ice:0)
Block(-12,16,6,biomesoplenty:hard_ice:0)
Block(-12,16,7,biomesoplenty:hard_ice:0)
Block(-12,16,8,biomesoplenty:hard_ice:0)
Block(-12,16,9,biomesoplenty:hard_ice:0)
Block(-12,16,10,biomesoplenty:hard_ice:0)
Block(-12,16,11,biomesoplenty:hard_ice:0)
Block(-12,16,12,biomesoplenty:hard_ice:0)
Block(-12,16,13,biomesoplenty:hard_ice:0)
Block(-12,17,3,biomesoplenty:hard_ice:0)
Block(-12,17,4,biomesoplenty:hard_ice:0)
Block(-12,17,5,biomesoplenty:hard_ice:0)
Block(-12,17,6,biomesoplenty:hard_ice:0)
Block(-12,17,7,biomesoplenty:hard_ice:0)
Block(-12,17,8,biomesoplenty:hard_ice:0)
Block(-12,17,9,biomesoplenty:hard_ice:0)
Block(-12,17,10,biomesoplenty:hard_ice:0)
Block(-12,17,11,biomesoplenty:hard_ice:0)
Block(-12,17,12,biomesoplenty:hard_ice:0)
Block(-12,17,13,biomesoplenty:hard_ice:0)
Block(-12,18,3,biomesoplenty:hard_ice:0)
Block(-12,18,4,biomesoplenty:hard_ice:0)
Block(-12,18,5,biomesoplenty:hard_ice:0)
Block(-12,18,6,biomesoplenty:hard_ice:0)
Block(-12,18,7,biomesoplenty:hard_ice:0)
Block(-12,18,8,biomesoplenty:hard_ice:0)
Block(-12,18,9,biomesoplenty:hard_ice:0)
Block(-12,18,10,biomesoplenty:hard_ice:0)
Block(-12,18,11,biomesoplenty:hard_ice:0)
Block(-12,18,12,biomesoplenty:hard_ice:0)
Block(-12,18,13,biomesoplenty:hard_ice:0)
Block(-12,19,4,biomesoplenty:hard_ice:0)
Block(-12,19,5,biomesoplenty:hard_ice:0)
Block(-12,19,6,biomesoplenty:hard_ice:0)
Block(-12,19,7,biomesoplenty:hard_ice:0)
Block(-12,19,8,biomesoplenty:hard_ice:0)
Block(-12,19,9,biomesoplenty:hard_ice:0)
Block(-12,19,10,biomesoplenty:hard_ice:0)
Block(-12,19,11,biomesoplenty:hard_ice:0)
Block(-12,19,12,biomesoplenty:hard_ice:0)
Block(-12,19,13,biomesoplenty:hard_ice:0)
Block(-12,19,14,biomesoplenty:hard_ice:0)
Block(-12,20,4,biomesoplenty:hard_ice:0)
Block(-12,20,5,biomesoplenty:hard_ice:0)
Block(-12,20,6,biomesoplenty:hard_ice:0)
Block(-12,20,7,biomesoplenty:hard_ice:0)
Block(-12,20,8,biomesoplenty:hard_ice:0)
Block(-12,20,9,biomesoplenty:hard_ice:0)
Block(-12,20,10,biomesoplenty:hard_ice:0)
Block(-12,20,11,biomesoplenty:hard_ice:0)
Block(-12,20,12,biomesoplenty:hard_ice:0)
Block(-12,20,13,biomesoplenty:hard_ice:0)
Block(-12,20,14,biomesoplenty:hard_ice:0)
Block(-12,21,4,biomesoplenty:hard_ice:0)
Block(-12,21,5,biomesoplenty:hard_ice:0)
Block(-12,21,6,biomesoplenty:hard_ice:0)
Block(-12,21,7,biomesoplenty:hard_ice:0)
Block(-12,21,8,biomesoplenty:hard_ice:0)
Block(-12,21,9,biomesoplenty:hard_ice:0)
Block(-12,21,10,biomesoplenty:hard_ice:0)
Block(-12,21,11,biomesoplenty:hard_ice:0)
Block(-12,21,12,biomesoplenty:hard_ice:0)
Block(-12,21,13,biomesoplenty:hard_ice:0)
Block(-12,21,14,biomesoplenty:hard_ice:0)
Block(-12,22,5,biomesoplenty:hard_ice:0)
Block(-12,22,6,biomesoplenty:hard_ice:0)
Block(-12,22,7,biomesoplenty:hard_ice:0)
Block(-12,22,8,biomesoplenty:hard_ice:0)
Block(-12,22,9,biomesoplenty:hard_ice:0)
Block(-12,22,10,biomesoplenty:hard_ice:0)
Block(-12,22,11,biomesoplenty:hard_ice:0)
Block(-12,22,12,biomesoplenty:hard_ice:0)
Block(-12,22,13,biomesoplenty:hard_ice:0)
Block(-12,22,14,biomesoplenty:hard_ice:0)
Block(-12,23,6,biomesoplenty:hard_ice:0)
Block(-12,23,7,biomesoplenty:hard_ice:0)
Block(-12,23,8,biomesoplenty:hard_ice:0)
Block(-12,23,9,biomesoplenty:hard_ice:0)
Block(-12,23,10,biomesoplenty:hard_ice:0)
Block(-12,23,11,biomesoplenty:hard_ice:0)
Block(-12,23,12,biomesoplenty:hard_ice:0)
Block(-12,23,13,biomesoplenty:hard_ice:0)
Block(-12,24,7,biomesoplenty:hard_ice:0)
Block(-12,24,8,biomesoplenty:hard_ice:0)
Block(-12,24,9,biomesoplenty:hard_ice:0)
Block(-12,24,10,biomesoplenty:hard_ice:0)
Block(-12,24,11,biomesoplenty:hard_ice:0)
Block(-12,24,12,biomesoplenty:hard_ice:0)
Block(-12,25,7,biomesoplenty:hard_ice:0)
Block(-12,25,8,biomesoplenty:hard_ice:0)
Block(-12,25,9,biomesoplenty:hard_ice:0)
Block(-12,25,10,biomesoplenty:hard_ice:0)
Block(-12,25,11,biomesoplenty:hard_ice:0)
Block(-12,25,12,biomesoplenty:hard_ice:0)
Block(-12,26,8,biomesoplenty:hard_ice:0)
Block(-12,26,9,biomesoplenty:hard_ice:0)
Block(-12,26,10,biomesoplenty:hard_ice:0)
Block(-12,26,11,biomesoplenty:hard_ice:0)
Block(-12,27,8,biomesoplenty:hard_ice:0)
Block(-12,27,9,biomesoplenty:hard_ice:0)
Block(-12,27,10,biomesoplenty:hard_ice:0)
Block(-12,28,8,biomesoplenty:hard_ice:0)
Block(-12,28,9,biomesoplenty:hard_ice:0)
Block(-12,28,10,biomesoplenty:hard_ice:0)
Block(-12,29,8,biomesoplenty:hard_ice:0)
Block(-12,29,9,biomesoplenty:hard_ice:0)
Block(-12,30,8,biomesoplenty:hard_ice:0)
Block(-11,8,3,biomesoplenty:hard_ice:0)
Block(-11,9,0,biomesoplenty:hard_ice:0)
Block(-11,9,1,biomesoplenty:hard_ice:0)
Block(-11,9,2,biomesoplenty:hard_ice:0)
Block(-11,9,3,biomesoplenty:hard_ice:0)
Block(-11,9,4,biomesoplenty:hard_ice:0)
Block(-11,9,5,biomesoplenty:hard_ice:0)
Block(-11,10,-3,biomesoplenty:hard_ice:0)
Block(-11,10,-2,biomesoplenty:hard_ice:0)
Block(-11,10,-1,biomesoplenty:hard_ice:0)
Block(-11,10,0,biomesoplenty:hard_ice:0)
Block(-11,10,1,biomesoplenty:hard_ice:0)
Block(-11,10,2,biomesoplenty:hard_ice:0)
Block(-11,10,3,biomesoplenty:hard_ice:0)
Block(-11,10,4,biomesoplenty:hard_ice:0)
Block(-11,10,5,biomesoplenty:hard_ice:0)
Block(-11,10,6,biomesoplenty:hard_ice:0)
Block(-11,11,-5,biomesoplenty:hard_ice:0)
Block(-11,11,-4,biomesoplenty:hard_ice:0)
Block(-11,11,-3,biomesoplenty:hard_ice:0)
Block(-11,11,-2,biomesoplenty:hard_ice:0)
Block(-11,11,-1,biomesoplenty:hard_ice:0)
Block(-11,11,0,biomesoplenty:hard_ice:0)
Block(-11,11,1,biomesoplenty:hard_ice:0)
Block(-11,11,2,biomesoplenty:hard_ice:0)
Block(-11,11,3,biomesoplenty:hard_ice:0)
Block(-11,11,4,biomesoplenty:hard_ice:0)
Block(-11,11,5,biomesoplenty:hard_ice:0)
Block(-11,11,6,biomesoplenty:hard_ice:0)
Block(-11,11,7,biomesoplenty:hard_ice:0)
Block(-11,12,-5,biomesoplenty:hard_ice:0)
Block(-11,12,-4,biomesoplenty:hard_ice:0)
Block(-11,12,-3,biomesoplenty:hard_ice:0)
Block(-11,12,-2,biomesoplenty:hard_ice:0)
Block(-11,12,-1,biomesoplenty:hard_ice:0)
Block(-11,12,0,biomesoplenty:hard_ice:0)
Block(-11,12,1,biomesoplenty:hard_ice:0)
Block(-11,12,2,biomesoplenty:hard_ice:0)
Block(-11,12,3,biomesoplenty:hard_ice:0)
Block(-11,12,4,biomesoplenty:hard_ice:0)
Block(-11,12,5,biomesoplenty:hard_ice:0)
Block(-11,12,6,biomesoplenty:hard_ice:0)
Block(-11,12,7,biomesoplenty:hard_ice:0)
Block(-11,12,8,biomesoplenty:hard_ice:0)
Block(-11,13,-5,biomesoplenty:hard_ice:0)
Block(-11,13,-4,biomesoplenty:hard_ice:0)
Block(-11,13,-3,biomesoplenty:hard_ice:0)
Block(-11,13,-2,biomesoplenty:hard_ice:0)
Block(-11,13,-1,biomesoplenty:hard_ice:0)
Block(-11,13,0,biomesoplenty:hard_ice:0)
Block(-11,13,1,biomesoplenty:hard_ice:0)
Block(-11,13,2,biomesoplenty:hard_ice:0)
Block(-11,13,3,biomesoplenty:hard_ice:0)
Block(-11,13,4,biomesoplenty:hard_ice:0)
Block(-11,13,5,biomesoplenty:hard_ice:0)
Block(-11,13,6,biomesoplenty:hard_ice:0)
Block(-11,13,7,biomesoplenty:hard_ice:0)
Block(-11,13,8,biomesoplenty:hard_ice:0)
Block(-11,13,9,biomesoplenty:hard_ice:0)
Block(-11,14,-4,biomesoplenty:hard_ice:0)
Block(-11,14,-3,biomesoplenty:hard_ice:0)
Block(-11,14,-2,biomesoplenty:hard_ice:0)
Block(-11,14,-1,biomesoplenty:hard_ice:0)
Block(-11,14,0,biomesoplenty:hard_ice:0)
Block(-11,14,1,biomesoplenty:hard_ice:0)
Block(-11,14,2,biomesoplenty:hard_ice:0)
Block(-11,14,3,biomesoplenty:hard_ice:0)
Block(-11,14,4,biomesoplenty:hard_ice:0)
Block(-11,14,5,biomesoplenty:hard_ice:0)
Block(-11,14,6,biomesoplenty:hard_ice:0)
Block(-11,14,7,biomesoplenty:hard_ice:0)
Block(-11,14,8,biomesoplenty:hard_ice:0)
Block(-11,14,9,biomesoplenty:hard_ice:0)
Block(-11,14,10,biomesoplenty:hard_ice:0)
Block(-11,14,11,biomesoplenty:hard_ice:0)
Block(-11,15,-3,biomesoplenty:hard_ice:0)
Block(-11,15,-2,biomesoplenty:hard_ice:0)
Block(-11,15,-1,biomesoplenty:hard_ice:0)
Block(-11,15,0,biomesoplenty:hard_ice:0)
Block(-11,15,1,biomesoplenty:hard_ice:0)
Block(-11,15,2,biomesoplenty:hard_ice:0)
Block(-11,15,3,biomesoplenty:hard_ice:0)
Block(-11,15,4,biomesoplenty:hard_ice:0)
Block(-11,15,5,biomesoplenty:hard_ice:0)
Block(-11,15,6,biomesoplenty:hard_ice:0)
Block(-11,15,7,biomesoplenty:hard_ice:0)
Block(-11,15,8,biomesoplenty:hard_ice:0)
Block(-11,15,9,biomesoplenty:hard_ice:0)
Block(-11,15,10,biomesoplenty:hard_ice:0)
Block(-11,15,11,biomesoplenty:hard_ice:0)
Block(-11,15,12,biomesoplenty:hard_ice:0)
Block(-11,15,13,biomesoplenty:hard_ice:0)
Block(-11,16,-3,biomesoplenty:hard_ice:0)
Block(-11,16,-2,biomesoplenty:hard_ice:0)
Block(-11,16,-1,biomesoplenty:hard_ice:0)
Block(-11,16,0,biomesoplenty:hard_ice:0)
Block(-11,16,1,biomesoplenty:hard_ice:0)
Block(-11,16,2,biomesoplenty:hard_ice:0)
Block(-11,16,3,biomesoplenty:hard_ice:0)
Block(-11,16,4,biomesoplenty:hard_ice:0)
Block(-11,16,5,biomesoplenty:hard_ice:0)
Block(-11,16,6,biomesoplenty:hard_ice:0)
Block(-11,16,7,biomesoplenty:hard_ice:0)
Block(-11,16,8,biomesoplenty:hard_ice:0)
Block(-11,16,9,biomesoplenty:hard_ice:0)
Block(-11,16,10,biomesoplenty:hard_ice:0)
Block(-11,16,11,biomesoplenty:hard_ice:0)
Block(-11,16,12,biomesoplenty:hard_ice:0)
Block(-11,16,13,biomesoplenty:hard_ice:0)
Block(-11,16,14,biomesoplenty:hard_ice:0)
Block(-11,17,-2,biomesoplenty:hard_ice:0)
Block(-11,17,-1,biomesoplenty:hard_ice:0)
Block(-11,17,0,biomesoplenty:hard_ice:0)
Block(-11,17,1,biomesoplenty:hard_ice:0)
Block(-11,17,2,biomesoplenty:hard_ice:0)
Block(-11,17,3,biomesoplenty:hard_ice:0)
Block(-11,17,4,biomesoplenty:hard_ice:0)
Block(-11,17,5,biomesoplenty:hard_ice:0)
Block(-11,17,6,biomesoplenty:hard_ice:0)
Block(-11,17,7,biomesoplenty:hard_ice:0)
Block(-11,17,8,biomesoplenty:hard_ice:0)
Block(-11,17,9,biomesoplenty:hard_ice:0)
Block(-11,17,10,biomesoplenty:hard_ice:0)
Block(-11,17,11,biomesoplenty:hard_ice:0)
Block(-11,17,12,biomesoplenty:hard_ice:0)
Block(-11,17,13,biomesoplenty:hard_ice:0)
Block(-11,17,14,biomesoplenty:hard_ice:0)
Block(-11,18,-2,biomesoplenty:hard_ice:0)
Block(-11,18,-1,biomesoplenty:hard_ice:0)
Block(-11,18,0,biomesoplenty:hard_ice:0)
Block(-11,18,1,biomesoplenty:hard_ice:0)
Block(-11,18,2,biomesoplenty:hard_ice:0)
Block(-11,18,3,biomesoplenty:hard_ice:0)
Block(-11,18,4,biomesoplenty:hard_ice:0)
Block(-11,18,5,biomesoplenty:hard_ice:0)
Block(-11,18,6,biomesoplenty:hard_ice:0)
Block(-11,18,7,biomesoplenty:hard_ice:0)
Block(-11,18,8,biomesoplenty:hard_ice:0)
Block(-11,18,9,biomesoplenty:hard_ice:0)
Block(-11,18,10,biomesoplenty:hard_ice:0)
Block(-11,18,11,biomesoplenty:hard_ice:0)
Block(-11,18,12,biomesoplenty:hard_ice:0)
Block(-11,18,13,biomesoplenty:hard_ice:0)
Block(-11,18,14,biomesoplenty:hard_ice:0)
Block(-11,19,-1,biomesoplenty:hard_ice:0)
Block(-11,19,0,biomesoplenty:hard_ice:0)
Block(-11,19,1,biomesoplenty:hard_ice:0)
Block(-11,19,2,biomesoplenty:hard_ice:0)
Block(-11,19,3,biomesoplenty:hard_ice:0)
Block(-11,19,4,biomesoplenty:hard_ice:0)
Block(-11,19,5,biomesoplenty:hard_ice:0)
Block(-11,19,6,biomesoplenty:hard_ice:0)
Block(-11,19,7,biomesoplenty:hard_ice:0)
Block(-11,19,8,biomesoplenty:hard_ice:0)
Block(-11,19,9,biomesoplenty:hard_ice:0)
Block(-11,19,10,biomesoplenty:hard_ice:0)
Block(-11,19,11,biomesoplenty:hard_ice:0)
Block(-11,19,12,biomesoplenty:hard_ice:0)
Block(-11,19,13,biomesoplenty:hard_ice:0)
Block(-11,19,14,biomesoplenty:hard_ice:0)
Block(-11,19,15,biomesoplenty:hard_ice:0)
Block(-11,20,-1,biomesoplenty:hard_ice:0)
Block(-11,20,0,biomesoplenty:hard_ice:0)
Block(-11,20,1,biomesoplenty:hard_ice:0)
Block(-11,20,2,biomesoplenty:hard_ice:0)
Block(-11,20,3,biomesoplenty:hard_ice:0)
Block(-11,20,4,biomesoplenty:hard_ice:0)
Block(-11,20,5,biomesoplenty:hard_ice:0)
Block(-11,20,6,biomesoplenty:hard_ice:0)
Block(-11,20,7,biomesoplenty:hard_ice:0)
Block(-11,20,8,biomesoplenty:hard_ice:0)
Block(-11,20,9,biomesoplenty:hard_ice:0)
Block(-11,20,10,biomesoplenty:hard_ice:0)
Block(-11,20,11,biomesoplenty:hard_ice:0)
Block(-11,20,12,biomesoplenty:hard_ice:0)
Block(-11,20,13,biomesoplenty:hard_ice:0)
Block(-11,20,14,biomesoplenty:hard_ice:0)
Block(-11,20,15,biomesoplenty:hard_ice:0)
Block(-11,21,0,biomesoplenty:hard_ice:0)
Block(-11,21,1,biomesoplenty:hard_ice:0)
Block(-11,21,2,biomesoplenty:hard_ice:0)
Block(-11,21,3,biomesoplenty:hard_ice:0)
Block(-11,21,4,biomesoplenty:hard_ice:0)
Block(-11,21,5,biomesoplenty:hard_ice:0)
Block(-11,21,6,biomesoplenty:hard_ice:0)
Block(-11,21,7,biomesoplenty:hard_ice:0)
Block(-11,21,8,biomesoplenty:hard_ice:0)
Block(-11,21,9,biomesoplenty:hard_ice:0)
Block(-11,21,10,biomesoplenty:hard_ice:0)
Block(-11,21,11,biomesoplenty:hard_ice:0)
Block(-11,21,12,biomesoplenty:hard_ice:0)
Block(-11,21,13,biomesoplenty:hard_ice:0)
Block(-11,21,14,biomesoplenty:hard_ice:0)
Block(-11,21,15,biomesoplenty:hard_ice:0)
Block(-11,22,0,biomesoplenty:hard_ice:0)
Block(-11,22,1,biomesoplenty:hard_ice:0)
Block(-11,22,2,biomesoplenty:hard_ice:0)
Block(-11,22,3,biomesoplenty:hard_ice:0)
Block(-11,22,4,biomesoplenty:hard_ice:0)
Block(-11,22,5,biomesoplenty:hard_ice:0)
Block(-11,22,6,biomesoplenty:hard_ice:0)
Block(-11,22,7,biomesoplenty:hard_ice:0)
Block(-11,22,8,biomesoplenty:hard_ice:0)
Block(-11,22,9,biomesoplenty:hard_ice:0)
Block(-11,22,10,biomesoplenty:hard_ice:0)
Block(-11,22,11,biomesoplenty:hard_ice:0)
Block(-11,22,12,biomesoplenty:hard_ice:0)
Block(-11,22,13,biomesoplenty:hard_ice:0)
Block(-11,22,14,biomesoplenty:hard_ice:0)
Block(-11,22,15,biomesoplenty:hard_ice:0)
Block(-11,23,0,biomesoplenty:hard_ice:0)
Block(-11,23,1,biomesoplenty:hard_ice:0)
Block(-11,23,2,biomesoplenty:hard_ice:0)
Block(-11,23,3,biomesoplenty:hard_ice:0)
Block(-11,23,4,biomesoplenty:hard_ice:0)
Block(-11,23,5,biomesoplenty:hard_ice:0)
Block(-11,23,6,biomesoplenty:hard_ice:0)
Block(-11,23,7,biomesoplenty:hard_ice:0)
Block(-11,23,8,biomesoplenty:hard_ice:0)
Block(-11,23,9,biomesoplenty:hard_ice:0)
Block(-11,23,10,biomesoplenty:hard_ice:0)
Block(-11,23,11,biomesoplenty:hard_ice:0)
Block(-11,23,12,biomesoplenty:hard_ice:0)
Block(-11,23,13,biomesoplenty:hard_ice:0)
Block(-11,23,14,biomesoplenty:hard_ice:0)
Block(-11,24,0,biomesoplenty:hard_ice:0)
Block(-11,24,1,biomesoplenty:hard_ice:0)
Block(-11,24,2,biomesoplenty:hard_ice:0)
Block(-11,24,3,biomesoplenty:hard_ice:0)
Block(-11,24,4,biomesoplenty:hard_ice:0)
Block(-11,24,5,biomesoplenty:hard_ice:0)
Block(-11,24,6,biomesoplenty:hard_ice:0)
Block(-11,24,7,biomesoplenty:hard_ice:0)
Block(-11,24,8,biomesoplenty:hard_ice:0)
Block(-11,24,9,biomesoplenty:hard_ice:0)
Block(-11,24,10,biomesoplenty:hard_ice:0)
Block(-11,24,11,biomesoplenty:hard_ice:0)
Block(-11,24,12,biomesoplenty:hard_ice:0)
Block(-11,24,13,biomesoplenty:hard_ice:0)
Block(-11,25,1,biomesoplenty:hard_ice:0)
Block(-11,25,2,biomesoplenty:hard_ice:0)
Block(-11,25,3,biomesoplenty:hard_ice:0)
Block(-11,25,4,biomesoplenty:hard_ice:0)
Block(-11,25,5,biomesoplenty:hard_ice:0)
Block(-11,25,6,biomesoplenty:hard_ice:0)
Block(-11,25,7,biomesoplenty:hard_ice:0)
Block(-11,25,8,biomesoplenty:hard_ice:0)
Block(-11,25,9,biomesoplenty:hard_ice:0)
Block(-11,25,10,biomesoplenty:hard_ice:0)
Block(-11,25,11,biomesoplenty:hard_ice:0)
Block(-11,25,12,biomesoplenty:hard_ice:0)
Block(-11,25,13,biomesoplenty:hard_ice:0)
Block(-11,26,3,biomesoplenty:hard_ice:0)
Block(-11,26,4,biomesoplenty:hard_ice:0)
Block(-11,26,5,biomesoplenty:hard_ice:0)
Block(-11,26,6,biomesoplenty:hard_ice:0)
Block(-11,26,7,biomesoplenty:hard_ice:0)
Block(-11,26,8,biomesoplenty:hard_ice:0)
Block(-11,26,9,biomesoplenty:hard_ice:0)
Block(-11,26,10,biomesoplenty:hard_ice:0)
Block(-11,26,11,biomesoplenty:hard_ice:0)
Block(-11,26,12,biomesoplenty:hard_ice:0)
Block(-11,27,4,biomesoplenty:hard_ice:0)
Block(-11,27,5,biomesoplenty:hard_ice:0)
Block(-11,27,6,biomesoplenty:hard_ice:0)
Block(-11,27,7,biomesoplenty:hard_ice:0)
Block(-11,27,8,biomesoplenty:hard_ice:0)
Block(-11,27,9,biomesoplenty:hard_ice:0)
Block(-11,27,10,biomesoplenty:hard_ice:0)
Block(-11,27,11,biomesoplenty:hard_ice:0)
Block(-11,28,4,biomesoplenty:hard_ice:0)
Block(-11,28,5,biomesoplenty:hard_ice:0)
Block(-11,28,6,biomesoplenty:hard_ice:0)
Block(-11,28,7,biomesoplenty:hard_ice:0)
Block(-11,28,8,biomesoplenty:hard_ice:0)
Block(-11,28,9,biomesoplenty:hard_ice:0)
Block(-11,28,10,biomesoplenty:hard_ice:0)
Block(-11,29,5,biomesoplenty:hard_ice:0)
Block(-11,29,6,biomesoplenty:hard_ice:0)
Block(-11,29,7,biomesoplenty:hard_ice:0)
Block(-11,29,8,biomesoplenty:hard_ice:0)
Block(-11,29,9,biomesoplenty:hard_ice:0)
Block(-11,29,10,biomesoplenty:hard_ice:0)
Block(-11,30,5,biomesoplenty:hard_ice:0)
Block(-11,30,6,biomesoplenty:hard_ice:0)
Block(-11,30,7,biomesoplenty:hard_ice:0)
Block(-11,30,8,biomesoplenty:hard_ice:0)
Block(-11,30,9,biomesoplenty:hard_ice:0)
Block(-11,31,5,biomesoplenty:hard_ice:0)
Block(-11,31,6,biomesoplenty:hard_ice:0)
Block(-11,31,7,biomesoplenty:hard_ice:0)
Block(-11,31,8,biomesoplenty:hard_ice:0)
Block(-11,32,6,biomesoplenty:hard_ice:0)
Block(-10,8,3,biomesoplenty:hard_ice:0)
Block(-10,8,4,biomesoplenty:hard_ice:0)
Block(-10,8,5,biomesoplenty:hard_ice:0)
Block(-10,9,0,biomesoplenty:hard_ice:0)
Block(-10,9,1,biomesoplenty:hard_ice:0)
Block(-10,9,2,biomesoplenty:hard_ice:0)
Block(-10,9,3,biomesoplenty:hard_ice:0)
Block(-10,9,4,biomesoplenty:hard_ice:0)
Block(-10,9,5,biomesoplenty:hard_ice:0)
Block(-10,9,6,biomesoplenty:hard_ice:0)
Block(-10,10,-4,biomesoplenty:hard_ice:0)
Block(-10,10,-3,biomesoplenty:hard_ice:0)
Block(-10,10,-2,biomesoplenty:hard_ice:0)
Block(-10,10,-1,biomesoplenty:hard_ice:0)
Block(-10,10,0,biomesoplenty:hard_ice:0)
Block(-10,10,1,biomesoplenty:hard_ice:0)
Block(-10,10,2,biomesoplenty:hard_ice:0)
Block(-10,10,3,biomesoplenty:hard_ice:0)
Block(-10,10,4,biomesoplenty:hard_ice:0)
Block(-10,10,5,biomesoplenty:hard_ice:0)
Block(-10,10,6,biomesoplenty:hard_ice:0)
Block(-10,10,7,biomesoplenty:hard_ice:0)
Block(-10,11,-7,biomesoplenty:hard_ice:0)
Block(-10,11,-6,biomesoplenty:hard_ice:0)
Block(-10,11,-5,biomesoplenty:hard_ice:0)
Block(-10,11,-4,biomesoplenty:hard_ice:0)
Block(-10,11,-3,biomesoplenty:hard_ice:0)
Block(-10,11,-2,biomesoplenty:hard_ice:0)
Block(-10,11,-1,biomesoplenty:hard_ice:0)
Block(-10,11,0,biomesoplenty:hard_ice:0)
Block(-10,11,1,biomesoplenty:hard_ice:0)
Block(-10,11,2,biomesoplenty:hard_ice:0)
Block(-10,11,3,biomesoplenty:hard_ice:0)
Block(-10,11,4,biomesoplenty:hard_ice:0)
Block(-10,11,5,biomesoplenty:hard_ice:0)
Block(-10,11,6,biomesoplenty:hard_ice:0)
Block(-10,11,7,biomesoplenty:hard_ice:0)
Block(-10,11,8,biomesoplenty:hard_ice:0)
Block(-10,12,-8,biomesoplenty:hard_ice:0)
Block(-10,12,-7,biomesoplenty:hard_ice:0)
Block(-10,12,-6,biomesoplenty:hard_ice:0)
Block(-10,12,-5,biomesoplenty:hard_ice:0)
Block(-10,12,-4,biomesoplenty:hard_ice:0)
Block(-10,12,-3,biomesoplenty:hard_ice:0)
Block(-10,12,-2,biomesoplenty:hard_ice:0)
Block(-10,12,-1,biomesoplenty:hard_ice:0)
Block(-10,12,0,biomesoplenty:hard_ice:0)
Block(-10,12,1,biomesoplenty:hard_ice:0)
Block(-10,12,2,biomesoplenty:hard_ice:0)
Block(-10,12,3,biomesoplenty:hard_ice:0)
Block(-10,12,4,biomesoplenty:hard_ice:0)
Block(-10,12,5,biomesoplenty:hard_ice:0)
Block(-10,12,6,biomesoplenty:hard_ice:0)
Block(-10,12,7,biomesoplenty:hard_ice:0)
Block(-10,12,8,biomesoplenty:hard_ice:0)
Block(-10,12,9,biomesoplenty:hard_ice:0)
Block(-10,13,-8,biomesoplenty:hard_ice:0)
Block(-10,13,-7,biomesoplenty:hard_ice:0)
Block(-10,13,-6,biomesoplenty:hard_ice:0)
Block(-10,13,-5,biomesoplenty:hard_ice:0)
Block(-10,13,-4,biomesoplenty:hard_ice:0)
Block(-10,13,-3,biomesoplenty:hard_ice:0)
Block(-10,13,-2,biomesoplenty:hard_ice:0)
Block(-10,13,-1,biomesoplenty:hard_ice:0)
Block(-10,13,0,biomesoplenty:hard_ice:0)
Block(-10,13,1,biomesoplenty:hard_ice:0)
Block(-10,13,2,biomesoplenty:hard_ice:0)
Block(-10,13,3,biomesoplenty:hard_ice:0)
Block(-10,13,4,biomesoplenty:hard_ice:0)
Block(-10,13,5,biomesoplenty:hard_ice:0)
Block(-10,13,6,biomesoplenty:hard_ice:0)
Block(-10,13,7,biomesoplenty:hard_ice:0)
Block(-10,13,8,biomesoplenty:hard_ice:0)
Block(-10,13,9,biomesoplenty:hard_ice:0)
Block(-10,13,10,biomesoplenty:hard_ice:0)
Block(-10,13,11,biomesoplenty:hard_ice:0)
Block(-10,14,-8,biomesoplenty:hard_ice:0)
Block(-10,14,-7,biomesoplenty:hard_ice:0)
Block(-10,14,-6,biomesoplenty:hard_ice:0)
Block(-10,14,-5,biomesoplenty:hard_ice:0)
Block(-10,14,-4,biomesoplenty:hard_ice:0)
Block(-10,14,-3,biomesoplenty:hard_ice:0)
Block(-10,14,-2,biomesoplenty:hard_ice:0)
Block(-10,14,-1,biomesoplenty:hard_ice:0)
Block(-10,14,0,biomesoplenty:hard_ice:0)
Block(-10,14,1,biomesoplenty:hard_ice:0)
Block(-10,14,2,biomesoplenty:hard_ice:0)
Block(-10,14,3,biomesoplenty:hard_ice:0)
Block(-10,14,4,biomesoplenty:hard_ice:0)
Block(-10,14,5,biomesoplenty:hard_ice:0)
Block(-10,14,6,biomesoplenty:hard_ice:0)
Block(-10,14,7,biomesoplenty:hard_ice:0)
Block(-10,14,8,biomesoplenty:hard_ice:0)
Block(-10,14,9,biomesoplenty:hard_ice:0)
Block(-10,14,10,biomesoplenty:hard_ice:0)
Block(-10,14,11,biomesoplenty:hard_ice:0)
Block(-10,14,12,biomesoplenty:hard_ice:0)
Block(-10,14,13,biomesoplenty:hard_ice:0)
Block(-10,15,-8,biomesoplenty:hard_ice:0)
Block(-10,15,-7,biomesoplenty:hard_ice:0)
Block(-10,15,-6,biomesoplenty:hard_ice:0)
Block(-10,15,-5,biomesoplenty:hard_ice:0)
Block(-10,15,-4,biomesoplenty:hard_ice:0)
Block(-10,15,-3,biomesoplenty:hard_ice:0)
Block(-10,15,-2,biomesoplenty:hard_ice:0)
Block(-10,15,-1,biomesoplenty:hard_ice:0)
Block(-10,15,0,biomesoplenty:hard_ice:0)
Block(-10,15,1,biomesoplenty:hard_ice:0)
Block(-10,15,2,biomesoplenty:hard_ice:0)
Block(-10,15,3,biomesoplenty:hard_ice:0)
Block(-10,15,4,biomesoplenty:hard_ice:0)
Block(-10,15,5,biomesoplenty:hard_ice:0)
Block(-10,15,6,biomesoplenty:hard_ice:0)
Block(-10,15,7,biomesoplenty:hard_ice:0)
Block(-10,15,8,biomesoplenty:hard_ice:0)
Block(-10,15,9,biomesoplenty:hard_ice:0)
Block(-10,15,10,biomesoplenty:hard_ice:0)
Block(-10,15,11,biomesoplenty:hard_ice:0)
Block(-10,15,12,biomesoplenty:hard_ice:0)
Block(-10,15,13,biomesoplenty:hard_ice:0)
Block(-10,15,14,biomesoplenty:hard_ice:0)
Block(-10,16,-8,biomesoplenty:hard_ice:0)
Block(-10,16,-7,biomesoplenty:hard_ice:0)
Block(-10,16,-6,biomesoplenty:hard_ice:0)
Block(-10,16,-5,biomesoplenty:hard_ice:0)
Block(-10,16,-4,biomesoplenty:hard_ice:0)
Block(-10,16,-3,biomesoplenty:hard_ice:0)
Block(-10,16,-2,biomesoplenty:hard_ice:0)
Block(-10,16,-1,biomesoplenty:hard_ice:0)
Block(-10,16,0,biomesoplenty:hard_ice:0)
Block(-10,16,1,biomesoplenty:hard_ice:0)
Block(-10,16,2,biomesoplenty:hard_ice:0)
Block(-10,16,3,biomesoplenty:hard_ice:0)
Block(-10,16,4,biomesoplenty:hard_ice:0)
Block(-10,16,5,biomesoplenty:hard_ice:0)
Block(-10,16,6,biomesoplenty:hard_ice:0)
Block(-10,16,7,biomesoplenty:hard_ice:0)
Block(-10,16,8,biomesoplenty:hard_ice:0)
Block(-10,16,9,biomesoplenty:hard_ice:0)
Block(-10,16,10,biomesoplenty:hard_ice:0)
Block(-10,16,11,biomesoplenty:hard_ice:0)
Block(-10,16,12,biomesoplenty:hard_ice:0)
Block(-10,16,13,biomesoplenty:hard_ice:0)
Block(-10,16,14,biomesoplenty:hard_ice:0)
Block(-10,16,15,biomesoplenty:hard_ice:0)
Block(-10,17,-7,biomesoplenty:hard_ice:0)
Block(-10,17,-6,biomesoplenty:hard_ice:0)
Block(-10,17,-5,biomesoplenty:hard_ice:0)
Block(-10,17,-4,biomesoplenty:hard_ice:0)
Block(-10,17,-3,biomesoplenty:hard_ice:0)
Block(-10,17,-2,biomesoplenty:hard_ice:0)
Block(-10,17,-1,biomesoplenty:hard_ice:0)
Block(-10,17,0,biomesoplenty:hard_ice:0)
Block(-10,17,1,biomesoplenty:hard_ice:0)
Block(-10,17,2,biomesoplenty:hard_ice:0)
Block(-10,17,3,biomesoplenty:hard_ice:0)
Block(-10,17,4,biomesoplenty:hard_ice:0)
Block(-10,17,5,biomesoplenty:hard_ice:0)
Block(-10,17,6,biomesoplenty:hard_ice:0)
Block(-10,17,7,biomesoplenty:hard_ice:0)
Block(-10,17,8,biomesoplenty:hard_ice:0)
Block(-10,17,9,biomesoplenty:hard_ice:0)
Block(-10,17,10,biomesoplenty:hard_ice:0)
Block(-10,17,11,biomesoplenty:hard_ice:0)
Block(-10,17,12,biomesoplenty:hard_ice:0)
Block(-10,17,13,biomesoplenty:hard_ice:0)
Block(-10,17,14,biomesoplenty:hard_ice:0)
Block(-10,17,15,biomesoplenty:hard_ice:0)
Block(-10,18,-6,biomesoplenty:hard_ice:0)
Block(-10,18,-5,biomesoplenty:hard_ice:0)
Block(-10,18,-4,biomesoplenty:hard_ice:0)
Block(-10,18,-3,biomesoplenty:hard_ice:0)
Block(-10,18,-2,biomesoplenty:hard_ice:0)
Block(-10,18,-1,biomesoplenty:hard_ice:0)
Block(-10,18,0,biomesoplenty:hard_ice:0)
Block(-10,18,1,biomesoplenty:hard_ice:0)
Block(-10,18,2,biomesoplenty:hard_ice:0)
Block(-10,18,3,biomesoplenty:hard_ice:0)
Block(-10,18,4,biomesoplenty:hard_ice:0)
Block(-10,18,5,biomesoplenty:hard_ice:0)
Block(-10,18,6,biomesoplenty:hard_ice:0)
Block(-10,18,7,biomesoplenty:hard_ice:0)
Block(-10,18,8,biomesoplenty:hard_ice:0)
Block(-10,18,9,biomesoplenty:hard_ice:0)
Block(-10,18,10,biomesoplenty:hard_ice:0)
Block(-10,18,11,biomesoplenty:hard_ice:0)
Block(-10,18,12,biomesoplenty:hard_ice:0)
Block(-10,18,13,biomesoplenty:hard_ice:0)
Block(-10,18,14,biomesoplenty:hard_ice:0)
Block(-10,18,15,biomesoplenty:hard_ice:0)
Block(-10,18,16,biomesoplenty:hard_ice:0)
Block(-10,19,-6,biomesoplenty:hard_ice:0)
Block(-10,19,-5,biomesoplenty:hard_ice:0)
Block(-10,19,-4,biomesoplenty:hard_ice:0)
Block(-10,19,-3,biomesoplenty:hard_ice:0)
Block(-10,19,-2,biomesoplenty:hard_ice:0)
Block(-10,19,-1,biomesoplenty:hard_ice:0)
Block(-10,19,0,biomesoplenty:hard_ice:0)
Block(-10,19,1,biomesoplenty:hard_ice:0)
Block(-10,19,2,biomesoplenty:hard_ice:0)
Block(-10,19,3,biomesoplenty:hard_ice:0)
Block(-10,19,4,biomesoplenty:hard_ice:0)
Block(-10,19,5,biomesoplenty:hard_ice:0)
Block(-10,19,6,biomesoplenty:hard_ice:0)
Block(-10,19,7,biomesoplenty:hard_ice:0)
Block(-10,19,8,biomesoplenty:hard_ice:0)
Block(-10,19,9,biomesoplenty:hard_ice:0)
Block(-10,19,10,biomesoplenty:hard_ice:0)
Block(-10,19,11,biomesoplenty:hard_ice:0)
Block(-10,19,12,biomesoplenty:hard_ice:0)
Block(-10,19,13,biomesoplenty:hard_ice:0)
Block(-10,19,14,biomesoplenty:hard_ice:0)
Block(-10,19,15,biomesoplenty:hard_ice:0)
Block(-10,19,16,biomesoplenty:hard_ice:0)
Block(-10,20,-5,biomesoplenty:hard_ice:0)
Block(-10,20,-4,biomesoplenty:hard_ice:0)
Block(-10,20,-3,biomesoplenty:hard_ice:0)
Block(-10,20,-2,biomesoplenty:hard_ice:0)
Block(-10,20,-1,biomesoplenty:hard_ice:0)
Block(-10,20,0,biomesoplenty:hard_ice:0)
Block(-10,20,1,biomesoplenty:hard_ice:0)
Block(-10,20,2,biomesoplenty:hard_ice:0)
Block(-10,20,3,biomesoplenty:hard_ice:0)
Block(-10,20,4,biomesoplenty:hard_ice:0)
Block(-10,20,5,biomesoplenty:hard_ice:0)
Block(-10,20,6,biomesoplenty:hard_ice:0)
Block(-10,20,7,biomesoplenty:hard_ice:0)
Block(-10,20,8,biomesoplenty:hard_ice:0)
Block(-10,20,9,biomesoplenty:hard_ice:0)
Block(-10,20,10,biomesoplenty:hard_ice:0)
Block(-10,20,11,biomesoplenty:hard_ice:0)
Block(-10,20,12,biomesoplenty:hard_ice:0)
Block(-10,20,13,biomesoplenty:hard_ice:0)
Block(-10,20,14,biomesoplenty:hard_ice:0)
Block(-10,20,15,biomesoplenty:hard_ice:0)
Block(-10,20,16,biomesoplenty:hard_ice:0)
Block(-10,20,17,biomesoplenty:hard_ice:0)
Block(-10,21,-4,biomesoplenty:hard_ice:0)
Block(-10,21,-3,biomesoplenty:hard_ice:0)
Block(-10,21,-2,biomesoplenty:hard_ice:0)
Block(-10,21,-1,biomesoplenty:hard_ice:0)
Block(-10,21,0,biomesoplenty:hard_ice:0)
Block(-10,21,1,biomesoplenty:hard_ice:0)
Block(-10,21,2,biomesoplenty:hard_ice:0)
Block(-10,21,3,biomesoplenty:hard_ice:0)
Block(-10,21,4,biomesoplenty:hard_ice:0)
Block(-10,21,5,biomesoplenty:hard_ice:0)
Block(-10,21,6,biomesoplenty:hard_ice:0)
Block(-10,21,7,biomesoplenty:hard_ice:0)
Block(-10,21,8,biomesoplenty:hard_ice:0)
Block(-10,21,9,biomesoplenty:hard_ice:0)
Block(-10,21,10,biomesoplenty:hard_ice:0)
Block(-10,21,11,biomesoplenty:hard_ice:0)
Block(-10,21,12,biomesoplenty:hard_ice:0)
Block(-10,21,13,biomesoplenty:hard_ice:0)
Block(-10,21,14,biomesoplenty:hard_ice:0)
Block(-10,21,15,biomesoplenty:hard_ice:0)
Block(-10,21,16,biomesoplenty:hard_ice:0)
Block(-10,21,17,biomesoplenty:hard_ice:0)
Block(-10,22,-4,biomesoplenty:hard_ice:0)
Block(-10,22,-3,biomesoplenty:hard_ice:0)
Block(-10,22,-2,biomesoplenty:hard_ice:0)
Block(-10,22,-1,biomesoplenty:hard_ice:0)
Block(-10,22,0,biomesoplenty:hard_ice:0)
Block(-10,22,1,biomesoplenty:hard_ice:0)
Block(-10,22,2,biomesoplenty:hard_ice:0)
Block(-10,22,3,biomesoplenty:hard_ice:0)
Block(-10,22,4,biomesoplenty:hard_ice:0)
Block(-10,22,5,biomesoplenty:hard_ice:0)
Block(-10,22,6,biomesoplenty:hard_ice:0)
Block(-10,22,7,biomesoplenty:hard_ice:0)
Block(-10,22,8,biomesoplenty:hard_ice:0)
Block(-10,22,9,biomesoplenty:hard_ice:0)
Block(-10,22,10,biomesoplenty:hard_ice:0)
Block(-10,22,11,biomesoplenty:hard_ice:0)
Block(-10,22,12,biomesoplenty:hard_ice:0)
Block(-10,22,13,biomesoplenty:hard_ice:0)
Block(-10,22,14,biomesoplenty:hard_ice:0)
Block(-10,22,15,biomesoplenty:hard_ice:0)
Block(-10,22,16,biomesoplenty:hard_ice:0)
Block(-10,23,-4,biomesoplenty:hard_ice:0)
Block(-10,23,-3,biomesoplenty:hard_ice:0)
Block(-10,23,-2,biomesoplenty:hard_ice:0)
Block(-10,23,-1,biomesoplenty:hard_ice:0)
Block(-10,23,0,biomesoplenty:hard_ice:0)
Block(-10,23,1,biomesoplenty:hard_ice:0)
Block(-10,23,2,biomesoplenty:hard_ice:0)
Block(-10,23,3,biomesoplenty:hard_ice:0)
Block(-10,23,4,biomesoplenty:hard_ice:0)
Block(-10,23,5,biomesoplenty:hard_ice:0)
Block(-10,23,6,biomesoplenty:hard_ice:0)
Block(-10,23,7,biomesoplenty:hard_ice:0)
Block(-10,23,8,biomesoplenty:hard_ice:0)
Block(-10,23,9,biomesoplenty:hard_ice:0)
Block(-10,23,10,biomesoplenty:hard_ice:0)
Block(-10,23,11,biomesoplenty:hard_ice:0)
Block(-10,23,12,biomesoplenty:hard_ice:0)
Block(-10,23,13,biomesoplenty:hard_ice:0)
Block(-10,23,14,biomesoplenty:hard_ice:0)
Block(-10,23,15,biomesoplenty:hard_ice:0)
Block(-10,24,-3,biomesoplenty:hard_ice:0)
Block(-10,24,-2,biomesoplenty:hard_ice:0)
Block(-10,24,-1,biomesoplenty:hard_ice:0)
Block(-10,24,0,biomesoplenty:hard_ice:0)
Block(-10,24,1,biomesoplenty:hard_ice:0)
Block(-10,24,2,biomesoplenty:hard_ice:0)
Block(-10,24,3,biomesoplenty:hard_ice:0)
Block(-10,24,4,biomesoplenty:hard_ice:0)
Block(-10,24,5,biomesoplenty:hard_ice:0)
Block(-10,24,6,biomesoplenty:hard_ice:0)
Block(-10,24,7,biomesoplenty:hard_ice:0)
Block(-10,24,8,biomesoplenty:hard_ice:0)
Block(-10,24,9,biomesoplenty:hard_ice:0)
Block(-10,24,10,biomesoplenty:hard_ice:0)
Block(-10,24,11,biomesoplenty:hard_ice:0)
Block(-10,24,12,biomesoplenty:hard_ice:0)
Block(-10,24,13,biomesoplenty:hard_ice:0)
Block(-10,24,14,biomesoplenty:hard_ice:0)
Block(-10,25,-3,biomesoplenty:hard_ice:0)
Block(-10,25,-2,biomesoplenty:hard_ice:0)
Block(-10,25,-1,biomesoplenty:hard_ice:0)
Block(-10,25,0,biomesoplenty:hard_ice:0)
Block(-10,25,1,biomesoplenty:hard_ice:0)
Block(-10,25,2,biomesoplenty:hard_ice:0)
Block(-10,25,3,biomesoplenty:hard_ice:0)
Block(-10,25,4,biomesoplenty:hard_ice:0)
Block(-10,25,5,biomesoplenty:hard_ice:0)
Block(-10,25,6,biomesoplenty:hard_ice:0)
Block(-10,25,7,biomesoplenty:hard_ice:0)
Block(-10,25,8,biomesoplenty:hard_ice:0)
Block(-10,25,9,biomesoplenty:hard_ice:0)
Block(-10,25,10,biomesoplenty:hard_ice:0)
Block(-10,25,11,biomesoplenty:hard_ice:0)
Block(-10,25,12,biomesoplenty:hard_ice:0)
Block(-10,25,13,biomesoplenty:hard_ice:0)
Block(-10,25,14,biomesoplenty:hard_ice:0)
Block(-10,26,-2,biomesoplenty:hard_ice:0)
Block(-10,26,-1,biomesoplenty:hard_ice:0)
Block(-10,26,0,biomesoplenty:hard_ice:0)
Block(-10,26,1,biomesoplenty:hard_ice:0)
Block(-10,26,2,biomesoplenty:hard_ice:0)
Block(-10,26,3,biomesoplenty:hard_ice:0)
Block(-10,26,4,biomesoplenty:hard_ice:0)
Block(-10,26,5,biomesoplenty:hard_ice:0)
Block(-10,26,6,biomesoplenty:hard_ice:0)
Block(-10,26,7,biomesoplenty:hard_ice:0)
Block(-10,26,8,biomesoplenty:hard_ice:0)
Block(-10,26,9,biomesoplenty:hard_ice:0)
Block(-10,26,10,biomesoplenty:hard_ice:0)
Block(-10,26,11,biomesoplenty:hard_ice:0)
Block(-10,26,12,biomesoplenty:hard_ice:0)
Block(-10,26,13,biomesoplenty:hard_ice:0)
Block(-10,27,-2,biomesoplenty:hard_ice:0)
Block(-10,27,-1,biomesoplenty:hard_ice:0)
Block(-10,27,0,biomesoplenty:hard_ice:0)
Block(-10,27,1,biomesoplenty:hard_ice:0)
Block(-10,27,2,biomesoplenty:hard_ice:0)
Block(-10,27,3,biomesoplenty:hard_ice:0)
Block(-10,27,4,biomesoplenty:hard_ice:0)
Block(-10,27,5,biomesoplenty:hard_ice:0)
Block(-10,27,6,biomesoplenty:hard_ice:0)
Block(-10,27,7,biomesoplenty:hard_ice:0)
Block(-10,27,8,biomesoplenty:hard_ice:0)
Block(-10,27,9,biomesoplenty:hard_ice:0)
Block(-10,27,10,biomesoplenty:hard_ice:0)
Block(-10,27,11,biomesoplenty:hard_ice:0)
Block(-10,27,12,biomesoplenty:hard_ice:0)
Block(-10,28,-1,biomesoplenty:hard_ice:0)
Block(-10,28,0,biomesoplenty:hard_ice:0)
Block(-10,28,1,biomesoplenty:hard_ice:0)
Block(-10,28,2,biomesoplenty:hard_ice:0)
Block(-10,28,3,biomesoplenty:hard_ice:0)
Block(-10,28,4,biomesoplenty:hard_ice:0)
Block(-10,28,5,biomesoplenty:hard_ice:0)
Block(-10,28,6,biomesoplenty:hard_ice:0)
Block(-10,28,7,biomesoplenty:hard_ice:0)
Block(-10,28,8,biomesoplenty:hard_ice:0)
Block(-10,28,9,biomesoplenty:hard_ice:0)
Block(-10,28,10,biomesoplenty:hard_ice:0)
Block(-10,28,11,biomesoplenty:hard_ice:0)
Block(-10,29,1,biomesoplenty:hard_ice:0)
Block(-10,29,2,biomesoplenty:hard_ice:0)
Block(-10,29,3,biomesoplenty:hard_ice:0)
Block(-10,29,4,biomesoplenty:hard_ice:0)
Block(-10,29,5,biomesoplenty:hard_ice:0)
Block(-10,29,6,biomesoplenty:hard_ice:0)
Block(-10,29,7,biomesoplenty:hard_ice:0)
Block(-10,29,8,biomesoplenty:hard_ice:0)
Block(-10,29,9,biomesoplenty:hard_ice:0)
Block(-10,29,10,biomesoplenty:hard_ice:0)
Block(-10,29,11,biomesoplenty:hard_ice:0)
Block(-10,30,3,biomesoplenty:hard_ice:0)
Block(-10,30,4,biomesoplenty:hard_ice:0)
Block(-10,30,5,biomesoplenty:hard_ice:0)
Block(-10,30,6,biomesoplenty:hard_ice:0)
Block(-10,30,7,biomesoplenty:hard_ice:0)
Block(-10,30,8,biomesoplenty:hard_ice:0)
Block(-10,30,9,biomesoplenty:hard_ice:0)
Block(-10,31,4,biomesoplenty:hard_ice:0)
Block(-10,31,5,biomesoplenty:hard_ice:0)
Block(-10,31,6,biomesoplenty:hard_ice:0)
Block(-10,31,7,biomesoplenty:hard_ice:0)
Block(-10,31,8,biomesoplenty:hard_ice:0)
Block(-10,32,6,biomesoplenty:hard_ice:0)
Block(-10,32,7,biomesoplenty:hard_ice:0)
Block(-9,8,3,biomesoplenty:hard_ice:0)
Block(-9,8,4,biomesoplenty:hard_ice:0)
Block(-9,8,5,biomesoplenty:hard_ice:0)
Block(-9,8,6,biomesoplenty:hard_ice:0)
Block(-9,9,0,biomesoplenty:hard_ice:0)
Block(-9,9,1,biomesoplenty:hard_ice:0)
Block(-9,9,2,biomesoplenty:hard_ice:0)
Block(-9,9,3,biomesoplenty:hard_ice:0)
Block(-9,9,4,biomesoplenty:hard_ice:0)
Block(-9,9,5,biomesoplenty:hard_ice:0)
Block(-9,9,6,biomesoplenty:hard_ice:0)
Block(-9,9,7,biomesoplenty:hard_ice:0)
Block(-9,9,8,biomesoplenty:hard_ice:0)
Block(-9,10,-4,biomesoplenty:hard_ice:0)
Block(-9,10,-3,biomesoplenty:hard_ice:0)
Block(-9,10,-2,biomesoplenty:hard_ice:0)
Block(-9,10,-1,biomesoplenty:hard_ice:0)
Block(-9,10,0,biomesoplenty:hard_ice:0)
Block(-9,10,1,biomesoplenty:hard_ice:0)
Block(-9,10,2,biomesoplenty:hard_ice:0)
Block(-9,10,3,biomesoplenty:hard_ice:0)
Block(-9,10,4,biomesoplenty:hard_ice:0)
Block(-9,10,5,biomesoplenty:hard_ice:0)
Block(-9,10,6,biomesoplenty:hard_ice:0)
Block(-9,10,7,biomesoplenty:hard_ice:0)
Block(-9,10,8,biomesoplenty:hard_ice:0)
Block(-9,11,-8,biomesoplenty:hard_ice:0)
Block(-9,11,-7,biomesoplenty:hard_ice:0)
Block(-9,11,-6,biomesoplenty:hard_ice:0)
Block(-9,11,-5,biomesoplenty:hard_ice:0)
Block(-9,11,-4,biomesoplenty:hard_ice:0)
Block(-9,11,-3,biomesoplenty:hard_ice:0)
Block(-9,11,-2,biomesoplenty:hard_ice:0)
Block(-9,11,-1,biomesoplenty:hard_ice:0)
Block(-9,11,0,biomesoplenty:hard_ice:0)
Block(-9,11,1,biomesoplenty:hard_ice:0)
Block(-9,11,2,biomesoplenty:hard_ice:0)
Block(-9,11,3,biomesoplenty:hard_ice:0)
Block(-9,11,4,biomesoplenty:hard_ice:0)
Block(-9,11,5,biomesoplenty:hard_ice:0)
Block(-9,11,6,biomesoplenty:hard_ice:0)
Block(-9,11,7,biomesoplenty:hard_ice:0)
Block(-9,11,8,biomesoplenty:hard_ice:0)
Block(-9,11,9,biomesoplenty:hard_ice:0)
Block(-9,11,10,biomesoplenty:hard_ice:0)
Block(-9,12,-8,biomesoplenty:hard_ice:0)
Block(-9,12,-7,biomesoplenty:hard_ice:0)
Block(-9,12,-6,biomesoplenty:hard_ice:0)
Block(-9,12,-5,biomesoplenty:hard_ice:0)
Block(-9,12,-4,biomesoplenty:hard_ice:0)
Block(-9,12,-3,biomesoplenty:hard_ice:0)
Block(-9,12,-2,biomesoplenty:hard_ice:0)
Block(-9,12,-1,biomesoplenty:hard_ice:0)
Block(-9,12,0,biomesoplenty:hard_ice:0)
Block(-9,12,1,biomesoplenty:hard_ice:0)
Block(-9,12,2,biomesoplenty:hard_ice:0)
Block(-9,12,3,biomesoplenty:hard_ice:0)
Block(-9,12,4,biomesoplenty:hard_ice:0)
Block(-9,12,5,biomesoplenty:hard_ice:0)
Block(-9,12,6,biomesoplenty:hard_ice:0)
Block(-9,12,7,biomesoplenty:hard_ice:0)
Block(-9,12,8,biomesoplenty:hard_ice:0)
Block(-9,12,9,biomesoplenty:hard_ice:0)
Block(-9,12,10,biomesoplenty:hard_ice:0)
Block(-9,12,11,biomesoplenty:hard_ice:0)
Block(-9,12,12,biomesoplenty:hard_ice:0)
Block(-9,13,-9,biomesoplenty:hard_ice:0)
Block(-9,13,-8,biomesoplenty:hard_ice:0)
Block(-9,13,-7,biomesoplenty:hard_ice:0)
Block(-9,13,-6,biomesoplenty:hard_ice:0)
Block(-9,13,-5,biomesoplenty:hard_ice:0)
Block(-9,13,-4,biomesoplenty:hard_ice:0)
Block(-9,13,-3,biomesoplenty:hard_ice:0)
Block(-9,13,-2,biomesoplenty:hard_ice:0)
Block(-9,13,-1,biomesoplenty:hard_ice:0)
Block(-9,13,0,biomesoplenty:hard_ice:0)
Block(-9,13,1,biomesoplenty:hard_ice:0)
Block(-9,13,2,biomesoplenty:hard_ice:0)
Block(-9,13,3,biomesoplenty:hard_ice:0)
Block(-9,13,4,biomesoplenty:hard_ice:0)
Block(-9,13,5,biomesoplenty:hard_ice:0)
Block(-9,13,6,biomesoplenty:hard_ice:0)
Block(-9,13,7,biomesoplenty:hard_ice:0)
Block(-9,13,8,biomesoplenty:hard_ice:0)
Block(-9,13,9,biomesoplenty:hard_ice:0)
Block(-9,13,10,biomesoplenty:hard_ice:0)
Block(-9,13,11,biomesoplenty:hard_ice:0)
Block(-9,13,12,biomesoplenty:hard_ice:0)
Block(-9,13,13,biomesoplenty:hard_ice:0)
Block(-9,13,14,biomesoplenty:hard_ice:0)
Block(-9,14,-9,biomesoplenty:hard_ice:0)
Block(-9,14,-8,biomesoplenty:hard_ice:0)
Block(-9,14,-7,biomesoplenty:hard_ice:0)
Block(-9,14,-6,biomesoplenty:hard_ice:0)
Block(-9,14,-5,biomesoplenty:hard_ice:0)
Block(-9,14,-4,biomesoplenty:hard_ice:0)
Block(-9,14,-3,biomesoplenty:hard_ice:0)
Block(-9,14,-2,biomesoplenty:hard_ice:0)
Block(-9,14,-1,biomesoplenty:hard_ice:0)
Block(-9,14,0,biomesoplenty:hard_ice:0)
Block(-9,14,1,biomesoplenty:hard_ice:0)
Block(-9,14,2,biomesoplenty:hard_ice:0)
Block(-9,14,3,biomesoplenty:hard_ice:0)
Block(-9,14,4,biomesoplenty:hard_ice:0)
Block(-9,14,5,biomesoplenty:hard_ice:0)
Block(-9,14,6,biomesoplenty:hard_ice:0)
Block(-9,14,7,biomesoplenty:hard_ice:0)
Block(-9,14,8,biomesoplenty:hard_ice:0)
Block(-9,14,9,biomesoplenty:hard_ice:0)
Block(-9,14,10,biomesoplenty:hard_ice:0)
Block(-9,14,11,biomesoplenty:hard_ice:0)
Block(-9,14,12,biomesoplenty:hard_ice:0)
Block(-9,14,13,biomesoplenty:hard_ice:0)
Block(-9,14,14,biomesoplenty:hard_ice:0)
Block(-9,14,15,biomesoplenty:hard_ice:0)
Block(-9,14,16,biomesoplenty:hard_ice:0)
Block(-9,14,17,biomesoplenty:hard_ice:0)
Block(-9,15,-9,biomesoplenty:hard_ice:0)
Block(-9,15,-8,biomesoplenty:hard_ice:0)
Block(-9,15,-7,biomesoplenty:hard_ice:0)
Block(-9,15,-6,biomesoplenty:hard_ice:0)
Block(-9,15,-5,biomesoplenty:hard_ice:0)
Block(-9,15,-4,biomesoplenty:hard_ice:0)
Block(-9,15,-3,biomesoplenty:hard_ice:0)
Block(-9,15,-2,biomesoplenty:hard_ice:0)
Block(-9,15,-1,biomesoplenty:hard_ice:0)
Block(-9,15,0,biomesoplenty:hard_ice:0)
Block(-9,15,1,biomesoplenty:hard_ice:0)
Block(-9,15,2,biomesoplenty:hard_ice:0)
Block(-9,15,3,biomesoplenty:hard_ice:0)
Block(-9,15,4,biomesoplenty:hard_ice:0)
Block(-9,15,5,biomesoplenty:hard_ice:0)
Block(-9,15,6,biomesoplenty:hard_ice:0)
Block(-9,15,7,biomesoplenty:hard_ice:0)
Block(-9,15,8,biomesoplenty:hard_ice:0)
Block(-9,15,9,biomesoplenty:hard_ice:0)
Block(-9,15,10,biomesoplenty:hard_ice:0)
Block(-9,15,11,biomesoplenty:hard_ice:0)
Block(-9,15,12,biomesoplenty:hard_ice:0)
Block(-9,15,13,biomesoplenty:hard_ice:0)
Block(-9,15,14,biomesoplenty:hard_ice:0)
Block(-9,15,15,biomesoplenty:hard_ice:0)
Block(-9,15,16,biomesoplenty:hard_ice:0)
Block(-9,15,17,biomesoplenty:hard_ice:0)
Block(-9,16,-8,biomesoplenty:hard_ice:0)
Block(-9,16,-7,biomesoplenty:hard_ice:0)
Block(-9,16,-6,biomesoplenty:hard_ice:0)
Block(-9,16,-5,biomesoplenty:hard_ice:0)
Block(-9,16,-4,biomesoplenty:hard_ice:0)
Block(-9,16,-3,biomesoplenty:hard_ice:0)
Block(-9,16,-2,biomesoplenty:hard_ice:0)
Block(-9,16,-1,biomesoplenty:hard_ice:0)
Block(-9,16,0,biomesoplenty:hard_ice:0)
Block(-9,16,1,biomesoplenty:hard_ice:0)
Block(-9,16,2,biomesoplenty:hard_ice:0)
Block(-9,16,3,biomesoplenty:hard_ice:0)
Block(-9,16,4,biomesoplenty:hard_ice:0)
Block(-9,16,5,biomesoplenty:hard_ice:0)
Block(-9,16,6,biomesoplenty:hard_ice:0)
Block(-9,16,7,biomesoplenty:hard_ice:0)
Block(-9,16,8,biomesoplenty:hard_ice:0)
Block(-9,16,9,biomesoplenty:hard_ice:0)
Block(-9,16,10,biomesoplenty:hard_ice:0)
Block(-9,16,11,biomesoplenty:hard_ice:0)
Block(-9,16,12,biomesoplenty:hard_ice:0)
Block(-9,16,13,biomesoplenty:hard_ice:0)
Block(-9,16,14,biomesoplenty:hard_ice:0)
Block(-9,16,15,biomesoplenty:hard_ice:0)
Block(-9,16,16,biomesoplenty:hard_ice:0)
Block(-9,16,17,biomesoplenty:hard_ice:0)
Block(-9,16,18,biomesoplenty:hard_ice:0)
Block(-9,17,-8,biomesoplenty:hard_ice:0)
Block(-9,17,-7,biomesoplenty:hard_ice:0)
Block(-9,17,-6,biomesoplenty:hard_ice:0)
Block(-9,17,-5,biomesoplenty:hard_ice:0)
Block(-9,17,-4,biomesoplenty:hard_ice:0)
Block(-9,17,-3,biomesoplenty:hard_ice:0)
Block(-9,17,-2,biomesoplenty:hard_ice:0)
Block(-9,17,-1,biomesoplenty:hard_ice:0)
Block(-9,17,0,biomesoplenty:hard_ice:0)
Block(-9,17,1,biomesoplenty:hard_ice:0)
Block(-9,17,2,biomesoplenty:hard_ice:0)
Block(-9,17,3,biomesoplenty:hard_ice:0)
Block(-9,17,4,biomesoplenty:hard_ice:0)
Block(-9,17,5,biomesoplenty:hard_ice:0)
Block(-9,17,6,biomesoplenty:hard_ice:0)
Block(-9,17,7,biomesoplenty:hard_ice:0)
Block(-9,17,8,biomesoplenty:hard_ice:0)
Block(-9,17,9,biomesoplenty:hard_ice:0)
Block(-9,17,10,biomesoplenty:hard_ice:0)
Block(-9,17,11,biomesoplenty:hard_ice:0)
Block(-9,17,12,biomesoplenty:hard_ice:0)
Block(-9,17,13,biomesoplenty:hard_ice:0)
Block(-9,17,14,biomesoplenty:hard_ice:0)
Block(-9,17,15,biomesoplenty:hard_ice:0)
Block(-9,17,16,biomesoplenty:hard_ice:0)
Block(-9,17,17,biomesoplenty:hard_ice:0)
Block(-9,17,18,biomesoplenty:hard_ice:0)
Block(-9,18,-7,biomesoplenty:hard_ice:0)
Block(-9,18,-6,biomesoplenty:hard_ice:0)
Block(-9,18,-5,biomesoplenty:hard_ice:0)
Block(-9,18,-4,biomesoplenty:hard_ice:0)
Block(-9,18,-3,biomesoplenty:hard_ice:0)
Block(-9,18,-2,biomesoplenty:hard_ice:0)
Block(-9,18,-1,biomesoplenty:hard_ice:0)
Block(-9,18,0,biomesoplenty:hard_ice:0)
Block(-9,18,1,biomesoplenty:hard_ice:0)
Block(-9,18,2,biomesoplenty:hard_ice:0)
Block(-9,18,3,biomesoplenty:hard_ice:0)
Block(-9,18,4,biomesoplenty:hard_ice:0)
Block(-9,18,5,biomesoplenty:hard_ice:0)
Block(-9,18,6,biomesoplenty:hard_ice:0)
Block(-9,18,7,biomesoplenty:hard_ice:0)
Block(-9,18,8,biomesoplenty:hard_ice:0)
Block(-9,18,9,biomesoplenty:hard_ice:0)
Block(-9,18,10,biomesoplenty:hard_ice:0)
Block(-9,18,11,biomesoplenty:hard_ice:0)
Block(-9,18,12,biomesoplenty:hard_ice:0)
Block(-9,18,13,biomesoplenty:hard_ice:0)
Block(-9,18,14,biomesoplenty:hard_ice:0)
Block(-9,18,15,biomesoplenty:hard_ice:0)
Block(-9,18,16,biomesoplenty:hard_ice:0)
Block(-9,18,17,biomesoplenty:hard_ice:0)
Block(-9,18,18,biomesoplenty:hard_ice:0)
Block(-9,19,-6,biomesoplenty:hard_ice:0)
Block(-9,19,-5,biomesoplenty:hard_ice:0)
Block(-9,19,-4,biomesoplenty:hard_ice:0)
Block(-9,19,-3,biomesoplenty:hard_ice:0)
Block(-9,19,-2,biomesoplenty:hard_ice:0)
Block(-9,19,-1,biomesoplenty:hard_ice:0)
Block(-9,19,0,biomesoplenty:hard_ice:0)
Block(-9,19,1,biomesoplenty:hard_ice:0)
Block(-9,19,2,biomesoplenty:hard_ice:0)
Block(-9,19,3,biomesoplenty:hard_ice:0)
Block(-9,19,4,biomesoplenty:hard_ice:0)
Block(-9,19,5,biomesoplenty:hard_ice:0)
Block(-9,19,6,biomesoplenty:hard_ice:0)
Block(-9,19,7,biomesoplenty:hard_ice:0)
Block(-9,19,8,biomesoplenty:hard_ice:0)
Block(-9,19,9,biomesoplenty:hard_ice:0)
Block(-9,19,10,biomesoplenty:hard_ice:0)
Block(-9,19,11,biomesoplenty:hard_ice:0)
Block(-9,19,12,biomesoplenty:hard_ice:0)
Block(-9,19,13,biomesoplenty:hard_ice:0)
Block(-9,19,14,biomesoplenty:hard_ice:0)
Block(-9,19,15,biomesoplenty:hard_ice:0)
Block(-9,19,16,biomesoplenty:hard_ice:0)
Block(-9,19,17,biomesoplenty:hard_ice:0)
Block(-9,19,18,biomesoplenty:hard_ice:0)
Block(-9,20,-5,biomesoplenty:hard_ice:0)
Block(-9,20,-4,biomesoplenty:hard_ice:0)
Block(-9,20,-3,biomesoplenty:hard_ice:0)
Block(-9,20,-2,biomesoplenty:hard_ice:0)
Block(-9,20,-1,biomesoplenty:hard_ice:0)
Block(-9,20,0,biomesoplenty:hard_ice:0)
Block(-9,20,1,biomesoplenty:hard_ice:0)
Block(-9,20,2,biomesoplenty:hard_ice:0)
Block(-9,20,3,biomesoplenty:hard_ice:0)
Block(-9,20,4,biomesoplenty:hard_ice:0)
Block(-9,20,5,biomesoplenty:hard_ice:0)
Block(-9,20,6,biomesoplenty:hard_ice:0)
Block(-9,20,7,biomesoplenty:hard_ice:0)
Block(-9,20,8,biomesoplenty:hard_ice:0)
Block(-9,20,9,biomesoplenty:hard_ice:0)
Block(-9,20,10,biomesoplenty:hard_ice:0)
Block(-9,20,11,biomesoplenty:hard_ice:0)
Block(-9,20,12,biomesoplenty:hard_ice:0)
Block(-9,20,13,biomesoplenty:hard_ice:0)
Block(-9,20,14,biomesoplenty:hard_ice:0)
Block(-9,20,15,biomesoplenty:hard_ice:0)
Block(-9,20,16,biomesoplenty:hard_ice:0)
Block(-9,20,17,biomesoplenty:hard_ice:0)
Block(-9,20,18,biomesoplenty:hard_ice:0)
Block(-9,20,19,biomesoplenty:hard_ice:0)
Block(-9,21,-5,biomesoplenty:hard_ice:0)
Block(-9,21,-4,biomesoplenty:hard_ice:0)
Block(-9,21,-3,biomesoplenty:hard_ice:0)
Block(-9,21,-2,biomesoplenty:hard_ice:0)
Block(-9,21,-1,biomesoplenty:hard_ice:0)
Block(-9,21,0,biomesoplenty:hard_ice:0)
Block(-9,21,1,biomesoplenty:hard_ice:0)
Block(-9,21,2,biomesoplenty:hard_ice:0)
Block(-9,21,3,biomesoplenty:hard_ice:0)
Block(-9,21,4,biomesoplenty:hard_ice:0)
Block(-9,21,5,biomesoplenty:hard_ice:0)
Block(-9,21,6,biomesoplenty:hard_ice:0)
Block(-9,21,7,biomesoplenty:hard_ice:0)
Block(-9,21,8,biomesoplenty:hard_ice:0)
Block(-9,21,9,biomesoplenty:hard_ice:0)
Block(-9,21,10,biomesoplenty:hard_ice:0)
Block(-9,21,11,biomesoplenty:hard_ice:0)
Block(-9,21,12,biomesoplenty:hard_ice:0)
Block(-9,21,13,biomesoplenty:hard_ice:0)
Block(-9,21,14,biomesoplenty:hard_ice:0)
Block(-9,21,15,biomesoplenty:hard_ice:0)
Block(-9,21,16,biomesoplenty:hard_ice:0)
Block(-9,21,17,biomesoplenty:hard_ice:0)
Block(-9,21,18,biomesoplenty:hard_ice:0)
Block(-9,21,19,biomesoplenty:hard_ice:0)
Block(-9,22,-4,biomesoplenty:hard_ice:0)
Block(-9,22,-3,biomesoplenty:hard_ice:0)
Block(-9,22,-2,biomesoplenty:hard_ice:0)
Block(-9,22,-1,biomesoplenty:hard_ice:0)
Block(-9,22,0,biomesoplenty:hard_ice:0)
Block(-9,22,1,biomesoplenty:hard_ice:0)
Block(-9,22,2,biomesoplenty:hard_ice:0)
Block(-9,22,3,biomesoplenty:hard_ice:0)
Block(-9,22,4,biomesoplenty:hard_ice:0)
Block(-9,22,5,biomesoplenty:hard_ice:0)
Block(-9,22,6,biomesoplenty:hard_ice:0)
Block(-9,22,7,biomesoplenty:hard_ice:0)
Block(-9,22,8,biomesoplenty:hard_ice:0)
Block(-9,22,9,biomesoplenty:hard_ice:0)
Block(-9,22,10,biomesoplenty:hard_ice:0)
Block(-9,22,11,biomesoplenty:hard_ice:0)
Block(-9,22,12,biomesoplenty:hard_ice:0)
Block(-9,22,13,biomesoplenty:hard_ice:0)
Block(-9,22,14,biomesoplenty:hard_ice:0)
Block(-9,22,15,biomesoplenty:hard_ice:0)
Block(-9,22,16,biomesoplenty:hard_ice:0)
Block(-9,22,17,biomesoplenty:hard_ice:0)
Block(-9,22,18,biomesoplenty:hard_ice:0)
Block(-9,23,-4,biomesoplenty:hard_ice:0)
Block(-9,23,-3,biomesoplenty:hard_ice:0)
Block(-9,23,-2,biomesoplenty:hard_ice:0)
Block(-9,23,-1,biomesoplenty:hard_ice:0)
Block(-9,23,0,biomesoplenty:hard_ice:0)
Block(-9,23,1,biomesoplenty:hard_ice:0)
Block(-9,23,2,biomesoplenty:hard_ice:0)
Block(-9,23,3,biomesoplenty:hard_ice:0)
Block(-9,23,4,biomesoplenty:hard_ice:0)
Block(-9,23,5,biomesoplenty:hard_ice:0)
Block(-9,23,6,biomesoplenty:hard_ice:0)
Block(-9,23,7,biomesoplenty:hard_ice:0)
Block(-9,23,8,biomesoplenty:hard_ice:0)
Block(-9,23,9,biomesoplenty:hard_ice:0)
Block(-9,23,10,biomesoplenty:hard_ice:0)
Block(-9,23,11,biomesoplenty:hard_ice:0)
Block(-9,23,12,biomesoplenty:hard_ice:0)
Block(-9,23,13,biomesoplenty:hard_ice:0)
Block(-9,23,14,biomesoplenty:hard_ice:0)
Block(-9,23,15,biomesoplenty:hard_ice:0)
Block(-9,23,16,biomesoplenty:hard_ice:0)
Block(-9,23,17,biomesoplenty:hard_ice:0)
Block(-9,24,-4,biomesoplenty:hard_ice:0)
Block(-9,24,-3,biomesoplenty:hard_ice:0)
Block(-9,24,-2,biomesoplenty:hard_ice:0)
Block(-9,24,-1,biomesoplenty:hard_ice:0)
Block(-9,24,0,biomesoplenty:hard_ice:0)
Block(-9,24,1,biomesoplenty:hard_ice:0)
Block(-9,24,2,biomesoplenty:hard_ice:0)
Block(-9,24,3,biomesoplenty:hard_ice:0)
Block(-9,24,4,biomesoplenty:hard_ice:0)
Block(-9,24,5,biomesoplenty:hard_ice:0)
Block(-9,24,6,biomesoplenty:hard_ice:0)
Block(-9,24,7,biomesoplenty:hard_ice:0)
Block(-9,24,8,biomesoplenty:hard_ice:0)
Block(-9,24,9,biomesoplenty:hard_ice:0)
Block(-9,24,10,biomesoplenty:hard_ice:0)
Block(-9,24,11,biomesoplenty:hard_ice:0)
Block(-9,24,12,biomesoplenty:hard_ice:0)
Block(-9,24,13,biomesoplenty:hard_ice:0)
Block(-9,24,14,biomesoplenty:hard_ice:0)
Block(-9,24,15,biomesoplenty:hard_ice:0)
Block(-9,24,16,biomesoplenty:hard_ice:0)
Block(-9,25,-3,biomesoplenty:hard_ice:0)
Block(-9,25,-2,biomesoplenty:hard_ice:0)
Block(-9,25,-1,biomesoplenty:hard_ice:0)
Block(-9,25,0,biomesoplenty:hard_ice:0)
Block(-9,25,1,biomesoplenty:hard_ice:0)
Block(-9,25,2,biomesoplenty:hard_ice:0)
Block(-9,25,3,biomesoplenty:hard_ice:0)
Block(-9,25,4,biomesoplenty:hard_ice:0)
Block(-9,25,5,biomesoplenty:hard_ice:0)
Block(-9,25,6,biomesoplenty:hard_ice:0)
Block(-9,25,7,biomesoplenty:hard_ice:0)
Block(-9,25,8,biomesoplenty:hard_ice:0)
Block(-9,25,9,biomesoplenty:hard_ice:0)
Block(-9,25,10,biomesoplenty:hard_ice:0)
Block(-9,25,11,biomesoplenty:hard_ice:0)
Block(-9,25,12,biomesoplenty:hard_ice:0)
Block(-9,25,13,biomesoplenty:hard_ice:0)
Block(-9,25,14,biomesoplenty:hard_ice:0)
Block(-9,25,15,biomesoplenty:hard_ice:0)
Block(-9,26,-2,biomesoplenty:hard_ice:0)
Block(-9,26,-1,biomesoplenty:hard_ice:0)
Block(-9,26,0,biomesoplenty:hard_ice:0)
Block(-9,26,1,biomesoplenty:hard_ice:0)
Block(-9,26,2,biomesoplenty:hard_ice:0)
Block(-9,26,3,biomesoplenty:hard_ice:0)
Block(-9,26,4,biomesoplenty:hard_ice:0)
Block(-9,26,5,biomesoplenty:hard_ice:0)
Block(-9,26,6,biomesoplenty:hard_ice:0)
Block(-9,26,7,biomesoplenty:hard_ice:0)
Block(-9,26,8,biomesoplenty:hard_ice:0)
Block(-9,26,9,biomesoplenty:hard_ice:0)
Block(-9,26,10,biomesoplenty:hard_ice:0)
Block(-9,26,11,biomesoplenty:hard_ice:0)
Block(-9,26,12,biomesoplenty:hard_ice:0)
Block(-9,26,13,biomesoplenty:hard_ice:0)
Block(-9,26,14,biomesoplenty:hard_ice:0)
Block(-9,27,-2,biomesoplenty:hard_ice:0)
Block(-9,27,-1,biomesoplenty:hard_ice:0)
Block(-9,27,0,biomesoplenty:hard_ice:0)
Block(-9,27,1,biomesoplenty:hard_ice:0)
Block(-9,27,2,biomesoplenty:hard_ice:0)
Block(-9,27,3,biomesoplenty:hard_ice:0)
Block(-9,27,4,biomesoplenty:hard_ice:0)
Block(-9,27,5,biomesoplenty:hard_ice:0)
Block(-9,27,6,biomesoplenty:hard_ice:0)
Block(-9,27,7,biomesoplenty:hard_ice:0)
Block(-9,27,8,biomesoplenty:hard_ice:0)
Block(-9,27,9,biomesoplenty:hard_ice:0)
Block(-9,27,10,biomesoplenty:hard_ice:0)
Block(-9,27,11,biomesoplenty:hard_ice:0)
Block(-9,27,12,biomesoplenty:hard_ice:0)
Block(-9,27,13,biomesoplenty:hard_ice:0)
Block(-9,28,-1,biomesoplenty:hard_ice:0)
Block(-9,28,0,biomesoplenty:hard_ice:0)
Block(-9,28,1,biomesoplenty:hard_ice:0)
Block(-9,28,2,biomesoplenty:hard_ice:0)
Block(-9,28,3,biomesoplenty:hard_ice:0)
Block(-9,28,4,biomesoplenty:hard_ice:0)
Block(-9,28,5,biomesoplenty:hard_ice:0)
Block(-9,28,6,biomesoplenty:hard_ice:0)
Block(-9,28,7,biomesoplenty:hard_ice:0)
Block(-9,28,8,biomesoplenty:hard_ice:0)
Block(-9,28,9,biomesoplenty:hard_ice:0)
Block(-9,28,10,biomesoplenty:hard_ice:0)
Block(-9,28,11,biomesoplenty:hard_ice:0)
Block(-9,28,12,biomesoplenty:hard_ice:0)
Block(-9,29,0,biomesoplenty:hard_ice:0)
Block(-9,29,1,biomesoplenty:hard_ice:0)
Block(-9,29,2,biomesoplenty:hard_ice:0)
Block(-9,29,3,biomesoplenty:hard_ice:0)
Block(-9,29,4,biomesoplenty:hard_ice:0)
Block(-9,29,5,biomesoplenty:hard_ice:0)
Block(-9,29,6,biomesoplenty:hard_ice:0)
Block(-9,29,7,biomesoplenty:hard_ice:0)
Block(-9,29,8,biomesoplenty:hard_ice:0)
Block(-9,29,9,biomesoplenty:hard_ice:0)
Block(-9,29,10,biomesoplenty:hard_ice:0)
Block(-9,29,11,biomesoplenty:hard_ice:0)
Block(-9,30,2,biomesoplenty:hard_ice:0)
Block(-9,30,3,biomesoplenty:hard_ice:0)
Block(-9,30,4,biomesoplenty:hard_ice:0)
Block(-9,30,5,biomesoplenty:hard_ice:0)
Block(-9,30,6,biomesoplenty:hard_ice:0)
Block(-9,30,7,biomesoplenty:hard_ice:0)
Block(-9,30,8,biomesoplenty:hard_ice:0)
Block(-9,30,9,biomesoplenty:hard_ice:0)
Block(-9,30,10,biomesoplenty:hard_ice:0)
Block(-9,31,4,biomesoplenty:hard_ice:0)
Block(-9,31,5,biomesoplenty:hard_ice:0)
Block(-9,31,6,biomesoplenty:hard_ice:0)
Block(-9,31,7,biomesoplenty:hard_ice:0)
Block(-9,31,8,biomesoplenty:hard_ice:0)
Block(-9,32,5,biomesoplenty:hard_ice:0)
Block(-9,32,6,biomesoplenty:hard_ice:0)
Block(-9,32,7,biomesoplenty:hard_ice:0)
Block(-8,8,3,biomesoplenty:hard_ice:0)
Block(-8,8,4,biomesoplenty:hard_ice:0)
Block(-8,8,5,biomesoplenty:hard_ice:0)
Block(-8,8,6,biomesoplenty:hard_ice:0)
Block(-8,8,7,biomesoplenty:hard_ice:0)
Block(-8,9,0,biomesoplenty:hard_ice:0)
Block(-8,9,1,biomesoplenty:hard_ice:0)
Block(-8,9,2,biomesoplenty:hard_ice:0)
Block(-8,9,3,biomesoplenty:hard_ice:0)
Block(-8,9,4,biomesoplenty:hard_ice:0)
Block(-8,9,5,biomesoplenty:hard_ice:0)
Block(-8,9,6,biomesoplenty:hard_ice:0)
Block(-8,9,7,biomesoplenty:hard_ice:0)
Block(-8,9,8,biomesoplenty:hard_ice:0)
Block(-8,9,9,biomesoplenty:hard_ice:0)
Block(-8,10,-5,biomesoplenty:hard_ice:0)
Block(-8,10,-4,biomesoplenty:hard_ice:0)
Block(-8,10,-3,biomesoplenty:hard_ice:0)
Block(-8,10,-2,biomesoplenty:hard_ice:0)
Block(-8,10,-1,biomesoplenty:hard_ice:0)
Block(-8,10,0,biomesoplenty:hard_ice:0)
Block(-8,10,1,biomesoplenty:hard_ice:0)
Block(-8,10,2,biomesoplenty:hard_ice:0)
Block(-8,10,3,biomesoplenty:hard_ice:0)
Block(-8,10,4,biomesoplenty:hard_ice:0)
Block(-8,10,5,biomesoplenty:hard_ice:0)
Block(-8,10,6,biomesoplenty:hard_ice:0)
Block(-8,10,7,biomesoplenty:hard_ice:0)
Block(-8,10,8,biomesoplenty:hard_ice:0)
Block(-8,10,9,biomesoplenty:hard_ice:0)
Block(-8,10,10,biomesoplenty:hard_ice:0)
Block(-8,11,-9,biomesoplenty:hard_ice:0)
Block(-8,11,-8,biomesoplenty:hard_ice:0)
Block(-8,11,-7,biomesoplenty:hard_ice:0)
Block(-8,11,-6,biomesoplenty:hard_ice:0)
Block(-8,11,-5,biomesoplenty:hard_ice:0)
Block(-8,11,-4,biomesoplenty:hard_ice:0)
Block(-8,11,-3,biomesoplenty:hard_ice:0)
Block(-8,11,-2,biomesoplenty:hard_ice:0)
Block(-8,11,-1,biomesoplenty:hard_ice:0)
Block(-8,11,0,biomesoplenty:hard_ice:0)
Block(-8,11,1,biomesoplenty:hard_ice:0)
Block(-8,11,2,biomesoplenty:hard_ice:0)
Block(-8,11,3,biomesoplenty:hard_ice:0)
Block(-8,11,4,biomesoplenty:hard_ice:0)
Block(-8,11,5,biomesoplenty:hard_ice:0)
Block(-8,11,6,biomesoplenty:hard_ice:0)
Block(-8,11,7,biomesoplenty:hard_ice:0)
Block(-8,11,8,biomesoplenty:hard_ice:0)
Block(-8,11,9,biomesoplenty:hard_ice:0)
Block(-8,11,10,biomesoplenty:hard_ice:0)
Block(-8,11,11,biomesoplenty:hard_ice:0)
Block(-8,11,12,biomesoplenty:hard_ice:0)
Block(-8,12,-9,biomesoplenty:hard_ice:0)
Block(-8,12,-8,biomesoplenty:hard_ice:0)
Block(-8,12,-7,biomesoplenty:hard_ice:0)
Block(-8,12,-6,biomesoplenty:hard_ice:0)
Block(-8,12,-5,biomesoplenty:hard_ice:0)
Block(-8,12,-4,biomesoplenty:hard_ice:0)
Block(-8,12,-3,biomesoplenty:hard_ice:0)
Block(-8,12,-2,biomesoplenty:hard_ice:0)
Block(-8,12,-1,biomesoplenty:hard_ice:0)
Block(-8,12,0,biomesoplenty:hard_ice:0)
Block(-8,12,1,biomesoplenty:hard_ice:0)
Block(-8,12,2,biomesoplenty:hard_ice:0)
Block(-8,12,3,biomesoplenty:hard_ice:0)
Block(-8,12,4,biomesoplenty:hard_ice:0)
Block(-8,12,5,biomesoplenty:hard_ice:0)
Block(-8,12,6,biomesoplenty:hard_ice:0)
Block(-8,12,7,biomesoplenty:hard_ice:0)
Block(-8,12,8,biomesoplenty:hard_ice:0)
Block(-8,12,9,biomesoplenty:hard_ice:0)
Block(-8,12,10,biomesoplenty:hard_ice:0)
Block(-8,12,11,biomesoplenty:hard_ice:0)
Block(-8,12,12,biomesoplenty:hard_ice:0)
Block(-8,12,13,biomesoplenty:hard_ice:0)
Block(-8,12,14,biomesoplenty:hard_ice:0)
Block(-8,13,-9,biomesoplenty:hard_ice:0)
Block(-8,13,-8,biomesoplenty:hard_ice:0)
Block(-8,13,-7,biomesoplenty:hard_ice:0)
Block(-8,13,-6,biomesoplenty:hard_ice:0)
Block(-8,13,-5,biomesoplenty:hard_ice:0)
Block(-8,13,-4,biomesoplenty:hard_ice:0)
Block(-8,13,-3,biomesoplenty:hard_ice:0)
Block(-8,13,-2,biomesoplenty:hard_ice:0)
Block(-8,13,-1,biomesoplenty:hard_ice:0)
Block(-8,13,0,biomesoplenty:hard_ice:0)
Block(-8,13,1,biomesoplenty:hard_ice:0)
Block(-8,13,2,biomesoplenty:hard_ice:0)
Block(-8,13,3,biomesoplenty:hard_ice:0)
Block(-8,13,4,biomesoplenty:hard_ice:0)
Block(-8,13,5,biomesoplenty:hard_ice:0)
Block(-8,13,6,biomesoplenty:hard_ice:0)
Block(-8,13,7,biomesoplenty:hard_ice:0)
Block(-8,13,8,biomesoplenty:hard_ice:0)
Block(-8,13,9,biomesoplenty:hard_ice:0)
Block(-8,13,10,biomesoplenty:hard_ice:0)
Block(-8,13,11,biomesoplenty:hard_ice:0)
Block(-8,13,12,biomesoplenty:hard_ice:0)
Block(-8,13,13,biomesoplenty:hard_ice:0)
Block(-8,13,14,biomesoplenty:hard_ice:0)
Block(-8,13,15,biomesoplenty:hard_ice:0)
Block(-8,13,16,biomesoplenty:hard_ice:0)
Block(-8,13,17,biomesoplenty:hard_ice:0)
Block(-8,13,18,biomesoplenty:hard_ice:0)
Block(-8,13,19,biomesoplenty:hard_ice:0)
Block(-8,14,-9,biomesoplenty:hard_ice:0)
Block(-8,14,-8,biomesoplenty:hard_ice:0)
Block(-8,14,-7,biomesoplenty:hard_ice:0)
Block(-8,14,-6,biomesoplenty:hard_ice:0)
Block(-8,14,-5,biomesoplenty:hard_ice:0)
Block(-8,14,-4,biomesoplenty:hard_ice:0)
Block(-8,14,-3,biomesoplenty:hard_ice:0)
Block(-8,14,-2,biomesoplenty:hard_ice:0)
Block(-8,14,-1,biomesoplenty:hard_ice:0)
Block(-8,14,0,biomesoplenty:hard_ice:0)
Block(-8,14,1,biomesoplenty:hard_ice:0)
Block(-8,14,2,biomesoplenty:hard_ice:0)
Block(-8,14,3,biomesoplenty:hard_ice:0)
Block(-8,14,4,biomesoplenty:hard_ice:0)
Block(-8,14,5,biomesoplenty:hard_ice:0)
Block(-8,14,6,biomesoplenty:hard_ice:0)
Block(-8,14,7,biomesoplenty:hard_ice:0)
Block(-8,14,8,biomesoplenty:hard_ice:0)
Block(-8,14,9,biomesoplenty:hard_ice:0)
Block(-8,14,10,biomesoplenty:hard_ice:0)
Block(-8,14,11,biomesoplenty:hard_ice:0)
Block(-8,14,12,biomesoplenty:hard_ice:0)
Block(-8,14,13,biomesoplenty:hard_ice:0)
Block(-8,14,14,biomesoplenty:hard_ice:0)
Block(-8,14,15,biomesoplenty:hard_ice:0)
Block(-8,14,16,biomesoplenty:hard_ice:0)
Block(-8,14,17,biomesoplenty:hard_ice:0)
Block(-8,14,18,biomesoplenty:hard_ice:0)
Block(-8,14,19,biomesoplenty:hard_ice:0)
Block(-8,15,-9,biomesoplenty:hard_ice:0)
Block(-8,15,-8,biomesoplenty:hard_ice:0)
Block(-8,15,-7,biomesoplenty:hard_ice:0)
Block(-8,15,-6,biomesoplenty:hard_ice:0)
Block(-8,15,-5,biomesoplenty:hard_ice:0)
Block(-8,15,-4,biomesoplenty:hard_ice:0)
Block(-8,15,-3,biomesoplenty:hard_ice:0)
Block(-8,15,-2,biomesoplenty:hard_ice:0)
Block(-8,15,-1,biomesoplenty:hard_ice:0)
Block(-8,15,0,biomesoplenty:hard_ice:0)
Block(-8,15,1,biomesoplenty:hard_ice:0)
Block(-8,15,2,biomesoplenty:hard_ice:0)
Block(-8,15,3,biomesoplenty:hard_ice:0)
Block(-8,15,4,biomesoplenty:hard_ice:0)
Block(-8,15,5,biomesoplenty:hard_ice:0)
Block(-8,15,6,biomesoplenty:hard_ice:0)
Block(-8,15,7,biomesoplenty:hard_ice:0)
Block(-8,15,8,biomesoplenty:hard_ice:0)
Block(-8,15,9,biomesoplenty:hard_ice:0)
Block(-8,15,10,biomesoplenty:hard_ice:0)
Block(-8,15,11,biomesoplenty:hard_ice:0)
Block(-8,15,12,biomesoplenty:hard_ice:0)
Block(-8,15,13,biomesoplenty:hard_ice:0)
Block(-8,15,14,biomesoplenty:hard_ice:0)
Block(-8,15,15,biomesoplenty:hard_ice:0)
Block(-8,15,16,biomesoplenty:hard_ice:0)
Block(-8,15,17,biomesoplenty:hard_ice:0)
Block(-8,15,18,biomesoplenty:hard_ice:0)
Block(-8,15,19,biomesoplenty:hard_ice:0)
Block(-8,16,-8,biomesoplenty:hard_ice:0)
Block(-8,16,-7,biomesoplenty:hard_ice:0)
Block(-8,16,-6,biomesoplenty:hard_ice:0)
Block(-8,16,-5,biomesoplenty:hard_ice:0)
Block(-8,16,-4,biomesoplenty:hard_ice:0)
Block(-8,16,-3,biomesoplenty:hard_ice:0)
Block(-8,16,-2,biomesoplenty:hard_ice:0)
Block(-8,16,-1,biomesoplenty:hard_ice:0)
Block(-8,16,0,biomesoplenty:hard_ice:0)
Block(-8,16,1,biomesoplenty:hard_ice:0)
Block(-8,16,2,biomesoplenty:hard_ice:0)
Block(-8,16,3,biomesoplenty:hard_ice:0)
Block(-8,16,4,biomesoplenty:hard_ice:0)
Block(-8,16,5,biomesoplenty:hard_ice:0)
Block(-8,16,6,biomesoplenty:hard_ice:0)
Block(-8,16,7,biomesoplenty:hard_ice:0)
Block(-8,16,8,biomesoplenty:hard_ice:0)
Block(-8,16,9,biomesoplenty:hard_ice:0)
Block(-8,16,10,biomesoplenty:hard_ice:0)
Block(-8,16,11,biomesoplenty:hard_ice:0)
Block(-8,16,12,biomesoplenty:hard_ice:0)
Block(-8,16,13,biomesoplenty:hard_ice:0)
Block(-8,16,14,biomesoplenty:hard_ice:0)
Block(-8,16,15,biomesoplenty:hard_ice:0)
Block(-8,16,16,biomesoplenty:hard_ice:0)
Block(-8,16,17,biomesoplenty:hard_ice:0)
Block(-8,16,18,biomesoplenty:hard_ice:0)
Block(-8,16,19,biomesoplenty:hard_ice:0)
Block(-8,17,-8,biomesoplenty:hard_ice:0)
Block(-8,17,-7,biomesoplenty:hard_ice:0)
Block(-8,17,-6,biomesoplenty:hard_ice:0)
Block(-8,17,-5,biomesoplenty:hard_ice:0)
Block(-8,17,-4,biomesoplenty:hard_ice:0)
Block(-8,17,-3,biomesoplenty:hard_ice:0)
Block(-8,17,-2,biomesoplenty:hard_ice:0)
Block(-8,17,-1,biomesoplenty:hard_ice:0)
Block(-8,17,0,biomesoplenty:hard_ice:0)
Block(-8,17,1,biomesoplenty:hard_ice:0)
Block(-8,17,2,biomesoplenty:hard_ice:0)
Block(-8,17,3,biomesoplenty:hard_ice:0)
Block(-8,17,4,biomesoplenty:hard_ice:0)
Block(-8,17,5,biomesoplenty:hard_ice:0)
Block(-8,17,6,biomesoplenty:hard_ice:0)
Block(-8,17,7,biomesoplenty:hard_ice:0)
Block(-8,17,8,biomesoplenty:hard_ice:0)
Block(-8,17,9,biomesoplenty:hard_ice:0)
Block(-8,17,10,biomesoplenty:hard_ice:0)
Block(-8,17,11,biomesoplenty:hard_ice:0)
Block(-8,17,12,biomesoplenty:hard_ice:0)
Block(-8,17,13,biomesoplenty:hard_ice:0)
Block(-8,17,14,biomesoplenty:hard_ice:0)
Block(-8,17,15,biomesoplenty:hard_ice:0)
Block(-8,17,16,biomesoplenty:hard_ice:0)
Block(-8,17,17,biomesoplenty:hard_ice:0)
Block(-8,17,18,biomesoplenty:hard_ice:0)
Block(-8,17,19,biomesoplenty:hard_ice:0)
Block(-8,18,-7,biomesoplenty:hard_ice:0)
Block(-8,18,-6,biomesoplenty:hard_ice:0)
Block(-8,18,-5,biomesoplenty:hard_ice:0)
Block(-8,18,-4,biomesoplenty:hard_ice:0)
Block(-8,18,-3,biomesoplenty:hard_ice:0)
Block(-8,18,-2,biomesoplenty:hard_ice:0)
Block(-8,18,-1,biomesoplenty:hard_ice:0)
Block(-8,18,0,biomesoplenty:hard_ice:0)
Block(-8,18,1,biomesoplenty:hard_ice:0)
Block(-8,18,2,biomesoplenty:hard_ice:0)
Block(-8,18,3,biomesoplenty:hard_ice:0)
Block(-8,18,4,biomesoplenty:hard_ice:0)
Block(-8,18,5,biomesoplenty:hard_ice:0)
Block(-8,18,6,biomesoplenty:hard_ice:0)
Block(-8,18,7,biomesoplenty:hard_ice:0)
Block(-8,18,8,biomesoplenty:hard_ice:0)
Block(-8,18,9,biomesoplenty:hard_ice:0)
Block(-8,18,10,biomesoplenty:hard_ice:0)
Block(-8,18,11,biomesoplenty:hard_ice:0)
Block(-8,18,12,biomesoplenty:hard_ice:0)
Block(-8,18,13,biomesoplenty:hard_ice:0)
Block(-8,18,14,biomesoplenty:hard_ice:0)
Block(-8,18,15,biomesoplenty:hard_ice:0)
Block(-8,18,16,biomesoplenty:hard_ice:0)
Block(-8,18,17,biomesoplenty:hard_ice:0)
Block(-8,18,18,biomesoplenty:hard_ice:0)
Block(-8,18,19,biomesoplenty:hard_ice:0)
Block(-8,19,-7,biomesoplenty:hard_ice:0)
Block(-8,19,-6,biomesoplenty:hard_ice:0)
Block(-8,19,-5,biomesoplenty:hard_ice:0)
Block(-8,19,-4,biomesoplenty:hard_ice:0)
Block(-8,19,-3,biomesoplenty:hard_ice:0)
Block(-8,19,-2,biomesoplenty:hard_ice:0)
Block(-8,19,-1,biomesoplenty:hard_ice:0)
Block(-8,19,0,biomesoplenty:hard_ice:0)
Block(-8,19,1,biomesoplenty:hard_ice:0)
Block(-8,19,2,biomesoplenty:hard_ice:0)
Block(-8,19,3,biomesoplenty:hard_ice:0)
Block(-8,19,4,biomesoplenty:hard_ice:0)
Block(-8,19,5,biomesoplenty:hard_ice:0)
Block(-8,19,6,biomesoplenty:hard_ice:0)
Block(-8,19,7,biomesoplenty:hard_ice:0)
Block(-8,19,8,biomesoplenty:hard_ice:0)
Block(-8,19,9,biomesoplenty:hard_ice:0)
Block(-8,19,10,biomesoplenty:hard_ice:0)
Block(-8,19,11,biomesoplenty:hard_ice:0)
Block(-8,19,12,biomesoplenty:hard_ice:0)
Block(-8,19,13,biomesoplenty:hard_ice:0)
Block(-8,19,14,biomesoplenty:hard_ice:0)
Block(-8,19,15,biomesoplenty:hard_ice:0)
Block(-8,19,16,biomesoplenty:hard_ice:0)
Block(-8,19,17,biomesoplenty:hard_ice:0)
Block(-8,19,18,biomesoplenty:hard_ice:0)
Block(-8,19,19,biomesoplenty:hard_ice:0)
Block(-8,20,-6,biomesoplenty:hard_ice:0)
Block(-8,20,-5,biomesoplenty:hard_ice:0)
Block(-8,20,-4,biomesoplenty:hard_ice:0)
Block(-8,20,-3,biomesoplenty:hard_ice:0)
Block(-8,20,-2,biomesoplenty:hard_ice:0)
Block(-8,20,-1,biomesoplenty:hard_ice:0)
Block(-8,20,0,biomesoplenty:hard_ice:0)
Block(-8,20,1,biomesoplenty:hard_ice:0)
Block(-8,20,2,biomesoplenty:hard_ice:0)
Block(-8,20,3,biomesoplenty:hard_ice:0)
Block(-8,20,4,biomesoplenty:hard_ice:0)
Block(-8,20,5,biomesoplenty:hard_ice:0)
Block(-8,20,6,biomesoplenty:hard_ice:0)
Block(-8,20,7,biomesoplenty:hard_ice:0)
Block(-8,20,8,biomesoplenty:hard_ice:0)
Block(-8,20,9,biomesoplenty:hard_ice:0)
Block(-8,20,10,biomesoplenty:hard_ice:0)
Block(-8,20,11,biomesoplenty:hard_ice:0)
Block(-8,20,12,biomesoplenty:hard_ice:0)
Block(-8,20,13,biomesoplenty:hard_ice:0)
Block(-8,20,14,biomesoplenty:hard_ice:0)
Block(-8,20,15,biomesoplenty:hard_ice:0)
Block(-8,20,16,biomesoplenty:hard_ice:0)
Block(-8,20,17,biomesoplenty:hard_ice:0)
Block(-8,20,18,biomesoplenty:hard_ice:0)
Block(-8,20,19,biomesoplenty:hard_ice:0)
Block(-8,21,-5,biomesoplenty:hard_ice:0)
Block(-8,21,-4,biomesoplenty:hard_ice:0)
Block(-8,21,-3,biomesoplenty:hard_ice:0)
Block(-8,21,-2,biomesoplenty:hard_ice:0)
Block(-8,21,-1,biomesoplenty:hard_ice:0)
Block(-8,21,0,biomesoplenty:hard_ice:0)
Block(-8,21,1,biomesoplenty:hard_ice:0)
Block(-8,21,2,biomesoplenty:hard_ice:0)
Block(-8,21,3,biomesoplenty:hard_ice:0)
Block(-8,21,4,biomesoplenty:hard_ice:0)
Block(-8,21,5,biomesoplenty:hard_ice:0)
Block(-8,21,6,biomesoplenty:hard_ice:0)
Block(-8,21,7,biomesoplenty:hard_ice:0)
Block(-8,21,8,biomesoplenty:hard_ice:0)
Block(-8,21,9,biomesoplenty:hard_ice:0)
Block(-8,21,10,biomesoplenty:hard_ice:0)
Block(-8,21,11,biomesoplenty:hard_ice:0)
Block(-8,21,12,biomesoplenty:hard_ice:0)
Block(-8,21,13,biomesoplenty:hard_ice:0)
Block(-8,21,14,biomesoplenty:hard_ice:0)
Block(-8,21,15,biomesoplenty:hard_ice:0)
Block(-8,21,16,biomesoplenty:hard_ice:0)
Block(-8,21,17,biomesoplenty:hard_ice:0)
Block(-8,21,18,biomesoplenty:hard_ice:0)
Block(-8,21,19,biomesoplenty:hard_ice:0)
Block(-8,22,-4,biomesoplenty:hard_ice:0)
Block(-8,22,-3,biomesoplenty:hard_ice:0)
Block(-8,22,-2,biomesoplenty:hard_ice:0)
Block(-8,22,-1,biomesoplenty:hard_ice:0)
Block(-8,22,0,biomesoplenty:hard_ice:0)
Block(-8,22,1,biomesoplenty:hard_ice:0)
Block(-8,22,2,biomesoplenty:hard_ice:0)
Block(-8,22,3,biomesoplenty:hard_ice:0)
Block(-8,22,4,biomesoplenty:hard_ice:0)
Block(-8,22,5,biomesoplenty:hard_ice:0)
Block(-8,22,6,biomesoplenty:hard_ice:0)
Block(-8,22,7,biomesoplenty:hard_ice:0)
Block(-8,22,8,biomesoplenty:hard_ice:0)
Block(-8,22,9,biomesoplenty:hard_ice:0)
Block(-8,22,10,biomesoplenty:hard_ice:0)
Block(-8,22,11,biomesoplenty:hard_ice:0)
Block(-8,22,12,biomesoplenty:hard_ice:0)
Block(-8,22,13,biomesoplenty:hard_ice:0)
Block(-8,22,14,biomesoplenty:hard_ice:0)
Block(-8,22,15,biomesoplenty:hard_ice:0)
Block(-8,22,16,biomesoplenty:hard_ice:0)
Block(-8,22,17,biomesoplenty:hard_ice:0)
Block(-8,22,18,biomesoplenty:hard_ice:0)
Block(-8,22,19,biomesoplenty:hard_ice:0)
Block(-8,23,-4,biomesoplenty:hard_ice:0)
Block(-8,23,-3,biomesoplenty:hard_ice:0)
Block(-8,23,-2,biomesoplenty:hard_ice:0)
Block(-8,23,-1,biomesoplenty:hard_ice:0)
Block(-8,23,0,biomesoplenty:hard_ice:0)
Block(-8,23,1,biomesoplenty:hard_ice:0)
Block(-8,23,2,biomesoplenty:hard_ice:0)
Block(-8,23,3,biomesoplenty:hard_ice:0)
Block(-8,23,4,biomesoplenty:hard_ice:0)
Block(-8,23,5,biomesoplenty:hard_ice:0)
Block(-8,23,6,biomesoplenty:hard_ice:0)
Block(-8,23,7,biomesoplenty:hard_ice:0)
Block(-8,23,8,biomesoplenty:hard_ice:0)
Block(-8,23,9,biomesoplenty:hard_ice:0)
Block(-8,23,10,biomesoplenty:hard_ice:0)
Block(-8,23,11,biomesoplenty:hard_ice:0)
Block(-8,23,12,biomesoplenty:hard_ice:0)
Block(-8,23,13,biomesoplenty:hard_ice:0)
Block(-8,23,14,biomesoplenty:hard_ice:0)
Block(-8,23,15,biomesoplenty:hard_ice:0)
Block(-8,23,16,biomesoplenty:hard_ice:0)
Block(-8,23,17,biomesoplenty:hard_ice:0)
Block(-8,23,18,biomesoplenty:hard_ice:0)
Block(-8,24,-4,biomesoplenty:hard_ice:0)
Block(-8,24,-3,biomesoplenty:hard_ice:0)
Block(-8,24,-2,biomesoplenty:hard_ice:0)
Block(-8,24,-1,biomesoplenty:hard_ice:0)
Block(-8,24,0,biomesoplenty:hard_ice:0)
Block(-8,24,1,biomesoplenty:hard_ice:0)
Block(-8,24,2,biomesoplenty:hard_ice:0)
Block(-8,24,3,biomesoplenty:hard_ice:0)
Block(-8,24,4,biomesoplenty:hard_ice:0)
Block(-8,24,5,biomesoplenty:hard_ice:0)
Block(-8,24,6,biomesoplenty:hard_ice:0)
Block(-8,24,7,biomesoplenty:hard_ice:0)
Block(-8,24,8,biomesoplenty:hard_ice:0)
Block(-8,24,9,biomesoplenty:hard_ice:0)
Block(-8,24,10,biomesoplenty:hard_ice:0)
Block(-8,24,11,biomesoplenty:hard_ice:0)
Block(-8,24,12,biomesoplenty:hard_ice:0)
Block(-8,24,13,biomesoplenty:hard_ice:0)
Block(-8,24,14,biomesoplenty:hard_ice:0)
Block(-8,24,15,biomesoplenty:hard_ice:0)
Block(-8,24,16,biomesoplenty:hard_ice:0)
Block(-8,24,17,biomesoplenty:hard_ice:0)
Block(-8,25,-3,biomesoplenty:hard_ice:0)
Block(-8,25,-2,biomesoplenty:hard_ice:0)
Block(-8,25,-1,biomesoplenty:hard_ice:0)
Block(-8,25,0,biomesoplenty:hard_ice:0)
Block(-8,25,1,biomesoplenty:hard_ice:0)
Block(-8,25,2,biomesoplenty:hard_ice:0)
Block(-8,25,3,biomesoplenty:hard_ice:0)
Block(-8,25,4,biomesoplenty:hard_ice:0)
Block(-8,25,5,biomesoplenty:hard_ice:0)
Block(-8,25,6,biomesoplenty:hard_ice:0)
Block(-8,25,7,biomesoplenty:hard_ice:0)
Block(-8,25,8,biomesoplenty:hard_ice:0)
Block(-8,25,9,biomesoplenty:hard_ice:0)
Block(-8,25,10,biomesoplenty:hard_ice:0)
Block(-8,25,11,biomesoplenty:hard_ice:0)
Block(-8,25,12,biomesoplenty:hard_ice:0)
Block(-8,25,13,biomesoplenty:hard_ice:0)
Block(-8,25,14,biomesoplenty:hard_ice:0)
Block(-8,25,15,biomesoplenty:hard_ice:0)
Block(-8,25,16,biomesoplenty:hard_ice:0)
Block(-8,26,-2,biomesoplenty:hard_ice:0)
Block(-8,26,-1,biomesoplenty:hard_ice:0)
Block(-8,26,0,biomesoplenty:hard_ice:0)
Block(-8,26,1,biomesoplenty:hard_ice:0)
Block(-8,26,2,biomesoplenty:hard_ice:0)
Block(-8,26,3,biomesoplenty:hard_ice:0)
Block(-8,26,4,biomesoplenty:hard_ice:0)
Block(-8,26,5,biomesoplenty:hard_ice:0)
Block(-8,26,6,biomesoplenty:hard_ice:0)
Block(-8,26,7,biomesoplenty:hard_ice:0)
Block(-8,26,8,biomesoplenty:hard_ice:0)
Block(-8,26,9,biomesoplenty:hard_ice:0)
Block(-8,26,10,biomesoplenty:hard_ice:0)
Block(-8,26,11,biomesoplenty:hard_ice:0)
Block(-8,26,12,biomesoplenty:hard_ice:0)
Block(-8,26,13,biomesoplenty:hard_ice:0)
Block(-8,26,14,biomesoplenty:hard_ice:0)
Block(-8,26,15,biomesoplenty:hard_ice:0)
Block(-8,27,-2,biomesoplenty:hard_ice:0)
Block(-8,27,-1,biomesoplenty:hard_ice:0)
Block(-8,27,0,biomesoplenty:hard_ice:0)
Block(-8,27,1,biomesoplenty:hard_ice:0)
Block(-8,27,2,biomesoplenty:hard_ice:0)
Block(-8,27,3,biomesoplenty:hard_ice:0)
Block(-8,27,4,biomesoplenty:hard_ice:0)
Block(-8,27,5,biomesoplenty:hard_ice:0)
Block(-8,27,6,biomesoplenty:hard_ice:0)
Block(-8,27,7,biomesoplenty:hard_ice:0)
Block(-8,27,8,biomesoplenty:hard_ice:0)
Block(-8,27,9,biomesoplenty:hard_ice:0)
Block(-8,27,10,biomesoplenty:hard_ice:0)
Block(-8,27,11,biomesoplenty:hard_ice:0)
Block(-8,27,12,biomesoplenty:hard_ice:0)
Block(-8,27,13,biomesoplenty:hard_ice:0)
Block(-8,27,14,biomesoplenty:hard_ice:0)
Block(-8,28,-1,biomesoplenty:hard_ice:0)
Block(-8,28,0,biomesoplenty:hard_ice:0)
Block(-8,28,1,biomesoplenty:hard_ice:0)
Block(-8,28,2,biomesoplenty:hard_ice:0)
Block(-8,28,3,biomesoplenty:hard_ice:0)
Block(-8,28,4,biomesoplenty:hard_ice:0)
Block(-8,28,5,biomesoplenty:hard_ice:0)
Block(-8,28,6,biomesoplenty:hard_ice:0)
Block(-8,28,7,biomesoplenty:hard_ice:0)
Block(-8,28,8,biomesoplenty:hard_ice:0)
Block(-8,28,9,biomesoplenty:hard_ice:0)
Block(-8,28,10,biomesoplenty:hard_ice:0)
Block(-8,28,11,biomesoplenty:hard_ice:0)
Block(-8,28,12,biomesoplenty:hard_ice:0)
Block(-8,28,13,biomesoplenty:hard_ice:0)
Block(-8,29,0,biomesoplenty:hard_ice:0)
Block(-8,29,1,biomesoplenty:hard_ice:0)
Block(-8,29,2,biomesoplenty:hard_ice:0)
Block(-8,29,3,biomesoplenty:hard_ice:0)
Block(-8,29,4,biomesoplenty:hard_ice:0)
Block(-8,29,5,biomesoplenty:hard_ice:0)
Block(-8,29,6,biomesoplenty:hard_ice:0)
Block(-8,29,7,biomesoplenty:hard_ice:0)
Block(-8,29,8,biomesoplenty:hard_ice:0)
Block(-8,29,9,biomesoplenty:hard_ice:0)
Block(-8,29,10,biomesoplenty:hard_ice:0)
Block(-8,29,11,biomesoplenty:hard_ice:0)
Block(-8,29,12,biomesoplenty:hard_ice:0)
Block(-8,30,1,biomesoplenty:hard_ice:0)
Block(-8,30,2,biomesoplenty:hard_ice:0)
Block(-8,30,3,biomesoplenty:hard_ice:0)
Block(-8,30,4,biomesoplenty:hard_ice:0)
Block(-8,30,5,biomesoplenty:hard_ice:0)
Block(-8,30,6,biomesoplenty:hard_ice:0)
Block(-8,30,7,biomesoplenty:hard_ice:0)
Block(-8,30,8,biomesoplenty:hard_ice:0)
Block(-8,30,9,biomesoplenty:hard_ice:0)
Block(-8,30,10,biomesoplenty:hard_ice:0)
Block(-8,31,3,biomesoplenty:hard_ice:0)
Block(-8,31,4,biomesoplenty:hard_ice:0)
Block(-8,31,5,biomesoplenty:hard_ice:0)
Block(-8,31,6,biomesoplenty:hard_ice:0)
Block(-8,31,7,biomesoplenty:hard_ice:0)
Block(-8,31,8,biomesoplenty:hard_ice:0)
Block(-8,31,9,biomesoplenty:hard_ice:0)
Block(-8,32,5,biomesoplenty:hard_ice:0)
Block(-8,32,6,biomesoplenty:hard_ice:0)
Block(-8,32,7,biomesoplenty:hard_ice:0)
Block(-8,32,8,biomesoplenty:hard_ice:0)
Block(-8,33,6,biomesoplenty:hard_ice:0)
Block(-7,7,6,biomesoplenty:hard_ice:0)
Block(-7,8,3,biomesoplenty:hard_ice:0)
Block(-7,8,4,biomesoplenty:hard_ice:0)
Block(-7,8,5,biomesoplenty:hard_ice:0)
Block(-7,8,6,biomesoplenty:hard_ice:0)
Block(-7,8,7,biomesoplenty:hard_ice:0)
Block(-7,8,8,biomesoplenty:hard_ice:0)
Block(-7,9,0,biomesoplenty:hard_ice:0)
Block(-7,9,1,biomesoplenty:hard_ice:0)
Block(-7,9,2,biomesoplenty:hard_ice:0)
Block(-7,9,3,biomesoplenty:hard_ice:0)
Block(-7,9,4,biomesoplenty:hard_ice:0)
Block(-7,9,5,biomesoplenty:hard_ice:0)
Block(-7,9,6,biomesoplenty:hard_ice:0)
Block(-7,9,7,biomesoplenty:hard_ice:0)
Block(-7,9,8,biomesoplenty:hard_ice:0)
Block(-7,9,9,biomesoplenty:hard_ice:0)
Block(-7,9,10,biomesoplenty:hard_ice:0)
Block(-7,9,11,biomesoplenty:hard_ice:0)
Block(-7,10,-5,biomesoplenty:hard_ice:0)
Block(-7,10,-4,biomesoplenty:hard_ice:0)
Block(-7,10,-3,biomesoplenty:hard_ice:0)
Block(-7,10,-2,biomesoplenty:hard_ice:0)
Block(-7,10,-1,biomesoplenty:hard_ice:0)
Block(-7,10,0,biomesoplenty:hard_ice:0)
Block(-7,10,1,biomesoplenty:hard_ice:0)
Block(-7,10,2,biomesoplenty:hard_ice:0)
Block(-7,10,3,biomesoplenty:hard_ice:0)
Block(-7,10,4,biomesoplenty:hard_ice:0)
Block(-7,10,5,biomesoplenty:hard_ice:0)
Block(-7,10,6,biomesoplenty:hard_ice:0)
Block(-7,10,7,biomesoplenty:hard_ice:0)
Block(-7,10,8,biomesoplenty:hard_ice:0)
Block(-7,10,9,biomesoplenty:hard_ice:0)
Block(-7,10,10,biomesoplenty:hard_ice:0)
Block(-7,10,11,biomesoplenty:hard_ice:0)
Block(-7,10,12,biomesoplenty:hard_ice:0)
Block(-7,10,13,biomesoplenty:hard_ice:0)
Block(-7,11,-9,biomesoplenty:hard_ice:0)
Block(-7,11,-8,biomesoplenty:hard_ice:0)
Block(-7,11,-7,biomesoplenty:hard_ice:0)
Block(-7,11,-6,biomesoplenty:hard_ice:0)
Block(-7,11,-5,biomesoplenty:hard_ice:0)
Block(-7,11,-4,biomesoplenty:hard_ice:0)
Block(-7,11,-3,biomesoplenty:hard_ice:0)
Block(-7,11,-2,biomesoplenty:hard_ice:0)
Block(-7,11,-1,biomesoplenty:hard_ice:0)
Block(-7,11,0,biomesoplenty:hard_ice:0)
Block(-7,11,1,biomesoplenty:hard_ice:0)
Block(-7,11,2,biomesoplenty:hard_ice:0)
Block(-7,11,3,biomesoplenty:hard_ice:0)
Block(-7,11,4,biomesoplenty:hard_ice:0)
Block(-7,11,5,biomesoplenty:hard_ice:0)
Block(-7,11,6,biomesoplenty:hard_ice:0)
Block(-7,11,7,biomesoplenty:hard_ice:0)
Block(-7,11,8,biomesoplenty:hard_ice:0)
Block(-7,11,9,biomesoplenty:hard_ice:0)
Block(-7,11,10,biomesoplenty:hard_ice:0)
Block(-7,11,11,biomesoplenty:hard_ice:0)
Block(-7,11,12,biomesoplenty:hard_ice:0)
Block(-7,11,13,biomesoplenty:hard_ice:0)
Block(-7,11,14,biomesoplenty:hard_ice:0)
Block(-7,11,15,biomesoplenty:hard_ice:0)
Block(-7,12,-9,biomesoplenty:hard_ice:0)
Block(-7,12,-8,biomesoplenty:hard_ice:0)
Block(-7,12,-7,biomesoplenty:hard_ice:0)
Block(-7,12,-6,biomesoplenty:hard_ice:0)
Block(-7,12,-5,biomesoplenty:hard_ice:0)
Block(-7,12,-4,biomesoplenty:hard_ice:0)
Block(-7,12,-3,biomesoplenty:hard_ice:0)
Block(-7,12,-2,biomesoplenty:hard_ice:0)
Block(-7,12,-1,biomesoplenty:hard_ice:0)
Block(-7,12,0,biomesoplenty:hard_ice:0)
Block(-7,12,1,biomesoplenty:hard_ice:0)
Block(-7,12,2,biomesoplenty:hard_ice:0)
Block(-7,12,3,biomesoplenty:hard_ice:0)
Block(-7,12,4,biomesoplenty:hard_ice:0)
Block(-7,12,5,biomesoplenty:hard_ice:0)
Block(-7,12,6,biomesoplenty:hard_ice:0)
Block(-7,12,7,biomesoplenty:hard_ice:0)
Block(-7,12,8,biomesoplenty:hard_ice:0)
Block(-7,12,9,biomesoplenty:hard_ice:0)
Block(-7,12,10,biomesoplenty:hard_ice:0)
Block(-7,12,11,biomesoplenty:hard_ice:0)
Block(-7,12,12,biomesoplenty:hard_ice:0)
Block(-7,12,13,biomesoplenty:hard_ice:0)
Block(-7,12,14,biomesoplenty:hard_ice:0)
Block(-7,12,15,biomesoplenty:hard_ice:0)
Block(-7,12,16,biomesoplenty:hard_ice:0)
Block(-7,12,17,biomesoplenty:hard_ice:0)
Block(-7,12,18,biomesoplenty:hard_ice:0)
Block(-7,13,-9,biomesoplenty:hard_ice:0)
Block(-7,13,-8,biomesoplenty:hard_ice:0)
Block(-7,13,-7,biomesoplenty:hard_ice:0)
Block(-7,13,-6,biomesoplenty:hard_ice:0)
Block(-7,13,-5,biomesoplenty:hard_ice:0)
Block(-7,13,-4,biomesoplenty:hard_ice:0)
Block(-7,13,-3,biomesoplenty:hard_ice:0)
Block(-7,13,-2,biomesoplenty:hard_ice:0)
Block(-7,13,-1,biomesoplenty:hard_ice:0)
Block(-7,13,0,biomesoplenty:hard_ice:0)
Block(-7,13,1,biomesoplenty:hard_ice:0)
Block(-7,13,2,biomesoplenty:hard_ice:0)
Block(-7,13,3,biomesoplenty:hard_ice:0)
Block(-7,13,4,biomesoplenty:hard_ice:0)
Block(-7,13,5,biomesoplenty:hard_ice:0)
Block(-7,13,6,biomesoplenty:hard_ice:0)
Block(-7,13,7,biomesoplenty:hard_ice:0)
Block(-7,13,8,biomesoplenty:hard_ice:0)
Block(-7,13,9,biomesoplenty:hard_ice:0)
Block(-7,13,10,biomesoplenty:hard_ice:0)
Block(-7,13,11,biomesoplenty:hard_ice:0)
Block(-7,13,12,biomesoplenty:hard_ice:0)
Block(-7,13,13,biomesoplenty:hard_ice:0)
Block(-7,13,14,biomesoplenty:hard_ice:0)
Block(-7,13,15,biomesoplenty:hard_ice:0)
Block(-7,13,16,biomesoplenty:hard_ice:0)
Block(-7,13,17,biomesoplenty:hard_ice:0)
Block(-7,13,18,biomesoplenty:hard_ice:0)
Block(-7,13,19,biomesoplenty:hard_ice:0)
Block(-7,14,-9,biomesoplenty:hard_ice:0)
Block(-7,14,-8,biomesoplenty:hard_ice:0)
Block(-7,14,-7,biomesoplenty:hard_ice:0)
Block(-7,14,-6,biomesoplenty:hard_ice:0)
Block(-7,14,-5,biomesoplenty:hard_ice:0)
Block(-7,14,-4,biomesoplenty:hard_ice:0)
Block(-7,14,-3,biomesoplenty:hard_ice:0)
Block(-7,14,-2,biomesoplenty:hard_ice:0)
Block(-7,14,-1,biomesoplenty:hard_ice:0)
Block(-7,14,0,biomesoplenty:hard_ice:0)
Block(-7,14,1,biomesoplenty:hard_ice:0)
Block(-7,14,2,biomesoplenty:hard_ice:0)
Block(-7,14,3,biomesoplenty:hard_ice:0)
Block(-7,14,4,biomesoplenty:hard_ice:0)
Block(-7,14,5,biomesoplenty:hard_ice:0)
Block(-7,14,6,biomesoplenty:hard_ice:0)
Block(-7,14,7,biomesoplenty:hard_ice:0)
Block(-7,14,8,biomesoplenty:hard_ice:0)
Block(-7,14,9,biomesoplenty:hard_ice:0)
Block(-7,14,10,biomesoplenty:hard_ice:0)
Block(-7,14,11,biomesoplenty:hard_ice:0)
Block(-7,14,12,biomesoplenty:hard_ice:0)
Block(-7,14,13,biomesoplenty:hard_ice:0)
Block(-7,14,14,biomesoplenty:hard_ice:0)
Block(-7,14,15,biomesoplenty:hard_ice:0)
Block(-7,14,16,biomesoplenty:hard_ice:0)
Block(-7,14,17,biomesoplenty:hard_ice:0)
Block(-7,14,18,biomesoplenty:hard_ice:0)
Block(-7,14,19,biomesoplenty:hard_ice:0)
Block(-7,15,-9,biomesoplenty:hard_ice:0)
Block(-7,15,-8,biomesoplenty:hard_ice:0)
Block(-7,15,-7,biomesoplenty:hard_ice:0)
Block(-7,15,-6,biomesoplenty:hard_ice:0)
Block(-7,15,-5,biomesoplenty:hard_ice:0)
Block(-7,15,-4,biomesoplenty:hard_ice:0)
Block(-7,15,-3,biomesoplenty:hard_ice:0)
Block(-7,15,-2,biomesoplenty:hard_ice:0)
Block(-7,15,-1,biomesoplenty:hard_ice:0)
Block(-7,15,0,biomesoplenty:hard_ice:0)
Block(-7,15,1,biomesoplenty:hard_ice:0)
Block(-7,15,2,biomesoplenty:hard_ice:0)
Block(-7,15,3,biomesoplenty:hard_ice:0)
Block(-7,15,4,biomesoplenty:hard_ice:0)
Block(-7,15,5,biomesoplenty:hard_ice:0)
Block(-7,15,6,biomesoplenty:hard_ice:0)
Block(-7,15,7,biomesoplenty:hard_ice:0)
Block(-7,15,8,biomesoplenty:hard_ice:0)
Block(-7,15,9,biomesoplenty:hard_ice:0)
Block(-7,15,10,biomesoplenty:hard_ice:0)
Block(-7,15,11,biomesoplenty:hard_ice:0)
Block(-7,15,12,biomesoplenty:hard_ice:0)
Block(-7,15,13,biomesoplenty:hard_ice:0)
Block(-7,15,14,biomesoplenty:hard_ice:0)
Block(-7,15,15,biomesoplenty:hard_ice:0)
Block(-7,15,16,biomesoplenty:hard_ice:0)
Block(-7,15,17,biomesoplenty:hard_ice:0)
Block(-7,15,18,biomesoplenty:hard_ice:0)
Block(-7,15,19,biomesoplenty:hard_ice:0)
Block(-7,16,-8,biomesoplenty:hard_ice:0)
Block(-7,16,-7,biomesoplenty:hard_ice:0)
Block(-7,16,-6,biomesoplenty:hard_ice:0)
Block(-7,16,-5,biomesoplenty:hard_ice:0)
Block(-7,16,-4,biomesoplenty:hard_ice:0)
Block(-7,16,-3,biomesoplenty:hard_ice:0)
Block(-7,16,-2,biomesoplenty:hard_ice:0)
Block(-7,16,-1,biomesoplenty:hard_ice:0)
Block(-7,16,0,biomesoplenty:hard_ice:0)
Block(-7,16,1,biomesoplenty:hard_ice:0)
Block(-7,16,2,biomesoplenty:hard_ice:0)
Block(-7,16,3,biomesoplenty:hard_ice:0)
Block(-7,16,4,biomesoplenty:hard_ice:0)
Block(-7,16,5,biomesoplenty:hard_ice:0)
Block(-7,16,6,biomesoplenty:hard_ice:0)
Block(-7,16,7,biomesoplenty:hard_ice:0)
Block(-7,16,8,biomesoplenty:hard_ice:0)
Block(-7,16,9,biomesoplenty:hard_ice:0)
Block(-7,16,10,biomesoplenty:hard_ice:0)
Block(-7,16,11,biomesoplenty:hard_ice:0)
Block(-7,16,12,biomesoplenty:hard_ice:0)
Block(-7,16,13,biomesoplenty:hard_ice:0)
Block(-7,16,14,biomesoplenty:hard_ice:0)
Block(-7,16,15,biomesoplenty:hard_ice:0)
Block(-7,16,16,biomesoplenty:hard_ice:0)
Block(-7,16,17,biomesoplenty:hard_ice:0)
Block(-7,16,18,biomesoplenty:hard_ice:0)
Block(-7,16,19,biomesoplenty:hard_ice:0)
Block(-7,17,-8,biomesoplenty:hard_ice:0)
Block(-7,17,-7,biomesoplenty:hard_ice:0)
Block(-7,17,-6,biomesoplenty:hard_ice:0)
Block(-7,17,-5,biomesoplenty:hard_ice:0)
Block(-7,17,-4,biomesoplenty:hard_ice:0)
Block(-7,17,-3,biomesoplenty:hard_ice:0)
Block(-7,17,-2,biomesoplenty:hard_ice:0)
Block(-7,17,-1,biomesoplenty:hard_ice:0)
Block(-7,17,0,biomesoplenty:hard_ice:0)
Block(-7,17,1,biomesoplenty:hard_ice:0)
Block(-7,17,2,biomesoplenty:hard_ice:0)
Block(-7,17,3,biomesoplenty:hard_ice:0)
Block(-7,17,4,biomesoplenty:hard_ice:0)
Block(-7,17,5,biomesoplenty:hard_ice:0)
Block(-7,17,6,biomesoplenty:hard_ice:0)
Block(-7,17,7,biomesoplenty:hard_ice:0)
Block(-7,17,8,biomesoplenty:hard_ice:0)
Block(-7,17,9,biomesoplenty:hard_ice:0)
Block(-7,17,10,biomesoplenty:hard_ice:0)
Block(-7,17,11,biomesoplenty:hard_ice:0)
Block(-7,17,12,biomesoplenty:hard_ice:0)
Block(-7,17,13,biomesoplenty:hard_ice:0)
Block(-7,17,14,biomesoplenty:hard_ice:0)
Block(-7,17,15,biomesoplenty:hard_ice:0)
Block(-7,17,16,biomesoplenty:hard_ice:0)
Block(-7,17,17,biomesoplenty:hard_ice:0)
Block(-7,17,18,biomesoplenty:hard_ice:0)
Block(-7,17,19,biomesoplenty:hard_ice:0)
Block(-7,18,-7,biomesoplenty:hard_ice:0)
Block(-7,18,-6,biomesoplenty:hard_ice:0)
Block(-7,18,-5,biomesoplenty:hard_ice:0)
Block(-7,18,-4,biomesoplenty:hard_ice:0)
Block(-7,18,-3,biomesoplenty:hard_ice:0)
Block(-7,18,-2,biomesoplenty:hard_ice:0)
Block(-7,18,-1,biomesoplenty:hard_ice:0)
Block(-7,18,0,biomesoplenty:hard_ice:0)
Block(-7,18,1,biomesoplenty:hard_ice:0)
Block(-7,18,2,biomesoplenty:hard_ice:0)
Block(-7,18,3,biomesoplenty:hard_ice:0)
Block(-7,18,4,biomesoplenty:hard_ice:0)
Block(-7,18,5,biomesoplenty:hard_ice:0)
Block(-7,18,6,biomesoplenty:hard_ice:0)
Block(-7,18,7,biomesoplenty:hard_ice:0)
Block(-7,18,8,biomesoplenty:hard_ice:0)
Block(-7,18,9,biomesoplenty:hard_ice:0)
Block(-7,18,10,biomesoplenty:hard_ice:0)
Block(-7,18,11,biomesoplenty:hard_ice:0)
Block(-7,18,12,biomesoplenty:hard_ice:0)
Block(-7,18,13,biomesoplenty:hard_ice:0)
Block(-7,18,14,biomesoplenty:hard_ice:0)
Block(-7,18,15,biomesoplenty:hard_ice:0)
Block(-7,18,16,biomesoplenty:hard_ice:0)
Block(-7,18,17,biomesoplenty:hard_ice:0)
Block(-7,18,18,biomesoplenty:hard_ice:0)
Block(-7,18,19,biomesoplenty:hard_ice:0)
Block(-7,19,-7,biomesoplenty:hard_ice:0)
Block(-7,19,-6,biomesoplenty:hard_ice:0)
Block(-7,19,-5,biomesoplenty:hard_ice:0)
Block(-7,19,-4,biomesoplenty:hard_ice:0)
Block(-7,19,-3,biomesoplenty:hard_ice:0)
Block(-7,19,-2,biomesoplenty:hard_ice:0)
Block(-7,19,-1,biomesoplenty:hard_ice:0)
Block(-7,19,0,biomesoplenty:hard_ice:0)
Block(-7,19,1,biomesoplenty:hard_ice:0)
Block(-7,19,2,biomesoplenty:hard_ice:0)
Block(-7,19,3,biomesoplenty:hard_ice:0)
Block(-7,19,4,biomesoplenty:hard_ice:0)
Block(-7,19,5,biomesoplenty:hard_ice:0)
Block(-7,19,6,biomesoplenty:hard_ice:0)
Block(-7,19,7,biomesoplenty:hard_ice:0)
Block(-7,19,8,biomesoplenty:hard_ice:0)
Block(-7,19,9,biomesoplenty:hard_ice:0)
Block(-7,19,10,biomesoplenty:hard_ice:0)
Block(-7,19,11,biomesoplenty:hard_ice:0)
Block(-7,19,12,biomesoplenty:hard_ice:0)
Block(-7,19,13,biomesoplenty:hard_ice:0)
Block(-7,19,14,biomesoplenty:hard_ice:0)
Block(-7,19,15,biomesoplenty:hard_ice:0)
Block(-7,19,16,biomesoplenty:hard_ice:0)
Block(-7,19,17,biomesoplenty:hard_ice:0)
Block(-7,19,18,biomesoplenty:hard_ice:0)
Block(-7,19,19,biomesoplenty:hard_ice:0)
Block(-7,20,-6,biomesoplenty:hard_ice:0)
Block(-7,20,-5,biomesoplenty:hard_ice:0)
Block(-7,20,-4,biomesoplenty:hard_ice:0)
Block(-7,20,-3,biomesoplenty:hard_ice:0)
Block(-7,20,-2,biomesoplenty:hard_ice:0)
Block(-7,20,-1,biomesoplenty:hard_ice:0)
Block(-7,20,0,biomesoplenty:hard_ice:0)
Block(-7,20,1,biomesoplenty:hard_ice:0)
Block(-7,20,2,biomesoplenty:hard_ice:0)
Block(-7,20,3,biomesoplenty:hard_ice:0)
Block(-7,20,4,biomesoplenty:hard_ice:0)
Block(-7,20,5,biomesoplenty:hard_ice:0)
Block(-7,20,6,biomesoplenty:hard_ice:0)
Block(-7,20,7,biomesoplenty:hard_ice:0)
Block(-7,20,8,biomesoplenty:hard_ice:0)
Block(-7,20,9,biomesoplenty:hard_ice:0)
Block(-7,20,10,biomesoplenty:hard_ice:0)
Block(-7,20,11,biomesoplenty:hard_ice:0)
Block(-7,20,12,biomesoplenty:hard_ice:0)
Block(-7,20,13,biomesoplenty:hard_ice:0)
Block(-7,20,14,biomesoplenty:hard_ice:0)
Block(-7,20,15,biomesoplenty:hard_ice:0)
Block(-7,20,16,biomesoplenty:hard_ice:0)
Block(-7,20,17,biomesoplenty:hard_ice:0)
Block(-7,20,18,biomesoplenty:hard_ice:0)
Block(-7,20,19,biomesoplenty:hard_ice:0)
Block(-7,21,-5,biomesoplenty:hard_ice:0)
Block(-7,21,-4,biomesoplenty:hard_ice:0)
Block(-7,21,-3,biomesoplenty:hard_ice:0)
Block(-7,21,-2,biomesoplenty:hard_ice:0)
Block(-7,21,-1,biomesoplenty:hard_ice:0)
Block(-7,21,0,biomesoplenty:hard_ice:0)
Block(-7,21,1,biomesoplenty:hard_ice:0)
Block(-7,21,2,biomesoplenty:hard_ice:0)
Block(-7,21,3,biomesoplenty:hard_ice:0)
Block(-7,21,4,biomesoplenty:hard_ice:0)
Block(-7,21,5,biomesoplenty:hard_ice:0)
Block(-7,21,6,biomesoplenty:hard_ice:0)
Block(-7,21,7,biomesoplenty:hard_ice:0)
Block(-7,21,8,biomesoplenty:hard_ice:0)
Block(-7,21,9,biomesoplenty:hard_ice:0)
Block(-7,21,10,biomesoplenty:hard_ice:0)
Block(-7,21,11,biomesoplenty:hard_ice:0)
Block(-7,21,12,biomesoplenty:hard_ice:0)
Block(-7,21,13,biomesoplenty:hard_ice:0)
Block(-7,21,14,biomesoplenty:hard_ice:0)
Block(-7,21,15,biomesoplenty:hard_ice:0)
Block(-7,21,16,biomesoplenty:hard_ice:0)
Block(-7,21,17,biomesoplenty:hard_ice:0)
Block(-7,21,18,biomesoplenty:hard_ice:0)
Block(-7,21,19,biomesoplenty:hard_ice:0)
Block(-7,22,-5,biomesoplenty:hard_ice:0)
Block(-7,22,-4,biomesoplenty:hard_ice:0)
Block(-7,22,-3,biomesoplenty:hard_ice:0)
Block(-7,22,-2,biomesoplenty:hard_ice:0)
Block(-7,22,-1,biomesoplenty:hard_ice:0)
Block(-7,22,0,biomesoplenty:hard_ice:0)
Block(-7,22,1,biomesoplenty:hard_ice:0)
Block(-7,22,2,biomesoplenty:hard_ice:0)
Block(-7,22,3,biomesoplenty:hard_ice:0)
Block(-7,22,4,biomesoplenty:hard_ice:0)
Block(-7,22,5,biomesoplenty:hard_ice:0)
Block(-7,22,6,biomesoplenty:hard_ice:0)
Block(-7,22,7,biomesoplenty:hard_ice:0)
Block(-7,22,8,biomesoplenty:hard_ice:0)
Block(-7,22,9,biomesoplenty:hard_ice:0)
Block(-7,22,10,biomesoplenty:hard_ice:0)
Block(-7,22,11,biomesoplenty:hard_ice:0)
Block(-7,22,12,biomesoplenty:hard_ice:0)
Block(-7,22,13,biomesoplenty:hard_ice:0)
Block(-7,22,14,biomesoplenty:hard_ice:0)
Block(-7,22,15,biomesoplenty:hard_ice:0)
Block(-7,22,16,biomesoplenty:hard_ice:0)
Block(-7,22,17,biomesoplenty:hard_ice:0)
Block(-7,22,18,biomesoplenty:hard_ice:0)
Block(-7,22,19,biomesoplenty:hard_ice:0)
Block(-7,23,-4,biomesoplenty:hard_ice:0)
Block(-7,23,-3,biomesoplenty:hard_ice:0)
Block(-7,23,-2,biomesoplenty:hard_ice:0)
Block(-7,23,-1,biomesoplenty:hard_ice:0)
Block(-7,23,0,biomesoplenty:hard_ice:0)
Block(-7,23,1,biomesoplenty:hard_ice:0)
Block(-7,23,2,biomesoplenty:hard_ice:0)
Block(-7,23,3,biomesoplenty:hard_ice:0)
Block(-7,23,4,biomesoplenty:hard_ice:0)
Block(-7,23,5,biomesoplenty:hard_ice:0)
Block(-7,23,6,biomesoplenty:hard_ice:0)
Block(-7,23,7,biomesoplenty:hard_ice:0)
Block(-7,23,8,biomesoplenty:hard_ice:0)
Block(-7,23,9,biomesoplenty:hard_ice:0)
Block(-7,23,10,biomesoplenty:hard_ice:0)
Block(-7,23,11,biomesoplenty:hard_ice:0)
Block(-7,23,12,biomesoplenty:hard_ice:0)
Block(-7,23,13,biomesoplenty:hard_ice:0)
Block(-7,23,14,biomesoplenty:hard_ice:0)
Block(-7,23,15,biomesoplenty:hard_ice:0)
Block(-7,23,16,biomesoplenty:hard_ice:0)
Block(-7,23,17,biomesoplenty:hard_ice:0)
Block(-7,23,18,biomesoplenty:hard_ice:0)
Block(-7,23,19,biomesoplenty:hard_ice:0)
Block(-7,24,-4,biomesoplenty:hard_ice:0)
Block(-7,24,-3,biomesoplenty:hard_ice:0)
Block(-7,24,-2,biomesoplenty:hard_ice:0)
Block(-7,24,-1,biomesoplenty:hard_ice:0)
Block(-7,24,0,biomesoplenty:hard_ice:0)
Block(-7,24,1,biomesoplenty:hard_ice:0)
Block(-7,24,2,biomesoplenty:hard_ice:0)
Block(-7,24,3,biomesoplenty:hard_ice:0)
Block(-7,24,4,biomesoplenty:hard_ice:0)
Block(-7,24,5,biomesoplenty:hard_ice:0)
Block(-7,24,6,biomesoplenty:hard_ice:0)
Block(-7,24,7,biomesoplenty:hard_ice:0)
Block(-7,24,8,biomesoplenty:hard_ice:0)
Block(-7,24,9,biomesoplenty:hard_ice:0)
Block(-7,24,10,biomesoplenty:hard_ice:0)
Block(-7,24,11,biomesoplenty:hard_ice:0)
Block(-7,24,12,biomesoplenty:hard_ice:0)
Block(-7,24,13,biomesoplenty:hard_ice:0)
Block(-7,24,14,biomesoplenty:hard_ice:0)
Block(-7,24,15,biomesoplenty:hard_ice:0)
Block(-7,24,16,biomesoplenty:hard_ice:0)
Block(-7,24,17,biomesoplenty:hard_ice:0)
Block(-7,24,18,biomesoplenty:hard_ice:0)
Block(-7,24,19,biomesoplenty:hard_ice:0)
Block(-7,25,-3,biomesoplenty:hard_ice:0)
Block(-7,25,-2,biomesoplenty:hard_ice:0)
Block(-7,25,-1,biomesoplenty:hard_ice:0)
Block(-7,25,0,biomesoplenty:hard_ice:0)
Block(-7,25,1,biomesoplenty:hard_ice:0)
Block(-7,25,2,biomesoplenty:hard_ice:0)
Block(-7,25,3,biomesoplenty:hard_ice:0)
Block(-7,25,4,biomesoplenty:hard_ice:0)
Block(-7,25,5,biomesoplenty:hard_ice:0)
Block(-7,25,6,biomesoplenty:hard_ice:0)
Block(-7,25,7,biomesoplenty:hard_ice:0)
Block(-7,25,8,biomesoplenty:hard_ice:0)
Block(-7,25,9,biomesoplenty:hard_ice:0)
Block(-7,25,10,biomesoplenty:hard_ice:0)
Block(-7,25,11,biomesoplenty:hard_ice:0)
Block(-7,25,12,biomesoplenty:hard_ice:0)
Block(-7,25,13,biomesoplenty:hard_ice:0)
Block(-7,25,14,biomesoplenty:hard_ice:0)
Block(-7,25,15,biomesoplenty:hard_ice:0)
Block(-7,25,16,biomesoplenty:hard_ice:0)
Block(-7,25,17,biomesoplenty:hard_ice:0)
Block(-7,25,18,biomesoplenty:hard_ice:0)
Block(-7,26,-2,biomesoplenty:hard_ice:0)
Block(-7,26,-1,biomesoplenty:hard_ice:0)
Block(-7,26,0,biomesoplenty:hard_ice:0)
Block(-7,26,1,biomesoplenty:hard_ice:0)
