#######################################################################
# +-----------------------------------------------------------------+ #
# |                            BO3 object                           | #
# +-----------------------------------------------------------------+ #
#######################################################################

# The descriptions in this file are accurate only for TerrainControl and OTG.
# For MCW and OTG+ these descriptions are only accurate if the BO3 is used as a CustomObject.
# MCW and OTG+ completely reimplemented CustomStructure, check the MCW/OTG+ documentation for more information.

# This is the config file of a custom object.
# If you add this object correctly to your BiomeConfigs, it will spawn in the world.

# This is the creator of this BO3 object
Author: Unknown

# A short description of this BO3 object
Description: This BO3 was converted from a schematic using OTGEdit. The author and description information of the schematic could not be found. If you know who the author of the schematic is then please add this information.

# The BO3 version, don't change this! It can be used by external applications to do a version check.
Version: 3

# The settings mode, WriteAll, WriteWithoutComments or WriteDisable. See WorldConfig.
SettingsMode: WriteDisable

#######################################################################
# +-----------------------------------------------------------------+ #
# |                          Main settings                          | #
# +-----------------------------------------------------------------+ #
#######################################################################

# This needs to be set to true to spawn the object in the Tree and Sapling resources.
Tree: true

# The frequency of the BO3 from 1 to 200. Tries this many times to spawn this BO3 when using the CustomObject(...) resource.
# Ignored by Tree(..), Sapling(..) and CustomStructure(..)
Frequency: 40

# The rarity of the BO3 from 0 to 100. Each spawn attempt has rarity% chance to succeed when using the CustomObject(...) resource.
# Ignored by Tree(..), Sapling(..) and CustomStructure(..)
Rarity: 100.0

# If you set this to true, the BO3 will be placed with a random rotation.
RotateRandomly: true

# The spawn height of the BO3 - randomY, highestBlock or highestSolidBlock.
SpawnHeight: randomY

# The height limits for the BO3.
MinHeight: 0

MaxHeight: 256

# Objects can have other objects attached to it: branches. Branches can also
# have branches attached to it, which can also have branches, etc. This is the
# maximum branch depth for this objects.
MaxBranchDepth: 10

# When spawned with the UseWorld keyword, this BO3 should NOT spawn in the following biomes.
# If you writer.write the BO3 name directly in the BiomeConfigs, this will be ignored.
ExcludedBiomes: All

# To optimise this BO3 for faster loading times you can use Notepad++ to find/replace comments and abbreviate things.
# Notepad++ find/replace with regex:
# Find: ^[#;].* replace to nothing removes all lines starting with # 
# Find: ^\s*$ replace to nothing removes most empty lines 
# Notepad++ find/replace without regex:
# *Warning: This will only work for OTG 1.10.2 v21 / OTG 1.11.2 v6 or higher. B( is not recognised by lower versions.
# Find: Block( replace to B(

#######################################################################
# +-----------------------------------------------------------------+ #
# |                      Source block settings                      | #
# +-----------------------------------------------------------------+ #
#######################################################################

# The block(s) the BO3 should spawn in.
SourceBlocks: AIR

# The maximum percentage of the BO3 that can be outside the SourceBlock.
# The BO3 won't be placed on a location with more blocks outside the SourceBlock than this percentage.
MaxPercentageOutsideSourceBlock: 100

# What to do when a block is about to be placed outside the SourceBlock? (dontPlace, placeAnyway)
OutsideSourceBlock: placeAnyway

#######################################################################
# +-----------------------------------------------------------------+ #
# |                              Blocks                             | #
# +-----------------------------------------------------------------+ #
#######################################################################

# All the blocks used in the BO3 are listed here. Possible blocks:
# Block(x,y,z,id[.data][,nbtfile.nbt) or B(x,y,z,id[.data][,nbtfile.nbt)
# RandomBlock(x,y,z,id[:data][,nbtfile.nbt],chance[,id[:data][,nbtfile.nbt],chance[,...]])
# So RandomBlock(0,0,0,CHEST,chest.nbt,50,CHEST,anotherchest.nbt,100) will spawn a chest at
# the BO3 origin, and give it a 50% chance to have the contents of chest.nbt, or, if that
# fails, a 100% percent chance to have the contents of anotherchest.nbt.

Block(-7,14,9,biomesoplenty:hard_ice:0)
Block(-7,15,8,biomesoplenty:hard_ice:0)
Block(-7,17,6,biomesoplenty:hard_ice:0)
Block(-6,11,9,biomesoplenty:hard_ice:0)
Block(-6,12,8,biomesoplenty:hard_ice:0)
Block(-6,12,9,biomesoplenty:hard_ice:0)
Block(-6,13,6,biomesoplenty:hard_ice:0)
Block(-6,13,7,biomesoplenty:hard_ice:0)
Block(-6,13,8,biomesoplenty:hard_ice:0)
Block(-6,13,9,biomesoplenty:hard_ice:0)
Block(-6,14,5,biomesoplenty:hard_ice:0)
Block(-6,14,6,biomesoplenty:hard_ice:0)
Block(-6,14,7,biomesoplenty:hard_ice:0)
Block(-6,14,8,biomesoplenty:hard_ice:0)
Block(-6,14,9,biomesoplenty:hard_ice:0)
Block(-6,15,4,biomesoplenty:hard_ice:0)
Block(-6,15,5,biomesoplenty:hard_ice:0)
Block(-6,15,6,biomesoplenty:hard_ice:0)
Block(-6,15,7,biomesoplenty:hard_ice:0)
Block(-6,15,8,biomesoplenty:hard_ice:0)
Block(-6,15,9,biomesoplenty:hard_ice:0)
Block(-6,16,3,biomesoplenty:hard_ice:0)
Block(-6,16,4,biomesoplenty:hard_ice:0)
Block(-6,16,5,biomesoplenty:hard_ice:0)
Block(-6,16,6,biomesoplenty:hard_ice:0)
Block(-6,16,7,biomesoplenty:hard_ice:0)
Block(-6,16,8,biomesoplenty:hard_ice:0)
Block(-6,17,2,biomesoplenty:hard_ice:0)
Block(-6,17,3,biomesoplenty:hard_ice:0)
Block(-6,17,4,biomesoplenty:hard_ice:0)
Block(-6,17,5,biomesoplenty:hard_ice:0)
Block(-6,17,6,biomesoplenty:hard_ice:0)
Block(-6,17,7,biomesoplenty:hard_ice:0)
Block(-6,18,0,biomesoplenty:hard_ice:0)
Block(-6,18,1,biomesoplenty:hard_ice:0)
Block(-6,18,2,biomesoplenty:hard_ice:0)
Block(-6,18,3,biomesoplenty:hard_ice:0)
Block(-6,18,4,biomesoplenty:hard_ice:0)
Block(-6,18,5,biomesoplenty:hard_ice:0)
Block(-6,18,6,biomesoplenty:hard_ice:0)
Block(-6,19,1,biomesoplenty:hard_ice:0)
Block(-6,19,2,biomesoplenty:hard_ice:0)
Block(-6,19,3,biomesoplenty:hard_ice:0)
Block(-6,19,4,biomesoplenty:hard_ice:0)
Block(-6,19,5,biomesoplenty:hard_ice:0)
Block(-6,20,3,biomesoplenty:hard_ice:0)
Block(-6,20,4,biomesoplenty:hard_ice:0)
Block(-5,9,7,biomesoplenty:hard_ice:0)
Block(-5,10,6,biomesoplenty:hard_ice:0)
Block(-5,10,7,biomesoplenty:hard_ice:0)
Block(-5,10,8,biomesoplenty:hard_ice:0)
Block(-5,10,9,biomesoplenty:hard_ice:0)
Block(-5,10,10,biomesoplenty:hard_ice:0)
Block(-5,11,6,biomesoplenty:hard_ice:0)
Block(-5,11,7,biomesoplenty:hard_ice:0)
Block(-5,11,8,biomesoplenty:hard_ice:0)
Block(-5,11,9,biomesoplenty:hard_ice:0)
Block(-5,11,10,biomesoplenty:hard_ice:0)
Block(-5,12,5,biomesoplenty:hard_ice:0)
Block(-5,12,6,biomesoplenty:hard_ice:0)
Block(-5,12,7,biomesoplenty:hard_ice:0)
Block(-5,12,8,biomesoplenty:hard_ice:0)
Block(-5,12,9,biomesoplenty:hard_ice:0)
Block(-5,12,10,biomesoplenty:hard_ice:0)
Block(-5,13,4,biomesoplenty:hard_ice:0)
Block(-5,13,5,biomesoplenty:hard_ice:0)
Block(-5,13,6,biomesoplenty:hard_ice:0)
Block(-5,13,7,biomesoplenty:hard_ice:0)
Block(-5,13,8,biomesoplenty:hard_ice:0)
Block(-5,13,9,biomesoplenty:hard_ice:0)
Block(-5,13,10,biomesoplenty:hard_ice:0)
Block(-5,14,2,biomesoplenty:hard_ice:0)
Block(-5,14,3,biomesoplenty:hard_ice:0)
Block(-5,14,4,biomesoplenty:hard_ice:0)
Block(-5,14,5,biomesoplenty:hard_ice:0)
Block(-5,14,6,biomesoplenty:hard_ice:0)
Block(-5,14,7,biomesoplenty:hard_ice:0)
Block(-5,14,8,biomesoplenty:hard_ice:0)
Block(-5,14,9,biomesoplenty:hard_ice:0)
Block(-5,14,10,biomesoplenty:hard_ice:0)
Block(-5,15,1,biomesoplenty:hard_ice:0)
Block(-5,15,2,biomesoplenty:hard_ice:0)
Block(-5,15,3,biomesoplenty:hard_ice:0)
Block(-5,15,4,biomesoplenty:hard_ice:0)
Block(-5,15,5,biomesoplenty:hard_ice:0)
Block(-5,15,6,biomesoplenty:hard_ice:0)
Block(-5,15,7,biomesoplenty:hard_ice:0)
Block(-5,15,8,biomesoplenty:hard_ice:0)
Block(-5,15,9,biomesoplenty:hard_ice:0)
Block(-5,15,10,biomesoplenty:hard_ice:0)
Block(-5,16,-1,biomesoplenty:hard_ice:0)
Block(-5,16,0,biomesoplenty:hard_ice:0)
Block(-5,16,1,biomesoplenty:hard_ice:0)
Block(-5,16,2,biomesoplenty:hard_ice:0)
Block(-5,16,3,biomesoplenty:hard_ice:0)
Block(-5,16,4,biomesoplenty:hard_ice:0)
Block(-5,16,5,biomesoplenty:hard_ice:0)
Block(-5,16,6,biomesoplenty:hard_ice:0)
Block(-5,16,7,biomesoplenty:hard_ice:0)
Block(-5,16,8,biomesoplenty:hard_ice:0)
Block(-5,16,9,biomesoplenty:hard_ice:0)
Block(-5,17,-3,biomesoplenty:hard_ice:0)
Block(-5,17,-2,biomesoplenty:hard_ice:0)
Block(-5,17,-1,biomesoplenty:hard_ice:0)
Block(-5,17,0,biomesoplenty:hard_ice:0)
Block(-5,17,1,biomesoplenty:hard_ice:0)
Block(-5,17,2,biomesoplenty:hard_ice:0)
Block(-5,17,3,biomesoplenty:hard_ice:0)
Block(-5,17,4,biomesoplenty:hard_ice:0)
Block(-5,17,5,biomesoplenty:hard_ice:0)
Block(-5,17,6,biomesoplenty:hard_ice:0)
Block(-5,17,7,biomesoplenty:hard_ice:0)
Block(-5,17,8,biomesoplenty:hard_ice:0)
Block(-5,18,-3,biomesoplenty:hard_ice:0)
Block(-5,18,-2,biomesoplenty:hard_ice:0)
Block(-5,18,-1,biomesoplenty:hard_ice:0)
Block(-5,18,0,biomesoplenty:hard_ice:0)
Block(-5,18,1,biomesoplenty:hard_ice:0)
Block(-5,18,2,biomesoplenty:hard_ice:0)
Block(-5,18,3,biomesoplenty:hard_ice:0)
Block(-5,18,4,biomesoplenty:hard_ice:0)
Block(-5,18,5,biomesoplenty:hard_ice:0)
Block(-5,18,6,biomesoplenty:hard_ice:0)
Block(-5,18,7,biomesoplenty:hard_ice:0)
Block(-5,19,-2,biomesoplenty:hard_ice:0)
Block(-5,19,-1,biomesoplenty:hard_ice:0)
Block(-5,19,0,biomesoplenty:hard_ice:0)
Block(-5,19,1,biomesoplenty:hard_ice:0)
Block(-5,19,2,biomesoplenty:hard_ice:0)
Block(-5,19,3,biomesoplenty:hard_ice:0)
Block(-5,19,4,biomesoplenty:hard_ice:0)
Block(-5,19,5,biomesoplenty:hard_ice:0)
Block(-5,19,6,biomesoplenty:hard_ice:0)
Block(-5,20,0,biomesoplenty:hard_ice:0)
Block(-5,20,1,biomesoplenty:hard_ice:0)
Block(-5,20,2,biomesoplenty:hard_ice:0)
Block(-5,20,3,biomesoplenty:hard_ice:0)
Block(-5,20,4,biomesoplenty:hard_ice:0)
Block(-5,20,5,biomesoplenty:hard_ice:0)
Block(-5,21,1,biomesoplenty:hard_ice:0)
Block(-5,21,2,biomesoplenty:hard_ice:0)
Block(-5,21,3,biomesoplenty:hard_ice:0)
Block(-5,21,4,biomesoplenty:hard_ice:0)
Block(-5,22,3,biomesoplenty:hard_ice:0)
Block(-4,8,4,biomesoplenty:hard_ice:0)
Block(-4,8,5,biomesoplenty:hard_ice:0)
Block(-4,8,6,biomesoplenty:hard_ice:0)
Block(-4,9,3,biomesoplenty:hard_ice:0)
Block(-4,9,4,biomesoplenty:hard_ice:0)
Block(-4,9,5,biomesoplenty:hard_ice:0)
Block(-4,9,6,biomesoplenty:hard_ice:0)
Block(-4,9,7,biomesoplenty:hard_ice:0)
Block(-4,9,8,biomesoplenty:hard_ice:0)
Block(-4,10,3,biomesoplenty:hard_ice:0)
Block(-4,10,4,biomesoplenty:hard_ice:0)
Block(-4,10,5,biomesoplenty:hard_ice:0)
Block(-4,10,6,biomesoplenty:hard_ice:0)
Block(-4,10,7,biomesoplenty:hard_ice:0)
Block(-4,10,8,biomesoplenty:hard_ice:0)
Block(-4,10,9,biomesoplenty:hard_ice:0)
Block(-4,10,10,biomesoplenty:hard_ice:0)
Block(-4,10,11,biomesoplenty:hard_ice:0)
Block(-4,11,2,biomesoplenty:hard_ice:0)
Block(-4,11,3,biomesoplenty:hard_ice:0)
Block(-4,11,4,biomesoplenty:hard_ice:0)
Block(-4,11,5,biomesoplenty:hard_ice:0)
Block(-4,11,6,biomesoplenty:hard_ice:0)
Block(-4,11,7,biomesoplenty:hard_ice:0)
Block(-4,11,8,biomesoplenty:hard_ice:0)
Block(-4,11,9,biomesoplenty:hard_ice:0)
Block(-4,11,10,biomesoplenty:hard_ice:0)
Block(-4,11,11,biomesoplenty:hard_ice:0)
Block(-4,12,2,biomesoplenty:hard_ice:0)
Block(-4,12,3,biomesoplenty:hard_ice:0)
Block(-4,12,4,biomesoplenty:hard_ice:0)
Block(-4,12,5,biomesoplenty:hard_ice:0)
Block(-4,12,6,biomesoplenty:hard_ice:0)
Block(-4,12,7,biomesoplenty:hard_ice:0)
Block(-4,12,8,biomesoplenty:hard_ice:0)
Block(-4,12,9,biomesoplenty:hard_ice:0)
Block(-4,12,10,biomesoplenty:hard_ice:0)
Block(-4,12,11,biomesoplenty:hard_ice:0)
Block(-4,13,0,biomesoplenty:hard_ice:0)
Block(-4,13,1,biomesoplenty:hard_ice:0)
Block(-4,13,2,biomesoplenty:hard_ice:0)
Block(-4,13,3,biomesoplenty:hard_ice:0)
Block(-4,13,4,biomesoplenty:hard_ice:0)
Block(-4,13,5,biomesoplenty:hard_ice:0)
Block(-4,13,6,biomesoplenty:hard_ice:0)
Block(-4,13,7,biomesoplenty:hard_ice:0)
Block(-4,13,8,biomesoplenty:hard_ice:0)
Block(-4,13,9,biomesoplenty:hard_ice:0)
Block(-4,13,10,biomesoplenty:hard_ice:0)
Block(-4,13,11,biomesoplenty:hard_ice:0)
Block(-4,14,-2,biomesoplenty:hard_ice:0)
Block(-4,14,-1,biomesoplenty:hard_ice:0)
Block(-4,14,0,biomesoplenty:hard_ice:0)
Block(-4,14,1,biomesoplenty:hard_ice:0)
Block(-4,14,2,biomesoplenty:hard_ice:0)
Block(-4,14,3,biomesoplenty:hard_ice:0)
Block(-4,14,4,biomesoplenty:hard_ice:0)
Block(-4,14,5,biomesoplenty:hard_ice:0)
Block(-4,14,6,biomesoplenty:hard_ice:0)
Block(-4,14,7,biomesoplenty:hard_ice:0)
Block(-4,14,8,biomesoplenty:hard_ice:0)
Block(-4,14,9,biomesoplenty:hard_ice:0)
Block(-4,14,10,biomesoplenty:hard_ice:0)
Block(-4,14,11,biomesoplenty:hard_ice:0)
Block(-4,15,-4,biomesoplenty:hard_ice:0)
Block(-4,15,-3,biomesoplenty:hard_ice:0)
Block(-4,15,-2,biomesoplenty:hard_ice:0)
Block(-4,15,-1,biomesoplenty:hard_ice:0)
Block(-4,15,0,biomesoplenty:hard_ice:0)
Block(-4,15,1,biomesoplenty:hard_ice:0)
Block(-4,15,2,biomesoplenty:hard_ice:0)
Block(-4,15,3,biomesoplenty:hard_ice:0)
Block(-4,15,4,biomesoplenty:hard_ice:0)
Block(-4,15,5,biomesoplenty:hard_ice:0)
Block(-4,15,6,biomesoplenty:hard_ice:0)
Block(-4,15,7,biomesoplenty:hard_ice:0)
Block(-4,15,8,biomesoplenty:hard_ice:0)
Block(-4,15,9,biomesoplenty:hard_ice:0)
Block(-4,15,10,biomesoplenty:hard_ice:0)
Block(-4,16,-6,biomesoplenty:hard_ice:0)
Block(-4,16,-5,biomesoplenty:hard_ice:0)
Block(-4,16,-4,biomesoplenty:hard_ice:0)
Block(-4,16,-3,biomesoplenty:hard_ice:0)
Block(-4,16,-2,biomesoplenty:hard_ice:0)
Block(-4,16,-1,biomesoplenty:hard_ice:0)
Block(-4,16,0,biomesoplenty:hard_ice:0)
Block(-4,16,1,biomesoplenty:hard_ice:0)
Block(-4,16,2,biomesoplenty:hard_ice:0)
Block(-4,16,3,biomesoplenty:hard_ice:0)
Block(-4,16,4,biomesoplenty:hard_ice:0)
Block(-4,16,5,biomesoplenty:hard_ice:0)
Block(-4,16,6,biomesoplenty:hard_ice:0)
Block(-4,16,7,biomesoplenty:hard_ice:0)
Block(-4,16,8,biomesoplenty:hard_ice:0)
Block(-4,16,9,biomesoplenty:hard_ice:0)
Block(-4,16,10,biomesoplenty:hard_ice:0)
Block(-4,17,-8,biomesoplenty:hard_ice:0)
Block(-4,17,-7,biomesoplenty:hard_ice:0)
Block(-4,17,-6,biomesoplenty:hard_ice:0)
Block(-4,17,-5,biomesoplenty:hard_ice:0)
Block(-4,17,-4,biomesoplenty:hard_ice:0)
Block(-4,17,-3,biomesoplenty:hard_ice:0)
Block(-4,17,-2,biomesoplenty:hard_ice:0)
Block(-4,17,-1,biomesoplenty:hard_ice:0)
Block(-4,17,0,biomesoplenty:hard_ice:0)
Block(-4,17,1,biomesoplenty:hard_ice:0)
Block(-4,17,2,biomesoplenty:hard_ice:0)
Block(-4,17,3,biomesoplenty:hard_ice:0)
Block(-4,17,4,biomesoplenty:hard_ice:0)
Block(-4,17,5,biomesoplenty:hard_ice:0)
Block(-4,17,6,biomesoplenty:hard_ice:0)
Block(-4,17,7,biomesoplenty:hard_ice:0)
Block(-4,17,8,biomesoplenty:hard_ice:0)
Block(-4,17,9,biomesoplenty:hard_ice:0)
Block(-4,18,-6,biomesoplenty:hard_ice:0)
Block(-4,18,-5,biomesoplenty:hard_ice:0)
Block(-4,18,-4,biomesoplenty:hard_ice:0)
Block(-4,18,-3,biomesoplenty:hard_ice:0)
Block(-4,18,-2,biomesoplenty:hard_ice:0)
Block(-4,18,-1,biomesoplenty:hard_ice:0)
Block(-4,18,0,biomesoplenty:hard_ice:0)
Block(-4,18,1,biomesoplenty:hard_ice:0)
Block(-4,18,2,biomesoplenty:hard_ice:0)
Block(-4,18,3,biomesoplenty:hard_ice:0)
Block(-4,18,4,biomesoplenty:hard_ice:0)
Block(-4,18,5,biomesoplenty:hard_ice:0)
Block(-4,18,6,biomesoplenty:hard_ice:0)
Block(-4,18,7,biomesoplenty:hard_ice:0)
Block(-4,18,8,biomesoplenty:hard_ice:0)
Block(-4,19,-4,biomesoplenty:hard_ice:0)
Block(-4,19,-3,biomesoplenty:hard_ice:0)
Block(-4,19,-2,biomesoplenty:hard_ice:0)
Block(-4,19,-1,biomesoplenty:hard_ice:0)
Block(-4,19,0,biomesoplenty:hard_ice:0)
Block(-4,19,1,biomesoplenty:hard_ice:0)
Block(-4,19,2,biomesoplenty:hard_ice:0)
Block(-4,19,3,biomesoplenty:hard_ice:0)
Block(-4,19,4,biomesoplenty:hard_ice:0)
Block(-4,19,5,biomesoplenty:hard_ice:0)
Block(-4,19,6,biomesoplenty:hard_ice:0)
Block(-4,19,7,biomesoplenty:hard_ice:0)
Block(-4,20,-2,biomesoplenty:hard_ice:0)
Block(-4,20,-1,biomesoplenty:hard_ice:0)
Block(-4,20,0,biomesoplenty:hard_ice:0)
Block(-4,20,1,biomesoplenty:hard_ice:0)
Block(-4,20,2,biomesoplenty:hard_ice:0)
Block(-4,20,3,biomesoplenty:hard_ice:0)
Block(-4,20,4,biomesoplenty:hard_ice:0)
Block(-4,20,5,biomesoplenty:hard_ice:0)
Block(-4,20,6,biomesoplenty:hard_ice:0)
Block(-4,21,-1,biomesoplenty:hard_ice:0)
Block(-4,21,0,biomesoplenty:hard_ice:0)
Block(-4,21,1,biomesoplenty:hard_ice:0)
Block(-4,21,2,biomesoplenty:hard_ice:0)
Block(-4,21,3,biomesoplenty:hard_ice:0)
Block(-4,21,4,biomesoplenty:hard_ice:0)
Block(-4,21,5,biomesoplenty:hard_ice:0)
Block(-4,22,0,biomesoplenty:hard_ice:0)
Block(-4,22,1,biomesoplenty:hard_ice:0)
Block(-4,22,2,biomesoplenty:hard_ice:0)
Block(-4,22,3,biomesoplenty:hard_ice:0)
Block(-4,22,4,biomesoplenty:hard_ice:0)
Block(-4,23,2,biomesoplenty:hard_ice:0)
Block(-4,23,3,biomesoplenty:hard_ice:0)
Block(-3,6,1,biomesoplenty:hard_ice:0)
Block(-3,6,2,biomesoplenty:hard_ice:0)
Block(-3,7,0,biomesoplenty:hard_ice:0)
Block(-3,7,1,biomesoplenty:hard_ice:0)
Block(-3,7,2,biomesoplenty:hard_ice:0)
Block(-3,7,3,biomesoplenty:hard_ice:0)
Block(-3,7,4,biomesoplenty:hard_ice:0)
Block(-3,8,-1,biomesoplenty:hard_ice:0)
Block(-3,8,0,biomesoplenty:hard_ice:0)
Block(-3,8,1,biomesoplenty:hard_ice:0)
Block(-3,8,2,biomesoplenty:hard_ice:0)
Block(-3,8,3,biomesoplenty:hard_ice:0)
Block(-3,8,4,biomesoplenty:hard_ice:0)
Block(-3,8,5,biomesoplenty:hard_ice:0)
Block(-3,8,6,biomesoplenty:hard_ice:0)
Block(-3,8,7,biomesoplenty:hard_ice:0)
Block(-3,9,-1,biomesoplenty:hard_ice:0)
Block(-3,9,0,biomesoplenty:hard_ice:0)
Block(-3,9,1,biomesoplenty:hard_ice:0)
Block(-3,9,2,biomesoplenty:hard_ice:0)
Block(-3,9,3,biomesoplenty:hard_ice:0)
Block(-3,9,4,biomesoplenty:hard_ice:0)
Block(-3,9,5,biomesoplenty:hard_ice:0)
Block(-3,9,6,biomesoplenty:hard_ice:0)
Block(-3,9,7,biomesoplenty:hard_ice:0)
Block(-3,9,8,biomesoplenty:hard_ice:0)
Block(-3,9,9,biomesoplenty:hard_ice:0)
Block(-3,10,-2,biomesoplenty:hard_ice:0)
Block(-3,10,-1,biomesoplenty:hard_ice:0)
Block(-3,10,0,biomesoplenty:hard_ice:0)
Block(-3,10,1,biomesoplenty:hard_ice:0)
Block(-3,10,2,biomesoplenty:hard_ice:0)
Block(-3,10,3,biomesoplenty:hard_ice:0)
Block(-3,10,4,biomesoplenty:hard_ice:0)
Block(-3,10,5,biomesoplenty:hard_ice:0)
Block(-3,10,6,biomesoplenty:hard_ice:0)
Block(-3,10,7,biomesoplenty:hard_ice:0)
Block(-3,10,8,biomesoplenty:hard_ice:0)
Block(-3,10,9,biomesoplenty:hard_ice:0)
Block(-3,10,10,biomesoplenty:hard_ice:0)
Block(-3,10,11,biomesoplenty:hard_ice:0)
Block(-3,11,-3,biomesoplenty:hard_ice:0)
Block(-3,11,-2,biomesoplenty:hard_ice:0)
Block(-3,11,-1,biomesoplenty:hard_ice:0)
Block(-3,11,0,biomesoplenty:hard_ice:0)
Block(-3,11,1,biomesoplenty:hard_ice:0)
Block(-3,11,2,biomesoplenty:hard_ice:0)
Block(-3,11,3,biomesoplenty:hard_ice:0)
Block(-3,11,4,biomesoplenty:hard_ice:0)
Block(-3,11,5,biomesoplenty:hard_ice:0)
Block(-3,11,6,biomesoplenty:hard_ice:0)
Block(-3,11,7,biomesoplenty:hard_ice:0)
Block(-3,11,8,biomesoplenty:hard_ice:0)
Block(-3,11,9,biomesoplenty:hard_ice:0)
Block(-3,11,10,biomesoplenty:hard_ice:0)
Block(-3,11,11,biomesoplenty:hard_ice:0)
Block(-3,12,-3,biomesoplenty:hard_ice:0)
Block(-3,12,-2,biomesoplenty:hard_ice:0)
Block(-3,12,-1,biomesoplenty:hard_ice:0)
Block(-3,12,0,biomesoplenty:hard_ice:0)
Block(-3,12,1,biomesoplenty:hard_ice:0)
Block(-3,12,2,biomesoplenty:hard_ice:0)
Block(-3,12,3,biomesoplenty:hard_ice:0)
Block(-3,12,4,biomesoplenty:hard_ice:0)
Block(-3,12,5,biomesoplenty:hard_ice:0)
Block(-3,12,6,biomesoplenty:hard_ice:0)
Block(-3,12,7,biomesoplenty:hard_ice:0)
Block(-3,12,8,biomesoplenty:hard_ice:0)
Block(-3,12,9,biomesoplenty:hard_ice:0)
Block(-3,12,10,biomesoplenty:hard_ice:0)
Block(-3,12,11,biomesoplenty:hard_ice:0)
Block(-3,13,-6,biomesoplenty:hard_ice:0)
Block(-3,13,-5,biomesoplenty:hard_ice:0)
Block(-3,13,-4,biomesoplenty:hard_ice:0)
Block(-3,13,-3,biomesoplenty:hard_ice:0)
Block(-3,13,-2,biomesoplenty:hard_ice:0)
Block(-3,13,-1,biomesoplenty:hard_ice:0)
Block(-3,13,0,biomesoplenty:hard_ice:0)
Block(-3,13,1,biomesoplenty:hard_ice:0)
Block(-3,13,2,biomesoplenty:hard_ice:0)
Block(-3,13,3,biomesoplenty:hard_ice:0)
Block(-3,13,4,biomesoplenty:hard_ice:0)
Block(-3,13,5,biomesoplenty:hard_ice:0)
Block(-3,13,6,biomesoplenty:hard_ice:0)
Block(-3,13,7,biomesoplenty:hard_ice:0)
Block(-3,13,8,biomesoplenty:hard_ice:0)
Block(-3,13,9,biomesoplenty:hard_ice:0)
Block(-3,13,10,biomesoplenty:hard_ice:0)
Block(-3,13,11,biomesoplenty:hard_ice:0)
Block(-3,14,-7,biomesoplenty:hard_ice:0)
Block(-3,14,-6,biomesoplenty:hard_ice:0)
Block(-3,14,-5,biomesoplenty:hard_ice:0)
Block(-3,14,-4,biomesoplenty:hard_ice:0)
Block(-3,14,-3,biomesoplenty:hard_ice:0)
Block(-3,14,-2,biomesoplenty:hard_ice:0)
Block(-3,14,-1,biomesoplenty:hard_ice:0)
Block(-3,14,0,biomesoplenty:hard_ice:0)
Block(-3,14,1,biomesoplenty:hard_ice:0)
Block(-3,14,2,biomesoplenty:hard_ice:0)
Block(-3,14,3,biomesoplenty:hard_ice:0)
Block(-3,14,4,biomesoplenty:hard_ice:0)
Block(-3,14,5,biomesoplenty:hard_ice:0)
Block(-3,14,6,biomesoplenty:hard_ice:0)
Block(-3,14,7,biomesoplenty:hard_ice:0)
Block(-3,14,8,biomesoplenty:hard_ice:0)
Block(-3,14,9,biomesoplenty:hard_ice:0)
Block(-3,14,10,biomesoplenty:hard_ice:0)
Block(-3,14,11,biomesoplenty:hard_ice:0)
Block(-3,15,-8,biomesoplenty:hard_ice:0)
Block(-3,15,-7,biomesoplenty:hard_ice:0)
Block(-3,15,-6,biomesoplenty:hard_ice:0)
Block(-3,15,-5,biomesoplenty:hard_ice:0)
Block(-3,15,-4,biomesoplenty:hard_ice:0)
Block(-3,15,-3,biomesoplenty:hard_ice:0)
Block(-3,15,-2,biomesoplenty:hard_ice:0)
Block(-3,15,-1,biomesoplenty:hard_ice:0)
Block(-3,15,0,biomesoplenty:hard_ice:0)
Block(-3,15,1,biomesoplenty:hard_ice:0)
Block(-3,15,2,biomesoplenty:hard_ice:0)
Block(-3,15,3,biomesoplenty:hard_ice:0)
Block(-3,15,4,biomesoplenty:hard_ice:0)
Block(-3,15,5,biomesoplenty:hard_ice:0)
Block(-3,15,6,biomesoplenty:hard_ice:0)
Block(-3,15,7,biomesoplenty:hard_ice:0)
Block(-3,15,8,biomesoplenty:hard_ice:0)
Block(-3,15,9,biomesoplenty:hard_ice:0)
Block(-3,15,10,biomesoplenty:hard_ice:0)
Block(-3,15,11,biomesoplenty:hard_ice:0)
Block(-3,16,-8,biomesoplenty:hard_ice:0)
Block(-3,16,-7,biomesoplenty:hard_ice:0)
Block(-3,16,-6,biomesoplenty:hard_ice:0)
Block(-3,16,-5,biomesoplenty:hard_ice:0)
Block(-3,16,-4,biomesoplenty:hard_ice:0)
Block(-3,16,-3,biomesoplenty:hard_ice:0)
Block(-3,16,-2,biomesoplenty:hard_ice:0)
Block(-3,16,-1,biomesoplenty:hard_ice:0)
Block(-3,16,0,biomesoplenty:hard_ice:0)
Block(-3,16,1,biomesoplenty:hard_ice:0)
Block(-3,16,2,biomesoplenty:hard_ice:0)
Block(-3,16,3,biomesoplenty:hard_ice:0)
Block(-3,16,4,biomesoplenty:hard_ice:0)
Block(-3,16,5,biomesoplenty:hard_ice:0)
Block(-3,16,6,biomesoplenty:hard_ice:0)
Block(-3,16,7,biomesoplenty:hard_ice:0)
Block(-3,16,8,biomesoplenty:hard_ice:0)
Block(-3,16,9,biomesoplenty:hard_ice:0)
Block(-3,16,10,biomesoplenty:hard_ice:0)
Block(-3,16,11,biomesoplenty:hard_ice:0)
Block(-3,17,-8,biomesoplenty:hard_ice:0)
Block(-3,17,-7,biomesoplenty:hard_ice:0)
Block(-3,17,-6,biomesoplenty:hard_ice:0)
Block(-3,17,-5,biomesoplenty:hard_ice:0)
Block(-3,17,-4,biomesoplenty:hard_ice:0)
Block(-3,17,-3,biomesoplenty:hard_ice:0)
Block(-3,17,-2,biomesoplenty:hard_ice:0)
Block(-3,17,-1,biomesoplenty:hard_ice:0)
Block(-3,17,0,biomesoplenty:hard_ice:0)
Block(-3,17,1,biomesoplenty:hard_ice:0)
Block(-3,17,2,biomesoplenty:hard_ice:0)
Block(-3,17,3,biomesoplenty:hard_ice:0)
Block(-3,17,4,biomesoplenty:hard_ice:0)
Block(-3,17,5,biomesoplenty:hard_ice:0)
Block(-3,17,6,biomesoplenty:hard_ice:0)
Block(-3,17,7,biomesoplenty:hard_ice:0)
Block(-3,17,8,biomesoplenty:hard_ice:0)
Block(-3,17,9,biomesoplenty:hard_ice:0)
Block(-3,17,10,biomesoplenty:hard_ice:0)
Block(-3,18,-9,biomesoplenty:hard_ice:0)
Block(-3,18,-8,biomesoplenty:hard_ice:0)
Block(-3,18,-7,biomesoplenty:hard_ice:0)
Block(-3,18,-6,biomesoplenty:hard_ice:0)
Block(-3,18,-5,biomesoplenty:hard_ice:0)
Block(-3,18,-4,biomesoplenty:hard_ice:0)
Block(-3,18,-3,biomesoplenty:hard_ice:0)
Block(-3,18,-2,biomesoplenty:hard_ice:0)
Block(-3,18,-1,biomesoplenty:hard_ice:0)
Block(-3,18,0,biomesoplenty:hard_ice:0)
Block(-3,18,1,biomesoplenty:hard_ice:0)
Block(-3,18,2,biomesoplenty:hard_ice:0)
Block(-3,18,3,biomesoplenty:hard_ice:0)
Block(-3,18,4,biomesoplenty:hard_ice:0)
Block(-3,18,5,biomesoplenty:hard_ice:0)
Block(-3,18,6,biomesoplenty:hard_ice:0)
Block(-3,18,7,biomesoplenty:hard_ice:0)
Block(-3,18,8,biomesoplenty:hard_ice:0)
Block(-3,18,9,biomesoplenty:hard_ice:0)
Block(-3,18,10,biomesoplenty:hard_ice:0)
Block(-3,19,-7,biomesoplenty:hard_ice:0)
Block(-3,19,-6,biomesoplenty:hard_ice:0)
Block(-3,19,-5,biomesoplenty:hard_ice:0)
Block(-3,19,-4,biomesoplenty:hard_ice:0)
Block(-3,19,-3,biomesoplenty:hard_ice:0)
Block(-3,19,-2,biomesoplenty:hard_ice:0)
Block(-3,19,-1,biomesoplenty:hard_ice:0)
Block(-3,19,0,biomesoplenty:hard_ice:0)
Block(-3,19,1,biomesoplenty:hard_ice:0)
Block(-3,19,2,biomesoplenty:hard_ice:0)
Block(-3,19,3,biomesoplenty:hard_ice:0)
Block(-3,19,4,biomesoplenty:hard_ice:0)
Block(-3,19,5,biomesoplenty:hard_ice:0)
Block(-3,19,6,biomesoplenty:hard_ice:0)
Block(-3,19,7,biomesoplenty:hard_ice:0)
Block(-3,19,8,biomesoplenty:hard_ice:0)
Block(-3,20,-5,biomesoplenty:hard_ice:0)
Block(-3,20,-4,biomesoplenty:hard_ice:0)
Block(-3,20,-3,biomesoplenty:hard_ice:0)
Block(-3,20,-2,biomesoplenty:hard_ice:0)
Block(-3,20,-1,biomesoplenty:hard_ice:0)
Block(-3,20,0,biomesoplenty:hard_ice:0)
Block(-3,20,1,biomesoplenty:hard_ice:0)
Block(-3,20,2,biomesoplenty:hard_ice:0)
Block(-3,20,3,biomesoplenty:hard_ice:0)
Block(-3,20,4,biomesoplenty:hard_ice:0)
Block(-3,20,5,biomesoplenty:hard_ice:0)
Block(-3,20,6,biomesoplenty:hard_ice:0)
Block(-3,20,7,biomesoplenty:hard_ice:0)
Block(-3,21,-3,biomesoplenty:hard_ice:0)
Block(-3,21,-2,biomesoplenty:hard_ice:0)
Block(-3,21,-1,biomesoplenty:hard_ice:0)
Block(-3,21,0,biomesoplenty:hard_ice:0)
Block(-3,21,1,biomesoplenty:hard_ice:0)
Block(-3,21,2,biomesoplenty:hard_ice:0)
Block(-3,21,3,biomesoplenty:hard_ice:0)
Block(-3,21,4,biomesoplenty:hard_ice:0)
Block(-3,21,5,biomesoplenty:hard_ice:0)
Block(-3,21,6,biomesoplenty:hard_ice:0)
Block(-3,22,-2,biomesoplenty:hard_ice:0)
Block(-3,22,-1,biomesoplenty:hard_ice:0)
Block(-3,22,0,biomesoplenty:hard_ice:0)
Block(-3,22,1,biomesoplenty:hard_ice:0)
Block(-3,22,2,biomesoplenty:hard_ice:0)
Block(-3,22,3,biomesoplenty:hard_ice:0)
Block(-3,22,4,biomesoplenty:hard_ice:0)
Block(-3,22,5,biomesoplenty:hard_ice:0)
Block(-3,23,0,biomesoplenty:hard_ice:0)
Block(-3,23,1,biomesoplenty:hard_ice:0)
Block(-3,23,2,biomesoplenty:hard_ice:0)
Block(-3,23,3,biomesoplenty:hard_ice:0)
Block(-3,23,4,biomesoplenty:hard_ice:0)
Block(-3,24,1,biomesoplenty:hard_ice:0)
Block(-3,24,2,biomesoplenty:hard_ice:0)
Block(-3,24,3,biomesoplenty:hard_ice:0)
Block(-3,25,2,biomesoplenty:hard_ice:0)
Block(-2,6,-1,biomesoplenty:hard_ice:0)
Block(-2,6,0,biomesoplenty:hard_ice:0)
Block(-2,6,1,biomesoplenty:hard_ice:0)
Block(-2,6,2,biomesoplenty:hard_ice:0)
Block(-2,6,3,biomesoplenty:hard_ice:0)
Block(-2,7,-2,biomesoplenty:hard_ice:0)
Block(-2,7,-1,biomesoplenty:hard_ice:0)
Block(-2,7,0,biomesoplenty:hard_ice:0)
Block(-2,7,1,biomesoplenty:hard_ice:0)
Block(-2,7,2,biomesoplenty:hard_ice:0)
Block(-2,7,3,biomesoplenty:hard_ice:0)
Block(-2,7,4,biomesoplenty:hard_ice:0)
Block(-2,7,5,biomesoplenty:hard_ice:0)
Block(-2,8,-3,biomesoplenty:hard_ice:0)
Block(-2,8,-2,biomesoplenty:hard_ice:0)
Block(-2,8,-1,biomesoplenty:hard_ice:0)
Block(-2,8,0,biomesoplenty:hard_ice:0)
Block(-2,8,1,biomesoplenty:hard_ice:0)
Block(-2,8,2,biomesoplenty:hard_ice:0)
Block(-2,8,3,biomesoplenty:hard_ice:0)
Block(-2,8,4,biomesoplenty:hard_ice:0)
Block(-2,8,5,biomesoplenty:hard_ice:0)
Block(-2,8,6,biomesoplenty:hard_ice:0)
Block(-2,8,7,biomesoplenty:hard_ice:0)
Block(-2,8,8,biomesoplenty:hard_ice:0)
Block(-2,9,-4,biomesoplenty:hard_ice:0)
Block(-2,9,-3,biomesoplenty:hard_ice:0)
Block(-2,9,-2,biomesoplenty:hard_ice:0)
Block(-2,9,-1,biomesoplenty:hard_ice:0)
Block(-2,9,0,biomesoplenty:hard_ice:0)
Block(-2,9,1,biomesoplenty:hard_ice:0)
Block(-2,9,2,biomesoplenty:hard_ice:0)
Block(-2,9,3,biomesoplenty:hard_ice:0)
Block(-2,9,4,biomesoplenty:hard_ice:0)
Block(-2,9,5,biomesoplenty:hard_ice:0)
Block(-2,9,6,biomesoplenty:hard_ice:0)
Block(-2,9,7,biomesoplenty:hard_ice:0)
Block(-2,9,8,biomesoplenty:hard_ice:0)
Block(-2,9,9,biomesoplenty:hard_ice:0)
Block(-2,9,10,biomesoplenty:hard_ice:0)
Block(-2,10,-5,biomesoplenty:hard_ice:0)
Block(-2,10,-4,biomesoplenty:hard_ice:0)
Block(-2,10,-3,biomesoplenty:hard_ice:0)
Block(-2,10,-2,biomesoplenty:hard_ice:0)
Block(-2,10,-1,biomesoplenty:hard_ice:0)
Block(-2,10,0,biomesoplenty:hard_ice:0)
Block(-2,10,1,biomesoplenty:hard_ice:0)
Block(-2,10,2,biomesoplenty:hard_ice:0)
Block(-2,10,3,biomesoplenty:hard_ice:0)
Block(-2,10,4,biomesoplenty:hard_ice:0)
Block(-2,10,5,biomesoplenty:hard_ice:0)
Block(-2,10,6,biomesoplenty:hard_ice:0)
Block(-2,10,7,biomesoplenty:hard_ice:0)
Block(-2,10,8,biomesoplenty:hard_ice:0)
Block(-2,10,9,biomesoplenty:hard_ice:0)
Block(-2,10,10,biomesoplenty:hard_ice:0)
Block(-2,10,11,biomesoplenty:hard_ice:0)
Block(-2,10,12,biomesoplenty:hard_ice:0)
Block(-2,11,-6,biomesoplenty:hard_ice:0)
Block(-2,11,-5,biomesoplenty:hard_ice:0)
Block(-2,11,-4,biomesoplenty:hard_ice:0)
Block(-2,11,-3,biomesoplenty:hard_ice:0)
Block(-2,11,-2,biomesoplenty:hard_ice:0)
Block(-2,11,-1,biomesoplenty:hard_ice:0)
Block(-2,11,0,biomesoplenty:hard_ice:0)
Block(-2,11,1,biomesoplenty:hard_ice:0)
Block(-2,11,2,biomesoplenty:hard_ice:0)
Block(-2,11,3,biomesoplenty:hard_ice:0)
Block(-2,11,4,biomesoplenty:hard_ice:0)
Block(-2,11,5,biomesoplenty:hard_ice:0)
Block(-2,11,6,biomesoplenty:hard_ice:0)
Block(-2,11,7,biomesoplenty:hard_ice:0)
Block(-2,11,8,biomesoplenty:hard_ice:0)
Block(-2,11,9,biomesoplenty:hard_ice:0)
Block(-2,11,10,biomesoplenty:hard_ice:0)
Block(-2,11,11,biomesoplenty:hard_ice:0)
Block(-2,11,12,biomesoplenty:hard_ice:0)
Block(-2,12,-7,biomesoplenty:hard_ice:0)
Block(-2,12,-6,biomesoplenty:hard_ice:0)
Block(-2,12,-5,biomesoplenty:hard_ice:0)
Block(-2,12,-4,biomesoplenty:hard_ice:0)
Block(-2,12,-3,biomesoplenty:hard_ice:0)
Block(-2,12,-2,biomesoplenty:hard_ice:0)
Block(-2,12,-1,biomesoplenty:hard_ice:0)
Block(-2,12,0,biomesoplenty:hard_ice:0)
Block(-2,12,1,biomesoplenty:hard_ice:0)
Block(-2,12,2,biomesoplenty:hard_ice:0)
Block(-2,12,3,biomesoplenty:hard_ice:0)
Block(-2,12,4,biomesoplenty:hard_ice:0)
Block(-2,12,5,biomesoplenty:hard_ice:0)
Block(-2,12,6,biomesoplenty:hard_ice:0)
Block(-2,12,7,biomesoplenty:hard_ice:0)
Block(-2,12,8,biomesoplenty:hard_ice:0)
Block(-2,12,9,biomesoplenty:hard_ice:0)
Block(-2,12,10,biomesoplenty:hard_ice:0)
Block(-2,12,11,biomesoplenty:hard_ice:0)
Block(-2,13,-9,biomesoplenty:hard_ice:0)
Block(-2,13,-8,biomesoplenty:hard_ice:0)
Block(-2,13,-7,biomesoplenty:hard_ice:0)
Block(-2,13,-6,biomesoplenty:hard_ice:0)
Block(-2,13,-5,biomesoplenty:hard_ice:0)
Block(-2,13,-4,biomesoplenty:hard_ice:0)
Block(-2,13,-3,biomesoplenty:hard_ice:0)
Block(-2,13,-2,biomesoplenty:hard_ice:0)
Block(-2,13,-1,biomesoplenty:hard_ice:0)
Block(-2,13,0,biomesoplenty:hard_ice:0)
Block(-2,13,1,biomesoplenty:hard_ice:0)
Block(-2,13,2,biomesoplenty:hard_ice:0)
Block(-2,13,3,biomesoplenty:hard_ice:0)
Block(-2,13,4,biomesoplenty:hard_ice:0)
Block(-2,13,5,biomesoplenty:hard_ice:0)
Block(-2,13,6,biomesoplenty:hard_ice:0)
Block(-2,13,7,biomesoplenty:hard_ice:0)
Block(-2,13,8,biomesoplenty:hard_ice:0)
Block(-2,13,9,biomesoplenty:hard_ice:0)
Block(-2,13,10,biomesoplenty:hard_ice:0)
Block(-2,13,11,biomesoplenty:hard_ice:0)
Block(-2,14,-9,biomesoplenty:hard_ice:0)
Block(-2,14,-8,biomesoplenty:hard_ice:0)
Block(-2,14,-7,biomesoplenty:hard_ice:0)
Block(-2,14,-6,biomesoplenty:hard_ice:0)
Block(-2,14,-5,biomesoplenty:hard_ice:0)
Block(-2,14,-4,biomesoplenty:hard_ice:0)
Block(-2,14,-3,biomesoplenty:hard_ice:0)
Block(-2,14,-2,biomesoplenty:hard_ice:0)
Block(-2,14,-1,biomesoplenty:hard_ice:0)
Block(-2,14,0,biomesoplenty:hard_ice:0)
Block(-2,14,1,biomesoplenty:hard_ice:0)
Block(-2,14,2,biomesoplenty:hard_ice:0)
Block(-2,14,3,biomesoplenty:hard_ice:0)
Block(-2,14,4,biomesoplenty:hard_ice:0)
Block(-2,14,5,biomesoplenty:hard_ice:0)
Block(-2,14,6,biomesoplenty:hard_ice:0)
Block(-2,14,7,biomesoplenty:hard_ice:0)
Block(-2,14,8,biomesoplenty:hard_ice:0)
Block(-2,14,9,biomesoplenty:hard_ice:0)
Block(-2,14,10,biomesoplenty:hard_ice:0)
Block(-2,14,11,biomesoplenty:hard_ice:0)
Block(-2,15,-9,biomesoplenty:hard_ice:0)
Block(-2,15,-8,biomesoplenty:hard_ice:0)
Block(-2,15,-7,biomesoplenty:hard_ice:0)
Block(-2,15,-6,biomesoplenty:hard_ice:0)
Block(-2,15,-5,biomesoplenty:hard_ice:0)
Block(-2,15,-4,biomesoplenty:hard_ice:0)
Block(-2,15,-3,biomesoplenty:hard_ice:0)
Block(-2,15,-2,biomesoplenty:hard_ice:0)
Block(-2,15,-1,biomesoplenty:hard_ice:0)
Block(-2,15,0,biomesoplenty:hard_ice:0)
Block(-2,15,1,biomesoplenty:hard_ice:0)
Block(-2,15,2,biomesoplenty:hard_ice:0)
Block(-2,15,3,biomesoplenty:hard_ice:0)
Block(-2,15,4,biomesoplenty:hard_ice:0)
Block(-2,15,5,biomesoplenty:hard_ice:0)
Block(-2,15,6,biomesoplenty:hard_ice:0)
Block(-2,15,7,biomesoplenty:hard_ice:0)
Block(-2,15,8,biomesoplenty:hard_ice:0)
Block(-2,15,9,biomesoplenty:hard_ice:0)
Block(-2,15,10,biomesoplenty:hard_ice:0)
Block(-2,15,11,biomesoplenty:hard_ice:0)
Block(-2,16,-9,biomesoplenty:hard_ice:0)
Block(-2,16,-8,biomesoplenty:hard_ice:0)
Block(-2,16,-7,biomesoplenty:hard_ice:0)
Block(-2,16,-6,biomesoplenty:hard_ice:0)
Block(-2,16,-5,biomesoplenty:hard_ice:0)
Block(-2,16,-4,biomesoplenty:hard_ice:0)
Block(-2,16,-3,biomesoplenty:hard_ice:0)
Block(-2,16,-2,biomesoplenty:hard_ice:0)
Block(-2,16,-1,biomesoplenty:hard_ice:0)
Block(-2,16,0,biomesoplenty:hard_ice:0)
Block(-2,16,1,biomesoplenty:hard_ice:0)
Block(-2,16,2,biomesoplenty:hard_ice:0)
Block(-2,16,3,biomesoplenty:hard_ice:0)
Block(-2,16,4,biomesoplenty:hard_ice:0)
Block(-2,16,5,biomesoplenty:hard_ice:0)
Block(-2,16,6,biomesoplenty:hard_ice:0)
Block(-2,16,7,biomesoplenty:hard_ice:0)
Block(-2,16,8,biomesoplenty:hard_ice:0)
Block(-2,16,9,biomesoplenty:hard_ice:0)
Block(-2,16,10,biomesoplenty:hard_ice:0)
Block(-2,16,11,biomesoplenty:hard_ice:0)
Block(-2,17,-9,biomesoplenty:hard_ice:0)
Block(-2,17,-8,biomesoplenty:hard_ice:0)
Block(-2,17,-7,biomesoplenty:hard_ice:0)
Block(-2,17,-6,biomesoplenty:hard_ice:0)
Block(-2,17,-5,biomesoplenty:hard_ice:0)
Block(-2,17,-4,biomesoplenty:hard_ice:0)
Block(-2,17,-3,biomesoplenty:hard_ice:0)
Block(-2,17,-2,biomesoplenty:hard_ice:0)
Block(-2,17,-1,biomesoplenty:hard_ice:0)
Block(-2,17,0,biomesoplenty:hard_ice:0)
Block(-2,17,1,biomesoplenty:hard_ice:0)
Block(-2,17,2,biomesoplenty:hard_ice:0)
Block(-2,17,3,biomesoplenty:hard_ice:0)
Block(-2,17,4,biomesoplenty:hard_ice:0)
Block(-2,17,5,biomesoplenty:hard_ice:0)
Block(-2,17,6,biomesoplenty:hard_ice:0)
Block(-2,17,7,biomesoplenty:hard_ice:0)
Block(-2,17,8,biomesoplenty:hard_ice:0)
Block(-2,17,9,biomesoplenty:hard_ice:0)
Block(-2,17,10,biomesoplenty:hard_ice:0)
Block(-2,17,11,biomesoplenty:hard_ice:0)
Block(-2,18,-9,biomesoplenty:hard_ice:0)
Block(-2,18,-8,biomesoplenty:hard_ice:0)
Block(-2,18,-7,biomesoplenty:hard_ice:0)
Block(-2,18,-6,biomesoplenty:hard_ice:0)
Block(-2,18,-5,biomesoplenty:hard_ice:0)
Block(-2,18,-4,biomesoplenty:hard_ice:0)
Block(-2,18,-3,biomesoplenty:hard_ice:0)
Block(-2,18,-2,biomesoplenty:hard_ice:0)
Block(-2,18,-1,biomesoplenty:hard_ice:0)
Block(-2,18,0,biomesoplenty:hard_ice:0)
Block(-2,18,1,biomesoplenty:hard_ice:0)
Block(-2,18,2,biomesoplenty:hard_ice:0)
Block(-2,18,3,biomesoplenty:hard_ice:0)
Block(-2,18,4,biomesoplenty:hard_ice:0)
Block(-2,18,5,biomesoplenty:hard_ice:0)
Block(-2,18,6,biomesoplenty:hard_ice:0)
Block(-2,18,7,biomesoplenty:hard_ice:0)
Block(-2,18,8,biomesoplenty:hard_ice:0)
Block(-2,18,9,biomesoplenty:hard_ice:0)
Block(-2,18,10,biomesoplenty:hard_ice:0)
Block(-2,19,-9,biomesoplenty:hard_ice:0)
Block(-2,19,-8,biomesoplenty:hard_ice:0)
Block(-2,19,-7,biomesoplenty:hard_ice:0)
Block(-2,19,-6,biomesoplenty:hard_ice:0)
Block(-2,19,-5,biomesoplenty:hard_ice:0)
Block(-2,19,-4,biomesoplenty:hard_ice:0)
Block(-2,19,-3,biomesoplenty:hard_ice:0)
Block(-2,19,-2,biomesoplenty:hard_ice:0)
Block(-2,19,-1,biomesoplenty:hard_ice:0)
Block(-2,19,0,biomesoplenty:hard_ice:0)
Block(-2,19,1,biomesoplenty:hard_ice:0)
Block(-2,19,2,biomesoplenty:hard_ice:0)
Block(-2,19,3,biomesoplenty:hard_ice:0)
Block(-2,19,4,biomesoplenty:hard_ice:0)
Block(-2,19,5,biomesoplenty:hard_ice:0)
Block(-2,19,6,biomesoplenty:hard_ice:0)
Block(-2,19,7,biomesoplenty:hard_ice:0)
Block(-2,19,8,biomesoplenty:hard_ice:0)
Block(-2,19,9,biomesoplenty:hard_ice:0)
Block(-2,19,10,biomesoplenty:hard_ice:0)
Block(-2,20,-7,biomesoplenty:hard_ice:0)
Block(-2,20,-6,biomesoplenty:hard_ice:0)
Block(-2,20,-5,biomesoplenty:hard_ice:0)
Block(-2,20,-4,biomesoplenty:hard_ice:0)
Block(-2,20,-3,biomesoplenty:hard_ice:0)
Block(-2,20,-2,biomesoplenty:hard_ice:0)
Block(-2,20,-1,biomesoplenty:hard_ice:0)
Block(-2,20,0,biomesoplenty:hard_ice:0)
Block(-2,20,1,biomesoplenty:hard_ice:0)
Block(-2,20,2,biomesoplenty:hard_ice:0)
Block(-2,20,3,biomesoplenty:hard_ice:0)
Block(-2,20,4,biomesoplenty:hard_ice:0)
Block(-2,20,5,biomesoplenty:hard_ice:0)
Block(-2,20,6,biomesoplenty:hard_ice:0)
Block(-2,20,7,biomesoplenty:hard_ice:0)
Block(-2,20,8,biomesoplenty:hard_ice:0)
Block(-2,20,9,biomesoplenty:hard_ice:0)
Block(-2,21,-5,biomesoplenty:hard_ice:0)
Block(-2,21,-4,biomesoplenty:hard_ice:0)
Block(-2,21,-3,biomesoplenty:hard_ice:0)
Block(-2,21,-2,biomesoplenty:hard_ice:0)
Block(-2,21,-1,biomesoplenty:hard_ice:0)
Block(-2,21,0,biomesoplenty:hard_ice:0)
Block(-2,21,1,biomesoplenty:hard_ice:0)
Block(-2,21,2,biomesoplenty:hard_ice:0)
Block(-2,21,3,biomesoplenty:hard_ice:0)
Block(-2,21,4,biomesoplenty:hard_ice:0)
Block(-2,21,5,biomesoplenty:hard_ice:0)
Block(-2,21,6,biomesoplenty:hard_ice:0)
Block(-2,21,7,biomesoplenty:hard_ice:0)
Block(-2,22,-4,biomesoplenty:hard_ice:0)
Block(-2,22,-3,biomesoplenty:hard_ice:0)
Block(-2,22,-2,biomesoplenty:hard_ice:0)
Block(-2,22,-1,biomesoplenty:hard_ice:0)
Block(-2,22,0,biomesoplenty:hard_ice:0)
Block(-2,22,1,biomesoplenty:hard_ice:0)
Block(-2,22,2,biomesoplenty:hard_ice:0)
Block(-2,22,3,biomesoplenty:hard_ice:0)
Block(-2,22,4,biomesoplenty:hard_ice:0)
Block(-2,22,5,biomesoplenty:hard_ice:0)
Block(-2,22,6,biomesoplenty:hard_ice:0)
Block(-2,23,-2,biomesoplenty:hard_ice:0)
Block(-2,23,-1,biomesoplenty:hard_ice:0)
Block(-2,23,0,biomesoplenty:hard_ice:0)
Block(-2,23,1,biomesoplenty:hard_ice:0)
Block(-2,23,2,biomesoplenty:hard_ice:0)
Block(-2,23,3,biomesoplenty:hard_ice:0)
Block(-2,23,4,biomesoplenty:hard_ice:0)
Block(-2,23,5,biomesoplenty:hard_ice:0)
Block(-2,24,-1,biomesoplenty:hard_ice:0)
Block(-2,24,0,biomesoplenty:hard_ice:0)
Block(-2,24,1,biomesoplenty:hard_ice:0)
Block(-2,24,2,biomesoplenty:hard_ice:0)
Block(-2,24,3,biomesoplenty:hard_ice:0)
Block(-2,24,4,biomesoplenty:hard_ice:0)
Block(-2,25,0,biomesoplenty:hard_ice:0)
Block(-2,25,1,biomesoplenty:hard_ice:0)
Block(-2,25,2,biomesoplenty:hard_ice:0)
Block(-2,25,3,biomesoplenty:hard_ice:0)
Block(-1,6,-1,biomesoplenty:hard_ice:0)
Block(-1,6,0,biomesoplenty:hard_ice:0)
Block(-1,6,1,biomesoplenty:hard_ice:0)
Block(-1,6,2,biomesoplenty:hard_ice:0)
Block(-1,6,3,biomesoplenty:hard_ice:0)
Block(-1,6,4,biomesoplenty:hard_ice:0)
Block(-1,7,-2,biomesoplenty:hard_ice:0)
Block(-1,7,-1,biomesoplenty:hard_ice:0)
Block(-1,7,0,biomesoplenty:hard_ice:0)
Block(-1,7,1,biomesoplenty:hard_ice:0)
Block(-1,7,2,biomesoplenty:hard_ice:0)
Block(-1,7,3,biomesoplenty:hard_ice:0)
Block(-1,7,4,biomesoplenty:hard_ice:0)
Block(-1,7,5,biomesoplenty:hard_ice:0)
Block(-1,7,6,biomesoplenty:hard_ice:0)
Block(-1,8,-3,biomesoplenty:hard_ice:0)
Block(-1,8,-2,biomesoplenty:hard_ice:0)
Block(-1,8,-1,biomesoplenty:hard_ice:0)
Block(-1,8,0,biomesoplenty:hard_ice:0)
Block(-1,8,1,biomesoplenty:hard_ice:0)
Block(-1,8,2,biomesoplenty:hard_ice:0)
Block(-1,8,3,biomesoplenty:hard_ice:0)
Block(-1,8,4,biomesoplenty:hard_ice:0)
Block(-1,8,5,biomesoplenty:hard_ice:0)
Block(-1,8,6,biomesoplenty:hard_ice:0)
Block(-1,8,7,biomesoplenty:hard_ice:0)
Block(-1,8,8,biomesoplenty:hard_ice:0)
Block(-1,9,-5,biomesoplenty:hard_ice:0)
Block(-1,9,-4,biomesoplenty:hard_ice:0)
Block(-1,9,-3,biomesoplenty:hard_ice:0)
Block(-1,9,-2,biomesoplenty:hard_ice:0)
Block(-1,9,-1,biomesoplenty:hard_ice:0)
Block(-1,9,0,biomesoplenty:hard_ice:0)
Block(-1,9,1,biomesoplenty:hard_ice:0)
Block(-1,9,2,biomesoplenty:hard_ice:0)
Block(-1,9,3,biomesoplenty:hard_ice:0)
Block(-1,9,4,biomesoplenty:hard_ice:0)
Block(-1,9,5,biomesoplenty:hard_ice:0)
Block(-1,9,6,biomesoplenty:hard_ice:0)
Block(-1,9,7,biomesoplenty:hard_ice:0)
Block(-1,9,8,biomesoplenty:hard_ice:0)
Block(-1,9,9,biomesoplenty:hard_ice:0)
Block(-1,9,10,biomesoplenty:hard_ice:0)
Block(-1,9,11,biomesoplenty:hard_ice:0)
Block(-1,10,-6,biomesoplenty:hard_ice:0)
Block(-1,10,-5,biomesoplenty:hard_ice:0)
Block(-1,10,-4,biomesoplenty:hard_ice:0)
Block(-1,10,-3,biomesoplenty:hard_ice:0)
Block(-1,10,-2,biomesoplenty:hard_ice:0)
Block(-1,10,-1,biomesoplenty:hard_ice:0)
Block(-1,10,0,biomesoplenty:hard_ice:0)
Block(-1,10,1,biomesoplenty:hard_ice:0)
Block(-1,10,2,biomesoplenty:hard_ice:0)
Block(-1,10,3,biomesoplenty:hard_ice:0)
Block(-1,10,4,biomesoplenty:hard_ice:0)
Block(-1,10,5,biomesoplenty:hard_ice:0)
Block(-1,10,6,biomesoplenty:hard_ice:0)
Block(-1,10,7,biomesoplenty:hard_ice:0)
Block(-1,10,8,biomesoplenty:hard_ice:0)
Block(-1,10,9,biomesoplenty:hard_ice:0)
Block(-1,10,10,biomesoplenty:hard_ice:0)
Block(-1,10,11,biomesoplenty:hard_ice:0)
Block(-1,10,12,biomesoplenty:hard_ice:0)
Block(-1,11,-7,biomesoplenty:hard_ice:0)
Block(-1,11,-6,biomesoplenty:hard_ice:0)
Block(-1,11,-5,biomesoplenty:hard_ice:0)
Block(-1,11,-4,biomesoplenty:hard_ice:0)
Block(-1,11,-3,biomesoplenty:hard_ice:0)
Block(-1,11,-2,biomesoplenty:hard_ice:0)
Block(-1,11,-1,biomesoplenty:hard_ice:0)
Block(-1,11,0,biomesoplenty:hard_ice:0)
Block(-1,11,1,biomesoplenty:hard_ice:0)
Block(-1,11,2,biomesoplenty:hard_ice:0)
Block(-1,11,3,biomesoplenty:hard_ice:0)
Block(-1,11,4,biomesoplenty:hard_ice:0)
Block(-1,11,5,biomesoplenty:hard_ice:0)
Block(-1,11,6,biomesoplenty:hard_ice:0)
Block(-1,11,7,biomesoplenty:hard_ice:0)
Block(-1,11,8,biomesoplenty:hard_ice:0)
Block(-1,11,9,biomesoplenty:hard_ice:0)
Block(-1,11,10,biomesoplenty:hard_ice:0)
Block(-1,11,11,biomesoplenty:hard_ice:0)
Block(-1,11,12,biomesoplenty:hard_ice:0)
Block(-1,12,-8,biomesoplenty:hard_ice:0)
Block(-1,12,-7,biomesoplenty:hard_ice:0)
Block(-1,12,-6,biomesoplenty:hard_ice:0)
Block(-1,12,-5,biomesoplenty:hard_ice:0)
Block(-1,12,-4,biomesoplenty:hard_ice:0)
Block(-1,12,-3,biomesoplenty:hard_ice:0)
Block(-1,12,-2,biomesoplenty:hard_ice:0)
Block(-1,12,-1,biomesoplenty:hard_ice:0)
Block(-1,12,0,biomesoplenty:hard_ice:0)
Block(-1,12,1,biomesoplenty:hard_ice:0)
Block(-1,12,2,biomesoplenty:hard_ice:0)
Block(-1,12,3,biomesoplenty:hard_ice:0)
Block(-1,12,4,biomesoplenty:hard_ice:0)
Block(-1,12,5,biomesoplenty:hard_ice:0)
Block(-1,12,6,biomesoplenty:hard_ice:0)
Block(-1,12,7,biomesoplenty:hard_ice:0)
Block(-1,12,8,biomesoplenty:hard_ice:0)
Block(-1,12,9,biomesoplenty:hard_ice:0)
Block(-1,12,10,biomesoplenty:hard_ice:0)
Block(-1,12,11,biomesoplenty:hard_ice:0)
Block(-1,12,12,biomesoplenty:hard_ice:0)
Block(-1,13,-9,biomesoplenty:hard_ice:0)
Block(-1,13,-8,biomesoplenty:hard_ice:0)
Block(-1,13,-7,biomesoplenty:hard_ice:0)
Block(-1,13,-6,biomesoplenty:hard_ice:0)
Block(-1,13,-5,biomesoplenty:hard_ice:0)
Block(-1,13,-4,biomesoplenty:hard_ice:0)
Block(-1,13,-3,biomesoplenty:hard_ice:0)
Block(-1,13,-2,biomesoplenty:hard_ice:0)
Block(-1,13,-1,biomesoplenty:hard_ice:0)
Block(-1,13,0,biomesoplenty:hard_ice:0)
Block(-1,13,1,biomesoplenty:hard_ice:0)
Block(-1,13,2,biomesoplenty:hard_ice:0)
Block(-1,13,3,biomesoplenty:hard_ice:0)
Block(-1,13,4,biomesoplenty:hard_ice:0)
Block(-1,13,5,biomesoplenty:hard_ice:0)
Block(-1,13,6,biomesoplenty:hard_ice:0)
Block(-1,13,7,biomesoplenty:hard_ice:0)
Block(-1,13,8,biomesoplenty:hard_ice:0)
Block(-1,13,9,biomesoplenty:hard_ice:0)
Block(-1,13,10,biomesoplenty:hard_ice:0)
Block(-1,13,11,biomesoplenty:hard_ice:0)
Block(-1,13,12,biomesoplenty:hard_ice:0)
Block(-1,14,-9,biomesoplenty:hard_ice:0)
Block(-1,14,-8,biomesoplenty:hard_ice:0)
Block(-1,14,-7,biomesoplenty:hard_ice:0)
Block(-1,14,-6,biomesoplenty:hard_ice:0)
Block(-1,14,-5,biomesoplenty:hard_ice:0)
Block(-1,14,-4,biomesoplenty:hard_ice:0)
Block(-1,14,-3,biomesoplenty:hard_ice:0)
Block(-1,14,-2,biomesoplenty:hard_ice:0)
Block(-1,14,-1,biomesoplenty:hard_ice:0)
Block(-1,14,0,biomesoplenty:hard_ice:0)
Block(-1,14,1,biomesoplenty:hard_ice:0)
Block(-1,14,2,biomesoplenty:hard_ice:0)
Block(-1,14,3,biomesoplenty:hard_ice:0)
Block(-1,14,4,biomesoplenty:hard_ice:0)
Block(-1,14,5,biomesoplenty:hard_ice:0)
Block(-1,14,6,biomesoplenty:hard_ice:0)
Block(-1,14,7,biomesoplenty:hard_ice:0)
Block(-1,14,8,biomesoplenty:hard_ice:0)
Block(-1,14,9,biomesoplenty:hard_ice:0)
Block(-1,14,10,biomesoplenty:hard_ice:0)
Block(-1,14,11,biomesoplenty:hard_ice:0)
Block(-1,15,-9,biomesoplenty:hard_ice:0)
Block(-1,15,-8,biomesoplenty:hard_ice:0)
Block(-1,15,-7,biomesoplenty:hard_ice:0)
Block(-1,15,-6,biomesoplenty:hard_ice:0)
Block(-1,15,-5,biomesoplenty:hard_ice:0)
Block(-1,15,-4,biomesoplenty:hard_ice:0)
Block(-1,15,-3,biomesoplenty:hard_ice:0)
Block(-1,15,-2,biomesoplenty:hard_ice:0)
Block(-1,15,-1,biomesoplenty:hard_ice:0)
Block(-1,15,0,biomesoplenty:hard_ice:0)
Block(-1,15,1,biomesoplenty:hard_ice:0)
Block(-1,15,2,biomesoplenty:hard_ice:0)
Block(-1,15,3,biomesoplenty:hard_ice:0)
Block(-1,15,4,biomesoplenty:hard_ice:0)
Block(-1,15,5,biomesoplenty:hard_ice:0)
Block(-1,15,6,biomesoplenty:hard_ice:0)
Block(-1,15,7,biomesoplenty:hard_ice:0)
Block(-1,15,8,biomesoplenty:hard_ice:0)
Block(-1,15,9,biomesoplenty:hard_ice:0)
Block(-1,15,10,biomesoplenty:hard_ice:0)
Block(-1,15,11,biomesoplenty:hard_ice:0)
Block(-1,16,-9,biomesoplenty:hard_ice:0)
Block(-1,16,-8,biomesoplenty:hard_ice:0)
Block(-1,16,-7,biomesoplenty:hard_ice:0)
Block(-1,16,-6,biomesoplenty:hard_ice:0)
Block(-1,16,-5,biomesoplenty:hard_ice:0)
Block(-1,16,-4,biomesoplenty:hard_ice:0)
Block(-1,16,-3,biomesoplenty:hard_ice:0)
Block(-1,16,-2,biomesoplenty:hard_ice:0)
Block(-1,16,-1,biomesoplenty:hard_ice:0)
Block(-1,16,0,biomesoplenty:hard_ice:0)
Block(-1,16,1,biomesoplenty:hard_ice:0)
Block(-1,16,2,biomesoplenty:hard_ice:0)
Block(-1,16,3,biomesoplenty:hard_ice:0)
Block(-1,16,4,biomesoplenty:hard_ice:0)
Block(-1,16,5,biomesoplenty:hard_ice:0)
Block(-1,16,6,biomesoplenty:hard_ice:0)
Block(-1,16,7,biomesoplenty:hard_ice:0)
Block(-1,16,8,biomesoplenty:hard_ice:0)
Block(-1,16,9,biomesoplenty:hard_ice:0)
Block(-1,16,10,biomesoplenty:hard_ice:0)
Block(-1,16,11,biomesoplenty:hard_ice:0)
Block(-1,17,-9,biomesoplenty:hard_ice:0)
Block(-1,17,-8,biomesoplenty:hard_ice:0)
Block(-1,17,-7,biomesoplenty:hard_ice:0)
Block(-1,17,-6,biomesoplenty:hard_ice:0)
Block(-1,17,-5,biomesoplenty:hard_ice:0)
Block(-1,17,-4,biomesoplenty:hard_ice:0)
Block(-1,17,-3,biomesoplenty:hard_ice:0)
Block(-1,17,-2,biomesoplenty:hard_ice:0)
Block(-1,17,-1,biomesoplenty:hard_ice:0)
Block(-1,17,0,biomesoplenty:hard_ice:0)
Block(-1,17,1,biomesoplenty:hard_ice:0)
Block(-1,17,2,biomesoplenty:hard_ice:0)
Block(-1,17,3,biomesoplenty:hard_ice:0)
Block(-1,17,4,biomesoplenty:hard_ice:0)
Block(-1,17,5,biomesoplenty:hard_ice:0)
Block(-1,17,6,biomesoplenty:hard_ice:0)
Block(-1,17,7,biomesoplenty:hard_ice:0)
Block(-1,17,8,biomesoplenty:hard_ice:0)
Block(-1,17,9,biomesoplenty:hard_ice:0)
Block(-1,17,10,biomesoplenty:hard_ice:0)
Block(-1,17,11,biomesoplenty:hard_ice:0)
Block(-1,18,-9,biomesoplenty:hard_ice:0)
Block(-1,18,-8,biomesoplenty:hard_ice:0)
Block(-1,18,-7,biomesoplenty:hard_ice:0)
Block(-1,18,-6,biomesoplenty:hard_ice:0)
Block(-1,18,-5,biomesoplenty:hard_ice:0)
Block(-1,18,-4,biomesoplenty:hard_ice:0)
Block(-1,18,-3,biomesoplenty:hard_ice:0)
Block(-1,18,-2,biomesoplenty:hard_ice:0)
Block(-1,18,-1,biomesoplenty:hard_ice:0)
Block(-1,18,0,biomesoplenty:hard_ice:0)
Block(-1,18,1,biomesoplenty:hard_ice:0)
Block(-1,18,2,biomesoplenty:hard_ice:0)
Block(-1,18,3,biomesoplenty:hard_ice:0)
Block(-1,18,4,biomesoplenty:hard_ice:0)
Block(-1,18,5,biomesoplenty:hard_ice:0)
Block(-1,18,6,biomesoplenty:hard_ice:0)
Block(-1,18,7,biomesoplenty:hard_ice:0)
Block(-1,18,8,biomesoplenty:hard_ice:0)
Block(-1,18,9,biomesoplenty:hard_ice:0)
Block(-1,18,10,biomesoplenty:hard_ice:0)
Block(-1,18,11,biomesoplenty:hard_ice:0)
Block(-1,19,-9,biomesoplenty:hard_ice:0)
Block(-1,19,-8,biomesoplenty:hard_ice:0)
Block(-1,19,-7,biomesoplenty:hard_ice:0)
Block(-1,19,-6,biomesoplenty:hard_ice:0)
Block(-1,19,-5,biomesoplenty:hard_ice:0)
Block(-1,19,-4,biomesoplenty:hard_ice:0)
Block(-1,19,-3,biomesoplenty:hard_ice:0)
Block(-1,19,-2,biomesoplenty:hard_ice:0)
Block(-1,19,-1,biomesoplenty:hard_ice:0)
Block(-1,19,0,biomesoplenty:hard_ice:0)
Block(-1,19,1,biomesoplenty:hard_ice:0)
Block(-1,19,2,biomesoplenty:hard_ice:0)
Block(-1,19,3,biomesoplenty:hard_ice:0)
Block(-1,19,4,biomesoplenty:hard_ice:0)
Block(-1,19,5,biomesoplenty:hard_ice:0)
Block(-1,19,6,biomesoplenty:hard_ice:0)
Block(-1,19,7,biomesoplenty:hard_ice:0)
Block(-1,19,8,biomesoplenty:hard_ice:0)
Block(-1,19,9,biomesoplenty:hard_ice:0)
Block(-1,19,10,biomesoplenty:hard_ice:0)
Block(-1,20,-9,biomesoplenty:hard_ice:0)
Block(-1,20,-8,biomesoplenty:hard_ice:0)
Block(-1,20,-7,biomesoplenty:hard_ice:0)
Block(-1,20,-6,biomesoplenty:hard_ice:0)
Block(-1,20,-5,biomesoplenty:hard_ice:0)
Block(-1,20,-4,biomesoplenty:hard_ice:0)
Block(-1,20,-3,biomesoplenty:hard_ice:0)
Block(-1,20,-2,biomesoplenty:hard_ice:0)
Block(-1,20,-1,biomesoplenty:hard_ice:0)
Block(-1,20,0,biomesoplenty:hard_ice:0)
Block(-1,20,1,biomesoplenty:hard_ice:0)
Block(-1,20,2,biomesoplenty:hard_ice:0)
Block(-1,20,3,biomesoplenty:hard_ice:0)
Block(-1,20,4,biomesoplenty:hard_ice:0)
Block(-1,20,5,biomesoplenty:hard_ice:0)
Block(-1,20,6,biomesoplenty:hard_ice:0)
Block(-1,20,7,biomesoplenty:hard_ice:0)
Block(-1,20,8,biomesoplenty:hard_ice:0)
Block(-1,20,9,biomesoplenty:hard_ice:0)
Block(-1,20,10,biomesoplenty:hard_ice:0)
Block(-1,21,-8,biomesoplenty:hard_ice:0)
Block(-1,21,-7,biomesoplenty:hard_ice:0)
Block(-1,21,-6,biomesoplenty:hard_ice:0)
Block(-1,21,-5,biomesoplenty:hard_ice:0)
Block(-1,21,-4,biomesoplenty:hard_ice:0)
Block(-1,21,-3,biomesoplenty:hard_ice:0)
Block(-1,21,-2,biomesoplenty:hard_ice:0)
Block(-1,21,-1,biomesoplenty:hard_ice:0)
Block(-1,21,0,biomesoplenty:hard_ice:0)
Block(-1,21,1,biomesoplenty:hard_ice:0)
Block(-1,21,2,biomesoplenty:hard_ice:0)
Block(-1,21,3,biomesoplenty:hard_ice:0)
Block(-1,21,4,biomesoplenty:hard_ice:0)
Block(-1,21,5,biomesoplenty:hard_ice:0)
Block(-1,21,6,biomesoplenty:hard_ice:0)
Block(-1,21,7,biomesoplenty:hard_ice:0)
Block(-1,21,8,biomesoplenty:hard_ice:0)
Block(-1,21,9,biomesoplenty:hard_ice:0)
Block(-1,22,-7,biomesoplenty:hard_ice:0)
Block(-1,22,-6,biomesoplenty:hard_ice:0)
Block(-1,22,-5,biomesoplenty:hard_ice:0)
Block(-1,22,-4,biomesoplenty:hard_ice:0)
Block(-1,22,-3,biomesoplenty:hard_ice:0)
Block(-1,22,-2,biomesoplenty:hard_ice:0)
Block(-1,22,-1,biomesoplenty:hard_ice:0)
Block(-1,22,0,biomesoplenty:hard_ice:0)
Block(-1,22,1,biomesoplenty:hard_ice:0)
Block(-1,22,2,biomesoplenty:hard_ice:0)
Block(-1,22,3,biomesoplenty:hard_ice:0)
Block(-1,22,4,biomesoplenty:hard_ice:0)
Block(-1,22,5,biomesoplenty:hard_ice:0)
Block(-1,22,6,biomesoplenty:hard_ice:0)
Block(-1,22,7,biomesoplenty:hard_ice:0)
Block(-1,22,8,biomesoplenty:hard_ice:0)
Block(-1,23,-5,biomesoplenty:hard_ice:0)
Block(-1,23,-4,biomesoplenty:hard_ice:0)
Block(-1,23,-3,biomesoplenty:hard_ice:0)
Block(-1,23,-2,biomesoplenty:hard_ice:0)
Block(-1,23,-1,biomesoplenty:hard_ice:0)
Block(-1,23,0,biomesoplenty:hard_ice:0)
Block(-1,23,1,biomesoplenty:hard_ice:0)
Block(-1,23,2,biomesoplenty:hard_ice:0)
Block(-1,23,3,biomesoplenty:hard_ice:0)
Block(-1,23,4,biomesoplenty:hard_ice:0)
Block(-1,23,5,biomesoplenty:hard_ice:0)
Block(-1,23,6,biomesoplenty:hard_ice:0)
Block(-1,23,7,biomesoplenty:hard_ice:0)
Block(-1,24,-4,biomesoplenty:hard_ice:0)
Block(-1,24,-3,biomesoplenty:hard_ice:0)
Block(-1,24,-2,biomesoplenty:hard_ice:0)
Block(-1,24,-1,biomesoplenty:hard_ice:0)
Block(-1,24,0,biomesoplenty:hard_ice:0)
Block(-1,24,1,biomesoplenty:hard_ice:0)
Block(-1,24,2,biomesoplenty:hard_ice:0)
Block(-1,24,3,biomesoplenty:hard_ice:0)
Block(-1,24,4,biomesoplenty:hard_ice:0)
Block(-1,24,5,biomesoplenty:hard_ice:0)
Block(-1,25,-3,biomesoplenty:hard_ice:0)
Block(-1,25,-2,biomesoplenty:hard_ice:0)
Block(-1,25,-1,biomesoplenty:hard_ice:0)
Block(-1,25,0,biomesoplenty:hard_ice:0)
Block(-1,25,1,biomesoplenty:hard_ice:0)
Block(-1,25,2,biomesoplenty:hard_ice:0)
Block(-1,25,3,biomesoplenty:hard_ice:0)
Block(-1,26,-1,biomesoplenty:hard_ice:0)
Block(-1,26,0,biomesoplenty:hard_ice:0)
Block(-1,26,1,biomesoplenty:hard_ice:0)
Block(0,6,-2,biomesoplenty:hard_ice:0)
Block(0,6,-1,biomesoplenty:hard_ice:0)
Block(0,6,0,biomesoplenty:hard_ice:0)
Block(0,6,1,biomesoplenty:hard_ice:0)
Block(0,6,2,biomesoplenty:hard_ice:0)
Block(0,6,3,biomesoplenty:hard_ice:0)
Block(0,6,4,biomesoplenty:hard_ice:0)
Block(0,6,5,biomesoplenty:hard_ice:0)
Block(0,7,-3,biomesoplenty:hard_ice:0)
Block(0,7,-2,biomesoplenty:hard_ice:0)
Block(0,7,-1,biomesoplenty:hard_ice:0)
Block(0,7,0,biomesoplenty:hard_ice:0)
Block(0,7,1,biomesoplenty:hard_ice:0)
Block(0,7,2,biomesoplenty:hard_ice:0)
Block(0,7,3,biomesoplenty:hard_ice:0)
Block(0,7,4,biomesoplenty:hard_ice:0)
Block(0,7,5,biomesoplenty:hard_ice:0)
Block(0,7,6,biomesoplenty:hard_ice:0)
Block(0,7,7,biomesoplenty:hard_ice:0)
Block(0,8,-4,biomesoplenty:hard_ice:0)
Block(0,8,-3,biomesoplenty:hard_ice:0)
Block(0,8,-2,biomesoplenty:hard_ice:0)
Block(0,8,-1,biomesoplenty:hard_ice:0)
Block(0,8,0,biomesoplenty:hard_ice:0)
Block(0,8,1,biomesoplenty:hard_ice:0)
Block(0,8,2,biomesoplenty:hard_ice:0)
Block(0,8,3,biomesoplenty:hard_ice:0)
Block(0,8,4,biomesoplenty:hard_ice:0)
Block(0,8,5,biomesoplenty:hard_ice:0)
Block(0,8,6,biomesoplenty:hard_ice:0)
Block(0,8,7,biomesoplenty:hard_ice:0)
Block(0,8,8,biomesoplenty:hard_ice:0)
Block(0,8,9,biomesoplenty:hard_ice:0)
Block(0,8,10,biomesoplenty:hard_ice:0)
Block(0,9,-6,biomesoplenty:hard_ice:0)
Block(0,9,-5,biomesoplenty:hard_ice:0)
Block(0,9,-4,biomesoplenty:hard_ice:0)
Block(0,9,-3,biomesoplenty:hard_ice:0)
Block(0,9,-2,biomesoplenty:hard_ice:0)
Block(0,9,-1,biomesoplenty:hard_ice:0)
Block(0,9,0,biomesoplenty:hard_ice:0)
Block(0,9,1,biomesoplenty:hard_ice:0)
Block(0,9,2,biomesoplenty:hard_ice:0)
Block(0,9,3,biomesoplenty:hard_ice:0)
Block(0,9,4,biomesoplenty:hard_ice:0)
Block(0,9,5,biomesoplenty:hard_ice:0)
Block(0,9,6,biomesoplenty:hard_ice:0)
Block(0,9,7,biomesoplenty:hard_ice:0)
Block(0,9,8,biomesoplenty:hard_ice:0)
Block(0,9,9,biomesoplenty:hard_ice:0)
Block(0,9,10,biomesoplenty:hard_ice:0)
Block(0,9,11,biomesoplenty:hard_ice:0)
Block(0,10,-7,biomesoplenty:hard_ice:0)
Block(0,10,-6,biomesoplenty:hard_ice:0)
Block(0,10,-5,biomesoplenty:hard_ice:0)
Block(0,10,-4,biomesoplenty:hard_ice:0)
Block(0,10,-3,biomesoplenty:hard_ice:0)
Block(0,10,-2,biomesoplenty:hard_ice:0)
Block(0,10,-1,biomesoplenty:hard_ice:0)
Block(0,10,0,biomesoplenty:hard_ice:0)
Block(0,10,1,biomesoplenty:hard_ice:0)
Block(0,10,2,biomesoplenty:hard_ice:0)
Block(0,10,3,biomesoplenty:hard_ice:0)
Block(0,10,4,biomesoplenty:hard_ice:0)
Block(0,10,5,biomesoplenty:hard_ice:0)
Block(0,10,6,biomesoplenty:hard_ice:0)
Block(0,10,7,biomesoplenty:hard_ice:0)
Block(0,10,8,biomesoplenty:hard_ice:0)
Block(0,10,9,biomesoplenty:hard_ice:0)
Block(0,10,10,biomesoplenty:hard_ice:0)
Block(0,10,11,biomesoplenty:hard_ice:0)
Block(0,10,12,biomesoplenty:hard_ice:0)
Block(0,11,-8,biomesoplenty:hard_ice:0)
Block(0,11,-7,biomesoplenty:hard_ice:0)
Block(0,11,-6,biomesoplenty:hard_ice:0)
Block(0,11,-5,biomesoplenty:hard_ice:0)
Block(0,11,-4,biomesoplenty:hard_ice:0)
Block(0,11,-3,biomesoplenty:hard_ice:0)
Block(0,11,-2,biomesoplenty:hard_ice:0)
Block(0,11,-1,biomesoplenty:hard_ice:0)
Block(0,11,0,biomesoplenty:hard_ice:0)
Block(0,11,1,biomesoplenty:hard_ice:0)
Block(0,11,2,biomesoplenty:hard_ice:0)
Block(0,11,3,biomesoplenty:hard_ice:0)
Block(0,11,4,biomesoplenty:hard_ice:0)
Block(0,11,5,biomesoplenty:hard_ice:0)
Block(0,11,6,biomesoplenty:hard_ice:0)
Block(0,11,7,biomesoplenty:hard_ice:0)
Block(0,11,8,biomesoplenty:hard_ice:0)
Block(0,11,9,biomesoplenty:hard_ice:0)
Block(0,11,10,biomesoplenty:hard_ice:0)
Block(0,11,11,biomesoplenty:hard_ice:0)
Block(0,11,12,biomesoplenty:hard_ice:0)
Block(0,12,-9,biomesoplenty:hard_ice:0)
Block(0,12,-8,biomesoplenty:hard_ice:0)
Block(0,12,-7,biomesoplenty:hard_ice:0)
Block(0,12,-6,biomesoplenty:hard_ice:0)
Block(0,12,-5,biomesoplenty:hard_ice:0)
Block(0,12,-4,biomesoplenty:hard_ice:0)
Block(0,12,-3,biomesoplenty:hard_ice:0)
Block(0,12,-2,biomesoplenty:hard_ice:0)
Block(0,12,-1,biomesoplenty:hard_ice:0)
Block(0,12,0,biomesoplenty:hard_ice:0)
Block(0,12,1,biomesoplenty:hard_ice:0)
Block(0,12,2,biomesoplenty:hard_ice:0)
Block(0,12,3,biomesoplenty:hard_ice:0)
Block(0,12,4,biomesoplenty:hard_ice:0)
Block(0,12,5,biomesoplenty:hard_ice:0)
Block(0,12,6,biomesoplenty:hard_ice:0)
Block(0,12,7,biomesoplenty:hard_ice:0)
Block(0,12,8,biomesoplenty:hard_ice:0)
Block(0,12,9,biomesoplenty:hard_ice:0)
Block(0,12,10,biomesoplenty:hard_ice:0)
Block(0,12,11,biomesoplenty:hard_ice:0)
Block(0,12,12,biomesoplenty:hard_ice:0)
Block(0,13,-9,biomesoplenty:hard_ice:0)
Block(0,13,-8,biomesoplenty:hard_ice:0)
Block(0,13,-7,biomesoplenty:hard_ice:0)
Block(0,13,-6,biomesoplenty:hard_ice:0)
Block(0,13,-5,biomesoplenty:hard_ice:0)
Block(0,13,-4,biomesoplenty:hard_ice:0)
Block(0,13,-3,biomesoplenty:hard_ice:0)
Block(0,13,-2,biomesoplenty:hard_ice:0)
Block(0,13,-1,biomesoplenty:hard_ice:0)
Block(0,13,0,biomesoplenty:hard_ice:0)
Block(0,13,1,biomesoplenty:hard_ice:0)
Block(0,13,2,biomesoplenty:hard_ice:0)
Block(0,13,3,biomesoplenty:hard_ice:0)
Block(0,13,4,biomesoplenty:hard_ice:0)
Block(0,13,5,biomesoplenty:hard_ice:0)
Block(0,13,6,biomesoplenty:hard_ice:0)
Block(0,13,7,biomesoplenty:hard_ice:0)
Block(0,13,8,biomesoplenty:hard_ice:0)
Block(0,13,9,biomesoplenty:hard_ice:0)
Block(0,13,10,biomesoplenty:hard_ice:0)
Block(0,13,11,biomesoplenty:hard_ice:0)
Block(0,13,12,biomesoplenty:hard_ice:0)
Block(0,14,-10,biomesoplenty:hard_ice:0)
Block(0,14,-9,biomesoplenty:hard_ice:0)
Block(0,14,-8,biomesoplenty:hard_ice:0)
Block(0,14,-7,biomesoplenty:hard_ice:0)
Block(0,14,-6,biomesoplenty:hard_ice:0)
Block(0,14,-5,biomesoplenty:hard_ice:0)
Block(0,14,-4,biomesoplenty:hard_ice:0)
Block(0,14,-3,biomesoplenty:hard_ice:0)
Block(0,14,-2,biomesoplenty:hard_ice:0)
Block(0,14,-1,biomesoplenty:hard_ice:0)
Block(0,14,0,biomesoplenty:hard_ice:0)
Block(0,14,1,biomesoplenty:hard_ice:0)
Block(0,14,2,biomesoplenty:hard_ice:0)
Block(0,14,3,biomesoplenty:hard_ice:0)
Block(0,14,4,biomesoplenty:hard_ice:0)
Block(0,14,5,biomesoplenty:hard_ice:0)
Block(0,14,6,biomesoplenty:hard_ice:0)
Block(0,14,7,biomesoplenty:hard_ice:0)
Block(0,14,8,biomesoplenty:hard_ice:0)
Block(0,14,9,biomesoplenty:hard_ice:0)
Block(0,14,10,biomesoplenty:hard_ice:0)
Block(0,14,11,biomesoplenty:hard_ice:0)
Block(0,14,12,biomesoplenty:hard_ice:0)
Block(0,15,-9,biomesoplenty:hard_ice:0)
Block(0,15,-8,biomesoplenty:hard_ice:0)
Block(0,15,-7,biomesoplenty:hard_ice:0)
Block(0,15,-6,biomesoplenty:hard_ice:0)
Block(0,15,-5,biomesoplenty:hard_ice:0)
Block(0,15,-4,biomesoplenty:hard_ice:0)
Block(0,15,-3,biomesoplenty:hard_ice:0)
Block(0,15,-2,biomesoplenty:hard_ice:0)
Block(0,15,-1,biomesoplenty:hard_ice:0)
Block(0,15,0,biomesoplenty:hard_ice:0)
Block(0,15,1,biomesoplenty:hard_ice:0)
Block(0,15,2,biomesoplenty:hard_ice:0)
Block(0,15,3,biomesoplenty:hard_ice:0)
Block(0,15,4,biomesoplenty:hard_ice:0)
Block(0,15,5,biomesoplenty:hard_ice:0)
Block(0,15,6,biomesoplenty:hard_ice:0)
Block(0,15,7,biomesoplenty:hard_ice:0)
Block(0,15,8,biomesoplenty:hard_ice:0)
Block(0,15,9,biomesoplenty:hard_ice:0)
Block(0,15,10,biomesoplenty:hard_ice:0)
Block(0,15,11,biomesoplenty:hard_ice:0)
Block(0,15,12,biomesoplenty:hard_ice:0)
Block(0,16,-9,biomesoplenty:hard_ice:0)
Block(0,16,-8,biomesoplenty:hard_ice:0)
Block(0,16,-7,biomesoplenty:hard_ice:0)
Block(0,16,-6,biomesoplenty:hard_ice:0)
Block(0,16,-5,biomesoplenty:hard_ice:0)
Block(0,16,-4,biomesoplenty:hard_ice:0)
Block(0,16,-3,biomesoplenty:hard_ice:0)
Block(0,16,-2,biomesoplenty:hard_ice:0)
Block(0,16,-1,biomesoplenty:hard_ice:0)
Block(0,16,0,biomesoplenty:hard_ice:0)
Block(0,16,1,biomesoplenty:hard_ice:0)
Block(0,16,2,biomesoplenty:hard_ice:0)
Block(0,16,3,biomesoplenty:hard_ice:0)
Block(0,16,4,biomesoplenty:hard_ice:0)
Block(0,16,5,biomesoplenty:hard_ice:0)
Block(0,16,6,biomesoplenty:hard_ice:0)
Block(0,16,7,biomesoplenty:hard_ice:0)
Block(0,16,8,biomesoplenty:hard_ice:0)
Block(0,16,9,biomesoplenty:hard_ice:0)
Block(0,16,10,biomesoplenty:hard_ice:0)
Block(0,16,11,biomesoplenty:hard_ice:0)
Block(0,17,-9,biomesoplenty:hard_ice:0)
Block(0,17,-8,biomesoplenty:hard_ice:0)
Block(0,17,-7,biomesoplenty:hard_ice:0)
Block(0,17,-6,biomesoplenty:hard_ice:0)
Block(0,17,-5,biomesoplenty:hard_ice:0)
Block(0,17,-4,biomesoplenty:hard_ice:0)
Block(0,17,-3,biomesoplenty:hard_ice:0)
Block(0,17,-2,biomesoplenty:hard_ice:0)
Block(0,17,-1,biomesoplenty:hard_ice:0)
Block(0,17,0,biomesoplenty:hard_ice:0)
Block(0,17,1,biomesoplenty:hard_ice:0)
Block(0,17,2,biomesoplenty:hard_ice:0)
Block(0,17,3,biomesoplenty:hard_ice:0)
Block(0,17,4,biomesoplenty:hard_ice:0)
Block(0,17,5,biomesoplenty:hard_ice:0)
Block(0,17,6,biomesoplenty:hard_ice:0)
Block(0,17,7,biomesoplenty:hard_ice:0)
Block(0,17,8,biomesoplenty:hard_ice:0)
Block(0,17,9,biomesoplenty:hard_ice:0)
Block(0,17,10,biomesoplenty:hard_ice:0)
Block(0,17,11,biomesoplenty:hard_ice:0)
Block(0,18,-9,biomesoplenty:hard_ice:0)
Block(0,18,-8,biomesoplenty:hard_ice:0)
Block(0,18,-7,biomesoplenty:hard_ice:0)
Block(0,18,-6,biomesoplenty:hard_ice:0)
Block(0,18,-5,biomesoplenty:hard_ice:0)
Block(0,18,-4,biomesoplenty:hard_ice:0)
Block(0,18,-3,biomesoplenty:hard_ice:0)
Block(0,18,-2,biomesoplenty:hard_ice:0)
Block(0,18,-1,biomesoplenty:hard_ice:0)
Block(0,18,0,biomesoplenty:hard_ice:0)
Block(0,18,1,biomesoplenty:hard_ice:0)
Block(0,18,2,biomesoplenty:hard_ice:0)
Block(0,18,3,biomesoplenty:hard_ice:0)
Block(0,18,4,biomesoplenty:hard_ice:0)
Block(0,18,5,biomesoplenty:hard_ice:0)
Block(0,18,6,biomesoplenty:hard_ice:0)
Block(0,18,7,biomesoplenty:hard_ice:0)
Block(0,18,8,biomesoplenty:hard_ice:0)
Block(0,18,9,biomesoplenty:hard_ice:0)
Block(0,18,10,biomesoplenty:hard_ice:0)
Block(0,18,11,biomesoplenty:hard_ice:0)
Block(0,19,-10,biomesoplenty:hard_ice:0)
Block(0,19,-9,biomesoplenty:hard_ice:0)
Block(0,19,-8,biomesoplenty:hard_ice:0)
Block(0,19,-7,biomesoplenty:hard_ice:0)
Block(0,19,-6,biomesoplenty:hard_ice:0)
Block(0,19,-5,biomesoplenty:hard_ice:0)
Block(0,19,-4,biomesoplenty:hard_ice:0)
Block(0,19,-3,biomesoplenty:hard_ice:0)
Block(0,19,-2,biomesoplenty:hard_ice:0)
Block(0,19,-1,biomesoplenty:hard_ice:0)
Block(0,19,0,biomesoplenty:hard_ice:0)
Block(0,19,1,biomesoplenty:hard_ice:0)
Block(0,19,2,biomesoplenty:hard_ice:0)
Block(0,19,3,biomesoplenty:hard_ice:0)
Block(0,19,4,biomesoplenty:hard_ice:0)
Block(0,19,5,biomesoplenty:hard_ice:0)
Block(0,19,6,biomesoplenty:hard_ice:0)
Block(0,19,7,biomesoplenty:hard_ice:0)
Block(0,19,8,biomesoplenty:hard_ice:0)
Block(0,19,9,biomesoplenty:hard_ice:0)
Block(0,19,10,biomesoplenty:hard_ice:0)
Block(0,19,11,biomesoplenty:hard_ice:0)
Block(0,20,-10,biomesoplenty:hard_ice:0)
Block(0,20,-9,biomesoplenty:hard_ice:0)
Block(0,20,-8,biomesoplenty:hard_ice:0)
Block(0,20,-7,biomesoplenty:hard_ice:0)
Block(0,20,-6,biomesoplenty:hard_ice:0)
Block(0,20,-5,biomesoplenty:hard_ice:0)
Block(0,20,-4,biomesoplenty:hard_ice:0)
Block(0,20,-3,biomesoplenty:hard_ice:0)
Block(0,20,-2,biomesoplenty:hard_ice:0)
Block(0,20,-1,biomesoplenty:hard_ice:0)
Block(0,20,0,biomesoplenty:hard_ice:0)
Block(0,20,1,biomesoplenty:hard_ice:0)
Block(0,20,2,biomesoplenty:hard_ice:0)
Block(0,20,3,biomesoplenty:hard_ice:0)
Block(0,20,4,biomesoplenty:hard_ice:0)
Block(0,20,5,biomesoplenty:hard_ice:0)
Block(0,20,6,biomesoplenty:hard_ice:0)
Block(0,20,7,biomesoplenty:hard_ice:0)
Block(0,20,8,biomesoplenty:hard_ice:0)
Block(0,20,9,biomesoplenty:hard_ice:0)
Block(0,20,10,biomesoplenty:hard_ice:0)
Block(0,21,-9,biomesoplenty:hard_ice:0)
Block(0,21,-8,biomesoplenty:hard_ice:0)
Block(0,21,-7,biomesoplenty:hard_ice:0)
Block(0,21,-6,biomesoplenty:hard_ice:0)
Block(0,21,-5,biomesoplenty:hard_ice:0)
Block(0,21,-4,biomesoplenty:hard_ice:0)
Block(0,21,-3,biomesoplenty:hard_ice:0)
Block(0,21,-2,biomesoplenty:hard_ice:0)
Block(0,21,-1,biomesoplenty:hard_ice:0)
Block(0,21,0,biomesoplenty:hard_ice:0)
Block(0,21,1,biomesoplenty:hard_ice:0)
Block(0,21,2,biomesoplenty:hard_ice:0)
Block(0,21,3,biomesoplenty:hard_ice:0)
Block(0,21,4,biomesoplenty:hard_ice:0)
Block(0,21,5,biomesoplenty:hard_ice:0)
Block(0,21,6,biomesoplenty:hard_ice:0)
Block(0,21,7,biomesoplenty:hard_ice:0)
Block(0,21,8,biomesoplenty:hard_ice:0)
Block(0,21,9,biomesoplenty:hard_ice:0)
Block(0,21,10,biomesoplenty:hard_ice:0)
Block(0,22,-8,biomesoplenty:hard_ice:0)
Block(0,22,-7,biomesoplenty:hard_ice:0)
Block(0,22,-6,biomesoplenty:hard_ice:0)
Block(0,22,-5,biomesoplenty:hard_ice:0)
Block(0,22,-4,biomesoplenty:hard_ice:0)
Block(0,22,-3,biomesoplenty:hard_ice:0)
Block(0,22,-2,biomesoplenty:hard_ice:0)
Block(0,22,-1,biomesoplenty:hard_ice:0)
Block(0,22,0,biomesoplenty:hard_ice:0)
Block(0,22,1,biomesoplenty:hard_ice:0)
Block(0,22,2,biomesoplenty:hard_ice:0)
Block(0,22,3,biomesoplenty:hard_ice:0)
Block(0,22,4,biomesoplenty:hard_ice:0)
Block(0,22,5,biomesoplenty:hard_ice:0)
Block(0,22,6,biomesoplenty:hard_ice:0)
Block(0,22,7,biomesoplenty:hard_ice:0)
Block(0,22,8,biomesoplenty:hard_ice:0)
Block(0,22,9,biomesoplenty:hard_ice:0)
Block(0,22,10,biomesoplenty:hard_ice:0)
Block(0,23,-7,biomesoplenty:hard_ice:0)
Block(0,23,-6,biomesoplenty:hard_ice:0)
Block(0,23,-5,biomesoplenty:hard_ice:0)
Block(0,23,-4,biomesoplenty:hard_ice:0)
Block(0,23,-3,biomesoplenty:hard_ice:0)
Block(0,23,-2,biomesoplenty:hard_ice:0)
Block(0,23,-1,biomesoplenty:hard_ice:0)
Block(0,23,0,biomesoplenty:hard_ice:0)
Block(0,23,1,biomesoplenty:hard_ice:0)
Block(0,23,2,biomesoplenty:hard_ice:0)
Block(0,23,3,biomesoplenty:hard_ice:0)
Block(0,23,4,biomesoplenty:hard_ice:0)
Block(0,23,5,biomesoplenty:hard_ice:0)
Block(0,23,6,biomesoplenty:hard_ice:0)
Block(0,23,7,biomesoplenty:hard_ice:0)
Block(0,23,8,biomesoplenty:hard_ice:0)
Block(0,24,-6,biomesoplenty:hard_ice:0)
Block(0,24,-5,biomesoplenty:hard_ice:0)
Block(0,24,-4,biomesoplenty:hard_ice:0)
Block(0,24,-3,biomesoplenty:hard_ice:0)
Block(0,24,-2,biomesoplenty:hard_ice:0)
Block(0,24,-1,biomesoplenty:hard_ice:0)
Block(0,24,0,biomesoplenty:hard_ice:0)
Block(0,24,1,biomesoplenty:hard_ice:0)
Block(0,24,2,biomesoplenty:hard_ice:0)
Block(0,24,3,biomesoplenty:hard_ice:0)
Block(0,24,4,biomesoplenty:hard_ice:0)
Block(0,24,5,biomesoplenty:hard_ice:0)
Block(0,24,6,biomesoplenty:hard_ice:0)
Block(0,24,7,biomesoplenty:hard_ice:0)
Block(0,25,-4,biomesoplenty:hard_ice:0)
Block(0,25,-3,biomesoplenty:hard_ice:0)
Block(0,25,-2,biomesoplenty:hard_ice:0)
Block(0,25,-1,biomesoplenty:hard_ice:0)
Block(0,25,0,biomesoplenty:hard_ice:0)
Block(0,25,1,biomesoplenty:hard_ice:0)
Block(0,25,2,biomesoplenty:hard_ice:0)
Block(0,25,3,biomesoplenty:hard_ice:0)
Block(0,25,4,biomesoplenty:hard_ice:0)
Block(0,25,5,biomesoplenty:hard_ice:0)
Block(0,26,-3,biomesoplenty:hard_ice:0)
Block(0,26,-2,biomesoplenty:hard_ice:0)
Block(0,26,-1,biomesoplenty:hard_ice:0)
Block(0,26,0,biomesoplenty:hard_ice:0)
Block(0,26,1,biomesoplenty:hard_ice:0)
Block(0,26,2,biomesoplenty:hard_ice:0)
Block(0,27,-1,biomesoplenty:hard_ice:0)
Block(1,6,-3,biomesoplenty:hard_ice:0)
Block(1,6,-2,biomesoplenty:hard_ice:0)
Block(1,6,-1,biomesoplenty:hard_ice:0)
Block(1,6,0,biomesoplenty:hard_ice:0)
Block(1,6,1,biomesoplenty:hard_ice:0)
Block(1,6,2,biomesoplenty:hard_ice:0)
Block(1,6,3,biomesoplenty:hard_ice:0)
Block(1,6,4,biomesoplenty:hard_ice:0)
Block(1,6,5,biomesoplenty:hard_ice:0)
Block(1,7,-4,biomesoplenty:hard_ice:0)
Block(1,7,-3,biomesoplenty:hard_ice:0)
Block(1,7,-2,biomesoplenty:hard_ice:0)
Block(1,7,-1,biomesoplenty:hard_ice:0)
Block(1,7,0,biomesoplenty:hard_ice:0)
Block(1,7,1,biomesoplenty:hard_ice:0)
Block(1,7,2,biomesoplenty:hard_ice:0)
Block(1,7,3,biomesoplenty:hard_ice:0)
Block(1,7,4,biomesoplenty:hard_ice:0)
Block(1,7,5,biomesoplenty:hard_ice:0)
Block(1,7,6,biomesoplenty:hard_ice:0)
Block(1,7,7,biomesoplenty:hard_ice:0)
Block(1,7,8,biomesoplenty:hard_ice:0)
Block(1,8,-5,biomesoplenty:hard_ice:0)
Block(1,8,-4,biomesoplenty:hard_ice:0)
Block(1,8,-3,biomesoplenty:hard_ice:0)
Block(1,8,-2,biomesoplenty:hard_ice:0)
Block(1,8,-1,biomesoplenty:hard_ice:0)
Block(1,8,0,biomesoplenty:hard_ice:0)
Block(1,8,1,biomesoplenty:hard_ice:0)
Block(1,8,2,biomesoplenty:hard_ice:0)
Block(1,8,3,biomesoplenty:hard_ice:0)
Block(1,8,4,biomesoplenty:hard_ice:0)
Block(1,8,5,biomesoplenty:hard_ice:0)
Block(1,8,6,biomesoplenty:hard_ice:0)
Block(1,8,7,biomesoplenty:hard_ice:0)
Block(1,8,8,biomesoplenty:hard_ice:0)
Block(1,8,9,biomesoplenty:hard_ice:0)
Block(1,8,10,biomesoplenty:hard_ice:0)
Block(1,8,11,biomesoplenty:hard_ice:0)
Block(1,9,-6,biomesoplenty:hard_ice:0)
Block(1,9,-5,biomesoplenty:hard_ice:0)
Block(1,9,-4,biomesoplenty:hard_ice:0)
Block(1,9,-3,biomesoplenty:hard_ice:0)
Block(1,9,-2,biomesoplenty:hard_ice:0)
Block(1,9,-1,biomesoplenty:hard_ice:0)
Block(1,9,0,biomesoplenty:hard_ice:0)
Block(1,9,1,biomesoplenty:hard_ice:0)
Block(1,9,2,biomesoplenty:hard_ice:0)
Block(1,9,3,biomesoplenty:hard_ice:0)
Block(1,9,4,biomesoplenty:hard_ice:0)
Block(1,9,5,biomesoplenty:hard_ice:0)
Block(1,9,6,biomesoplenty:hard_ice:0)
Block(1,9,7,biomesoplenty:hard_ice:0)
Block(1,9,8,biomesoplenty:hard_ice:0)
Block(1,9,9,biomesoplenty:hard_ice:0)
Block(1,9,10,biomesoplenty:hard_ice:0)
Block(1,9,11,biomesoplenty:hard_ice:0)
Block(1,9,12,biomesoplenty:hard_ice:0)
Block(1,10,-8,biomesoplenty:hard_ice:0)
Block(1,10,-7,biomesoplenty:hard_ice:0)
Block(1,10,-6,biomesoplenty:hard_ice:0)
Block(1,10,-5,biomesoplenty:hard_ice:0)
Block(1,10,-4,biomesoplenty:hard_ice:0)
Block(1,10,-3,biomesoplenty:hard_ice:0)
Block(1,10,-2,biomesoplenty:hard_ice:0)
Block(1,10,-1,biomesoplenty:hard_ice:0)
Block(1,10,0,biomesoplenty:hard_ice:0)
Block(1,10,1,biomesoplenty:hard_ice:0)
Block(1,10,2,biomesoplenty:hard_ice:0)
Block(1,10,3,biomesoplenty:hard_ice:0)
Block(1,10,4,biomesoplenty:hard_ice:0)
Block(1,10,5,biomesoplenty:hard_ice:0)
Block(1,10,6,biomesoplenty:hard_ice:0)
Block(1,10,7,biomesoplenty:hard_ice:0)
Block(1,10,8,biomesoplenty:hard_ice:0)
Block(1,10,9,biomesoplenty:hard_ice:0)
Block(1,10,10,biomesoplenty:hard_ice:0)
Block(1,10,11,biomesoplenty:hard_ice:0)
Block(1,10,12,biomesoplenty:hard_ice:0)
Block(1,11,-9,biomesoplenty:hard_ice:0)
Block(1,11,-8,biomesoplenty:hard_ice:0)
Block(1,11,-7,biomesoplenty:hard_ice:0)
Block(1,11,-6,biomesoplenty:hard_ice:0)
Block(1,11,-5,biomesoplenty:hard_ice:0)
Block(1,11,-4,biomesoplenty:hard_ice:0)
Block(1,11,-3,biomesoplenty:hard_ice:0)
Block(1,11,-2,biomesoplenty:hard_ice:0)
Block(1,11,-1,biomesoplenty:hard_ice:0)
Block(1,11,0,biomesoplenty:hard_ice:0)
Block(1,11,1,biomesoplenty:hard_ice:0)
Block(1,11,2,biomesoplenty:hard_ice:0)
Block(1,11,3,biomesoplenty:hard_ice:0)
Block(1,11,4,biomesoplenty:hard_ice:0)
Block(1,11,5,biomesoplenty:hard_ice:0)
Block(1,11,6,biomesoplenty:hard_ice:0)
Block(1,11,7,biomesoplenty:hard_ice:0)
Block(1,11,8,biomesoplenty:hard_ice:0)
Block(1,11,9,biomesoplenty:hard_ice:0)
Block(1,11,10,biomesoplenty:hard_ice:0)
Block(1,11,11,biomesoplenty:hard_ice:0)
Block(1,11,12,biomesoplenty:hard_ice:0)
Block(1,12,-10,biomesoplenty:hard_ice:0)
Block(1,12,-9,biomesoplenty:hard_ice:0)
Block(1,12,-8,biomesoplenty:hard_ice:0)
Block(1,12,-7,biomesoplenty:hard_ice:0)
Block(1,12,-6,biomesoplenty:hard_ice:0)
Block(1,12,-5,biomesoplenty:hard_ice:0)
Block(1,12,-4,biomesoplenty:hard_ice:0)
Block(1,12,-3,biomesoplenty:hard_ice:0)
Block(1,12,-2,biomesoplenty:hard_ice:0)
Block(1,12,-1,biomesoplenty:hard_ice:0)
Block(1,12,0,biomesoplenty:hard_ice:0)
Block(1,12,1,biomesoplenty:hard_ice:0)
Block(1,12,2,biomesoplenty:hard_ice:0)
Block(1,12,3,biomesoplenty:hard_ice:0)
Block(1,12,4,biomesoplenty:hard_ice:0)
Block(1,12,5,biomesoplenty:hard_ice:0)
Block(1,12,6,biomesoplenty:hard_ice:0)
Block(1,12,7,biomesoplenty:hard_ice:0)
Block(1,12,8,biomesoplenty:hard_ice:0)
Block(1,12,9,biomesoplenty:hard_ice:0)
Block(1,12,10,biomesoplenty:hard_ice:0)
Block(1,12,11,biomesoplenty:hard_ice:0)
Block(1,12,12,biomesoplenty:hard_ice:0)
Block(1,13,-10,biomesoplenty:hard_ice:0)
Block(1,13,-9,biomesoplenty:hard_ice:0)
Block(1,13,-8,biomesoplenty:hard_ice:0)
Block(1,13,-7,biomesoplenty:hard_ice:0)
Block(1,13,-6,biomesoplenty:hard_ice:0)
Block(1,13,-5,biomesoplenty:hard_ice:0)
Block(1,13,-4,biomesoplenty:hard_ice:0)
Block(1,13,-3,biomesoplenty:hard_ice:0)
Block(1,13,-2,biomesoplenty:hard_ice:0)
Block(1,13,-1,biomesoplenty:hard_ice:0)
Block(1,13,0,biomesoplenty:hard_ice:0)
Block(1,13,1,biomesoplenty:hard_ice:0)
Block(1,13,2,biomesoplenty:hard_ice:0)
Block(1,13,3,biomesoplenty:hard_ice:0)
Block(1,13,4,biomesoplenty:hard_ice:0)
Block(1,13,5,biomesoplenty:hard_ice:0)
Block(1,13,6,biomesoplenty:hard_ice:0)
Block(1,13,7,biomesoplenty:hard_ice:0)
Block(1,13,8,biomesoplenty:hard_ice:0)
Block(1,13,9,biomesoplenty:hard_ice:0)
Block(1,13,10,biomesoplenty:hard_ice:0)
Block(1,13,11,biomesoplenty:hard_ice:0)
Block(1,13,12,biomesoplenty:hard_ice:0)
Block(1,14,-10,biomesoplenty:hard_ice:0)
Block(1,14,-9,biomesoplenty:hard_ice:0)
Block(1,14,-8,biomesoplenty:hard_ice:0)
Block(1,14,-7,biomesoplenty:hard_ice:0)
Block(1,14,-6,biomesoplenty:hard_ice:0)
Block(1,14,-5,biomesoplenty:hard_ice:0)
Block(1,14,-4,biomesoplenty:hard_ice:0)
Block(1,14,-3,biomesoplenty:hard_ice:0)
Block(1,14,-2,biomesoplenty:hard_ice:0)
Block(1,14,-1,biomesoplenty:hard_ice:0)
Block(1,14,0,biomesoplenty:hard_ice:0)
Block(1,14,1,biomesoplenty:hard_ice:0)
Block(1,14,2,biomesoplenty:hard_ice:0)
Block(1,14,3,biomesoplenty:hard_ice:0)
Block(1,14,4,biomesoplenty:hard_ice:0)
Block(1,14,5,biomesoplenty:hard_ice:0)
Block(1,14,6,biomesoplenty:hard_ice:0)
Block(1,14,7,biomesoplenty:hard_ice:0)
Block(1,14,8,biomesoplenty:hard_ice:0)
Block(1,14,9,biomesoplenty:hard_ice:0)
Block(1,14,10,biomesoplenty:hard_ice:0)
Block(1,14,11,biomesoplenty:hard_ice:0)
Block(1,14,12,biomesoplenty:hard_ice:0)
Block(1,15,-10,biomesoplenty:hard_ice:0)
Block(1,15,-9,biomesoplenty:hard_ice:0)
Block(1,15,-8,biomesoplenty:hard_ice:0)
Block(1,15,-7,biomesoplenty:hard_ice:0)
Block(1,15,-6,biomesoplenty:hard_ice:0)
Block(1,15,-5,biomesoplenty:hard_ice:0)
Block(1,15,-4,biomesoplenty:hard_ice:0)
Block(1,15,-3,biomesoplenty:hard_ice:0)
Block(1,15,-2,biomesoplenty:hard_ice:0)
Block(1,15,-1,biomesoplenty:hard_ice:0)
Block(1,15,0,biomesoplenty:hard_ice:0)
Block(1,15,1,biomesoplenty:hard_ice:0)
Block(1,15,2,biomesoplenty:hard_ice:0)
Block(1,15,3,biomesoplenty:hard_ice:0)
Block(1,15,4,biomesoplenty:hard_ice:0)
Block(1,15,5,biomesoplenty:hard_ice:0)
Block(1,15,6,biomesoplenty:hard_ice:0)
Block(1,15,7,biomesoplenty:hard_ice:0)
Block(1,15,8,biomesoplenty:hard_ice:0)
Block(1,15,9,biomesoplenty:hard_ice:0)
Block(1,15,10,biomesoplenty:hard_ice:0)
Block(1,15,11,biomesoplenty:hard_ice:0)
Block(1,15,12,biomesoplenty:hard_ice:0)
Block(1,16,-10,biomesoplenty:hard_ice:0)
Block(1,16,-9,biomesoplenty:hard_ice:0)
Block(1,16,-8,biomesoplenty:hard_ice:0)
Block(1,16,-7,biomesoplenty:hard_ice:0)
Block(1,16,-6,biomesoplenty:hard_ice:0)
Block(1,16,-5,biomesoplenty:hard_ice:0)
Block(1,16,-4,biomesoplenty:hard_ice:0)
Block(1,16,-3,biomesoplenty:hard_ice:0)
Block(1,16,-2,biomesoplenty:hard_ice:0)
Block(1,16,-1,biomesoplenty:hard_ice:0)
Block(1,16,0,biomesoplenty:hard_ice:0)
Block(1,16,1,biomesoplenty:hard_ice:0)
Block(1,16,2,biomesoplenty:hard_ice:0)
Block(1,16,3,biomesoplenty:hard_ice:0)
Block(1,16,4,biomesoplenty:hard_ice:0)
Block(1,16,5,biomesoplenty:hard_ice:0)
Block(1,16,6,biomesoplenty:hard_ice:0)
Block(1,16,7,biomesoplenty:hard_ice:0)
Block(1,16,8,biomesoplenty:hard_ice:0)
Block(1,16,9,biomesoplenty:hard_ice:0)
Block(1,16,10,biomesoplenty:hard_ice:0)
Block(1,16,11,biomesoplenty:hard_ice:0)
Block(1,16,12,biomesoplenty:hard_ice:0)
Block(1,17,-10,biomesoplenty:hard_ice:0)
Block(1,17,-9,biomesoplenty:hard_ice:0)
Block(1,17,-8,biomesoplenty:hard_ice:0)
Block(1,17,-7,biomesoplenty:hard_ice:0)
Block(1,17,-6,biomesoplenty:hard_ice:0)
Block(1,17,-5,biomesoplenty:hard_ice:0)
Block(1,17,-4,biomesoplenty:hard_ice:0)
Block(1,17,-3,biomesoplenty:hard_ice:0)
Block(1,17,-2,biomesoplenty:hard_ice:0)
Block(1,17,-1,biomesoplenty:hard_ice:0)
Block(1,17,0,biomesoplenty:hard_ice:0)
Block(1,17,1,biomesoplenty:hard_ice:0)
Block(1,17,2,biomesoplenty:hard_ice:0)
Block(1,17,3,biomesoplenty:hard_ice:0)
Block(1,17,4,biomesoplenty:hard_ice:0)
Block(1,17,5,biomesoplenty:hard_ice:0)
Block(1,17,6,biomesoplenty:hard_ice:0)
Block(1,17,7,biomesoplenty:hard_ice:0)
Block(1,17,8,biomesoplenty:hard_ice:0)
Block(1,17,9,biomesoplenty:hard_ice:0)
Block(1,17,10,biomesoplenty:hard_ice:0)
Block(1,17,11,biomesoplenty:hard_ice:0)
Block(1,18,-10,biomesoplenty:hard_ice:0)
Block(1,18,-9,biomesoplenty:hard_ice:0)
Block(1,18,-8,biomesoplenty:hard_ice:0)
Block(1,18,-7,biomesoplenty:hard_ice:0)
Block(1,18,-6,biomesoplenty:hard_ice:0)
Block(1,18,-5,biomesoplenty:hard_ice:0)
Block(1,18,-4,biomesoplenty:hard_ice:0)
Block(1,18,-3,biomesoplenty:hard_ice:0)
Block(1,18,-2,biomesoplenty:hard_ice:0)
Block(1,18,-1,biomesoplenty:hard_ice:0)
Block(1,18,0,biomesoplenty:hard_ice:0)
Block(1,18,1,biomesoplenty:hard_ice:0)
Block(1,18,2,biomesoplenty:hard_ice:0)
Block(1,18,3,biomesoplenty:hard_ice:0)
Block(1,18,4,biomesoplenty:hard_ice:0)
Block(1,18,5,biomesoplenty:hard_ice:0)
Block(1,18,6,biomesoplenty:hard_ice:0)
Block(1,18,7,biomesoplenty:hard_ice:0)
Block(1,18,8,biomesoplenty:hard_ice:0)
Block(1,18,9,biomesoplenty:hard_ice:0)
Block(1,18,10,biomesoplenty:hard_ice:0)
Block(1,18,11,biomesoplenty:hard_ice:0)
Block(1,19,-10,biomesoplenty:hard_ice:0)
Block(1,19,-9,biomesoplenty:hard_ice:0)
Block(1,19,-8,biomesoplenty:hard_ice:0)
Block(1,19,-7,biomesoplenty:hard_ice:0)
Block(1,19,-6,biomesoplenty:hard_ice:0)
Block(1,19,-5,biomesoplenty:hard_ice:0)
Block(1,19,-4,biomesoplenty:hard_ice:0)
Block(1,19,-3,biomesoplenty:hard_ice:0)
Block(1,19,-2,biomesoplenty:hard_ice:0)
Block(1,19,-1,biomesoplenty:hard_ice:0)
Block(1,19,0,biomesoplenty:hard_ice:0)
Block(1,19,1,biomesoplenty:hard_ice:0)
Block(1,19,2,biomesoplenty:hard_ice:0)
Block(1,19,3,biomesoplenty:hard_ice:0)
Block(1,19,4,biomesoplenty:hard_ice:0)
Block(1,19,5,biomesoplenty:hard_ice:0)
Block(1,19,6,biomesoplenty:hard_ice:0)
Block(1,19,7,biomesoplenty:hard_ice:0)
Block(1,19,8,biomesoplenty:hard_ice:0)
Block(1,19,9,biomesoplenty:hard_ice:0)
Block(1,19,10,biomesoplenty:hard_ice:0)
Block(1,19,11,biomesoplenty:hard_ice:0)
Block(1,20,-10,biomesoplenty:hard_ice:0)
Block(1,20,-9,biomesoplenty:hard_ice:0)
Block(1,20,-8,biomesoplenty:hard_ice:0)
Block(1,20,-7,biomesoplenty:hard_ice:0)
Block(1,20,-6,biomesoplenty:hard_ice:0)
Block(1,20,-5,biomesoplenty:hard_ice:0)
Block(1,20,-4,biomesoplenty:hard_ice:0)
Block(1,20,-3,biomesoplenty:hard_ice:0)
Block(1,20,-2,biomesoplenty:hard_ice:0)
Block(1,20,-1,biomesoplenty:hard_ice:0)
Block(1,20,0,biomesoplenty:hard_ice:0)
Block(1,20,1,biomesoplenty:hard_ice:0)
Block(1,20,2,biomesoplenty:hard_ice:0)
Block(1,20,3,biomesoplenty:hard_ice:0)
Block(1,20,4,biomesoplenty:hard_ice:0)
Block(1,20,5,biomesoplenty:hard_ice:0)
Block(1,20,6,biomesoplenty:hard_ice:0)
Block(1,20,7,biomesoplenty:hard_ice:0)
Block(1,20,8,biomesoplenty:hard_ice:0)
Block(1,20,9,biomesoplenty:hard_ice:0)
Block(1,20,10,biomesoplenty:hard_ice:0)
Block(1,20,11,biomesoplenty:hard_ice:0)
Block(1,21,-9,biomesoplenty:hard_ice:0)
Block(1,21,-8,biomesoplenty:hard_ice:0)
Block(1,21,-7,biomesoplenty:hard_ice:0)
Block(1,21,-6,biomesoplenty:hard_ice:0)
Block(1,21,-5,biomesoplenty:hard_ice:0)
Block(1,21,-4,biomesoplenty:hard_ice:0)
Block(1,21,-3,biomesoplenty:hard_ice:0)
Block(1,21,-2,biomesoplenty:hard_ice:0)
Block(1,21,-1,biomesoplenty:hard_ice:0)
Block(1,21,0,biomesoplenty:hard_ice:0)
Block(1,21,1,biomesoplenty:hard_ice:0)
Block(1,21,2,biomesoplenty:hard_ice:0)
Block(1,21,3,biomesoplenty:hard_ice:0)
Block(1,21,4,biomesoplenty:hard_ice:0)
Block(1,21,5,biomesoplenty:hard_ice:0)
Block(1,21,6,biomesoplenty:hard_ice:0)
Block(1,21,7,biomesoplenty:hard_ice:0)
Block(1,21,8,biomesoplenty:hard_ice:0)
Block(1,21,9,biomesoplenty:hard_ice:0)
Block(1,21,10,biomesoplenty:hard_ice:0)
Block(1,22,-8,biomesoplenty:hard_ice:0)
Block(1,22,-7,biomesoplenty:hard_ice:0)
Block(1,22,-6,biomesoplenty:hard_ice:0)
Block(1,22,-5,biomesoplenty:hard_ice:0)
Block(1,22,-4,biomesoplenty:hard_ice:0)
Block(1,22,-3,biomesoplenty:hard_ice:0)
Block(1,22,-2,biomesoplenty:hard_ice:0)
Block(1,22,-1,biomesoplenty:hard_ice:0)
Block(1,22,0,biomesoplenty:hard_ice:0)
Block(1,22,1,biomesoplenty:hard_ice:0)
Block(1,22,2,biomesoplenty:hard_ice:0)
Block(1,22,3,biomesoplenty:hard_ice:0)
Block(1,22,4,biomesoplenty:hard_ice:0)
Block(1,22,5,biomesoplenty:hard_ice:0)
Block(1,22,6,biomesoplenty:hard_ice:0)
Block(1,22,7,biomesoplenty:hard_ice:0)
Block(1,22,8,biomesoplenty:hard_ice:0)
Block(1,22,9,biomesoplenty:hard_ice:0)
Block(1,22,10,biomesoplenty:hard_ice:0)
Block(1,23,-7,biomesoplenty:hard_ice:0)
Block(1,23,-6,biomesoplenty:hard_ice:0)
Block(1,23,-5,biomesoplenty:hard_ice:0)
Block(1,23,-4,biomesoplenty:hard_ice:0)
Block(1,23,-3,biomesoplenty:hard_ice:0)
Block(1,23,-2,biomesoplenty:hard_ice:0)
Block(1,23,-1,biomesoplenty:hard_ice:0)
Block(1,23,0,biomesoplenty:hard_ice:0)
Block(1,23,1,biomesoplenty:hard_ice:0)
Block(1,23,2,biomesoplenty:hard_ice:0)
Block(1,23,3,biomesoplenty:hard_ice:0)
Block(1,23,4,biomesoplenty:hard_ice:0)
Block(1,23,5,biomesoplenty:hard_ice:0)
Block(1,23,6,biomesoplenty:hard_ice:0)
Block(1,23,7,biomesoplenty:hard_ice:0)
Block(1,23,8,biomesoplenty:hard_ice:0)
Block(1,23,9,biomesoplenty:hard_ice:0)
Block(1,23,10,biomesoplenty:hard_ice:0)
Block(1,24,-6,biomesoplenty:hard_ice:0)
Block(1,24,-5,biomesoplenty:hard_ice:0)
Block(1,24,-4,biomesoplenty:hard_ice:0)
Block(1,24,-3,biomesoplenty:hard_ice:0)
Block(1,24,-2,biomesoplenty:hard_ice:0)
Block(1,24,-1,biomesoplenty:hard_ice:0)
Block(1,24,0,biomesoplenty:hard_ice:0)
Block(1,24,1,biomesoplenty:hard_ice:0)
Block(1,24,2,biomesoplenty:hard_ice:0)
Block(1,24,3,biomesoplenty:hard_ice:0)
Block(1,24,4,biomesoplenty:hard_ice:0)
Block(1,24,5,biomesoplenty:hard_ice:0)
Block(1,24,6,biomesoplenty:hard_ice:0)
Block(1,24,7,biomesoplenty:hard_ice:0)
Block(1,24,8,biomesoplenty:hard_ice:0)
Block(1,24,9,biomesoplenty:hard_ice:0)
Block(1,25,-5,biomesoplenty:hard_ice:0)
Block(1,25,-4,biomesoplenty:hard_ice:0)
Block(1,25,-3,biomesoplenty:hard_ice:0)
Block(1,25,-2,biomesoplenty:hard_ice:0)
Block(1,25,-1,biomesoplenty:hard_ice:0)
Block(1,25,0,biomesoplenty:hard_ice:0)
Block(1,25,1,biomesoplenty:hard_ice:0)
Block(1,25,2,biomesoplenty:hard_ice:0)
Block(1,25,3,biomesoplenty:hard_ice:0)
Block(1,25,4,biomesoplenty:hard_ice:0)
Block(1,25,5,biomesoplenty:hard_ice:0)
Block(1,25,6,biomesoplenty:hard_ice:0)
Block(1,26,-3,biomesoplenty:hard_ice:0)
Block(1,26,-2,biomesoplenty:hard_ice:0)
Block(1,26,-1,biomesoplenty:hard_ice:0)
Block(1,26,0,biomesoplenty:hard_ice:0)
Block(1,26,1,biomesoplenty:hard_ice:0)
Block(1,26,2,biomesoplenty:hard_ice:0)
Block(1,26,3,biomesoplenty:hard_ice:0)
Block(1,27,-2,biomesoplenty:hard_ice:0)
Block(1,27,-1,biomesoplenty:hard_ice:0)
Block(1,27,0,biomesoplenty:hard_ice:0)
Block(2,6,-4,biomesoplenty:hard_ice:0)
Block(2,6,-3,biomesoplenty:hard_ice:0)
Block(2,6,-2,biomesoplenty:hard_ice:0)
Block(2,6,-1,biomesoplenty:hard_ice:0)
Block(2,6,0,biomesoplenty:hard_ice:0)
Block(2,6,1,biomesoplenty:hard_ice:0)
Block(2,6,2,biomesoplenty:hard_ice:0)
Block(2,6,3,biomesoplenty:hard_ice:0)
Block(2,6,4,biomesoplenty:hard_ice:0)
Block(2,6,5,biomesoplenty:hard_ice:0)
Block(2,6,6,biomesoplenty:hard_ice:0)
Block(2,7,-5,biomesoplenty:hard_ice:0)
Block(2,7,-4,biomesoplenty:hard_ice:0)
Block(2,7,-3,biomesoplenty:hard_ice:0)
Block(2,7,-2,biomesoplenty:hard_ice:0)
Block(2,7,-1,biomesoplenty:hard_ice:0)
Block(2,7,0,biomesoplenty:hard_ice:0)
Block(2,7,1,biomesoplenty:hard_ice:0)
Block(2,7,2,biomesoplenty:hard_ice:0)
Block(2,7,3,biomesoplenty:hard_ice:0)
Block(2,7,4,biomesoplenty:hard_ice:0)
Block(2,7,5,biomesoplenty:hard_ice:0)
Block(2,7,6,biomesoplenty:hard_ice:0)
Block(2,7,7,biomesoplenty:hard_ice:0)
Block(2,7,8,biomesoplenty:hard_ice:0)
Block(2,7,9,biomesoplenty:hard_ice:0)
Block(2,7,10,biomesoplenty:hard_ice:0)
Block(2,8,-6,biomesoplenty:hard_ice:0)
Block(2,8,-5,biomesoplenty:hard_ice:0)
Block(2,8,-4,biomesoplenty:hard_ice:0)
Block(2,8,-3,biomesoplenty:hard_ice:0)
Block(2,8,-2,biomesoplenty:hard_ice:0)
Block(2,8,-1,biomesoplenty:hard_ice:0)
Block(2,8,0,biomesoplenty:hard_ice:0)
Block(2,8,1,biomesoplenty:hard_ice:0)
Block(2,8,2,biomesoplenty:hard_ice:0)
Block(2,8,3,biomesoplenty:hard_ice:0)
Block(2,8,4,biomesoplenty:hard_ice:0)
Block(2,8,5,biomesoplenty:hard_ice:0)
Block(2,8,6,biomesoplenty:hard_ice:0)
Block(2,8,7,biomesoplenty:hard_ice:0)
Block(2,8,8,biomesoplenty:hard_ice:0)
Block(2,8,9,biomesoplenty:hard_ice:0)
Block(2,8,10,biomesoplenty:hard_ice:0)
Block(2,8,11,biomesoplenty:hard_ice:0)
Block(2,9,-7,biomesoplenty:hard_ice:0)
Block(2,9,-6,biomesoplenty:hard_ice:0)
Block(2,9,-5,biomesoplenty:hard_ice:0)
Block(2,9,-4,biomesoplenty:hard_ice:0)
Block(2,9,-3,biomesoplenty:hard_ice:0)
Block(2,9,-2,biomesoplenty:hard_ice:0)
Block(2,9,-1,biomesoplenty:hard_ice:0)
Block(2,9,0,biomesoplenty:hard_ice:0)
Block(2,9,1,biomesoplenty:hard_ice:0)
Block(2,9,2,biomesoplenty:hard_ice:0)
Block(2,9,3,biomesoplenty:hard_ice:0)
Block(2,9,4,biomesoplenty:hard_ice:0)
Block(2,9,5,biomesoplenty:hard_ice:0)
Block(2,9,6,biomesoplenty:hard_ice:0)
Block(2,9,7,biomesoplenty:hard_ice:0)
Block(2,9,8,biomesoplenty:hard_ice:0)
Block(2,9,9,biomesoplenty:hard_ice:0)
Block(2,9,10,biomesoplenty:hard_ice:0)
Block(2,9,11,biomesoplenty:hard_ice:0)
Block(2,9,12,biomesoplenty:hard_ice:0)
Block(2,10,-8,biomesoplenty:hard_ice:0)
Block(2,10,-7,biomesoplenty:hard_ice:0)
Block(2,10,-6,biomesoplenty:hard_ice:0)
Block(2,10,-5,biomesoplenty:hard_ice:0)
Block(2,10,-4,biomesoplenty:hard_ice:0)
Block(2,10,-3,biomesoplenty:hard_ice:0)
Block(2,10,-2,biomesoplenty:hard_ice:0)
Block(2,10,-1,biomesoplenty:hard_ice:0)
Block(2,10,0,biomesoplenty:hard_ice:0)
Block(2,10,1,biomesoplenty:hard_ice:0)
Block(2,10,2,biomesoplenty:hard_ice:0)
Block(2,10,3,biomesoplenty:hard_ice:0)
Block(2,10,4,biomesoplenty:hard_ice:0)
Block(2,10,5,biomesoplenty:hard_ice:0)
Block(2,10,6,biomesoplenty:hard_ice:0)
Block(2,10,7,biomesoplenty:hard_ice:0)
Block(2,10,8,biomesoplenty:hard_ice:0)
Block(2,10,9,biomesoplenty:hard_ice:0)
Block(2,10,10,biomesoplenty:hard_ice:0)
Block(2,10,11,biomesoplenty:hard_ice:0)
Block(2,10,12,biomesoplenty:hard_ice:0)
Block(2,10,13,biomesoplenty:hard_ice:0)
Block(2,11,-9,biomesoplenty:hard_ice:0)
Block(2,11,-8,biomesoplenty:hard_ice:0)
Block(2,11,-7,biomesoplenty:hard_ice:0)
Block(2,11,-6,biomesoplenty:hard_ice:0)
Block(2,11,-5,biomesoplenty:hard_ice:0)
Block(2,11,-4,biomesoplenty:hard_ice:0)
Block(2,11,-3,biomesoplenty:hard_ice:0)
Block(2,11,-2,biomesoplenty:hard_ice:0)
Block(2,11,-1,biomesoplenty:hard_ice:0)
Block(2,11,0,biomesoplenty:hard_ice:0)
Block(2,11,1,biomesoplenty:hard_ice:0)
Block(2,11,2,biomesoplenty:hard_ice:0)
Block(2,11,3,biomesoplenty:hard_ice:0)
Block(2,11,4,biomesoplenty:hard_ice:0)
Block(2,11,5,biomesoplenty:hard_ice:0)
Block(2,11,6,biomesoplenty:hard_ice:0)
Block(2,11,7,biomesoplenty:hard_ice:0)
Block(2,11,8,biomesoplenty:hard_ice:0)
Block(2,11,9,biomesoplenty:hard_ice:0)
Block(2,11,10,biomesoplenty:hard_ice:0)
Block(2,11,11,biomesoplenty:hard_ice:0)
Block(2,11,12,biomesoplenty:hard_ice:0)
Block(2,11,13,biomesoplenty:hard_ice:0)
Block(2,12,-10,biomesoplenty:hard_ice:0)
Block(2,12,-9,biomesoplenty:hard_ice:0)
Block(2,12,-8,biomesoplenty:hard_ice:0)
Block(2,12,-7,biomesoplenty:hard_ice:0)
Block(2,12,-6,biomesoplenty:hard_ice:0)
Block(2,12,-5,biomesoplenty:hard_ice:0)
Block(2,12,-4,biomesoplenty:hard_ice:0)
Block(2,12,-3,biomesoplenty:hard_ice:0)
Block(2,12,-2,biomesoplenty:hard_ice:0)
Block(2,12,-1,biomesoplenty:hard_ice:0)
Block(2,12,0,biomesoplenty:hard_ice:0)
Block(2,12,1,biomesoplenty:hard_ice:0)
Block(2,12,2,biomesoplenty:hard_ice:0)
Block(2,12,3,biomesoplenty:hard_ice:0)
Block(2,12,4,biomesoplenty:hard_ice:0)
Block(2,12,5,biomesoplenty:hard_ice:0)
Block(2,12,6,biomesoplenty:hard_ice:0)
Block(2,12,7,biomesoplenty:hard_ice:0)
Block(2,12,8,biomesoplenty:hard_ice:0)
Block(2,12,9,biomesoplenty:hard_ice:0)
Block(2,12,10,biomesoplenty:hard_ice:0)
Block(2,12,11,biomesoplenty:hard_ice:0)
Block(2,12,12,biomesoplenty:hard_ice:0)
Block(2,12,13,biomesoplenty:hard_ice:0)
Block(2,13,-10,biomesoplenty:hard_ice:0)
Block(2,13,-9,biomesoplenty:hard_ice:0)
Block(2,13,-8,biomesoplenty:hard_ice:0)
Block(2,13,-7,biomesoplenty:hard_ice:0)
Block(2,13,-6,biomesoplenty:hard_ice:0)
Block(2,13,-5,biomesoplenty:hard_ice:0)
Block(2,13,-4,biomesoplenty:hard_ice:0)
Block(2,13,-3,biomesoplenty:hard_ice:0)
Block(2,13,-2,biomesoplenty:hard_ice:0)
Block(2,13,-1,biomesoplenty:hard_ice:0)
Block(2,13,0,biomesoplenty:hard_ice:0)
Block(2,13,1,biomesoplenty:hard_ice:0)
Block(2,13,2,biomesoplenty:hard_ice:0)
Block(2,13,3,biomesoplenty:hard_ice:0)
Block(2,13,4,biomesoplenty:hard_ice:0)
Block(2,13,5,biomesoplenty:hard_ice:0)
Block(2,13,6,biomesoplenty:hard_ice:0)
Block(2,13,7,biomesoplenty:hard_ice:0)
Block(2,13,8,biomesoplenty:hard_ice:0)
Block(2,13,9,biomesoplenty:hard_ice:0)
Block(2,13,10,biomesoplenty:hard_ice:0)
Block(2,13,11,biomesoplenty:hard_ice:0)
Block(2,13,12,biomesoplenty:hard_ice:0)
Block(2,14,-10,biomesoplenty:hard_ice:0)
Block(2,14,-9,biomesoplenty:hard_ice:0)
Block(2,14,-8,biomesoplenty:hard_ice:0)
Block(2,14,-7,biomesoplenty:hard_ice:0)
Block(2,14,-6,biomesoplenty:hard_ice:0)
Block(2,14,-5,biomesoplenty:hard_ice:0)
Block(2,14,-4,biomesoplenty:hard_ice:0)
Block(2,14,-3,biomesoplenty:hard_ice:0)
Block(2,14,-2,biomesoplenty:hard_ice:0)
Block(2,14,-1,biomesoplenty:hard_ice:0)
Block(2,14,0,biomesoplenty:hard_ice:0)
Block(2,14,1,biomesoplenty:hard_ice:0)
Block(2,14,2,biomesoplenty:hard_ice:0)
Block(2,14,3,biomesoplenty:hard_ice:0)
Block(2,14,4,biomesoplenty:hard_ice:0)
Block(2,14,5,biomesoplenty:hard_ice:0)
Block(2,14,6,biomesoplenty:hard_ice:0)
Block(2,14,7,biomesoplenty:hard_ice:0)
Block(2,14,8,biomesoplenty:hard_ice:0)
Block(2,14,9,biomesoplenty:hard_ice:0)
Block(2,14,10,biomesoplenty:hard_ice:0)
Block(2,14,11,biomesoplenty:hard_ice:0)
Block(2,14,12,biomesoplenty:hard_ice:0)
Block(2,15,-10,biomesoplenty:hard_ice:0)
Block(2,15,-9,biomesoplenty:hard_ice:0)
Block(2,15,-8,biomesoplenty:hard_ice:0)
Block(2,15,-7,biomesoplenty:hard_ice:0)
Block(2,15,-6,biomesoplenty:hard_ice:0)
Block(2,15,-5,biomesoplenty:hard_ice:0)
Block(2,15,-4,biomesoplenty:hard_ice:0)
Block(2,15,-3,biomesoplenty:hard_ice:0)
Block(2,15,-2,biomesoplenty:hard_ice:0)
Block(2,15,-1,biomesoplenty:hard_ice:0)
Block(2,15,0,biomesoplenty:hard_ice:0)
Block(2,15,1,biomesoplenty:hard_ice:0)
Block(2,15,2,biomesoplenty:hard_ice:0)
Block(2,15,3,biomesoplenty:hard_ice:0)
Block(2,15,4,biomesoplenty:hard_ice:0)
Block(2,15,5,biomesoplenty:hard_ice:0)
Block(2,15,6,biomesoplenty:hard_ice:0)
Block(2,15,7,biomesoplenty:hard_ice:0)
Block(2,15,8,biomesoplenty:hard_ice:0)
Block(2,15,9,biomesoplenty:hard_ice:0)
Block(2,15,10,biomesoplenty:hard_ice:0)
Block(2,15,11,biomesoplenty:hard_ice:0)
Block(2,15,12,biomesoplenty:hard_ice:0)
Block(2,16,-10,biomesoplenty:hard_ice:0)
Block(2,16,-9,biomesoplenty:hard_ice:0)
Block(2,16,-8,biomesoplenty:hard_ice:0)
Block(2,16,-7,biomesoplenty:hard_ice:0)
Block(2,16,-6,biomesoplenty:hard_ice:0)
Block(2,16,-5,biomesoplenty:hard_ice:0)
Block(2,16,-4,biomesoplenty:hard_ice:0)
Block(2,16,-3,biomesoplenty:hard_ice:0)
Block(2,16,-2,biomesoplenty:hard_ice:0)
Block(2,16,-1,biomesoplenty:hard_ice:0)
Block(2,16,0,biomesoplenty:hard_ice:0)
Block(2,16,1,biomesoplenty:hard_ice:0)
Block(2,16,2,biomesoplenty:hard_ice:0)
Block(2,16,3,biomesoplenty:hard_ice:0)
Block(2,16,4,biomesoplenty:hard_ice:0)
Block(2,16,5,biomesoplenty:hard_ice:0)
Block(2,16,6,biomesoplenty:hard_ice:0)
Block(2,16,7,biomesoplenty:hard_ice:0)
Block(2,16,8,biomesoplenty:hard_ice:0)
Block(2,16,9,biomesoplenty:hard_ice:0)
Block(2,16,10,biomesoplenty:hard_ice:0)
Block(2,16,11,biomesoplenty:hard_ice:0)
Block(2,16,12,biomesoplenty:hard_ice:0)
Block(2,17,-10,biomesoplenty:hard_ice:0)
Block(2,17,-9,biomesoplenty:hard_ice:0)
Block(2,17,-8,biomesoplenty:hard_ice:0)
Block(2,17,-7,biomesoplenty:hard_ice:0)
Block(2,17,-6,biomesoplenty:hard_ice:0)
Block(2,17,-5,biomesoplenty:hard_ice:0)
Block(2,17,-4,biomesoplenty:hard_ice:0)
Block(2,17,-3,biomesoplenty:hard_ice:0)
Block(2,17,-2,biomesoplenty:hard_ice:0)
Block(2,17,-1,biomesoplenty:hard_ice:0)
Block(2,17,0,biomesoplenty:hard_ice:0)
Block(2,17,1,biomesoplenty:hard_ice:0)
Block(2,17,2,biomesoplenty:hard_ice:0)
Block(2,17,3,biomesoplenty:hard_ice:0)
Block(2,17,4,biomesoplenty:hard_ice:0)
Block(2,17,5,biomesoplenty:hard_ice:0)
Block(2,17,6,biomesoplenty:hard_ice:0)
Block(2,17,7,biomesoplenty:hard_ice:0)
Block(2,17,8,biomesoplenty:hard_ice:0)
Block(2,17,9,biomesoplenty:hard_ice:0)
Block(2,17,10,biomesoplenty:hard_ice:0)
Block(2,17,11,biomesoplenty:hard_ice:0)
Block(2,17,12,biomesoplenty:hard_ice:0)
Block(2,18,-10,biomesoplenty:hard_ice:0)
Block(2,18,-9,biomesoplenty:hard_ice:0)
Block(2,18,-8,biomesoplenty:hard_ice:0)
Block(2,18,-7,biomesoplenty:hard_ice:0)
Block(2,18,-6,biomesoplenty:hard_ice:0)
Block(2,18,-5,biomesoplenty:hard_ice:0)
Block(2,18,-4,biomesoplenty:hard_ice:0)
Block(2,18,-3,biomesoplenty:hard_ice:0)
Block(2,18,-2,biomesoplenty:hard_ice:0)
Block(2,18,-1,biomesoplenty:hard_ice:0)
Block(2,18,0,biomesoplenty:hard_ice:0)
Block(2,18,1,biomesoplenty:hard_ice:0)
Block(2,18,2,biomesoplenty:hard_ice:0)
Block(2,18,3,biomesoplenty:hard_ice:0)
Block(2,18,4,biomesoplenty:hard_ice:0)
Block(2,18,5,biomesoplenty:hard_ice:0)
Block(2,18,6,biomesoplenty:hard_ice:0)
Block(2,18,7,biomesoplenty:hard_ice:0)
Block(2,18,8,biomesoplenty:hard_ice:0)
Block(2,18,9,biomesoplenty:hard_ice:0)
Block(2,18,10,biomesoplenty:hard_ice:0)
Block(2,18,11,biomesoplenty:hard_ice:0)
Block(2,18,12,biomesoplenty:hard_ice:0)
Block(2,19,-11,biomesoplenty:hard_ice:0)
Block(2,19,-10,biomesoplenty:hard_ice:0)
Block(2,19,-9,biomesoplenty:hard_ice:0)
Block(2,19,-8,biomesoplenty:hard_ice:0)
Block(2,19,-7,biomesoplenty:hard_ice:0)
Block(2,19,-6,biomesoplenty:hard_ice:0)
Block(2,19,-5,biomesoplenty:hard_ice:0)
Block(2,19,-4,biomesoplenty:hard_ice:0)
Block(2,19,-3,biomesoplenty:hard_ice:0)
Block(2,19,-2,biomesoplenty:hard_ice:0)
Block(2,19,-1,biomesoplenty:hard_ice:0)
Block(2,19,0,biomesoplenty:hard_ice:0)
Block(2,19,1,biomesoplenty:hard_ice:0)
Block(2,19,2,biomesoplenty:hard_ice:0)
Block(2,19,3,biomesoplenty:hard_ice:0)
Block(2,19,4,biomesoplenty:hard_ice:0)
Block(2,19,5,biomesoplenty:hard_ice:0)
Block(2,19,6,biomesoplenty:hard_ice:0)
Block(2,19,7,biomesoplenty:hard_ice:0)
Block(2,19,8,biomesoplenty:hard_ice:0)
Block(2,19,9,biomesoplenty:hard_ice:0)
Block(2,19,10,biomesoplenty:hard_ice:0)
Block(2,19,11,biomesoplenty:hard_ice:0)
Block(2,20,-11,biomesoplenty:hard_ice:0)
Block(2,20,-10,biomesoplenty:hard_ice:0)
Block(2,20,-9,biomesoplenty:hard_ice:0)
Block(2,20,-8,biomesoplenty:hard_ice:0)
Block(2,20,-7,biomesoplenty:hard_ice:0)
Block(2,20,-6,biomesoplenty:hard_ice:0)
Block(2,20,-5,biomesoplenty:hard_ice:0)
Block(2,20,-4,biomesoplenty:hard_ice:0)
Block(2,20,-3,biomesoplenty:hard_ice:0)
Block(2,20,-2,biomesoplenty:hard_ice:0)
Block(2,20,-1,biomesoplenty:hard_ice:0)
Block(2,20,0,biomesoplenty:hard_ice:0)
Block(2,20,1,biomesoplenty:hard_ice:0)
Block(2,20,2,biomesoplenty:hard_ice:0)
Block(2,20,3,biomesoplenty:hard_ice:0)
Block(2,20,4,biomesoplenty:hard_ice:0)
Block(2,20,5,biomesoplenty:hard_ice:0)
Block(2,20,6,biomesoplenty:hard_ice:0)
Block(2,20,7,biomesoplenty:hard_ice:0)
Block(2,20,8,biomesoplenty:hard_ice:0)
Block(2,20,9,biomesoplenty:hard_ice:0)
Block(2,20,10,biomesoplenty:hard_ice:0)
Block(2,20,11,biomesoplenty:hard_ice:0)
Block(2,21,-10,biomesoplenty:hard_ice:0)
Block(2,21,-9,biomesoplenty:hard_ice:0)
Block(2,21,-8,biomesoplenty:hard_ice:0)
Block(2,21,-7,biomesoplenty:hard_ice:0)
Block(2,21,-6,biomesoplenty:hard_ice:0)
Block(2,21,-5,biomesoplenty:hard_ice:0)
Block(2,21,-4,biomesoplenty:hard_ice:0)
Block(2,21,-3,biomesoplenty:hard_ice:0)
Block(2,21,-2,biomesoplenty:hard_ice:0)
Block(2,21,-1,biomesoplenty:hard_ice:0)
Block(2,21,0,biomesoplenty:hard_ice:0)
Block(2,21,1,biomesoplenty:hard_ice:0)
Block(2,21,2,biomesoplenty:hard_ice:0)
Block(2,21,3,biomesoplenty:hard_ice:0)
Block(2,21,4,biomesoplenty:hard_ice:0)
Block(2,21,5,biomesoplenty:hard_ice:0)
Block(2,21,6,biomesoplenty:hard_ice:0)
Block(2,21,7,biomesoplenty:hard_ice:0)
Block(2,21,8,biomesoplenty:hard_ice:0)
Block(2,21,9,biomesoplenty:hard_ice:0)
Block(2,21,10,biomesoplenty:hard_ice:0)
Block(2,21,11,biomesoplenty:hard_ice:0)
Block(2,22,-8,biomesoplenty:hard_ice:0)
Block(2,22,-7,biomesoplenty:hard_ice:0)
Block(2,22,-6,biomesoplenty:hard_ice:0)
Block(2,22,-5,biomesoplenty:hard_ice:0)
Block(2,22,-4,biomesoplenty:hard_ice:0)
Block(2,22,-3,biomesoplenty:hard_ice:0)
Block(2,22,-2,biomesoplenty:hard_ice:0)
Block(2,22,-1,biomesoplenty:hard_ice:0)
Block(2,22,0,biomesoplenty:hard_ice:0)
Block(2,22,1,biomesoplenty:hard_ice:0)
Block(2,22,2,biomesoplenty:hard_ice:0)
Block(2,22,3,biomesoplenty:hard_ice:0)
Block(2,22,4,biomesoplenty:hard_ice:0)
Block(2,22,5,biomesoplenty:hard_ice:0)
Block(2,22,6,biomesoplenty:hard_ice:0)
Block(2,22,7,biomesoplenty:hard_ice:0)
Block(2,22,8,biomesoplenty:hard_ice:0)
Block(2,22,9,biomesoplenty:hard_ice:0)
Block(2,22,10,biomesoplenty:hard_ice:0)
Block(2,22,11,biomesoplenty:hard_ice:0)
Block(2,23,-7,biomesoplenty:hard_ice:0)
Block(2,23,-6,biomesoplenty:hard_ice:0)
Block(2,23,-5,biomesoplenty:hard_ice:0)
Block(2,23,-4,biomesoplenty:hard_ice:0)
Block(2,23,-3,biomesoplenty:hard_ice:0)
Block(2,23,-2,biomesoplenty:hard_ice:0)
Block(2,23,-1,biomesoplenty:hard_ice:0)
Block(2,23,0,biomesoplenty:hard_ice:0)
Block(2,23,1,biomesoplenty:hard_ice:0)
Block(2,23,2,biomesoplenty:hard_ice:0)
Block(2,23,3,biomesoplenty:hard_ice:0)
Block(2,23,4,biomesoplenty:hard_ice:0)
Block(2,23,5,biomesoplenty:hard_ice:0)
Block(2,23,6,biomesoplenty:hard_ice:0)
Block(2,23,7,biomesoplenty:hard_ice:0)
Block(2,23,8,biomesoplenty:hard_ice:0)
Block(2,23,9,biomesoplenty:hard_ice:0)
Block(2,23,10,biomesoplenty:hard_ice:0)
Block(2,24,-6,biomesoplenty:hard_ice:0)
Block(2,24,-5,biomesoplenty:hard_ice:0)
Block(2,24,-4,biomesoplenty:hard_ice:0)
Block(2,24,-3,biomesoplenty:hard_ice:0)
Block(2,24,-2,biomesoplenty:hard_ice:0)
Block(2,24,-1,biomesoplenty:hard_ice:0)
Block(2,24,0,biomesoplenty:hard_ice:0)
Block(2,24,1,biomesoplenty:hard_ice:0)
Block(2,24,2,biomesoplenty:hard_ice:0)
Block(2,24,3,biomesoplenty:hard_ice:0)
Block(2,24,4,biomesoplenty:hard_ice:0)
Block(2,24,5,biomesoplenty:hard_ice:0)
Block(2,24,6,biomesoplenty:hard_ice:0)
Block(2,24,7,biomesoplenty:hard_ice:0)
Block(2,24,8,biomesoplenty:hard_ice:0)
Block(2,24,9,biomesoplenty:hard_ice:0)
Block(2,24,10,biomesoplenty:hard_ice:0)
Block(2,25,-5,biomesoplenty:hard_ice:0)
Block(2,25,-4,biomesoplenty:hard_ice:0)
Block(2,25,-3,biomesoplenty:hard_ice:0)
Block(2,25,-2,biomesoplenty:hard_ice:0)
Block(2,25,-1,biomesoplenty:hard_ice:0)
Block(2,25,0,biomesoplenty:hard_ice:0)
Block(2,25,1,biomesoplenty:hard_ice:0)
Block(2,25,2,biomesoplenty:hard_ice:0)
Block(2,25,3,biomesoplenty:hard_ice:0)
Block(2,25,4,biomesoplenty:hard_ice:0)
Block(2,25,5,biomesoplenty:hard_ice:0)
Block(2,25,6,biomesoplenty:hard_ice:0)
Block(2,25,7,biomesoplenty:hard_ice:0)
Block(2,25,8,biomesoplenty:hard_ice:0)
Block(2,25,9,biomesoplenty:hard_ice:0)
Block(2,26,-3,biomesoplenty:hard_ice:0)
Block(2,26,-2,biomesoplenty:hard_ice:0)
Block(2,26,-1,biomesoplenty:hard_ice:0)
Block(2,26,0,biomesoplenty:hard_ice:0)
Block(2,26,1,biomesoplenty:hard_ice:0)
Block(2,26,2,biomesoplenty:hard_ice:0)
Block(2,26,3,biomesoplenty:hard_ice:0)
Block(2,26,4,biomesoplenty:hard_ice:0)
Block(2,26,5,biomesoplenty:hard_ice:0)
Block(2,27,-2,biomesoplenty:hard_ice:0)
Block(2,27,-1,biomesoplenty:hard_ice:0)
Block(2,27,0,biomesoplenty:hard_ice:0)
Block(2,27,1,biomesoplenty:hard_ice:0)
Block(2,27,2,biomesoplenty:hard_ice:0)
