#######################################################################
# +-----------------------------------------------------------------+ #
# |                            BO3 object                           | #
# +-----------------------------------------------------------------+ #
#######################################################################

# The descriptions in this file are accurate only for TerrainControl and OTG.
# For MCW and OTG+ these descriptions are only accurate if the BO3 is used as a CustomObject.
# MCW and OTG+ completely reimplemented CustomStructure, check the MCW/OTG+ documentation for more information.

# This is the config file of a custom object.
# If you add this object correctly to your BiomeConfigs, it will spawn in the world.

# This is the creator of this BO3 object
Author: Unknown

# A short description of this BO3 object
Description: This BO3 was converted from a schematic using OTGEdit. The author and description information of the schematic could not be found. If you know who the author of the schematic is then please add this information.

# The BO3 version, don't change this! It can be used by external applications to do a version check.
Version: 3

# The settings mode, WriteAll, WriteWithoutComments or WriteDisable. See WorldConfig.
SettingsMode: WriteDisable

#######################################################################
# +-----------------------------------------------------------------+ #
# |                          Main settings                          | #
# +-----------------------------------------------------------------+ #
#######################################################################

# This needs to be set to true to spawn the object in the Tree and Sapling resources.
Tree: true

# The frequency of the BO3 from 1 to 200. Tries this many times to spawn this BO3 when using the CustomObject(...) resource.
# Ignored by Tree(..), Sapling(..) and CustomStructure(..)
Frequency: 40

# The rarity of the BO3 from 0 to 100. Each spawn attempt has rarity% chance to succeed when using the CustomObject(...) resource.
# Ignored by Tree(..), Sapling(..) and CustomStructure(..)
Rarity: 100.0

# If you set this to true, the BO3 will be placed with a random rotation.
RotateRandomly: true

# The spawn height of the BO3 - randomY, highestBlock or highestSolidBlock.
SpawnHeight: randomY

# The height limits for the BO3.
MinHeight: 0

MaxHeight: 256

# Objects can have other objects attached to it: branches. Branches can also
# have branches attached to it, which can also have branches, etc. This is the
# maximum branch depth for this objects.
MaxBranchDepth: 10

# When spawned with the UseWorld keyword, this BO3 should NOT spawn in the following biomes.
# If you writer.write the BO3 name directly in the BiomeConfigs, this will be ignored.
ExcludedBiomes: All

# To optimise this BO3 for faster loading times you can use Notepad++ to find/replace comments and abbreviate things.
# Notepad++ find/replace with regex:
# Find: ^[#;].* replace to nothing removes all lines starting with # 
# Find: ^\s*$ replace to nothing removes most empty lines 
# Notepad++ find/replace without regex:
# *Warning: This will only work for OTG 1.10.2 v21 / OTG 1.11.2 v6 or higher. B( is not recognised by lower versions.
# Find: Block( replace to B(

#######################################################################
# +-----------------------------------------------------------------+ #
# |                      Source block settings                      | #
# +-----------------------------------------------------------------+ #
#######################################################################

# The block(s) the BO3 should spawn in.
SourceBlocks: AIR

# The maximum percentage of the BO3 that can be outside the SourceBlock.
# The BO3 won't be placed on a location with more blocks outside the SourceBlock than this percentage.
MaxPercentageOutsideSourceBlock: 100

# What to do when a block is about to be placed outside the SourceBlock? (dontPlace, placeAnyway)
OutsideSourceBlock: placeAnyway

#######################################################################
# +-----------------------------------------------------------------+ #
# |                              Blocks                             | #
# +-----------------------------------------------------------------+ #
#######################################################################

# All the blocks used in the BO3 are listed here. Possible blocks:
# Block(x,y,z,id[.data][,nbtfile.nbt) or B(x,y,z,id[.data][,nbtfile.nbt)
# RandomBlock(x,y,z,id[:data][,nbtfile.nbt],chance[,id[:data][,nbtfile.nbt],chance[,...]])
# So RandomBlock(0,0,0,CHEST,chest.nbt,50,CHEST,anotherchest.nbt,100) will spawn a chest at
# the BO3 origin, and give it a 50% chance to have the contents of chest.nbt, or, if that
# fails, a 100% percent chance to have the contents of anotherchest.nbt.

Block(4,18,5,1)
Block(4,19,5,1)
Block(4,19,6,1)
Block(4,20,5,1)
Block(4,20,6,1)
Block(4,21,5,1)
Block(4,22,5,1)
Block(5,12,4,1)
Block(5,13,2,1)
Block(5,13,3,1)
Block(5,13,4,1)
Block(5,13,5,1)
Block(5,13,6,1)
Block(5,14,2,1)
Block(5,14,3,1)
Block(5,14,4,1)
Block(5,14,5,1)
Block(5,14,6,1)
Block(5,15,2,1)
Block(5,15,3,1)
Block(5,15,4,1)
Block(5,15,5,1)
Block(5,15,6,1)
Block(5,15,7,1)
Block(5,16,3,1)
Block(5,16,4,1)
Block(5,16,5,1)
Block(5,16,6,1)
Block(5,16,7,1)
Block(5,17,3,1)
Block(5,17,4,1)
Block(5,17,5,1)
Block(5,17,6,1)
Block(5,17,7,1)
Block(5,18,3,1)
Block(5,18,4,1)
Block(5,18,5,1)
Block(5,18,6,1)
Block(5,18,7,1)
Block(5,19,4,1)
Block(5,19,5,1)
Block(5,19,6,1)
Block(5,19,7,1)
Block(5,20,4,1)
Block(5,20,5,1)
Block(5,20,6,1)
Block(5,20,7,1)
Block(5,21,4,1)
Block(5,21,5,1)
Block(5,21,6,1)
Block(5,21,7,1)
Block(5,22,4,1)
Block(5,22,5,1)
Block(5,22,6,1)
Block(5,23,4,1)
Block(5,23,5,1)
Block(6,9,1,1)
Block(6,9,2,1)
Block(6,9,3,1)
Block(6,10,1,1)
Block(6,10,2,1)
Block(6,10,3,1)
Block(6,10,4,1)
Block(6,10,5,1)
Block(6,11,1,1)
Block(6,11,2,1)
Block(6,11,3,1)
Block(6,11,4,1)
Block(6,11,5,1)
Block(6,11,6,1)
Block(6,12,1,1)
Block(6,12,2,1)
Block(6,12,3,1)
Block(6,12,4,1)
Block(6,12,5,1)
Block(6,12,6,1)
Block(6,12,7,1)
Block(6,12,8,1)
Block(6,13,1,1)
Block(6,13,2,1)
Block(6,13,3,1)
Block(6,13,4,1)
Block(6,13,5,1)
Block(6,13,6,1)
Block(6,13,7,1)
Block(6,13,8,1)
Block(6,14,1,1)
Block(6,14,2,1)
Block(6,14,3,1)
Block(6,14,4,1)
Block(6,14,5,1)
Block(6,14,6,1)
Block(6,14,7,1)
Block(6,14,8,1)
Block(6,14,9,1)
Block(6,15,2,1)
Block(6,15,3,1)
Block(6,15,4,1)
Block(6,15,5,1)
Block(6,15,6,1)
Block(6,15,7,1)
Block(6,15,8,1)
Block(6,15,9,1)
Block(6,16,2,1)
Block(6,16,3,1)
Block(6,16,4,1)
Block(6,16,5,1)
Block(6,16,6,1)
Block(6,16,7,1)
Block(6,16,8,1)
Block(6,16,9,1)
Block(6,17,2,1)
Block(6,17,3,1)
Block(6,17,4,1)
Block(6,17,5,1)
Block(6,17,6,1)
Block(6,17,7,1)
Block(6,17,8,1)
Block(6,17,9,1)
Block(6,18,2,1)
Block(6,18,3,1)
Block(6,18,4,1)
Block(6,18,5,1)
Block(6,18,6,1)
Block(6,18,7,1)
Block(6,18,8,1)
Block(6,18,9,1)
Block(6,19,2,1)
Block(6,19,3,1)
Block(6,19,4,1)
Block(6,19,5,1)
Block(6,19,6,1)
Block(6,19,7,1)
Block(6,19,8,1)
Block(6,20,2,1)
Block(6,20,3,1)
Block(6,20,4,1)
Block(6,20,5,1)
Block(6,20,6,1)
Block(6,20,7,1)
Block(6,20,8,1)
Block(6,21,2,1)
Block(6,21,3,1)
Block(6,21,4,1)
Block(6,21,5,1)
Block(6,21,6,1)
Block(6,21,7,1)
Block(6,21,8,1)
Block(6,22,2,1)
Block(6,22,3,1)
Block(6,22,4,1)
Block(6,22,5,1)
Block(6,22,6,1)
Block(6,22,7,1)
Block(6,23,2,1)
Block(6,23,3,1)
Block(6,23,4,1)
Block(6,23,5,1)
Block(6,23,6,1)
Block(6,24,2,1)
Block(6,24,3,1)
Block(6,24,4,1)
Block(7,6,0,1)
Block(7,6,1,1)
Block(7,6,2,1)
Block(7,7,0,1)
Block(7,7,1,1)
Block(7,7,2,1)
Block(7,7,3,1)
Block(7,7,4,1)
Block(7,8,0,1)
Block(7,8,1,1)
Block(7,8,2,1)
Block(7,8,3,1)
Block(7,8,4,1)
Block(7,8,5,1)
Block(7,9,0,1)
Block(7,9,1,1)
Block(7,9,2,1)
Block(7,9,3,1)
Block(7,9,4,1)
Block(7,9,5,1)
Block(7,9,6,1)
Block(7,9,7,1)
Block(7,10,0,1)
Block(7,10,1,1)
Block(7,10,2,1)
Block(7,10,3,1)
Block(7,10,4,1)
Block(7,10,5,1)
Block(7,10,6,1)
Block(7,10,7,1)
Block(7,10,8,1)
Block(7,11,0,1)
Block(7,11,1,1)
Block(7,11,2,1)
Block(7,11,3,1)
Block(7,11,4,1)
Block(7,11,5,1)
Block(7,11,6,1)
Block(7,11,7,1)
Block(7,11,8,1)
Block(7,11,9,1)
Block(7,12,0,1)
Block(7,12,1,1)
Block(7,12,2,1)
Block(7,12,3,1)
Block(7,12,4,1)
Block(7,12,5,1)
Block(7,12,6,1)
Block(7,12,7,1)
Block(7,12,8,1)
Block(7,12,9,1)
Block(7,13,0,1)
Block(7,13,1,1)
Block(7,13,2,1)
Block(7,13,3,1)
Block(7,13,4,1)
Block(7,13,5,1)
Block(7,13,6,1)
Block(7,13,7,1)
Block(7,13,8,1)
Block(7,13,9,1)
Block(7,13,10,1)
Block(7,14,1,1)
Block(7,14,2,1)
Block(7,14,3,1)
Block(7,14,4,1)
Block(7,14,5,1)
Block(7,14,6,1)
Block(7,14,7,1)
Block(7,14,8,1)
Block(7,14,9,1)
Block(7,14,10,1)
Block(7,15,1,1)
Block(7,15,2,1)
Block(7,15,3,1)
Block(7,15,4,1)
Block(7,15,5,1)
Block(7,15,6,1)
Block(7,15,7,1)
Block(7,15,8,1)
Block(7,15,9,1)
Block(7,15,10,1)
Block(7,16,1,1)
Block(7,16,2,1)
Block(7,16,3,1)
Block(7,16,4,1)
Block(7,16,5,1)
Block(7,16,6,1)
Block(7,16,7,1)
Block(7,16,8,1)
Block(7,16,9,1)
Block(7,16,10,1)
Block(7,17,1,1)
Block(7,17,2,1)
Block(7,17,3,1)
Block(7,17,4,1)
Block(7,17,5,1)
Block(7,17,6,1)
Block(7,17,7,1)
Block(7,17,8,1)
Block(7,17,9,1)
Block(7,17,10,1)
Block(7,18,1,1)
Block(7,18,2,1)
Block(7,18,3,1)
Block(7,18,4,1)
Block(7,18,5,1)
Block(7,18,6,1)
Block(7,18,7,1)
Block(7,18,8,1)
Block(7,18,9,1)
Block(7,19,1,1)
Block(7,19,2,1)
Block(7,19,3,1)
Block(7,19,4,1)
Block(7,19,5,1)
Block(7,19,6,1)
Block(7,19,7,1)
Block(7,19,8,1)
Block(7,19,9,1)
Block(7,20,1,1)
Block(7,20,2,1)
Block(7,20,3,1)
Block(7,20,4,1)
Block(7,20,5,1)
Block(7,20,6,1)
Block(7,20,7,1)
Block(7,20,8,1)
Block(7,20,9,1)
Block(7,21,1,1)
Block(7,21,2,1)
Block(7,21,3,1)
Block(7,21,4,1)
Block(7,21,5,1)
Block(7,21,6,1)
Block(7,21,7,1)
Block(7,21,8,1)
Block(7,21,9,1)
Block(7,22,1,1)
Block(7,22,2,1)
Block(7,22,3,1)
Block(7,22,4,1)
Block(7,22,5,1)
Block(7,22,6,1)
Block(7,22,7,1)
Block(7,22,8,1)
Block(7,23,1,1)
Block(7,23,2,1)
Block(7,23,3,1)
Block(7,23,4,1)
Block(7,23,5,1)
Block(7,23,6,1)
Block(7,23,7,1)
Block(7,24,1,1)
Block(7,24,2,1)
Block(7,24,3,1)
Block(7,24,4,1)
Block(8,4,1,1)
Block(8,4,2,1)
Block(8,4,3,1)
Block(8,5,0,1)
Block(8,5,1,1)
Block(8,5,2,1)
Block(8,5,3,1)
Block(8,5,4,1)
Block(8,6,0,1)
Block(8,6,1,1)
Block(8,6,2,1)
Block(8,6,3,1)
Block(8,6,4,1)
Block(8,6,5,1)
Block(8,7,0,1)
Block(8,7,1,1)
Block(8,7,2,1)
Block(8,7,3,1)
Block(8,7,4,1)
Block(8,7,5,1)
Block(8,7,6,1)
Block(8,7,7,1)
Block(8,8,-1,1)
Block(8,8,0,1)
Block(8,8,1,1)
Block(8,8,2,1)
Block(8,8,3,1)
Block(8,8,4,1)
Block(8,8,5,1)
Block(8,8,6,1)
Block(8,8,7,1)
Block(8,8,8,1)
Block(8,9,-1,1)
Block(8,9,0,1)
Block(8,9,1,1)
Block(8,9,2,1)
Block(8,9,3,1)
Block(8,9,4,1)
Block(8,9,5,1)
Block(8,9,6,1)
Block(8,9,7,1)
Block(8,9,8,1)
Block(8,9,9,1)
Block(8,10,-1,1)
Block(8,10,0,1)
Block(8,10,1,1)
Block(8,10,2,1)
Block(8,10,3,1)
Block(8,10,4,1)
Block(8,10,5,1)
Block(8,10,6,1)
Block(8,10,7,1)
Block(8,10,8,1)
Block(8,10,9,1)
Block(8,11,-1,1)
Block(8,11,0,1)
Block(8,11,1,1)
Block(8,11,2,1)
Block(8,11,3,1)
Block(8,11,4,1)
Block(8,11,5,1)
Block(8,11,6,1)
Block(8,11,7,1)
Block(8,11,8,1)
Block(8,11,9,1)
Block(8,11,10,1)
Block(8,12,-1,1)
Block(8,12,0,1)
Block(8,12,1,1)
Block(8,12,2,1)
Block(8,12,3,1)
Block(8,12,4,1)
Block(8,12,5,1)
Block(8,12,6,1)
Block(8,12,7,1)
Block(8,12,8,1)
Block(8,12,9,1)
Block(8,12,10,1)
Block(8,13,-1,1)
Block(8,13,0,1)
Block(8,13,1,1)
Block(8,13,2,1)
Block(8,13,3,1)
Block(8,13,4,1)
Block(8,13,5,1)
Block(8,13,6,1)
Block(8,13,7,1)
Block(8,13,8,1)
Block(8,13,9,1)
Block(8,13,10,1)
Block(8,14,-1,1)
Block(8,14,0,1)
Block(8,14,1,1)
Block(8,14,2,1)
Block(8,14,3,1)
Block(8,14,4,1)
Block(8,14,5,1)
Block(8,14,6,1)
Block(8,14,7,1)
Block(8,14,8,1)
Block(8,14,9,1)
Block(8,14,10,1)
Block(8,15,-1,1)
Block(8,15,0,1)
Block(8,15,1,1)
Block(8,15,2,1)
Block(8,15,3,1)
Block(8,15,4,1)
Block(8,15,5,1)
Block(8,15,6,1)
Block(8,15,7,1)
Block(8,15,8,1)
Block(8,15,9,1)
Block(8,15,10,1)
Block(8,16,-1,1)
Block(8,16,0,1)
Block(8,16,1,1)
Block(8,16,2,1)
Block(8,16,3,1)
Block(8,16,4,1)
Block(8,16,5,1)
Block(8,16,6,1)
Block(8,16,7,1)
Block(8,16,8,1)
Block(8,16,9,1)
Block(8,16,10,1)
Block(8,17,-1,1)
Block(8,17,0,1)
Block(8,17,1,1)
Block(8,17,2,1)
Block(8,17,3,1)
Block(8,17,4,1)
Block(8,17,5,1)
Block(8,17,6,1)
Block(8,17,7,1)
Block(8,17,8,1)
Block(8,17,9,1)
Block(8,17,10,1)
Block(8,18,-1,1)
Block(8,18,0,1)
Block(8,18,1,1)
Block(8,18,2,1)
Block(8,18,3,1)
Block(8,18,4,1)
Block(8,18,5,1)
Block(8,18,6,1)
Block(8,18,7,1)
Block(8,18,8,1)
Block(8,18,9,1)
Block(8,18,10,1)
Block(8,19,-1,1)
Block(8,19,0,1)
Block(8,19,1,1)
Block(8,19,2,1)
Block(8,19,3,1)
Block(8,19,4,1)
Block(8,19,5,1)
Block(8,19,6,1)
Block(8,19,7,1)
Block(8,19,8,1)
Block(8,19,9,1)
Block(8,19,10,1)
Block(8,20,-1,1)
Block(8,20,0,1)
Block(8,20,1,1)
Block(8,20,2,1)
Block(8,20,3,1)
Block(8,20,4,1)
Block(8,20,5,1)
Block(8,20,6,1)
Block(8,20,7,1)
Block(8,20,8,1)
Block(8,20,9,1)
Block(8,20,10,1)
Block(8,21,-1,1)
Block(8,21,0,1)
Block(8,21,1,1)
Block(8,21,2,1)
Block(8,21,3,1)
Block(8,21,4,1)
Block(8,21,5,1)
Block(8,21,6,1)
Block(8,21,7,1)
Block(8,21,8,1)
Block(8,21,9,1)
Block(8,22,-1,1)
Block(8,22,0,1)
Block(8,22,1,1)
Block(8,22,2,1)
Block(8,22,3,1)
Block(8,22,4,1)
Block(8,22,5,1)
Block(8,22,6,1)
Block(8,22,7,1)
Block(8,22,8,1)
Block(8,23,0,1)
Block(8,23,1,1)
Block(8,23,2,1)
Block(8,23,3,1)
Block(8,23,4,1)
Block(8,23,5,1)
Block(8,23,6,1)
Block(8,23,7,1)
Block(8,24,0,1)
Block(8,24,1,1)
Block(8,24,2,1)
Block(8,24,3,1)
Block(9,4,-1,1)
Block(9,4,0,1)
Block(9,4,1,1)
Block(9,4,2,1)
Block(9,4,3,1)
Block(9,4,4,1)
Block(9,5,-1,1)
Block(9,5,0,1)
Block(9,5,1,1)
Block(9,5,2,1)
Block(9,5,3,1)
Block(9,5,4,1)
Block(9,5,5,1)
Block(9,5,6,1)
Block(9,6,-1,1)
Block(9,6,0,1)
Block(9,6,1,1)
Block(9,6,2,1)
Block(9,6,3,1)
Block(9,6,4,1)
Block(9,6,5,1)
Block(9,6,6,1)
Block(9,6,7,1)
Block(9,7,-1,1)
Block(9,7,0,1)
Block(9,7,1,1)
Block(9,7,2,1)
Block(9,7,3,1)
Block(9,7,4,1)
Block(9,7,5,1)
Block(9,7,6,1)
Block(9,7,7,1)
Block(9,7,8,1)
Block(9,8,-2,1)
Block(9,8,-1,1)
Block(9,8,0,1)
Block(9,8,1,1)
Block(9,8,2,1)
Block(9,8,3,1)
Block(9,8,4,1)
Block(9,8,5,1)
Block(9,8,6,1)
Block(9,8,7,1)
Block(9,8,8,1)
Block(9,8,9,1)
Block(9,9,-3,1)
Block(9,9,-2,1)
Block(9,9,-1,1)
Block(9,9,0,1)
Block(9,9,1,1)
Block(9,9,2,1)
Block(9,9,3,1)
Block(9,9,4,1)
Block(9,9,5,1)
Block(9,9,6,1)
Block(9,9,7,1)
Block(9,9,8,1)
Block(9,9,9,1)
Block(9,10,-3,1)
Block(9,10,-2,1)
Block(9,10,-1,1)
Block(9,10,0,1)
Block(9,10,1,1)
Block(9,10,2,1)
Block(9,10,3,1)
Block(9,10,4,1)
Block(9,10,5,1)
Block(9,10,6,1)
Block(9,10,7,1)
Block(9,10,8,1)
Block(9,10,9,1)
Block(9,10,10,1)
Block(9,11,-2,1)
Block(9,11,-1,1)
Block(9,11,0,1)
Block(9,11,1,1)
Block(9,11,2,1)
Block(9,11,3,1)
Block(9,11,4,1)
Block(9,11,5,1)
Block(9,11,6,1)
Block(9,11,7,1)
Block(9,11,8,1)
Block(9,11,9,1)
Block(9,11,10,1)
Block(9,12,-2,1)
Block(9,12,-1,1)
Block(9,12,0,1)
Block(9,12,1,1)
Block(9,12,2,1)
Block(9,12,3,1)
Block(9,12,4,1)
Block(9,12,5,1)
Block(9,12,6,1)
Block(9,12,7,1)
Block(9,12,8,1)
Block(9,12,9,1)
Block(9,12,10,1)
Block(9,13,-2,1)
Block(9,13,-1,1)
Block(9,13,0,1)
Block(9,13,1,1)
Block(9,13,2,1)
Block(9,13,3,1)
Block(9,13,4,1)
Block(9,13,5,1)
Block(9,13,6,1)
Block(9,13,7,1)
Block(9,13,8,1)
Block(9,13,9,1)
Block(9,13,10,1)
Block(9,14,-2,1)
Block(9,14,-1,1)
Block(9,14,0,1)
Block(9,14,1,1)
Block(9,14,2,1)
Block(9,14,3,1)
Block(9,14,4,1)
Block(9,14,5,1)
Block(9,14,6,1)
Block(9,14,7,1)
Block(9,14,8,1)
Block(9,14,9,1)
Block(9,14,10,1)
Block(9,14,11,1)
Block(9,15,-2,1)
Block(9,15,-1,1)
Block(9,15,0,1)
Block(9,15,1,1)
Block(9,15,2,1)
Block(9,15,3,1)
Block(9,15,4,1)
Block(9,15,5,1)
Block(9,15,6,1)
Block(9,15,7,1)
Block(9,15,8,1)
Block(9,15,9,1)
Block(9,15,10,1)
Block(9,16,-2,1)
Block(9,16,-1,1)
Block(9,16,0,1)
Block(9,16,1,1)
Block(9,16,2,1)
Block(9,16,3,1)
Block(9,16,4,1)
Block(9,16,5,1)
Block(9,16,6,1)
Block(9,16,7,1)
Block(9,16,8,1)
Block(9,16,9,1)
Block(9,16,10,1)
Block(9,17,-2,1)
Block(9,17,-1,1)
Block(9,17,0,1)
Block(9,17,1,1)
Block(9,17,2,1)
Block(9,17,3,1)
Block(9,17,4,1)
Block(9,17,5,1)
Block(9,17,6,1)
Block(9,17,7,1)
Block(9,17,8,1)
Block(9,17,9,1)
Block(9,17,10,1)
Block(9,18,-2,1)
Block(9,18,-1,1)
Block(9,18,0,1)
Block(9,18,1,1)
Block(9,18,2,1)
Block(9,18,3,1)
Block(9,18,4,1)
Block(9,18,5,1)
Block(9,18,6,1)
Block(9,18,7,1)
Block(9,18,8,1)
Block(9,18,9,1)
Block(9,18,10,1)
Block(9,19,-2,1)
Block(9,19,-1,1)
Block(9,19,0,1)
Block(9,19,1,1)
Block(9,19,2,1)
Block(9,19,3,1)
Block(9,19,4,1)
Block(9,19,5,1)
Block(9,19,6,1)
Block(9,19,7,1)
Block(9,19,8,1)
Block(9,19,9,1)
Block(9,19,10,1)
Block(9,20,-2,1)
Block(9,20,-1,1)
Block(9,20,0,1)
Block(9,20,1,1)
Block(9,20,2,1)
Block(9,20,3,1)
Block(9,20,4,1)
Block(9,20,5,1)
Block(9,20,6,1)
Block(9,20,7,1)
Block(9,20,8,1)
Block(9,20,9,1)
Block(9,21,-2,1)
Block(9,21,-1,1)
Block(9,21,0,1)
Block(9,21,1,1)
Block(9,21,2,1)
Block(9,21,3,1)
Block(9,21,4,1)
Block(9,21,5,1)
Block(9,21,6,1)
Block(9,21,7,1)
Block(9,21,8,1)
Block(9,21,9,1)
Block(9,22,-2,1)
Block(9,22,-1,1)
Block(9,22,0,1)
Block(9,22,1,1)
Block(9,22,2,1)
Block(9,22,3,1)
Block(9,22,4,1)
Block(9,22,5,1)
Block(9,22,6,1)
Block(9,22,7,1)
Block(9,23,-1,1)
Block(9,23,0,1)
Block(9,23,1,1)
Block(9,23,2,1)
Block(9,23,3,1)
Block(9,23,4,1)
Block(9,23,5,1)
Block(9,23,6,1)
Block(9,24,-1,1)
Block(9,24,0,1)
Block(9,24,1,1)
Block(9,24,2,1)
Block(9,25,-1,1)
Block(10,3,-1,1)
Block(10,3,0,1)
Block(10,4,-2,1)
Block(10,4,-1,1)
Block(10,4,0,1)
Block(10,4,1,1)
Block(10,4,2,1)
Block(10,4,3,1)
Block(10,4,4,1)
Block(10,4,5,1)
Block(10,4,6,1)
Block(10,5,-4,1)
Block(10,5,-3,1)
Block(10,5,-2,1)
Block(10,5,-1,1)
Block(10,5,0,1)
Block(10,5,1,1)
Block(10,5,2,1)
Block(10,5,3,1)
Block(10,5,4,1)
Block(10,5,5,1)
Block(10,5,6,1)
Block(10,5,7,1)
Block(10,6,-5,1)
Block(10,6,-4,1)
Block(10,6,-3,1)
Block(10,6,-2,1)
Block(10,6,-1,1)
Block(10,6,0,1)
Block(10,6,1,1)
Block(10,6,2,1)
Block(10,6,3,1)
Block(10,6,4,1)
Block(10,6,5,1)
Block(10,6,6,1)
Block(10,6,7,1)
Block(10,6,8,1)
Block(10,7,-5,1)
Block(10,7,-4,1)
Block(10,7,-3,1)
Block(10,7,-2,1)
Block(10,7,-1,1)
Block(10,7,0,1)
Block(10,7,1,1)
Block(10,7,2,1)
Block(10,7,3,1)
Block(10,7,4,1)
Block(10,7,5,1)
Block(10,7,6,1)
Block(10,7,7,1)
Block(10,7,8,1)
Block(10,7,9,1)
Block(10,8,-4,1)
Block(10,8,-3,1)
Block(10,8,-2,1)
Block(10,8,-1,1)
Block(10,8,0,1)
Block(10,8,1,1)
Block(10,8,2,1)
Block(10,8,3,1)
Block(10,8,4,1)
Block(10,8,5,1)
Block(10,8,6,1)
Block(10,8,7,1)
Block(10,8,8,1)
Block(10,8,9,1)
Block(10,9,-4,1)
Block(10,9,-3,1)
Block(10,9,-2,1)
Block(10,9,-1,1)
Block(10,9,0,1)
Block(10,9,1,1)
Block(10,9,2,1)
Block(10,9,3,1)
Block(10,9,4,1)
Block(10,9,5,1)
Block(10,9,6,1)
Block(10,9,7,1)
Block(10,9,8,1)
Block(10,9,9,1)
Block(10,9,10,1)
Block(10,10,-4,1)
Block(10,10,-3,1)
Block(10,10,-2,1)
Block(10,10,-1,1)
Block(10,10,0,1)
Block(10,10,1,1)
Block(10,10,2,1)
Block(10,10,3,1)
Block(10,10,4,1)
Block(10,10,5,1)
Block(10,10,6,1)
Block(10,10,7,1)
Block(10,10,8,1)
Block(10,10,9,1)
Block(10,10,10,1)
Block(10,11,-4,1)
Block(10,11,-3,1)
Block(10,11,-2,1)
Block(10,11,-1,1)
Block(10,11,0,1)
Block(10,11,1,1)
Block(10,11,2,1)
Block(10,11,3,1)
Block(10,11,4,1)
Block(10,11,5,1)
Block(10,11,6,1)
Block(10,11,7,1)
Block(10,11,8,1)
Block(10,11,9,1)
Block(10,11,10,1)
Block(10,12,-4,1)
Block(10,12,-3,1)
Block(10,12,-2,1)
Block(10,12,-1,1)
Block(10,12,0,1)
Block(10,12,1,1)
Block(10,12,2,1)
Block(10,12,3,1)
Block(10,12,4,1)
Block(10,12,5,1)
Block(10,12,6,1)
Block(10,12,7,1)
Block(10,12,8,1)
Block(10,12,9,1)
Block(10,12,10,1)
Block(10,13,-4,1)
Block(10,13,-3,1)
Block(10,13,-2,1)
Block(10,13,-1,1)
Block(10,13,0,1)
Block(10,13,1,1)
Block(10,13,2,1)
Block(10,13,3,1)
Block(10,13,4,1)
Block(10,13,5,1)
Block(10,13,6,1)
Block(10,13,7,1)
Block(10,13,8,1)
Block(10,13,9,1)
Block(10,13,10,1)
Block(10,14,-4,1)
Block(10,14,-3,1)
Block(10,14,-2,1)
Block(10,14,-1,1)
Block(10,14,0,1)
Block(10,14,1,1)
Block(10,14,2,1)
Block(10,14,3,1)
Block(10,14,4,1)
Block(10,14,5,1)
Block(10,14,6,1)
Block(10,14,7,1)
Block(10,14,8,1)
Block(10,14,9,1)
Block(10,14,10,1)
Block(10,15,-4,1)
Block(10,15,-3,1)
Block(10,15,-2,1)
Block(10,15,-1,1)
Block(10,15,0,1)
Block(10,15,1,1)
Block(10,15,2,1)
Block(10,15,3,1)
Block(10,15,4,1)
Block(10,15,5,1)
Block(10,15,6,1)
Block(10,15,7,1)
Block(10,15,8,1)
Block(10,15,9,1)
Block(10,15,10,1)
Block(10,16,-4,1)
Block(10,16,-3,1)
Block(10,16,-2,1)
Block(10,16,-1,1)
Block(10,16,0,1)
Block(10,16,1,1)
Block(10,16,2,1)
Block(10,16,3,1)
Block(10,16,4,1)
Block(10,16,5,1)
Block(10,16,6,1)
Block(10,16,7,1)
Block(10,16,8,1)
Block(10,16,9,1)
Block(10,16,10,1)
Block(10,17,-4,1)
Block(10,17,-3,1)
Block(10,17,-2,1)
Block(10,17,-1,1)
Block(10,17,0,1)
Block(10,17,1,1)
Block(10,17,2,1)
Block(10,17,3,1)
Block(10,17,4,1)
Block(10,17,5,1)
Block(10,17,6,1)
Block(10,17,7,1)
Block(10,17,8,1)
Block(10,17,9,1)
Block(10,17,10,1)
Block(10,18,-4,1)
Block(10,18,-3,1)
Block(10,18,-2,1)
Block(10,18,-1,1)
Block(10,18,0,1)
Block(10,18,1,1)
Block(10,18,2,1)
Block(10,18,3,1)
Block(10,18,4,1)
Block(10,18,5,1)
Block(10,18,6,1)
Block(10,18,7,1)
Block(10,18,8,1)
Block(10,18,9,1)
Block(10,18,10,1)
Block(10,19,-4,1)
Block(10,19,-3,1)
Block(10,19,-2,1)
Block(10,19,-1,1)
Block(10,19,0,1)
Block(10,19,1,1)
Block(10,19,2,1)
Block(10,19,3,1)
Block(10,19,4,1)
Block(10,19,5,1)
Block(10,19,6,1)
Block(10,19,7,1)
Block(10,19,8,1)
Block(10,19,9,1)
Block(10,20,-4,1)
Block(10,20,-3,1)
Block(10,20,-2,1)
Block(10,20,-1,1)
Block(10,20,0,1)
Block(10,20,1,1)
Block(10,20,2,1)
Block(10,20,3,1)
Block(10,20,4,1)
Block(10,20,5,1)
Block(10,20,6,1)
Block(10,20,7,1)
Block(10,20,8,1)
Block(10,20,9,1)
Block(10,21,-3,1)
Block(10,21,-2,1)
Block(10,21,-1,1)
Block(10,21,0,1)
Block(10,21,1,1)
Block(10,21,2,1)
Block(10,21,3,1)
Block(10,21,4,1)
Block(10,21,5,1)
Block(10,21,6,1)
Block(10,21,7,1)
Block(10,21,8,1)
Block(10,22,-3,1)
Block(10,22,-2,1)
Block(10,22,-1,1)
Block(10,22,0,1)
Block(10,22,1,1)
Block(10,22,2,1)
Block(10,22,3,1)
Block(10,22,4,1)
Block(10,22,5,1)
Block(10,22,6,1)
Block(10,23,-3,1)
Block(10,23,-2,1)
Block(10,23,-1,1)
Block(10,23,0,1)
Block(10,23,1,1)
Block(10,23,2,1)
Block(10,23,3,1)
Block(10,23,4,1)
Block(10,23,5,1)
Block(10,24,-2,1)
Block(10,24,-1,1)
Block(10,24,0,1)
Block(10,24,1,1)
Block(10,24,2,1)
Block(10,25,-2,1)
Block(11,3,-1,1)
Block(11,3,0,1)
Block(11,3,1,1)
Block(11,4,-4,1)
Block(11,4,-3,1)
Block(11,4,-2,1)
Block(11,4,-1,1)
Block(11,4,0,1)
Block(11,4,1,1)
Block(11,4,2,1)
Block(11,4,3,1)
Block(11,4,4,1)
Block(11,4,5,1)
Block(11,4,6,1)
Block(11,4,7,1)
Block(11,4,8,1)
Block(11,5,-5,1)
Block(11,5,-4,1)
Block(11,5,-3,1)
Block(11,5,-2,1)
Block(11,5,-1,1)
Block(11,5,0,1)
Block(11,5,1,1)
Block(11,5,2,1)
Block(11,5,3,1)
Block(11,5,4,1)
Block(11,5,5,1)
Block(11,5,6,1)
Block(11,5,7,1)
Block(11,5,8,1)
Block(11,6,-5,1)
Block(11,6,-4,1)
Block(11,6,-3,1)
Block(11,6,-2,1)
Block(11,6,-1,1)
Block(11,6,0,1)
Block(11,6,1,1)
Block(11,6,2,1)
Block(11,6,3,1)
Block(11,6,4,1)
Block(11,6,5,1)
Block(11,6,6,1)
Block(11,6,7,1)
Block(11,6,8,1)
Block(11,6,9,1)
Block(11,7,-5,1)
Block(11,7,-4,1)
Block(11,7,-3,1)
Block(11,7,-2,1)
Block(11,7,-1,1)
Block(11,7,0,1)
Block(11,7,1,1)
Block(11,7,2,1)
Block(11,7,3,1)
Block(11,7,4,1)
Block(11,7,5,1)
Block(11,7,6,1)
Block(11,7,7,1)
Block(11,7,8,1)
Block(11,7,9,1)
Block(11,8,-5,1)
Block(11,8,-4,1)
Block(11,8,-3,1)
Block(11,8,-2,1)
Block(11,8,-1,1)
Block(11,8,0,1)
Block(11,8,1,1)
Block(11,8,2,1)
Block(11,8,3,1)
Block(11,8,4,1)
Block(11,8,5,1)
Block(11,8,6,1)
Block(11,8,7,1)
Block(11,8,8,1)
Block(11,8,9,1)
Block(11,9,-5,1)
Block(11,9,-4,1)
Block(11,9,-3,1)
Block(11,9,-2,1)
Block(11,9,-1,1)
Block(11,9,0,1)
Block(11,9,1,1)
Block(11,9,2,1)
Block(11,9,3,1)
Block(11,9,4,1)
Block(11,9,5,1)
Block(11,9,6,1)
Block(11,9,7,1)
Block(11,9,8,1)
Block(11,9,9,1)
Block(11,10,-5,1)
Block(11,10,-4,1)
Block(11,10,-3,1)
Block(11,10,-2,1)
Block(11,10,-1,1)
Block(11,10,0,1)
Block(11,10,1,1)
Block(11,10,2,1)
Block(11,10,3,1)
Block(11,10,4,1)
Block(11,10,5,1)
Block(11,10,6,1)
Block(11,10,7,1)
Block(11,10,8,1)
Block(11,10,9,1)
Block(11,11,-5,1)
Block(11,11,-4,1)
Block(11,11,-3,1)
Block(11,11,-2,1)
Block(11,11,-1,1)
Block(11,11,0,1)
Block(11,11,1,1)
Block(11,11,2,1)
Block(11,11,3,1)
Block(11,11,4,1)
Block(11,11,5,1)
Block(11,11,6,1)
Block(11,11,7,1)
Block(11,11,8,1)
Block(11,11,9,1)
Block(11,11,10,1)
Block(11,12,-5,1)
Block(11,12,-4,1)
Block(11,12,-3,1)
Block(11,12,-2,1)
Block(11,12,-1,1)
Block(11,12,0,1)
Block(11,12,1,1)
Block(11,12,2,1)
Block(11,12,3,1)
Block(11,12,4,1)
Block(11,12,5,1)
Block(11,12,6,1)
Block(11,12,7,1)
Block(11,12,8,1)
Block(11,12,9,1)
Block(11,13,-5,1)
Block(11,13,-4,1)
Block(11,13,-3,1)
Block(11,13,-2,1)
Block(11,13,-1,1)
Block(11,13,0,1)
Block(11,13,1,1)
Block(11,13,2,1)
Block(11,13,3,1)
Block(11,13,4,1)
Block(11,13,5,1)
Block(11,13,6,1)
Block(11,13,7,1)
Block(11,13,8,1)
Block(11,13,9,1)
Block(11,14,-5,1)
Block(11,14,-4,1)
Block(11,14,-3,1)
Block(11,14,-2,1)
Block(11,14,-1,1)
Block(11,14,0,1)
Block(11,14,1,1)
Block(11,14,2,1)
Block(11,14,3,1)
Block(11,14,4,1)
Block(11,14,5,1)
Block(11,14,6,1)
Block(11,14,7,1)
Block(11,14,8,1)
Block(11,14,9,1)
Block(11,15,-5,1)
Block(11,15,-4,1)
Block(11,15,-3,1)
Block(11,15,-2,1)
Block(11,15,-1,1)
Block(11,15,0,1)
Block(11,15,1,1)
Block(11,15,2,1)
Block(11,15,3,1)
Block(11,15,4,1)
Block(11,15,5,1)
Block(11,15,6,1)
Block(11,15,7,1)
Block(11,15,8,1)
Block(11,15,9,1)
Block(11,16,-5,1)
Block(11,16,-4,1)
Block(11,16,-3,1)
Block(11,16,-2,1)
Block(11,16,-1,1)
Block(11,16,0,1)
Block(11,16,1,1)
Block(11,16,2,1)
Block(11,16,3,1)
Block(11,16,4,1)
Block(11,16,5,1)
Block(11,16,6,1)
Block(11,16,7,1)
Block(11,16,8,1)
Block(11,16,9,1)
Block(11,17,-5,1)
Block(11,17,-4,1)
Block(11,17,-3,1)
Block(11,17,-2,1)
Block(11,17,-1,1)
Block(11,17,0,1)
Block(11,17,1,1)
Block(11,17,2,1)
Block(11,17,3,1)
Block(11,17,4,1)
Block(11,17,5,1)
Block(11,17,6,1)
Block(11,17,7,1)
Block(11,17,8,1)
Block(11,17,9,1)
Block(11,18,-5,1)
Block(11,18,-4,1)
Block(11,18,-3,1)
Block(11,18,-2,1)
Block(11,18,-1,1)
Block(11,18,0,1)
Block(11,18,1,1)
Block(11,18,2,1)
Block(11,18,3,1)
Block(11,18,4,1)
Block(11,18,5,1)
Block(11,18,6,1)
Block(11,18,7,1)
Block(11,18,8,1)
Block(11,18,9,1)
Block(11,19,-5,1)
Block(11,19,-4,1)
Block(11,19,-3,1)
Block(11,19,-2,1)
Block(11,19,-1,1)
Block(11,19,0,1)
Block(11,19,1,1)
Block(11,19,2,1)
Block(11,19,3,1)
Block(11,19,4,1)
Block(11,19,5,1)
Block(11,19,6,1)
Block(11,19,7,1)
Block(11,19,8,1)
Block(11,20,-5,1)
Block(11,20,-4,1)
Block(11,20,-3,1)
Block(11,20,-2,1)
Block(11,20,-1,1)
Block(11,20,0,1)
Block(11,20,1,1)
Block(11,20,2,1)
Block(11,20,3,1)
Block(11,20,4,1)
Block(11,20,5,1)
Block(11,20,6,1)
Block(11,20,7,1)
Block(11,20,8,1)
Block(11,21,-4,1)
Block(11,21,-3,1)
Block(11,21,-2,1)
Block(11,21,-1,1)
Block(11,21,0,1)
Block(11,21,1,1)
Block(11,21,2,1)
Block(11,21,3,1)
Block(11,21,4,1)
Block(11,21,5,1)
Block(11,21,6,1)
Block(11,21,7,1)
Block(11,22,-3,1)
Block(11,22,-2,1)
Block(11,22,-1,1)
Block(11,22,0,1)
Block(11,22,1,1)
Block(11,22,2,1)
Block(11,22,3,1)
Block(11,22,4,1)
Block(11,22,5,1)
Block(11,23,-3,1)
Block(11,23,-2,1)
Block(11,23,-1,1)
Block(11,23,0,1)
Block(11,23,1,1)
Block(11,23,2,1)
Block(11,23,3,1)
Block(11,23,4,1)
Block(11,24,-1,1)
Block(11,24,0,1)
Block(11,24,1,1)
Block(12,4,-4,1)
Block(12,4,-3,1)
Block(12,4,-2,1)
Block(12,4,-1,1)
Block(12,4,0,1)
Block(12,4,1,1)
Block(12,4,2,1)
Block(12,4,3,1)
Block(12,4,4,1)
Block(12,4,5,1)
Block(12,4,6,1)
Block(12,4,7,1)
Block(12,4,8,1)
Block(12,5,-5,1)
Block(12,5,-4,1)
Block(12,5,-3,1)
Block(12,5,-2,1)
Block(12,5,-1,1)
Block(12,5,0,1)
Block(12,5,1,1)
Block(12,5,2,1)
Block(12,5,3,1)
Block(12,5,4,1)
Block(12,5,5,1)
Block(12,5,6,1)
Block(12,5,7,1)
Block(12,5,8,1)
Block(12,6,-5,1)
Block(12,6,-4,1)
Block(12,6,-3,1)
Block(12,6,-2,1)
Block(12,6,-1,1)
Block(12,6,0,1)
Block(12,6,1,1)
Block(12,6,2,1)
Block(12,6,3,1)
Block(12,6,4,1)
Block(12,6,5,1)
Block(12,6,6,1)
Block(12,6,7,1)
Block(12,6,8,1)
Block(12,7,-5,1)
Block(12,7,-4,1)
Block(12,7,-3,1)
Block(12,7,-2,1)
Block(12,7,-1,1)
Block(12,7,0,1)
Block(12,7,1,1)
Block(12,7,2,1)
Block(12,7,3,1)
Block(12,7,4,1)
Block(12,7,5,1)
Block(12,7,6,1)
Block(12,7,7,1)
Block(12,7,8,1)
Block(12,8,-5,1)
Block(12,8,-4,1)
Block(12,8,-3,1)
Block(12,8,-2,1)
Block(12,8,-1,1)
Block(12,8,0,1)
Block(12,8,1,1)
Block(12,8,2,1)
Block(12,8,3,1)
Block(12,8,4,1)
Block(12,8,5,1)
Block(12,8,6,1)
Block(12,8,7,1)
Block(12,8,8,1)
Block(12,9,-5,1)
Block(12,9,-4,1)
Block(12,9,-3,1)
Block(12,9,-2,1)
Block(12,9,-1,1)
Block(12,9,0,1)
Block(12,9,1,1)
Block(12,9,2,1)
Block(12,9,3,1)
Block(12,9,4,1)
Block(12,9,5,1)
Block(12,9,6,1)
Block(12,9,7,1)
Block(12,9,8,1)
Block(12,9,9,1)
Block(12,10,-6,1)
Block(12,10,-5,1)
Block(12,10,-4,1)
Block(12,10,-3,1)
Block(12,10,-2,1)
Block(12,10,-1,1)
Block(12,10,0,1)
Block(12,10,1,1)
Block(12,10,2,1)
Block(12,10,3,1)
Block(12,10,4,1)
Block(12,10,5,1)
Block(12,10,6,1)
Block(12,10,7,1)
Block(12,10,8,1)
Block(12,10,9,1)
Block(12,11,-6,1)
Block(12,11,-5,1)
Block(12,11,-4,1)
Block(12,11,-3,1)
Block(12,11,-2,1)
Block(12,11,-1,1)
Block(12,11,0,1)
Block(12,11,1,1)
Block(12,11,2,1)
Block(12,11,3,1)
Block(12,11,4,1)
Block(12,11,5,1)
Block(12,11,6,1)
Block(12,11,7,1)
Block(12,11,8,1)
Block(12,11,9,1)
Block(12,12,-6,1)
Block(12,12,-5,1)
Block(12,12,-4,1)
Block(12,12,-3,1)
Block(12,12,-2,1)
Block(12,12,-1,1)
Block(12,12,0,1)
Block(12,12,1,1)
Block(12,12,2,1)
Block(12,12,3,1)
Block(12,12,4,1)
Block(12,12,5,1)
Block(12,12,6,1)
Block(12,12,7,1)
Block(12,12,8,1)
Block(12,12,9,1)
Block(12,13,-6,1)
Block(12,13,-5,1)
Block(12,13,-4,1)
Block(12,13,-3,1)
Block(12,13,-2,1)
Block(12,13,-1,1)
Block(12,13,0,1)
Block(12,13,1,1)
Block(12,13,2,1)
Block(12,13,3,1)
Block(12,13,4,1)
Block(12,13,5,1)
Block(12,13,6,1)
Block(12,13,7,1)
Block(12,13,8,1)
Block(12,13,9,1)
Block(12,14,-6,1)
Block(12,14,-5,1)
Block(12,14,-4,1)
Block(12,14,-3,1)
Block(12,14,-2,1)
Block(12,14,-1,1)
Block(12,14,0,1)
Block(12,14,1,1)
Block(12,14,2,1)
Block(12,14,3,1)
Block(12,14,4,1)
Block(12,14,5,1)
Block(12,14,6,1)
Block(12,14,7,1)
Block(12,14,8,1)
Block(12,14,9,1)
Block(12,15,-6,1)
Block(12,15,-5,1)
Block(12,15,-4,1)
Block(12,15,-3,1)
Block(12,15,-2,1)
Block(12,15,-1,1)
Block(12,15,0,1)
Block(12,15,1,1)
Block(12,15,2,1)
Block(12,15,3,1)
Block(12,15,4,1)
Block(12,15,5,1)
Block(12,15,6,1)
Block(12,15,7,1)
Block(12,15,8,1)
Block(12,16,-6,1)
Block(12,16,-5,1)
Block(12,16,-4,1)
Block(12,16,-3,1)
Block(12,16,-2,1)
Block(12,16,-1,1)
Block(12,16,0,1)
Block(12,16,1,1)
Block(12,16,2,1)
Block(12,16,3,1)
Block(12,16,4,1)
Block(12,16,5,1)
Block(12,16,6,1)
Block(12,16,7,1)
Block(12,16,8,1)
Block(12,17,-5,1)
Block(12,17,-4,1)
Block(12,17,-3,1)
Block(12,17,-2,1)
Block(12,17,-1,1)
Block(12,17,0,1)
Block(12,17,1,1)
Block(12,17,2,1)
Block(12,17,3,1)
Block(12,17,4,1)
Block(12,17,5,1)
Block(12,17,6,1)
Block(12,17,7,1)
Block(12,17,8,1)
Block(12,18,-5,1)
Block(12,18,-4,1)
Block(12,18,-3,1)
Block(12,18,-2,1)
Block(12,18,-1,1)
Block(12,18,0,1)
Block(12,18,1,1)
Block(12,18,2,1)
Block(12,18,3,1)
Block(12,18,4,1)
Block(12,18,5,1)
Block(12,18,6,1)
Block(12,18,7,1)
Block(12,18,8,1)
Block(12,19,-5,1)
Block(12,19,-4,1)
Block(12,19,-3,1)
Block(12,19,-2,1)
Block(12,19,-1,1)
Block(12,19,0,1)
Block(12,19,1,1)
Block(12,19,2,1)
Block(12,19,3,1)
Block(12,19,4,1)
Block(12,19,5,1)
Block(12,19,6,1)
Block(12,19,7,1)
Block(12,19,8,1)
Block(12,20,-4,1)
Block(12,20,-3,1)
Block(12,20,-2,1)
Block(12,20,-1,1)
Block(12,20,0,1)
Block(12,20,1,1)
Block(12,20,2,1)
Block(12,20,3,1)
Block(12,20,4,1)
Block(12,20,5,1)
Block(12,20,6,1)
Block(12,20,7,1)
Block(12,21,-3,1)
Block(12,21,-2,1)
Block(12,21,-1,1)
Block(12,21,0,1)
Block(12,21,1,1)
Block(12,21,2,1)
Block(12,21,3,1)
Block(12,21,4,1)
Block(12,21,5,1)
Block(12,21,6,1)
Block(12,22,-3,1)
Block(12,22,-2,1)
Block(12,22,-1,1)
Block(12,22,0,1)
Block(12,22,1,1)
Block(12,22,2,1)
Block(12,22,3,1)
Block(12,22,4,1)
Block(12,22,5,1)
Block(12,23,1,1)
Block(12,23,2,1)
Block(12,23,3,1)
Block(13,4,-4,1)
Block(13,4,-3,1)
Block(13,4,-2,1)
Block(13,4,-1,1)
Block(13,4,0,1)
Block(13,4,1,1)
Block(13,4,2,1)
Block(13,4,3,1)
Block(13,4,4,1)
Block(13,4,5,1)
Block(13,4,6,1)
Block(13,4,7,1)
Block(13,5,-5,1)
Block(13,5,-4,1)
Block(13,5,-3,1)
Block(13,5,-2,1)
Block(13,5,-1,1)
Block(13,5,0,1)
Block(13,5,1,1)
Block(13,5,2,1)
Block(13,5,3,1)
Block(13,5,4,1)
Block(13,5,5,1)
Block(13,5,6,1)
Block(13,5,7,1)
Block(13,6,-5,1)
Block(13,6,-4,1)
Block(13,6,-3,1)
Block(13,6,-2,1)
Block(13,6,-1,1)
Block(13,6,0,1)
Block(13,6,1,1)
Block(13,6,2,1)
Block(13,6,3,1)
Block(13,6,4,1)
Block(13,6,5,1)
Block(13,6,6,1)
Block(13,6,7,1)
Block(13,7,-5,1)
Block(13,7,-4,1)
Block(13,7,-3,1)
Block(13,7,-2,1)
Block(13,7,-1,1)
Block(13,7,0,1)
Block(13,7,1,1)
Block(13,7,2,1)
Block(13,7,3,1)
Block(13,7,4,1)
Block(13,7,5,1)
Block(13,7,6,1)
Block(13,7,7,1)
Block(13,7,8,1)
Block(13,8,-5,1)
Block(13,8,-4,1)
Block(13,8,-3,1)
Block(13,8,-2,1)
Block(13,8,-1,1)
Block(13,8,0,1)
Block(13,8,1,1)
Block(13,8,2,1)
Block(13,8,3,1)
Block(13,8,4,1)
Block(13,8,5,1)
Block(13,8,6,1)
Block(13,8,7,1)
Block(13,8,8,1)
Block(13,9,-6,1)
Block(13,9,-5,1)
Block(13,9,-4,1)
Block(13,9,-3,1)
Block(13,9,-2,1)
Block(13,9,-1,1)
Block(13,9,0,1)
Block(13,9,1,1)
Block(13,9,2,1)
Block(13,9,3,1)
Block(13,9,4,1)
Block(13,9,5,1)
Block(13,9,6,1)
Block(13,9,7,1)
Block(13,9,8,1)
Block(13,10,-6,1)
Block(13,10,-5,1)
Block(13,10,-4,1)
Block(13,10,-3,1)
Block(13,10,-2,1)
Block(13,10,-1,1)
Block(13,10,0,1)
Block(13,10,1,1)
Block(13,10,2,1)
Block(13,10,3,1)
Block(13,10,4,1)
Block(13,10,5,1)
Block(13,10,6,1)
Block(13,10,7,1)
Block(13,10,8,1)
Block(13,11,-6,1)
Block(13,11,-5,1)
Block(13,11,-4,1)
Block(13,11,-3,1)
Block(13,11,-2,1)
Block(13,11,-1,1)
Block(13,11,0,1)
Block(13,11,1,1)
Block(13,11,2,1)
Block(13,11,3,1)
Block(13,11,4,1)
Block(13,11,5,1)
Block(13,11,6,1)
Block(13,11,7,1)
Block(13,11,8,1)
Block(13,12,-6,1)
Block(13,12,-5,1)
Block(13,12,-4,1)
Block(13,12,-3,1)
Block(13,12,-2,1)
Block(13,12,-1,1)
Block(13,12,0,1)
Block(13,12,1,1)
Block(13,12,2,1)
Block(13,12,3,1)
Block(13,12,4,1)
Block(13,12,5,1)
Block(13,12,6,1)
Block(13,12,7,1)
Block(13,12,8,1)
Block(13,13,-6,1)
Block(13,13,-5,1)
Block(13,13,-4,1)
Block(13,13,-3,1)
Block(13,13,-2,1)
Block(13,13,-1,1)
Block(13,13,0,1)
Block(13,13,1,1)
Block(13,13,2,1)
Block(13,13,3,1)
Block(13,13,4,1)
Block(13,13,5,1)
Block(13,13,6,1)
Block(13,13,7,1)
Block(13,13,8,1)
Block(13,14,-6,1)
Block(13,14,-5,1)
Block(13,14,-4,1)
Block(13,14,-3,1)
Block(13,14,-2,1)
Block(13,14,-1,1)
Block(13,14,0,1)
Block(13,14,1,1)
Block(13,14,2,1)
Block(13,14,3,1)
Block(13,14,4,1)
Block(13,14,5,1)
Block(13,14,6,1)
Block(13,14,7,1)
Block(13,14,8,1)
Block(13,15,-6,1)
Block(13,15,-5,1)
Block(13,15,-4,1)
Block(13,15,-3,1)
Block(13,15,-2,1)
Block(13,15,-1,1)
Block(13,15,0,1)
Block(13,15,1,1)
Block(13,15,2,1)
Block(13,15,3,1)
Block(13,15,4,1)
Block(13,15,5,1)
Block(13,15,6,1)
Block(13,15,7,1)
Block(13,15,8,1)
Block(13,16,-5,1)
Block(13,16,-4,1)
Block(13,16,-3,1)
Block(13,16,-2,1)
Block(13,16,-1,1)
Block(13,16,0,1)
Block(13,16,1,1)
Block(13,16,2,1)
Block(13,16,3,1)
Block(13,16,4,1)
Block(13,16,5,1)
Block(13,16,6,1)
Block(13,16,7,1)
Block(13,16,8,1)
Block(13,17,-5,1)
Block(13,17,-4,1)
Block(13,17,-3,1)
Block(13,17,-2,1)
Block(13,17,-1,1)
Block(13,17,0,1)
Block(13,17,1,1)
Block(13,17,2,1)
Block(13,17,3,1)
Block(13,17,4,1)
Block(13,17,5,1)
Block(13,17,6,1)
Block(13,17,7,1)
Block(13,18,-5,1)
Block(13,18,-4,1)
Block(13,18,-3,1)
Block(13,18,-2,1)
Block(13,18,-1,1)
Block(13,18,0,1)
Block(13,18,1,1)
Block(13,18,2,1)
Block(13,18,3,1)
Block(13,18,4,1)
Block(13,18,5,1)
Block(13,18,6,1)
Block(13,18,7,1)
Block(13,19,-4,1)
Block(13,19,-3,1)
Block(13,19,-2,1)
Block(13,19,-1,1)
Block(13,19,0,1)
Block(13,19,1,1)
Block(13,19,2,1)
Block(13,19,3,1)
Block(13,19,4,1)
Block(13,19,5,1)
Block(13,19,6,1)
Block(13,19,7,1)
Block(13,20,-4,1)
Block(13,20,-3,1)
Block(13,20,-2,1)
Block(13,20,-1,1)
Block(13,20,0,1)
Block(13,20,1,1)
Block(13,20,2,1)
Block(13,20,3,1)
Block(13,20,4,1)
Block(13,20,5,1)
Block(13,20,6,1)
Block(13,21,-1,1)
Block(13,21,0,1)
Block(13,21,1,1)
Block(13,21,2,1)
Block(13,21,3,1)
Block(13,21,4,1)
Block(13,21,5,1)
Block(13,22,3,1)
Block(13,22,4,1)
Block(14,4,-3,1)
Block(14,4,-2,1)
Block(14,4,-1,1)
Block(14,4,0,1)
Block(14,4,1,1)
Block(14,4,2,1)
Block(14,4,3,1)
Block(14,4,4,1)
Block(14,4,5,1)
Block(14,4,6,1)
Block(14,5,-3,1)
Block(14,5,-2,1)
Block(14,5,-1,1)
Block(14,5,0,1)
Block(14,5,1,1)
Block(14,5,2,1)
Block(14,5,3,1)
Block(14,5,4,1)
Block(14,5,5,1)
Block(14,5,6,1)
Block(14,6,-4,1)
Block(14,6,-3,1)
Block(14,6,-2,1)
Block(14,6,-1,1)
Block(14,6,0,1)
Block(14,6,1,1)
Block(14,6,2,1)
Block(14,6,3,1)
Block(14,6,4,1)
Block(14,6,5,1)
Block(14,6,6,1)
Block(14,6,7,1)
Block(14,7,-4,1)
Block(14,7,-3,1)
Block(14,7,-2,1)
Block(14,7,-1,1)
Block(14,7,0,1)
Block(14,7,1,1)
Block(14,7,2,1)
Block(14,7,3,1)
Block(14,7,4,1)
Block(14,7,5,1)
Block(14,7,6,1)
Block(14,7,7,1)
Block(14,8,-5,1)
Block(14,8,-4,1)
Block(14,8,-3,1)
Block(14,8,-2,1)
Block(14,8,-1,1)
Block(14,8,0,1)
Block(14,8,1,1)
Block(14,8,2,1)
Block(14,8,3,1)
Block(14,8,4,1)
Block(14,8,5,1)
Block(14,8,6,1)
Block(14,8,7,1)
Block(14,9,-5,1)
Block(14,9,-4,1)
Block(14,9,-3,1)
Block(14,9,-2,1)
Block(14,9,-1,1)
Block(14,9,0,1)
Block(14,9,1,1)
Block(14,9,2,1)
Block(14,9,3,1)
Block(14,9,4,1)
Block(14,9,5,1)
Block(14,9,6,1)
Block(14,9,7,1)
Block(14,10,-5,1)
Block(14,10,-4,1)
Block(14,10,-3,1)
Block(14,10,-2,1)
Block(14,10,-1,1)
Block(14,10,0,1)
Block(14,10,1,1)
Block(14,10,2,1)
Block(14,10,3,1)
Block(14,10,4,1)
Block(14,10,5,1)
Block(14,10,6,1)
Block(14,10,7,1)
Block(14,10,8,1)
Block(14,11,-5,1)
Block(14,11,-4,1)
Block(14,11,-3,1)
Block(14,11,-2,1)
Block(14,11,-1,1)
Block(14,11,0,1)
Block(14,11,1,1)
Block(14,11,2,1)
Block(14,11,3,1)
Block(14,11,4,1)
Block(14,11,5,1)
Block(14,11,6,1)
Block(14,11,7,1)
Block(14,12,-5,1)
Block(14,12,-4,1)
Block(14,12,-3,1)
Block(14,12,-2,1)
Block(14,12,-1,1)
Block(14,12,0,1)
Block(14,12,1,1)
Block(14,12,2,1)
Block(14,12,3,1)
Block(14,12,4,1)
Block(14,12,5,1)
Block(14,12,6,1)
Block(14,12,7,1)
Block(14,13,-5,1)
Block(14,13,-4,1)
Block(14,13,-3,1)
Block(14,13,-2,1)
Block(14,13,-1,1)
Block(14,13,0,1)
Block(14,13,1,1)
Block(14,13,2,1)
Block(14,13,3,1)
Block(14,13,4,1)
Block(14,13,5,1)
Block(14,13,6,1)
Block(14,13,7,1)
Block(14,14,-5,1)
Block(14,14,-4,1)
Block(14,14,-3,1)
Block(14,14,-2,1)
Block(14,14,-1,1)
Block(14,14,0,1)
Block(14,14,1,1)
Block(14,14,2,1)
Block(14,14,3,1)
Block(14,14,4,1)
Block(14,14,5,1)
Block(14,14,6,1)
Block(14,14,7,1)
Block(14,15,-5,1)
Block(14,15,-4,1)
Block(14,15,-3,1)
Block(14,15,-2,1)
Block(14,15,-1,1)
Block(14,15,0,1)
Block(14,15,1,1)
Block(14,15,2,1)
Block(14,15,3,1)
Block(14,15,4,1)
Block(14,15,5,1)
Block(14,15,6,1)
Block(14,15,7,1)
Block(14,16,-5,1)
Block(14,16,-4,1)
Block(14,16,-3,1)
Block(14,16,-2,1)
Block(14,16,-1,1)
Block(14,16,0,1)
Block(14,16,1,1)
Block(14,16,2,1)
Block(14,16,3,1)
Block(14,16,4,1)
Block(14,16,5,1)
Block(14,16,6,1)
Block(14,17,-4,1)
Block(14,17,-3,1)
Block(14,17,-2,1)
Block(14,17,-1,1)
Block(14,17,0,1)
Block(14,17,1,1)
Block(14,17,2,1)
Block(14,17,3,1)
Block(14,17,4,1)
Block(14,17,5,1)
Block(14,17,6,1)
Block(14,18,-4,1)
Block(14,18,-3,1)
Block(14,18,-2,1)
Block(14,18,-1,1)
Block(14,18,0,1)
Block(14,18,1,1)
Block(14,18,2,1)
Block(14,18,3,1)
Block(14,18,4,1)
Block(14,18,5,1)
Block(14,18,6,1)
Block(14,19,0,1)
Block(14,19,1,1)
Block(14,19,2,1)
Block(14,19,3,1)
Block(14,19,4,1)
Block(14,19,5,1)
Block(14,19,6,1)
Block(14,20,2,1)
Block(14,20,3,1)
Block(14,20,4,1)
Block(14,20,5,1)
Block(14,20,6,1)
Block(14,21,3,1)
Block(14,21,4,1)
Block(14,21,5,1)
Block(15,4,-2,1)
Block(15,4,-1,1)
Block(15,4,0,1)
Block(15,4,1,1)
Block(15,4,2,1)
Block(15,4,3,1)
Block(15,4,4,1)
Block(15,4,5,1)
Block(15,5,-2,1)
Block(15,5,-1,1)
Block(15,5,0,1)
Block(15,5,1,1)
Block(15,5,2,1)
Block(15,5,3,1)
Block(15,5,4,1)
Block(15,5,5,1)
Block(15,6,-3,1)
Block(15,6,-2,1)
Block(15,6,-1,1)
Block(15,6,0,1)
Block(15,6,1,1)
Block(15,6,2,1)
Block(15,6,3,1)
Block(15,6,4,1)
Block(15,6,5,1)
Block(15,6,6,1)
Block(15,7,-3,1)
Block(15,7,-2,1)
Block(15,7,-1,1)
Block(15,7,0,1)
Block(15,7,1,1)
Block(15,7,2,1)
Block(15,7,3,1)
Block(15,7,4,1)
Block(15,7,5,1)
Block(15,7,6,1)
Block(15,8,-4,1)
Block(15,8,-3,1)
Block(15,8,-2,1)
Block(15,8,-1,1)
Block(15,8,0,1)
Block(15,8,1,1)
Block(15,8,2,1)
Block(15,8,3,1)
Block(15,8,4,1)
Block(15,8,5,1)
Block(15,8,6,1)
Block(15,8,7,1)
Block(15,9,-4,1)
Block(15,9,-3,1)
Block(15,9,-2,1)
Block(15,9,-1,1)
Block(15,9,0,1)
Block(15,9,1,1)
Block(15,9,2,1)
Block(15,9,3,1)
Block(15,9,4,1)
Block(15,9,5,1)
Block(15,9,6,1)
Block(15,9,7,1)
Block(15,10,-4,1)
Block(15,10,-3,1)
Block(15,10,-2,1)
Block(15,10,-1,1)
Block(15,10,0,1)
Block(15,10,1,1)
Block(15,10,2,1)
Block(15,10,3,1)
Block(15,10,4,1)
Block(15,10,5,1)
Block(15,10,6,1)
Block(15,10,7,1)
Block(15,11,-4,1)
Block(15,11,-3,1)
Block(15,11,-2,1)
Block(15,11,-1,1)
Block(15,11,0,1)
Block(15,11,1,1)
Block(15,11,2,1)
Block(15,11,3,1)
Block(15,11,4,1)
Block(15,11,5,1)
Block(15,11,6,1)
Block(15,11,7,1)
Block(15,12,-4,1)
Block(15,12,-3,1)
Block(15,12,-2,1)
Block(15,12,-1,1)
Block(15,12,0,1)
Block(15,12,1,1)
Block(15,12,2,1)
Block(15,12,3,1)
Block(15,12,4,1)
Block(15,12,5,1)
Block(15,12,6,1)
Block(15,12,7,1)
Block(15,13,-5,1)
Block(15,13,-4,1)
Block(15,13,-3,1)
Block(15,13,-2,1)
Block(15,13,-1,1)
Block(15,13,0,1)
Block(15,13,1,1)
Block(15,13,2,1)
Block(15,13,3,1)
Block(15,13,4,1)
Block(15,13,5,1)
Block(15,13,6,1)
Block(15,14,-5,1)
Block(15,14,-4,1)
Block(15,14,-3,1)
Block(15,14,-2,1)
Block(15,14,-1,1)
Block(15,14,0,1)
Block(15,14,1,1)
Block(15,14,2,1)
Block(15,14,3,1)
Block(15,14,4,1)
Block(15,14,5,1)
Block(15,14,6,1)
Block(15,15,-4,1)
Block(15,15,-3,1)
Block(15,15,-2,1)
Block(15,15,-1,1)
Block(15,15,0,1)
Block(15,15,1,1)
Block(15,15,2,1)
Block(15,15,3,1)
Block(15,15,4,1)
Block(15,15,5,1)
Block(15,16,-2,1)
Block(15,16,-1,1)
Block(15,16,0,1)
Block(15,16,1,1)
Block(15,16,2,1)
Block(15,16,3,1)
Block(15,16,4,1)
Block(15,16,5,1)
Block(15,17,-1,1)
Block(15,17,0,1)
Block(15,17,1,1)
Block(15,17,2,1)
Block(15,17,3,1)
Block(15,17,4,1)
Block(15,17,5,1)
Block(15,18,0,1)
Block(15,18,1,1)
Block(15,18,2,1)
Block(15,18,3,1)
Block(15,18,4,1)
Block(15,18,5,1)
Block(15,19,2,1)
Block(15,19,3,1)
Block(15,19,4,1)
Block(15,19,5,1)
Block(15,20,4,1)
Block(15,20,5,1)
Block(16,4,0,1)
Block(16,4,1,1)
Block(16,4,2,1)
Block(16,4,3,1)
Block(16,4,4,1)
Block(16,5,-1,1)
Block(16,5,0,1)
Block(16,5,1,1)
Block(16,5,2,1)
Block(16,5,3,1)
Block(16,5,4,1)
Block(16,6,-2,1)
Block(16,6,-1,1)
Block(16,6,0,1)
Block(16,6,1,1)
Block(16,6,2,1)
Block(16,6,3,1)
Block(16,6,4,1)
Block(16,7,-2,1)
Block(16,7,-1,1)
Block(16,7,0,1)
Block(16,7,1,1)
Block(16,7,2,1)
Block(16,7,3,1)
Block(16,7,4,1)
Block(16,7,5,1)
Block(16,8,-3,1)
Block(16,8,-2,1)
Block(16,8,-1,1)
Block(16,8,0,1)
Block(16,8,1,1)
Block(16,8,2,1)
Block(16,8,3,1)
Block(16,8,4,1)
Block(16,8,5,1)
Block(16,8,6,1)
Block(16,9,-3,1)
Block(16,9,-2,1)
Block(16,9,-1,1)
Block(16,9,0,1)
Block(16,9,1,1)
Block(16,9,2,1)
Block(16,9,3,1)
Block(16,9,4,1)
Block(16,9,5,1)
Block(16,9,6,1)
Block(16,10,-3,1)
Block(16,10,-2,1)
Block(16,10,-1,1)
Block(16,10,0,1)
Block(16,10,1,1)
Block(16,10,2,1)
Block(16,10,3,1)
Block(16,10,4,1)
Block(16,10,5,1)
Block(16,10,6,1)
Block(16,11,-4,1)
Block(16,11,-3,1)
Block(16,11,-2,1)
Block(16,11,-1,1)
Block(16,11,0,1)
Block(16,11,1,1)
Block(16,11,2,1)
Block(16,11,3,1)
Block(16,11,4,1)
Block(16,11,5,1)
Block(16,11,6,1)
Block(16,12,-4,1)
Block(16,12,-3,1)
Block(16,12,-2,1)
Block(16,12,-1,1)
Block(16,12,0,1)
Block(16,12,1,1)
Block(16,12,2,1)
Block(16,12,3,1)
Block(16,12,4,1)
Block(16,12,5,1)
Block(16,13,-4,1)
Block(16,13,-3,1)
Block(16,13,-2,1)
Block(16,13,-1,1)
Block(16,13,0,1)
Block(16,13,1,1)
Block(16,13,2,1)
Block(16,13,3,1)
Block(16,13,4,1)
Block(16,13,5,1)
Block(16,14,-3,1)
Block(16,14,-2,1)
Block(16,14,-1,1)
Block(16,14,0,1)
Block(16,14,1,1)
Block(16,14,2,1)
Block(16,14,3,1)
Block(16,14,4,1)
Block(16,15,-2,1)
Block(16,15,-1,1)
Block(16,15,0,1)
Block(16,15,1,1)
Block(16,15,2,1)
Block(16,15,3,1)
Block(16,15,4,1)
Block(16,16,-1,1)
Block(16,16,0,1)
Block(16,16,1,1)
Block(16,16,2,1)
Block(16,16,3,1)
Block(16,16,4,1)
Block(16,17,1,1)
Block(16,17,2,1)
Block(16,17,3,1)
Block(16,17,4,1)
Block(16,18,2,1)
Block(16,18,3,1)
Block(16,18,4,1)
Block(17,4,2,1)
Block(17,4,3,1)
Block(17,5,1,1)
Block(17,5,2,1)
Block(17,5,3,1)
Block(17,6,0,1)
Block(17,6,1,1)
Block(17,6,2,1)
Block(17,6,3,1)
Block(17,7,-1,1)
Block(17,7,0,1)
Block(17,7,1,1)
Block(17,7,2,1)
Block(17,7,3,1)
Block(17,7,4,1)
Block(17,8,-1,1)
Block(17,8,0,1)
Block(17,8,1,1)
Block(17,8,2,1)
Block(17,8,3,1)
Block(17,8,4,1)
Block(17,8,5,1)
Block(17,9,-1,1)
Block(17,9,0,1)
Block(17,9,1,1)
Block(17,9,2,1)
Block(17,9,3,1)
Block(17,9,4,1)
Block(17,9,5,1)
Block(17,9,6,1)
Block(17,10,-2,1)
Block(17,10,-1,1)
Block(17,10,0,1)
Block(17,10,1,1)
Block(17,10,2,1)
Block(17,10,3,1)
Block(17,10,4,1)
Block(17,10,5,1)
Block(17,11,-2,1)
Block(17,11,-1,1)
Block(17,11,0,1)
Block(17,11,1,1)
Block(17,11,2,1)
Block(17,11,3,1)
Block(17,11,4,1)
Block(17,11,5,1)
Block(17,12,-3,1)
Block(17,12,-2,1)
Block(17,12,-1,1)
Block(17,12,0,1)
Block(17,12,1,1)
Block(17,12,2,1)
Block(17,12,3,1)
Block(17,12,4,1)
Block(17,13,-2,1)
Block(17,13,-1,1)
Block(17,13,0,1)
Block(17,13,1,1)
Block(17,13,2,1)
Block(17,13,3,1)
Block(17,14,-1,1)
Block(17,14,0,1)
Block(17,14,1,1)
Block(17,14,2,1)
Block(17,14,3,1)
Block(17,15,0,1)
Block(17,15,1,1)
Block(17,15,2,1)
Block(17,15,3,1)
Block(17,16,1,1)
Block(17,16,2,1)
Block(17,16,3,1)
Block(17,17,2,1)
Block(18,5,2,1)
Block(18,6,1,1)
Block(18,6,2,1)
Block(18,7,0,1)
Block(18,7,1,1)
Block(18,7,2,1)
Block(18,7,3,1)
Block(18,8,0,1)
Block(18,8,1,1)
Block(18,8,2,1)
Block(18,8,3,1)
Block(18,9,0,1)
Block(18,9,1,1)
Block(18,9,2,1)
Block(18,9,3,1)
Block(18,9,4,1)
Block(18,10,0,1)
Block(18,10,1,1)
Block(18,10,2,1)
Block(18,10,3,1)
Block(18,10,4,1)
Block(18,11,-1,1)
Block(18,11,0,1)
Block(18,11,1,1)
Block(18,11,2,1)
Block(18,11,3,1)
Block(18,12,-1,1)
Block(18,12,0,1)
Block(18,12,1,1)
Block(18,12,2,1)
Block(18,12,3,1)
Block(18,13,-1,1)
Block(18,13,0,1)
Block(18,13,1,1)
Block(18,13,2,1)
Block(18,14,0,1)
Block(18,14,1,1)
Block(18,14,2,1)
Block(18,15,2,1)
Block(19,8,1,1)
Block(19,9,1,1)
Block(19,10,1,1)
Block(19,11,1,1)
Block(19,12,1,1)
Block(19,13,1,1)


#######################################################################
# +-----------------------------------------------------------------+ #
# |                             Entities                            | #
# +-----------------------------------------------------------------+ #
#######################################################################

# Entity() spawns an entity instead of a block. The entity is spawned only once when the BO3 is spawned.
# Entities are persistent by default so they don't de-spawn when no player is near, they are only unloaded.
# Usage: Entity(x,y,z,mobName,groupSize,NameTagOrNBTFileName) or Entity(x,y,z,mobName,groupSize)
# Use /tc entities or /otg entities to get a list of entities that can be used as mobName, this includes entities added by other mods.
# NameTagOrNBTFileName can be either a nametag for the mob or an nbt file (such as mymobinfo.nbt or mymobinfo.txt).
# When using a text file you can use the same mob spawning parameters used with the /summon command to equip the
# entity and give it custom attributes etc. You can copy the DATA part of a summon command including surrounding
# curly braces to a .txt file, for instance for: "/summon Skeleton x y z {DATA}"

#######################################################################
# +-----------------------------------------------------------------+ #
# |                            BO3 checks                           | #
# +-----------------------------------------------------------------+ #
#######################################################################

# Require a condition at a certain location in order for the BO3 to be spawned.
# BlockCheck(x,y,z,BlockName[,BlockName[,...]]) - one of the blocks must be at the location
# BlockCheckNot(x,y,z,BlockName[,BlockName[,...]]) - all the blocks must not be at the location
# LightCheck(x,y,z,minLightLevel,maxLightLevel) - light must be between min and max (inclusive)

# You can use "Solid" as a BlockName for matching all solid blocks or "All" to match all blocks that aren't air.

# Examples:
#   BlockCheck(0,-1,0,GRASS,DIRT)  Require grass or dirt just below the object
#   BlockCheck(0,-1,0,Solid)       Require any solid block just below the object
#   BlockCheck(0,-1,0,WOOL)        Require any type of wool just below the object
#   BlockCheck(0,-1,0,WOOL:0)      Require white wool just below the object
#   BlockCheckNot(0,-1,0,WOOL:0)   Require that there is no white wool below the object
#   LightCheck(0,0,0,0,1)          Require almost complete darkness just below the object
BlockCheck(0,10,0,AIR)
BlockCheck(0,15,0,AIR)
BlockCheck(0,5,0,solid,minecraft:water)

BlockCheck(-13,0,-13,solid)
BlockCheck(-13,0,-12,solid)
BlockCheck(-13,0,-11,solid)
BlockCheck(-13,0,-10,solid)
BlockCheck(-13,0,-9,solid)
BlockCheck(-13,0,-8,solid)
BlockCheck(-13,0,-7,solid)
BlockCheck(-13,0,-6,solid)
BlockCheck(-13,0,-5,solid)
BlockCheck(-13,0,-4,solid)
BlockCheck(-13,0,-3,solid)
BlockCheck(-13,0,-2,solid)
BlockCheck(-13,0,-1,solid)
BlockCheck(-13,0,0,solid)
BlockCheck(-13,0,1,solid)
BlockCheck(-13,0,2,solid)
BlockCheck(-13,0,3,solid)
BlockCheck(-13,0,4,solid)
BlockCheck(-13,0,5,solid)
BlockCheck(-13,0,6,solid)
BlockCheck(-13,0,7,solid)
BlockCheck(-13,0,8,solid)
BlockCheck(-13,0,9,solid)
BlockCheck(-13,0,10,solid)
BlockCheck(-13,0,11,solid)
BlockCheck(-13,0,12,solid)
BlockCheck(-13,0,13,solid)
BlockCheck(-12,0,-13,solid)
BlockCheck(-12,0,-12,solid)
BlockCheck(-12,0,-11,solid)
BlockCheck(-12,0,-10,solid)
BlockCheck(-12,0,-9,solid)
BlockCheck(-12,0,-8,solid)
BlockCheck(-12,0,-7,solid)
BlockCheck(-12,0,-6,solid)
BlockCheck(-12,0,-5,solid)
BlockCheck(-12,0,-4,solid)
BlockCheck(-12,0,-3,solid)
BlockCheck(-12,0,-2,solid)
BlockCheck(-12,0,-1,solid)
BlockCheck(-12,0,0,solid)
BlockCheck(-12,0,1,solid)
BlockCheck(-12,0,2,solid)
BlockCheck(-12,0,3,solid)
BlockCheck(-12,0,4,solid)
BlockCheck(-12,0,5,solid)
BlockCheck(-12,0,6,solid)
BlockCheck(-12,0,7,solid)
BlockCheck(-12,0,8,solid)
BlockCheck(-12,0,9,solid)
BlockCheck(-12,0,10,solid)
BlockCheck(-12,0,11,solid)
BlockCheck(-12,0,12,solid)
BlockCheck(-12,0,13,solid)
BlockCheck(-11,0,-13,solid)
BlockCheck(-11,0,-12,solid)
BlockCheck(-11,0,-11,solid)
BlockCheck(-11,0,-10,solid)
BlockCheck(-11,0,-9,solid)
BlockCheck(-11,0,-8,solid)
BlockCheck(-11,0,-7,solid)
BlockCheck(-11,0,-6,solid)
BlockCheck(-11,0,-5,solid)
BlockCheck(-11,0,-4,solid)
BlockCheck(-11,0,-3,solid)
BlockCheck(-11,0,-2,solid)
BlockCheck(-11,0,-1,solid)
BlockCheck(-11,0,0,solid)
BlockCheck(-11,0,1,solid)
BlockCheck(-11,0,2,solid)
BlockCheck(-11,0,3,solid)
BlockCheck(-11,0,4,solid)
BlockCheck(-11,0,5,solid)
BlockCheck(-11,0,6,solid)
BlockCheck(-11,0,7,solid)
BlockCheck(-11,0,8,solid)
BlockCheck(-11,0,9,solid)
BlockCheck(-11,0,10,solid)
BlockCheck(-11,0,11,solid)
BlockCheck(-11,0,12,solid)
BlockCheck(-11,0,13,solid)
BlockCheck(-10,0,-13,solid)
BlockCheck(-10,0,-12,solid)
BlockCheck(-10,0,-11,solid)
BlockCheck(-10,0,-10,solid)
BlockCheck(-10,0,-9,solid)
BlockCheck(-10,0,-8,solid)
BlockCheck(-10,0,-7,solid)
BlockCheck(-10,0,-6,solid)
BlockCheck(-10,0,-5,solid)
BlockCheck(-10,0,-4,solid)
BlockCheck(-10,0,-3,solid)
BlockCheck(-10,0,-2,solid)
BlockCheck(-10,0,-1,solid)
BlockCheck(-10,0,0,solid)
BlockCheck(-10,0,1,solid)
BlockCheck(-10,0,2,solid)
BlockCheck(-10,0,3,solid)
BlockCheck(-10,0,4,solid)
BlockCheck(-10,0,5,solid)
BlockCheck(-10,0,6,solid)
BlockCheck(-10,0,7,solid)
BlockCheck(-10,0,8,solid)
BlockCheck(-10,0,9,solid)
BlockCheck(-10,0,10,solid)
BlockCheck(-10,0,11,solid)
BlockCheck(-10,0,12,solid)
BlockCheck(-10,0,13,solid)
BlockCheck(-9,0,-13,solid)
BlockCheck(-9,0,-12,solid)
BlockCheck(-9,0,-11,solid)
BlockCheck(-9,0,-10,solid)
BlockCheck(-9,0,-9,solid)
BlockCheck(-9,0,-8,solid)
BlockCheck(-9,0,-7,solid)
BlockCheck(-9,0,-6,solid)
BlockCheck(-9,0,-5,solid)
BlockCheck(-9,0,-4,solid)
BlockCheck(-9,0,-3,solid)
BlockCheck(-9,0,-2,solid)
BlockCheck(-9,0,-1,solid)
BlockCheck(-9,0,0,solid)
BlockCheck(-9,0,1,solid)
BlockCheck(-9,0,2,solid)
BlockCheck(-9,0,3,solid)
BlockCheck(-9,0,4,solid)
BlockCheck(-9,0,5,solid)
BlockCheck(-9,0,6,solid)
BlockCheck(-9,0,7,solid)
BlockCheck(-9,0,8,solid)
BlockCheck(-9,0,9,solid)
BlockCheck(-9,0,10,solid)
BlockCheck(-9,0,11,solid)
BlockCheck(-9,0,12,solid)
BlockCheck(-9,0,13,solid)
BlockCheck(-8,0,-13,solid)
BlockCheck(-8,0,-12,solid)
BlockCheck(-8,0,-11,solid)
BlockCheck(-8,0,-10,solid)
BlockCheck(-8,0,-9,solid)
BlockCheck(-8,0,-8,solid)
BlockCheck(-8,0,-7,solid)
BlockCheck(-8,0,-6,solid)
BlockCheck(-8,0,-5,solid)
BlockCheck(-8,0,-4,solid)
BlockCheck(-8,0,-3,solid)
BlockCheck(-8,0,-2,solid)
BlockCheck(-8,0,-1,solid)
BlockCheck(-8,0,0,solid)
BlockCheck(-8,0,1,solid)
BlockCheck(-8,0,2,solid)
BlockCheck(-8,0,3,solid)
BlockCheck(-8,0,4,solid)
BlockCheck(-8,0,5,solid)
BlockCheck(-8,0,6,solid)
BlockCheck(-8,0,7,solid)
BlockCheck(-8,0,8,solid)
BlockCheck(-8,0,9,solid)
BlockCheck(-8,0,10,solid)
BlockCheck(-8,0,11,solid)
BlockCheck(-8,0,12,solid)
BlockCheck(-8,0,13,solid)
BlockCheck(-7,0,-13,solid)
BlockCheck(-7,0,-12,solid)
BlockCheck(-7,0,-11,solid)
BlockCheck(-7,0,-10,solid)
BlockCheck(-7,0,-9,solid)
BlockCheck(-7,0,-8,solid)
BlockCheck(-7,0,-7,solid)
BlockCheck(-7,0,-6,solid)
BlockCheck(-7,0,-5,solid)
BlockCheck(-7,0,-4,solid)
BlockCheck(-7,0,-3,solid)
BlockCheck(-7,0,-2,solid)
BlockCheck(-7,0,-1,solid)
BlockCheck(-7,0,0,solid)
BlockCheck(-7,0,1,solid)
BlockCheck(-7,0,2,solid)
BlockCheck(-7,0,3,solid)
BlockCheck(-7,0,4,solid)
BlockCheck(-7,0,5,solid)
BlockCheck(-7,0,6,solid)
BlockCheck(-7,0,7,solid)
BlockCheck(-7,0,8,solid)
BlockCheck(-7,0,9,solid)
BlockCheck(-7,0,10,solid)
BlockCheck(-7,0,11,solid)
BlockCheck(-7,0,12,solid)
BlockCheck(-7,0,13,solid)
BlockCheck(-6,0,-13,solid)
BlockCheck(-6,0,-12,solid)
BlockCheck(-6,0,-11,solid)
BlockCheck(-6,0,-10,solid)
BlockCheck(-6,0,-9,solid)
BlockCheck(-6,0,-8,solid)
BlockCheck(-6,0,-7,solid)
BlockCheck(-6,0,-6,solid)
BlockCheck(-6,0,-5,solid)
BlockCheck(-6,0,-4,solid)
BlockCheck(-6,0,-3,solid)
BlockCheck(-6,0,-2,solid)
BlockCheck(-6,0,-1,solid)
BlockCheck(-6,0,0,solid)
BlockCheck(-6,0,1,solid)
BlockCheck(-6,0,2,solid)
BlockCheck(-6,0,3,solid)
BlockCheck(-6,0,4,solid)
BlockCheck(-6,0,5,solid)
BlockCheck(-6,0,6,solid)
BlockCheck(-6,0,7,solid)
BlockCheck(-6,0,8,solid)
BlockCheck(-6,0,9,solid)
BlockCheck(-6,0,10,solid)
BlockCheck(-6,0,11,solid)
BlockCheck(-6,0,12,solid)
BlockCheck(-6,0,13,solid)
BlockCheck(-5,0,-13,solid)
BlockCheck(-5,0,-12,solid)
BlockCheck(-5,0,-11,solid)
BlockCheck(-5,0,-10,solid)
BlockCheck(-5,0,-9,solid)
BlockCheck(-5,0,-8,solid)
BlockCheck(-5,0,-7,solid)
BlockCheck(-5,0,-6,solid)
BlockCheck(-5,0,-5,solid)
BlockCheck(-5,0,-4,solid)
BlockCheck(-5,0,-3,solid)
BlockCheck(-5,0,-2,solid)
BlockCheck(-5,0,-1,solid)
BlockCheck(-5,0,0,solid)
BlockCheck(-5,0,1,solid)
BlockCheck(-5,0,2,solid)
BlockCheck(-5,0,3,solid)
BlockCheck(-5,0,4,solid)
BlockCheck(-5,0,5,solid)
BlockCheck(-5,0,6,solid)
BlockCheck(-5,0,7,solid)
BlockCheck(-5,0,8,solid)
BlockCheck(-5,0,9,solid)
BlockCheck(-5,0,10,solid)
BlockCheck(-5,0,11,solid)
BlockCheck(-5,0,12,solid)
BlockCheck(-5,0,13,solid)
BlockCheck(-4,0,-13,solid)
BlockCheck(-4,0,-12,solid)
BlockCheck(-4,0,-11,solid)
BlockCheck(-4,0,-10,solid)
BlockCheck(-4,0,-9,solid)
BlockCheck(-4,0,-8,solid)
BlockCheck(-4,0,-7,solid)
BlockCheck(-4,0,-6,solid)
BlockCheck(-4,0,-5,solid)
BlockCheck(-4,0,-4,solid)
BlockCheck(-4,0,-3,solid)
BlockCheck(-4,0,-2,solid)
BlockCheck(-4,0,-1,solid)
BlockCheck(-4,0,0,solid)
BlockCheck(-4,0,1,solid)
BlockCheck(-4,0,2,solid)
BlockCheck(-4,0,3,solid)
BlockCheck(-4,0,4,solid)
BlockCheck(-4,0,5,solid)
BlockCheck(-4,0,6,solid)
BlockCheck(-4,0,7,solid)
BlockCheck(-4,0,8,solid)
BlockCheck(-4,0,9,solid)
BlockCheck(-4,0,10,solid)
BlockCheck(-4,0,11,solid)
BlockCheck(-4,0,12,solid)
BlockCheck(-4,0,13,solid)
BlockCheck(-3,0,-13,solid)
BlockCheck(-3,0,-12,solid)
BlockCheck(-3,0,-11,solid)
BlockCheck(-3,0,-10,solid)
BlockCheck(-3,0,-9,solid)
BlockCheck(-3,0,-8,solid)
BlockCheck(-3,0,-7,solid)
BlockCheck(-3,0,-6,solid)
BlockCheck(-3,0,-5,solid)
BlockCheck(-3,0,-4,solid)
BlockCheck(-3,0,-3,solid)
BlockCheck(-3,0,-2,solid)
BlockCheck(-3,0,-1,solid)
BlockCheck(-3,0,0,solid)
BlockCheck(-3,0,1,solid)
BlockCheck(-3,0,2,solid)
BlockCheck(-3,0,3,solid)
BlockCheck(-3,0,4,solid)
BlockCheck(-3,0,5,solid)
BlockCheck(-3,0,6,solid)
BlockCheck(-3,0,7,solid)
BlockCheck(-3,0,8,solid)
BlockCheck(-3,0,9,solid)
BlockCheck(-3,0,10,solid)
BlockCheck(-3,0,11,solid)
BlockCheck(-3,0,12,solid)
BlockCheck(-3,0,13,solid)
BlockCheck(-2,0,-13,solid)
BlockCheck(-2,0,-12,solid)
BlockCheck(-2,0,-11,solid)
BlockCheck(-2,0,-10,solid)
BlockCheck(-2,0,-9,solid)
BlockCheck(-2,0,-8,solid)
BlockCheck(-2,0,-7,solid)
BlockCheck(-2,0,-6,solid)
BlockCheck(-2,0,-5,solid)
BlockCheck(-2,0,-4,solid)
BlockCheck(-2,0,-3,solid)
BlockCheck(-2,0,-2,solid)
BlockCheck(-2,0,-1,solid)
BlockCheck(-2,0,0,solid)
BlockCheck(-2,0,1,solid)
BlockCheck(-2,0,2,solid)
BlockCheck(-2,0,3,solid)
BlockCheck(-2,0,4,solid)
BlockCheck(-2,0,5,solid)
BlockCheck(-2,0,6,solid)
BlockCheck(-2,0,7,solid)
BlockCheck(-2,0,8,solid)
BlockCheck(-2,0,9,solid)
BlockCheck(-2,0,10,solid)
BlockCheck(-2,0,11,solid)
BlockCheck(-2,0,12,solid)
BlockCheck(-2,0,13,solid)
BlockCheck(-1,0,-13,solid)
BlockCheck(-1,0,-12,solid)
BlockCheck(-1,0,-11,solid)
BlockCheck(-1,0,-10,solid)
BlockCheck(-1,0,-9,solid)
BlockCheck(-1,0,-8,solid)
BlockCheck(-1,0,-7,solid)
BlockCheck(-1,0,-6,solid)
BlockCheck(-1,0,-5,solid)
BlockCheck(-1,0,-4,solid)
BlockCheck(-1,0,-3,solid)
BlockCheck(-1,0,-2,solid)
BlockCheck(-1,0,-1,solid)
BlockCheck(-1,0,0,solid)
BlockCheck(-1,0,1,solid)
BlockCheck(-1,0,2,solid)
BlockCheck(-1,0,3,solid)
BlockCheck(-1,0,4,solid)
BlockCheck(-1,0,5,solid)
BlockCheck(-1,0,6,solid)
BlockCheck(-1,0,7,solid)
BlockCheck(-1,0,8,solid)
BlockCheck(-1,0,9,solid)
BlockCheck(-1,0,10,solid)
BlockCheck(-1,0,11,solid)
BlockCheck(-1,0,12,solid)
BlockCheck(-1,0,13,solid)
BlockCheck(0,0,-13,solid)
BlockCheck(0,0,-12,solid)
BlockCheck(0,0,-11,solid)
BlockCheck(0,0,-10,solid)
BlockCheck(0,0,-9,solid)
BlockCheck(0,0,-8,solid)
BlockCheck(0,0,-7,solid)
BlockCheck(0,0,-6,solid)
BlockCheck(0,0,-5,solid)
BlockCheck(0,0,-4,solid)
BlockCheck(0,0,-3,solid)
BlockCheck(0,0,-2,solid)
BlockCheck(0,0,-1,solid)
BlockCheck(0,0,0,solid)
BlockCheck(0,0,1,solid)
BlockCheck(0,0,2,solid)
BlockCheck(0,0,3,solid)
BlockCheck(0,0,4,solid)
BlockCheck(0,0,5,solid)
BlockCheck(0,0,6,solid)
BlockCheck(0,0,7,solid)
BlockCheck(0,0,8,solid)
BlockCheck(0,0,9,solid)
BlockCheck(0,0,10,solid)
BlockCheck(0,0,11,solid)
BlockCheck(0,0,12,solid)
BlockCheck(0,0,13,solid)
BlockCheck(1,0,-13,solid)
BlockCheck(1,0,-12,solid)
BlockCheck(1,0,-11,solid)
BlockCheck(1,0,-10,solid)
BlockCheck(1,0,-9,solid)
BlockCheck(1,0,-8,solid)
BlockCheck(1,0,-7,solid)
BlockCheck(1,0,-6,solid)
BlockCheck(1,0,-5,solid)
BlockCheck(1,0,-4,solid)
BlockCheck(1,0,-3,solid)
BlockCheck(1,0,-2,solid)
BlockCheck(1,0,-1,solid)
BlockCheck(1,0,0,solid)
BlockCheck(1,0,1,solid)
BlockCheck(1,0,2,solid)
BlockCheck(1,0,3,solid)
BlockCheck(1,0,4,solid)
BlockCheck(1,0,5,solid)
BlockCheck(1,0,6,solid)
BlockCheck(1,0,7,solid)
BlockCheck(1,0,8,solid)
BlockCheck(1,0,9,solid)
BlockCheck(1,0,10,solid)
BlockCheck(1,0,11,solid)
BlockCheck(1,0,12,solid)
BlockCheck(1,0,13,solid)
BlockCheck(2,0,-13,solid)
BlockCheck(2,0,-12,solid)
BlockCheck(2,0,-11,solid)
BlockCheck(2,0,-10,solid)
BlockCheck(2,0,-9,solid)
BlockCheck(2,0,-8,solid)
BlockCheck(2,0,-7,solid)
BlockCheck(2,0,-6,solid)
BlockCheck(2,0,-5,solid)
BlockCheck(2,0,-4,solid)
BlockCheck(2,0,-3,solid)
BlockCheck(2,0,-2,solid)
BlockCheck(2,0,-1,solid)
BlockCheck(2,0,0,solid)
BlockCheck(2,0,1,solid)
BlockCheck(2,0,2,solid)
BlockCheck(2,0,3,solid)
BlockCheck(2,0,4,solid)
BlockCheck(2,0,5,solid)
BlockCheck(2,0,6,solid)
BlockCheck(2,0,7,solid)
BlockCheck(2,0,8,solid)
BlockCheck(2,0,9,solid)
BlockCheck(2,0,10,solid)
BlockCheck(2,0,11,solid)
BlockCheck(2,0,12,solid)
BlockCheck(2,0,13,solid)
BlockCheck(3,0,-13,solid)
BlockCheck(3,0,-12,solid)
BlockCheck(3,0,-11,solid)
BlockCheck(3,0,-10,solid)
BlockCheck(3,0,-9,solid)
BlockCheck(3,0,-8,solid)
BlockCheck(3,0,-7,solid)
BlockCheck(3,0,-6,solid)
BlockCheck(3,0,-5,solid)
BlockCheck(3,0,-4,solid)
BlockCheck(3,0,-3,solid)
BlockCheck(3,0,-2,solid)
BlockCheck(3,0,-1,solid)
BlockCheck(3,0,0,solid)
BlockCheck(3,0,1,solid)
BlockCheck(3,0,2,solid)
BlockCheck(3,0,3,solid)
BlockCheck(3,0,4,solid)
BlockCheck(3,0,5,solid)
BlockCheck(3,0,6,solid)
BlockCheck(3,0,7,solid)
BlockCheck(3,0,8,solid)
BlockCheck(3,0,9,solid)
BlockCheck(3,0,10,solid)
BlockCheck(3,0,11,solid)
BlockCheck(3,0,12,solid)
BlockCheck(3,0,13,solid)
BlockCheck(4,0,-13,solid)
BlockCheck(4,0,-12,solid)
BlockCheck(4,0,-11,solid)
BlockCheck(4,0,-10,solid)
BlockCheck(4,0,-9,solid)
BlockCheck(4,0,-8,solid)
BlockCheck(4,0,-7,solid)
BlockCheck(4,0,-6,solid)
BlockCheck(4,0,-5,solid)
BlockCheck(4,0,-4,solid)
BlockCheck(4,0,-3,solid)
BlockCheck(4,0,-2,solid)
BlockCheck(4,0,-1,solid)
BlockCheck(4,0,0,solid)
BlockCheck(4,0,1,solid)
BlockCheck(4,0,2,solid)
BlockCheck(4,0,3,solid)
BlockCheck(4,0,4,solid)
BlockCheck(4,0,5,solid)
BlockCheck(4,0,6,solid)
BlockCheck(4,0,7,solid)
BlockCheck(4,0,8,solid)
BlockCheck(4,0,9,solid)
BlockCheck(4,0,10,solid)
BlockCheck(4,0,11,solid)
BlockCheck(4,0,12,solid)
BlockCheck(4,0,13,solid)
BlockCheck(5,0,-13,solid)
BlockCheck(5,0,-12,solid)
BlockCheck(5,0,-11,solid)
BlockCheck(5,0,-10,solid)
BlockCheck(5,0,-9,solid)
BlockCheck(5,0,-8,solid)
BlockCheck(5,0,-7,solid)
BlockCheck(5,0,-6,solid)
BlockCheck(5,0,-5,solid)
BlockCheck(5,0,-4,solid)
BlockCheck(5,0,-3,solid)
BlockCheck(5,0,-2,solid)
BlockCheck(5,0,-1,solid)
BlockCheck(5,0,0,solid)
BlockCheck(5,0,1,solid)
BlockCheck(5,0,2,solid)
BlockCheck(5,0,3,solid)
BlockCheck(5,0,4,solid)
BlockCheck(5,0,5,solid)
BlockCheck(5,0,6,solid)
BlockCheck(5,0,7,solid)
BlockCheck(5,0,8,solid)
BlockCheck(5,0,9,solid)
BlockCheck(5,0,10,solid)
BlockCheck(5,0,11,solid)
BlockCheck(5,0,12,solid)
BlockCheck(5,0,13,solid)
BlockCheck(6,0,-13,solid)
BlockCheck(6,0,-12,solid)
BlockCheck(6,0,-11,solid)
BlockCheck(6,0,-10,solid)
BlockCheck(6,0,-9,solid)
BlockCheck(6,0,-8,solid)
BlockCheck(6,0,-7,solid)
BlockCheck(6,0,-6,solid)
BlockCheck(6,0,-5,solid)
BlockCheck(6,0,-4,solid)
BlockCheck(6,0,-3,solid)
BlockCheck(6,0,-2,solid)
BlockCheck(6,0,-1,solid)
BlockCheck(6,0,0,solid)
BlockCheck(6,0,1,solid)
BlockCheck(6,0,2,solid)
BlockCheck(6,0,3,solid)
BlockCheck(6,0,4,solid)
BlockCheck(6,0,5,solid)
BlockCheck(6,0,6,solid)
BlockCheck(6,0,7,solid)
BlockCheck(6,0,8,solid)
BlockCheck(6,0,9,solid)
BlockCheck(6,0,10,solid)
BlockCheck(6,0,11,solid)
BlockCheck(6,0,12,solid)
BlockCheck(6,0,13,solid)
BlockCheck(7,0,-13,solid)
BlockCheck(7,0,-12,solid)
BlockCheck(7,0,-11,solid)
BlockCheck(7,0,-10,solid)
BlockCheck(7,0,-9,solid)
BlockCheck(7,0,-8,solid)
BlockCheck(7,0,-7,solid)
BlockCheck(7,0,-6,solid)
BlockCheck(7,0,-5,solid)
BlockCheck(7,0,-4,solid)
BlockCheck(7,0,-3,solid)
BlockCheck(7,0,-2,solid)
BlockCheck(7,0,-1,solid)
BlockCheck(7,0,0,solid)
BlockCheck(7,0,1,solid)
BlockCheck(7,0,2,solid)
BlockCheck(7,0,3,solid)
BlockCheck(7,0,4,solid)
BlockCheck(7,0,5,solid)
BlockCheck(7,0,6,solid)
BlockCheck(7,0,7,solid)
BlockCheck(7,0,8,solid)
BlockCheck(7,0,9,solid)
BlockCheck(7,0,10,solid)
BlockCheck(7,0,11,solid)
BlockCheck(7,0,12,solid)
BlockCheck(7,0,13,solid)
BlockCheck(8,0,-13,solid)
BlockCheck(8,0,-12,solid)
BlockCheck(8,0,-11,solid)
BlockCheck(8,0,-10,solid)
BlockCheck(8,0,-9,solid)
BlockCheck(8,0,-8,solid)
BlockCheck(8,0,-7,solid)
BlockCheck(8,0,-6,solid)
BlockCheck(8,0,-5,solid)
BlockCheck(8,0,-4,solid)
BlockCheck(8,0,-3,solid)
BlockCheck(8,0,-2,solid)
BlockCheck(8,0,-1,solid)
BlockCheck(8,0,0,solid)
BlockCheck(8,0,1,solid)
BlockCheck(8,0,2,solid)
BlockCheck(8,0,3,solid)
BlockCheck(8,0,4,solid)
BlockCheck(8,0,5,solid)
BlockCheck(8,0,6,solid)
BlockCheck(8,0,7,solid)
BlockCheck(8,0,8,solid)
BlockCheck(8,0,9,solid)
BlockCheck(8,0,10,solid)
BlockCheck(8,0,11,solid)
BlockCheck(8,0,12,solid)
BlockCheck(8,0,13,solid)
BlockCheck(9,0,-13,solid)
BlockCheck(9,0,-12,solid)
BlockCheck(9,0,-11,solid)
BlockCheck(9,0,-10,solid)
BlockCheck(9,0,-9,solid)
BlockCheck(9,0,-8,solid)
BlockCheck(9,0,-7,solid)
BlockCheck(9,0,-6,solid)
BlockCheck(9,0,-5,solid)
BlockCheck(9,0,-4,solid)
BlockCheck(9,0,-3,solid)
BlockCheck(9,0,-2,solid)
BlockCheck(9,0,-1,solid)
BlockCheck(9,0,0,solid)
BlockCheck(9,0,1,solid)
BlockCheck(9,0,2,solid)
BlockCheck(9,0,3,solid)
BlockCheck(9,0,4,solid)
BlockCheck(9,0,5,solid)
BlockCheck(9,0,6,solid)
BlockCheck(9,0,7,solid)
BlockCheck(9,0,8,solid)
BlockCheck(9,0,9,solid)
BlockCheck(9,0,10,solid)
BlockCheck(9,0,11,solid)
BlockCheck(10,0,-12,solid)
BlockCheck(10,0,-11,solid)
BlockCheck(10,0,-10,solid)
BlockCheck(10,0,-9,solid)
BlockCheck(10,0,-8,solid)
BlockCheck(10,0,-7,solid)
BlockCheck(10,0,-6,solid)
BlockCheck(10,0,-5,solid)
BlockCheck(10,0,-4,solid)
BlockCheck(10,0,-3,solid)
BlockCheck(10,0,-2,solid)
BlockCheck(10,0,-1,solid)
BlockCheck(10,0,0,solid)
BlockCheck(10,0,1,solid)
BlockCheck(10,0,2,solid)
BlockCheck(10,0,3,solid)
BlockCheck(10,0,4,solid)
BlockCheck(10,0,5,solid)
BlockCheck(10,0,6,solid)
BlockCheck(10,0,7,solid)
BlockCheck(10,0,8,solid)
BlockCheck(10,0,9,solid)
BlockCheck(10,0,10,solid)
BlockCheck(10,0,11,solid)
BlockCheck(10,0,12,solid)
BlockCheck(10,0,13,solid)
BlockCheck(11,0,-13,solid)
BlockCheck(11,0,-12,solid)
BlockCheck(11,0,-11,solid)
BlockCheck(11,0,-10,solid)
BlockCheck(11,0,-9,solid)
BlockCheck(11,0,-8,solid)
BlockCheck(11,0,-7,solid)
BlockCheck(11,0,-6,solid)
BlockCheck(11,0,-5,solid)
BlockCheck(11,0,-4,solid)
BlockCheck(11,0,-3,solid)
BlockCheck(11,0,-2,solid)
BlockCheck(11,0,-1,solid)
BlockCheck(11,0,0,solid)
BlockCheck(11,0,1,solid)
BlockCheck(11,0,2,solid)
BlockCheck(11,0,3,solid)
BlockCheck(11,0,4,solid)
BlockCheck(11,0,5,solid)
BlockCheck(11,0,6,solid)
BlockCheck(11,0,7,solid)
BlockCheck(11,0,8,solid)
BlockCheck(11,0,9,solid)
BlockCheck(11,0,10,solid)
BlockCheck(11,0,11,solid)
BlockCheck(11,0,12,solid)
BlockCheck(11,0,13,solid)
BlockCheck(12,0,-13,solid)
BlockCheck(12,0,-12,solid)
BlockCheck(12,0,-11,solid)
BlockCheck(12,0,-10,solid)
BlockCheck(12,0,-9,solid)
BlockCheck(12,0,-8,solid)
BlockCheck(12,0,-7,solid)
BlockCheck(12,0,-6,solid)
BlockCheck(12,0,-5,solid)
BlockCheck(12,0,-4,solid)
BlockCheck(12,0,-3,solid)
BlockCheck(12,0,-2,solid)
BlockCheck(12,0,-1,solid)
BlockCheck(12,0,0,solid)
BlockCheck(12,0,1,solid)
BlockCheck(12,0,2,solid)
BlockCheck(12,0,3,solid)
BlockCheck(12,0,4,solid)
BlockCheck(12,0,5,solid)
BlockCheck(12,0,6,solid)
BlockCheck(12,0,7,solid)
BlockCheck(12,0,8,solid)
BlockCheck(12,0,9,solid)
BlockCheck(12,0,10,solid)
BlockCheck(12,0,11,solid)
BlockCheck(12,0,12,solid)
BlockCheck(12,0,13,solid)
BlockCheck(13,0,-13,solid)
BlockCheck(13,0,-12,solid)
BlockCheck(13,0,-11,solid)
BlockCheck(13,0,-10,solid)
BlockCheck(13,0,-9,solid)
BlockCheck(13,0,-8,solid)
BlockCheck(13,0,-7,solid)
BlockCheck(13,0,-6,solid)
BlockCheck(13,0,-5,solid)
BlockCheck(13,0,-4,solid)
BlockCheck(13,0,-3,solid)
BlockCheck(13,0,-2,solid)
BlockCheck(13,0,-1,solid)
BlockCheck(13,0,0,solid)
BlockCheck(13,0,1,solid)
BlockCheck(13,0,2,solid)
BlockCheck(13,0,3,solid)
BlockCheck(13,0,4,solid)
BlockCheck(13,0,5,solid)
BlockCheck(13,0,6,solid)
BlockCheck(13,0,7,solid)
BlockCheck(13,0,8,solid)
BlockCheck(13,0,9,solid)
BlockCheck(13,0,10,solid)
BlockCheck(13,0,11,solid)
BlockCheck(13,0,12,solid)
BlockCheck(13,0,13,solid)


