#######################################################################
# +-----------------------------------------------------------------+ #
# |                            BO3 object                           | #
# +-----------------------------------------------------------------+ #
#######################################################################

# The descriptions in this file are accurate only for TerrainControl and OTG.
# For MCW and OTG+ these descriptions are only accurate if the BO3 is used as a CustomObject.
# MCW and OTG+ completely reimplemented CustomStructure, check the MCW/OTG+ documentation for more information.

# This is the config file of a custom object.
# If you add this object correctly to your BiomeConfigs, it will spawn in the world.

# This is the creator of this BO3 object
Author: Unknown

# A short description of this BO3 object
Description: This BO3 was converted from a schematic using OTGEdit. The author and description information of the schematic could not be found. If you know who the author of the schematic is then please add this information.

# The BO3 version, don't change this! It can be used by external applications to do a version check.
Version: 3

# The settings mode, WriteAll, WriteWithoutComments or WriteDisable. See WorldConfig.
SettingsMode: WriteDisable

#######################################################################
# +-----------------------------------------------------------------+ #
# |                          Main settings                          | #
# +-----------------------------------------------------------------+ #
#######################################################################

# This needs to be set to true to spawn the object in the Tree and Sapling resources.
Tree: true

# The frequency of the BO3 from 1 to 200. Tries this many times to spawn this BO3 when using the CustomObject(...) resource.
# Ignored by Tree(..), Sapling(..) and CustomStructure(..)
Frequency: 40

# The rarity of the BO3 from 0 to 100. Each spawn attempt has rarity% chance to succeed when using the CustomObject(...) resource.
# Ignored by Tree(..), Sapling(..) and CustomStructure(..)
Rarity: 100.0

# If you set this to true, the BO3 will be placed with a random rotation.
RotateRandomly: true

# The spawn height of the BO3 - randomY, highestBlock or highestSolidBlock.
SpawnHeight: randomY

# The height limits for the BO3.
MinHeight: 0

MaxHeight: 254

# Objects can have other objects attached to it: branches. Branches can also
# have branches attached to it, which can also have branches, etc. This is the
# maximum branch depth for this objects.
MaxBranchDepth: 10

# When spawned with the UseWorld keyword, this BO3 should NOT spawn in the following biomes.
# If you writer.write the BO3 name directly in the BiomeConfigs, this will be ignored.
ExcludedBiomes: All

# To optimise this BO3 for faster loading times you can use Notepad++ to find/replace comments and abbreviate things.
# Notepad++ find/replace with regex:
# Find: ^[#;].* replace to nothing removes all lines starting with # 
# Find: ^\s*$ replace to nothing removes most empty lines 
# Notepad++ find/replace without regex:
# *Warning: This will only work for OTG 1.10.2 v21 / OTG 1.11.2 v6 or higher. B( is not recognised by lower versions.
# Find: Block( replace to B(

#######################################################################
# +-----------------------------------------------------------------+ #
# |                      Source block settings                      | #
# +-----------------------------------------------------------------+ #
#######################################################################

# The block(s) the BO3 should spawn in.
SourceBlocks: AIR, minecraft:water

# The maximum percentage of the BO3 that can be outside the SourceBlock.
# The BO3 won't be placed on a location with more blocks outside the SourceBlock than this percentage.
MaxPercentageOutsideSourceBlock: 100

# What to do when a block is about to be placed outside the SourceBlock? (dontPlace, placeAnyway)
OutsideSourceBlock: placeAnyway

#######################################################################
# +-----------------------------------------------------------------+ #
# |                              Blocks                             | #
# +-----------------------------------------------------------------+ #
#######################################################################

# All the blocks used in the BO3 are listed here. Possible blocks:
# Block(x,y,z,id[.data][,nbtfile.nbt) or B(x,y,z,id[.data][,nbtfile.nbt)
# RandomBlock(x,y,z,id[:data][,nbtfile.nbt],chance[,id[:data][,nbtfile.nbt],chance[,...]])
# So RandomBlock(0,0,0,CHEST,chest.nbt,50,CHEST,anotherchest.nbt,100) will spawn a chest at
# the BO3 origin, and give it a 50% chance to have the contents of chest.nbt, or, if that
# fails, a 100% percent chance to have the contents of anotherchest.nbt.

Block(-10,11,3,24)
Block(-10,11,4,24)
Block(-10,11,5,24)
Block(-10,11,6,24)
Block(-10,12,4,24)
Block(-10,12,5,24)
Block(-10,13,4,24)
Block(-10,13,5,24)
Block(-9,10,0,24)
Block(-9,10,1,24)
Block(-9,10,2,24)
Block(-9,10,3,24)
Block(-9,10,4,24)
Block(-9,10,5,24)
Block(-9,11,1,24)
Block(-9,11,2,24)
Block(-9,11,3,24)
Block(-9,11,4,24)
Block(-9,11,5,24)
Block(-9,11,6,24)
Block(-9,11,7,24)
Block(-9,11,8,24)
Block(-9,11,9,24)
Block(-9,12,2,24)
Block(-9,12,3,24)
Block(-9,12,4,24)
Block(-9,12,5,24)
Block(-9,12,6,24)
Block(-9,12,7,24)
Block(-9,12,8,24)
Block(-9,13,2,24)
Block(-9,13,3,24)
Block(-9,13,4,24)
Block(-9,13,5,24)
Block(-9,13,6,24)
Block(-9,13,7,24)
Block(-9,14,3,24)
Block(-9,14,4,24)
Block(-9,14,5,24)
Block(-9,14,6,24)
Block(-9,14,7,24)
Block(-9,15,3,24)
Block(-9,15,4,24)
Block(-9,15,5,24)
Block(-9,15,6,24)
Block(-9,16,4,24)
Block(-9,16,5,24)
Block(-9,16,6,24)
Block(-9,17,4,24)
Block(-9,17,5,24)
Block(-9,18,4,24)
Block(-9,18,5,24)
Block(-9,19,4,24)
Block(-9,19,5,24)
Block(-9,20,4,24)
Block(-9,21,4,24)
Block(-9,22,4,24)
Block(-9,23,3,24)
Block(-9,24,3,24)
Block(-9,25,3,24)
Block(-9,27,1,24)
Block(-9,27,2,24)
Block(-9,28,0,24)
Block(-9,28,1,24)
Block(-9,29,-1,24)
Block(-9,29,0,24)
Block(-9,29,1,24)
Block(-9,30,-2,24)
Block(-9,30,-1,24)
Block(-9,30,0,24)
Block(-9,30,1,24)
Block(-9,31,-3,24)
Block(-9,31,-2,24)
Block(-9,31,-1,24)
Block(-8,9,0,24)
Block(-8,9,1,24)
Block(-8,9,2,24)
Block(-8,10,0,24)
Block(-8,10,1,24)
Block(-8,10,2,24)
Block(-8,10,3,24)
Block(-8,10,4,24)
Block(-8,10,5,24)
Block(-8,10,6,24)
Block(-8,10,7,24)
Block(-8,10,8,24)
Block(-8,11,-1,24)
Block(-8,11,0,24)
Block(-8,11,1,24)
Block(-8,11,2,24)
Block(-8,11,3,24)
Block(-8,11,4,24)
Block(-8,11,5,24)
Block(-8,11,6,24)
Block(-8,11,7,24)
Block(-8,11,8,24)
Block(-8,11,9,24)
Block(-8,11,10,24)
Block(-8,11,11,24)
Block(-8,12,-1,24)
Block(-8,12,0,24)
Block(-8,12,1,24)
Block(-8,12,2,24)
Block(-8,12,3,24)
Block(-8,12,4,24)
Block(-8,12,5,24)
Block(-8,12,6,24)
Block(-8,12,7,24)
Block(-8,12,8,24)
Block(-8,12,9,24)
Block(-8,12,10,24)
Block(-8,13,0,24)
Block(-8,13,1,24)
Block(-8,13,2,24)
Block(-8,13,3,24)
Block(-8,13,4,24)
Block(-8,13,5,24)
Block(-8,13,6,24)
Block(-8,13,7,24)
Block(-8,13,8,24)
Block(-8,13,9,24)
Block(-8,13,10,24)
Block(-8,14,0,24)
Block(-8,14,1,24)
Block(-8,14,2,24)
Block(-8,14,3,24)
Block(-8,14,4,24)
Block(-8,14,5,24)
Block(-8,14,6,24)
Block(-8,14,7,24)
Block(-8,14,8,24)
Block(-8,14,9,24)
Block(-8,15,1,24)
Block(-8,15,2,24)
Block(-8,15,3,24)
Block(-8,15,4,24)
Block(-8,15,5,24)
Block(-8,15,6,24)
Block(-8,15,7,24)
Block(-8,15,8,24)
Block(-8,15,9,24)
Block(-8,16,1,24)
Block(-8,16,2,24)
Block(-8,16,3,24)
Block(-8,16,4,24)
Block(-8,16,5,24)
Block(-8,16,6,24)
Block(-8,16,7,24)
Block(-8,16,8,24)
Block(-8,17,2,24)
Block(-8,17,3,24)
Block(-8,17,4,24)
Block(-8,17,5,24)
Block(-8,17,6,24)
Block(-8,17,7,24)
Block(-8,17,8,24)
Block(-8,18,2,24)
Block(-8,18,3,24)
Block(-8,18,4,24)
Block(-8,18,5,24)
Block(-8,18,6,24)
Block(-8,18,7,24)
Block(-8,18,8,24)
Block(-8,19,2,24)
Block(-8,19,3,24)
Block(-8,19,4,24)
Block(-8,19,5,24)
Block(-8,19,6,24)
Block(-8,19,7,24)
Block(-8,20,2,24)
Block(-8,20,3,24)
Block(-8,20,4,24)
Block(-8,20,5,24)
Block(-8,20,6,24)
Block(-8,20,7,24)
Block(-8,21,2,24)
Block(-8,21,3,24)
Block(-8,21,4,24)
Block(-8,21,5,24)
Block(-8,21,6,24)
Block(-8,21,7,24)
Block(-8,22,2,24)
Block(-8,22,3,24)
Block(-8,22,4,24)
Block(-8,22,5,24)
Block(-8,22,6,24)
Block(-8,23,2,24)
Block(-8,23,3,24)
Block(-8,23,4,24)
Block(-8,23,5,24)
Block(-8,23,6,24)
Block(-8,24,2,24)
Block(-8,24,3,24)
Block(-8,24,4,24)
Block(-8,24,5,24)
Block(-8,24,6,24)
Block(-8,25,1,24)
Block(-8,25,2,24)
Block(-8,25,3,24)
Block(-8,25,4,24)
Block(-8,25,5,24)
Block(-8,26,0,24)
Block(-8,26,1,24)
Block(-8,26,2,24)
Block(-8,26,3,24)
Block(-8,26,4,24)
Block(-8,27,-1,24)
Block(-8,27,0,24)
Block(-8,27,1,24)
Block(-8,27,2,24)
Block(-8,27,3,24)
Block(-8,27,4,24)
Block(-8,28,-3,24)
Block(-8,28,-2,24)
Block(-8,28,-1,24)
Block(-8,28,0,24)
Block(-8,28,1,24)
Block(-8,28,2,24)
Block(-8,28,3,24)
Block(-8,29,-5,24)
Block(-8,29,-4,24)
Block(-8,29,-3,24)
Block(-8,29,-2,24)
Block(-8,29,-1,24)
Block(-8,29,0,24)
Block(-8,29,1,24)
Block(-8,29,2,24)
Block(-8,29,3,24)
Block(-8,30,-5,24)
Block(-8,30,-4,24)
Block(-8,30,-3,24)
Block(-8,30,-2,24)
Block(-8,30,-1,24)
Block(-8,30,0,24)
Block(-8,30,1,24)
Block(-8,30,2,24)
Block(-8,31,-4,24)
Block(-8,31,-3,24)
Block(-8,31,-2,24)
Block(-8,31,-1,24)
Block(-8,31,0,24)
Block(-7,8,-1,24)
Block(-7,8,0,24)
Block(-7,9,-1,24)
Block(-7,9,0,24)
Block(-7,9,1,24)
Block(-7,9,2,24)
Block(-7,9,3,24)
Block(-7,9,4,24)
Block(-7,9,5,24)
Block(-7,10,-1,24)
Block(-7,10,0,24)
Block(-7,10,1,24)
Block(-7,10,2,24)
Block(-7,10,3,24)
Block(-7,10,4,24)
Block(-7,10,5,24)
Block(-7,10,6,24)
Block(-7,10,7,24)
Block(-7,10,8,24)
Block(-7,10,9,24)
Block(-7,10,10,24)
Block(-7,10,11,24)
Block(-7,10,12,24)
Block(-7,10,13,24)
Block(-7,10,14,24)
Block(-7,11,-1,24)
Block(-7,11,0,24)
Block(-7,11,1,24)
Block(-7,11,2,24)
Block(-7,11,3,24)
Block(-7,11,4,24)
Block(-7,11,5,24)
Block(-7,11,6,24)
Block(-7,11,7,24)
Block(-7,11,8,24)
Block(-7,11,9,24)
Block(-7,11,10,24)
Block(-7,11,11,24)
Block(-7,11,12,24)
Block(-7,11,13,24)
Block(-7,11,14,24)
Block(-7,12,-1,24)
Block(-7,12,0,24)
Block(-7,12,1,24)
Block(-7,12,2,24)
Block(-7,12,3,24)
Block(-7,12,4,24)
Block(-7,12,5,24)
Block(-7,12,6,24)
Block(-7,12,7,24)
Block(-7,12,8,24)
Block(-7,12,9,24)
Block(-7,12,10,24)
Block(-7,12,11,24)
Block(-7,12,12,24)
Block(-7,12,13,24)
Block(-7,13,-2,24)
Block(-7,13,-1,24)
Block(-7,13,0,24)
Block(-7,13,1,24)
Block(-7,13,2,24)
Block(-7,13,3,24)
Block(-7,13,4,24)
Block(-7,13,5,24)
Block(-7,13,6,24)
Block(-7,13,7,24)
Block(-7,13,8,24)
Block(-7,13,9,24)
Block(-7,13,10,24)
Block(-7,13,11,24)
Block(-7,13,12,24)
Block(-7,14,-2,24)
Block(-7,14,-1,24)
Block(-7,14,0,24)
Block(-7,14,1,24)
Block(-7,14,2,24)
Block(-7,14,3,24)
Block(-7,14,4,24)
Block(-7,14,5,24)
Block(-7,14,6,24)
Block(-7,14,7,24)
Block(-7,14,8,24)
Block(-7,14,9,24)
Block(-7,14,10,24)
Block(-7,14,11,24)
Block(-7,15,-2,24)
Block(-7,15,-1,24)
Block(-7,15,0,24)
Block(-7,15,1,24)
Block(-7,15,2,24)
Block(-7,15,3,24)
Block(-7,15,4,24)
Block(-7,15,5,24)
Block(-7,15,6,24)
Block(-7,15,7,24)
Block(-7,15,8,24)
Block(-7,15,9,24)
Block(-7,15,10,24)
Block(-7,15,11,24)
Block(-7,16,-1,24)
Block(-7,16,0,24)
Block(-7,16,1,24)
Block(-7,16,2,24)
Block(-7,16,3,24)
Block(-7,16,4,24)
Block(-7,16,5,24)
Block(-7,16,6,24)
Block(-7,16,7,24)
Block(-7,16,8,24)
Block(-7,16,9,24)
Block(-7,16,10,24)
Block(-7,17,-1,24)
Block(-7,17,0,24)
Block(-7,17,1,24)
Block(-7,17,2,24)
Block(-7,17,3,24)
Block(-7,17,4,24)
Block(-7,17,5,24)
Block(-7,17,6,24)
Block(-7,17,7,24)
Block(-7,17,8,24)
Block(-7,17,9,24)
Block(-7,17,10,24)
Block(-7,18,0,24)
Block(-7,18,1,24)
Block(-7,18,2,24)
Block(-7,18,3,24)
Block(-7,18,4,24)
Block(-7,18,5,24)
Block(-7,18,6,24)
Block(-7,18,7,24)
Block(-7,18,8,24)
Block(-7,18,9,24)
Block(-7,19,0,24)
Block(-7,19,1,24)
Block(-7,19,2,24)
Block(-7,19,3,24)
Block(-7,19,4,24)
Block(-7,19,5,24)
Block(-7,19,6,24)
Block(-7,19,7,24)
Block(-7,19,8,24)
Block(-7,19,9,24)
Block(-7,20,0,24)
Block(-7,20,1,24)
Block(-7,20,2,24)
Block(-7,20,3,24)
Block(-7,20,4,24)
Block(-7,20,5,24)
Block(-7,20,6,24)
Block(-7,20,7,24)
Block(-7,20,8,24)
Block(-7,20,9,24)
Block(-7,21,0,24)
Block(-7,21,1,24)
Block(-7,21,2,24)
Block(-7,21,3,24)
Block(-7,21,4,24)
Block(-7,21,5,24)
Block(-7,21,6,24)
Block(-7,21,7,24)
Block(-7,21,8,24)
Block(-7,21,9,24)
Block(-7,22,0,24)
Block(-7,22,1,24)
Block(-7,22,2,24)
Block(-7,22,3,24)
Block(-7,22,4,24)
Block(-7,22,5,24)
Block(-7,22,6,24)
Block(-7,22,7,24)
Block(-7,22,8,24)
Block(-7,22,9,24)
Block(-7,23,-1,24)
Block(-7,23,0,24)
Block(-7,23,1,24)
Block(-7,23,2,24)
Block(-7,23,3,24)
Block(-7,23,4,24)
Block(-7,23,5,24)
Block(-7,23,6,24)
Block(-7,23,7,24)
Block(-7,23,8,24)
Block(-7,23,9,24)
Block(-7,24,-3,24)
Block(-7,24,-2,24)
Block(-7,24,-1,24)
Block(-7,24,0,24)
Block(-7,24,1,24)
Block(-7,24,2,24)
Block(-7,24,3,24)
Block(-7,24,4,24)
Block(-7,24,5,24)
Block(-7,24,6,24)
Block(-7,24,7,24)
Block(-7,24,8,24)
Block(-7,25,-4,24)
Block(-7,25,-3,24)
Block(-7,25,-2,24)
Block(-7,25,-1,24)
Block(-7,25,0,24)
Block(-7,25,1,24)
Block(-7,25,2,24)
Block(-7,25,3,24)
Block(-7,25,4,24)
Block(-7,25,5,24)
Block(-7,25,6,24)
Block(-7,25,7,24)
Block(-7,26,-6,24)
Block(-7,26,-5,24)
Block(-7,26,-4,24)
Block(-7,26,-3,24)
Block(-7,26,-2,24)
Block(-7,26,-1,24)
Block(-7,26,0,24)
Block(-7,26,1,24)
Block(-7,26,2,24)
Block(-7,26,3,24)
Block(-7,26,4,24)
Block(-7,26,5,24)
Block(-7,26,6,24)
Block(-7,27,-7,24)
Block(-7,27,-6,24)
Block(-7,27,-5,24)
Block(-7,27,-4,24)
Block(-7,27,-3,24)
Block(-7,27,-2,24)
Block(-7,27,-1,24)
Block(-7,27,0,24)
Block(-7,27,1,24)
Block(-7,27,2,24)
Block(-7,27,3,24)
Block(-7,27,4,24)
Block(-7,27,5,24)
Block(-7,28,-6,24)
Block(-7,28,-5,24)
Block(-7,28,-4,24)
Block(-7,28,-3,24)
Block(-7,28,-2,24)
Block(-7,28,-1,24)
Block(-7,28,0,24)
Block(-7,28,1,24)
Block(-7,28,2,24)
Block(-7,28,3,24)
Block(-7,28,4,24)
Block(-7,28,5,24)
Block(-7,29,-5,24)
Block(-7,29,-4,24)
Block(-7,29,-3,24)
Block(-7,29,-2,24)
Block(-7,29,-1,24)
Block(-7,29,0,24)
Block(-7,29,1,24)
Block(-7,29,2,24)
Block(-7,29,3,24)
Block(-7,29,4,24)
Block(-7,29,5,24)
Block(-7,30,-4,24)
Block(-7,30,-3,24)
Block(-7,30,-2,24)
Block(-7,30,-1,24)
Block(-7,30,0,24)
Block(-7,30,1,24)
Block(-7,30,2,24)
Block(-7,30,3,24)
Block(-7,31,-3,24)
Block(-7,31,-2,24)
Block(-7,31,-1,24)
Block(-7,31,0,24)
Block(-7,31,1,24)
Block(-6,8,-1,24)
Block(-6,8,0,24)
Block(-6,8,1,24)
Block(-6,8,2,24)
Block(-6,9,-1,24)
Block(-6,9,0,24)
Block(-6,9,1,24)
Block(-6,9,2,24)
Block(-6,9,3,24)
Block(-6,9,4,24)
Block(-6,9,5,24)
Block(-6,9,6,24)
Block(-6,9,7,24)
Block(-6,9,8,24)
Block(-6,10,-1,24)
Block(-6,10,0,24)
Block(-6,10,1,24)
Block(-6,10,2,24)
Block(-6,10,3,24)
Block(-6,10,4,24)
Block(-6,10,5,24)
Block(-6,10,6,24)
Block(-6,10,7,24)
Block(-6,10,8,24)
Block(-6,10,9,24)
Block(-6,10,10,24)
Block(-6,10,11,24)
Block(-6,10,12,24)
Block(-6,10,13,24)
Block(-6,10,14,24)
Block(-6,11,-1,24)
Block(-6,11,0,24)
Block(-6,11,1,24)
Block(-6,11,2,24)
Block(-6,11,3,24)
Block(-6,11,4,24)
Block(-6,11,5,24)
Block(-6,11,6,24)
Block(-6,11,7,24)
Block(-6,11,8,24)
Block(-6,11,9,24)
Block(-6,11,10,24)
Block(-6,11,11,24)
Block(-6,11,12,24)
Block(-6,11,13,24)
Block(-6,11,14,24)
Block(-6,11,15,24)
Block(-6,11,16,24)
Block(-6,12,-2,24)
Block(-6,12,-1,24)
Block(-6,12,0,24)
Block(-6,12,1,24)
Block(-6,12,2,24)
Block(-6,12,3,24)
Block(-6,12,4,24)
Block(-6,12,5,24)
Block(-6,12,6,24)
Block(-6,12,7,24)
Block(-6,12,8,24)
Block(-6,12,9,24)
Block(-6,12,10,24)
Block(-6,12,11,24)
Block(-6,12,12,24)
Block(-6,12,13,24)
Block(-6,12,14,24)
Block(-6,12,15,24)
Block(-6,12,16,24)
Block(-6,13,-2,24)
Block(-6,13,-1,24)
Block(-6,13,0,24)
Block(-6,13,1,24)
Block(-6,13,2,24)
Block(-6,13,3,24)
Block(-6,13,4,24)
Block(-6,13,5,24)
Block(-6,13,6,24)
Block(-6,13,7,24)
Block(-6,13,8,24)
Block(-6,13,9,24)
Block(-6,13,10,24)
Block(-6,13,11,24)
Block(-6,13,12,24)
Block(-6,13,13,24)
Block(-6,13,14,24)
Block(-6,13,15,24)
Block(-6,14,-3,24)
Block(-6,14,-2,24)
Block(-6,14,-1,24)
Block(-6,14,0,24)
Block(-6,14,1,24)
Block(-6,14,2,24)
Block(-6,14,3,24)
Block(-6,14,4,24)
Block(-6,14,5,24)
Block(-6,14,6,24)
Block(-6,14,7,24)
Block(-6,14,8,24)
Block(-6,14,9,24)
Block(-6,14,10,24)
Block(-6,14,11,24)
Block(-6,14,12,24)
Block(-6,14,13,24)
Block(-6,14,14,24)
Block(-6,15,-3,24)
Block(-6,15,-2,24)
Block(-6,15,-1,24)
Block(-6,15,0,24)
Block(-6,15,1,24)
Block(-6,15,2,24)
Block(-6,15,3,24)
Block(-6,15,4,24)
Block(-6,15,5,24)
Block(-6,15,6,24)
Block(-6,15,7,24)
Block(-6,15,8,24)
Block(-6,15,9,24)
Block(-6,15,10,24)
Block(-6,15,11,24)
Block(-6,15,12,24)
Block(-6,15,13,24)
Block(-6,16,-4,24)
Block(-6,16,-3,24)
Block(-6,16,-2,24)
Block(-6,16,-1,24)
Block(-6,16,0,24)
Block(-6,16,1,24)
Block(-6,16,2,24)
Block(-6,16,3,24)
Block(-6,16,4,24)
Block(-6,16,5,24)
Block(-6,16,6,24)
Block(-6,16,7,24)
Block(-6,16,8,24)
Block(-6,16,9,24)
Block(-6,16,10,24)
Block(-6,16,11,24)
Block(-6,16,12,24)
Block(-6,17,-5,24)
Block(-6,17,-4,24)
Block(-6,17,-3,24)
Block(-6,17,-2,24)
Block(-6,17,-1,24)
Block(-6,17,0,24)
Block(-6,17,1,24)
Block(-6,17,2,24)
Block(-6,17,3,24)
Block(-6,17,4,24)
Block(-6,17,5,24)
Block(-6,17,6,24)
Block(-6,17,7,24)
Block(-6,17,8,24)
Block(-6,17,9,24)
Block(-6,17,10,24)
Block(-6,17,11,24)
Block(-6,17,12,24)
Block(-6,18,-5,24)
Block(-6,18,-4,24)
Block(-6,18,-3,24)
Block(-6,18,-2,24)
Block(-6,18,-1,24)
Block(-6,18,0,24)
Block(-6,18,1,24)
Block(-6,18,2,24)
Block(-6,18,3,24)
Block(-6,18,4,24)
Block(-6,18,5,24)
Block(-6,18,6,24)
Block(-6,18,7,24)
Block(-6,18,8,24)
Block(-6,18,9,24)
Block(-6,18,10,24)
Block(-6,18,11,24)
Block(-6,19,-5,24)
Block(-6,19,-4,24)
Block(-6,19,-3,24)
Block(-6,19,-2,24)
Block(-6,19,-1,24)
Block(-6,19,0,24)
Block(-6,19,1,24)
Block(-6,19,2,24)
Block(-6,19,3,24)
Block(-6,19,4,24)
Block(-6,19,5,24)
Block(-6,19,6,24)
Block(-6,19,7,24)
Block(-6,19,8,24)
Block(-6,19,9,24)
Block(-6,19,10,24)
Block(-6,19,11,24)
Block(-6,20,-5,24)
Block(-6,20,-4,24)
Block(-6,20,-3,24)
Block(-6,20,-2,24)
Block(-6,20,-1,24)
Block(-6,20,0,24)
Block(-6,20,1,24)
Block(-6,20,2,24)
Block(-6,20,3,24)
Block(-6,20,4,24)
Block(-6,20,5,24)
Block(-6,20,6,24)
Block(-6,20,7,24)
Block(-6,20,8,24)
Block(-6,20,9,24)
Block(-6,20,10,24)
Block(-6,20,11,24)
Block(-6,21,-5,24)
Block(-6,21,-4,24)
Block(-6,21,-3,24)
Block(-6,21,-2,24)
Block(-6,21,-1,24)
Block(-6,21,0,24)
Block(-6,21,1,24)
Block(-6,21,2,24)
Block(-6,21,3,24)
Block(-6,21,4,24)
Block(-6,21,5,24)
Block(-6,21,6,24)
Block(-6,21,7,24)
Block(-6,21,8,24)
Block(-6,21,9,24)
Block(-6,21,10,24)
Block(-6,21,11,24)
Block(-6,22,-6,24)
Block(-6,22,-5,24)
Block(-6,22,-4,24)
Block(-6,22,-3,24)
Block(-6,22,-2,24)
Block(-6,22,-1,24)
Block(-6,22,0,24)
Block(-6,22,1,24)
Block(-6,22,2,24)
Block(-6,22,3,24)
Block(-6,22,4,24)
Block(-6,22,5,24)
Block(-6,22,6,24)
Block(-6,22,7,24)
Block(-6,22,8,24)
Block(-6,22,9,24)
Block(-6,22,10,24)
Block(-6,22,11,24)
Block(-6,23,-8,24)
Block(-6,23,-7,24)
Block(-6,23,-6,24)
Block(-6,23,-5,24)
Block(-6,23,-4,24)
Block(-6,23,-3,24)
Block(-6,23,-2,24)
Block(-6,23,-1,24)
Block(-6,23,0,24)
Block(-6,23,1,24)
Block(-6,23,2,24)
Block(-6,23,3,24)
Block(-6,23,4,24)
Block(-6,23,5,24)
Block(-6,23,6,24)
Block(-6,23,7,24)
Block(-6,23,8,24)
Block(-6,23,9,24)
Block(-6,23,10,24)
Block(-6,23,11,24)
Block(-6,24,-9,24)
Block(-6,24,-8,24)
Block(-6,24,-7,24)
Block(-6,24,-6,24)
Block(-6,24,-5,24)
Block(-6,24,-4,24)
Block(-6,24,-3,24)
Block(-6,24,-2,24)
Block(-6,24,-1,24)
Block(-6,24,0,24)
Block(-6,24,1,24)
Block(-6,24,2,24)
Block(-6,24,3,24)
Block(-6,24,4,24)
Block(-6,24,5,24)
Block(-6,24,6,24)
Block(-6,24,7,24)
Block(-6,24,8,24)
Block(-6,24,9,24)
Block(-6,24,10,24)
Block(-6,25,-9,24)
Block(-6,25,-8,24)
Block(-6,25,-7,24)
Block(-6,25,-6,24)
Block(-6,25,-5,24)
Block(-6,25,-4,24)
Block(-6,25,-3,24)
Block(-6,25,-2,24)
Block(-6,25,-1,24)
Block(-6,25,0,24)
Block(-6,25,1,24)
Block(-6,25,2,24)
Block(-6,25,3,24)
Block(-6,25,4,24)
Block(-6,25,5,24)
Block(-6,25,6,24)
Block(-6,25,7,24)
Block(-6,25,8,24)
Block(-6,25,9,24)
Block(-6,26,-8,24)
Block(-6,26,-7,24)
Block(-6,26,-6,24)
Block(-6,26,-5,24)
Block(-6,26,-4,24)
Block(-6,26,-3,24)
Block(-6,26,-2,24)
Block(-6,26,-1,24)
Block(-6,26,0,24)
Block(-6,26,1,24)
Block(-6,26,2,24)
Block(-6,26,3,24)
Block(-6,26,4,24)
Block(-6,26,5,24)
Block(-6,26,6,24)
Block(-6,26,7,24)
Block(-6,26,8,24)
Block(-6,27,-7,24)
Block(-6,27,-6,24)
Block(-6,27,-5,24)
Block(-6,27,-4,24)
Block(-6,27,-3,24)
Block(-6,27,-2,24)
Block(-6,27,-1,24)
Block(-6,27,0,24)
Block(-6,27,1,24)
Block(-6,27,2,24)
Block(-6,27,3,24)
Block(-6,27,4,24)
Block(-6,27,5,24)
Block(-6,27,6,24)
Block(-6,27,7,24)
Block(-6,28,-6,24)
Block(-6,28,-5,24)
Block(-6,28,-4,24)
Block(-6,28,-3,24)
Block(-6,28,-2,24)
Block(-6,28,-1,24)
Block(-6,28,0,24)
Block(-6,28,1,24)
Block(-6,28,2,24)
Block(-6,28,3,24)
Block(-6,28,4,24)
Block(-6,28,5,24)
Block(-6,28,6,24)
Block(-6,28,7,24)
Block(-6,29,-5,24)
Block(-6,29,-4,24)
Block(-6,29,-3,24)
Block(-6,29,-2,24)
Block(-6,29,-1,24)
Block(-6,29,0,24)
Block(-6,29,1,24)
Block(-6,29,2,24)
Block(-6,29,3,24)
Block(-6,29,4,24)
Block(-6,29,5,24)
Block(-6,29,6,24)
Block(-6,30,-4,24)
Block(-6,30,-3,24)
Block(-6,30,-2,24)
Block(-6,30,-1,24)
Block(-6,30,0,24)
Block(-6,30,1,24)
Block(-6,30,2,24)
Block(-6,30,3,24)
Block(-6,30,4,24)
Block(-6,31,-3,24)
Block(-6,31,-2,24)
Block(-6,31,-1,24)
Block(-6,31,0,24)
Block(-6,31,1,24)
Block(-5,7,-2,24)
Block(-5,7,-1,24)
Block(-5,7,0,24)
Block(-5,8,-2,24)
Block(-5,8,-1,24)
Block(-5,8,0,24)
Block(-5,8,1,24)
Block(-5,8,2,24)
Block(-5,8,3,24)
Block(-5,8,4,24)
Block(-5,9,-2,24)
Block(-5,9,-1,24)
Block(-5,9,0,24)
Block(-5,9,1,24)
Block(-5,9,2,24)
Block(-5,9,3,24)
Block(-5,9,4,24)
Block(-5,9,5,24)
Block(-5,9,6,24)
Block(-5,9,7,24)
Block(-5,9,8,24)
Block(-5,9,9,24)
Block(-5,9,10,24)
Block(-5,9,11,24)
Block(-5,10,-2,24)
Block(-5,10,-1,24)
Block(-5,10,0,24)
Block(-5,10,1,24)
Block(-5,10,2,24)
Block(-5,10,3,24)
Block(-5,10,4,24)
Block(-5,10,5,24)
Block(-5,10,6,24)
Block(-5,10,7,24)
Block(-5,10,8,24)
Block(-5,10,9,24)
Block(-5,10,10,24)
Block(-5,10,11,24)
Block(-5,10,12,24)
Block(-5,10,13,24)
Block(-5,10,14,24)
Block(-5,11,-2,24)
Block(-5,11,-1,24)
Block(-5,11,0,24)
Block(-5,11,1,24)
Block(-5,11,2,24)
Block(-5,11,3,24)
Block(-5,11,4,24)
Block(-5,11,5,24)
Block(-5,11,6,24)
Block(-5,11,7,24)
Block(-5,11,8,24)
Block(-5,11,9,24)
Block(-5,11,10,24)
Block(-5,11,11,24)
Block(-5,11,12,24)
Block(-5,11,13,24)
Block(-5,11,14,24)
Block(-5,11,15,24)
Block(-5,12,-2,24)
Block(-5,12,-1,24)
Block(-5,12,0,24)
Block(-5,12,1,24)
Block(-5,12,2,24)
Block(-5,12,3,24)
Block(-5,12,4,24)
Block(-5,12,5,24)
Block(-5,12,6,24)
Block(-5,12,7,24)
Block(-5,12,8,24)
Block(-5,12,9,24)
Block(-5,12,10,24)
Block(-5,12,11,24)
Block(-5,12,12,24)
Block(-5,12,13,24)
Block(-5,12,14,24)
Block(-5,12,15,24)
Block(-5,12,16,24)
Block(-5,12,17,24)
Block(-5,13,-3,24)
Block(-5,13,-2,24)
Block(-5,13,-1,24)
Block(-5,13,0,24)
Block(-5,13,1,24)
Block(-5,13,2,24)
Block(-5,13,3,24)
Block(-5,13,4,24)
Block(-5,13,5,24)
Block(-5,13,6,24)
Block(-5,13,7,24)
Block(-5,13,8,24)
Block(-5,13,9,24)
Block(-5,13,10,24)
Block(-5,13,11,24)
Block(-5,13,12,24)
Block(-5,13,13,24)
Block(-5,13,14,24)
Block(-5,13,15,24)
Block(-5,13,16,24)
Block(-5,13,17,24)
Block(-5,13,18,24)
Block(-5,14,-3,24)
Block(-5,14,-2,24)
Block(-5,14,-1,24)
Block(-5,14,0,24)
Block(-5,14,1,24)
Block(-5,14,2,24)
Block(-5,14,3,24)
Block(-5,14,4,24)
Block(-5,14,5,24)
Block(-5,14,6,24)
Block(-5,14,7,24)
Block(-5,14,8,24)
Block(-5,14,9,24)
Block(-5,14,10,24)
Block(-5,14,11,24)
Block(-5,14,12,24)
Block(-5,14,13,24)
Block(-5,14,14,24)
Block(-5,14,15,24)
Block(-5,14,16,24)
Block(-5,14,17,24)
Block(-5,14,18,24)
Block(-5,15,-4,24)
Block(-5,15,-3,24)
Block(-5,15,-2,24)
Block(-5,15,-1,24)
Block(-5,15,0,24)
Block(-5,15,1,24)
Block(-5,15,2,24)
Block(-5,15,3,24)
Block(-5,15,4,24)
Block(-5,15,5,24)
Block(-5,15,6,24)
Block(-5,15,7,24)
Block(-5,15,8,24)
Block(-5,15,9,24)
Block(-5,15,10,24)
Block(-5,15,11,24)
Block(-5,15,12,24)
Block(-5,15,13,24)
Block(-5,15,14,24)
Block(-5,15,15,24)
Block(-5,15,16,24)
Block(-5,15,17,24)
Block(-5,16,-5,24)
Block(-5,16,-4,24)
Block(-5,16,-3,24)
Block(-5,16,-2,24)
Block(-5,16,-1,24)
Block(-5,16,0,24)
Block(-5,16,1,24)
Block(-5,16,2,24)
Block(-5,16,3,24)
Block(-5,16,4,24)
Block(-5,16,5,24)
Block(-5,16,6,24)
Block(-5,16,7,24)
Block(-5,16,8,24)
Block(-5,16,9,24)
Block(-5,16,10,24)
Block(-5,16,11,24)
Block(-5,16,12,24)
Block(-5,16,13,24)
Block(-5,16,14,24)
Block(-5,16,15,24)
Block(-5,16,16,24)
Block(-5,17,-6,24)
Block(-5,17,-5,24)
Block(-5,17,-4,24)
Block(-5,17,-3,24)
Block(-5,17,-2,24)
Block(-5,17,-1,24)
Block(-5,17,0,24)
Block(-5,17,1,24)
Block(-5,17,2,24)
Block(-5,17,3,24)
Block(-5,17,4,24)
Block(-5,17,5,24)
Block(-5,17,6,24)
Block(-5,17,7,24)
Block(-5,17,8,24)
Block(-5,17,9,24)
Block(-5,17,10,24)
Block(-5,17,11,24)
Block(-5,17,12,24)
Block(-5,17,13,24)
Block(-5,17,14,24)
Block(-5,17,15,24)
Block(-5,18,-7,24)
Block(-5,18,-6,24)
Block(-5,18,-5,24)
Block(-5,18,-4,24)
Block(-5,18,-3,24)
Block(-5,18,-2,24)
Block(-5,18,-1,24)
Block(-5,18,0,24)
Block(-5,18,1,24)
Block(-5,18,2,24)
Block(-5,18,3,24)
Block(-5,18,4,24)
Block(-5,18,5,24)
Block(-5,18,6,24)
Block(-5,18,7,24)
Block(-5,18,8,24)
Block(-5,18,9,24)
Block(-5,18,10,24)
Block(-5,18,11,24)
Block(-5,18,12,24)
Block(-5,18,13,24)
Block(-5,18,14,24)
Block(-5,19,-8,24)
Block(-5,19,-7,24)
Block(-5,19,-6,24)
Block(-5,19,-5,24)
Block(-5,19,-4,24)
Block(-5,19,-3,24)
Block(-5,19,-2,24)
Block(-5,19,-1,24)
Block(-5,19,0,24)
Block(-5,19,1,24)
Block(-5,19,2,24)
Block(-5,19,3,24)
Block(-5,19,4,24)
Block(-5,19,5,24)
Block(-5,19,6,24)
Block(-5,19,7,24)
Block(-5,19,8,24)
Block(-5,19,9,24)
Block(-5,19,10,24)
Block(-5,19,11,24)
Block(-5,19,12,24)
Block(-5,19,13,24)
Block(-5,19,14,24)
Block(-5,20,-9,24)
Block(-5,20,-8,24)
Block(-5,20,-7,24)
Block(-5,20,-6,24)
Block(-5,20,-5,24)
Block(-5,20,-4,24)
Block(-5,20,-3,24)
Block(-5,20,-2,24)
Block(-5,20,-1,24)
Block(-5,20,0,24)
Block(-5,20,1,24)
Block(-5,20,2,24)
Block(-5,20,3,24)
Block(-5,20,4,24)
Block(-5,20,5,24)
Block(-5,20,6,24)
Block(-5,20,7,24)
Block(-5,20,8,24)
Block(-5,20,9,24)
Block(-5,20,10,24)
Block(-5,20,11,24)
Block(-5,20,12,24)
Block(-5,20,13,24)
Block(-5,20,14,24)
Block(-5,21,-10,24)
Block(-5,21,-9,24)
Block(-5,21,-8,24)
Block(-5,21,-7,24)
Block(-5,21,-6,24)
Block(-5,21,-5,24)
Block(-5,21,-4,24)
Block(-5,21,-3,24)
Block(-5,21,-2,24)
Block(-5,21,-1,24)
Block(-5,21,0,24)
Block(-5,21,1,24)
Block(-5,21,2,24)
Block(-5,21,3,24)
Block(-5,21,4,24)
Block(-5,21,5,24)
Block(-5,21,6,24)
Block(-5,21,7,24)
Block(-5,21,8,24)
Block(-5,21,9,24)
Block(-5,21,10,24)
Block(-5,21,11,24)
Block(-5,21,12,24)
Block(-5,21,13,24)
Block(-5,22,-11,24)
Block(-5,22,-10,24)
Block(-5,22,-9,24)
Block(-5,22,-8,24)
Block(-5,22,-7,24)
Block(-5,22,-6,24)
Block(-5,22,-5,24)
Block(-5,22,-4,24)
Block(-5,22,-3,24)
Block(-5,22,-2,24)
Block(-5,22,-1,24)
Block(-5,22,0,24)
Block(-5,22,1,24)
Block(-5,22,2,24)
Block(-5,22,3,24)
Block(-5,22,4,24)
Block(-5,22,5,24)
Block(-5,22,6,24)
Block(-5,22,7,24)
Block(-5,22,8,24)
Block(-5,22,9,24)
Block(-5,22,10,24)
Block(-5,22,11,24)
Block(-5,22,12,24)
Block(-5,22,13,24)
Block(-5,23,-10,24)
Block(-5,23,-9,24)
Block(-5,23,-8,24)
Block(-5,23,-7,24)
Block(-5,23,-6,24)
Block(-5,23,-5,24)
Block(-5,23,-4,24)
Block(-5,23,-3,24)
Block(-5,23,-2,24)
Block(-5,23,-1,24)
Block(-5,23,0,24)
Block(-5,23,1,24)
Block(-5,23,2,24)
Block(-5,23,3,24)
Block(-5,23,4,24)
Block(-5,23,5,24)
Block(-5,23,6,24)
Block(-5,23,7,24)
Block(-5,23,8,24)
Block(-5,23,9,24)
Block(-5,23,10,24)
Block(-5,23,11,24)
Block(-5,23,12,24)
Block(-5,24,-9,24)
Block(-5,24,-8,24)
Block(-5,24,-7,24)
Block(-5,24,-6,24)
Block(-5,24,-5,24)
Block(-5,24,-4,24)
Block(-5,24,-3,24)
Block(-5,24,-2,24)
Block(-5,24,-1,24)
Block(-5,24,0,24)
Block(-5,24,1,24)
Block(-5,24,2,24)
Block(-5,24,3,24)
Block(-5,24,4,24)
Block(-5,24,5,24)
Block(-5,24,6,24)
Block(-5,24,7,24)
Block(-5,24,8,24)
Block(-5,24,9,24)
Block(-5,24,10,24)
Block(-5,24,11,24)
Block(-5,24,12,24)
Block(-5,25,-8,24)
Block(-5,25,-7,24)
Block(-5,25,-6,24)
Block(-5,25,-5,24)
Block(-5,25,-4,24)
Block(-5,25,-3,24)
Block(-5,25,-2,24)
Block(-5,25,-1,24)
Block(-5,25,0,24)
Block(-5,25,1,24)
Block(-5,25,2,24)
Block(-5,25,3,24)
Block(-5,25,4,24)
Block(-5,25,5,24)
Block(-5,25,6,24)
Block(-5,25,7,24)
Block(-5,25,8,24)
Block(-5,25,9,24)
Block(-5,25,10,24)
Block(-5,25,11,24)
Block(-5,25,12,24)
Block(-5,26,-7,24)
Block(-5,26,-6,24)
Block(-5,26,-5,24)
Block(-5,26,-4,24)
Block(-5,26,-3,24)
Block(-5,26,-2,24)
Block(-5,26,-1,24)
Block(-5,26,0,24)
Block(-5,26,1,24)
Block(-5,26,2,24)
Block(-5,26,3,24)
Block(-5,26,4,24)
Block(-5,26,5,24)
Block(-5,26,6,24)
Block(-5,26,7,24)
Block(-5,26,8,24)
Block(-5,26,9,24)
Block(-5,26,10,24)
Block(-5,26,11,24)
Block(-5,26,12,24)
Block(-5,27,-6,24)
Block(-5,27,-5,24)
Block(-5,27,-4,24)
Block(-5,27,-3,24)
Block(-5,27,-2,24)
Block(-5,27,-1,24)
Block(-5,27,0,24)
Block(-5,27,1,24)
Block(-5,27,2,24)
Block(-5,27,3,24)
Block(-5,27,4,24)
Block(-5,27,5,24)
Block(-5,27,6,24)
Block(-5,27,7,24)
Block(-5,27,8,24)
Block(-5,27,9,24)
Block(-5,27,10,24)
Block(-5,28,-5,24)
Block(-5,28,-4,24)
Block(-5,28,-3,24)
Block(-5,28,-2,24)
Block(-5,28,-1,24)
Block(-5,28,0,24)
Block(-5,28,1,24)
Block(-5,28,2,24)
Block(-5,28,3,24)
Block(-5,28,4,24)
Block(-5,28,5,24)
Block(-5,28,6,24)
Block(-5,28,7,24)
Block(-5,28,8,24)
Block(-5,28,9,24)
Block(-5,29,-5,24)
Block(-5,29,-4,24)
Block(-5,29,-3,24)
Block(-5,29,-2,24)
Block(-5,29,-1,24)
Block(-5,29,0,24)
Block(-5,29,1,24)
Block(-5,29,2,24)
Block(-5,29,3,24)
Block(-5,29,4,24)
Block(-5,29,5,24)
Block(-5,29,6,24)
Block(-5,29,7,24)
Block(-5,30,-4,24)
Block(-5,30,-3,24)
Block(-5,30,-2,24)
Block(-5,30,-1,24)
Block(-5,30,0,24)
Block(-5,30,1,24)
Block(-5,30,2,24)
Block(-5,30,3,24)
Block(-5,30,4,24)
Block(-5,31,-3,24)
Block(-5,31,-2,24)
Block(-5,31,-1,24)
Block(-5,31,0,24)
Block(-5,31,1,24)
Block(-5,31,2,24)
Block(-5,32,-2,24)
Block(-5,32,-1,24)
Block(-4,6,-2,24)
Block(-4,6,-1,24)
Block(-4,7,-2,24)
Block(-4,7,-1,24)
Block(-4,7,0,24)
Block(-4,7,1,24)
Block(-4,7,2,24)
Block(-4,8,-2,24)
Block(-4,8,-1,24)
Block(-4,8,0,24)
Block(-4,8,1,24)
Block(-4,8,2,24)
Block(-4,8,3,24)
Block(-4,8,4,24)
Block(-4,8,5,24)
Block(-4,8,6,24)
Block(-4,9,-2,24)
Block(-4,9,-1,24)
Block(-4,9,0,24)
Block(-4,9,1,24)
Block(-4,9,2,24)
Block(-4,9,3,24)
Block(-4,9,4,24)
Block(-4,9,5,24)
Block(-4,9,6,24)
Block(-4,9,7,24)
Block(-4,9,8,24)
Block(-4,9,9,24)
Block(-4,9,10,24)
Block(-4,9,11,24)
Block(-4,9,12,24)
Block(-4,10,-2,24)
Block(-4,10,-1,24)
Block(-4,10,0,24)
Block(-4,10,1,24)
Block(-4,10,2,24)
Block(-4,10,3,24)
Block(-4,10,4,24)
Block(-4,10,5,24)
Block(-4,10,6,24)
Block(-4,10,7,24)
Block(-4,10,8,24)
Block(-4,10,9,24)
Block(-4,10,10,24)
Block(-4,10,11,24)
Block(-4,10,12,24)
Block(-4,10,13,24)
Block(-4,10,14,24)
Block(-4,11,-2,24)
Block(-4,11,-1,24)
Block(-4,11,0,24)
Block(-4,11,1,24)
Block(-4,11,2,24)
Block(-4,11,3,24)
Block(-4,11,4,24)
Block(-4,11,5,24)
Block(-4,11,6,24)
Block(-4,11,7,24)
Block(-4,11,8,24)
Block(-4,11,9,24)
Block(-4,11,10,24)
Block(-4,11,11,24)
Block(-4,11,12,24)
Block(-4,11,13,24)
Block(-4,11,14,24)
Block(-4,11,15,24)
Block(-4,11,16,24)
Block(-4,12,-3,24)
Block(-4,12,-2,24)
Block(-4,12,-1,24)
Block(-4,12,0,24)
Block(-4,12,1,24)
Block(-4,12,2,24)
Block(-4,12,3,24)
Block(-4,12,4,24)
Block(-4,12,5,24)
Block(-4,12,6,24)
Block(-4,12,7,24)
Block(-4,12,8,24)
Block(-4,12,9,24)
Block(-4,12,10,24)
Block(-4,12,11,24)
Block(-4,12,12,24)
Block(-4,12,13,24)
Block(-4,12,14,24)
Block(-4,12,15,24)
Block(-4,12,16,24)
Block(-4,12,17,24)
Block(-4,13,-3,24)
Block(-4,13,-2,24)
Block(-4,13,-1,24)
Block(-4,13,0,24)
Block(-4,13,1,24)
Block(-4,13,2,24)
Block(-4,13,3,24)
Block(-4,13,4,24)
Block(-4,13,5,24)
Block(-4,13,6,24)
Block(-4,13,7,24)
Block(-4,13,8,24)
Block(-4,13,9,24)
Block(-4,13,10,24)
Block(-4,13,11,24)
Block(-4,13,12,24)
Block(-4,13,13,24)
Block(-4,13,14,24)
Block(-4,13,15,24)
Block(-4,13,16,24)
Block(-4,13,17,24)
Block(-4,14,-4,24)
Block(-4,14,-3,24)
Block(-4,14,-2,24)
Block(-4,14,-1,24)
Block(-4,14,0,24)
Block(-4,14,1,24)
Block(-4,14,2,24)
Block(-4,14,3,24)
Block(-4,14,4,24)
Block(-4,14,5,24)
Block(-4,14,6,24)
Block(-4,14,7,24)
Block(-4,14,8,24)
Block(-4,14,9,24)
Block(-4,14,10,24)
Block(-4,14,11,24)
Block(-4,14,12,24)
Block(-4,14,13,24)
Block(-4,14,14,24)
Block(-4,14,15,24)
Block(-4,14,16,24)
Block(-4,14,17,24)
Block(-4,14,18,24)
Block(-4,15,-5,24)
Block(-4,15,-4,24)
Block(-4,15,-3,24)
Block(-4,15,-2,24)
Block(-4,15,-1,24)
Block(-4,15,0,24)
Block(-4,15,1,24)
Block(-4,15,2,24)
Block(-4,15,3,24)
Block(-4,15,4,24)
Block(-4,15,5,24)
Block(-4,15,6,24)
Block(-4,15,7,24)
Block(-4,15,8,24)
Block(-4,15,9,24)
Block(-4,15,10,24)
Block(-4,15,11,24)
Block(-4,15,12,24)
Block(-4,15,13,24)
Block(-4,15,14,24)
Block(-4,15,15,24)
Block(-4,15,16,24)
Block(-4,15,17,24)
Block(-4,15,18,24)
Block(-4,16,-6,24)
Block(-4,16,-5,24)
Block(-4,16,-4,24)
Block(-4,16,-3,24)
Block(-4,16,-2,24)
Block(-4,16,-1,24)
Block(-4,16,0,24)
Block(-4,16,1,24)
Block(-4,16,2,24)
Block(-4,16,3,24)
Block(-4,16,4,24)
Block(-4,16,5,24)
Block(-4,16,6,24)
Block(-4,16,7,24)
Block(-4,16,8,24)
Block(-4,16,9,24)
Block(-4,16,10,24)
Block(-4,16,11,24)
Block(-4,16,12,24)
Block(-4,16,13,24)
Block(-4,16,14,24)
Block(-4,16,15,24)
Block(-4,16,16,24)
Block(-4,16,17,24)
Block(-4,16,18,24)
Block(-4,17,-7,24)
Block(-4,17,-6,24)
Block(-4,17,-5,24)
Block(-4,17,-4,24)
Block(-4,17,-3,24)
Block(-4,17,-2,24)
Block(-4,17,-1,24)
Block(-4,17,0,24)
Block(-4,17,1,24)
Block(-4,17,2,24)
Block(-4,17,3,24)
Block(-4,17,4,24)
Block(-4,17,5,24)
Block(-4,17,6,24)
Block(-4,17,7,24)
Block(-4,17,8,24)
Block(-4,17,9,24)
Block(-4,17,10,24)
Block(-4,17,11,24)
Block(-4,17,12,24)
Block(-4,17,13,24)
Block(-4,17,14,24)
Block(-4,17,15,24)
Block(-4,17,16,24)
Block(-4,17,17,24)
Block(-4,17,18,24)
Block(-4,18,-8,24)
Block(-4,18,-7,24)
Block(-4,18,-6,24)
Block(-4,18,-5,24)
Block(-4,18,-4,24)
Block(-4,18,-3,24)
Block(-4,18,-2,24)
Block(-4,18,-1,24)
Block(-4,18,0,24)
Block(-4,18,1,24)
Block(-4,18,2,24)
Block(-4,18,3,24)
Block(-4,18,4,24)
Block(-4,18,5,24)
Block(-4,18,6,24)
Block(-4,18,7,24)
Block(-4,18,8,24)
Block(-4,18,9,24)
Block(-4,18,10,24)
Block(-4,18,11,24)
Block(-4,18,12,24)
Block(-4,18,13,24)
Block(-4,18,14,24)
Block(-4,18,15,24)
Block(-4,18,16,24)
Block(-4,18,17,24)
Block(-4,18,18,24)
Block(-4,19,-9,24)
Block(-4,19,-8,24)
Block(-4,19,-7,24)
Block(-4,19,-6,24)
Block(-4,19,-5,24)
Block(-4,19,-4,24)
Block(-4,19,-3,24)
Block(-4,19,-2,24)
Block(-4,19,-1,24)
Block(-4,19,0,24)
Block(-4,19,1,24)
Block(-4,19,2,24)
Block(-4,19,3,24)
Block(-4,19,4,24)
Block(-4,19,5,24)
Block(-4,19,6,24)
Block(-4,19,7,24)
Block(-4,19,8,24)
Block(-4,19,9,24)
Block(-4,19,10,24)
Block(-4,19,11,24)
Block(-4,19,12,24)
Block(-4,19,13,24)
Block(-4,19,14,24)
Block(-4,19,15,24)
Block(-4,19,16,24)
Block(-4,19,17,24)
Block(-4,19,18,24)
Block(-4,20,-10,24)
Block(-4,20,-9,24)
Block(-4,20,-8,24)
Block(-4,20,-7,24)
Block(-4,20,-6,24)
Block(-4,20,-5,24)
Block(-4,20,-4,24)
Block(-4,20,-3,24)
Block(-4,20,-2,24)
Block(-4,20,-1,24)
Block(-4,20,0,24)
Block(-4,20,1,24)
Block(-4,20,2,24)
Block(-4,20,3,24)
Block(-4,20,4,24)
Block(-4,20,5,24)
Block(-4,20,6,24)
Block(-4,20,7,24)
Block(-4,20,8,24)
Block(-4,20,9,24)
Block(-4,20,10,24)
Block(-4,20,11,24)
Block(-4,20,12,24)
Block(-4,20,13,24)
Block(-4,20,14,24)
Block(-4,20,15,24)
Block(-4,20,16,24)
Block(-4,20,17,24)
Block(-4,21,-11,24)
Block(-4,21,-10,24)
Block(-4,21,-9,24)
Block(-4,21,-8,24)
Block(-4,21,-7,24)
Block(-4,21,-6,24)
Block(-4,21,-5,24)
Block(-4,21,-4,24)
Block(-4,21,-3,24)
Block(-4,21,-2,24)
Block(-4,21,-1,24)
Block(-4,21,0,24)
Block(-4,21,1,24)
Block(-4,21,2,24)
Block(-4,21,3,24)
Block(-4,21,4,24)
Block(-4,21,5,24)
Block(-4,21,6,24)
Block(-4,21,7,24)
Block(-4,21,8,24)
Block(-4,21,9,24)
Block(-4,21,10,24)
Block(-4,21,11,24)
Block(-4,21,12,24)
Block(-4,21,13,24)
Block(-4,21,14,24)
Block(-4,21,15,24)
Block(-4,21,16,24)
Block(-4,22,-10,24)
Block(-4,22,-9,24)
Block(-4,22,-8,24)
Block(-4,22,-7,24)
Block(-4,22,-6,24)
Block(-4,22,-5,24)
Block(-4,22,-4,24)
Block(-4,22,-3,24)
Block(-4,22,-2,24)
Block(-4,22,-1,24)
Block(-4,22,0,24)
Block(-4,22,1,24)
Block(-4,22,2,24)
Block(-4,22,3,24)
Block(-4,22,4,24)
Block(-4,22,5,24)
Block(-4,22,6,24)
Block(-4,22,7,24)
Block(-4,22,8,24)
Block(-4,22,9,24)
Block(-4,22,10,24)
Block(-4,22,11,24)
Block(-4,22,12,24)
Block(-4,22,13,24)
Block(-4,22,14,24)
Block(-4,22,15,24)
Block(-4,22,16,24)
Block(-4,23,-10,24)
Block(-4,23,-9,24)
Block(-4,23,-8,24)
Block(-4,23,-7,24)
Block(-4,23,-6,24)
Block(-4,23,-5,24)
Block(-4,23,-4,24)
Block(-4,23,-3,24)
Block(-4,23,-2,24)
Block(-4,23,-1,24)
Block(-4,23,0,24)
Block(-4,23,1,24)
Block(-4,23,2,24)
Block(-4,23,3,24)
Block(-4,23,4,24)
Block(-4,23,5,24)
Block(-4,23,6,24)
Block(-4,23,7,24)
Block(-4,23,8,24)
Block(-4,23,9,24)
Block(-4,23,10,24)
Block(-4,23,11,24)
Block(-4,23,12,24)
Block(-4,23,13,24)
Block(-4,23,14,24)
Block(-4,23,15,24)
Block(-4,24,-9,24)
Block(-4,24,-8,24)
Block(-4,24,-7,24)
Block(-4,24,-6,24)
Block(-4,24,-5,24)
Block(-4,24,-4,24)
Block(-4,24,-3,24)
Block(-4,24,-2,24)
Block(-4,24,-1,24)
Block(-4,24,0,24)
Block(-4,24,1,24)
Block(-4,24,2,24)
Block(-4,24,3,24)
Block(-4,24,4,24)
Block(-4,24,5,24)
Block(-4,24,6,24)
Block(-4,24,7,24)
Block(-4,24,8,24)
Block(-4,24,9,24)
Block(-4,24,10,24)
Block(-4,24,11,24)
Block(-4,24,12,24)
Block(-4,24,13,24)
Block(-4,24,14,24)
Block(-4,25,-8,24)
Block(-4,25,-7,24)
Block(-4,25,-6,24)
Block(-4,25,-5,24)
Block(-4,25,-4,24)
Block(-4,25,-3,24)
Block(-4,25,-2,24)
Block(-4,25,-1,24)
Block(-4,25,0,24)
Block(-4,25,1,24)
Block(-4,25,2,24)
Block(-4,25,3,24)
Block(-4,25,4,24)
Block(-4,25,5,24)
Block(-4,25,6,24)
Block(-4,25,7,24)
Block(-4,25,8,24)
Block(-4,25,9,24)
Block(-4,25,10,24)
Block(-4,25,11,24)
Block(-4,25,12,24)
Block(-4,25,13,24)
Block(-4,25,14,24)
Block(-4,26,-7,24)
Block(-4,26,-6,24)
Block(-4,26,-5,24)
Block(-4,26,-4,24)
Block(-4,26,-3,24)
Block(-4,26,-2,24)
Block(-4,26,-1,24)
Block(-4,26,0,24)
Block(-4,26,1,24)
Block(-4,26,2,24)
Block(-4,26,3,24)
Block(-4,26,4,24)
Block(-4,26,5,24)
Block(-4,26,6,24)
Block(-4,26,7,24)
Block(-4,26,8,24)
Block(-4,26,9,24)
Block(-4,26,10,24)
Block(-4,26,11,24)
Block(-4,26,12,24)
Block(-4,26,13,24)
Block(-4,27,-6,24)
Block(-4,27,-5,24)
Block(-4,27,-4,24)
Block(-4,27,-3,24)
Block(-4,27,-2,24)
Block(-4,27,-1,24)
Block(-4,27,0,24)
Block(-4,27,1,24)
Block(-4,27,2,24)
Block(-4,27,3,24)
Block(-4,27,4,24)
Block(-4,27,5,24)
Block(-4,27,6,24)
Block(-4,27,7,24)
Block(-4,27,8,24)
Block(-4,27,9,24)
Block(-4,27,10,24)
Block(-4,27,11,24)
Block(-4,27,12,24)
Block(-4,27,13,24)
Block(-4,28,-5,24)
Block(-4,28,-4,24)
Block(-4,28,-3,24)
Block(-4,28,-2,24)
Block(-4,28,-1,24)
Block(-4,28,0,24)
Block(-4,28,1,24)
Block(-4,28,2,24)
Block(-4,28,3,24)
Block(-4,28,4,24)
Block(-4,28,5,24)
Block(-4,28,6,24)
Block(-4,28,7,24)
Block(-4,28,8,24)
Block(-4,28,9,24)
Block(-4,28,10,24)
Block(-4,29,-4,24)
Block(-4,29,-3,24)
Block(-4,29,-2,24)
Block(-4,29,-1,24)
Block(-4,29,0,24)
Block(-4,29,1,24)
Block(-4,29,2,24)
Block(-4,29,3,24)
Block(-4,29,4,24)
Block(-4,29,5,24)
Block(-4,29,6,24)
Block(-4,29,7,24)
Block(-4,30,-4,24)
Block(-4,30,-3,24)
Block(-4,30,-2,24)
Block(-4,30,-1,24)
Block(-4,30,0,24)
Block(-4,30,1,24)
Block(-4,30,2,24)
Block(-4,30,3,24)
Block(-4,30,4,24)
Block(-4,30,5,24)
Block(-4,31,-3,24)
Block(-4,31,-2,24)
Block(-4,31,-1,24)
Block(-4,31,0,24)
Block(-4,31,1,24)
Block(-4,31,2,24)
Block(-4,31,3,24)
Block(-4,32,-2,24)
Block(-4,32,-1,24)
Block(-4,32,0,24)
Block(-3,5,-3,24)
Block(-3,6,-3,24)
Block(-3,6,-2,24)
Block(-3,6,-1,24)
Block(-3,6,0,24)
Block(-3,7,-3,24)
Block(-3,7,-2,24)
Block(-3,7,-1,24)
Block(-3,7,0,24)
Block(-3,7,1,24)
Block(-3,7,2,24)
Block(-3,7,3,24)
Block(-3,8,-3,24)
Block(-3,8,-2,24)
Block(-3,8,-1,24)
Block(-3,8,0,24)
Block(-3,8,1,24)
Block(-3,8,2,24)
Block(-3,8,3,24)
Block(-3,8,4,24)
Block(-3,8,5,24)
Block(-3,8,6,24)
Block(-3,8,7,24)
Block(-3,8,8,24)
Block(-3,9,-3,24)
Block(-3,9,-2,24)
Block(-3,9,-1,24)
Block(-3,9,0,24)
Block(-3,9,1,24)
Block(-3,9,2,24)
Block(-3,9,3,24)
Block(-3,9,4,24)
Block(-3,9,5,24)
Block(-3,9,6,24)
Block(-3,9,7,24)
Block(-3,9,8,24)
Block(-3,9,9,24)
Block(-3,9,10,24)
Block(-3,9,11,24)
Block(-3,9,12,24)
Block(-3,10,-3,24)
Block(-3,10,-2,24)
Block(-3,10,-1,24)
Block(-3,10,0,24)
Block(-3,10,1,24)
Block(-3,10,2,24)
Block(-3,10,3,24)
Block(-3,10,4,24)
Block(-3,10,5,24)
Block(-3,10,6,24)
Block(-3,10,7,24)
Block(-3,10,8,24)
Block(-3,10,9,24)
Block(-3,10,10,24)
Block(-3,10,11,24)
Block(-3,10,12,24)
Block(-3,10,13,24)
Block(-3,10,14,24)
Block(-3,11,-3,24)
Block(-3,11,-2,24)
Block(-3,11,-1,24)
Block(-3,11,0,24)
Block(-3,11,1,24)
Block(-3,11,2,24)
Block(-3,11,3,24)
Block(-3,11,4,24)
Block(-3,11,5,24)
Block(-3,11,6,24)
Block(-3,11,7,24)
Block(-3,11,8,24)
Block(-3,11,9,24)
Block(-3,11,10,24)
Block(-3,11,11,24)
Block(-3,11,12,24)
Block(-3,11,13,24)
Block(-3,11,14,24)
Block(-3,11,15,24)
Block(-3,11,16,24)
Block(-3,12,-3,24)
Block(-3,12,-2,24)
Block(-3,12,-1,24)
Block(-3,12,0,24)
Block(-3,12,1,24)
Block(-3,12,2,24)
Block(-3,12,3,24)
Block(-3,12,4,24)
Block(-3,12,5,24)
Block(-3,12,6,24)
Block(-3,12,7,24)
Block(-3,12,8,24)
Block(-3,12,9,24)
Block(-3,12,10,24)
Block(-3,12,11,24)
Block(-3,12,12,24)
Block(-3,12,13,24)
Block(-3,12,14,24)
Block(-3,12,15,24)
Block(-3,12,16,24)
Block(-3,12,17,24)
Block(-3,13,-4,24)
Block(-3,13,-3,24)
Block(-3,13,-2,24)
Block(-3,13,-1,24)
Block(-3,13,0,24)
Block(-3,13,1,24)
Block(-3,13,2,24)
Block(-3,13,3,24)
Block(-3,13,4,24)
Block(-3,13,5,24)
Block(-3,13,6,24)
Block(-3,13,7,24)
Block(-3,13,8,24)
Block(-3,13,9,24)
Block(-3,13,10,24)
Block(-3,13,11,24)
Block(-3,13,12,24)
Block(-3,13,13,24)
Block(-3,13,14,24)
Block(-3,13,15,24)
Block(-3,13,16,24)
Block(-3,13,17,24)
Block(-3,14,-5,24)
Block(-3,14,-4,24)
Block(-3,14,-3,24)
Block(-3,14,-2,24)
Block(-3,14,-1,24)
Block(-3,14,0,24)
Block(-3,14,1,24)
Block(-3,14,2,24)
Block(-3,14,3,24)
Block(-3,14,4,24)
Block(-3,14,5,24)
Block(-3,14,6,24)
Block(-3,14,7,24)
Block(-3,14,8,24)
Block(-3,14,9,24)
Block(-3,14,10,24)
Block(-3,14,11,24)
Block(-3,14,12,24)
Block(-3,14,13,24)
Block(-3,14,14,24)
Block(-3,14,15,24)
Block(-3,14,16,24)
Block(-3,14,17,24)
Block(-3,14,18,24)
Block(-3,15,-6,24)
Block(-3,15,-5,24)
Block(-3,15,-4,24)
Block(-3,15,-3,24)
Block(-3,15,-2,24)
Block(-3,15,-1,24)
Block(-3,15,0,24)
Block(-3,15,1,24)
Block(-3,15,2,24)
Block(-3,15,3,24)
Block(-3,15,4,24)
Block(-3,15,5,24)
Block(-3,15,6,24)
Block(-3,15,7,24)
Block(-3,15,8,24)
Block(-3,15,9,24)
Block(-3,15,10,24)
Block(-3,15,11,24)
Block(-3,15,12,24)
Block(-3,15,13,24)
Block(-3,15,14,24)
Block(-3,15,15,24)
Block(-3,15,16,24)
Block(-3,15,17,24)
Block(-3,15,18,24)
Block(-3,16,-7,24)
Block(-3,16,-6,24)
Block(-3,16,-5,24)
Block(-3,16,-4,24)
Block(-3,16,-3,24)
Block(-3,16,-2,24)
Block(-3,16,-1,24)
Block(-3,16,0,24)
Block(-3,16,1,24)
Block(-3,16,2,24)
Block(-3,16,3,24)
Block(-3,16,4,24)
Block(-3,16,5,24)
Block(-3,16,6,24)
Block(-3,16,7,24)
Block(-3,16,8,24)
Block(-3,16,9,24)
Block(-3,16,10,24)
Block(-3,16,11,24)
Block(-3,16,12,24)
Block(-3,16,13,24)
Block(-3,16,14,24)
Block(-3,16,15,24)
Block(-3,16,16,24)
Block(-3,16,17,24)
Block(-3,16,18,24)
Block(-3,17,-8,24)
Block(-3,17,-7,24)
Block(-3,17,-6,24)
Block(-3,17,-5,24)
Block(-3,17,-4,24)
Block(-3,17,-3,24)
Block(-3,17,-2,24)
Block(-3,17,-1,24)
Block(-3,17,0,24)
Block(-3,17,1,24)
Block(-3,17,2,24)
Block(-3,17,3,24)
Block(-3,17,4,24)
Block(-3,17,5,24)
Block(-3,17,6,24)
Block(-3,17,7,24)
Block(-3,17,8,24)
Block(-3,17,9,24)
Block(-3,17,10,24)
Block(-3,17,11,24)
Block(-3,17,12,24)
Block(-3,17,13,24)
Block(-3,17,14,24)
Block(-3,17,15,24)
Block(-3,17,16,24)
Block(-3,17,17,24)
Block(-3,17,18,24)
Block(-3,18,-9,24)
Block(-3,18,-8,24)
Block(-3,18,-7,24)
Block(-3,18,-6,24)
Block(-3,18,-5,24)
Block(-3,18,-4,24)
Block(-3,18,-3,24)
Block(-3,18,-2,24)
Block(-3,18,-1,24)
Block(-3,18,0,24)
Block(-3,18,1,24)
Block(-3,18,2,24)
Block(-3,18,3,24)
Block(-3,18,4,24)
Block(-3,18,5,24)
Block(-3,18,6,24)
Block(-3,18,7,24)
Block(-3,18,8,24)
Block(-3,18,9,24)
Block(-3,18,10,24)
Block(-3,18,11,24)
Block(-3,18,12,24)
Block(-3,18,13,24)
Block(-3,18,14,24)
Block(-3,18,15,24)
Block(-3,18,16,24)
Block(-3,18,17,24)
Block(-3,18,18,24)
Block(-3,19,-10,24)
Block(-3,19,-9,24)
Block(-3,19,-8,24)
Block(-3,19,-7,24)
Block(-3,19,-6,24)
Block(-3,19,-5,24)
Block(-3,19,-4,24)
Block(-3,19,-3,24)
Block(-3,19,-2,24)
Block(-3,19,-1,24)
Block(-3,19,0,24)
Block(-3,19,1,24)
Block(-3,19,2,24)
Block(-3,19,3,24)
Block(-3,19,4,24)
Block(-3,19,5,24)
Block(-3,19,6,24)
Block(-3,19,7,24)
Block(-3,19,8,24)
Block(-3,19,9,24)
Block(-3,19,10,24)
Block(-3,19,11,24)
Block(-3,19,12,24)
Block(-3,19,13,24)
Block(-3,19,14,24)
Block(-3,19,15,24)
Block(-3,19,16,24)
Block(-3,19,17,24)
Block(-3,19,18,24)
Block(-3,20,-11,24)
Block(-3,20,-10,24)
Block(-3,20,-9,24)
Block(-3,20,-8,24)
Block(-3,20,-7,24)
Block(-3,20,-6,24)
Block(-3,20,-5,24)
Block(-3,20,-4,24)
Block(-3,20,-3,24)
Block(-3,20,-2,24)
Block(-3,20,-1,24)
Block(-3,20,0,24)
Block(-3,20,1,24)
Block(-3,20,2,24)
Block(-3,20,3,24)
Block(-3,20,4,24)
Block(-3,20,5,24)
Block(-3,20,6,24)
Block(-3,20,7,24)
Block(-3,20,8,24)
Block(-3,20,9,24)
Block(-3,20,10,24)
Block(-3,20,11,24)
Block(-3,20,12,24)
Block(-3,20,13,24)
Block(-3,20,14,24)
Block(-3,20,15,24)
Block(-3,20,16,24)
Block(-3,20,17,24)
Block(-3,21,-10,24)
Block(-3,21,-9,24)
Block(-3,21,-8,24)
Block(-3,21,-7,24)
Block(-3,21,-6,24)
Block(-3,21,-5,24)
Block(-3,21,-4,24)
Block(-3,21,-3,24)
Block(-3,21,-2,24)
Block(-3,21,-1,24)
Block(-3,21,0,24)
Block(-3,21,1,24)
Block(-3,21,2,24)
Block(-3,21,3,24)
Block(-3,21,4,24)
Block(-3,21,5,24)
Block(-3,21,6,24)
Block(-3,21,7,24)
Block(-3,21,8,24)
Block(-3,21,9,24)
Block(-3,21,10,24)
Block(-3,21,11,24)
Block(-3,21,12,24)
Block(-3,21,13,24)
Block(-3,21,14,24)
Block(-3,21,15,24)
Block(-3,21,16,24)
Block(-3,21,17,24)
Block(-3,22,-10,24)
Block(-3,22,-9,24)
Block(-3,22,-8,24)
Block(-3,22,-7,24)
Block(-3,22,-6,24)
Block(-3,22,-5,24)
Block(-3,22,-4,24)
Block(-3,22,-3,24)
Block(-3,22,-2,24)
Block(-3,22,-1,24)
Block(-3,22,0,24)
Block(-3,22,1,24)
Block(-3,22,2,24)
Block(-3,22,3,24)
Block(-3,22,4,24)
Block(-3,22,5,24)
Block(-3,22,6,24)
Block(-3,22,7,24)
Block(-3,22,8,24)
Block(-3,22,9,24)
Block(-3,22,10,24)
Block(-3,22,11,24)
Block(-3,22,12,24)
Block(-3,22,13,24)
Block(-3,22,14,24)
Block(-3,22,15,24)
Block(-3,22,16,24)
Block(-3,23,-9,24)
Block(-3,23,-8,24)
Block(-3,23,-7,24)
Block(-3,23,-6,24)
Block(-3,23,-5,24)
Block(-3,23,-4,24)
Block(-3,23,-3,24)
Block(-3,23,-2,24)
Block(-3,23,-1,24)
Block(-3,23,0,24)
Block(-3,23,1,24)
Block(-3,23,2,24)
Block(-3,23,3,24)
Block(-3,23,4,24)
Block(-3,23,5,24)
Block(-3,23,6,24)
Block(-3,23,7,24)
Block(-3,23,8,24)
Block(-3,23,9,24)
Block(-3,23,10,24)
Block(-3,23,11,24)
Block(-3,23,12,24)
Block(-3,23,13,24)
Block(-3,23,14,24)
Block(-3,23,15,24)
Block(-3,24,-8,24)
Block(-3,24,-7,24)
Block(-3,24,-6,24)
Block(-3,24,-5,24)
Block(-3,24,-4,24)
Block(-3,24,-3,24)
Block(-3,24,-2,24)
Block(-3,24,-1,24)
Block(-3,24,0,24)
Block(-3,24,1,24)
Block(-3,24,2,24)
Block(-3,24,3,24)
Block(-3,24,4,24)
Block(-3,24,5,24)
Block(-3,24,6,24)
Block(-3,24,7,24)
Block(-3,24,8,24)
Block(-3,24,9,24)
Block(-3,24,10,24)
Block(-3,24,11,24)
Block(-3,24,12,24)
Block(-3,24,13,24)
Block(-3,24,14,24)
Block(-3,24,15,24)
Block(-3,25,-8,24)
Block(-3,25,-7,24)
Block(-3,25,-6,24)
Block(-3,25,-5,24)
Block(-3,25,-4,24)
Block(-3,25,-3,24)
Block(-3,25,-2,24)
Block(-3,25,-1,24)
Block(-3,25,0,24)
Block(-3,25,1,24)
Block(-3,25,2,24)
Block(-3,25,3,24)
Block(-3,25,4,24)
Block(-3,25,5,24)
Block(-3,25,6,24)
Block(-3,25,7,24)
Block(-3,25,8,24)
Block(-3,25,9,24)
Block(-3,25,10,24)
Block(-3,25,11,24)
Block(-3,25,12,24)
Block(-3,25,13,24)
Block(-3,25,14,24)
Block(-3,26,-7,24)
Block(-3,26,-6,24)
Block(-3,26,-5,24)
Block(-3,26,-4,24)
Block(-3,26,-3,24)
Block(-3,26,-2,24)
Block(-3,26,-1,24)
Block(-3,26,0,24)
Block(-3,26,1,24)
Block(-3,26,2,24)
Block(-3,26,3,24)
Block(-3,26,4,24)
Block(-3,26,5,24)
Block(-3,26,6,24)
Block(-3,26,7,24)
Block(-3,26,8,24)
Block(-3,26,9,24)
Block(-3,26,10,24)
Block(-3,26,11,24)
Block(-3,26,12,24)
Block(-3,26,13,24)
Block(-3,26,14,24)
Block(-3,27,-6,24)
Block(-3,27,-5,24)
Block(-3,27,-4,24)
Block(-3,27,-3,24)
Block(-3,27,-2,24)
Block(-3,27,-1,24)
Block(-3,27,0,24)
Block(-3,27,1,24)
Block(-3,27,2,24)
Block(-3,27,3,24)
Block(-3,27,4,24)
Block(-3,27,5,24)
Block(-3,27,6,24)
Block(-3,27,7,24)
Block(-3,27,8,24)
Block(-3,27,9,24)
Block(-3,27,10,24)
Block(-3,27,11,24)
Block(-3,27,12,24)
Block(-3,27,13,24)
Block(-3,28,-5,24)
Block(-3,28,-4,24)
Block(-3,28,-3,24)
Block(-3,28,-2,24)
Block(-3,28,-1,24)
Block(-3,28,0,24)
Block(-3,28,1,24)
Block(-3,28,2,24)
Block(-3,28,3,24)
Block(-3,28,4,24)
Block(-3,28,5,24)
Block(-3,28,6,24)
Block(-3,28,7,24)
Block(-3,28,8,24)
Block(-3,28,9,24)
Block(-3,28,10,24)
Block(-3,28,11,24)
Block(-3,28,12,24)
Block(-3,29,-4,24)
Block(-3,29,-3,24)
Block(-3,29,-2,24)
Block(-3,29,-1,24)
Block(-3,29,0,24)
Block(-3,29,1,24)
Block(-3,29,2,24)
Block(-3,29,3,24)
Block(-3,29,4,24)
Block(-3,29,5,24)
Block(-3,29,6,24)
Block(-3,29,7,24)
Block(-3,29,8,24)
Block(-3,30,-3,24)
Block(-3,30,-2,24)
Block(-3,30,-1,24)
Block(-3,30,0,24)
Block(-3,30,1,24)
Block(-3,30,2,24)
Block(-3,30,3,24)
Block(-3,30,4,24)
Block(-3,30,5,24)
Block(-3,30,6,24)
Block(-3,31,-2,24)
Block(-3,31,-1,24)
Block(-3,31,0,24)
Block(-3,31,1,24)
Block(-3,31,2,24)
Block(-3,31,3,24)
Block(-3,31,4,24)
Block(-3,32,-2,24)
Block(-3,32,-1,24)
Block(-3,32,0,24)
Block(-3,32,1,24)
Block(-2,5,-3,24)
Block(-2,5,-2,24)
Block(-2,5,-1,24)
Block(-2,6,-4,24)
Block(-2,6,-3,24)
Block(-2,6,-2,24)
Block(-2,6,-1,24)
Block(-2,6,0,24)
Block(-2,6,1,24)
Block(-2,6,2,24)
Block(-2,7,-4,24)
Block(-2,7,-3,24)
Block(-2,7,-2,24)
Block(-2,7,-1,24)
Block(-2,7,0,24)
Block(-2,7,1,24)
Block(-2,7,2,24)
Block(-2,7,3,24)
Block(-2,7,4,24)
Block(-2,8,-4,24)
Block(-2,8,-3,24)
Block(-2,8,-2,24)
Block(-2,8,-1,24)
Block(-2,8,0,24)
Block(-2,8,1,24)
Block(-2,8,2,24)
Block(-2,8,3,24)
Block(-2,8,4,24)
Block(-2,8,5,24)
Block(-2,8,6,24)
Block(-2,8,7,24)
Block(-2,8,8,24)
Block(-2,8,9,24)
Block(-2,8,10,24)
Block(-2,8,11,24)
Block(-2,8,12,24)
Block(-2,9,-4,24)
Block(-2,9,-3,24)
Block(-2,9,-2,24)
Block(-2,9,-1,24)
Block(-2,9,0,24)
Block(-2,9,1,24)
Block(-2,9,2,24)
Block(-2,9,3,24)
Block(-2,9,4,24)
Block(-2,9,5,24)
Block(-2,9,6,24)
Block(-2,9,7,24)
Block(-2,9,8,24)
Block(-2,9,9,24)
Block(-2,9,10,24)
Block(-2,9,11,24)
Block(-2,9,12,24)
Block(-2,9,13,24)
Block(-2,10,-4,24)
Block(-2,10,-3,24)
Block(-2,10,-2,24)
Block(-2,10,-1,24)
Block(-2,10,0,24)
Block(-2,10,1,24)
Block(-2,10,2,24)
Block(-2,10,3,24)
Block(-2,10,4,24)
Block(-2,10,5,24)
Block(-2,10,6,24)
Block(-2,10,7,24)
Block(-2,10,8,24)
Block(-2,10,9,24)
Block(-2,10,10,24)
Block(-2,10,11,24)
Block(-2,10,12,24)
Block(-2,10,13,24)
Block(-2,10,14,24)
Block(-2,11,-5,24)
Block(-2,11,-4,24)
Block(-2,11,-3,24)
Block(-2,11,-2,24)
Block(-2,11,-1,24)
Block(-2,11,0,24)
Block(-2,11,1,24)
Block(-2,11,2,24)
Block(-2,11,3,24)
Block(-2,11,4,24)
Block(-2,11,5,24)
Block(-2,11,6,24)
Block(-2,11,7,24)
Block(-2,11,8,24)
Block(-2,11,9,24)
Block(-2,11,10,24)
Block(-2,11,11,24)
Block(-2,11,12,24)
Block(-2,11,13,24)
Block(-2,11,14,24)
Block(-2,11,15,24)
Block(-2,11,16,24)
Block(-2,12,-5,24)
Block(-2,12,-4,24)
Block(-2,12,-3,24)
Block(-2,12,-2,24)
Block(-2,12,-1,24)
Block(-2,12,0,24)
Block(-2,12,1,24)
Block(-2,12,2,24)
Block(-2,12,3,24)
Block(-2,12,4,24)
Block(-2,12,5,24)
Block(-2,12,6,24)
Block(-2,12,7,24)
Block(-2,12,8,24)
Block(-2,12,9,24)
Block(-2,12,10,24)
Block(-2,12,11,24)
Block(-2,12,12,24)
Block(-2,12,13,24)
Block(-2,12,14,24)
Block(-2,12,15,24)
Block(-2,12,16,24)
Block(-2,12,17,24)
Block(-2,13,-6,24)
Block(-2,13,-5,24)
Block(-2,13,-4,24)
Block(-2,13,-3,24)
Block(-2,13,-2,24)
Block(-2,13,-1,24)
Block(-2,13,0,24)
Block(-2,13,1,24)
Block(-2,13,2,24)
Block(-2,13,3,24)
Block(-2,13,4,24)
Block(-2,13,5,24)
Block(-2,13,6,24)
Block(-2,13,7,24)
Block(-2,13,8,24)
Block(-2,13,9,24)
Block(-2,13,10,24)
Block(-2,13,11,24)
Block(-2,13,12,24)
Block(-2,13,13,24)
Block(-2,13,14,24)
Block(-2,13,15,24)
Block(-2,13,16,24)
Block(-2,13,17,24)
Block(-2,14,-6,24)
Block(-2,14,-5,24)
Block(-2,14,-4,24)
Block(-2,14,-3,24)
Block(-2,14,-2,24)
Block(-2,14,-1,24)
Block(-2,14,0,24)
Block(-2,14,1,24)
Block(-2,14,2,24)
Block(-2,14,3,24)
Block(-2,14,4,24)
Block(-2,14,5,24)
Block(-2,14,6,24)
Block(-2,14,7,24)
Block(-2,14,8,24)
Block(-2,14,9,24)
Block(-2,14,10,24)
Block(-2,14,11,24)
Block(-2,14,12,24)
Block(-2,14,13,24)
Block(-2,14,14,24)
Block(-2,14,15,24)
Block(-2,14,16,24)
Block(-2,14,17,24)
Block(-2,14,18,24)
Block(-2,15,-7,24)
Block(-2,15,-6,24)
Block(-2,15,-5,24)
Block(-2,15,-4,24)
Block(-2,15,-3,24)
Block(-2,15,-2,24)
Block(-2,15,-1,24)
Block(-2,15,0,24)
Block(-2,15,1,24)
Block(-2,15,2,24)
Block(-2,15,3,24)
Block(-2,15,4,24)
Block(-2,15,5,24)
Block(-2,15,6,24)
Block(-2,15,7,24)
Block(-2,15,8,24)
Block(-2,15,9,24)
Block(-2,15,10,24)
Block(-2,15,11,24)
Block(-2,15,12,24)
Block(-2,15,13,24)
Block(-2,15,14,24)
Block(-2,15,15,24)
Block(-2,15,16,24)
Block(-2,15,17,24)
Block(-2,15,18,24)
Block(-2,16,-8,24)
Block(-2,16,-7,24)
Block(-2,16,-6,24)
Block(-2,16,-5,24)
Block(-2,16,-4,24)
Block(-2,16,-3,24)
Block(-2,16,-2,24)
Block(-2,16,-1,24)
Block(-2,16,0,24)
Block(-2,16,1,24)
Block(-2,16,2,24)
Block(-2,16,3,24)
Block(-2,16,4,24)
Block(-2,16,5,24)
Block(-2,16,6,24)
Block(-2,16,7,24)
Block(-2,16,8,24)
Block(-2,16,9,24)
Block(-2,16,10,24)
Block(-2,16,11,24)
Block(-2,16,12,24)
Block(-2,16,13,24)
Block(-2,16,14,24)
Block(-2,16,15,24)
Block(-2,16,16,24)
Block(-2,16,17,24)
Block(-2,16,18,24)
Block(-2,17,-9,24)
Block(-2,17,-8,24)
Block(-2,17,-7,24)
Block(-2,17,-6,24)
Block(-2,17,-5,24)
Block(-2,17,-4,24)
Block(-2,17,-3,24)
Block(-2,17,-2,24)
Block(-2,17,-1,24)
Block(-2,17,0,24)
Block(-2,17,1,24)
Block(-2,17,2,24)
Block(-2,17,3,24)
Block(-2,17,4,24)
Block(-2,17,5,24)
Block(-2,17,6,24)
Block(-2,17,7,24)
Block(-2,17,8,24)
Block(-2,17,9,24)
Block(-2,17,10,24)
Block(-2,17,11,24)
Block(-2,17,12,24)
Block(-2,17,13,24)
Block(-2,17,14,24)
Block(-2,17,15,24)
Block(-2,17,16,24)
Block(-2,17,17,24)
Block(-2,17,18,24)
Block(-2,18,-11,24)
Block(-2,18,-10,24)
Block(-2,18,-9,24)
Block(-2,18,-8,24)
Block(-2,18,-7,24)
Block(-2,18,-6,24)
Block(-2,18,-5,24)
Block(-2,18,-4,24)
Block(-2,18,-3,24)
Block(-2,18,-2,24)
Block(-2,18,-1,24)
Block(-2,18,0,24)
Block(-2,18,1,24)
Block(-2,18,2,24)
Block(-2,18,3,24)
Block(-2,18,4,24)
Block(-2,18,5,24)
Block(-2,18,6,24)
Block(-2,18,7,24)
Block(-2,18,8,24)
Block(-2,18,9,24)
Block(-2,18,10,24)
Block(-2,18,11,24)
Block(-2,18,12,24)
Block(-2,18,13,24)
Block(-2,18,14,24)
Block(-2,18,15,24)
Block(-2,18,16,24)
Block(-2,18,17,24)
Block(-2,18,18,24)
Block(-2,19,-10,24)
Block(-2,19,-9,24)
Block(-2,19,-8,24)
Block(-2,19,-7,24)
Block(-2,19,-6,24)
Block(-2,19,-5,24)
Block(-2,19,-4,24)
Block(-2,19,-3,24)
Block(-2,19,-2,24)
Block(-2,19,-1,24)
Block(-2,19,0,24)
Block(-2,19,1,24)
Block(-2,19,2,24)
Block(-2,19,3,24)
Block(-2,19,4,24)
Block(-2,19,5,24)
Block(-2,19,6,24)
Block(-2,19,7,24)
Block(-2,19,8,24)
Block(-2,19,9,24)
Block(-2,19,10,24)
Block(-2,19,11,24)
Block(-2,19,12,24)
Block(-2,19,13,24)
Block(-2,19,14,24)
Block(-2,19,15,24)
Block(-2,19,16,24)
Block(-2,19,17,24)
Block(-2,19,18,24)
Block(-2,19,19,24)
Block(-2,20,-10,24)
Block(-2,20,-9,24)
Block(-2,20,-8,24)
Block(-2,20,-7,24)
Block(-2,20,-6,24)
Block(-2,20,-5,24)
Block(-2,20,-4,24)
Block(-2,20,-3,24)
Block(-2,20,-2,24)
Block(-2,20,-1,24)
Block(-2,20,0,24)
Block(-2,20,1,24)
Block(-2,20,2,24)
Block(-2,20,3,24)
Block(-2,20,4,24)
Block(-2,20,5,24)
Block(-2,20,6,24)
Block(-2,20,7,24)
Block(-2,20,8,24)
Block(-2,20,9,24)
Block(-2,20,10,24)
Block(-2,20,11,24)
Block(-2,20,12,24)
Block(-2,20,13,24)
Block(-2,20,14,24)
Block(-2,20,15,24)
Block(-2,20,16,24)
Block(-2,20,17,24)
Block(-2,20,18,24)
Block(-2,21,-10,24)
Block(-2,21,-9,24)
Block(-2,21,-8,24)
Block(-2,21,-7,24)
Block(-2,21,-6,24)
Block(-2,21,-5,24)
Block(-2,21,-4,24)
Block(-2,21,-3,24)
Block(-2,21,-2,24)
Block(-2,21,-1,24)
Block(-2,21,0,24)
Block(-2,21,1,24)
Block(-2,21,2,24)
Block(-2,21,3,24)
Block(-2,21,4,24)
Block(-2,21,5,24)
Block(-2,21,6,24)
Block(-2,21,7,24)
Block(-2,21,8,24)
Block(-2,21,9,24)
Block(-2,21,10,24)
Block(-2,21,11,24)
Block(-2,21,12,24)
Block(-2,21,13,24)
Block(-2,21,14,24)
Block(-2,21,15,24)
Block(-2,21,16,24)
Block(-2,21,17,24)
Block(-2,22,-10,24)
Block(-2,22,-9,24)
Block(-2,22,-8,24)
Block(-2,22,-7,24)
Block(-2,22,-6,24)
Block(-2,22,-5,24)
Block(-2,22,-4,24)
Block(-2,22,-3,24)
Block(-2,22,-2,24)
Block(-2,22,-1,24)
Block(-2,22,0,24)
Block(-2,22,1,24)
Block(-2,22,2,24)
Block(-2,22,3,24)
Block(-2,22,4,24)
Block(-2,22,5,24)
Block(-2,22,6,24)
Block(-2,22,7,24)
Block(-2,22,8,24)
Block(-2,22,9,24)
Block(-2,22,10,24)
Block(-2,22,11,24)
Block(-2,22,12,24)
Block(-2,22,13,24)
Block(-2,22,14,24)
Block(-2,22,15,24)
Block(-2,22,16,24)
Block(-2,23,-9,24)
Block(-2,23,-8,24)
Block(-2,23,-7,24)
Block(-2,23,-6,24)
Block(-2,23,-5,24)
Block(-2,23,-4,24)
Block(-2,23,-3,24)
Block(-2,23,-2,24)
Block(-2,23,-1,24)
Block(-2,23,0,24)
Block(-2,23,1,24)
Block(-2,23,2,24)
Block(-2,23,3,24)
Block(-2,23,4,24)
Block(-2,23,5,24)
Block(-2,23,6,24)
Block(-2,23,7,24)
Block(-2,23,8,24)
Block(-2,23,9,24)
Block(-2,23,10,24)
Block(-2,23,11,24)
Block(-2,23,12,24)
Block(-2,23,13,24)
Block(-2,23,14,24)
Block(-2,23,15,24)
Block(-2,23,16,24)
Block(-2,24,-8,24)
Block(-2,24,-7,24)
Block(-2,24,-6,24)
Block(-2,24,-5,24)
Block(-2,24,-4,24)
Block(-2,24,-3,24)
Block(-2,24,-2,24)
Block(-2,24,-1,24)
Block(-2,24,0,24)
Block(-2,24,1,24)
Block(-2,24,2,24)
Block(-2,24,3,24)
Block(-2,24,4,24)
Block(-2,24,5,24)
Block(-2,24,6,24)
Block(-2,24,7,24)
Block(-2,24,8,24)
Block(-2,24,9,24)
Block(-2,24,10,24)
Block(-2,24,11,24)
Block(-2,24,12,24)
Block(-2,24,13,24)
Block(-2,24,14,24)
Block(-2,24,15,24)
Block(-2,25,-7,24)
Block(-2,25,-6,24)
Block(-2,25,-5,24)
Block(-2,25,-4,24)
Block(-2,25,-3,24)
Block(-2,25,-2,24)
Block(-2,25,-1,24)
Block(-2,25,0,24)
Block(-2,25,1,24)
Block(-2,25,2,24)
Block(-2,25,3,24)
Block(-2,25,4,24)
Block(-2,25,5,24)
Block(-2,25,6,24)
Block(-2,25,7,24)
Block(-2,25,8,24)
Block(-2,25,9,24)
Block(-2,25,10,24)
Block(-2,25,11,24)
Block(-2,25,12,24)
Block(-2,25,13,24)
Block(-2,25,14,24)
Block(-2,25,15,24)
Block(-2,26,-6,24)
Block(-2,26,-5,24)
Block(-2,26,-4,24)
Block(-2,26,-3,24)
Block(-2,26,-2,24)
Block(-2,26,-1,24)
Block(-2,26,0,24)
Block(-2,26,1,24)
Block(-2,26,2,24)
Block(-2,26,3,24)
Block(-2,26,4,24)
Block(-2,26,5,24)
Block(-2,26,6,24)
Block(-2,26,7,24)
Block(-2,26,8,24)
Block(-2,26,9,24)
Block(-2,26,10,24)
Block(-2,26,11,24)
Block(-2,26,12,24)
Block(-2,26,13,24)
Block(-2,26,14,24)
Block(-2,27,-6,24)
Block(-2,27,-5,24)
Block(-2,27,-4,24)
Block(-2,27,-3,24)
Block(-2,27,-2,24)
Block(-2,27,-1,24)
Block(-2,27,0,24)
Block(-2,27,1,24)
Block(-2,27,2,24)
Block(-2,27,3,24)
Block(-2,27,4,24)
Block(-2,27,5,24)
Block(-2,27,6,24)
Block(-2,27,7,24)
Block(-2,27,8,24)
Block(-2,27,9,24)
Block(-2,27,10,24)
Block(-2,27,11,24)
Block(-2,27,12,24)
Block(-2,27,13,24)
Block(-2,27,14,24)
Block(-2,28,-5,24)
Block(-2,28,-4,24)
Block(-2,28,-3,24)
Block(-2,28,-2,24)
Block(-2,28,-1,24)
Block(-2,28,0,24)
Block(-2,28,1,24)
Block(-2,28,2,24)
Block(-2,28,3,24)
Block(-2,28,4,24)
Block(-2,28,5,24)
Block(-2,28,6,24)
Block(-2,28,7,24)
Block(-2,28,8,24)
Block(-2,28,9,24)
Block(-2,28,10,24)
Block(-2,28,11,24)
Block(-2,28,12,24)
Block(-2,28,13,24)
Block(-2,29,-4,24)
Block(-2,29,-3,24)
Block(-2,29,-2,24)
Block(-2,29,-1,24)
Block(-2,29,0,24)
Block(-2,29,1,24)
Block(-2,29,2,24)
Block(-2,29,3,24)
Block(-2,29,4,24)
Block(-2,29,5,24)
Block(-2,29,6,24)
Block(-2,29,7,24)
Block(-2,29,8,24)
Block(-2,29,9,24)
Block(-2,30,-3,24)
Block(-2,30,-2,24)
Block(-2,30,-1,24)
Block(-2,30,0,24)
Block(-2,30,1,24)
Block(-2,30,2,24)
Block(-2,30,3,24)
Block(-2,30,4,24)
Block(-2,30,5,24)
Block(-2,30,6,24)
Block(-2,30,7,24)
Block(-2,31,-2,24)
Block(-2,31,-1,24)
Block(-2,31,0,24)
Block(-2,31,1,24)
Block(-2,31,2,24)
Block(-2,31,3,24)
Block(-2,31,4,24)
Block(-2,31,5,24)
Block(-2,32,-1,24)
Block(-2,32,0,24)
Block(-2,32,1,24)
Block(-2,32,2,24)
Block(-1,5,-2,24)
Block(-1,5,-1,24)
Block(-1,5,0,24)
Block(-1,6,-3,24)
Block(-1,6,-2,24)
Block(-1,6,-1,24)
Block(-1,6,0,24)
Block(-1,6,1,24)
Block(-1,6,2,24)
Block(-1,6,3,24)
Block(-1,7,-5,24)
Block(-1,7,-4,24)
Block(-1,7,-3,24)
Block(-1,7,-2,24)
Block(-1,7,-1,24)
Block(-1,7,0,24)
Block(-1,7,1,24)
Block(-1,7,2,24)
Block(-1,7,3,24)
Block(-1,7,4,24)
Block(-1,7,5,24)
Block(-1,7,6,24)
Block(-1,8,-5,24)
Block(-1,8,-4,24)
Block(-1,8,-3,24)
Block(-1,8,-2,24)
Block(-1,8,-1,24)
Block(-1,8,0,24)
Block(-1,8,1,24)
Block(-1,8,2,24)
Block(-1,8,3,24)
Block(-1,8,4,24)
Block(-1,8,5,24)
Block(-1,8,6,24)
Block(-1,8,7,24)
Block(-1,8,8,24)
Block(-1,8,9,24)
Block(-1,8,10,24)
Block(-1,8,11,24)
Block(-1,8,12,24)
Block(-1,9,-6,24)
Block(-1,9,-5,24)
Block(-1,9,-4,24)
Block(-1,9,-3,24)
Block(-1,9,-2,24)
Block(-1,9,-1,24)
Block(-1,9,0,24)
Block(-1,9,1,24)
Block(-1,9,2,24)
Block(-1,9,3,24)
Block(-1,9,4,24)
Block(-1,9,5,24)
Block(-1,9,6,24)
Block(-1,9,7,24)
Block(-1,9,8,24)
Block(-1,9,9,24)
Block(-1,9,10,24)
Block(-1,9,11,24)
Block(-1,9,12,24)
Block(-1,9,13,24)
Block(-1,10,-6,24)
Block(-1,10,-5,24)
Block(-1,10,-4,24)
Block(-1,10,-3,24)
Block(-1,10,-2,24)
Block(-1,10,-1,24)
Block(-1,10,0,24)
Block(-1,10,1,24)
Block(-1,10,2,24)
Block(-1,10,3,24)
Block(-1,10,4,24)
Block(-1,10,5,24)
Block(-1,10,6,24)
Block(-1,10,7,24)
Block(-1,10,8,24)
Block(-1,10,9,24)
Block(-1,10,10,24)
Block(-1,10,11,24)
Block(-1,10,12,24)
Block(-1,10,13,24)
Block(-1,10,14,24)
Block(-1,10,15,24)
Block(-1,11,-7,24)
Block(-1,11,-6,24)
Block(-1,11,-5,24)
Block(-1,11,-4,24)
Block(-1,11,-3,24)
Block(-1,11,-2,24)
Block(-1,11,-1,24)
Block(-1,11,0,24)
Block(-1,11,1,24)
Block(-1,11,2,24)
Block(-1,11,3,24)
Block(-1,11,4,24)
Block(-1,11,5,24)
Block(-1,11,6,24)
Block(-1,11,7,24)
Block(-1,11,8,24)
Block(-1,11,9,24)
Block(-1,11,10,24)
Block(-1,11,11,24)
Block(-1,11,12,24)
Block(-1,11,13,24)
Block(-1,11,14,24)
Block(-1,11,15,24)
Block(-1,11,16,24)
Block(-1,12,-7,24)
Block(-1,12,-6,24)
Block(-1,12,-5,24)
Block(-1,12,-4,24)
Block(-1,12,-3,24)
Block(-1,12,-2,24)
Block(-1,12,-1,24)
Block(-1,12,0,24)
Block(-1,12,1,24)
Block(-1,12,2,24)
Block(-1,12,3,24)
Block(-1,12,4,24)
Block(-1,12,5,24)
Block(-1,12,6,24)
Block(-1,12,7,24)
Block(-1,12,8,24)
Block(-1,12,9,24)
Block(-1,12,10,24)
Block(-1,12,11,24)
Block(-1,12,12,24)
Block(-1,12,13,24)
Block(-1,12,14,24)
Block(-1,12,15,24)
Block(-1,12,16,24)
Block(-1,12,17,24)
Block(-1,12,18,24)
Block(-1,13,-7,24)
Block(-1,13,-6,24)
Block(-1,13,-5,24)
Block(-1,13,-4,24)
Block(-1,13,-3,24)
Block(-1,13,-2,24)
Block(-1,13,-1,24)
Block(-1,13,0,24)
Block(-1,13,1,24)
Block(-1,13,2,24)
Block(-1,13,3,24)
Block(-1,13,4,24)
Block(-1,13,5,24)
Block(-1,13,6,24)
Block(-1,13,7,24)
Block(-1,13,8,24)
Block(-1,13,9,24)
Block(-1,13,10,24)
Block(-1,13,11,24)
Block(-1,13,12,24)
Block(-1,13,13,24)
Block(-1,13,14,24)
Block(-1,13,15,24)
Block(-1,13,16,24)
Block(-1,13,17,24)
Block(-1,13,18,24)
Block(-1,14,-8,24)
Block(-1,14,-7,24)
Block(-1,14,-6,24)
Block(-1,14,-5,24)
Block(-1,14,-4,24)
Block(-1,14,-3,24)
Block(-1,14,-2,24)
Block(-1,14,-1,24)
Block(-1,14,0,24)
Block(-1,14,1,24)
Block(-1,14,2,24)
Block(-1,14,3,24)
Block(-1,14,4,24)
Block(-1,14,5,24)
Block(-1,14,6,24)
Block(-1,14,7,24)
Block(-1,14,8,24)
Block(-1,14,9,24)
Block(-1,14,10,24)
Block(-1,14,11,24)
Block(-1,14,12,24)
Block(-1,14,13,24)
Block(-1,14,14,24)
Block(-1,14,15,24)
Block(-1,14,16,24)
Block(-1,14,17,24)
Block(-1,14,18,24)
Block(-1,15,-9,24)
Block(-1,15,-8,24)
Block(-1,15,-7,24)
Block(-1,15,-6,24)
Block(-1,15,-5,24)
Block(-1,15,-4,24)
Block(-1,15,-3,24)
Block(-1,15,-2,24)
Block(-1,15,-1,24)
Block(-1,15,0,24)
Block(-1,15,1,24)
Block(-1,15,2,24)
Block(-1,15,3,24)
Block(-1,15,4,24)
Block(-1,15,5,24)
Block(-1,15,6,24)
Block(-1,15,7,24)
Block(-1,15,8,24)
Block(-1,15,9,24)
Block(-1,15,10,24)
Block(-1,15,11,24)
Block(-1,15,12,24)
Block(-1,15,13,24)
Block(-1,15,14,24)
Block(-1,15,15,24)
Block(-1,15,16,24)
Block(-1,15,17,24)
Block(-1,15,18,24)
Block(-1,16,-10,24)
Block(-1,16,-9,24)
Block(-1,16,-8,24)
Block(-1,16,-7,24)
Block(-1,16,-6,24)
Block(-1,16,-5,24)
Block(-1,16,-4,24)
Block(-1,16,-3,24)
Block(-1,16,-2,24)
Block(-1,16,-1,24)
Block(-1,16,0,24)
Block(-1,16,1,24)
Block(-1,16,2,24)
Block(-1,16,3,24)
Block(-1,16,4,24)
Block(-1,16,5,24)
Block(-1,16,6,24)
Block(-1,16,7,24)
Block(-1,16,8,24)
Block(-1,16,9,24)
Block(-1,16,10,24)
Block(-1,16,11,24)
Block(-1,16,12,24)
Block(-1,16,13,24)
Block(-1,16,14,24)
Block(-1,16,15,24)
Block(-1,16,16,24)
Block(-1,16,17,24)
Block(-1,16,18,24)
Block(-1,17,-10,24)
Block(-1,17,-9,24)
Block(-1,17,-8,24)
Block(-1,17,-7,24)
Block(-1,17,-6,24)
Block(-1,17,-5,24)
Block(-1,17,-4,24)
Block(-1,17,-3,24)
Block(-1,17,-2,24)
Block(-1,17,-1,24)
Block(-1,17,0,24)
Block(-1,17,1,24)
Block(-1,17,2,24)
Block(-1,17,3,24)
Block(-1,17,4,24)
Block(-1,17,5,24)
Block(-1,17,6,24)
Block(-1,17,7,24)
Block(-1,17,8,24)
Block(-1,17,9,24)
Block(-1,17,10,24)
Block(-1,17,11,24)
Block(-1,17,12,24)
Block(-1,17,13,24)
Block(-1,17,14,24)
Block(-1,17,15,24)
Block(-1,17,16,24)
Block(-1,17,17,24)
Block(-1,17,18,24)
Block(-1,18,-10,24)
Block(-1,18,-9,24)
Block(-1,18,-8,24)
Block(-1,18,-7,24)
Block(-1,18,-6,24)
Block(-1,18,-5,24)
Block(-1,18,-4,24)
Block(-1,18,-3,24)
Block(-1,18,-2,24)
Block(-1,18,-1,24)
Block(-1,18,0,24)
Block(-1,18,1,24)
Block(-1,18,2,24)
Block(-1,18,3,24)
Block(-1,18,4,24)
Block(-1,18,5,24)
Block(-1,18,6,24)
Block(-1,18,7,24)
Block(-1,18,8,24)
Block(-1,18,9,24)
Block(-1,18,10,24)
Block(-1,18,11,24)
Block(-1,18,12,24)
Block(-1,18,13,24)
Block(-1,18,14,24)
Block(-1,18,15,24)
Block(-1,18,16,24)
Block(-1,18,17,24)
Block(-1,18,18,24)
Block(-1,18,19,24)
Block(-1,19,-10,24)
Block(-1,19,-9,24)
Block(-1,19,-8,24)
Block(-1,19,-7,24)
Block(-1,19,-6,24)
Block(-1,19,-5,24)
Block(-1,19,-4,24)
Block(-1,19,-3,24)
Block(-1,19,-2,24)
Block(-1,19,-1,24)
Block(-1,19,0,24)
Block(-1,19,1,24)
Block(-1,19,2,24)
Block(-1,19,3,24)
Block(-1,19,4,24)
Block(-1,19,5,24)
Block(-1,19,6,24)
Block(-1,19,7,24)
Block(-1,19,8,24)
Block(-1,19,9,24)
Block(-1,19,10,24)
Block(-1,19,11,24)
Block(-1,19,12,24)
Block(-1,19,13,24)
Block(-1,19,14,24)
Block(-1,19,15,24)
Block(-1,19,16,24)
Block(-1,19,17,24)
Block(-1,19,18,24)
Block(-1,19,19,24)
Block(-1,20,-10,24)
Block(-1,20,-9,24)
Block(-1,20,-8,24)
Block(-1,20,-7,24)
Block(-1,20,-6,24)
Block(-1,20,-5,24)
Block(-1,20,-4,24)
Block(-1,20,-3,24)
Block(-1,20,-2,24)
Block(-1,20,-1,24)
Block(-1,20,0,24)
Block(-1,20,1,24)
Block(-1,20,2,24)
Block(-1,20,3,24)
Block(-1,20,4,24)
Block(-1,20,5,24)
Block(-1,20,6,24)
Block(-1,20,7,24)
Block(-1,20,8,24)
Block(-1,20,9,24)
Block(-1,20,10,24)
Block(-1,20,11,24)
Block(-1,20,12,24)
Block(-1,20,13,24)
Block(-1,20,14,24)
Block(-1,20,15,24)
Block(-1,20,16,24)
Block(-1,20,17,24)
Block(-1,20,18,24)
Block(-1,20,19,24)
Block(-1,21,-10,24)
Block(-1,21,-9,24)
Block(-1,21,-8,24)
Block(-1,21,-7,24)
Block(-1,21,-6,24)
Block(-1,21,-5,24)
Block(-1,21,-4,24)
Block(-1,21,-3,24)
Block(-1,21,-2,24)
Block(-1,21,-1,24)
Block(-1,21,0,24)
Block(-1,21,1,24)
Block(-1,21,2,24)
Block(-1,21,3,24)
Block(-1,21,4,24)
Block(-1,21,5,24)
Block(-1,21,6,24)
Block(-1,21,7,24)
Block(-1,21,8,24)
Block(-1,21,9,24)
Block(-1,21,10,24)
Block(-1,21,11,24)
Block(-1,21,12,24)
Block(-1,21,13,24)
Block(-1,21,14,24)
Block(-1,21,15,24)
Block(-1,21,16,24)
Block(-1,21,17,24)
Block(-1,21,18,24)
Block(-1,22,-9,24)
Block(-1,22,-8,24)
Block(-1,22,-7,24)
Block(-1,22,-6,24)
Block(-1,22,-5,24)
Block(-1,22,-4,24)
Block(-1,22,-3,24)
Block(-1,22,-2,24)
Block(-1,22,-1,24)
Block(-1,22,0,24)
Block(-1,22,1,24)
Block(-1,22,2,24)
Block(-1,22,3,24)
Block(-1,22,4,24)
Block(-1,22,5,24)
Block(-1,22,6,24)
Block(-1,22,7,24)
Block(-1,22,8,24)
Block(-1,22,9,24)
Block(-1,22,10,24)
Block(-1,22,11,24)
Block(-1,22,12,24)
Block(-1,22,13,24)
Block(-1,22,14,24)
Block(-1,22,15,24)
Block(-1,22,16,24)
Block(-1,22,17,24)
Block(-1,23,-9,24)
Block(-1,23,-8,24)
Block(-1,23,-7,24)
Block(-1,23,-6,24)
Block(-1,23,-5,24)
Block(-1,23,-4,24)
Block(-1,23,-3,24)
Block(-1,23,-2,24)
Block(-1,23,-1,24)
Block(-1,23,0,24)
Block(-1,23,1,24)
Block(-1,23,2,24)
Block(-1,23,3,24)
Block(-1,23,4,24)
Block(-1,23,5,24)
Block(-1,23,6,24)
Block(-1,23,7,24)
Block(-1,23,8,24)
Block(-1,23,9,24)
Block(-1,23,10,24)
Block(-1,23,11,24)
Block(-1,23,12,24)
Block(-1,23,13,24)
Block(-1,23,14,24)
Block(-1,23,15,24)
Block(-1,23,16,24)
Block(-1,24,-8,24)
Block(-1,24,-7,24)
Block(-1,24,-6,24)
Block(-1,24,-5,24)
Block(-1,24,-4,24)
Block(-1,24,-3,24)
Block(-1,24,-2,24)
Block(-1,24,-1,24)
Block(-1,24,0,24)
Block(-1,24,1,24)
Block(-1,24,2,24)
Block(-1,24,3,24)
Block(-1,24,4,24)
Block(-1,24,5,24)
Block(-1,24,6,24)
Block(-1,24,7,24)
Block(-1,24,8,24)
Block(-1,24,9,24)
Block(-1,24,10,24)
Block(-1,24,11,24)
Block(-1,24,12,24)
Block(-1,24,13,24)
Block(-1,24,14,24)
Block(-1,24,15,24)
Block(-1,24,16,24)
Block(-1,25,-7,24)
Block(-1,25,-6,24)
Block(-1,25,-5,24)
Block(-1,25,-4,24)
Block(-1,25,-3,24)
Block(-1,25,-2,24)
Block(-1,25,-1,24)
Block(-1,25,0,24)
Block(-1,25,1,24)
Block(-1,25,2,24)
Block(-1,25,3,24)
Block(-1,25,4,24)
Block(-1,25,5,24)
Block(-1,25,6,24)
Block(-1,25,7,24)
Block(-1,25,8,24)
Block(-1,25,9,24)
Block(-1,25,10,24)
Block(-1,25,11,24)
Block(-1,25,12,24)
Block(-1,25,13,24)
Block(-1,25,14,24)
Block(-1,25,15,24)
Block(-1,26,-6,24)
Block(-1,26,-5,24)
Block(-1,26,-4,24)
Block(-1,26,-3,24)
Block(-1,26,-2,24)
Block(-1,26,-1,24)
Block(-1,26,0,24)
Block(-1,26,1,24)
Block(-1,26,2,24)
Block(-1,26,3,24)
Block(-1,26,4,24)
Block(-1,26,5,24)
Block(-1,26,6,24)
Block(-1,26,7,24)
Block(-1,26,8,24)
Block(-1,26,9,24)
Block(-1,26,10,24)
Block(-1,26,11,24)
Block(-1,26,12,24)
Block(-1,26,13,24)
Block(-1,26,14,24)
Block(-1,26,15,24)
Block(-1,27,-5,24)
Block(-1,27,-4,24)
Block(-1,27,-3,24)
Block(-1,27,-2,24)
Block(-1,27,-1,24)
Block(-1,27,0,24)
Block(-1,27,1,24)
Block(-1,27,2,24)
Block(-1,27,3,24)
Block(-1,27,4,24)
Block(-1,27,5,24)
Block(-1,27,6,24)
Block(-1,27,7,24)
Block(-1,27,8,24)
Block(-1,27,9,24)
Block(-1,27,10,24)
Block(-1,27,11,24)
Block(-1,27,12,24)
Block(-1,27,13,24)
Block(-1,27,14,24)
Block(-1,28,-4,24)
Block(-1,28,-3,24)
Block(-1,28,-2,24)
Block(-1,28,-1,24)
Block(-1,28,0,24)
Block(-1,28,1,24)
Block(-1,28,2,24)
Block(-1,28,3,24)
Block(-1,28,4,24)
Block(-1,28,5,24)
Block(-1,28,6,24)
Block(-1,28,7,24)
Block(-1,28,8,24)
Block(-1,28,9,24)
Block(-1,28,10,24)
Block(-1,28,11,24)
Block(-1,28,12,24)
Block(-1,28,13,24)
Block(-1,28,14,24)
Block(-1,29,-3,24)
Block(-1,29,-2,24)
Block(-1,29,-1,24)
Block(-1,29,0,24)
Block(-1,29,1,24)
Block(-1,29,2,24)
Block(-1,29,3,24)
Block(-1,29,4,24)
Block(-1,29,5,24)
Block(-1,29,6,24)
Block(-1,29,7,24)
Block(-1,29,8,24)
Block(-1,29,9,24)
Block(-1,29,10,24)
Block(-1,29,11,24)
Block(-1,29,12,24)
Block(-1,30,-3,24)
Block(-1,30,-2,24)
Block(-1,30,-1,24)
Block(-1,30,0,24)
Block(-1,30,1,24)
Block(-1,30,2,24)
Block(-1,30,3,24)
Block(-1,30,4,24)
Block(-1,30,5,24)
Block(-1,30,6,24)
Block(-1,30,7,24)
Block(-1,30,8,24)
Block(-1,31,-2,24)
Block(-1,31,-1,24)
Block(-1,31,0,24)
Block(-1,31,1,24)
Block(-1,31,2,24)
Block(-1,31,3,24)
Block(-1,31,4,24)
Block(-1,31,5,24)
Block(-1,31,6,24)
Block(-1,32,-1,24)
Block(-1,32,0,24)
Block(-1,32,1,24)
Block(-1,32,2,24)
Block(-1,32,3,24)
Block(-1,32,4,24)
Block(-1,33,0,24)
Block(0,5,-1,24)
Block(0,5,0,24)
Block(0,5,1,24)
Block(0,5,2,24)
Block(0,6,-3,24)
Block(0,6,-2,24)
Block(0,6,-1,24)
Block(0,6,0,24)
Block(0,6,1,24)
Block(0,6,2,24)
Block(0,6,3,24)
Block(0,6,4,24)
Block(0,6,5,24)
Block(0,7,-4,24)
Block(0,7,-3,24)
Block(0,7,-2,24)
Block(0,7,-1,24)
Block(0,7,0,24)
Block(0,7,1,24)
Block(0,7,2,24)
Block(0,7,3,24)
Block(0,7,4,24)
Block(0,7,5,24)
Block(0,7,6,24)
Block(0,7,7,24)
Block(0,7,8,24)
Block(0,7,9,24)
Block(0,7,10,24)
Block(0,7,11,24)
Block(0,8,-5,24)
Block(0,8,-4,24)
Block(0,8,-3,24)
Block(0,8,-2,24)
Block(0,8,-1,24)
Block(0,8,0,24)
Block(0,8,1,24)
Block(0,8,2,24)
Block(0,8,3,24)
Block(0,8,4,24)
Block(0,8,5,24)
Block(0,8,6,24)
Block(0,8,7,24)
Block(0,8,8,24)
Block(0,8,9,24)
Block(0,8,10,24)
Block(0,8,11,24)
Block(0,8,12,24)
Block(0,9,-6,24)
Block(0,9,-5,24)
Block(0,9,-4,24)
Block(0,9,-3,24)
Block(0,9,-2,24)
Block(0,9,-1,24)
Block(0,9,0,24)
Block(0,9,1,24)
Block(0,9,2,24)
Block(0,9,3,24)
Block(0,9,4,24)
Block(0,9,5,24)
Block(0,9,6,24)
Block(0,9,7,24)
Block(0,9,8,24)
Block(0,9,9,24)
Block(0,9,10,24)
Block(0,9,11,24)
Block(0,9,12,24)
Block(0,9,13,24)
Block(0,10,-7,24)
Block(0,10,-6,24)
Block(0,10,-5,24)
Block(0,10,-4,24)
Block(0,10,-3,24)
Block(0,10,-2,24)
Block(0,10,-1,24)
Block(0,10,0,24)
Block(0,10,1,24)
Block(0,10,2,24)
Block(0,10,3,24)
Block(0,10,4,24)
Block(0,10,5,24)
Block(0,10,6,24)
Block(0,10,7,24)
Block(0,10,8,24)
Block(0,10,9,24)
Block(0,10,10,24)
Block(0,10,11,24)
Block(0,10,12,24)
Block(0,10,13,24)
Block(0,10,14,24)
Block(0,10,15,24)
Block(0,11,-8,24)
Block(0,11,-7,24)
Block(0,11,-6,24)
Block(0,11,-5,24)
Block(0,11,-4,24)
Block(0,11,-3,24)
Block(0,11,-2,24)
Block(0,11,-1,24)
Block(0,11,0,24)
Block(0,11,1,24)
Block(0,11,2,24)
Block(0,11,3,24)
Block(0,11,4,24)
Block(0,11,5,24)
Block(0,11,6,24)
Block(0,11,7,24)
Block(0,11,8,24)
Block(0,11,9,24)
Block(0,11,10,24)
Block(0,11,11,24)
Block(0,11,12,24)
Block(0,11,13,24)
Block(0,11,14,24)
Block(0,11,15,24)
Block(0,11,16,24)
Block(0,11,17,24)
Block(0,12,-9,24)
Block(0,12,-8,24)
Block(0,12,-7,24)
Block(0,12,-6,24)
Block(0,12,-5,24)
Block(0,12,-4,24)
Block(0,12,-3,24)
Block(0,12,-2,24)
Block(0,12,-1,24)
Block(0,12,0,24)
Block(0,12,1,24)
Block(0,12,2,24)
Block(0,12,3,24)
Block(0,12,4,24)
Block(0,12,5,24)
Block(0,12,6,24)
Block(0,12,7,24)
Block(0,12,8,24)
Block(0,12,9,24)
Block(0,12,10,24)
Block(0,12,11,24)
Block(0,12,12,24)
Block(0,12,13,24)
Block(0,12,14,24)
Block(0,12,15,24)
Block(0,12,16,24)
Block(0,12,17,24)
Block(0,12,18,24)
Block(0,13,-9,24)
Block(0,13,-8,24)
Block(0,13,-7,24)
Block(0,13,-6,24)
Block(0,13,-5,24)
Block(0,13,-4,24)
Block(0,13,-3,24)
Block(0,13,-2,24)
Block(0,13,-1,24)
Block(0,13,0,24)
Block(0,13,1,24)
Block(0,13,2,24)
Block(0,13,3,24)
Block(0,13,4,24)
Block(0,13,5,24)
Block(0,13,6,24)
Block(0,13,7,24)
Block(0,13,8,24)
Block(0,13,9,24)
Block(0,13,10,24)
Block(0,13,11,24)
Block(0,13,12,24)
Block(0,13,13,24)
Block(0,13,14,24)
Block(0,13,15,24)
Block(0,13,16,24)
Block(0,13,17,24)
Block(0,13,18,24)
Block(0,14,-9,24)
Block(0,14,-8,24)
Block(0,14,-7,24)
Block(0,14,-6,24)
Block(0,14,-5,24)
Block(0,14,-4,24)
Block(0,14,-3,24)
Block(0,14,-2,24)
Block(0,14,-1,24)
Block(0,14,0,24)
Block(0,14,1,24)
Block(0,14,2,24)
Block(0,14,3,24)
Block(0,14,4,24)
Block(0,14,5,24)
Block(0,14,6,24)
Block(0,14,7,24)
Block(0,14,8,24)
Block(0,14,9,24)
Block(0,14,10,24)
Block(0,14,11,24)
Block(0,14,12,24)
Block(0,14,13,24)
Block(0,14,14,24)
Block(0,14,15,24)
Block(0,14,16,24)
Block(0,14,17,24)
Block(0,14,18,24)
Block(0,15,-10,24)
Block(0,15,-9,24)
Block(0,15,-8,24)
Block(0,15,-7,24)
Block(0,15,-6,24)
Block(0,15,-5,24)
Block(0,15,-4,24)
Block(0,15,-3,24)
Block(0,15,-2,24)
Block(0,15,-1,24)
Block(0,15,0,24)
Block(0,15,1,24)
Block(0,15,2,24)
Block(0,15,3,24)
Block(0,15,4,24)
Block(0,15,5,24)
Block(0,15,6,24)
Block(0,15,7,24)
Block(0,15,8,24)
Block(0,15,9,24)
Block(0,15,10,24)
Block(0,15,11,24)
Block(0,15,12,24)
Block(0,15,13,24)
Block(0,15,14,24)
Block(0,15,15,24)
Block(0,15,16,24)
Block(0,15,17,24)
Block(0,15,18,24)
Block(0,16,-10,24)
Block(0,16,-9,24)
Block(0,16,-8,24)
Block(0,16,-7,24)
Block(0,16,-6,24)
Block(0,16,-5,24)
Block(0,16,-4,24)
Block(0,16,-3,24)
Block(0,16,-2,24)
Block(0,16,-1,24)
Block(0,16,0,24)
Block(0,16,1,24)
Block(0,16,2,24)
Block(0,16,3,24)
Block(0,16,4,24)
Block(0,16,5,24)
Block(0,16,6,24)
Block(0,16,7,24)
Block(0,16,8,24)
Block(0,16,9,24)
Block(0,16,10,24)
Block(0,16,11,24)
Block(0,16,12,24)
Block(0,16,13,24)
Block(0,16,14,24)
Block(0,16,15,24)
Block(0,16,16,24)
Block(0,16,17,24)
Block(0,16,18,24)
Block(0,17,-10,24)
Block(0,17,-9,24)
Block(0,17,-8,24)
Block(0,17,-7,24)
Block(0,17,-6,24)
Block(0,17,-5,24)
Block(0,17,-4,24)
Block(0,17,-3,24)
Block(0,17,-2,24)
Block(0,17,-1,24)
Block(0,17,0,24)
Block(0,17,1,24)
Block(0,17,2,24)
Block(0,17,3,24)
Block(0,17,4,24)
Block(0,17,5,24)
Block(0,17,6,24)
Block(0,17,7,24)
Block(0,17,8,24)
Block(0,17,9,24)
Block(0,17,10,24)
Block(0,17,11,24)
Block(0,17,12,24)
Block(0,17,13,24)
Block(0,17,14,24)
Block(0,17,15,24)
Block(0,17,16,24)
Block(0,17,17,24)
Block(0,17,18,24)
Block(0,18,-10,24)
Block(0,18,-9,24)
Block(0,18,-8,24)
Block(0,18,-7,24)
Block(0,18,-6,24)
Block(0,18,-5,24)
Block(0,18,-4,24)
Block(0,18,-3,24)
Block(0,18,-2,24)
Block(0,18,-1,24)
Block(0,18,0,24)
Block(0,18,1,24)
Block(0,18,2,24)
Block(0,18,3,24)
Block(0,18,4,24)
Block(0,18,5,24)
Block(0,18,6,24)
Block(0,18,7,24)
Block(0,18,8,24)
Block(0,18,9,24)
Block(0,18,10,24)
Block(0,18,11,24)
Block(0,18,12,24)
Block(0,18,13,24)
Block(0,18,14,24)
Block(0,18,15,24)
Block(0,18,16,24)
Block(0,18,17,24)
Block(0,18,18,24)
Block(0,18,19,24)
Block(0,19,-10,24)
Block(0,19,-9,24)
Block(0,19,-8,24)
Block(0,19,-7,24)
Block(0,19,-6,24)
Block(0,19,-5,24)
Block(0,19,-4,24)
Block(0,19,-3,24)
Block(0,19,-2,24)
Block(0,19,-1,24)
Block(0,19,0,24)
Block(0,19,1,24)
Block(0,19,2,24)
Block(0,19,3,24)
Block(0,19,4,24)
Block(0,19,5,24)
Block(0,19,6,24)
Block(0,19,7,24)
Block(0,19,8,24)
Block(0,19,9,24)
Block(0,19,10,24)
Block(0,19,11,24)
Block(0,19,12,24)
Block(0,19,13,24)
Block(0,19,14,24)
Block(0,19,15,24)
Block(0,19,16,24)
Block(0,19,17,24)
Block(0,19,18,24)
Block(0,19,19,24)
Block(0,20,-10,24)
Block(0,20,-9,24)
Block(0,20,-8,24)
Block(0,20,-7,24)
Block(0,20,-6,24)
Block(0,20,-5,24)
Block(0,20,-4,24)
Block(0,20,-3,24)
Block(0,20,-2,24)
Block(0,20,-1,24)
Block(0,20,0,24)
Block(0,20,1,24)
Block(0,20,2,24)
Block(0,20,3,24)
Block(0,20,4,24)
Block(0,20,5,24)
Block(0,20,6,24)
Block(0,20,7,24)
Block(0,20,8,24)
Block(0,20,9,24)
Block(0,20,10,24)
Block(0,20,11,24)
Block(0,20,12,24)
Block(0,20,13,24)
Block(0,20,14,24)
Block(0,20,15,24)
Block(0,20,16,24)
Block(0,20,17,24)
Block(0,20,18,24)
Block(0,20,19,24)
Block(0,20,20,24)
Block(0,21,-9,24)
Block(0,21,-8,24)
Block(0,21,-7,24)
Block(0,21,-6,24)
Block(0,21,-5,24)
Block(0,21,-4,24)
Block(0,21,-3,24)
Block(0,21,-2,24)
Block(0,21,-1,24)
Block(0,21,0,24)
Block(0,21,1,24)
Block(0,21,2,24)
Block(0,21,3,24)
Block(0,21,4,24)
Block(0,21,5,24)
Block(0,21,6,24)
Block(0,21,7,24)
Block(0,21,8,24)
Block(0,21,9,24)
Block(0,21,10,24)
Block(0,21,11,24)
Block(0,21,12,24)
Block(0,21,13,24)
Block(0,21,14,24)
Block(0,21,15,24)
Block(0,21,16,24)
Block(0,21,17,24)
Block(0,21,18,24)
Block(0,21,19,24)
Block(0,22,-9,24)
Block(0,22,-8,24)
Block(0,22,-7,24)
Block(0,22,-6,24)
Block(0,22,-5,24)
Block(0,22,-4,24)
Block(0,22,-3,24)
Block(0,22,-2,24)
Block(0,22,-1,24)
Block(0,22,0,24)
Block(0,22,1,24)
Block(0,22,2,24)
Block(0,22,3,24)
Block(0,22,4,24)
Block(0,22,5,24)
Block(0,22,6,24)
Block(0,22,7,24)
Block(0,22,8,24)
Block(0,22,9,24)
Block(0,22,10,24)
Block(0,22,11,24)
Block(0,22,12,24)
Block(0,22,13,24)
Block(0,22,14,24)
Block(0,22,15,24)
Block(0,22,16,24)
Block(0,22,17,24)
Block(0,22,18,24)
Block(0,23,-8,24)
Block(0,23,-7,24)
Block(0,23,-6,24)
Block(0,23,-5,24)
Block(0,23,-4,24)
Block(0,23,-3,24)
Block(0,23,-2,24)
Block(0,23,-1,24)
Block(0,23,0,24)
Block(0,23,1,24)
Block(0,23,2,24)
Block(0,23,3,24)
Block(0,23,4,24)
Block(0,23,5,24)
Block(0,23,6,24)
Block(0,23,7,24)
Block(0,23,8,24)
Block(0,23,9,24)
Block(0,23,10,24)
Block(0,23,11,24)
Block(0,23,12,24)
Block(0,23,13,24)
Block(0,23,14,24)
Block(0,23,15,24)
Block(0,23,16,24)
Block(0,23,17,24)
Block(0,24,-8,24)
Block(0,24,-7,24)
Block(0,24,-6,24)
Block(0,24,-5,24)
Block(0,24,-4,24)
Block(0,24,-3,24)
Block(0,24,-2,24)
Block(0,24,-1,24)
Block(0,24,0,24)
Block(0,24,1,24)
Block(0,24,2,24)
Block(0,24,3,24)
Block(0,24,4,24)
Block(0,24,5,24)
Block(0,24,6,24)
Block(0,24,7,24)
Block(0,24,8,24)
Block(0,24,9,24)
Block(0,24,10,24)
Block(0,24,11,24)
Block(0,24,12,24)
Block(0,24,13,24)
Block(0,24,14,24)
Block(0,24,15,24)
Block(0,24,16,24)
Block(0,24,17,24)
Block(0,25,-7,24)
Block(0,25,-6,24)
Block(0,25,-5,24)
Block(0,25,-4,24)
Block(0,25,-3,24)
Block(0,25,-2,24)
Block(0,25,-1,24)
Block(0,25,0,24)
Block(0,25,1,24)
Block(0,25,2,24)
Block(0,25,3,24)
Block(0,25,4,24)
Block(0,25,5,24)
Block(0,25,6,24)
Block(0,25,7,24)
Block(0,25,8,24)
Block(0,25,9,24)
Block(0,25,10,24)
Block(0,25,11,24)
Block(0,25,12,24)
Block(0,25,13,24)
Block(0,25,14,24)
Block(0,25,15,24)
Block(0,25,16,24)
Block(0,26,-6,24)
Block(0,26,-5,24)
Block(0,26,-4,24)
Block(0,26,-3,24)
Block(0,26,-2,24)
Block(0,26,-1,24)
Block(0,26,0,24)
Block(0,26,1,24)
Block(0,26,2,24)
Block(0,26,3,24)
Block(0,26,4,24)
Block(0,26,5,24)
Block(0,26,6,24)
Block(0,26,7,24)
Block(0,26,8,24)
Block(0,26,9,24)
Block(0,26,10,24)
Block(0,26,11,24)
Block(0,26,12,24)
Block(0,26,13,24)
Block(0,26,14,24)
Block(0,26,15,24)
Block(0,26,16,24)
Block(0,27,-5,24)
Block(0,27,-4,24)
Block(0,27,-3,24)
Block(0,27,-2,24)
Block(0,27,-1,24)
Block(0,27,0,24)
Block(0,27,1,24)
Block(0,27,2,24)
Block(0,27,3,24)
Block(0,27,4,24)
Block(0,27,5,24)
Block(0,27,6,24)
Block(0,27,7,24)
Block(0,27,8,24)
Block(0,27,9,24)
Block(0,27,10,24)
Block(0,27,11,24)
Block(0,27,12,24)
Block(0,27,13,24)
Block(0,27,14,24)
Block(0,27,15,24)
Block(0,28,-4,24)
Block(0,28,-3,24)
Block(0,28,-2,24)
Block(0,28,-1,24)
Block(0,28,0,24)
Block(0,28,1,24)
Block(0,28,2,24)
Block(0,28,3,24)
Block(0,28,4,24)
Block(0,28,5,24)
Block(0,28,6,24)
Block(0,28,7,24)
Block(0,28,8,24)
Block(0,28,9,24)
Block(0,28,10,24)
Block(0,28,11,24)
Block(0,28,12,24)
Block(0,28,13,24)
Block(0,28,14,24)
Block(0,28,15,24)
Block(0,29,-3,24)
Block(0,29,-2,24)
Block(0,29,-1,24)
Block(0,29,0,24)
Block(0,29,1,24)
Block(0,29,2,24)
Block(0,29,3,24)
Block(0,29,4,24)
Block(0,29,5,24)
Block(0,29,6,24)
Block(0,29,7,24)
Block(0,29,8,24)
Block(0,29,9,24)
Block(0,29,10,24)
Block(0,29,11,24)
Block(0,29,12,24)
Block(0,29,13,24)
Block(0,29,14,24)
Block(0,30,-2,24)
Block(0,30,-1,24)
Block(0,30,0,24)
Block(0,30,1,24)
Block(0,30,2,24)
Block(0,30,3,24)
Block(0,30,4,24)
Block(0,30,5,24)
Block(0,30,6,24)
Block(0,30,7,24)
Block(0,30,8,24)
Block(0,30,9,24)
Block(0,31,-1,24)
Block(0,31,0,24)
Block(0,31,1,24)
Block(0,31,2,24)
Block(0,31,3,24)
Block(0,31,4,24)
Block(0,31,5,24)
Block(0,31,6,24)
Block(0,31,7,24)
Block(0,32,-1,24)
Block(0,32,0,24)
Block(0,32,1,24)
Block(0,32,2,24)
Block(0,32,3,24)
Block(0,32,4,24)
Block(0,32,5,24)
Block(0,33,0,24)
Block(0,33,1,24)
Block(0,33,2,24)
Block(0,33,3,24)
Block(1,5,-1,24)
Block(1,5,0,24)
Block(1,5,1,24)
Block(1,5,2,24)
Block(1,5,3,24)
Block(1,5,4,24)
Block(1,6,-3,24)
Block(1,6,-2,24)
Block(1,6,-1,24)
Block(1,6,0,24)
Block(1,6,1,24)
Block(1,6,2,24)
Block(1,6,3,24)
Block(1,6,4,24)
Block(1,6,5,24)
Block(1,6,6,24)
Block(1,6,7,24)
Block(1,6,8,24)
Block(1,6,9,24)
Block(1,6,10,24)
Block(1,6,11,24)
Block(1,7,-4,24)
Block(1,7,-3,24)
Block(1,7,-2,24)
Block(1,7,-1,24)
Block(1,7,0,24)
Block(1,7,1,24)
Block(1,7,2,24)
Block(1,7,3,24)
Block(1,7,4,24)
Block(1,7,5,24)
Block(1,7,6,24)
Block(1,7,7,24)
Block(1,7,8,24)
Block(1,7,9,24)
Block(1,7,10,24)
Block(1,7,11,24)
Block(1,8,-5,24)
Block(1,8,-4,24)
Block(1,8,-3,24)
Block(1,8,-2,24)
Block(1,8,-1,24)
Block(1,8,0,24)
Block(1,8,1,24)
Block(1,8,2,24)
Block(1,8,3,24)
Block(1,8,4,24)
Block(1,8,5,24)
Block(1,8,6,24)
Block(1,8,7,24)
Block(1,8,8,24)
Block(1,8,9,24)
Block(1,8,10,24)
Block(1,8,11,24)
Block(1,8,12,24)
Block(1,9,-5,24)
Block(1,9,-4,24)
Block(1,9,-3,24)
Block(1,9,-2,24)
Block(1,9,-1,24)
Block(1,9,0,24)
Block(1,9,1,24)
Block(1,9,2,24)
Block(1,9,3,24)
Block(1,9,4,24)
Block(1,9,5,24)
Block(1,9,6,24)
Block(1,9,7,24)
Block(1,9,8,24)
Block(1,9,9,24)
Block(1,9,10,24)
Block(1,9,11,24)
Block(1,9,12,24)
Block(1,9,13,24)
Block(1,9,14,24)
Block(1,10,-6,24)
Block(1,10,-5,24)
Block(1,10,-4,24)
Block(1,10,-3,24)
Block(1,10,-2,24)
Block(1,10,-1,24)
Block(1,10,0,24)
Block(1,10,1,24)
Block(1,10,2,24)
Block(1,10,3,24)
Block(1,10,4,24)
Block(1,10,5,24)
Block(1,10,6,24)
Block(1,10,7,24)
Block(1,10,8,24)
Block(1,10,9,24)
Block(1,10,10,24)
Block(1,10,11,24)
Block(1,10,12,24)
Block(1,10,13,24)
Block(1,10,14,24)
Block(1,10,15,24)
Block(1,11,-7,24)
Block(1,11,-6,24)
Block(1,11,-5,24)
Block(1,11,-4,24)
Block(1,11,-3,24)
Block(1,11,-2,24)
Block(1,11,-1,24)
Block(1,11,0,24)
Block(1,11,1,24)
Block(1,11,2,24)
Block(1,11,3,24)
Block(1,11,4,24)
Block(1,11,5,24)
Block(1,11,6,24)
Block(1,11,7,24)
Block(1,11,8,24)
Block(1,11,9,24)
Block(1,11,10,24)
Block(1,11,11,24)
Block(1,11,12,24)
Block(1,11,13,24)
Block(1,11,14,24)
Block(1,11,15,24)
Block(1,11,16,24)
Block(1,11,17,24)
Block(1,12,-8,24)
Block(1,12,-7,24)
Block(1,12,-6,24)
Block(1,12,-5,24)
Block(1,12,-4,24)
Block(1,12,-3,24)
Block(1,12,-2,24)
Block(1,12,-1,24)
Block(1,12,0,24)
Block(1,12,1,24)
Block(1,12,2,24)
Block(1,12,3,24)
Block(1,12,4,24)
Block(1,12,5,24)
Block(1,12,6,24)
Block(1,12,7,24)
Block(1,12,8,24)
Block(1,12,9,24)
Block(1,12,10,24)
Block(1,12,11,24)
Block(1,12,12,24)
Block(1,12,13,24)
Block(1,12,14,24)
Block(1,12,15,24)
Block(1,12,16,24)
Block(1,12,17,24)
Block(1,12,18,24)
Block(1,13,-9,24)
Block(1,13,-8,24)
Block(1,13,-7,24)
Block(1,13,-6,24)
Block(1,13,-5,24)
Block(1,13,-4,24)
Block(1,13,-3,24)
Block(1,13,-2,24)
Block(1,13,-1,24)
Block(1,13,0,24)
Block(1,13,1,24)
Block(1,13,2,24)
Block(1,13,3,24)
Block(1,13,4,24)
Block(1,13,5,24)
Block(1,13,6,24)
Block(1,13,7,24)
Block(1,13,8,24)
Block(1,13,9,24)
Block(1,13,10,24)
Block(1,13,11,24)
Block(1,13,12,24)
Block(1,13,13,24)
Block(1,13,14,24)
Block(1,13,15,24)
Block(1,13,16,24)
Block(1,13,17,24)
Block(1,13,18,24)
Block(1,14,-10,24)
Block(1,14,-9,24)
Block(1,14,-8,24)
Block(1,14,-7,24)
Block(1,14,-6,24)
Block(1,14,-5,24)
Block(1,14,-4,24)
Block(1,14,-3,24)
Block(1,14,-2,24)
Block(1,14,-1,24)
Block(1,14,0,24)
Block(1,14,1,24)
Block(1,14,2,24)
Block(1,14,3,24)
Block(1,14,4,24)
Block(1,14,5,24)
Block(1,14,6,24)
Block(1,14,7,24)
Block(1,14,8,24)
Block(1,14,9,24)
Block(1,14,10,24)
Block(1,14,11,24)
Block(1,14,12,24)
Block(1,14,13,24)
Block(1,14,14,24)
Block(1,14,15,24)
Block(1,14,16,24)
Block(1,14,17,24)
Block(1,14,18,24)
Block(1,15,-10,24)
Block(1,15,-9,24)
Block(1,15,-8,24)
Block(1,15,-7,24)
Block(1,15,-6,24)
Block(1,15,-5,24)
Block(1,15,-4,24)
Block(1,15,-3,24)
Block(1,15,-2,24)
Block(1,15,-1,24)
Block(1,15,0,24)
Block(1,15,1,24)
Block(1,15,2,24)
Block(1,15,3,24)
Block(1,15,4,24)
Block(1,15,5,24)
Block(1,15,6,24)
Block(1,15,7,24)
Block(1,15,8,24)
Block(1,15,9,24)
Block(1,15,10,24)
Block(1,15,11,24)
Block(1,15,12,24)
Block(1,15,13,24)
Block(1,15,14,24)
Block(1,15,15,24)
Block(1,15,16,24)
Block(1,15,17,24)
Block(1,15,18,24)
Block(1,16,-10,24)
Block(1,16,-9,24)
Block(1,16,-8,24)
Block(1,16,-7,24)
Block(1,16,-6,24)
Block(1,16,-5,24)
Block(1,16,-4,24)
Block(1,16,-3,24)
Block(1,16,-2,24)
Block(1,16,-1,24)
Block(1,16,0,24)
Block(1,16,1,24)
Block(1,16,2,24)
Block(1,16,3,24)
Block(1,16,4,24)
Block(1,16,5,24)
Block(1,16,6,24)
Block(1,16,7,24)
Block(1,16,8,24)
Block(1,16,9,24)
Block(1,16,10,24)
Block(1,16,11,24)
Block(1,16,12,24)
Block(1,16,13,24)
Block(1,16,14,24)
Block(1,16,15,24)
Block(1,16,16,24)
Block(1,16,17,24)
Block(1,16,18,24)
Block(1,17,-10,24)
Block(1,17,-9,24)
Block(1,17,-8,24)
Block(1,17,-7,24)
Block(1,17,-6,24)
Block(1,17,-5,24)
Block(1,17,-4,24)
Block(1,17,-3,24)
Block(1,17,-2,24)
Block(1,17,-1,24)
Block(1,17,0,24)
Block(1,17,1,24)
Block(1,17,2,24)
Block(1,17,3,24)
Block(1,17,4,24)
Block(1,17,5,24)
Block(1,17,6,24)
Block(1,17,7,24)
Block(1,17,8,24)
Block(1,17,9,24)
Block(1,17,10,24)
Block(1,17,11,24)
Block(1,17,12,24)
Block(1,17,13,24)
Block(1,17,14,24)
Block(1,17,15,24)
Block(1,17,16,24)
Block(1,17,17,24)
Block(1,17,18,24)
Block(1,17,19,24)
Block(1,18,-9,24)
Block(1,18,-8,24)
Block(1,18,-7,24)
Block(1,18,-6,24)
Block(1,18,-5,24)
Block(1,18,-4,24)
Block(1,18,-3,24)
Block(1,18,-2,24)
Block(1,18,-1,24)
Block(1,18,0,24)
Block(1,18,1,24)
Block(1,18,2,24)
Block(1,18,3,24)
Block(1,18,4,24)
Block(1,18,5,24)
Block(1,18,6,24)
Block(1,18,7,24)
Block(1,18,8,24)
Block(1,18,9,24)
Block(1,18,10,24)
Block(1,18,11,24)
Block(1,18,12,24)
Block(1,18,13,24)
Block(1,18,14,24)
Block(1,18,15,24)
Block(1,18,16,24)
Block(1,18,17,24)
Block(1,18,18,24)
Block(1,18,19,24)
Block(1,19,-9,24)
Block(1,19,-8,24)
Block(1,19,-7,24)
Block(1,19,-6,24)
Block(1,19,-5,24)
Block(1,19,-4,24)
Block(1,19,-3,24)
Block(1,19,-2,24)
Block(1,19,-1,24)
Block(1,19,0,24)
Block(1,19,1,24)
Block(1,19,2,24)
Block(1,19,3,24)
Block(1,19,4,24)
Block(1,19,5,24)
Block(1,19,6,24)
Block(1,19,7,24)
Block(1,19,8,24)
Block(1,19,9,24)
Block(1,19,10,24)
Block(1,19,11,24)
Block(1,19,12,24)
Block(1,19,13,24)
Block(1,19,14,24)
Block(1,19,15,24)
Block(1,19,16,24)
Block(1,19,17,24)
Block(1,19,18,24)
Block(1,19,19,24)
Block(1,20,-9,24)
Block(1,20,-8,24)
Block(1,20,-7,24)
Block(1,20,-6,24)
Block(1,20,-5,24)
Block(1,20,-4,24)
Block(1,20,-3,24)
Block(1,20,-2,24)
Block(1,20,-1,24)
Block(1,20,0,24)
Block(1,20,1,24)
Block(1,20,2,24)
Block(1,20,3,24)
Block(1,20,4,24)
Block(1,20,5,24)
Block(1,20,6,24)
Block(1,20,7,24)
Block(1,20,8,24)
Block(1,20,9,24)
Block(1,20,10,24)
Block(1,20,11,24)
Block(1,20,12,24)
Block(1,20,13,24)
Block(1,20,14,24)
Block(1,20,15,24)
Block(1,20,16,24)
Block(1,20,17,24)
Block(1,20,18,24)
Block(1,20,19,24)
Block(1,20,20,24)
Block(1,21,-9,24)
Block(1,21,-8,24)
Block(1,21,-7,24)
Block(1,21,-6,24)
Block(1,21,-5,24)
Block(1,21,-4,24)
Block(1,21,-3,24)
Block(1,21,-2,24)
Block(1,21,-1,24)
Block(1,21,0,24)
Block(1,21,1,24)
Block(1,21,2,24)
Block(1,21,3,24)
Block(1,21,4,24)
Block(1,21,5,24)
Block(1,21,6,24)
Block(1,21,7,24)
Block(1,21,8,24)
Block(1,21,9,24)
Block(1,21,10,24)
Block(1,21,11,24)
Block(1,21,12,24)
Block(1,21,13,24)
Block(1,21,14,24)
Block(1,21,15,24)
Block(1,21,16,24)
Block(1,21,17,24)
Block(1,21,18,24)
Block(1,21,19,24)
Block(1,21,20,24)
Block(1,22,-9,24)
Block(1,22,-8,24)
Block(1,22,-7,24)
Block(1,22,-6,24)
Block(1,22,-5,24)
Block(1,22,-4,24)
Block(1,22,-3,24)
Block(1,22,-2,24)
Block(1,22,-1,24)
Block(1,22,0,24)
Block(1,22,1,24)
Block(1,22,2,24)
Block(1,22,3,24)
Block(1,22,4,24)
Block(1,22,5,24)
Block(1,22,6,24)
Block(1,22,7,24)
Block(1,22,8,24)
Block(1,22,9,24)
Block(1,22,10,24)
Block(1,22,11,24)
Block(1,22,12,24)
Block(1,22,13,24)
Block(1,22,14,24)
Block(1,22,15,24)
Block(1,22,16,24)
Block(1,22,17,24)
Block(1,22,18,24)
Block(1,22,19,24)
Block(1,23,-8,24)
Block(1,23,-7,24)
Block(1,23,-6,24)
Block(1,23,-5,24)
Block(1,23,-4,24)
Block(1,23,-3,24)
Block(1,23,-2,24)
Block(1,23,-1,24)
Block(1,23,0,24)
Block(1,23,1,24)
Block(1,23,2,24)
Block(1,23,3,24)
Block(1,23,4,24)
Block(1,23,5,24)
Block(1,23,6,24)
Block(1,23,7,24)
Block(1,23,8,24)
Block(1,23,9,24)
Block(1,23,10,24)
Block(1,23,11,24)
Block(1,23,12,24)
Block(1,23,13,24)
Block(1,23,14,24)
Block(1,23,15,24)
Block(1,23,16,24)
Block(1,23,17,24)
Block(1,23,18,24)
Block(1,24,-7,24)
Block(1,24,-6,24)
Block(1,24,-5,24)
Block(1,24,-4,24)
Block(1,24,-3,24)
Block(1,24,-2,24)
Block(1,24,-1,24)
Block(1,24,0,24)
Block(1,24,1,24)
Block(1,24,2,24)
Block(1,24,3,24)
Block(1,24,4,24)
Block(1,24,5,24)
Block(1,24,6,24)
Block(1,24,7,24)
Block(1,24,8,24)
Block(1,24,9,24)
Block(1,24,10,24)
Block(1,24,11,24)
Block(1,24,12,24)
Block(1,24,13,24)
Block(1,24,14,24)
Block(1,24,15,24)
Block(1,24,16,24)
Block(1,24,17,24)
Block(1,24,18,24)
Block(1,25,-6,24)
Block(1,25,-5,24)
Block(1,25,-4,24)
Block(1,25,-3,24)
Block(1,25,-2,24)
Block(1,25,-1,24)
Block(1,25,0,24)
Block(1,25,1,24)
Block(1,25,2,24)
Block(1,25,3,24)
Block(1,25,4,24)
Block(1,25,5,24)
Block(1,25,6,24)
Block(1,25,7,24)
Block(1,25,8,24)
Block(1,25,9,24)
Block(1,25,10,24)
Block(1,25,11,24)
Block(1,25,12,24)
Block(1,25,13,24)
Block(1,25,14,24)
Block(1,25,15,24)
Block(1,25,16,24)
Block(1,25,17,24)
Block(1,26,-5,24)
Block(1,26,-4,24)
Block(1,26,-3,24)
Block(1,26,-2,24)
Block(1,26,-1,24)
Block(1,26,0,24)
Block(1,26,1,24)
Block(1,26,2,24)
Block(1,26,3,24)
Block(1,26,4,24)
Block(1,26,5,24)
Block(1,26,6,24)
Block(1,26,7,24)
Block(1,26,8,24)
Block(1,26,9,24)
Block(1,26,10,24)
Block(1,26,11,24)
Block(1,26,12,24)
Block(1,26,13,24)
Block(1,26,14,24)
Block(1,26,15,24)
Block(1,26,16,24)
Block(1,26,17,24)
Block(1,27,-4,24)
Block(1,27,-3,24)
Block(1,27,-2,24)
Block(1,27,-1,24)
Block(1,27,0,24)
Block(1,27,1,24)
Block(1,27,2,24)
Block(1,27,3,24)
Block(1,27,4,24)
Block(1,27,5,24)
Block(1,27,6,24)
Block(1,27,7,24)
Block(1,27,8,24)
Block(1,27,9,24)
Block(1,27,10,24)
Block(1,27,11,24)
Block(1,27,12,24)
Block(1,27,13,24)
Block(1,27,14,24)
Block(1,27,15,24)
Block(1,27,16,24)
Block(1,28,-3,24)
Block(1,28,-2,24)
Block(1,28,-1,24)
Block(1,28,0,24)
Block(1,28,1,24)
Block(1,28,2,24)
Block(1,28,3,24)
Block(1,28,4,24)
Block(1,28,5,24)
Block(1,28,6,24)
Block(1,28,7,24)
Block(1,28,8,24)
Block(1,28,9,24)
Block(1,28,10,24)
Block(1,28,11,24)
Block(1,28,12,24)
Block(1,28,13,24)
Block(1,28,14,24)
Block(1,28,15,24)
Block(1,28,16,24)
Block(1,29,-2,24)
Block(1,29,-1,24)
Block(1,29,0,24)
Block(1,29,1,24)
Block(1,29,2,24)
Block(1,29,3,24)
Block(1,29,4,24)
Block(1,29,5,24)
Block(1,29,6,24)
Block(1,29,7,24)
Block(1,29,8,24)
Block(1,29,9,24)
Block(1,29,10,24)
Block(1,29,11,24)
Block(1,29,12,24)
Block(1,29,13,24)
Block(1,29,14,24)
Block(1,29,15,24)
Block(1,30,-2,24)
Block(1,30,-1,24)
Block(1,30,0,24)
Block(1,30,1,24)
Block(1,30,2,24)
Block(1,30,3,24)
Block(1,30,4,24)
Block(1,30,5,24)
Block(1,30,6,24)
Block(1,30,7,24)
Block(1,30,8,24)
Block(1,30,9,24)
Block(1,30,10,24)
Block(1,30,11,24)
Block(1,30,12,24)
Block(1,30,13,24)
Block(1,30,14,24)
Block(1,30,15,24)
Block(1,31,-1,24)
Block(1,31,0,24)
Block(1,31,1,24)
Block(1,31,2,24)
Block(1,31,3,24)
Block(1,31,4,24)
Block(1,31,5,24)
Block(1,31,6,24)
Block(1,31,7,24)
Block(1,32,0,24)
Block(1,32,1,24)
Block(1,32,2,24)
Block(1,32,3,24)
Block(1,32,4,24)
Block(1,32,5,24)
Block(1,32,6,24)
Block(1,33,0,24)
Block(1,33,1,24)
Block(1,33,2,24)
Block(1,33,3,24)
Block(1,33,4,24)
Block(1,33,5,24)
Block(2,4,4,24)
Block(2,5,0,24)
Block(2,5,1,24)
Block(2,5,2,24)
Block(2,5,3,24)
Block(2,5,4,24)
Block(2,5,5,24)
Block(2,5,6,24)
Block(2,5,7,24)
Block(2,5,8,24)
Block(2,6,-3,24)
Block(2,6,-2,24)
Block(2,6,-1,24)
Block(2,6,0,24)
Block(2,6,1,24)
Block(2,6,2,24)
Block(2,6,3,24)
Block(2,6,4,24)
Block(2,6,5,24)
Block(2,6,6,24)
Block(2,6,7,24)
Block(2,6,8,24)
Block(2,6,9,24)
Block(2,6,10,24)
Block(2,6,11,24)
Block(2,7,-3,24)
Block(2,7,-2,24)
Block(2,7,-1,24)
Block(2,7,0,24)
Block(2,7,1,24)
Block(2,7,2,24)
Block(2,7,3,24)
Block(2,7,4,24)
Block(2,7,5,24)
Block(2,7,6,24)
Block(2,7,7,24)
Block(2,7,8,24)
Block(2,7,9,24)
Block(2,7,10,24)
Block(2,7,11,24)
Block(2,7,12,24)
Block(2,8,-4,24)
Block(2,8,-3,24)
Block(2,8,-2,24)
Block(2,8,-1,24)
Block(2,8,0,24)
Block(2,8,1,24)
Block(2,8,2,24)
Block(2,8,3,24)
Block(2,8,4,24)
Block(2,8,5,24)
Block(2,8,6,24)
Block(2,8,7,24)
Block(2,8,8,24)
Block(2,8,9,24)
Block(2,8,10,24)
Block(2,8,11,24)
Block(2,8,12,24)
Block(2,8,13,24)
Block(2,9,-5,24)
Block(2,9,-4,24)
Block(2,9,-3,24)
Block(2,9,-2,24)
Block(2,9,-1,24)
Block(2,9,0,24)
Block(2,9,1,24)
Block(2,9,2,24)
Block(2,9,3,24)
Block(2,9,4,24)
Block(2,9,5,24)
Block(2,9,6,24)
Block(2,9,7,24)
Block(2,9,8,24)
Block(2,9,9,24)
Block(2,9,10,24)
Block(2,9,11,24)
Block(2,9,12,24)
Block(2,9,13,24)
Block(2,9,14,24)
Block(2,10,-6,24)
Block(2,10,-5,24)
Block(2,10,-4,24)
Block(2,10,-3,24)
Block(2,10,-2,24)
Block(2,10,-1,24)
Block(2,10,0,24)
Block(2,10,1,24)
Block(2,10,2,24)
Block(2,10,3,24)
Block(2,10,4,24)
Block(2,10,5,24)
Block(2,10,6,24)
Block(2,10,7,24)
Block(2,10,8,24)
Block(2,10,9,24)
Block(2,10,10,24)
Block(2,10,11,24)
Block(2,10,12,24)
Block(2,10,13,24)
Block(2,10,14,24)
Block(2,10,15,24)
Block(2,10,16,24)
Block(2,11,-6,24)
Block(2,11,-5,24)
Block(2,11,-4,24)
Block(2,11,-3,24)
Block(2,11,-2,24)
Block(2,11,-1,24)
Block(2,11,0,24)
Block(2,11,1,24)
Block(2,11,2,24)
Block(2,11,3,24)
Block(2,11,4,24)
Block(2,11,5,24)
Block(2,11,6,24)
Block(2,11,7,24)
Block(2,11,8,24)
Block(2,11,9,24)
Block(2,11,10,24)
Block(2,11,11,24)
Block(2,11,12,24)
Block(2,11,13,24)
Block(2,11,14,24)
Block(2,11,15,24)
Block(2,11,16,24)
Block(2,11,17,24)
Block(2,12,-7,24)
Block(2,12,-6,24)
Block(2,12,-5,24)
Block(2,12,-4,24)
Block(2,12,-3,24)
Block(2,12,-2,24)
Block(2,12,-1,24)
Block(2,12,0,24)
Block(2,12,1,24)
Block(2,12,2,24)
Block(2,12,3,24)
Block(2,12,4,24)
Block(2,12,5,24)
Block(2,12,6,24)
Block(2,12,7,24)
Block(2,12,8,24)
Block(2,12,9,24)
Block(2,12,10,24)
Block(2,12,11,24)
Block(2,12,12,24)
Block(2,12,13,24)
Block(2,12,14,24)
Block(2,12,15,24)
Block(2,12,16,24)
Block(2,12,17,24)
Block(2,12,18,24)
Block(2,12,19,24)
Block(2,13,-8,24)
Block(2,13,-7,24)
Block(2,13,-6,24)
Block(2,13,-5,24)
Block(2,13,-4,24)
Block(2,13,-3,24)
Block(2,13,-2,24)
Block(2,13,-1,24)
Block(2,13,0,24)
Block(2,13,1,24)
Block(2,13,2,24)
Block(2,13,3,24)
Block(2,13,4,24)
Block(2,13,5,24)
Block(2,13,6,24)
Block(2,13,7,24)
Block(2,13,8,24)
Block(2,13,9,24)
Block(2,13,10,24)
Block(2,13,11,24)
Block(2,13,12,24)
Block(2,13,13,24)
Block(2,13,14,24)
Block(2,13,15,24)
Block(2,13,16,24)
Block(2,13,17,24)
Block(2,13,18,24)
Block(2,13,19,24)
Block(2,14,-9,24)
Block(2,14,-8,24)
Block(2,14,-7,24)
Block(2,14,-6,24)
Block(2,14,-5,24)
Block(2,14,-4,24)
Block(2,14,-3,24)
Block(2,14,-2,24)
Block(2,14,-1,24)
Block(2,14,0,24)
Block(2,14,1,24)
Block(2,14,2,24)
Block(2,14,3,24)
Block(2,14,4,24)
Block(2,14,5,24)
Block(2,14,6,24)
Block(2,14,7,24)
Block(2,14,8,24)
Block(2,14,9,24)
Block(2,14,10,24)
Block(2,14,11,24)
Block(2,14,12,24)
Block(2,14,13,24)
Block(2,14,14,24)
Block(2,14,15,24)
Block(2,14,16,24)
Block(2,14,17,24)
Block(2,14,18,24)
Block(2,14,19,24)
Block(2,15,-10,24)
Block(2,15,-9,24)
Block(2,15,-8,24)
Block(2,15,-7,24)
Block(2,15,-6,24)
Block(2,15,-5,24)
Block(2,15,-4,24)
Block(2,15,-3,24)
Block(2,15,-2,24)
Block(2,15,-1,24)
Block(2,15,0,24)
Block(2,15,1,24)
Block(2,15,2,24)
Block(2,15,3,24)
Block(2,15,4,24)
Block(2,15,5,24)
Block(2,15,6,24)
Block(2,15,7,24)
Block(2,15,8,24)
Block(2,15,9,24)
Block(2,15,10,24)
Block(2,15,11,24)
Block(2,15,12,24)
Block(2,15,13,24)
Block(2,15,14,24)
Block(2,15,15,24)
Block(2,15,16,24)
Block(2,15,17,24)
Block(2,15,18,24)
Block(2,15,19,24)
Block(2,16,-9,24)
Block(2,16,-8,24)
Block(2,16,-7,24)
Block(2,16,-6,24)
Block(2,16,-5,24)
Block(2,16,-4,24)
Block(2,16,-3,24)
Block(2,16,-2,24)
Block(2,16,-1,24)
Block(2,16,0,24)
Block(2,16,1,24)
Block(2,16,2,24)
Block(2,16,3,24)
Block(2,16,4,24)
Block(2,16,5,24)
Block(2,16,6,24)
Block(2,16,7,24)
Block(2,16,8,24)
Block(2,16,9,24)
Block(2,16,10,24)
Block(2,16,11,24)
Block(2,16,12,24)
Block(2,16,13,24)
Block(2,16,14,24)
Block(2,16,15,24)
Block(2,16,16,24)
Block(2,16,17,24)
Block(2,16,18,24)
Block(2,16,19,24)
Block(2,17,-9,24)
Block(2,17,-8,24)
Block(2,17,-7,24)
Block(2,17,-6,24)
Block(2,17,-5,24)
Block(2,17,-4,24)
Block(2,17,-3,24)
Block(2,17,-2,24)
Block(2,17,-1,24)
Block(2,17,0,24)
Block(2,17,1,24)
Block(2,17,2,24)
Block(2,17,3,24)
Block(2,17,4,24)
Block(2,17,5,24)
Block(2,17,6,24)
Block(2,17,7,24)
Block(2,17,8,24)
Block(2,17,9,24)
Block(2,17,10,24)
Block(2,17,11,24)
Block(2,17,12,24)
Block(2,17,13,24)
Block(2,17,14,24)
Block(2,17,15,24)
Block(2,17,16,24)
Block(2,17,17,24)
Block(2,17,18,24)
Block(2,17,19,24)
Block(2,18,-9,24)
Block(2,18,-8,24)
Block(2,18,-7,24)
Block(2,18,-6,24)
Block(2,18,-5,24)
Block(2,18,-4,24)
Block(2,18,-3,24)
Block(2,18,-2,24)
Block(2,18,-1,24)
Block(2,18,0,24)
Block(2,18,1,24)
Block(2,18,2,24)
Block(2,18,3,24)
Block(2,18,4,24)
Block(2,18,5,24)
Block(2,18,6,24)
Block(2,18,7,24)
Block(2,18,8,24)
Block(2,18,9,24)
Block(2,18,10,24)
Block(2,18,11,24)
Block(2,18,12,24)
Block(2,18,13,24)
Block(2,18,14,24)
Block(2,18,15,24)
Block(2,18,16,24)
Block(2,18,17,24)
Block(2,18,18,24)
Block(2,18,19,24)
Block(2,19,-9,24)
Block(2,19,-8,24)
Block(2,19,-7,24)
Block(2,19,-6,24)
Block(2,19,-5,24)
Block(2,19,-4,24)
Block(2,19,-3,24)
Block(2,19,-2,24)
Block(2,19,-1,24)
Block(2,19,0,24)
Block(2,19,1,24)
Block(2,19,2,24)
Block(2,19,3,24)
Block(2,19,4,24)
Block(2,19,5,24)
Block(2,19,6,24)
Block(2,19,7,24)
Block(2,19,8,24)
Block(2,19,9,24)
Block(2,19,10,24)
Block(2,19,11,24)
Block(2,19,12,24)
Block(2,19,13,24)
Block(2,19,14,24)
Block(2,19,15,24)
Block(2,19,16,24)
Block(2,19,17,24)
Block(2,19,18,24)
Block(2,19,19,24)
Block(2,19,20,24)
Block(2,20,-9,24)
Block(2,20,-8,24)
Block(2,20,-7,24)
Block(2,20,-6,24)
Block(2,20,-5,24)
Block(2,20,-4,24)
Block(2,20,-3,24)
Block(2,20,-2,24)
Block(2,20,-1,24)
Block(2,20,0,24)
Block(2,20,1,24)
Block(2,20,2,24)
Block(2,20,3,24)
Block(2,20,4,24)
Block(2,20,5,24)
Block(2,20,6,24)
Block(2,20,7,24)
Block(2,20,8,24)
Block(2,20,9,24)
Block(2,20,10,24)
Block(2,20,11,24)
Block(2,20,12,24)
Block(2,20,13,24)
Block(2,20,14,24)
Block(2,20,15,24)
Block(2,20,16,24)
Block(2,20,17,24)
Block(2,20,18,24)
Block(2,20,19,24)
Block(2,20,20,24)
Block(2,21,-9,24)
Block(2,21,-8,24)
Block(2,21,-7,24)
Block(2,21,-6,24)
Block(2,21,-5,24)
Block(2,21,-4,24)
Block(2,21,-3,24)
Block(2,21,-2,24)
Block(2,21,-1,24)
Block(2,21,0,24)
Block(2,21,1,24)
Block(2,21,2,24)
Block(2,21,3,24)
Block(2,21,4,24)
Block(2,21,5,24)
Block(2,21,6,24)
Block(2,21,7,24)
Block(2,21,8,24)
Block(2,21,9,24)
Block(2,21,10,24)
Block(2,21,11,24)
Block(2,21,12,24)
Block(2,21,13,24)
Block(2,21,14,24)
Block(2,21,15,24)
Block(2,21,16,24)
Block(2,21,17,24)
Block(2,21,18,24)
Block(2,21,19,24)
Block(2,21,20,24)
Block(2,22,-8,24)
Block(2,22,-7,24)
Block(2,22,-6,24)
Block(2,22,-5,24)
Block(2,22,-4,24)
Block(2,22,-3,24)
Block(2,22,-2,24)
Block(2,22,-1,24)
Block(2,22,0,24)
Block(2,22,1,24)
Block(2,22,2,24)
Block(2,22,3,24)
Block(2,22,4,24)
Block(2,22,5,24)
Block(2,22,6,24)
Block(2,22,7,24)
Block(2,22,8,24)
Block(2,22,9,24)
Block(2,22,10,24)
Block(2,22,11,24)
Block(2,22,12,24)
Block(2,22,13,24)
Block(2,22,14,24)
Block(2,22,15,24)
Block(2,22,16,24)
Block(2,22,17,24)
Block(2,22,18,24)
Block(2,22,19,24)
Block(2,22,20,24)
Block(2,23,-8,24)
