#######################################################################
# +-----------------------------------------------------------------+ #
# |                            BO3 object                           | #
# +-----------------------------------------------------------------+ #
#######################################################################

# The descriptions in this file are accurate only for TerrainControl and OTG.
# For MCW and OTG+ these descriptions are only accurate if the BO3 is used as a CustomObject.
# MCW and OTG+ completely reimplemented CustomStructure, check the MCW/OTG+ documentation for more information.

# This is the config file of a custom object.
# If you add this object correctly to your BiomeConfigs, it will spawn in the world.

# This is the creator of this BO3 object
Author: Unknown

# A short description of this BO3 object
Description: This BO3 was converted from a schematic using OTGEdit. The author and description information of the schematic could not be found. If you know who the author of the schematic is then please add this information.

# The BO3 version, don't change this! It can be used by external applications to do a version check.
Version: 3

# The settings mode, WriteAll, WriteWithoutComments or WriteDisable. See WorldConfig.
SettingsMode: WriteDisable

#######################################################################
# +-----------------------------------------------------------------+ #
# |                          Main settings                          | #
# +-----------------------------------------------------------------+ #
#######################################################################

# This needs to be set to true to spawn the object in the Tree and Sapling resources.
Tree: false

# The frequency of the BO3 from 1 to 200. Tries this many times to spawn this BO3 when using the CustomObject(...) resource.
# Ignored by Tree(..), Sapling(..) and CustomStructure(..)
Frequency: 40

# The rarity of the BO3 from 0 to 100. Each spawn attempt has rarity% chance to succeed when using the CustomObject(...) resource.
# Ignored by Tree(..), Sapling(..) and CustomStructure(..)
Rarity: 100.0

# If you set this to true, the BO3 will be placed with a random rotation.
RotateRandomly: true

# The spawn height of the BO3 - randomY, highestBlock or highestSolidBlock.
SpawnHeight: randomY

# The height limits for the BO3.
MinHeight: 92

MaxHeight: 256

# Objects can have other objects attached to it: branches. Branches can also
# have branches attached to it, which can also have branches, etc. This is the
# maximum branch depth for this objects.
MaxBranchDepth: 10

# When spawned with the UseWorld keyword, this BO3 should NOT spawn in the following biomes.
# If you writer.write the BO3 name directly in the BiomeConfigs, this will be ignored.
ExcludedBiomes: All

# To optimise this BO3 for faster loading times you can use Notepad++ to find/replace comments and abbreviate things.
# Notepad++ find/replace with regex:
# Find: ^[#;].* replace to nothing removes all lines starting with # 
# Find: ^\s*$ replace to nothing removes most empty lines 
# Notepad++ find/replace without regex:
# *Warning: This will only work for OTG 1.10.2 v21 / OTG 1.11.2 v6 or higher. B( is not recognised by lower versions.
# Find: Block( replace to B(

#######################################################################
# +-----------------------------------------------------------------+ #
# |                      Source block settings                      | #
# +-----------------------------------------------------------------+ #
#######################################################################

# The block(s) the BO3 should spawn in.
SourceBlocks: AIR

# The maximum percentage of the BO3 that can be outside the SourceBlock.
# The BO3 won't be placed on a location with more blocks outside the SourceBlock than this percentage.
MaxPercentageOutsideSourceBlock: 100

# What to do when a block is about to be placed outside the SourceBlock? (dontPlace, placeAnyway)
OutsideSourceBlock: placeAnyway

#######################################################################
# +-----------------------------------------------------------------+ #
# |                              Blocks                             | #
# +-----------------------------------------------------------------+ #
#######################################################################

# All the blocks used in the BO3 are listed here. Possible blocks:
# Block(x,y,z,id[.data][,nbtfile.nbt) or B(x,y,z,id[.data][,nbtfile.nbt)
# RandomBlock(x,y,z,id[:data][,nbtfile.nbt],chance[,id[:data][,nbtfile.nbt],chance[,...]])
# So RandomBlock(0,0,0,CHEST,chest.nbt,50,CHEST,anotherchest.nbt,100) will spawn a chest at
# the BO3 origin, and give it a 50% chance to have the contents of chest.nbt, or, if that
# fails, a 100% percent chance to have the contents of anotherchest.nbt.

Block(-11,18,1,161:1)
Block(-11,19,2,161:1)
Block(-11,19,4,161:1)
Block(-10,16,2,161:1)
Block(-10,18,1,161:1)
Block(-10,18,2,161:1)
Block(-10,19,-2,161:1)
Block(-10,19,0,161:1)
Block(-10,19,1,161:1)
Block(-10,19,2,161:1)
Block(-10,19,3,161:1)
Block(-10,21,1,161:1)
Block(-10,21,4,161:1)
Block(-9,17,1,161:1)
Block(-9,17,2,161:1)
Block(-9,18,0,161:1)
Block(-9,18,1,161:1)
Block(-9,18,2,161:1)
Block(-9,18,3,161:1)
Block(-9,18,5,161:1)
Block(-9,19,-1,161:1)
Block(-9,19,0,161:1)
Block(-9,19,1,161:1)
Block(-9,19,2,161:1)
Block(-9,19,3,161:1)
Block(-9,19,4,161:1)
Block(-9,20,1,161:1)
Block(-9,20,2,161:1)
Block(-9,20,3,161:1)
Block(-9,20,4,161:1)
Block(-9,21,3,161:1)
Block(-9,21,4,162:13)
Block(-9,21,5,161:1)
Block(-9,21,7,161:1)
Block(-9,22,4,161:1)
Block(-8,16,-1,161:1)
Block(-8,17,0,161:1)
Block(-8,17,1,161:1)
Block(-8,17,2,161:1)
Block(-8,17,3,161:1)
Block(-8,17,4,161:1)
Block(-8,18,-2,161:1)
Block(-8,18,-1,161:1)
Block(-8,18,0,161:1)
Block(-8,18,1,161:1)
Block(-8,18,2,161:1)
Block(-8,18,3,161:1)
Block(-8,19,-1,161:1)
Block(-8,19,0,161:1)
Block(-8,19,1,161:1)
Block(-8,19,2,161:1)
Block(-8,19,3,162:13)
Block(-8,19,4,161:1)
Block(-8,19,5,161:1)
Block(-8,20,0,161:1)
Block(-8,20,1,161:1)
Block(-8,20,2,161:1)
Block(-8,20,3,162:13)
Block(-8,20,4,162:13)
Block(-8,20,5,161:1)
Block(-8,21,-1,161:1)
Block(-8,21,1,161:1)
Block(-8,21,3,161:1)
Block(-8,21,4,162:13)
Block(-8,21,5,161:1)
Block(-8,21,6,161:1)
Block(-8,22,4,161:1)
Block(-8,23,5,161:1)
Block(-7,17,0,161:1)
Block(-7,17,1,162:13)
Block(-7,17,2,162:13)
Block(-7,18,-2,161:1)
Block(-7,18,-1,161:1)
Block(-7,18,0,161:1)
Block(-7,18,1,161:1)
Block(-7,18,2,162:13)
Block(-7,18,3,162:13)
Block(-7,18,4,161:1)
Block(-7,19,-4,161:1)
Block(-7,19,-2,161:1)
Block(-7,19,-1,161:1)
Block(-7,19,0,161:1)
Block(-7,19,1,161:1)
Block(-7,19,2,161:1)
Block(-7,19,3,162:13)
Block(-7,19,4,161:1)
Block(-7,19,5,161:1)
Block(-7,19,6,161:1)
Block(-7,20,0,161:1)
Block(-7,20,1,161:1)
Block(-7,20,2,161:1)
Block(-7,20,3,161:1)
Block(-7,20,4,161:1)
Block(-7,20,5,161:1)
Block(-7,20,7,161:1)
Block(-7,21,-3,161:1)
Block(-7,21,1,161:1)
Block(-7,21,2,161:1)
Block(-7,21,3,161:1)
Block(-7,21,4,161:1)
Block(-7,22,3,161:1)
Block(-7,22,4,161:1)
Block(-7,23,1,161:1)
Block(-6,16,0,162:13)
Block(-6,16,1,162:13)
Block(-6,17,-1,161:1)
Block(-6,17,0,162:13)
Block(-6,17,1,162:13)
Block(-6,18,-6,161:1)
Block(-6,18,0,161:1)
Block(-6,18,1,162:13)
Block(-6,18,2,162:13)
Block(-6,18,3,161:1)
Block(-6,18,4,161:1)
Block(-6,19,-3,161:1)
Block(-6,19,-2,161:1)
Block(-6,19,-1,161:1)
Block(-6,19,0,161:1)
Block(-6,19,1,161:1)
Block(-6,19,2,161:1)
Block(-6,19,3,161:1)
Block(-6,19,4,161:1)
Block(-6,19,5,161:1)
Block(-6,19,6,161:1)
Block(-6,19,7,161:1)
Block(-6,20,-6,161:1)
Block(-6,20,-3,161:1)
Block(-6,20,-1,161:1)
Block(-6,20,0,161:1)
Block(-6,20,1,161:1)
Block(-6,20,2,161:1)
Block(-6,20,3,161:1)
Block(-6,20,4,161:1)
Block(-6,20,5,161:1)
Block(-6,20,6,161:1)
Block(-6,21,0,161:1)
Block(-6,21,1,161:1)
Block(-6,21,2,161:1)
Block(-6,21,3,161:1)
Block(-6,21,4,161:1)
Block(-6,21,5,161:1)
Block(-6,22,-6,161:1)
Block(-6,22,-1,161:1)
Block(-6,22,1,161:1)
Block(-6,22,2,161:1)
Block(-6,22,3,161:1)
Block(-6,22,4,161:1)
Block(-6,22,6,161:1)
Block(-6,23,3,161:1)
Block(-6,24,0,161:1)
Block(-6,24,4,161:1)
Block(-5,10,-7,161:1)
Block(-5,15,0,162:13)
Block(-5,16,0,162:13)
Block(-5,16,1,162:13)
Block(-5,17,-6,161:1)
Block(-5,17,-4,161:1)
Block(-5,17,0,161:1)
Block(-5,17,1,162:13)
Block(-5,17,4,161:1)
Block(-5,18,-6,161:1)
Block(-5,18,-5,161:1)
Block(-5,18,-3,161:1)
Block(-5,18,0,161:1)
Block(-5,18,1,161:1)
Block(-5,18,2,161:1)
Block(-5,18,5,161:1)
Block(-5,18,6,161:1)
Block(-5,19,-7,161:1)
Block(-5,19,-6,161:1)
Block(-5,19,-5,161:1)
Block(-5,19,-4,161:1)
Block(-5,19,-3,161:1)
Block(-5,19,-2,161:1)
Block(-5,19,1,161:1)
Block(-5,19,2,161:1)
Block(-5,19,4,161:1)
Block(-5,19,5,161:1)
Block(-5,19,6,161:1)
Block(-5,19,7,161:1)
Block(-5,20,-7,161:1)
Block(-5,20,-6,162:13)
Block(-5,20,-5,161:1)
Block(-5,20,-2,161:1)
Block(-5,20,-1,161:1)
Block(-5,20,0,161:1)
Block(-5,20,1,161:1)
Block(-5,20,2,161:1)
Block(-5,20,3,161:1)
Block(-5,20,4,161:1)
Block(-5,20,5,161:1)
Block(-5,20,6,161:1)
Block(-5,20,7,161:1)
Block(-5,21,-6,161:1)
Block(-5,21,-1,161:1)
Block(-5,21,0,161:1)
Block(-5,21,1,161:1)
Block(-5,21,2,161:1)
Block(-5,21,3,161:1)
Block(-5,21,4,161:1)
Block(-5,21,5,161:1)
Block(-5,21,6,161:1)
Block(-5,21,9,161:1)
Block(-5,22,-3,161:1)
Block(-5,22,0,161:1)
Block(-5,22,1,161:1)
Block(-5,22,2,161:1)
Block(-5,22,3,161:1)
Block(-5,22,4,161:1)
Block(-5,22,5,161:1)
Block(-5,23,-4,161:1)
Block(-5,23,1,161:1)
Block(-5,23,2,161:1)
Block(-5,23,3,161:1)
Block(-5,24,5,161:1)
Block(-5,25,2,161:1)
Block(-4,10,-9,161:1)
Block(-4,10,-5,161:1)
Block(-4,11,-7,161:1)
Block(-4,12,-6,161:1)
Block(-4,12,-5,161:1)
Block(-4,14,0,162:13)
Block(-4,15,-1,162:13)
Block(-4,15,0,162:13)
Block(-4,15,1,162:13)
Block(-4,16,-1,39)
Block(-4,16,0,162:13)
Block(-4,16,1,162:13)
Block(-4,17,1,161:1)
Block(-4,18,-7,161:1)
Block(-4,18,-6,161:1)
Block(-4,18,-5,161:1)
Block(-4,18,-4,161:1)
Block(-4,18,-2,161:1)
Block(-4,18,5,161:1)
Block(-4,19,-8,161:1)
Block(-4,19,-7,161:1)
Block(-4,19,-6,161:1)
Block(-4,19,-5,161:1)
Block(-4,19,-4,161:1)
Block(-4,19,-3,161:1)
Block(-4,19,-2,161:1)
Block(-4,19,-1,161:1)
Block(-4,19,2,161:1)
Block(-4,19,3,161:1)
Block(-4,19,4,161:1)
Block(-4,19,5,161:1)
Block(-4,19,6,161:1)
Block(-4,20,-7,161:1)
Block(-4,20,-6,162:13)
Block(-4,20,-5,162:13)
Block(-4,20,-4,161:1)
Block(-4,20,-3,161:1)
Block(-4,20,-2,161:1)
Block(-4,20,-1,161:1)
Block(-4,20,3,161:1)
Block(-4,20,4,161:1)
Block(-4,20,5,161:1)
Block(-4,20,6,161:1)
Block(-4,20,7,161:1)
Block(-4,21,-6,161:1)
Block(-4,21,-5,161:1)
Block(-4,21,-2,161:1)
Block(-4,21,-1,161:1)
Block(-4,21,0,161:1)
Block(-4,21,1,161:1)
Block(-4,21,2,161:1)
Block(-4,21,3,161:1)
Block(-4,21,4,161:1)
Block(-4,21,5,161:1)
Block(-4,21,6,161:1)
Block(-4,21,7,161:1)
Block(-4,21,8,161:1)
Block(-4,22,-7,161:1)
Block(-4,22,-5,161:1)
Block(-4,22,-1,161:1)
Block(-4,22,0,161:1)
Block(-4,22,1,161:1)
Block(-4,22,2,161:1)
Block(-4,22,3,161:1)
Block(-4,22,4,161:1)
Block(-4,22,5,161:1)
Block(-4,22,6,161:1)
Block(-4,23,0,161:1)
Block(-4,23,1,161:1)
Block(-4,23,2,161:1)
Block(-4,23,3,161:1)
Block(-4,23,4,161:1)
Block(-4,23,5,161:1)
Block(-4,23,7,161:1)
Block(-4,24,-3,161:1)
Block(-4,24,-1,161:1)
Block(-4,24,2,161:1)
Block(-4,24,6,161:1)
Block(-3,0,0,162:13)
Block(-3,10,-7,161:1)
Block(-3,10,-6,161:1)
Block(-3,11,-8,161:1)
Block(-3,11,-7,161:1)
Block(-3,11,-6,161:1)
Block(-3,12,-5,161:1)
Block(-3,13,-7,161:1)
Block(-3,13,0,162:13)
Block(-3,14,-1,162:13)
Block(-3,14,0,162:13)
Block(-3,14,1,162:13)
Block(-3,15,-1,162:13)
Block(-3,15,0,162:13)
Block(-3,15,1,162:13)
Block(-3,16,-1,39)
Block(-3,16,0,39)
Block(-3,16,4,161:1)
Block(-3,17,-5,161:1)
Block(-3,17,5,161:1)
Block(-3,18,-6,161:1)
Block(-3,18,-5,161:1)
Block(-3,18,-4,161:1)
Block(-3,18,-3,161:1)
Block(-3,18,-1,161:1)
Block(-3,18,4,161:1)
Block(-3,18,5,161:1)
Block(-3,18,6,161:1)
Block(-3,19,-8,161:1)
Block(-3,19,-7,161:1)
Block(-3,19,-6,161:1)
Block(-3,19,-5,162:13)
Block(-3,19,-4,162:13)
Block(-3,19,-3,161:1)
Block(-3,19,-2,161:1)
Block(-3,19,-1,161:1)
Block(-3,19,1,161:1)
Block(-3,19,3,161:1)
Block(-3,19,5,161:1)
Block(-3,19,6,161:1)
Block(-3,19,7,161:1)
Block(-3,20,-7,161:1)
Block(-3,20,-6,161:1)
Block(-3,20,-5,162:13)
Block(-3,20,-4,161:1)
Block(-3,20,-3,161:1)
Block(-3,20,-2,161:1)
Block(-3,20,1,161:1)
Block(-3,20,2,161:1)
Block(-3,20,3,161:1)
Block(-3,20,4,161:1)
Block(-3,20,5,161:1)
Block(-3,20,6,161:1)
Block(-3,21,-8,161:1)
Block(-3,21,-6,161:1)
Block(-3,21,-5,161:1)
Block(-3,21,-3,161:1)
Block(-3,21,-2,161:1)
Block(-3,21,-1,161:1)
Block(-3,21,0,161:1)
Block(-3,21,1,161:1)
Block(-3,21,2,161:1)
Block(-3,21,3,161:1)
Block(-3,21,4,161:1)
Block(-3,21,5,161:1)
Block(-3,21,6,161:1)
Block(-3,21,7,161:1)
Block(-3,22,-2,161:1)
Block(-3,22,-1,161:1)
Block(-3,22,0,161:1)
Block(-3,22,1,161:1)
Block(-3,22,2,161:1)
Block(-3,22,3,161:1)
Block(-3,22,4,161:1)
Block(-3,22,5,161:1)
Block(-3,22,6,161:1)
Block(-3,23,-2,161:1)
Block(-3,23,-1,161:1)
Block(-3,23,0,161:1)
Block(-3,23,1,161:1)
Block(-3,23,2,161:1)
Block(-3,23,3,161:1)
Block(-3,23,4,161:1)
Block(-3,23,5,161:1)
Block(-3,24,-2,161:1)
Block(-3,24,1,161:1)
Block(-3,24,2,161:1)
Block(-3,24,3,161:1)
Block(-3,25,1,161:1)
Block(-3,25,4,161:1)
Block(-2,0,-1,162:13)
Block(-2,10,-8,161:1)
Block(-2,10,-7,161:1)
Block(-2,10,-6,161:1)
Block(-2,11,-9,161:1)
Block(-2,11,-8,161:1)
Block(-2,11,-7,161:1)
Block(-2,11,-6,161:1)
Block(-2,11,-5,161:1)
Block(-2,11,-4,161:1)
Block(-2,11,-2,162:13)
Block(-2,11,-1,162:13)
Block(-2,12,-8,161:1)
Block(-2,12,-7,161:1)
Block(-2,12,-6,161:1)
Block(-2,12,-2,162:13)
Block(-2,12,-1,162:13)
Block(-2,12,0,162:13)
Block(-2,13,-5,161:1)
Block(-2,13,-1,162:13)
Block(-2,13,0,162:13)
Block(-2,13,1,162:13)
Block(-2,14,-7,161:1)
Block(-2,14,-2,161:1)
Block(-2,14,-1,162:13)
Block(-2,14,0,162:13)
Block(-2,15,-2,39)
Block(-2,15,-1,161:1)
Block(-2,16,-7,161:1)
Block(-2,16,-1,39)
Block(-2,17,-6,161:1)
Block(-2,17,-5,161:1)
Block(-2,17,-4,161:1)
Block(-2,17,2,161:1)
Block(-2,18,-7,161:1)
Block(-2,18,-6,161:1)
Block(-2,18,-5,161:1)
Block(-2,18,-4,162:13)
Block(-2,18,-3,162:13)
Block(-2,18,-2,161:1)
Block(-2,18,-1,161:1)
Block(-2,18,1,161:1)
Block(-2,18,4,161:1)
Block(-2,18,5,161:1)
Block(-2,19,-9,161:1)
Block(-2,19,-7,161:1)
Block(-2,19,-6,161:1)
Block(-2,19,-5,162:13)
Block(-2,19,-4,162:13)
Block(-2,19,-3,161:1)
Block(-2,19,-2,161:1)
Block(-2,19,-1,161:1)
Block(-2,19,0,161:1)
Block(-2,19,1,161:1)
Block(-2,19,2,161:1)
Block(-2,19,3,161:1)
Block(-2,19,4,161:1)
Block(-2,19,5,161:1)
Block(-2,19,6,161:1)
Block(-2,19,7,161:1)
Block(-2,20,-6,161:1)
Block(-2,20,-5,161:1)
Block(-2,20,-4,161:1)
Block(-2,20,-3,161:1)
Block(-2,20,0,161:1)
Block(-2,20,1,161:1)
Block(-2,20,2,161:1)
Block(-2,20,3,161:1)
Block(-2,20,4,161:1)
Block(-2,20,5,161:1)
Block(-2,20,6,161:1)
Block(-2,21,-5,161:1)
Block(-2,21,-4,161:1)
Block(-2,21,-3,161:1)
Block(-2,21,0,161:1)
Block(-2,21,1,161:1)
Block(-2,21,3,161:1)
Block(-2,21,4,161:1)
Block(-2,21,5,162:13)
Block(-2,21,6,161:1)
Block(-2,21,7,161:1)
Block(-2,22,-5,161:1)
Block(-2,22,-3,161:1)
Block(-2,22,-2,161:1)
Block(-2,22,-1,161:1)
Block(-2,22,0,161:1)
Block(-2,22,1,161:1)
Block(-2,22,2,161:1)
Block(-2,22,3,161:1)
Block(-2,22,4,161:1)
Block(-2,22,5,162:13)
Block(-2,22,6,161:1)
Block(-2,22,7,161:1)
Block(-2,23,-2,161:1)
Block(-2,23,-1,161:1)
Block(-2,23,0,161:1)
Block(-2,23,1,161:1)
Block(-2,23,2,161:1)
Block(-2,23,3,161:1)
Block(-2,23,4,161:1)
Block(-2,23,5,161:1)
Block(-2,24,-4,161:1)
Block(-2,24,-1,161:1)
Block(-2,24,0,161:1)
Block(-2,24,1,161:1)
Block(-2,24,2,161:1)
Block(-2,24,3,161:1)
Block(-2,24,4,161:1)
Block(-2,25,-2,161:1)
Block(-1,0,-3,161:1)
Block(-1,0,-2,162:13)
Block(-1,0,-1,162:13)
Block(-1,0,4,162:13)
Block(-1,0,5,162:13)
Block(-1,1,-3,161:1)
Block(-1,1,-2,162:13)
Block(-1,1,-1,161:1)
Block(-1,2,-2,161:1)
Block(-1,2,-1,106:8)
Block(-1,3,-2,161:1)
Block(-1,3,-1,106:8)
Block(-1,4,-2,106:8)
Block(-1,4,-1,106:8)
Block(-1,5,-2,106:8)
Block(-1,5,-1,106:8)
Block(-1,9,-2,162:13)
Block(-1,10,-9,161:1)
Block(-1,10,-8,161:1)
Block(-1,10,-7,161:1)
Block(-1,10,-6,161:1)
Block(-1,10,-2,162:13)
Block(-1,10,-1,162:13)
Block(-1,11,-9,161:1)
Block(-1,11,-8,162:13)
Block(-1,11,-7,162:13)
Block(-1,11,-6,161:1)
Block(-1,11,-5,161:1)
Block(-1,11,-2,162:13)
Block(-1,11,-1,162:13)
Block(-1,12,-8,161:1)
Block(-1,12,-7,161:1)
Block(-1,12,-6,161:1)
Block(-1,12,-2,162:13)
Block(-1,12,-1,162:13)
Block(-1,12,0,162:13)
Block(-1,13,-9,161:1)
Block(-1,13,-7,161:1)
Block(-1,13,-1,162:13)
Block(-1,13,0,162:13)
Block(-1,14,-2,162:13)
Block(-1,14,-1,162:13)
Block(-1,14,0,39)
Block(-1,15,-2,162:13)
Block(-1,15,-1,162:13)
Block(-1,16,-2,162:13)
Block(-1,16,-1,161:1)
Block(-1,17,-5,161:1)
Block(-1,17,-4,161:1)
Block(-1,17,-3,162:13)
Block(-1,17,-2,162:13)
Block(-1,18,-6,161:1)
Block(-1,18,-5,161:1)
Block(-1,18,-4,162:13)
Block(-1,18,-3,162:13)
Block(-1,18,-2,161:1)
Block(-1,18,1,161:1)
Block(-1,18,2,162:13)
Block(-1,18,5,161:1)
Block(-1,19,-8,161:1)
Block(-1,19,-7,161:1)
Block(-1,19,-6,161:1)
Block(-1,19,-5,161:1)
Block(-1,19,-4,161:1)
Block(-1,19,-3,161:1)
Block(-1,19,-2,161:1)
Block(-1,19,1,161:1)
Block(-1,19,2,161:1)
Block(-1,19,3,162:13)
Block(-1,19,4,162:13)
Block(-1,19,5,161:1)
Block(-1,19,6,161:1)
Block(-1,20,-7,161:1)
Block(-1,20,-6,161:1)
Block(-1,20,-5,161:1)
Block(-1,20,-4,161:1)
Block(-1,20,-3,161:1)
Block(-1,20,-1,161:1)
Block(-1,20,0,161:1)
Block(-1,20,1,161:1)
Block(-1,20,2,161:1)
Block(-1,20,3,162:13)
Block(-1,20,4,162:13)
Block(-1,20,5,161:1)
Block(-1,20,6,161:1)
Block(-1,21,-6,161:1)
Block(-1,21,-5,161:1)
Block(-1,21,-4,161:1)
Block(-1,21,-3,161:1)
Block(-1,21,-2,161:1)
Block(-1,21,0,161:1)
Block(-1,21,1,161:1)
Block(-1,21,2,161:1)
Block(-1,21,3,161:1)
Block(-1,21,4,162:13)
Block(-1,21,5,162:13)
Block(-1,21,6,161:1)
Block(-1,21,7,161:1)
Block(-1,22,-6,161:1)
Block(-1,22,-5,161:1)
Block(-1,22,-4,161:1)
Block(-1,22,-3,161:1)
Block(-1,22,-2,161:1)
Block(-1,22,-1,161:1)
Block(-1,22,1,161:1)
Block(-1,22,2,161:1)
Block(-1,22,3,161:1)
Block(-1,22,4,161:1)
Block(-1,22,5,161:1)
Block(-1,22,6,161:1)
Block(-1,23,-7,161:1)
Block(-1,23,-4,161:1)
Block(-1,23,-3,161:1)
Block(-1,23,-2,161:1)
Block(-1,23,-1,161:1)
Block(-1,23,0,161:1)
Block(-1,23,1,161:1)
Block(-1,23,2,161:1)
Block(-1,23,3,161:1)
Block(-1,23,4,161:1)
Block(-1,23,5,161:1)
Block(-1,24,-1,161:1)
Block(-1,24,0,161:1)
Block(-1,24,1,161:1)
Block(-1,24,6,161:1)
Block(-1,25,1,161:1)
Block(-1,25,3,161:1)
Block(0,0,-8,162:13)
Block(0,0,-7,162:13)
Block(0,0,-6,162:13)
Block(0,0,-4,161:1)
Block(0,0,-3,162:13)
Block(0,0,-2,162:13)
Block(0,0,-1,162:13)
Block(0,0,0,162:13)
Block(0,0,2,162:13)
Block(0,0,3,162:13)
Block(0,0,4,162:13)
Block(0,1,-3,162:13)
Block(0,1,-2,162:13)
Block(0,1,-1,162:13)
Block(0,1,0,162:13)
Block(0,1,2,162:13)
Block(0,1,3,161:1)
Block(0,2,-3,162:13)
Block(0,2,-2,162:13)
Block(0,2,-1,162:13)
Block(0,2,0,106:4)
Block(0,3,-3,162:13)
Block(0,3,-2,162:13)
Block(0,3,-1,162:13)
Block(0,3,0,106:8)
Block(0,4,-3,161:1)
Block(0,4,-2,162:13)
Block(0,4,-1,162:13)
Block(0,4,0,106:8)
Block(0,5,-3,161:1)
Block(0,5,-2,162:13)
Block(0,5,-1,162:13)
Block(0,5,0,106:12)
Block(0,6,-2,162:13)
Block(0,6,-1,162:13)
Block(0,7,-2,162:13)
Block(0,7,-1,162:13)
Block(0,7,0,161:1)
Block(0,8,-2,162:13)
Block(0,8,-1,162:13)
Block(0,8,0,161:1)
Block(0,9,-2,162:13)
Block(0,9,-1,162:13)
Block(0,10,-8,161:1)
Block(0,10,-7,162:13)
Block(0,10,-6,162:13)
Block(0,10,-5,161:1)
Block(0,10,-2,162:13)
Block(0,10,-1,162:13)
Block(0,11,-9,161:1)
Block(0,11,-8,161:1)
Block(0,11,-7,162:13)
Block(0,11,-6,162:13)
Block(0,11,-5,161:1)
Block(0,11,-2,162:13)
Block(0,11,-1,162:13)
Block(0,11,0,162:13)
Block(0,12,-10,161:1)
Block(0,12,-8,161:1)
Block(0,12,-7,161:1)
Block(0,12,-6,161:1)
Block(0,12,-2,162:13)
Block(0,12,-1,162:13)
Block(0,12,0,162:13)
Block(0,13,-2,162:13)
Block(0,13,-1,162:13)
Block(0,13,0,162:13)
Block(0,14,-2,162:13)
Block(0,14,-1,162:13)
Block(0,14,0,162:13)
Block(0,15,-2,162:13)
Block(0,15,-1,162:13)
Block(0,15,0,162:13)
Block(0,16,-3,162:13)
Block(0,16,-2,162:13)
Block(0,16,-1,162:13)
Block(0,16,0,162:13)
Block(0,16,1,162:13)
Block(0,16,4,161:1)
Block(0,17,-3,162:13)
Block(0,17,-2,162:13)
Block(0,17,-1,161:1)
Block(0,17,1,162:13)
Block(0,17,2,162:13)
Block(0,18,-6,161:1)
Block(0,18,-4,161:1)
Block(0,18,-3,161:1)
Block(0,18,2,162:13)
Block(0,18,3,162:13)
Block(0,18,4,161:1)
Block(0,19,-10,161:1)
Block(0,19,-8,161:1)
Block(0,19,-7,161:1)
Block(0,19,-6,161:1)
Block(0,19,-5,161:1)
Block(0,19,-4,161:1)
Block(0,19,-3,161:1)
Block(0,19,-2,161:1)
Block(0,19,-1,161:1)
Block(0,19,2,161:1)
Block(0,19,3,162:13)
Block(0,19,4,161:1)
Block(0,19,5,161:1)
Block(0,19,6,161:1)
Block(0,20,-8,161:1)
Block(0,20,-7,161:1)
Block(0,20,-6,161:1)
Block(0,20,-5,161:1)
Block(0,20,-4,161:1)
Block(0,20,-3,161:1)
Block(0,20,-2,161:1)
Block(0,20,-1,161:1)
Block(0,20,0,161:1)
Block(0,20,1,161:1)
Block(0,20,2,161:1)
Block(0,20,3,161:1)
Block(0,20,4,161:1)
Block(0,21,-9,161:1)
Block(0,21,-6,161:1)
Block(0,21,-5,161:1)
Block(0,21,-4,161:1)
Block(0,21,-3,161:1)
Block(0,21,-2,161:1)
Block(0,21,-1,161:1)
Block(0,21,0,161:1)
Block(0,21,2,161:1)
Block(0,21,3,161:1)
Block(0,21,4,161:1)
Block(0,21,5,161:1)
Block(0,22,-5,161:1)
Block(0,22,-4,161:1)
Block(0,22,-3,161:1)
Block(0,22,-1,161:1)
Block(0,22,0,161:1)
Block(0,22,1,161:1)
Block(0,22,2,161:1)
Block(0,22,3,161:1)
Block(0,22,4,161:1)
Block(0,22,5,161:1)
Block(0,23,-5,161:1)
Block(0,23,-4,161:1)
Block(0,23,-3,161:1)
Block(0,23,-2,161:1)
Block(0,23,-1,161:1)
Block(0,23,0,161:1)
Block(0,23,1,161:1)
Block(0,23,2,161:1)
Block(0,24,-4,161:1)
Block(0,24,-2,161:1)
Block(0,24,-1,161:1)
Block(0,24,0,161:1)
Block(0,24,4,161:1)
Block(0,25,-1,161:1)
Block(1,0,-7,162:13)
Block(1,0,-6,162:13)
Block(1,0,-5,162:13)
Block(1,0,-4,162:13)
Block(1,0,-3,162:13)
Block(1,0,-2,162:13)
Block(1,0,-1,162:13)
Block(1,0,0,162:13)
Block(1,0,1,162:13)
Block(1,0,2,162:13)
Block(1,0,3,162:13)
Block(1,0,4,161:1)
Block(1,1,-5,162:13)
Block(1,1,-4,162:13)
Block(1,1,-3,162:13)
Block(1,1,-2,162:13)
Block(1,1,-1,162:13)
Block(1,1,0,162:13)
Block(1,1,1,162:13)
Block(1,1,2,162:13)
Block(1,2,-4,162:13)
Block(1,2,-3,162:13)
Block(1,2,-2,162:13)
Block(1,2,-1,162:13)
Block(1,2,0,162:13)
Block(1,2,1,162:13)
Block(1,2,2,161:1)
Block(1,3,-4,162:13)
Block(1,3,-3,162:13)
Block(1,3,-2,162:13)
Block(1,3,-1,162:13)
Block(1,3,0,162:13)
Block(1,3,1,106:4)
Block(1,4,-4,162:13)
Block(1,4,-3,162:13)
Block(1,4,-2,162:13)
Block(1,4,-1,162:13)
Block(1,4,0,162:13)
Block(1,4,1,106:4)
Block(1,5,-4,162:13)
Block(1,5,-3,162:13)
Block(1,5,-2,162:13)
Block(1,5,-1,162:13)
Block(1,5,0,162:13)
Block(1,6,-3,162:13)
Block(1,6,-2,162:13)
Block(1,6,-1,162:13)
Block(1,6,0,162:13)
Block(1,7,-3,162:13)
Block(1,7,-2,162:13)
Block(1,7,-1,162:13)
Block(1,7,0,162:13)
Block(1,8,-4,162:13)
Block(1,8,-3,162:13)
Block(1,8,-2,162:13)
Block(1,8,-1,162:13)
Block(1,8,0,162:13)
Block(1,9,-5,162:13)
Block(1,9,-4,162:13)
Block(1,9,-3,162:13)
Block(1,9,-2,162:13)
Block(1,9,-1,162:13)
Block(1,9,0,162:13)
Block(1,9,1,161:1)
Block(1,10,-7,161:1)
Block(1,10,-6,162:13)
Block(1,10,-5,162:13)
Block(1,10,-3,162:13)
Block(1,10,-2,162:13)
Block(1,10,-1,162:13)
Block(1,10,0,162:13)
Block(1,11,-8,161:1)
Block(1,11,-7,161:1)
Block(1,11,-6,161:1)
Block(1,11,-3,162:13)
Block(1,11,-2,162:13)
Block(1,11,-1,162:13)
Block(1,11,0,162:13)
Block(1,12,-7,161:1)
Block(1,12,-3,162:13)
Block(1,12,-2,162:13)
Block(1,12,-1,162:13)
Block(1,12,0,162:13)
Block(1,13,-8,161:1)
Block(1,13,-6,161:1)
Block(1,13,-3,39)
Block(1,13,-2,162:13)
Block(1,13,-1,162:13)
Block(1,13,0,162:13)
Block(1,14,-2,162:13)
Block(1,14,-1,162:13)
Block(1,14,0,162:13)
Block(1,15,-2,162:13)
Block(1,15,-1,162:13)
Block(1,15,0,162:13)
Block(1,15,1,162:13)
Block(1,16,-2,162:13)
Block(1,16,-1,162:13)
Block(1,16,0,162:13)
Block(1,16,1,162:13)
Block(1,17,-8,161:1)
Block(1,17,-4,161:1)
Block(1,17,-1,162:13)
Block(1,17,0,161:1)
Block(1,17,1,162:13)
Block(1,17,2,162:13)
Block(1,17,4,161:1)
Block(1,18,-7,161:1)
Block(1,18,-1,162:13)
Block(1,18,0,161:1)
Block(1,18,2,162:13)
Block(1,18,3,161:1)
Block(1,18,4,161:1)
Block(1,18,5,161:1)
Block(1,19,-9,161:1)
Block(1,19,-8,161:1)
Block(1,19,-7,161:1)
Block(1,19,-6,161:1)
Block(1,19,-5,161:1)
Block(1,19,-4,161:1)
Block(1,19,-3,161:1)
Block(1,19,-2,161:1)
Block(1,19,-1,161:1)
Block(1,19,3,161:1)
Block(1,19,5,161:1)
Block(1,19,6,161:1)
Block(1,20,-7,161:1)
Block(1,20,-6,161:1)
Block(1,20,-5,161:1)
Block(1,20,-4,161:1)
Block(1,20,-3,161:1)
Block(1,20,-2,161:1)
Block(1,20,-1,161:1)
Block(1,20,0,161:1)
Block(1,20,1,161:1)
Block(1,20,2,161:1)
Block(1,20,3,161:1)
Block(1,20,4,161:1)
Block(1,20,5,161:1)
Block(1,21,-7,161:1)
Block(1,21,-6,161:1)
Block(1,21,-5,161:1)
Block(1,21,-3,161:1)
Block(1,21,-2,161:1)
Block(1,21,-1,161:1)
Block(1,21,0,161:1)
Block(1,21,1,161:1)
Block(1,21,3,161:1)
Block(1,21,6,161:1)
Block(1,22,-6,161:1)
Block(1,22,-5,161:1)
Block(1,22,-3,161:1)
Block(1,22,-2,161:1)
Block(1,22,-1,161:1)
Block(1,22,0,161:1)
Block(1,22,1,161:1)
Block(1,22,2,161:1)
Block(1,23,-7,161:1)
Block(1,23,-5,161:1)
Block(1,23,-4,161:1)
Block(1,23,-3,161:1)
Block(1,23,-2,161:1)
Block(1,23,-1,161:1)
Block(1,23,0,161:1)
Block(1,23,1,161:1)
Block(1,23,5,161:1)
Block(1,24,-6,161:1)
Block(1,24,-3,161:1)
Block(1,24,-2,161:1)
Block(1,24,-1,161:1)
Block(1,24,2,161:1)
Block(1,25,-4,161:1)
Block(1,25,-2,161:1)
Block(2,0,-7,161:1)
Block(2,0,-6,162:13)
Block(2,0,-5,162:13)
Block(2,0,-4,162:13)
Block(2,0,-3,162:13)
Block(2,0,-2,162:13)
Block(2,0,-1,162:13)
Block(2,0,0,162:13)
Block(2,0,1,162:13)
Block(2,1,-6,162:13)
Block(2,1,-5,162:13)
Block(2,1,-4,162:13)
Block(2,1,-3,162:13)
Block(2,1,-2,162:13)
Block(2,1,-1,162:13)
Block(2,1,0,162:13)
Block(2,1,1,162:13)
Block(2,2,-5,162:13)
Block(2,2,-4,162:13)
Block(2,2,-3,162:13)
Block(2,2,-2,162:13)
Block(2,2,-1,162:13)
Block(2,2,0,162:13)
Block(2,2,1,162:13)
Block(2,3,-5,162:13)
Block(2,3,-4,162:13)
Block(2,3,-3,162:13)
Block(2,3,-2,162:13)
Block(2,3,-1,162:13)
Block(2,3,0,162:13)
Block(2,3,1,162:13)
Block(2,4,-4,162:13)
Block(2,4,-3,162:13)
Block(2,4,-2,162:13)
Block(2,4,-1,162:13)
Block(2,4,0,162:13)
Block(2,4,1,162:13)
Block(2,5,-4,162:13)
Block(2,5,-3,162:13)
Block(2,5,-2,162:13)
Block(2,5,-1,162:13)
Block(2,5,0,162:13)
Block(2,5,1,162:13)
Block(2,6,-4,162:13)
Block(2,6,-3,162:13)
Block(2,6,-2,162:13)
Block(2,6,-1,162:13)
Block(2,6,0,162:13)
Block(2,7,-4,162:13)
Block(2,7,-3,162:13)
Block(2,7,-2,162:13)
Block(2,7,-1,162:13)
Block(2,7,0,162:13)
Block(2,8,-4,162:13)
Block(2,8,-3,162:13)
Block(2,8,-2,162:13)
Block(2,8,-1,162:13)
Block(2,8,0,162:13)
Block(2,9,-5,162:13)
Block(2,9,-4,162:13)
Block(2,9,-3,162:13)
Block(2,9,-2,162:13)
Block(2,9,-1,162:13)
Block(2,9,0,162:13)
Block(2,10,-6,161:1)
Block(2,10,-5,162:13)
Block(2,10,-4,162:13)
Block(2,10,-3,162:13)
Block(2,10,-2,162:13)
Block(2,10,-1,162:13)
Block(2,10,0,162:13)
Block(2,10,1,161:1)
Block(2,11,-8,161:1)
Block(2,11,-4,162:13)
Block(2,11,-3,162:13)
Block(2,11,-2,162:13)
Block(2,11,-1,162:13)
Block(2,11,0,162:13)
Block(2,11,1,161:1)
Block(2,12,-4,162:13)
Block(2,12,-3,162:13)
Block(2,12,-2,162:13)
Block(2,12,-1,162:13)
Block(2,12,0,162:13)
Block(2,12,3,161:1)
Block(2,13,-4,39)
Block(2,13,-3,162:13)
Block(2,13,-2,162:13)
Block(2,13,-1,162:13)
Block(2,13,0,162:13)
Block(2,14,-4,161:1)
Block(2,14,-3,162:13)
Block(2,14,-2,162:13)
Block(2,14,-1,162:13)
Block(2,15,-3,161:1)
Block(2,15,-2,162:13)
Block(2,15,-1,162:13)
Block(2,16,-2,162:13)
Block(2,16,-1,162:13)
Block(2,16,0,30)
Block(2,17,-2,161:1)
Block(2,17,-1,161:1)
Block(2,17,0,161:1)
Block(2,18,-8,161:1)
Block(2,18,-7,161:1)
Block(2,18,-3,161:1)
Block(2,18,-2,161:1)
Block(2,18,-1,162:13)
Block(2,18,0,161:1)
Block(2,18,1,161:1)
Block(2,18,3,161:1)
Block(2,18,4,161:1)
Block(2,19,-9,161:1)
Block(2,19,-8,161:1)
Block(2,19,-7,161:1)
Block(2,19,-6,161:1)
Block(2,19,-2,161:1)
Block(2,19,-1,162:13)
Block(2,19,0,161:1)
Block(2,19,1,161:1)
Block(2,19,2,161:1)
Block(2,19,3,161:1)
Block(2,19,4,161:1)
Block(2,19,5,161:1)
Block(2,20,-8,161:1)
Block(2,20,-7,161:1)
Block(2,20,-6,161:1)
Block(2,20,-5,161:1)
Block(2,20,-4,161:1)
Block(2,20,-3,161:1)
Block(2,20,-2,161:1)
Block(2,20,-1,161:1)
Block(2,20,0,161:1)
Block(2,20,1,161:1)
Block(2,20,2,161:1)
Block(2,20,3,161:1)
Block(2,20,4,161:1)
Block(2,20,7,161:1)
Block(2,21,-9,161:1)
Block(2,21,-7,161:1)
Block(2,21,-5,161:1)
Block(2,21,-4,161:1)
Block(2,21,-3,161:1)
Block(2,21,-2,161:1)
Block(2,21,-1,161:1)
Block(2,21,0,161:1)
Block(2,21,1,161:1)
Block(2,21,2,161:1)
Block(2,21,4,161:1)
Block(2,22,-6,161:1)
Block(2,22,-5,161:1)
Block(2,22,-4,161:1)
Block(2,22,-3,161:1)
Block(2,22,-2,161:1)
Block(2,22,0,161:1)
Block(2,22,1,161:1)
Block(2,23,-4,161:1)
Block(2,23,-3,161:1)
Block(2,23,-2,161:1)
Block(2,23,-1,161:1)
Block(2,23,0,161:1)
Block(2,24,-3,161:1)
Block(2,24,-2,161:1)
Block(2,24,-1,161:1)
Block(2,24,0,161:1)
Block(2,25,1,161:1)
Block(3,0,-5,162:13)
Block(3,0,-4,162:13)
Block(3,0,-3,162:13)
Block(3,0,-2,162:13)
Block(3,0,-1,162:13)
Block(3,0,0,162:13)
Block(3,0,1,162:13)
Block(3,0,2,162:13)
Block(3,1,-5,106:1)
Block(3,1,-4,162:13)
Block(3,1,-3,162:13)
Block(3,1,-2,162:13)
Block(3,1,-1,162:13)
Block(3,1,0,162:13)
Block(3,1,1,162:13)
Block(3,2,-4,162:13)
Block(3,2,-3,162:13)
Block(3,2,-2,162:13)
Block(3,2,-1,162:13)
Block(3,2,0,162:13)
Block(3,2,1,162:13)
Block(3,3,-4,162:13)
Block(3,3,-3,162:13)
Block(3,3,-2,162:13)
Block(3,3,-1,162:13)
Block(3,3,0,162:13)
Block(3,3,1,162:13)
Block(3,4,-4,162:13)
Block(3,4,-3,162:13)
Block(3,4,-2,162:13)
Block(3,4,-1,162:13)
Block(3,4,0,162:13)
Block(3,5,-4,162:13)
Block(3,5,-3,162:13)
Block(3,5,-2,162:13)
Block(3,5,-1,162:13)
Block(3,5,0,162:13)
Block(3,6,-4,162:13)
Block(3,6,-3,162:13)
Block(3,6,-2,162:13)
Block(3,6,-1,162:13)
Block(3,6,0,162:13)
Block(3,6,1,161:1)
Block(3,7,-4,162:13)
Block(3,7,-3,162:13)
Block(3,7,-2,162:13)
Block(3,7,-1,162:13)
Block(3,7,0,162:13)
Block(3,8,-4,162:13)
Block(3,8,-3,162:13)
Block(3,8,-2,162:13)
Block(3,8,-1,162:13)
Block(3,8,0,162:13)
Block(3,9,-4,162:13)
Block(3,9,-3,162:13)
Block(3,9,-2,162:13)
Block(3,9,-1,162:13)
Block(3,9,0,162:13)
Block(3,9,1,162:13)
Block(3,10,-4,162:13)
Block(3,10,-3,162:13)
Block(3,10,-2,162:13)
Block(3,10,-1,162:13)
Block(3,10,0,162:13)
Block(3,10,1,162:13)
Block(3,10,2,161:1)
Block(3,10,4,161:1)
Block(3,11,-4,162:13)
Block(3,11,-3,162:13)
Block(3,11,-2,162:13)
Block(3,11,-1,162:13)
Block(3,11,0,162:13)
Block(3,11,1,162:13)
Block(3,11,2,161:1)
Block(3,11,3,161:1)
Block(3,12,-4,162:13)
Block(3,12,-3,162:13)
Block(3,12,-2,162:13)
Block(3,12,-1,162:13)
Block(3,12,0,162:13)
Block(3,12,1,161:1)
Block(3,12,3,161:1)
Block(3,12,4,161:1)
Block(3,12,5,161:1)
Block(3,13,-4,39)
Block(3,13,-3,162:13)
Block(3,13,-2,162:13)
Block(3,13,-1,162:13)
Block(3,13,3,161:1)
Block(3,14,-3,162:13)
Block(3,14,-2,162:13)
Block(3,14,-1,162:13)
Block(3,14,4,161:1)
Block(3,15,-5,162:13)
Block(3,15,-4,162:13)
Block(3,15,-3,162:13)
Block(3,15,-2,162:13)
Block(3,15,-1,162:13)
Block(3,16,-5,161:1)
Block(3,16,-4,161:1)
Block(3,16,-3,162:13)
Block(3,16,-2,162:13)
Block(3,16,-1,161:1)
Block(3,16,2,161:1)
Block(3,17,-9,161:1)
Block(3,17,-6,161:1)
Block(3,17,-4,161:1)
Block(3,17,-3,161:1)
Block(3,17,-2,161:1)
Block(3,17,-1,161:1)
Block(3,17,0,161:1)
Block(3,17,1,161:1)
Block(3,18,-8,161:1)
Block(3,18,-4,161:1)
Block(3,18,-3,161:1)
Block(3,18,-2,161:1)
Block(3,18,-1,161:1)
Block(3,18,0,161:1)
Block(3,18,1,161:1)
Block(3,18,2,161:1)
Block(3,18,3,161:1)
Block(3,19,-10,161:1)
Block(3,19,-9,161:1)
Block(3,19,-8,161:1)
Block(3,19,-7,161:1)
Block(3,19,-3,161:1)
Block(3,19,-2,161:1)
Block(3,19,-1,161:1)
Block(3,19,0,161:1)
Block(3,19,1,161:1)
Block(3,19,2,161:1)
Block(3,19,3,161:1)
Block(3,19,4,161:1)
Block(3,20,-8,161:1)
Block(3,20,-7,161:1)
Block(3,20,-6,161:1)
Block(3,20,-5,161:1)
Block(3,20,-4,161:1)
Block(3,20,-3,161:1)
Block(3,20,-2,161:1)
Block(3,20,-1,161:1)
Block(3,20,0,161:1)
Block(3,20,1,161:1)
Block(3,20,2,161:1)
Block(3,20,3,161:1)
Block(3,21,-8,161:1)
Block(3,21,-7,161:1)
Block(3,21,-6,161:1)
Block(3,21,-5,161:1)
Block(3,21,-4,161:1)
Block(3,21,-3,161:1)
Block(3,21,-2,161:1)
Block(3,21,-1,161:1)
Block(3,21,0,161:1)
Block(3,21,1,161:1)
Block(3,21,2,161:1)
Block(3,22,-7,161:1)
Block(3,22,-6,161:1)
Block(3,22,-5,161:1)
Block(3,22,-4,161:1)
Block(3,22,-3,161:1)
Block(3,22,-2,161:1)
Block(3,22,-1,161:1)
Block(3,22,0,161:1)
Block(3,22,1,161:1)
Block(3,22,2,161:1)
Block(3,23,-8,161:1)
Block(3,23,-6,161:1)
Block(3,23,-5,161:1)
Block(3,23,-4,161:1)
Block(3,23,-3,161:1)
Block(3,23,-2,161:1)
Block(3,23,-1,161:1)
Block(3,23,1,161:1)
Block(3,23,3,161:1)
Block(3,24,-4,161:1)
Block(3,24,-3,161:1)
Block(3,25,-5,161:1)
Block(3,25,-1,161:1)
Block(4,0,-5,106:1)
Block(4,0,-4,162:13)
Block(4,0,-3,162:13)
Block(4,0,-2,162:13)
Block(4,0,-1,162:13)
Block(4,0,0,162:13)
Block(4,1,-5,106:1)
Block(4,1,-4,162:13)
Block(4,1,-3,162:13)
Block(4,1,-2,162:13)
Block(4,1,-1,162:13)
Block(4,1,0,162:13)
Block(4,2,-3,162:13)
Block(4,2,-2,162:13)
Block(4,2,-1,162:13)
Block(4,2,0,162:13)
Block(4,3,-3,162:13)
Block(4,3,-2,162:13)
Block(4,3,-1,162:13)
Block(4,4,-3,162:13)
Block(4,4,-2,162:13)
Block(4,4,-1,162:13)
Block(4,5,-3,162:13)
Block(4,5,-2,162:13)
Block(4,5,-1,162:13)
Block(4,5,0,161:1)
Block(4,6,-4,161:1)
Block(4,6,-3,162:13)
Block(4,6,-2,162:13)
Block(4,6,-1,162:13)
Block(4,7,-4,161:1)
Block(4,7,-3,162:13)
Block(4,7,-2,162:13)
Block(4,7,-1,162:13)
Block(4,8,-3,162:13)
Block(4,8,-2,162:13)
Block(4,8,-1,162:13)
Block(4,9,-3,162:13)
Block(4,9,-2,162:13)
Block(4,9,-1,162:13)
Block(4,9,0,162:13)
Block(4,10,-3,162:13)
Block(4,10,-2,162:13)
Block(4,10,-1,162:13)
Block(4,10,0,162:13)
Block(4,10,1,162:13)
Block(4,10,2,161:1)
Block(4,11,-3,162:13)
Block(4,11,-2,162:13)
Block(4,11,-1,162:13)
Block(4,11,0,162:13)
Block(4,11,1,162:13)
Block(4,11,2,162:13)
Block(4,11,3,161:1)
Block(4,12,-4,161:1)
Block(4,12,-3,162:13)
Block(4,12,-2,162:13)
Block(4,12,-1,162:13)
Block(4,12,0,161:1)
Block(4,12,1,161:1)
Block(4,12,2,161:1)
Block(4,12,3,161:1)
Block(4,12,4,161:1)
Block(4,13,-4,39)
Block(4,13,-3,162:13)
Block(4,13,-2,162:13)
Block(4,13,1,161:1)
Block(4,13,3,161:1)
Block(4,13,4,161:1)
Block(4,14,-3,162:13)
Block(4,14,-2,162:13)
Block(4,14,3,161:1)
Block(4,15,-5,162:13)
Block(4,15,-4,162:13)
Block(4,15,-3,162:13)
Block(4,15,-2,162:13)
Block(4,15,2,161:1)
Block(4,15,4,161:1)
Block(4,16,-7,161:1)
Block(4,16,-6,162:13)
Block(4,16,-5,162:13)
Block(4,16,-4,162:13)
Block(4,16,-3,162:13)
Block(4,16,-2,161:1)
Block(4,17,-6,161:1)
Block(4,17,-5,161:1)
Block(4,17,-4,161:1)
Block(4,17,-3,162:13)
Block(4,17,-2,161:1)
Block(4,17,-1,161:1)
Block(4,17,0,161:1)
Block(4,17,3,161:1)
Block(4,18,-8,161:1)
Block(4,18,-6,161:1)
Block(4,18,-5,161:1)
Block(4,18,-4,161:1)
Block(4,18,-3,161:1)
Block(4,18,-2,161:1)
Block(4,18,-1,161:1)
Block(4,18,0,161:1)
Block(4,18,1,161:1)
Block(4,18,2,161:1)
Block(4,19,-10,161:1)
Block(4,19,-9,161:1)
Block(4,19,-8,161:1)
Block(4,19,-5,161:1)
Block(4,19,-4,161:1)
Block(4,19,-3,161:1)
Block(4,19,-2,161:1)
Block(4,19,-1,161:1)
Block(4,19,1,161:1)
Block(4,19,2,161:1)
Block(4,19,3,161:1)
Block(4,19,4,161:1)
Block(4,20,-9,161:1)
Block(4,20,-8,161:1)
Block(4,20,-7,161:1)
Block(4,20,-4,161:1)
Block(4,20,-3,161:1)
Block(4,20,-2,161:1)
Block(4,20,-1,161:1)
Block(4,20,0,161:1)
Block(4,20,1,161:1)
Block(4,20,2,161:1)
Block(4,20,5,161:1)
Block(4,21,-10,161:1)
Block(4,21,-7,161:1)
Block(4,21,-6,161:1)
Block(4,21,-5,161:1)
Block(4,21,-4,161:1)
Block(4,21,-3,161:1)
Block(4,21,-2,161:1)
Block(4,21,-1,161:1)
Block(4,21,0,161:1)
Block(4,21,1,161:1)
Block(4,22,-7,161:1)
Block(4,22,-5,161:1)
Block(4,22,-4,161:1)
Block(4,22,-3,161:1)
Block(4,22,-2,161:1)
Block(4,22,-1,161:1)
Block(4,23,-4,161:1)
Block(4,23,-3,161:1)
Block(4,24,-6,161:1)
Block(4,24,-2,161:1)
Block(4,25,-3,161:1)
Block(5,0,-4,162:13)
Block(5,0,-3,162:13)
Block(5,0,-2,162:13)
Block(5,0,-1,162:13)
Block(5,0,0,162:13)
Block(5,0,1,162:13)
Block(5,1,-4,106:2)
Block(5,1,-3,162:13)
Block(5,1,-2,162:13)
Block(5,1,-1,161:1)
Block(5,1,0,162:13)
Block(5,2,-3,162:13)
Block(5,2,-2,162:13)
Block(5,3,-3,162:13)
Block(5,3,-2,162:13)
Block(5,4,-2,162:13)
Block(5,5,-2,162:13)
Block(5,6,-2,162:13)
Block(5,7,-2,162:13)
Block(5,8,-3,161:1)
Block(5,8,-2,162:13)
Block(5,9,-3,161:1)
Block(5,9,-2,162:13)
Block(5,10,-2,162:13)
Block(5,10,1,161:1)
Block(5,10,2,161:1)
Block(5,10,4,161:1)
Block(5,11,-2,162:13)
Block(5,11,-1,161:1)
Block(5,11,0,161:1)
Block(5,11,1,162:13)
Block(5,11,2,162:13)
Block(5,11,3,161:1)
Block(5,11,4,161:1)
Block(5,12,-2,162:13)
Block(5,12,1,161:1)
Block(5,12,2,162:13)
Block(5,12,3,162:13)
Block(5,12,4,161:1)
Block(5,12,5,161:1)
Block(5,13,-3,161:1)
Block(5,13,-2,161:1)
Block(5,13,2,161:1)
Block(5,13,3,161:1)
Block(5,13,4,161:1)
Block(5,14,-3,39)
Block(5,14,-2,161:1)
Block(5,14,3,161:1)
Block(5,14,4,161:1)
Block(5,14,5,161:1)
Block(5,15,-3,162:13)
Block(5,15,3,161:1)
Block(5,16,-6,161:1)
Block(5,16,-5,162:13)
Block(5,16,-4,162:13)
Block(5,16,-3,162:13)
Block(5,17,-7,161:1)
Block(5,17,-6,162:13)
Block(5,17,-5,162:13)
Block(5,17,-4,162:13)
Block(5,17,-3,161:1)
Block(5,17,-2,161:1)
Block(5,17,-1,161:1)
Block(5,17,0,161:1)
Block(5,18,-7,161:1)
Block(5,18,-6,161:1)
Block(5,18,-5,162:13)
Block(5,18,-4,162:13)
Block(5,18,-3,161:1)
Block(5,18,-2,161:1)
Block(5,18,-1,161:1)
Block(5,18,1,161:1)
Block(5,19,-9,161:1)
Block(5,19,-8,161:1)
Block(5,19,-7,161:1)
Block(5,19,-6,161:1)
Block(5,19,-5,161:1)
Block(5,19,-4,161:1)
Block(5,19,-3,161:1)
Block(5,19,-2,161:1)
Block(5,19,-1,161:1)
Block(5,19,0,161:1)
Block(5,19,1,161:1)
Block(5,19,2,161:1)
Block(5,19,3,161:1)
Block(5,20,-9,161:1)
Block(5,20,-8,161:1)
Block(5,20,-6,161:1)
Block(5,20,-5,161:1)
Block(5,20,-4,161:1)
Block(5,20,-3,161:1)
Block(5,20,-2,161:1)
Block(5,20,-1,161:1)
Block(5,20,0,161:1)
Block(5,20,1,161:1)
Block(5,20,2,161:1)
Block(5,21,-9,161:1)
Block(5,21,-8,161:1)
Block(5,21,-7,161:1)
Block(5,21,-6,161:1)
Block(5,21,-4,161:1)
Block(5,21,-3,161:1)
Block(5,21,-2,161:1)
Block(5,21,-1,161:1)
Block(5,21,0,161:1)
Block(5,21,3,161:1)
Block(5,22,-6,161:1)
Block(5,22,-4,161:1)
Block(5,22,-3,161:1)
Block(5,22,-2,161:1)
Block(5,22,-1,161:1)
Block(5,22,1,161:1)
Block(5,23,-9,161:1)
Block(5,23,-4,161:1)
Block(5,23,0,161:1)
Block(5,24,-1,161:1)
Block(6,0,-5,162:13)
Block(6,0,-3,162:13)
Block(6,0,-2,162:13)
Block(6,0,-1,161:1)
Block(6,0,0,162:13)
Block(6,0,1,162:13)
Block(6,0,2,162:13)
Block(6,1,-3,162:13)
Block(6,1,-2,162:13)
Block(6,2,-3,162:13)
Block(6,10,-2,161:1)
Block(6,10,3,161:1)
Block(6,11,1,161:1)
Block(6,11,2,161:1)
Block(6,11,3,161:1)
Block(6,11,4,161:1)
Block(6,12,2,161:1)
Block(6,12,3,162:13)
Block(6,12,4,162:13)
Block(6,12,5,161:1)
Block(6,12,6,161:1)
Block(6,13,2,161:1)
Block(6,13,3,161:1)
Block(6,13,4,161:1)
Block(6,13,5,161:1)
Block(6,14,1,161:1)
Block(6,14,3,161:1)
Block(6,14,4,161:1)
Block(6,15,5,161:1)
Block(6,16,-6,161:1)
Block(6,16,-5,161:1)
Block(6,17,-9,161:1)
Block(6,17,-7,161:1)
Block(6,17,-6,162:13)
Block(6,17,-5,162:13)
Block(6,17,-4,161:1)
Block(6,17,-3,161:1)
Block(6,17,-2,161:1)
Block(6,18,-8,161:1)
Block(6,18,-7,161:1)
Block(6,18,-6,162:13)
Block(6,18,-5,162:13)
Block(6,18,-4,162:13)
Block(6,18,-3,161:1)
Block(6,18,-2,161:1)
Block(6,18,-1,161:1)
Block(6,18,0,161:1)
Block(6,18,1,161:1)
Block(6,19,-10,161:1)
Block(6,19,-8,161:1)
Block(6,19,-7,161:1)
Block(6,19,-6,162:13)
Block(6,19,-5,162:13)
Block(6,19,-4,161:1)
Block(6,19,-3,161:1)
Block(6,19,-2,161:1)
Block(6,19,-1,161:1)
Block(6,19,0,161:1)
Block(6,19,1,161:1)
Block(6,19,2,161:1)
Block(6,20,-9,161:1)
Block(6,20,-8,161:1)
Block(6,20,-7,161:1)
Block(6,20,-6,161:1)
Block(6,20,-5,161:1)
Block(6,20,-4,161:1)
Block(6,20,-3,161:1)
Block(6,20,-2,161:1)
Block(6,20,-1,161:1)
Block(6,20,0,161:1)
Block(6,20,1,161:1)
Block(6,21,-10,161:1)
Block(6,21,-9,161:1)
Block(6,21,-8,161:1)
Block(6,21,-7,161:1)
Block(6,21,-5,161:1)
Block(6,21,-4,161:1)
Block(6,21,-3,161:1)
Block(6,21,-2,161:1)
Block(6,21,-1,161:1)
Block(6,22,-9,161:1)
Block(6,22,-7,161:1)
Block(6,22,-5,161:1)
Block(6,22,-4,161:1)
Block(6,22,-2,161:1)
Block(6,23,-1,161:1)
Block(7,0,-4,161:1)
Block(7,0,-3,162:13)
Block(7,0,-2,106:4)
Block(7,0,0,161:1)
Block(7,1,-4,161:1)
Block(7,1,-3,162:13)
Block(7,1,-2,106:4)
Block(7,10,1,161:1)
Block(7,11,2,161:1)
Block(7,11,3,161:1)
Block(7,12,1,161:1)
Block(7,12,2,161:1)
Block(7,12,3,161:1)
Block(7,12,4,161:1)
Block(7,13,2,161:1)
Block(7,13,3,161:1)
Block(7,13,4,161:1)
Block(7,14,3,161:1)
Block(7,15,3,161:1)
Block(7,16,-7,161:1)
Block(7,16,-6,161:1)
Block(7,17,-8,161:1)
Block(7,17,-7,161:1)
Block(7,17,-6,161:1)
Block(7,17,-5,161:1)
Block(7,17,-4,161:1)
Block(7,17,1,161:1)
Block(7,18,-8,161:1)
Block(7,18,-7,161:1)
Block(7,18,-6,162:13)
Block(7,18,-5,162:13)
Block(7,18,-4,161:1)
Block(7,18,-3,161:1)
Block(7,18,-2,161:1)
Block(7,18,-1,161:1)
Block(7,19,-9,161:1)
Block(7,19,-8,161:1)
Block(7,19,-7,162:13)
Block(7,19,-6,162:13)
Block(7,19,-5,161:1)
Block(7,19,-4,161:1)
Block(7,19,-3,161:1)
Block(7,19,-2,161:1)
Block(7,19,-1,161:1)
Block(7,19,0,161:1)
Block(7,19,1,161:1)
Block(7,19,3,161:1)
Block(7,20,-8,161:1)
Block(7,20,-7,162:13)
Block(7,20,-6,162:13)
Block(7,20,-5,161:1)
Block(7,20,-4,161:1)
Block(7,20,-3,161:1)
Block(7,20,-2,161:1)
Block(7,20,-1,161:1)
Block(7,21,-7,161:1)
Block(7,21,-6,161:1)
Block(7,21,-5,161:1)
Block(7,21,-4,161:1)
Block(7,21,-3,161:1)
Block(7,21,1,161:1)
Block(7,22,-5,161:1)
Block(7,23,-6,161:1)
Block(7,23,-4,161:1)
Block(8,0,-5,161:1)
Block(8,0,-4,162:13)
Block(8,0,-3,162:13)
Block(8,12,2,161:1)
Block(8,13,3,161:1)
Block(8,13,5,161:1)
Block(8,14,1,161:1)
Block(8,16,-4,161:1)
Block(8,17,-7,161:1)
Block(8,17,-1,161:1)
Block(8,18,-8,161:1)
Block(8,18,-7,161:1)
Block(8,18,-6,161:1)
Block(8,18,-5,161:1)
Block(8,18,-4,161:1)
Block(8,18,-3,161:1)
Block(8,18,-2,161:1)
Block(8,19,-10,161:1)
Block(8,19,-8,161:1)
Block(8,19,-7,161:1)
Block(8,19,-6,162:13)
Block(8,19,-5,161:1)
Block(8,19,-4,161:1)
Block(8,19,-3,161:1)
Block(8,19,-2,161:1)
Block(8,19,-1,161:1)
Block(8,19,0,161:1)
Block(8,20,-9,161:1)
Block(8,20,-8,162:13)
Block(8,20,-7,162:13)
Block(8,20,-6,161:1)
Block(8,20,-5,161:1)
Block(8,20,-4,161:1)
Block(8,20,-3,161:1)
Block(8,20,-2,161:1)
Block(8,20,-1,161:1)
Block(8,21,-8,161:1)
Block(8,21,-7,161:1)
Block(8,21,-6,161:1)
Block(8,21,-4,161:1)
Block(8,21,-2,161:1)
Block(8,22,-8,161:1)
Block(8,24,-3,161:1)
Block(9,0,-4,162:13)
Block(9,17,-9,161:1)
Block(9,17,-2,161:1)
Block(9,18,-6,161:1)
Block(9,18,-5,161:1)
Block(9,18,-4,161:1)
Block(9,19,-8,161:1)
Block(9,19,-7,161:1)
Block(9,19,-6,161:1)
Block(9,19,-5,161:1)
Block(9,19,-4,161:1)
Block(9,19,-3,161:1)
Block(9,19,-2,161:1)
Block(9,19,-1,161:1)
Block(9,19,1,161:1)
Block(9,20,-9,161:1)
Block(9,20,-8,162:13)
Block(9,20,-7,161:1)
Block(9,20,-6,161:1)
Block(9,20,-5,161:1)
Block(9,20,-2,161:1)
Block(9,21,-8,161:1)
Block(9,21,-7,161:1)
Block(9,22,-4,161:1)
Block(9,22,-2,161:1)
Block(10,17,-5,161:1)
Block(10,19,-8,161:1)
Block(10,19,-7,161:1)
Block(10,19,-6,161:1)
Block(10,19,-5,161:1)
Block(10,19,-3,161:1)
Block(10,19,-2,161:1)
Block(10,20,-8,161:1)
Block(11,18,-7,161:1)
Block(11,20,-6,161:1)


#######################################################################
# +-----------------------------------------------------------------+ #
# |                             Entities                            | #
# +-----------------------------------------------------------------+ #
#######################################################################

# Entity() spawns an entity instead of a block. The entity is spawned only once when the BO3 is spawned.
# Entities are persistent by default so they don't de-spawn when no player is near, they are only unloaded.
# Usage: Entity(x,y,z,mobName,groupSize,NameTagOrNBTFileName) or Entity(x,y,z,mobName,groupSize)
# Use /tc entities or /otg entities to get a list of entities that can be used as mobName, this includes entities added by other mods.
# NameTagOrNBTFileName can be either a nametag for the mob or an nbt file (such as mymobinfo.nbt or mymobinfo.txt).
# When using a text file you can use the same mob spawning parameters used with the /summon command to equip the
# entity and give it custom attributes etc. You can copy the DATA part of a summon command including surrounding
# curly braces to a .txt file, for instance for: "/summon Skeleton x y z {DATA}"

#######################################################################
# +-----------------------------------------------------------------+ #
# |                            BO3 checks                           | #
# +-----------------------------------------------------------------+ #
#######################################################################

# Require a condition at a certain location in order for the BO3 to be spawned.
# BlockCheck(x,y,z,BlockName[,BlockName[,...]]) - one of the blocks must be at the location
# BlockCheckNot(x,y,z,BlockName[,BlockName[,...]]) - all the blocks must not be at the location
# LightCheck(x,y,z,minLightLevel,maxLightLevel) - light must be between min and max (inclusive)

# You can use "Solid" as a BlockName for matching all solid blocks or "All" to match all blocks that aren't air.

# Examples:
#   BlockCheck(0,-1,0,GRASS,DIRT)  Require grass or dirt just below the object
#   BlockCheck(0,-1,0,Solid)       Require any solid block just below the object
#   BlockCheck(0,-1,0,WOOL)        Require any type of wool just below the object
#   BlockCheck(0,-1,0,WOOL:0)      Require white wool just below the object
#   BlockCheckNot(0,-1,0,WOOL:0)   Require that there is no white wool below the object
#   LightCheck(0,0,0,0,1)          Require almost complete darkness just below the object
BlockCheck(0,10,0,AIR)
BlockCheck(0,5,0,AIR)
BlockCheck(0,2,0,AIR)
BlockCheck(-4,0,-4,Solid)
BlockCheck(-3,0,-4,Solid)
BlockCheck(-2,0,-4,Solid)
BlockCheck(-1,0,-4,Solid)
BlockCheck(0,0,-4,Solid)
BlockCheck(1,0,-4,Solid)
BlockCheck(2,0,-4,Solid)
BlockCheck(3,0,-4,Solid)
BlockCheck(4,0,-4,Solid)
BlockCheck(-4,0,-3,Solid)
BlockCheck(-3,0,-3,Solid)
BlockCheck(-2,0,-3,Solid)
BlockCheck(-1,0,-3,Solid)
BlockCheck(0,0,-3,Solid)
BlockCheck(1,0,-3,Solid)
BlockCheck(2,0,-3,Solid)
BlockCheck(3,0,-3,Solid)
BlockCheck(4,0,-3,Solid)
BlockCheck(-4,0,-2,Solid)
BlockCheck(-3,0,-2,Solid)
BlockCheck(-2,0,-2,Solid)
BlockCheck(-1,0,-2,Solid)
BlockCheck(0,0,-2,Solid)
BlockCheck(1,0,-2,Solid)
BlockCheck(2,0,-2,Solid)
BlockCheck(3,0,-2,Solid)
BlockCheck(4,0,-2,Solid)
BlockCheck(-4,0,-1,Solid)
BlockCheck(-3,0,-1,Solid)
BlockCheck(-2,0,-1,Solid)
BlockCheck(-1,0,-1,Solid)
BlockCheck(0,0,-1,Solid)
BlockCheck(1,0,-1,Solid)
BlockCheck(2,0,-1,Solid)
BlockCheck(3,0,-1,Solid)
BlockCheck(4,0,-1,Solid)
BlockCheck(-4,0,0,Solid)
BlockCheck(-3,0,0,Solid)
BlockCheck(-2,0,0,Solid)
BlockCheck(-1,0,0,Solid)
BlockCheck(0,0,0,Solid)
BlockCheck(1,0,0,Solid)
BlockCheck(2,0,0,Solid)
BlockCheck(3,0,0,Solid)
BlockCheck(4,0,0,Solid)
BlockCheck(-4,0,1,Solid)
BlockCheck(-3,0,1,Solid)
BlockCheck(-2,0,1,Solid)
BlockCheck(-1,0,1,Solid)
BlockCheck(0,0,1,Solid)
BlockCheck(1,0,1,Solid)
BlockCheck(2,0,1,Solid)
BlockCheck(3,0,1,Solid)
BlockCheck(4,0,1,Solid)
BlockCheck(-4,0,2,Solid)
BlockCheck(-3,0,2,Solid)
BlockCheck(-2,0,2,Solid)
BlockCheck(-1,0,2,Solid)
BlockCheck(0,0,2,Solid)
BlockCheck(1,0,2,Solid)
BlockCheck(2,0,2,Solid)
BlockCheck(3,0,2,Solid)
BlockCheck(4,0,2,Solid)
BlockCheck(-4,0,3,Solid)
BlockCheck(-3,0,3,Solid)
BlockCheck(-2,0,3,Solid)
BlockCheck(-1,0,3,Solid)
BlockCheck(0,0,3,Solid)
BlockCheck(1,0,3,Solid)
BlockCheck(2,0,3,Solid)
BlockCheck(3,0,3,Solid)
BlockCheck(4,0,3,Solid)
BlockCheck(-4,0,4,Solid)
BlockCheck(-3,0,4,Solid)
BlockCheck(-2,0,4,Solid)
BlockCheck(-1,0,4,Solid)
BlockCheck(0,0,4,Solid)
BlockCheck(1,0,4,Solid)
BlockCheck(2,0,4,Solid)
BlockCheck(3,0,4,Solid)
BlockCheck(4,0,4,Solid)


