#######################################################################
# +-----------------------------------------------------------------+ #
# |                            BO3 object                           | #
# +-----------------------------------------------------------------+ #
#######################################################################

# The descriptions in this file are accurate only for TerrainControl and OTG.
# For MCW and OTG+ these descriptions are only accurate if the BO3 is used as a CustomObject.
# MCW and OTG+ completely reimplemented CustomStructure, check the MCW/OTG+ documentation for more information.

# This is the config file of a custom object.
# If you add this object correctly to your BiomeConfigs, it will spawn in the world.

# This is the creator of this BO3 object
Author: Unknown

# A short description of this BO3 object
Description: This BO3 was converted from a schematic using OTGEdit. The author and description information of the schematic could not be found. If you know who the author of the schematic is then please add this information.

# The BO3 version, don't change this! It can be used by external applications to do a version check.
Version: 3

# The settings mode, WriteAll, WriteWithoutComments or WriteDisable. See WorldConfig.
SettingsMode: WriteDisable

#######################################################################
# +-----------------------------------------------------------------+ #
# |                          Main settings                          | #
# +-----------------------------------------------------------------+ #
#######################################################################

# This needs to be set to true to spawn the object in the Tree and Sapling resources.
Tree: false

# The frequency of the BO3 from 1 to 200. Tries this many times to spawn this BO3 when using the CustomObject(...) resource.
# Ignored by Tree(..), Sapling(..) and CustomStructure(..)
Frequency: 40

# The rarity of the BO3 from 0 to 100. Each spawn attempt has rarity% chance to succeed when using the CustomObject(...) resource.
# Ignored by Tree(..), Sapling(..) and CustomStructure(..)
Rarity: 100.0

# If you set this to true, the BO3 will be placed with a random rotation.
RotateRandomly: true

# The spawn height of the BO3 - randomY, highestBlock or highestSolidBlock.
SpawnHeight: randomY

# The height limits for the BO3.
MinHeight: 92

MaxHeight: 256

# Objects can have other objects attached to it: branches. Branches can also
# have branches attached to it, which can also have branches, etc. This is the
# maximum branch depth for this objects.
MaxBranchDepth: 10

# When spawned with the UseWorld keyword, this BO3 should NOT spawn in the following biomes.
# If you writer.write the BO3 name directly in the BiomeConfigs, this will be ignored.
ExcludedBiomes: All

# To optimise this BO3 for faster loading times you can use Notepad++ to find/replace comments and abbreviate things.
# Notepad++ find/replace with regex:
# Find: ^[#;].* replace to nothing removes all lines starting with # 
# Find: ^\s*$ replace to nothing removes most empty lines 
# Notepad++ find/replace without regex:
# *Warning: This will only work for OTG 1.10.2 v21 / OTG 1.11.2 v6 or higher. B( is not recognised by lower versions.
# Find: Block( replace to B(

#######################################################################
# +-----------------------------------------------------------------+ #
# |                      Source block settings                      | #
# +-----------------------------------------------------------------+ #
#######################################################################

# The block(s) the BO3 should spawn in.
SourceBlocks: AIR

# The maximum percentage of the BO3 that can be outside the SourceBlock.
# The BO3 won't be placed on a location with more blocks outside the SourceBlock than this percentage.
MaxPercentageOutsideSourceBlock: 100

# What to do when a block is about to be placed outside the SourceBlock? (dontPlace, placeAnyway)
OutsideSourceBlock: placeAnyway

#######################################################################
# +-----------------------------------------------------------------+ #
# |                              Blocks                             | #
# +-----------------------------------------------------------------+ #
#######################################################################

# All the blocks used in the BO3 are listed here. Possible blocks:
# Block(x,y,z,id[.data][,nbtfile.nbt) or B(x,y,z,id[.data][,nbtfile.nbt)
# RandomBlock(x,y,z,id[:data][,nbtfile.nbt],chance[,id[:data][,nbtfile.nbt],chance[,...]])
# So RandomBlock(0,0,0,CHEST,chest.nbt,50,CHEST,anotherchest.nbt,100) will spawn a chest at
# the BO3 origin, and give it a 50% chance to have the contents of chest.nbt, or, if that
# fails, a 100% percent chance to have the contents of anotherchest.nbt.

Block(-13,33,-1,biomesoplenty:leaves_5:11)
Block(-12,28,-1,biomesoplenty:leaves_5:11)
Block(-12,30,-1,biomesoplenty:leaves_5:11)
Block(-12,32,-1,biomesoplenty:leaves_5:11)
Block(-12,32,3,biomesoplenty:leaves_5:11)
Block(-11,28,4,biomesoplenty:leaves_5:11)
Block(-11,29,-1,biomesoplenty:leaves_5:11)
Block(-11,30,-3,biomesoplenty:leaves_5:11)
Block(-11,30,-2,biomesoplenty:leaves_5:11)
Block(-11,30,-1,biomesoplenty:leaves_5:11)
Block(-11,30,0,biomesoplenty:leaves_5:11)
Block(-11,30,1,biomesoplenty:leaves_5:11)
Block(-11,31,-8,biomesoplenty:leaves_5:11)
Block(-11,31,-5,biomesoplenty:leaves_5:11)
Block(-11,31,-2,biomesoplenty:leaves_5:11)
Block(-11,31,-1,biomesoplenty:leaves_5:11)
Block(-11,31,2,biomesoplenty:leaves_5:11)
Block(-11,32,-3,biomesoplenty:leaves_5:11)
Block(-11,32,2,biomesoplenty:leaves_5:11)
Block(-11,34,-1,biomesoplenty:leaves_5:11)
Block(-10,12,3,biomesoplenty:leaves_5:11)
Block(-10,28,-3,biomesoplenty:leaves_5:11)
Block(-10,29,-5,biomesoplenty:leaves_5:11)
Block(-10,29,3,biomesoplenty:leaves_5:11)
Block(-10,30,-7,biomesoplenty:leaves_5:11)
Block(-10,30,-5,biomesoplenty:leaves_5:11)
Block(-10,30,-4,biomesoplenty:leaves_5:11)
Block(-10,30,-3,biomesoplenty:leaves_5:11)
Block(-10,30,-2,biomesoplenty:leaves_5:11)
Block(-10,30,-1,biomesoplenty:leaves_5:11)
Block(-10,30,0,biomesoplenty:leaves_5:11)
Block(-10,30,1,biomesoplenty:leaves_5:11)
Block(-10,30,2,biomesoplenty:leaves_5:11)
Block(-10,30,3,biomesoplenty:leaves_5:11)
Block(-10,31,-3,biomesoplenty:leaves_5:11)
Block(-10,31,-2,biomesoplenty:leaves_5:11)
Block(-10,31,-1,biomesoplenty:leaves_5:11)
Block(-10,31,0,biomesoplenty:leaves_5:11)
Block(-10,32,-4,biomesoplenty:leaves_5:11)
Block(-10,32,-1,biomesoplenty:leaves_5:11)
Block(-10,32,6,biomesoplenty:leaves_5:11)
Block(-10,33,-1,biomesoplenty:leaves_5:11)
Block(-10,33,4,biomesoplenty:leaves_5:11)
Block(-10,34,1,biomesoplenty:leaves_5:11)
Block(-10,35,-7,biomesoplenty:leaves_5:11)
Block(-10,35,3,biomesoplenty:leaves_5:11)
Block(-9,9,1,biomesoplenty:leaves_5:11)
Block(-9,10,3,biomesoplenty:leaves_5:11)
Block(-9,12,0,biomesoplenty:leaves_5:11)
Block(-9,12,3,biomesoplenty:leaves_5:11)
Block(-9,13,4,biomesoplenty:leaves_5:11)
Block(-9,22,-4,biomesoplenty:leaves_5:11)
Block(-9,23,-8,biomesoplenty:leaves_5:11)
Block(-9,23,-6,biomesoplenty:leaves_5:11)
Block(-9,25,-8,biomesoplenty:leaves_5:11)
Block(-9,26,-1,biomesoplenty:leaves_5:11)
Block(-9,27,-1,biomesoplenty:leaves_5:11)
Block(-9,29,-3,biomesoplenty:leaves_5:11)
Block(-9,29,-2,biomesoplenty:leaves_5:11)
Block(-9,29,-1,biomesoplenty:leaves_5:11)
Block(-9,29,0,biomesoplenty:leaves_5:11)
Block(-9,29,1,biomesoplenty:leaves_5:11)
Block(-9,30,-6,biomesoplenty:leaves_5:11)
Block(-9,30,-5,biomesoplenty:leaves_5:11)
Block(-9,30,-4,biomesoplenty:leaves_5:11)
Block(-9,30,-3,biomesoplenty:leaves_5:11)
Block(-9,30,-2,biomesoplenty:leaves_5:11)
Block(-9,30,-1,biomesoplenty:leaves_5:11)
Block(-9,30,0,biomesoplenty:leaves_5:11)
Block(-9,30,1,biomesoplenty:leaves_5:11)
Block(-9,30,2,biomesoplenty:leaves_5:11)
Block(-9,30,3,biomesoplenty:leaves_5:11)
Block(-9,30,4,biomesoplenty:leaves_5:11)
Block(-9,31,-5,biomesoplenty:leaves_5:11)
Block(-9,31,-4,biomesoplenty:leaves_5:11)
Block(-9,31,-3,biomesoplenty:leaves_5:11)
Block(-9,31,-2,biomesoplenty:leaves_5:11)
Block(-9,31,-1,biomesoplenty:leaves_5:11)
Block(-9,31,0,biomesoplenty:leaves_5:11)
Block(-9,31,1,biomesoplenty:leaves_5:11)
Block(-9,31,2,biomesoplenty:leaves_5:11)
Block(-9,31,3,biomesoplenty:leaves_5:11)
Block(-9,31,5,biomesoplenty:leaves_5:11)
Block(-9,32,-2,biomesoplenty:leaves_5:11)
Block(-9,32,0,biomesoplenty:leaves_5:11)
Block(-9,32,1,biomesoplenty:leaves_5:11)
Block(-9,32,2,biomesoplenty:leaves_5:11)
Block(-9,32,3,biomesoplenty:leaves_5:11)
Block(-9,33,-6,biomesoplenty:leaves_5:11)
Block(-9,33,1,biomesoplenty:leaves_5:11)
Block(-9,33,3,biomesoplenty:leaves_5:11)
Block(-9,34,-7,biomesoplenty:leaves_5:11)
Block(-9,34,-3,biomesoplenty:leaves_5:11)
Block(-9,34,3,biomesoplenty:leaves_5:11)
Block(-9,36,0,biomesoplenty:leaves_5:11)
Block(-8,10,1,biomesoplenty:leaves_5:11)
Block(-8,11,3,biomesoplenty:leaves_5:11)
Block(-8,11,5,biomesoplenty:leaves_5:11)
Block(-8,12,1,biomesoplenty:leaves_5:11)
Block(-8,20,-6,biomesoplenty:leaves_5:11)
Block(-8,21,-4,biomesoplenty:leaves_5:11)
Block(-8,22,-8,biomesoplenty:leaves_5:11)
Block(-8,23,-9,biomesoplenty:leaves_5:11)
Block(-8,23,-8,biomesoplenty:log_3:7)
Block(-8,23,-7,biomesoplenty:leaves_5:11)
Block(-8,23,-4,biomesoplenty:leaves_5:11)
Block(-8,23,-3,biomesoplenty:leaves_5:11)
Block(-8,24,-8,biomesoplenty:leaves_5:11)
Block(-8,25,-6,biomesoplenty:leaves_5:11)
Block(-8,27,-3,biomesoplenty:leaves_5:11)
Block(-8,27,2,biomesoplenty:leaves_5:11)
Block(-8,28,-8,biomesoplenty:leaves_5:11)
Block(-8,28,-5,biomesoplenty:leaves_5:11)
Block(-8,28,-1,biomesoplenty:leaves_5:11)
Block(-8,28,1,biomesoplenty:leaves_5:11)
Block(-8,28,6,biomesoplenty:leaves_5:11)
Block(-8,29,-5,biomesoplenty:leaves_5:11)
Block(-8,29,-4,biomesoplenty:leaves_5:11)
Block(-8,29,-3,biomesoplenty:leaves_5:11)
Block(-8,29,-2,biomesoplenty:leaves_5:11)
Block(-8,29,-1,biomesoplenty:leaves_5:11)
Block(-8,29,0,biomesoplenty:leaves_5:11)
Block(-8,29,1,biomesoplenty:leaves_5:11)
Block(-8,29,5,biomesoplenty:leaves_5:11)
Block(-8,29,6,biomesoplenty:leaves_5:11)
Block(-8,30,-10,biomesoplenty:leaves_5:11)
Block(-8,30,-7,biomesoplenty:leaves_5:11)
Block(-8,30,-6,biomesoplenty:leaves_5:11)
Block(-8,30,-5,biomesoplenty:leaves_5:11)
Block(-8,30,-4,biomesoplenty:leaves_5:11)
Block(-8,30,-3,biomesoplenty:leaves_5:11)
Block(-8,30,-2,biomesoplenty:leaves_5:11)
Block(-8,30,-1,biomesoplenty:leaves_5:11)
Block(-8,30,0,biomesoplenty:leaves_5:11)
Block(-8,30,1,biomesoplenty:leaves_5:11)
Block(-8,30,2,biomesoplenty:leaves_5:11)
Block(-8,30,3,biomesoplenty:leaves_5:11)
Block(-8,30,4,biomesoplenty:leaves_5:11)
Block(-8,30,5,biomesoplenty:leaves_5:11)
Block(-8,31,-6,biomesoplenty:leaves_5:11)
Block(-8,31,-5,biomesoplenty:leaves_5:11)
Block(-8,31,-4,biomesoplenty:leaves_5:11)
Block(-8,31,-3,biomesoplenty:leaves_5:11)
Block(-8,31,-2,biomesoplenty:leaves_5:11)
Block(-8,31,-1,biomesoplenty:leaves_5:11)
Block(-8,31,0,biomesoplenty:leaves_5:11)
Block(-8,31,1,biomesoplenty:leaves_5:11)
Block(-8,31,2,biomesoplenty:leaves_5:11)
Block(-8,31,3,biomesoplenty:leaves_5:11)
Block(-8,31,4,biomesoplenty:leaves_5:11)
Block(-8,31,9,biomesoplenty:leaves_5:11)
Block(-8,32,-5,biomesoplenty:leaves_5:11)
Block(-8,32,-3,biomesoplenty:leaves_5:11)
Block(-8,32,-2,biomesoplenty:leaves_5:11)
Block(-8,32,-1,biomesoplenty:leaves_5:11)
Block(-8,32,0,biomesoplenty:leaves_5:11)
Block(-8,32,1,biomesoplenty:leaves_5:11)
Block(-8,32,2,biomesoplenty:leaves_5:11)
Block(-8,32,3,biomesoplenty:leaves_5:11)
Block(-8,32,4,biomesoplenty:leaves_5:11)
Block(-8,32,7,biomesoplenty:leaves_5:11)
Block(-8,33,-2,biomesoplenty:leaves_5:11)
Block(-8,33,-1,biomesoplenty:leaves_5:11)
Block(-8,33,2,biomesoplenty:leaves_5:11)
Block(-8,33,3,biomesoplenty:leaves_5:11)
Block(-8,33,5,biomesoplenty:leaves_5:11)
Block(-8,34,-3,biomesoplenty:leaves_5:11)
Block(-8,34,0,biomesoplenty:leaves_5:11)
Block(-8,34,6,biomesoplenty:leaves_5:11)
Block(-8,35,-3,biomesoplenty:leaves_5:11)
Block(-8,35,0,biomesoplenty:leaves_5:11)
Block(-8,36,-2,biomesoplenty:leaves_5:11)
Block(-7,0,-2,biomesoplenty:log_3:7)
Block(-7,8,2,biomesoplenty:leaves_5:11)
Block(-7,9,0,biomesoplenty:leaves_5:11)
Block(-7,9,5,biomesoplenty:leaves_5:11)
Block(-7,10,1,biomesoplenty:leaves_5:11)
Block(-7,10,3,biomesoplenty:leaves_5:11)
Block(-7,11,2,biomesoplenty:leaves_5:11)
Block(-7,11,3,biomesoplenty:leaves_5:11)
Block(-7,11,4,biomesoplenty:leaves_5:11)
Block(-7,12,6,biomesoplenty:leaves_5:11)
Block(-7,13,3,biomesoplenty:leaves_5:11)
Block(-7,15,1,biomesoplenty:leaves_5:11)
Block(-7,20,-6,biomesoplenty:leaves_5:11)
Block(-7,21,-8,biomesoplenty:leaves_5:11)
Block(-7,21,-4,biomesoplenty:leaves_5:11)
Block(-7,22,-9,biomesoplenty:leaves_5:11)
Block(-7,22,-8,biomesoplenty:log_3:7)
Block(-7,22,-7,biomesoplenty:leaves_5:11)
Block(-7,22,-5,biomesoplenty:leaves_5:11)
Block(-7,22,-4,biomesoplenty:leaves_5:11)
Block(-7,23,-10,biomesoplenty:leaves_5:11)
Block(-7,23,-9,biomesoplenty:log_3:7)
Block(-7,23,-8,biomesoplenty:log_3:7)
Block(-7,23,-7,biomesoplenty:log_3:7)
Block(-7,23,-6,biomesoplenty:leaves_5:11)
Block(-7,24,-9,biomesoplenty:leaves_5:11)
Block(-7,24,-8,biomesoplenty:leaves_5:11)
Block(-7,24,-7,biomesoplenty:leaves_5:11)
Block(-7,24,-5,biomesoplenty:leaves_5:11)
Block(-7,25,-11,biomesoplenty:leaves_5:11)
Block(-7,25,-10,biomesoplenty:leaves_5:11)
Block(-7,25,-7,biomesoplenty:leaves_5:11)
Block(-7,25,-4,biomesoplenty:leaves_5:11)
Block(-7,26,-8,biomesoplenty:leaves_5:11)
Block(-7,26,-4,biomesoplenty:leaves_5:11)
Block(-7,27,-2,biomesoplenty:leaves_5:11)
Block(-7,27,4,biomesoplenty:leaves_5:11)
Block(-7,28,-2,biomesoplenty:leaves_5:11)
Block(-7,28,-1,biomesoplenty:leaves_5:11)
Block(-7,28,0,biomesoplenty:leaves_5:11)
Block(-7,29,-7,biomesoplenty:leaves_5:11)
Block(-7,29,-5,biomesoplenty:leaves_5:11)
Block(-7,29,-4,biomesoplenty:leaves_5:11)
Block(-7,29,-3,biomesoplenty:leaves_5:11)
Block(-7,29,-2,biomesoplenty:leaves_5:11)
Block(-7,29,-1,biomesoplenty:leaves_5:11)
Block(-7,29,0,biomesoplenty:leaves_5:11)
Block(-7,29,1,biomesoplenty:leaves_5:11)
Block(-7,29,2,biomesoplenty:leaves_5:11)
Block(-7,30,-9,biomesoplenty:leaves_5:11)
Block(-7,30,-8,biomesoplenty:leaves_5:11)
Block(-7,30,-7,biomesoplenty:leaves_5:11)
Block(-7,30,-6,biomesoplenty:leaves_5:11)
Block(-7,30,-5,biomesoplenty:leaves_5:11)
Block(-7,30,-4,biomesoplenty:leaves_5:11)
Block(-7,30,-3,biomesoplenty:leaves_5:11)
Block(-7,30,-2,biomesoplenty:leaves_5:11)
Block(-7,30,-1,biomesoplenty:leaves_5:11)
Block(-7,30,0,biomesoplenty:leaves_5:11)
Block(-7,30,1,biomesoplenty:leaves_5:11)
Block(-7,30,2,biomesoplenty:leaves_5:11)
Block(-7,30,3,biomesoplenty:leaves_5:11)
Block(-7,30,4,biomesoplenty:leaves_5:11)
Block(-7,30,5,biomesoplenty:leaves_5:11)
Block(-7,31,-7,biomesoplenty:leaves_5:11)
Block(-7,31,-6,biomesoplenty:leaves_5:11)
Block(-7,31,-5,biomesoplenty:leaves_5:11)
Block(-7,31,-4,biomesoplenty:leaves_5:11)
Block(-7,31,-2,biomesoplenty:leaves_5:11)
Block(-7,31,-1,biomesoplenty:leaves_5:11)
Block(-7,31,0,biomesoplenty:leaves_5:11)
Block(-7,31,1,biomesoplenty:leaves_5:11)
Block(-7,31,2,biomesoplenty:leaves_5:11)
Block(-7,31,4,biomesoplenty:leaves_5:11)
Block(-7,31,7,biomesoplenty:leaves_5:11)
Block(-7,31,8,biomesoplenty:leaves_5:11)
Block(-7,32,-4,biomesoplenty:leaves_5:11)
Block(-7,32,-3,biomesoplenty:leaves_5:11)
Block(-7,32,-2,biomesoplenty:leaves_5:11)
Block(-7,32,-1,biomesoplenty:leaves_5:11)
Block(-7,32,0,biomesoplenty:leaves_5:11)
Block(-7,32,1,biomesoplenty:leaves_5:11)
Block(-7,32,2,biomesoplenty:leaves_5:11)
Block(-7,32,3,biomesoplenty:leaves_5:11)
Block(-7,32,4,biomesoplenty:leaves_5:11)
Block(-7,33,-8,biomesoplenty:leaves_5:11)
Block(-7,33,-3,biomesoplenty:leaves_5:11)
Block(-7,33,-2,biomesoplenty:leaves_5:11)
Block(-7,33,-1,biomesoplenty:leaves_5:11)
Block(-7,33,0,biomesoplenty:leaves_5:11)
Block(-7,33,1,biomesoplenty:leaves_5:11)
Block(-7,33,2,biomesoplenty:leaves_5:11)
Block(-7,33,3,biomesoplenty:leaves_5:11)
Block(-7,34,-1,biomesoplenty:leaves_5:11)
Block(-7,34,0,biomesoplenty:leaves_5:11)
Block(-7,34,1,biomesoplenty:leaves_5:11)
Block(-7,35,-5,biomesoplenty:leaves_5:11)
Block(-7,35,4,biomesoplenty:leaves_5:11)
Block(-7,36,-5,biomesoplenty:leaves_5:11)
Block(-7,36,0,biomesoplenty:leaves_5:11)
Block(-7,36,4,biomesoplenty:leaves_5:11)
Block(-6,0,-2,biomesoplenty:log_3:7)
Block(-6,0,-1,biomesoplenty:leaves_5:11)
Block(-6,9,2,biomesoplenty:leaves_5:11)
Block(-6,9,4,biomesoplenty:leaves_5:11)
Block(-6,10,2,biomesoplenty:leaves_5:11)
Block(-6,10,3,biomesoplenty:leaves_5:11)
Block(-6,10,4,biomesoplenty:leaves_5:11)
Block(-6,11,1,biomesoplenty:leaves_5:11)
Block(-6,11,2,biomesoplenty:leaves_5:11)
Block(-6,11,3,biomesoplenty:log_3:7)
Block(-6,11,4,biomesoplenty:leaves_5:11)
Block(-6,11,5,biomesoplenty:leaves_5:11)
Block(-6,12,0,biomesoplenty:leaves_5:11)
Block(-6,12,3,biomesoplenty:leaves_5:11)
Block(-6,13,5,biomesoplenty:leaves_5:11)
Block(-6,14,2,biomesoplenty:leaves_5:11)
Block(-6,20,-9,biomesoplenty:leaves_5:11)
Block(-6,21,-8,biomesoplenty:leaves_5:11)
Block(-6,21,-7,biomesoplenty:leaves_5:11)
Block(-6,21,-6,biomesoplenty:leaves_5:11)
Block(-6,21,-5,biomesoplenty:leaves_5:11)
Block(-6,22,-9,biomesoplenty:leaves_5:11)
Block(-6,22,-8,biomesoplenty:log_3:7)
Block(-6,22,-7,biomesoplenty:log_3:7)
Block(-6,22,-6,biomesoplenty:leaves_5:11)
Block(-6,22,-5,biomesoplenty:leaves_5:11)
Block(-6,23,-9,biomesoplenty:leaves_5:11)
Block(-6,23,-8,biomesoplenty:log_3:7)
Block(-6,23,-7,biomesoplenty:log_3:7)
Block(-6,23,-6,biomesoplenty:leaves_5:11)
Block(-6,23,-5,biomesoplenty:leaves_5:11)
Block(-6,23,-4,biomesoplenty:leaves_5:11)
Block(-6,24,-8,biomesoplenty:leaves_5:11)
Block(-6,24,-7,biomesoplenty:leaves_5:11)
Block(-6,24,-6,biomesoplenty:leaves_5:11)
Block(-6,24,-3,biomesoplenty:leaves_5:11)
Block(-6,24,-2,biomesoplenty:leaves_5:11)
Block(-6,25,-8,biomesoplenty:leaves_5:11)
Block(-6,27,-7,biomesoplenty:leaves_5:11)
Block(-6,27,-4,biomesoplenty:leaves_5:11)
Block(-6,27,0,biomesoplenty:leaves_5:11)
Block(-6,27,8,biomesoplenty:leaves_5:11)
Block(-6,28,-6,biomesoplenty:leaves_5:11)
Block(-6,28,-4,biomesoplenty:leaves_5:11)
Block(-6,28,-3,biomesoplenty:leaves_5:11)
Block(-6,28,-2,biomesoplenty:leaves_5:11)
Block(-6,28,1,biomesoplenty:leaves_5:11)
Block(-6,28,3,biomesoplenty:leaves_5:11)
Block(-6,28,7,biomesoplenty:leaves_5:11)
Block(-6,29,-6,biomesoplenty:leaves_5:11)
Block(-6,29,-5,biomesoplenty:leaves_5:11)
Block(-6,29,-4,biomesoplenty:leaves_5:11)
Block(-6,29,-3,biomesoplenty:leaves_5:11)
Block(-6,29,-2,biomesoplenty:leaves_5:11)
Block(-6,29,-1,biomesoplenty:leaves_5:11)
Block(-6,29,0,biomesoplenty:leaves_5:11)
Block(-6,29,1,biomesoplenty:leaves_5:11)
Block(-6,29,2,biomesoplenty:leaves_5:11)
Block(-6,29,3,biomesoplenty:leaves_5:11)
Block(-6,29,4,biomesoplenty:leaves_5:11)
Block(-6,30,-8,biomesoplenty:leaves_5:11)
Block(-6,30,-7,biomesoplenty:leaves_5:11)
Block(-6,30,-6,biomesoplenty:leaves_5:11)
Block(-6,30,-5,biomesoplenty:leaves_5:11)
Block(-6,30,-4,biomesoplenty:leaves_5:11)
Block(-6,30,-3,biomesoplenty:leaves_5:11)
Block(-6,30,-2,biomesoplenty:leaves_5:11)
Block(-6,30,-1,biomesoplenty:leaves_5:11)
Block(-6,30,0,biomesoplenty:leaves_5:11)
Block(-6,30,1,biomesoplenty:leaves_5:11)
Block(-6,30,2,biomesoplenty:leaves_5:11)
Block(-6,30,3,biomesoplenty:leaves_5:11)
Block(-6,30,4,biomesoplenty:leaves_5:11)
Block(-6,30,5,biomesoplenty:leaves_5:11)
Block(-6,30,6,biomesoplenty:leaves_5:11)
Block(-6,30,7,biomesoplenty:leaves_5:11)
Block(-6,31,-8,biomesoplenty:leaves_5:11)
Block(-6,31,-7,biomesoplenty:leaves_5:11)
Block(-6,31,-6,biomesoplenty:leaves_5:11)
Block(-6,31,-5,biomesoplenty:leaves_5:11)
Block(-6,31,-4,biomesoplenty:leaves_5:11)
Block(-6,31,-3,biomesoplenty:leaves_5:11)
Block(-6,31,-2,biomesoplenty:leaves_5:11)
Block(-6,31,-1,biomesoplenty:leaves_5:11)
Block(-6,31,0,biomesoplenty:leaves_5:11)
Block(-6,31,1,biomesoplenty:leaves_5:11)
Block(-6,31,2,biomesoplenty:leaves_5:11)
Block(-6,31,3,biomesoplenty:leaves_5:11)
Block(-6,31,4,biomesoplenty:leaves_5:11)
Block(-6,31,5,biomesoplenty:leaves_5:11)
Block(-6,31,6,biomesoplenty:leaves_5:11)
Block(-6,31,7,biomesoplenty:leaves_5:11)
Block(-6,31,10,biomesoplenty:leaves_5:11)
Block(-6,32,-8,biomesoplenty:leaves_5:11)
Block(-6,32,-6,biomesoplenty:leaves_5:11)
Block(-6,32,-5,biomesoplenty:leaves_5:11)
Block(-6,32,-4,biomesoplenty:leaves_5:11)
Block(-6,32,-3,biomesoplenty:leaves_5:11)
Block(-6,32,-2,biomesoplenty:leaves_5:11)
Block(-6,32,-1,biomesoplenty:leaves_5:11)
Block(-6,32,0,biomesoplenty:leaves_5:11)
Block(-6,32,1,biomesoplenty:leaves_5:11)
Block(-6,32,2,biomesoplenty:leaves_5:11)
Block(-6,32,3,biomesoplenty:leaves_5:11)
Block(-6,32,4,biomesoplenty:leaves_5:11)
Block(-6,32,5,biomesoplenty:leaves_5:11)
Block(-6,33,-4,biomesoplenty:leaves_5:11)
Block(-6,33,-3,biomesoplenty:leaves_5:11)
Block(-6,33,-2,biomesoplenty:leaves_5:11)
Block(-6,33,-1,biomesoplenty:leaves_5:11)
Block(-6,33,0,biomesoplenty:leaves_5:11)
Block(-6,33,1,biomesoplenty:leaves_5:11)
Block(-6,33,2,biomesoplenty:leaves_5:11)
Block(-6,33,3,biomesoplenty:leaves_5:11)
Block(-6,33,4,biomesoplenty:leaves_5:11)
Block(-6,33,7,biomesoplenty:leaves_5:11)
Block(-6,34,-5,biomesoplenty:leaves_5:11)
Block(-6,34,-4,biomesoplenty:leaves_5:11)
Block(-6,34,-3,biomesoplenty:leaves_5:11)
Block(-6,34,-2,biomesoplenty:leaves_5:11)
Block(-6,34,-1,biomesoplenty:leaves_5:11)
Block(-6,34,0,biomesoplenty:leaves_5:11)
Block(-6,34,1,biomesoplenty:leaves_5:11)
Block(-6,34,2,biomesoplenty:leaves_5:11)
Block(-6,34,4,biomesoplenty:leaves_5:11)
Block(-6,34,6,biomesoplenty:leaves_5:11)
Block(-6,35,-6,biomesoplenty:leaves_5:11)
Block(-6,35,-5,biomesoplenty:leaves_5:11)
Block(-6,35,-1,biomesoplenty:leaves_5:11)
Block(-6,35,0,biomesoplenty:leaves_5:11)
Block(-6,35,1,biomesoplenty:leaves_5:11)
Block(-6,36,-7,biomesoplenty:leaves_5:11)
Block(-6,36,-2,biomesoplenty:leaves_5:11)
Block(-6,36,2,biomesoplenty:leaves_5:11)
Block(-6,37,-3,biomesoplenty:leaves_5:11)
Block(-6,37,-2,biomesoplenty:leaves_5:11)
Block(-6,37,2,biomesoplenty:leaves_5:11)
Block(-6,38,-2,biomesoplenty:leaves_5:11)
Block(-5,1,-1,biomesoplenty:log_3:7)
Block(-5,1,0,biomesoplenty:log_3:7)
Block(-5,2,0,biomesoplenty:leaves_5:11)
Block(-5,9,0,biomesoplenty:leaves_5:11)
Block(-5,9,6,biomesoplenty:leaves_5:11)
Block(-5,10,-2,biomesoplenty:leaves_5:11)
Block(-5,10,1,biomesoplenty:leaves_5:11)
Block(-5,10,2,biomesoplenty:leaves_5:11)
Block(-5,10,3,biomesoplenty:leaves_5:11)
Block(-5,10,4,biomesoplenty:leaves_5:11)
Block(-5,10,5,biomesoplenty:leaves_5:11)
Block(-5,11,-1,biomesoplenty:leaves_5:11)
Block(-5,11,0,biomesoplenty:leaves_5:11)
Block(-5,11,1,biomesoplenty:leaves_5:11)
Block(-5,11,2,biomesoplenty:leaves_5:11)
Block(-5,11,3,biomesoplenty:log_3:7)
Block(-5,11,4,biomesoplenty:log_3:7)
Block(-5,11,5,biomesoplenty:leaves_5:11)
Block(-5,11,6,biomesoplenty:leaves_5:11)
Block(-5,12,2,biomesoplenty:leaves_5:11)
Block(-5,12,3,biomesoplenty:leaves_5:11)
Block(-5,12,4,biomesoplenty:leaves_5:11)
Block(-5,12,7,biomesoplenty:leaves_5:11)
Block(-5,13,1,biomesoplenty:leaves_5:11)
Block(-5,13,3,biomesoplenty:leaves_5:11)
Block(-5,13,8,biomesoplenty:leaves_5:11)
Block(-5,20,-5,biomesoplenty:leaves_5:11)
Block(-5,20,-4,biomesoplenty:leaves_5:11)
Block(-5,21,-11,biomesoplenty:leaves_5:11)
Block(-5,21,-9,biomesoplenty:leaves_5:11)
Block(-5,21,-8,biomesoplenty:leaves_5:11)
Block(-5,21,-7,biomesoplenty:log_3:7)
Block(-5,21,-6,biomesoplenty:log_3:7)
Block(-5,21,-5,biomesoplenty:leaves_5:11)
Block(-5,21,-4,biomesoplenty:leaves_5:11)
Block(-5,21,-3,biomesoplenty:leaves_5:11)
Block(-5,21,-2,biomesoplenty:leaves_5:11)
Block(-5,22,-10,biomesoplenty:leaves_5:11)
Block(-5,22,-9,biomesoplenty:leaves_5:11)
Block(-5,22,-8,biomesoplenty:log_3:7)
Block(-5,22,-7,biomesoplenty:log_3:7)
Block(-5,22,-6,biomesoplenty:log_3:7)
Block(-5,22,-5,biomesoplenty:leaves_5:11)
Block(-5,22,-4,biomesoplenty:leaves_5:11)
Block(-5,23,-11,biomesoplenty:leaves_5:11)
Block(-5,23,-8,biomesoplenty:leaves_5:11)
Block(-5,23,-7,biomesoplenty:leaves_5:11)
Block(-5,23,-6,biomesoplenty:leaves_5:11)
Block(-5,23,-5,biomesoplenty:leaves_5:11)
Block(-5,24,-11,biomesoplenty:leaves_5:11)
Block(-5,24,-6,biomesoplenty:leaves_5:11)
Block(-5,25,-8,biomesoplenty:leaves_5:11)
Block(-5,26,4,biomesoplenty:leaves_5:11)
Block(-5,26,6,biomesoplenty:leaves_5:11)
Block(-5,27,-9,biomesoplenty:leaves_5:11)
Block(-5,27,4,biomesoplenty:leaves_5:11)
Block(-5,27,5,biomesoplenty:leaves_5:11)
Block(-5,28,-9,biomesoplenty:leaves_5:11)
Block(-5,28,-5,biomesoplenty:leaves_5:11)
Block(-5,28,-4,biomesoplenty:leaves_5:11)
Block(-5,28,-3,biomesoplenty:leaves_5:11)
Block(-5,28,-2,biomesoplenty:leaves_5:11)
Block(-5,28,1,biomesoplenty:leaves_5:11)
Block(-5,28,3,biomesoplenty:leaves_5:11)
Block(-5,28,4,biomesoplenty:leaves_5:11)
Block(-5,29,-7,biomesoplenty:leaves_5:11)
Block(-5,29,-6,biomesoplenty:leaves_5:11)
Block(-5,29,-5,biomesoplenty:leaves_5:11)
Block(-5,29,-4,biomesoplenty:leaves_5:11)
Block(-5,29,-3,biomesoplenty:leaves_5:11)
Block(-5,29,-2,biomesoplenty:leaves_5:11)
Block(-5,29,-1,biomesoplenty:leaves_5:11)
Block(-5,29,0,biomesoplenty:leaves_5:11)
Block(-5,29,1,biomesoplenty:leaves_5:11)
Block(-5,29,2,biomesoplenty:leaves_5:11)
Block(-5,29,3,biomesoplenty:leaves_5:11)
Block(-5,29,4,biomesoplenty:leaves_5:11)
Block(-5,29,5,biomesoplenty:leaves_5:11)
Block(-5,29,6,biomesoplenty:leaves_5:11)
Block(-5,29,9,biomesoplenty:leaves_5:11)
Block(-5,29,10,biomesoplenty:leaves_5:11)
Block(-5,30,-10,biomesoplenty:leaves_5:11)
Block(-5,30,-9,biomesoplenty:leaves_5:11)
Block(-5,30,-8,biomesoplenty:leaves_5:11)
Block(-5,30,-7,biomesoplenty:leaves_5:11)
Block(-5,30,-6,biomesoplenty:leaves_5:11)
Block(-5,30,-5,biomesoplenty:leaves_5:11)
Block(-5,30,-4,biomesoplenty:leaves_5:11)
Block(-5,30,-3,biomesoplenty:leaves_5:11)
Block(-5,30,-2,biomesoplenty:leaves_5:11)
Block(-5,30,-1,biomesoplenty:leaves_5:11)
Block(-5,30,0,biomesoplenty:leaves_5:11)
Block(-5,30,1,biomesoplenty:leaves_5:11)
Block(-5,30,2,biomesoplenty:leaves_5:11)
Block(-5,30,3,biomesoplenty:leaves_5:11)
Block(-5,30,4,biomesoplenty:leaves_5:11)
Block(-5,30,5,biomesoplenty:leaves_5:11)
Block(-5,30,6,biomesoplenty:leaves_5:11)
Block(-5,30,7,biomesoplenty:leaves_5:11)
Block(-5,31,-9,biomesoplenty:leaves_5:11)
Block(-5,31,-8,biomesoplenty:leaves_5:11)
Block(-5,31,-7,biomesoplenty:leaves_5:11)
Block(-5,31,-6,biomesoplenty:leaves_5:11)
Block(-5,31,-4,biomesoplenty:leaves_5:11)
Block(-5,31,-3,biomesoplenty:leaves_5:11)
Block(-5,31,-2,biomesoplenty:leaves_5:11)
Block(-5,31,-1,biomesoplenty:leaves_5:11)
Block(-5,31,0,biomesoplenty:leaves_5:11)
Block(-5,31,1,biomesoplenty:leaves_5:11)
Block(-5,31,2,biomesoplenty:leaves_5:11)
Block(-5,31,3,biomesoplenty:leaves_5:11)
Block(-5,31,4,biomesoplenty:leaves_5:11)
Block(-5,31,5,biomesoplenty:leaves_5:11)
Block(-5,31,6,biomesoplenty:leaves_5:11)
Block(-5,31,9,biomesoplenty:leaves_5:11)
Block(-5,32,-10,biomesoplenty:leaves_5:11)
Block(-5,32,-7,biomesoplenty:leaves_5:11)
Block(-5,32,-6,biomesoplenty:leaves_5:11)
Block(-5,32,-5,biomesoplenty:leaves_5:11)
Block(-5,32,-4,biomesoplenty:leaves_5:11)
Block(-5,32,-3,biomesoplenty:leaves_5:11)
Block(-5,32,-2,biomesoplenty:leaves_5:11)
Block(-5,32,-1,biomesoplenty:leaves_5:11)
Block(-5,32,0,biomesoplenty:leaves_5:11)
Block(-5,32,1,biomesoplenty:leaves_5:11)
Block(-5,32,2,biomesoplenty:leaves_5:11)
Block(-5,32,3,biomesoplenty:leaves_5:11)
Block(-5,32,4,biomesoplenty:leaves_5:11)
Block(-5,32,5,biomesoplenty:leaves_5:11)
Block(-5,32,6,biomesoplenty:leaves_5:11)
Block(-5,33,-10,biomesoplenty:leaves_5:11)
Block(-5,33,-5,biomesoplenty:leaves_5:11)
Block(-5,33,-4,biomesoplenty:leaves_5:11)
Block(-5,33,-3,biomesoplenty:leaves_5:11)
Block(-5,33,-2,biomesoplenty:leaves_5:11)
Block(-5,33,-1,biomesoplenty:leaves_5:11)
Block(-5,33,0,biomesoplenty:leaves_5:11)
Block(-5,33,1,biomesoplenty:leaves_5:11)
Block(-5,33,2,biomesoplenty:leaves_5:11)
Block(-5,33,3,biomesoplenty:leaves_5:11)
Block(-5,33,4,biomesoplenty:leaves_5:11)
Block(-5,33,5,biomesoplenty:leaves_5:11)
Block(-5,33,9,biomesoplenty:leaves_5:11)
Block(-5,34,-4,biomesoplenty:leaves_5:11)
Block(-5,34,-3,biomesoplenty:leaves_5:11)
Block(-5,34,-2,biomesoplenty:leaves_5:11)
Block(-5,34,-1,biomesoplenty:leaves_5:11)
Block(-5,34,0,biomesoplenty:leaves_5:11)
Block(-5,34,1,biomesoplenty:leaves_5:11)
Block(-5,34,2,biomesoplenty:leaves_5:11)
Block(-5,34,3,biomesoplenty:leaves_5:11)
Block(-5,34,4,biomesoplenty:leaves_5:11)
Block(-5,34,9,biomesoplenty:leaves_5:11)
Block(-5,35,-2,biomesoplenty:leaves_5:11)
Block(-5,35,-1,biomesoplenty:leaves_5:11)
Block(-5,35,0,biomesoplenty:leaves_5:11)
Block(-5,35,1,biomesoplenty:leaves_5:11)
Block(-5,35,2,biomesoplenty:leaves_5:11)
Block(-5,36,-2,biomesoplenty:leaves_5:11)
Block(-5,36,0,biomesoplenty:leaves_5:11)
Block(-5,36,6,biomesoplenty:leaves_5:11)
Block(-5,38,0,biomesoplenty:leaves_5:11)
Block(-4,1,0,biomesoplenty:log_3:7)
Block(-4,2,-1,biomesoplenty:leaves_5:11)
Block(-4,2,0,biomesoplenty:log_3:7)
Block(-4,10,0,biomesoplenty:leaves_5:11)
Block(-4,10,1,biomesoplenty:log_3:7)
Block(-4,10,2,biomesoplenty:log_3:7)
Block(-4,10,3,biomesoplenty:leaves_5:11)
Block(-4,10,4,biomesoplenty:leaves_5:11)
Block(-4,11,1,biomesoplenty:leaves_5:11)
Block(-4,11,2,biomesoplenty:log_3:7)
Block(-4,11,3,biomesoplenty:log_3:7)
Block(-4,11,4,biomesoplenty:leaves_5:11)
Block(-4,11,5,biomesoplenty:leaves_5:11)
Block(-4,12,0,biomesoplenty:leaves_5:11)
Block(-4,12,2,biomesoplenty:leaves_5:11)
Block(-4,12,3,biomesoplenty:log_3:7)
Block(-4,12,4,biomesoplenty:leaves_5:11)
Block(-4,13,3,biomesoplenty:leaves_5:11)
Block(-4,14,4,biomesoplenty:leaves_5:11)
Block(-4,19,-5,biomesoplenty:log_3:7)
Block(-4,19,-4,biomesoplenty:log_3:7)
Block(-4,20,-7,biomesoplenty:leaves_5:11)
Block(-4,20,-6,biomesoplenty:log_3:7)
Block(-4,20,-5,biomesoplenty:log_3:7)
Block(-4,20,-4,biomesoplenty:log_3:7)
Block(-4,21,-8,biomesoplenty:leaves_5:11)
Block(-4,21,-7,biomesoplenty:log_3:7)
Block(-4,21,-6,biomesoplenty:log_3:7)
Block(-4,21,-5,biomesoplenty:log_3:7)
Block(-4,21,-4,biomesoplenty:leaves_5:11)
Block(-4,22,-9,biomesoplenty:leaves_5:11)
Block(-4,22,-8,biomesoplenty:leaves_5:11)
Block(-4,22,-7,biomesoplenty:log_3:7)
Block(-4,22,-6,biomesoplenty:log_3:7)
Block(-4,22,-5,biomesoplenty:leaves_5:11)
Block(-4,23,-9,biomesoplenty:leaves_5:11)
Block(-4,23,-7,biomesoplenty:leaves_5:11)
Block(-4,23,-6,biomesoplenty:leaves_5:11)
Block(-4,23,-4,biomesoplenty:leaves_5:11)
Block(-4,23,-3,biomesoplenty:leaves_5:11)
Block(-4,24,-10,biomesoplenty:leaves_5:11)
Block(-4,24,-7,biomesoplenty:leaves_5:11)
Block(-4,25,-10,biomesoplenty:leaves_5:11)
Block(-4,26,0,biomesoplenty:leaves_5:11)
Block(-4,28,-9,biomesoplenty:leaves_5:11)
Block(-4,28,-7,biomesoplenty:leaves_5:11)
Block(-4,28,-6,biomesoplenty:leaves_5:11)
Block(-4,28,-4,biomesoplenty:leaves_5:11)
Block(-4,28,-3,biomesoplenty:leaves_5:11)
Block(-4,28,1,biomesoplenty:leaves_5:11)
Block(-4,28,2,biomesoplenty:leaves_5:11)
Block(-4,28,3,biomesoplenty:leaves_5:11)
Block(-4,28,5,biomesoplenty:leaves_5:11)
Block(-4,29,-9,biomesoplenty:leaves_5:11)
Block(-4,29,-8,biomesoplenty:leaves_5:11)
Block(-4,29,-7,biomesoplenty:leaves_5:11)
Block(-4,29,-6,biomesoplenty:leaves_5:11)
Block(-4,29,-5,biomesoplenty:leaves_5:11)
Block(-4,29,-4,biomesoplenty:leaves_5:11)
Block(-4,29,-3,biomesoplenty:leaves_5:11)
Block(-4,29,-2,biomesoplenty:leaves_5:11)
Block(-4,29,-1,biomesoplenty:leaves_5:11)
Block(-4,29,0,biomesoplenty:leaves_5:11)
Block(-4,29,1,biomesoplenty:leaves_5:11)
Block(-4,29,2,biomesoplenty:leaves_5:11)
Block(-4,29,3,biomesoplenty:leaves_5:11)
Block(-4,29,4,biomesoplenty:leaves_5:11)
Block(-4,29,5,biomesoplenty:leaves_5:11)
Block(-4,29,6,biomesoplenty:leaves_5:11)
Block(-4,30,-11,biomesoplenty:leaves_5:11)
Block(-4,30,-10,biomesoplenty:leaves_5:11)
Block(-4,30,-9,biomesoplenty:leaves_5:11)
Block(-4,30,-8,biomesoplenty:leaves_5:11)
Block(-4,30,-7,biomesoplenty:leaves_5:11)
Block(-4,30,-6,biomesoplenty:leaves_5:11)
Block(-4,30,-5,biomesoplenty:leaves_5:11)
Block(-4,30,-4,biomesoplenty:leaves_5:11)
Block(-4,30,-3,biomesoplenty:leaves_5:11)
Block(-4,30,-2,biomesoplenty:leaves_5:11)
Block(-4,30,-1,biomesoplenty:leaves_5:11)
Block(-4,30,0,biomesoplenty:leaves_5:11)
Block(-4,30,1,biomesoplenty:leaves_5:11)
Block(-4,30,2,biomesoplenty:leaves_5:11)
Block(-4,30,3,biomesoplenty:leaves_5:11)
Block(-4,30,4,biomesoplenty:leaves_5:11)
Block(-4,30,5,biomesoplenty:leaves_5:11)
Block(-4,30,6,biomesoplenty:leaves_5:11)
Block(-4,30,7,biomesoplenty:leaves_5:11)
Block(-4,30,8,biomesoplenty:leaves_5:11)
Block(-4,30,9,biomesoplenty:leaves_5:11)
Block(-4,31,-10,biomesoplenty:leaves_5:11)
Block(-4,31,-9,biomesoplenty:leaves_5:11)
Block(-4,31,-8,biomesoplenty:leaves_5:11)
Block(-4,31,-7,biomesoplenty:leaves_5:11)
Block(-4,31,-5,biomesoplenty:leaves_5:11)
Block(-4,31,-4,biomesoplenty:leaves_5:11)
Block(-4,31,-3,biomesoplenty:leaves_5:11)
Block(-4,31,-2,biomesoplenty:leaves_5:11)
Block(-4,31,-1,biomesoplenty:leaves_5:11)
Block(-4,31,0,biomesoplenty:leaves_5:11)
Block(-4,31,1,biomesoplenty:leaves_5:11)
Block(-4,31,2,biomesoplenty:leaves_5:11)
Block(-4,31,3,biomesoplenty:leaves_5:11)
Block(-4,31,4,biomesoplenty:leaves_5:11)
Block(-4,31,5,biomesoplenty:leaves_5:11)
Block(-4,31,6,biomesoplenty:leaves_5:11)
Block(-4,31,7,biomesoplenty:leaves_5:11)
Block(-4,31,8,biomesoplenty:leaves_5:11)
Block(-4,32,-7,biomesoplenty:leaves_5:11)
Block(-4,32,-6,biomesoplenty:leaves_5:11)
Block(-4,32,-5,biomesoplenty:leaves_5:11)
Block(-4,32,-4,biomesoplenty:leaves_5:11)
Block(-4,32,-3,biomesoplenty:leaves_5:11)
Block(-4,32,-2,biomesoplenty:leaves_5:11)
Block(-4,32,-1,biomesoplenty:leaves_5:11)
Block(-4,32,0,biomesoplenty:leaves_5:11)
Block(-4,32,1,biomesoplenty:leaves_5:11)
Block(-4,32,2,biomesoplenty:leaves_5:11)
Block(-4,32,3,biomesoplenty:leaves_5:11)
Block(-4,32,4,biomesoplenty:leaves_5:11)
Block(-4,32,5,biomesoplenty:leaves_5:11)
Block(-4,32,6,biomesoplenty:leaves_5:11)
Block(-4,32,7,biomesoplenty:leaves_5:11)
Block(-4,32,8,biomesoplenty:leaves_5:11)
Block(-4,33,-7,biomesoplenty:leaves_5:11)
Block(-4,33,-6,biomesoplenty:leaves_5:11)
Block(-4,33,-5,biomesoplenty:leaves_5:11)
Block(-4,33,-4,biomesoplenty:leaves_5:11)
Block(-4,33,-3,biomesoplenty:leaves_5:11)
Block(-4,33,-2,biomesoplenty:leaves_5:11)
Block(-4,33,-1,biomesoplenty:leaves_5:11)
Block(-4,33,0,biomesoplenty:leaves_5:11)
Block(-4,33,1,biomesoplenty:leaves_5:11)
Block(-4,33,2,biomesoplenty:leaves_5:11)
Block(-4,33,3,biomesoplenty:leaves_5:11)
Block(-4,33,4,biomesoplenty:leaves_5:11)
Block(-4,33,5,biomesoplenty:leaves_5:11)
Block(-4,33,6,biomesoplenty:leaves_5:11)
Block(-4,34,-8,biomesoplenty:leaves_5:11)
Block(-4,34,-5,biomesoplenty:leaves_5:11)
Block(-4,34,-4,biomesoplenty:leaves_5:11)
Block(-4,34,-3,biomesoplenty:leaves_5:11)
Block(-4,34,-2,biomesoplenty:leaves_5:11)
Block(-4,34,-1,biomesoplenty:leaves_5:11)
Block(-4,34,0,biomesoplenty:leaves_5:11)
Block(-4,34,1,biomesoplenty:leaves_5:11)
Block(-4,34,2,biomesoplenty:leaves_5:11)
Block(-4,34,3,biomesoplenty:leaves_5:11)
Block(-4,34,4,biomesoplenty:leaves_5:11)
Block(-4,34,5,biomesoplenty:leaves_5:11)
Block(-4,35,-5,biomesoplenty:leaves_5:11)
Block(-4,35,-2,biomesoplenty:leaves_5:11)
Block(-4,35,-1,biomesoplenty:leaves_5:11)
Block(-4,35,0,biomesoplenty:leaves_5:11)
Block(-4,35,1,biomesoplenty:leaves_5:11)
Block(-4,35,2,biomesoplenty:leaves_5:11)
Block(-4,35,3,biomesoplenty:leaves_5:11)
Block(-4,35,6,biomesoplenty:leaves_5:11)
Block(-4,36,-6,biomesoplenty:leaves_5:11)
Block(-4,36,-1,biomesoplenty:leaves_5:11)
Block(-4,36,0,biomesoplenty:leaves_5:11)
Block(-4,36,1,biomesoplenty:leaves_5:11)
Block(-4,36,3,biomesoplenty:leaves_5:11)
Block(-4,36,4,biomesoplenty:leaves_5:11)
Block(-4,37,-3,biomesoplenty:leaves_5:11)
Block(-4,37,0,biomesoplenty:leaves_5:11)
Block(-4,37,4,biomesoplenty:leaves_5:11)
Block(-3,0,-3,biomesoplenty:log_3:7)
Block(-3,0,-2,biomesoplenty:log_3:7)
Block(-3,0,-1,biomesoplenty:log_3:7)
Block(-3,0,0,biomesoplenty:log_3:7)
Block(-3,0,1,106:4)
Block(-3,0,2,biomesoplenty:log_3:7)
Block(-3,0,6,106:8)
Block(-3,1,-1,biomesoplenty:log_3:7)
Block(-3,1,0,biomesoplenty:log_3:7)
Block(-3,1,1,106:4)
Block(-3,2,-1,biomesoplenty:log_3:7)
Block(-3,2,0,biomesoplenty:log_3:7)
Block(-3,2,1,106:4)
Block(-3,3,-1,biomesoplenty:leaves_5:11)
Block(-3,3,0,biomesoplenty:log_3:7)
Block(-3,4,-1,106:8)
Block(-3,4,0,biomesoplenty:log_3:7)
Block(-3,5,-1,106:8)
Block(-3,6,-1,106:8)
Block(-3,7,-1,106:8)
Block(-3,8,-1,106:8)
Block(-3,9,-1,106:8)
Block(-3,9,0,biomesoplenty:log_3:7)
Block(-3,9,1,biomesoplenty:log_3:7)
Block(-3,10,-1,106:8)
Block(-3,10,0,106:8)
Block(-3,10,1,biomesoplenty:log_3:7)
Block(-3,10,2,biomesoplenty:log_3:7)
Block(-3,10,3,biomesoplenty:log_3:7)
Block(-3,10,6,biomesoplenty:leaves_5:11)
Block(-3,11,-1,106:8)
Block(-3,11,0,106:8)
Block(-3,11,2,biomesoplenty:leaves_5:11)
Block(-3,11,3,biomesoplenty:log_3:7)
Block(-3,11,4,biomesoplenty:leaves_5:11)
Block(-3,11,5,biomesoplenty:leaves_5:11)
Block(-3,12,-1,106:8)
Block(-3,12,0,106:8)
Block(-3,12,3,biomesoplenty:leaves_5:11)
Block(-3,12,4,biomesoplenty:leaves_5:11)
Block(-3,12,6,biomesoplenty:leaves_5:11)
Block(-3,13,-1,106:8)
Block(-3,13,0,106:8)
Block(-3,13,7,biomesoplenty:leaves_5:11)
Block(-3,14,-1,106:8)
Block(-3,14,0,106:8)
Block(-3,15,-1,106:8)
Block(-3,15,0,106:8)
Block(-3,16,-1,106:8)
Block(-3,16,0,106:8)
Block(-3,17,-1,106:8)
Block(-3,17,0,106:8)
Block(-3,18,-3,biomesoplenty:log_3:7)
Block(-3,18,-1,106:8)
Block(-3,18,0,106:8)
Block(-3,19,-4,biomesoplenty:log_3:7)
Block(-3,19,-3,biomesoplenty:log_3:7)
Block(-3,19,-1,106:8)
Block(-3,19,0,106:8)
Block(-3,20,-6,biomesoplenty:leaves_5:11)
Block(-3,20,-5,biomesoplenty:log_3:7)
Block(-3,20,-4,biomesoplenty:log_3:7)
Block(-3,20,-1,106:8)
Block(-3,20,0,106:8)
Block(-3,21,-7,biomesoplenty:leaves_5:11)
Block(-3,21,-6,biomesoplenty:log_3:7)
Block(-3,21,-5,biomesoplenty:log_3:7)
Block(-3,21,-1,106:8)
Block(-3,21,0,106:8)
Block(-3,22,-8,biomesoplenty:leaves_5:11)
Block(-3,22,-7,biomesoplenty:leaves_5:11)
Block(-3,22,-6,biomesoplenty:leaves_5:11)
Block(-3,22,-5,biomesoplenty:leaves_5:11)
Block(-3,22,-1,106:8)
Block(-3,22,0,127:11)
Block(-3,23,-10,biomesoplenty:leaves_5:11)
Block(-3,23,-6,biomesoplenty:leaves_5:11)
Block(-3,23,0,106:8)
Block(-3,24,-1,biomesoplenty:leaves_5:11)
Block(-3,24,0,106:8)
Block(-3,25,-7,biomesoplenty:leaves_5:11)
Block(-3,25,-1,biomesoplenty:leaves_5:11)
Block(-3,26,0,biomesoplenty:leaves_5:11)
Block(-3,27,-1,biomesoplenty:leaves_5:11)
Block(-3,27,1,biomesoplenty:leaves_5:11)
Block(-3,28,-8,biomesoplenty:leaves_5:11)
Block(-3,28,-7,biomesoplenty:leaves_5:11)
Block(-3,28,-6,biomesoplenty:leaves_5:11)
Block(-3,28,-5,biomesoplenty:leaves_5:11)
Block(-3,28,-2,biomesoplenty:leaves_5:11)
Block(-3,28,-1,biomesoplenty:leaves_5:11)
Block(-3,28,3,biomesoplenty:leaves_5:11)
Block(-3,28,4,biomesoplenty:leaves_5:11)
Block(-3,28,5,biomesoplenty:leaves_5:11)
Block(-3,28,8,biomesoplenty:leaves_5:11)
Block(-3,29,-9,biomesoplenty:leaves_5:11)
Block(-3,29,-8,biomesoplenty:leaves_5:11)
Block(-3,29,-7,biomesoplenty:leaves_5:11)
Block(-3,29,-6,biomesoplenty:leaves_5:11)
Block(-3,29,-5,biomesoplenty:leaves_5:11)
Block(-3,29,-4,biomesoplenty:leaves_5:11)
Block(-3,29,-3,biomesoplenty:leaves_5:11)
Block(-3,29,-2,biomesoplenty:leaves_5:11)
Block(-3,29,-1,biomesoplenty:leaves_5:11)
Block(-3,29,0,biomesoplenty:leaves_5:11)
Block(-3,29,1,biomesoplenty:leaves_5:11)
Block(-3,29,2,biomesoplenty:leaves_5:11)
Block(-3,29,3,biomesoplenty:leaves_5:11)
Block(-3,29,4,biomesoplenty:leaves_5:11)
Block(-3,29,5,biomesoplenty:leaves_5:11)
Block(-3,29,6,biomesoplenty:leaves_5:11)
Block(-3,29,7,biomesoplenty:leaves_5:11)
Block(-3,30,-11,biomesoplenty:leaves_5:11)
Block(-3,30,-10,biomesoplenty:leaves_5:11)
Block(-3,30,-9,biomesoplenty:leaves_5:11)
Block(-3,30,-8,biomesoplenty:leaves_5:11)
Block(-3,30,-7,biomesoplenty:leaves_5:11)
Block(-3,30,-6,biomesoplenty:leaves_5:11)
Block(-3,30,-5,biomesoplenty:leaves_5:11)
Block(-3,30,-4,biomesoplenty:leaves_5:11)
Block(-3,30,-3,biomesoplenty:leaves_5:11)
Block(-3,30,-2,biomesoplenty:leaves_5:11)
Block(-3,30,-1,biomesoplenty:leaves_5:11)
Block(-3,30,0,biomesoplenty:leaves_5:11)
Block(-3,30,1,biomesoplenty:leaves_5:11)
Block(-3,30,2,biomesoplenty:leaves_5:11)
Block(-3,30,3,biomesoplenty:leaves_5:11)
Block(-3,30,4,biomesoplenty:leaves_5:11)
Block(-3,30,5,biomesoplenty:leaves_5:11)
Block(-3,30,6,biomesoplenty:leaves_5:11)
Block(-3,30,7,biomesoplenty:leaves_5:11)
Block(-3,30,8,biomesoplenty:leaves_5:11)
Block(-3,30,9,biomesoplenty:leaves_5:11)
Block(-3,30,11,biomesoplenty:leaves_5:11)
Block(-3,31,-11,biomesoplenty:leaves_5:11)
Block(-3,31,-10,biomesoplenty:leaves_5:11)
Block(-3,31,-9,biomesoplenty:leaves_5:11)
Block(-3,31,-8,biomesoplenty:leaves_5:11)
Block(-3,31,-7,biomesoplenty:leaves_5:11)
Block(-3,31,-6,biomesoplenty:leaves_5:11)
Block(-3,31,-5,biomesoplenty:leaves_5:11)
Block(-3,31,-4,biomesoplenty:leaves_5:11)
Block(-3,31,-3,biomesoplenty:leaves_5:11)
Block(-3,31,-2,biomesoplenty:leaves_5:11)
Block(-3,31,-1,biomesoplenty:leaves_5:11)
Block(-3,31,0,biomesoplenty:leaves_5:11)
Block(-3,31,1,biomesoplenty:leaves_5:11)
Block(-3,31,2,biomesoplenty:leaves_5:11)
Block(-3,31,3,biomesoplenty:leaves_5:11)
Block(-3,31,4,biomesoplenty:leaves_5:11)
Block(-3,31,5,biomesoplenty:leaves_5:11)
Block(-3,31,6,biomesoplenty:leaves_5:11)
Block(-3,31,7,biomesoplenty:leaves_5:11)
Block(-3,31,8,biomesoplenty:leaves_5:11)
Block(-3,31,9,biomesoplenty:leaves_5:11)
Block(-3,31,10,biomesoplenty:leaves_5:11)
Block(-3,32,-12,biomesoplenty:leaves_5:11)
Block(-3,32,-11,biomesoplenty:leaves_5:11)
Block(-3,32,-8,biomesoplenty:leaves_5:11)
Block(-3,32,-7,biomesoplenty:leaves_5:11)
Block(-3,32,-6,biomesoplenty:leaves_5:11)
Block(-3,32,-5,biomesoplenty:leaves_5:11)
Block(-3,32,-4,biomesoplenty:leaves_5:11)
Block(-3,32,-3,biomesoplenty:leaves_5:11)
Block(-3,32,-2,biomesoplenty:leaves_5:11)
Block(-3,32,-1,biomesoplenty:leaves_5:11)
Block(-3,32,0,biomesoplenty:leaves_5:11)
Block(-3,32,1,biomesoplenty:leaves_5:11)
Block(-3,32,2,biomesoplenty:leaves_5:11)
Block(-3,32,3,biomesoplenty:leaves_5:11)
Block(-3,32,4,biomesoplenty:leaves_5:11)
Block(-3,32,5,biomesoplenty:leaves_5:11)
Block(-3,32,6,biomesoplenty:leaves_5:11)
Block(-3,32,7,biomesoplenty:leaves_5:11)
Block(-3,32,8,biomesoplenty:leaves_5:11)
Block(-3,32,9,biomesoplenty:leaves_5:11)
Block(-3,33,-13,biomesoplenty:leaves_5:11)
Block(-3,33,-6,biomesoplenty:leaves_5:11)
Block(-3,33,-5,biomesoplenty:leaves_5:11)
Block(-3,33,-4,biomesoplenty:leaves_5:11)
Block(-3,33,-3,biomesoplenty:leaves_5:11)
Block(-3,33,-2,biomesoplenty:leaves_5:11)
Block(-3,33,-1,biomesoplenty:leaves_5:11)
Block(-3,33,0,biomesoplenty:leaves_5:11)
Block(-3,33,1,biomesoplenty:leaves_5:11)
Block(-3,33,2,biomesoplenty:leaves_5:11)
Block(-3,33,3,biomesoplenty:leaves_5:11)
Block(-3,33,4,biomesoplenty:leaves_5:11)
Block(-3,33,5,biomesoplenty:leaves_5:11)
Block(-3,33,6,biomesoplenty:leaves_5:11)
Block(-3,33,7,biomesoplenty:leaves_5:11)
Block(-3,33,10,biomesoplenty:leaves_5:11)
Block(-3,34,-5,biomesoplenty:leaves_5:11)
Block(-3,34,-4,biomesoplenty:leaves_5:11)
Block(-3,34,-3,biomesoplenty:leaves_5:11)
Block(-3,34,-2,biomesoplenty:leaves_5:11)
Block(-3,34,-1,biomesoplenty:leaves_5:11)
Block(-3,34,0,biomesoplenty:leaves_5:11)
Block(-3,34,1,biomesoplenty:leaves_5:11)
Block(-3,34,2,biomesoplenty:leaves_5:11)
Block(-3,34,3,biomesoplenty:leaves_5:11)
Block(-3,34,4,biomesoplenty:leaves_5:11)
Block(-3,34,5,biomesoplenty:leaves_5:11)
Block(-3,34,6,biomesoplenty:leaves_5:11)
Block(-3,35,-3,biomesoplenty:leaves_5:11)
Block(-3,35,-2,biomesoplenty:leaves_5:11)
Block(-3,35,-1,biomesoplenty:leaves_5:11)
Block(-3,35,0,biomesoplenty:leaves_5:11)
Block(-3,35,1,biomesoplenty:leaves_5:11)
Block(-3,35,2,biomesoplenty:leaves_5:11)
Block(-3,35,3,biomesoplenty:leaves_5:11)
Block(-3,35,4,biomesoplenty:leaves_5:11)
Block(-3,35,6,biomesoplenty:leaves_5:11)
Block(-3,35,7,biomesoplenty:leaves_5:11)
Block(-3,36,-3,biomesoplenty:leaves_5:11)
Block(-3,36,-2,biomesoplenty:leaves_5:11)
Block(-3,36,-1,biomesoplenty:leaves_5:11)
Block(-3,36,0,biomesoplenty:leaves_5:11)
Block(-3,36,1,biomesoplenty:leaves_5:11)
Block(-3,36,7,biomesoplenty:leaves_5:11)
Block(-3,37,1,biomesoplenty:leaves_5:11)
Block(-3,38,-1,biomesoplenty:leaves_5:11)
Block(-3,38,2,biomesoplenty:leaves_5:11)
Block(-2,0,-8,biomesoplenty:log_3:7)
Block(-2,0,-3,106:8)
Block(-2,0,-2,biomesoplenty:log_3:7)
Block(-2,0,-1,biomesoplenty:log_3:7)
Block(-2,0,0,biomesoplenty:log_3:7)
Block(-2,0,1,biomesoplenty:log_3:7)
Block(-2,0,6,biomesoplenty:log_3:7)
Block(-2,0,7,106:4)
Block(-2,1,-3,106:8)
Block(-2,1,-2,biomesoplenty:log_3:7)
Block(-2,1,-1,biomesoplenty:log_3:7)
Block(-2,1,0,biomesoplenty:log_3:7)
Block(-2,1,1,biomesoplenty:log_3:7)
Block(-2,2,-3,106:8)
Block(-2,2,-2,106:8)
Block(-2,2,-1,biomesoplenty:log_3:7)
Block(-2,2,0,biomesoplenty:log_3:7)
Block(-2,2,1,biomesoplenty:log_3:7)
Block(-2,3,-3,106:8)
Block(-2,3,-2,106:8)
Block(-2,3,-1,biomesoplenty:log_3:7)
Block(-2,3,0,biomesoplenty:log_3:7)
Block(-2,3,1,biomesoplenty:leaves_5:11)
Block(-2,4,-2,106:8)
Block(-2,4,-1,biomesoplenty:log_3:7)
Block(-2,4,0,biomesoplenty:log_3:7)
Block(-2,4,1,biomesoplenty:leaves_5:11)
Block(-2,5,-2,106:8)
Block(-2,5,-1,biomesoplenty:log_3:7)
Block(-2,5,0,biomesoplenty:log_3:7)
Block(-2,6,-2,106:8)
Block(-2,6,-1,biomesoplenty:log_3:7)
Block(-2,6,0,biomesoplenty:log_3:7)
Block(-2,7,-2,106:8)
Block(-2,7,-1,biomesoplenty:log_3:7)
Block(-2,7,0,biomesoplenty:log_3:7)
Block(-2,7,1,biomesoplenty:log_3:7)
Block(-2,8,-2,106:8)
Block(-2,8,-1,biomesoplenty:log_3:7)
Block(-2,8,0,biomesoplenty:log_3:7)
Block(-2,8,1,biomesoplenty:log_3:7)
Block(-2,9,-2,106:8)
Block(-2,9,-1,biomesoplenty:log_3:7)
Block(-2,9,0,biomesoplenty:log_3:7)
Block(-2,9,1,biomesoplenty:log_3:7)
Block(-2,9,2,biomesoplenty:log_3:7)
Block(-2,10,-2,106:8)
Block(-2,10,-1,biomesoplenty:log_3:7)
Block(-2,10,0,biomesoplenty:log_3:7)
Block(-2,10,1,biomesoplenty:log_3:7)
Block(-2,10,2,biomesoplenty:log_3:7)
Block(-2,11,-2,106:8)
Block(-2,11,-1,biomesoplenty:log_3:7)
Block(-2,11,0,biomesoplenty:log_3:7)
Block(-2,11,1,biomesoplenty:leaves_5:11)
Block(-2,11,4,biomesoplenty:leaves_5:11)
Block(-2,11,5,biomesoplenty:leaves_5:11)
Block(-2,12,-2,106:8)
Block(-2,12,-1,biomesoplenty:log_3:7)
Block(-2,12,0,biomesoplenty:log_3:7)
Block(-2,13,-2,106:8)
Block(-2,13,-1,biomesoplenty:log_3:7)
Block(-2,13,0,biomesoplenty:log_3:7)
Block(-2,13,1,biomesoplenty:leaves_5:11)
Block(-2,13,4,biomesoplenty:leaves_5:11)
Block(-2,13,5,biomesoplenty:leaves_5:11)
Block(-2,14,-2,106:8)
Block(-2,14,-1,biomesoplenty:log_3:7)
Block(-2,14,0,biomesoplenty:log_3:7)
Block(-2,14,1,106:8)
Block(-2,14,4,biomesoplenty:leaves_5:11)
Block(-2,15,-1,biomesoplenty:log_3:7)
Block(-2,15,0,biomesoplenty:log_3:7)
Block(-2,15,1,106:8)
Block(-2,16,-2,biomesoplenty:log_3:7)
Block(-2,16,-1,biomesoplenty:log_3:7)
Block(-2,16,0,biomesoplenty:log_3:7)
Block(-2,16,1,106:8)
Block(-2,17,-3,biomesoplenty:log_3:7)
Block(-2,17,-2,biomesoplenty:log_3:7)
Block(-2,17,-1,biomesoplenty:log_3:7)
Block(-2,17,0,biomesoplenty:log_3:7)
Block(-2,17,1,106:8)
Block(-2,18,-4,biomesoplenty:log_3:7)
Block(-2,18,-3,biomesoplenty:log_3:7)
Block(-2,18,-2,biomesoplenty:log_3:7)
Block(-2,18,-1,biomesoplenty:log_3:7)
Block(-2,18,0,biomesoplenty:log_3:7)
Block(-2,18,1,106:8)
Block(-2,19,-5,biomesoplenty:log_3:7)
Block(-2,19,-4,biomesoplenty:log_3:7)
Block(-2,19,-3,biomesoplenty:log_3:7)
Block(-2,19,-2,biomesoplenty:log_3:7)
Block(-2,19,-1,biomesoplenty:log_3:7)
Block(-2,19,0,biomesoplenty:log_3:7)
Block(-2,20,-4,biomesoplenty:log_3:7)
Block(-2,20,-3,biomesoplenty:log_3:7)
Block(-2,20,-2,biomesoplenty:log_3:7)
Block(-2,20,-1,biomesoplenty:log_3:7)
Block(-2,20,0,biomesoplenty:log_3:7)
Block(-2,21,-8,biomesoplenty:leaves_5:11)
Block(-2,21,-6,biomesoplenty:leaves_5:11)
Block(-2,21,-2,106:8)
Block(-2,21,-1,biomesoplenty:log_3:7)
Block(-2,21,0,biomesoplenty:log_3:7)
Block(-2,22,-2,106:8)
Block(-2,22,-1,biomesoplenty:log_3:7)
Block(-2,22,0,biomesoplenty:log_3:7)
Block(-2,22,1,biomesoplenty:log_3:7)
Block(-2,23,-7,biomesoplenty:leaves_5:11)
Block(-2,23,-2,106:8)
Block(-2,23,-1,biomesoplenty:log_3:7)
Block(-2,23,0,biomesoplenty:log_3:7)
Block(-2,23,1,biomesoplenty:log_3:7)
Block(-2,24,-10,biomesoplenty:leaves_5:11)
Block(-2,24,-2,106:8)
Block(-2,24,-1,biomesoplenty:log_3:7)
Block(-2,24,0,biomesoplenty:log_3:7)
Block(-2,24,1,biomesoplenty:log_3:7)
Block(-2,25,-2,106:8)
Block(-2,25,-1,biomesoplenty:log_3:7)
Block(-2,25,0,biomesoplenty:log_3:7)
Block(-2,25,1,biomesoplenty:log_3:7)
Block(-2,25,2,biomesoplenty:leaves_5:11)
Block(-2,26,-2,106:9)
Block(-2,26,-1,biomesoplenty:log_3:7)
Block(-2,26,0,biomesoplenty:log_3:7)
Block(-2,26,6,biomesoplenty:leaves_5:11)
Block(-2,27,-11,biomesoplenty:leaves_5:11)
Block(-2,27,-2,biomesoplenty:leaves_5:11)
Block(-2,27,-1,biomesoplenty:log_3:7)
Block(-2,27,0,biomesoplenty:log_3:7)
Block(-2,27,1,biomesoplenty:leaves_5:11)
Block(-2,27,5,biomesoplenty:leaves_5:11)
Block(-2,28,-11,biomesoplenty:leaves_5:11)
Block(-2,28,-7,biomesoplenty:leaves_5:11)
Block(-2,28,-6,biomesoplenty:leaves_5:11)
Block(-2,28,-3,biomesoplenty:leaves_5:11)
Block(-2,28,-2,biomesoplenty:leaves_5:11)
Block(-2,28,-1,biomesoplenty:log_3:7)
Block(-2,28,0,biomesoplenty:leaves_5:11)
Block(-2,28,1,biomesoplenty:leaves_5:11)
Block(-2,28,4,biomesoplenty:leaves_5:11)
Block(-2,28,5,biomesoplenty:leaves_5:11)
Block(-2,29,-10,biomesoplenty:leaves_5:11)
Block(-2,29,-9,biomesoplenty:leaves_5:11)
Block(-2,29,-8,biomesoplenty:leaves_5:11)
Block(-2,29,-7,biomesoplenty:leaves_5:11)
Block(-2,29,-6,biomesoplenty:leaves_5:11)
Block(-2,29,-5,biomesoplenty:leaves_5:11)
Block(-2,29,-4,biomesoplenty:leaves_5:11)
Block(-2,29,-3,biomesoplenty:leaves_5:11)
Block(-2,29,-2,biomesoplenty:leaves_5:11)
Block(-2,29,-1,biomesoplenty:leaves_5:11)
Block(-2,29,0,biomesoplenty:leaves_5:11)
Block(-2,29,1,biomesoplenty:leaves_5:11)
Block(-2,29,2,biomesoplenty:leaves_5:11)
Block(-2,29,3,biomesoplenty:leaves_5:11)
Block(-2,29,4,biomesoplenty:leaves_5:11)
Block(-2,29,5,biomesoplenty:leaves_5:11)
Block(-2,29,6,biomesoplenty:leaves_5:11)
Block(-2,29,7,biomesoplenty:leaves_5:11)
Block(-2,29,10,biomesoplenty:leaves_5:11)
Block(-2,30,-12,biomesoplenty:leaves_5:11)
Block(-2,30,-11,biomesoplenty:leaves_5:11)
Block(-2,30,-10,biomesoplenty:leaves_5:11)
Block(-2,30,-9,biomesoplenty:leaves_5:11)
Block(-2,30,-8,biomesoplenty:leaves_5:11)
Block(-2,30,-7,biomesoplenty:leaves_5:11)
Block(-2,30,-6,biomesoplenty:leaves_5:11)
Block(-2,30,-5,biomesoplenty:leaves_5:11)
Block(-2,30,-3,biomesoplenty:leaves_5:11)
Block(-2,30,-2,biomesoplenty:leaves_5:11)
Block(-2,30,-1,biomesoplenty:leaves_5:11)
Block(-2,30,0,biomesoplenty:leaves_5:11)
Block(-2,30,1,biomesoplenty:leaves_5:11)
Block(-2,30,2,biomesoplenty:leaves_5:11)
Block(-2,30,3,biomesoplenty:leaves_5:11)
Block(-2,30,4,biomesoplenty:leaves_5:11)
Block(-2,30,5,biomesoplenty:leaves_5:11)
Block(-2,30,6,biomesoplenty:leaves_5:11)
Block(-2,30,7,biomesoplenty:leaves_5:11)
Block(-2,30,8,biomesoplenty:leaves_5:11)
Block(-2,30,9,biomesoplenty:leaves_5:11)
Block(-2,31,-11,biomesoplenty:leaves_5:11)
Block(-2,31,-10,biomesoplenty:leaves_5:11)
Block(-2,31,-9,biomesoplenty:leaves_5:11)
Block(-2,31,-8,biomesoplenty:leaves_5:11)
Block(-2,31,-7,biomesoplenty:leaves_5:11)
Block(-2,31,-6,biomesoplenty:leaves_5:11)
Block(-2,31,-5,biomesoplenty:leaves_5:11)
Block(-2,31,-4,biomesoplenty:leaves_5:11)
Block(-2,31,-3,biomesoplenty:leaves_5:11)
Block(-2,31,-2,biomesoplenty:leaves_5:11)
Block(-2,31,-1,biomesoplenty:leaves_5:11)
Block(-2,31,0,biomesoplenty:leaves_5:11)
Block(-2,31,1,biomesoplenty:leaves_5:11)
Block(-2,31,2,biomesoplenty:leaves_5:11)
Block(-2,31,3,biomesoplenty:leaves_5:11)
Block(-2,31,4,biomesoplenty:leaves_5:11)
Block(-2,31,5,biomesoplenty:leaves_5:11)
Block(-2,31,6,biomesoplenty:leaves_5:11)
Block(-2,31,7,biomesoplenty:leaves_5:11)
Block(-2,31,8,biomesoplenty:leaves_5:11)
Block(-2,32,-9,biomesoplenty:leaves_5:11)
Block(-2,32,-8,biomesoplenty:leaves_5:11)
Block(-2,32,-7,biomesoplenty:leaves_5:11)
Block(-2,32,-6,biomesoplenty:leaves_5:11)
Block(-2,32,-5,biomesoplenty:leaves_5:11)
Block(-2,32,-4,biomesoplenty:leaves_5:11)
Block(-2,32,-3,biomesoplenty:leaves_5:11)
Block(-2,32,-2,biomesoplenty:leaves_5:11)
Block(-2,32,-1,biomesoplenty:leaves_5:11)
Block(-2,32,0,biomesoplenty:leaves_5:11)
Block(-2,32,1,biomesoplenty:leaves_5:11)
Block(-2,32,2,biomesoplenty:leaves_5:11)
Block(-2,32,3,biomesoplenty:leaves_5:11)
Block(-2,32,4,biomesoplenty:leaves_5:11)
Block(-2,32,5,biomesoplenty:leaves_5:11)
Block(-2,32,6,biomesoplenty:leaves_5:11)
Block(-2,32,7,biomesoplenty:leaves_5:11)
Block(-2,32,8,biomesoplenty:leaves_5:11)
Block(-2,33,-10,biomesoplenty:leaves_5:11)
Block(-2,33,-8,biomesoplenty:leaves_5:11)
Block(-2,33,-7,biomesoplenty:leaves_5:11)
Block(-2,33,-6,biomesoplenty:leaves_5:11)
Block(-2,33,-5,biomesoplenty:leaves_5:11)
Block(-2,33,-4,biomesoplenty:leaves_5:11)
Block(-2,33,-3,biomesoplenty:leaves_5:11)
Block(-2,33,-2,biomesoplenty:leaves_5:11)
Block(-2,33,-1,biomesoplenty:leaves_5:11)
Block(-2,33,0,biomesoplenty:leaves_5:11)
Block(-2,33,1,biomesoplenty:leaves_5:11)
Block(-2,33,2,biomesoplenty:leaves_5:11)
Block(-2,33,3,biomesoplenty:leaves_5:11)
Block(-2,33,4,biomesoplenty:leaves_5:11)
Block(-2,33,5,biomesoplenty:leaves_5:11)
Block(-2,33,6,biomesoplenty:leaves_5:11)
Block(-2,33,7,biomesoplenty:leaves_5:11)
Block(-2,33,8,biomesoplenty:leaves_5:11)
Block(-2,34,-11,biomesoplenty:leaves_5:11)
Block(-2,34,-7,biomesoplenty:leaves_5:11)
Block(-2,34,-6,biomesoplenty:leaves_5:11)
Block(-2,34,-5,biomesoplenty:leaves_5:11)
Block(-2,34,-4,biomesoplenty:leaves_5:11)
Block(-2,34,-3,biomesoplenty:leaves_5:11)
Block(-2,34,-2,biomesoplenty:leaves_5:11)
Block(-2,34,-1,biomesoplenty:leaves_5:11)
Block(-2,34,0,biomesoplenty:leaves_5:11)
Block(-2,34,1,biomesoplenty:leaves_5:11)
Block(-2,34,2,biomesoplenty:leaves_5:11)
Block(-2,34,3,biomesoplenty:leaves_5:11)
Block(-2,34,4,biomesoplenty:leaves_5:11)
Block(-2,34,5,biomesoplenty:leaves_5:11)
Block(-2,34,6,biomesoplenty:leaves_5:11)
Block(-2,34,7,biomesoplenty:leaves_5:11)
Block(-2,34,9,biomesoplenty:leaves_5:11)
Block(-2,35,-7,biomesoplenty:leaves_5:11)
Block(-2,35,-4,biomesoplenty:leaves_5:11)
Block(-2,35,-3,biomesoplenty:leaves_5:11)
Block(-2,35,-2,biomesoplenty:leaves_5:11)
Block(-2,35,-1,biomesoplenty:leaves_5:11)
Block(-2,35,0,biomesoplenty:leaves_5:11)
Block(-2,35,1,biomesoplenty:leaves_5:11)
Block(-2,35,2,biomesoplenty:leaves_5:11)
Block(-2,35,3,biomesoplenty:leaves_5:11)
Block(-2,35,4,biomesoplenty:leaves_5:11)
Block(-2,35,5,biomesoplenty:leaves_5:11)
Block(-2,35,9,biomesoplenty:leaves_5:11)
Block(-2,36,-8,biomesoplenty:leaves_5:11)
Block(-2,36,-2,biomesoplenty:leaves_5:11)
Block(-2,36,-1,biomesoplenty:leaves_5:11)
Block(-2,36,0,biomesoplenty:leaves_5:11)
Block(-2,36,1,biomesoplenty:leaves_5:11)
Block(-2,36,2,biomesoplenty:leaves_5:11)
Block(-2,36,3,biomesoplenty:leaves_5:11)
Block(-2,36,10,biomesoplenty:leaves_5:11)
Block(-2,37,-5,biomesoplenty:leaves_5:11)
Block(-2,37,-2,biomesoplenty:leaves_5:11)
Block(-2,37,-1,biomesoplenty:leaves_5:11)
Block(-2,37,3,biomesoplenty:leaves_5:11)
Block(-2,37,6,biomesoplenty:leaves_5:11)
Block(-2,38,-3,biomesoplenty:leaves_5:11)
Block(-2,38,-1,biomesoplenty:leaves_5:11)
Block(-2,38,4,biomesoplenty:leaves_5:11)
Block(-2,39,-1,biomesoplenty:leaves_5:11)
Block(-1,0,-7,biomesoplenty:log_3:7)
Block(-1,0,-6,biomesoplenty:log_3:7)
Block(-1,0,-3,biomesoplenty:log_3:7)
Block(-1,0,-2,biomesoplenty:log_3:7)
Block(-1,0,-1,biomesoplenty:log_3:7)
Block(-1,0,0,biomesoplenty:log_3:7)
Block(-1,0,1,biomesoplenty:log_3:7)
Block(-1,0,2,biomesoplenty:log_3:7)
Block(-1,0,3,biomesoplenty:leaves_5:11)
Block(-1,0,4,106:1)
Block(-1,0,5,biomesoplenty:log_3:7)
Block(-1,0,6,106:6)
Block(-1,1,-5,biomesoplenty:log_3:7)
Block(-1,1,-4,biomesoplenty:log_3:7)
Block(-1,1,-3,biomesoplenty:log_3:7)
Block(-1,1,-2,biomesoplenty:log_3:7)
Block(-1,1,-1,biomesoplenty:log_3:7)
Block(-1,1,0,biomesoplenty:log_3:7)
Block(-1,1,1,biomesoplenty:log_3:7)
Block(-1,1,2,biomesoplenty:log_3:7)
Block(-1,1,3,biomesoplenty:leaves_5:11)
Block(-1,1,4,biomesoplenty:log_3:7)
Block(-1,2,-4,biomesoplenty:log_3:7)
Block(-1,2,-3,biomesoplenty:log_3:7)
Block(-1,2,-2,biomesoplenty:log_3:7)
Block(-1,2,-1,biomesoplenty:log_3:7)
Block(-1,2,0,biomesoplenty:log_3:7)
Block(-1,2,1,biomesoplenty:log_3:7)
Block(-1,2,2,biomesoplenty:leaves_5:11)
Block(-1,3,-3,biomesoplenty:log_3:7)
Block(-1,3,-2,biomesoplenty:log_3:7)
Block(-1,3,-1,biomesoplenty:log_3:7)
Block(-1,3,0,biomesoplenty:log_3:7)
Block(-1,3,1,biomesoplenty:log_3:7)
Block(-1,3,2,106:8)
Block(-1,4,-3,biomesoplenty:log_3:7)
Block(-1,4,-2,biomesoplenty:log_3:7)
Block(-1,4,-1,biomesoplenty:log_3:7)
Block(-1,4,0,biomesoplenty:log_3:7)
Block(-1,4,1,biomesoplenty:log_3:7)
Block(-1,4,2,106:4)
Block(-1,5,-3,biomesoplenty:log_3:7)
Block(-1,5,-2,biomesoplenty:log_3:7)
Block(-1,5,-1,biomesoplenty:log_3:7)
Block(-1,5,0,biomesoplenty:log_3:7)
Block(-1,5,1,biomesoplenty:log_3:7)
Block(-1,5,2,106:4)
Block(-1,6,-3,biomesoplenty:log_3:7)
Block(-1,6,-2,biomesoplenty:log_3:7)
Block(-1,6,-1,biomesoplenty:log_3:7)
Block(-1,6,0,biomesoplenty:log_3:7)
Block(-1,6,1,biomesoplenty:log_3:7)
Block(-1,6,2,106:4)
Block(-1,7,-3,biomesoplenty:log_3:7)
Block(-1,7,-2,biomesoplenty:log_3:7)
Block(-1,7,-1,biomesoplenty:log_3:7)
Block(-1,7,0,biomesoplenty:log_3:7)
Block(-1,7,1,biomesoplenty:log_3:7)
Block(-1,7,2,106:4)
Block(-1,8,-2,biomesoplenty:log_3:7)
Block(-1,8,-1,biomesoplenty:log_3:7)
Block(-1,8,0,biomesoplenty:log_3:7)
Block(-1,8,1,biomesoplenty:log_3:7)
Block(-1,8,2,106:4)
Block(-1,9,-3,biomesoplenty:leaves_5:11)
Block(-1,9,-2,biomesoplenty:log_3:7)
Block(-1,9,-1,biomesoplenty:log_3:7)
Block(-1,9,0,biomesoplenty:log_3:7)
Block(-1,9,1,biomesoplenty:log_3:7)
Block(-1,9,2,106:4)
Block(-1,10,-3,biomesoplenty:leaves_5:11)
Block(-1,10,-2,biomesoplenty:log_3:7)
Block(-1,10,-1,biomesoplenty:log_3:7)
Block(-1,10,0,biomesoplenty:log_3:7)
Block(-1,10,1,biomesoplenty:log_3:7)
Block(-1,10,2,106:4)
Block(-1,10,4,biomesoplenty:leaves_5:11)
Block(-1,11,-3,106:1)
Block(-1,11,-2,biomesoplenty:log_3:7)
Block(-1,11,-1,biomesoplenty:log_3:7)
Block(-1,11,0,biomesoplenty:log_3:7)
Block(-1,11,1,biomesoplenty:log_3:7)
Block(-1,12,-3,106:1)
Block(-1,12,-2,biomesoplenty:log_3:7)
Block(-1,12,-1,biomesoplenty:log_3:7)
Block(-1,12,0,biomesoplenty:log_3:7)
Block(-1,12,1,biomesoplenty:log_3:7)
Block(-1,13,-3,106:1)
Block(-1,13,-2,biomesoplenty:log_3:7)
Block(-1,13,-1,biomesoplenty:log_3:7)
Block(-1,13,0,biomesoplenty:log_3:7)
Block(-1,13,1,biomesoplenty:log_3:7)
Block(-1,13,4,biomesoplenty:leaves_5:11)
Block(-1,14,-3,106:1)
Block(-1,14,-2,biomesoplenty:log_3:7)
Block(-1,14,-1,biomesoplenty:log_3:7)
Block(-1,14,0,biomesoplenty:log_3:7)
Block(-1,14,1,biomesoplenty:log_3:7)
Block(-1,14,6,biomesoplenty:leaves_5:11)
Block(-1,15,-3,106:1)
Block(-1,15,-2,biomesoplenty:log_3:7)
Block(-1,15,-1,biomesoplenty:log_3:7)
Block(-1,15,0,biomesoplenty:log_3:7)
Block(-1,15,1,biomesoplenty:log_3:7)
Block(-1,16,-2,biomesoplenty:log_3:7)
Block(-1,16,-1,biomesoplenty:log_3:7)
Block(-1,16,0,biomesoplenty:log_3:7)
Block(-1,16,1,biomesoplenty:log_3:7)
Block(-1,17,-3,biomesoplenty:log_3:7)
Block(-1,17,-2,biomesoplenty:log_3:7)
Block(-1,17,-1,biomesoplenty:log_3:7)
Block(-1,17,0,biomesoplenty:log_3:7)
Block(-1,17,1,biomesoplenty:log_3:7)
Block(-1,18,-3,biomesoplenty:log_3:7)
Block(-1,18,-2,biomesoplenty:log_3:7)
Block(-1,18,-1,biomesoplenty:log_3:7)
Block(-1,18,0,biomesoplenty:log_3:7)
Block(-1,18,1,biomesoplenty:log_3:7)
Block(-1,19,-4,biomesoplenty:log_3:7)
Block(-1,19,-3,biomesoplenty:log_3:7)
Block(-1,19,-2,biomesoplenty:log_3:7)
Block(-1,19,-1,biomesoplenty:log_3:7)
Block(-1,19,0,biomesoplenty:log_3:7)
Block(-1,19,1,biomesoplenty:log_3:7)
Block(-1,19,2,biomesoplenty:log_3:7)
Block(-1,20,-3,106:1)
Block(-1,20,-2,biomesoplenty:log_3:7)
Block(-1,20,-1,biomesoplenty:log_3:7)
Block(-1,20,0,biomesoplenty:log_3:7)
Block(-1,20,1,biomesoplenty:log_3:7)
Block(-1,20,2,106:4)
Block(-1,21,-3,106:1)
Block(-1,21,-2,biomesoplenty:log_3:7)
Block(-1,21,-1,biomesoplenty:log_3:7)
Block(-1,21,0,biomesoplenty:log_3:7)
Block(-1,21,1,biomesoplenty:log_3:7)
Block(-1,21,2,106:4)
Block(-1,22,-3,106:1)
Block(-1,22,-2,biomesoplenty:log_3:7)
Block(-1,22,-1,biomesoplenty:log_3:7)
Block(-1,22,0,biomesoplenty:log_3:7)
Block(-1,22,1,biomesoplenty:log_3:7)
Block(-1,22,2,106:4)
Block(-1,23,-3,106:1)
Block(-1,23,-2,biomesoplenty:log_3:7)
Block(-1,23,-1,biomesoplenty:log_3:7)
Block(-1,23,0,biomesoplenty:log_3:7)
Block(-1,23,1,biomesoplenty:log_3:7)
Block(-1,23,2,106:4)
Block(-1,24,-3,106:1)
Block(-1,24,-2,biomesoplenty:log_3:7)
Block(-1,24,-1,biomesoplenty:log_3:7)
Block(-1,24,0,biomesoplenty:log_3:7)
Block(-1,24,1,biomesoplenty:log_3:7)
Block(-1,24,2,127:10)
Block(-1,24,11,biomesoplenty:leaves_5:11)
Block(-1,25,-8,biomesoplenty:leaves_5:11)
Block(-1,25,-3,127:8)
Block(-1,25,-2,biomesoplenty:log_3:7)
Block(-1,25,-1,biomesoplenty:log_3:7)
Block(-1,25,0,biomesoplenty:log_3:7)
Block(-1,25,1,biomesoplenty:log_3:7)
Block(-1,25,2,106:4)
Block(-1,26,-7,biomesoplenty:leaves_5:11)
Block(-1,26,-3,106:1)
Block(-1,26,-2,biomesoplenty:log_3:7)
Block(-1,26,-1,biomesoplenty:log_3:7)
Block(-1,26,0,biomesoplenty:log_3:7)
Block(-1,26,1,biomesoplenty:log_3:7)
Block(-1,26,2,biomesoplenty:leaves_5:11)
Block(-1,27,-7,biomesoplenty:leaves_5:11)
Block(-1,27,-2,biomesoplenty:log_3:7)
Block(-1,27,-1,biomesoplenty:log_3:7)
Block(-1,27,0,biomesoplenty:log_3:7)
Block(-1,27,1,biomesoplenty:log_3:7)
Block(-1,28,-8,biomesoplenty:leaves_5:11)
Block(-1,28,-7,biomesoplenty:leaves_5:11)
Block(-1,28,-3,biomesoplenty:leaves_5:11)
Block(-1,28,-2,biomesoplenty:log_3:7)
Block(-1,28,-1,biomesoplenty:log_3:7)
Block(-1,28,0,biomesoplenty:log_3:7)
Block(-1,28,1,biomesoplenty:leaves_5:11)
Block(-1,28,3,biomesoplenty:leaves_5:11)
Block(-1,28,4,biomesoplenty:leaves_5:11)
Block(-1,28,7,biomesoplenty:leaves_5:11)
Block(-1,28,8,biomesoplenty:leaves_5:11)
Block(-1,29,-10,biomesoplenty:leaves_5:11)
Block(-1,29,-9,biomesoplenty:leaves_5:11)
Block(-1,29,-8,biomesoplenty:leaves_5:11)
Block(-1,29,-7,biomesoplenty:leaves_5:11)
Block(-1,29,-6,biomesoplenty:leaves_5:11)
Block(-1,29,-5,biomesoplenty:leaves_5:11)
Block(-1,29,-3,biomesoplenty:leaves_5:11)
Block(-1,29,-2,biomesoplenty:leaves_5:11)
Block(-1,29,-1,biomesoplenty:log_3:7)
Block(-1,29,0,biomesoplenty:log_3:7)
Block(-1,29,1,biomesoplenty:leaves_5:11)
Block(-1,29,2,biomesoplenty:leaves_5:11)
Block(-1,29,3,biomesoplenty:leaves_5:11)
Block(-1,29,4,biomesoplenty:leaves_5:11)
Block(-1,29,5,biomesoplenty:leaves_5:11)
Block(-1,29,6,biomesoplenty:leaves_5:11)
Block(-1,30,-12,biomesoplenty:leaves_5:11)
Block(-1,30,-11,biomesoplenty:leaves_5:11)
Block(-1,30,-10,biomesoplenty:leaves_5:11)
Block(-1,30,-9,biomesoplenty:leaves_5:11)
Block(-1,30,-8,biomesoplenty:leaves_5:11)
Block(-1,30,-7,biomesoplenty:leaves_5:11)
Block(-1,30,-6,biomesoplenty:leaves_5:11)
Block(-1,30,-5,biomesoplenty:leaves_5:11)
Block(-1,30,-4,biomesoplenty:leaves_5:11)
Block(-1,30,-2,biomesoplenty:leaves_5:11)
Block(-1,30,-1,biomesoplenty:leaves_5:11)
Block(-1,30,0,biomesoplenty:log_3:7)
Block(-1,30,1,biomesoplenty:leaves_5:11)
Block(-1,30,2,biomesoplenty:leaves_5:11)
Block(-1,30,3,biomesoplenty:leaves_5:11)
Block(-1,30,4,biomesoplenty:leaves_5:11)
Block(-1,30,5,biomesoplenty:leaves_5:11)
Block(-1,30,6,biomesoplenty:leaves_5:11)
Block(-1,30,7,biomesoplenty:leaves_5:11)
Block(-1,30,8,biomesoplenty:leaves_5:11)
Block(-1,31,-12,biomesoplenty:leaves_5:11)
Block(-1,31,-11,biomesoplenty:leaves_5:11)
Block(-1,31,-10,biomesoplenty:leaves_5:11)
Block(-1,31,-9,biomesoplenty:leaves_5:11)
Block(-1,31,-8,biomesoplenty:leaves_5:11)
Block(-1,31,-7,biomesoplenty:leaves_5:11)
Block(-1,31,-6,biomesoplenty:leaves_5:11)
Block(-1,31,-5,biomesoplenty:leaves_5:11)
Block(-1,31,-4,biomesoplenty:leaves_5:11)
Block(-1,31,-3,biomesoplenty:leaves_5:11)
Block(-1,31,-2,biomesoplenty:leaves_5:11)
Block(-1,31,-1,biomesoplenty:leaves_5:11)
Block(-1,31,0,biomesoplenty:leaves_5:11)
Block(-1,31,1,biomesoplenty:leaves_5:11)
Block(-1,31,2,biomesoplenty:leaves_5:11)
Block(-1,31,3,biomesoplenty:leaves_5:11)
Block(-1,31,4,biomesoplenty:leaves_5:11)
Block(-1,31,5,biomesoplenty:leaves_5:11)
Block(-1,31,6,biomesoplenty:leaves_5:11)
Block(-1,31,7,biomesoplenty:leaves_5:11)
Block(-1,31,8,biomesoplenty:leaves_5:11)
Block(-1,31,9,biomesoplenty:leaves_5:11)
Block(-1,32,-9,biomesoplenty:leaves_5:11)
Block(-1,32,-8,biomesoplenty:leaves_5:11)
Block(-1,32,-7,biomesoplenty:leaves_5:11)
Block(-1,32,-6,biomesoplenty:leaves_5:11)
Block(-1,32,-5,biomesoplenty:leaves_5:11)
Block(-1,32,-4,biomesoplenty:leaves_5:11)
Block(-1,32,-3,biomesoplenty:leaves_5:11)
Block(-1,32,-2,biomesoplenty:leaves_5:11)
Block(-1,32,-1,biomesoplenty:leaves_5:11)
Block(-1,32,0,biomesoplenty:leaves_5:11)
Block(-1,32,1,biomesoplenty:leaves_5:11)
Block(-1,32,2,biomesoplenty:leaves_5:11)
Block(-1,32,3,biomesoplenty:leaves_5:11)
Block(-1,32,4,biomesoplenty:leaves_5:11)
Block(-1,32,5,biomesoplenty:leaves_5:11)
Block(-1,32,6,biomesoplenty:leaves_5:11)
Block(-1,32,7,biomesoplenty:leaves_5:11)
Block(-1,32,8,biomesoplenty:leaves_5:11)
Block(-1,33,-8,biomesoplenty:leaves_5:11)
Block(-1,33,-7,biomesoplenty:leaves_5:11)
Block(-1,33,-6,biomesoplenty:leaves_5:11)
Block(-1,33,-5,biomesoplenty:leaves_5:11)
Block(-1,33,-4,biomesoplenty:leaves_5:11)
Block(-1,33,-3,biomesoplenty:leaves_5:11)
Block(-1,33,-2,biomesoplenty:leaves_5:11)
Block(-1,33,-1,biomesoplenty:leaves_5:11)
Block(-1,33,0,biomesoplenty:leaves_5:11)
Block(-1,33,1,biomesoplenty:leaves_5:11)
Block(-1,33,2,biomesoplenty:leaves_5:11)
Block(-1,33,3,biomesoplenty:leaves_5:11)
Block(-1,33,4,biomesoplenty:leaves_5:11)
Block(-1,33,5,biomesoplenty:leaves_5:11)
Block(-1,33,6,biomesoplenty:leaves_5:11)
Block(-1,33,7,biomesoplenty:leaves_5:11)
Block(-1,34,-8,biomesoplenty:leaves_5:11)
Block(-1,34,-7,biomesoplenty:leaves_5:11)
Block(-1,34,-6,biomesoplenty:leaves_5:11)
Block(-1,34,-5,biomesoplenty:leaves_5:11)
Block(-1,34,-4,biomesoplenty:leaves_5:11)
Block(-1,34,-3,biomesoplenty:leaves_5:11)
Block(-1,34,-2,biomesoplenty:leaves_5:11)
Block(-1,34,-1,biomesoplenty:leaves_5:11)
Block(-1,34,0,biomesoplenty:leaves_5:11)
Block(-1,34,1,biomesoplenty:leaves_5:11)
Block(-1,34,2,biomesoplenty:leaves_5:11)
Block(-1,34,3,biomesoplenty:leaves_5:11)
Block(-1,34,4,biomesoplenty:leaves_5:11)
Block(-1,34,5,biomesoplenty:leaves_5:11)
Block(-1,34,6,biomesoplenty:leaves_5:11)
Block(-1,35,-5,biomesoplenty:leaves_5:11)
Block(-1,35,-4,biomesoplenty:leaves_5:11)
Block(-1,35,-3,biomesoplenty:leaves_5:11)
Block(-1,35,-2,biomesoplenty:leaves_5:11)
Block(-1,35,-1,biomesoplenty:leaves_5:11)
Block(-1,35,0,biomesoplenty:leaves_5:11)
Block(-1,35,1,biomesoplenty:leaves_5:11)
Block(-1,35,2,biomesoplenty:leaves_5:11)
Block(-1,35,3,biomesoplenty:leaves_5:11)
Block(-1,35,4,biomesoplenty:leaves_5:11)
Block(-1,35,5,biomesoplenty:leaves_5:11)
Block(-1,35,6,biomesoplenty:leaves_5:11)
Block(-1,36,-5,biomesoplenty:leaves_5:11)
Block(-1,36,-2,biomesoplenty:leaves_5:11)
Block(-1,36,-1,biomesoplenty:leaves_5:11)
Block(-1,36,0,biomesoplenty:leaves_5:11)
Block(-1,36,1,biomesoplenty:leaves_5:11)
Block(-1,36,2,biomesoplenty:leaves_5:11)
Block(-1,36,3,biomesoplenty:leaves_5:11)
Block(-1,36,5,biomesoplenty:leaves_5:11)
Block(-1,37,0,biomesoplenty:leaves_5:11)
Block(-1,37,6,biomesoplenty:leaves_5:11)
Block(-1,38,1,biomesoplenty:leaves_5:11)
Block(-1,38,6,biomesoplenty:leaves_5:11)
Block(0,0,-6,biomesoplenty:log_3:7)
Block(0,0,-3,biomesoplenty:log_3:7)
Block(0,0,-2,biomesoplenty:log_3:7)
Block(0,0,-1,biomesoplenty:log_3:7)
Block(0,0,0,biomesoplenty:log_3:7)
Block(0,0,1,biomesoplenty:log_3:7)
Block(0,0,2,biomesoplenty:log_3:7)
Block(0,0,3,biomesoplenty:log_3:7)
Block(0,0,5,106:2)
Block(0,1,-5,biomesoplenty:log_3:7)
Block(0,1,-3,biomesoplenty:log_3:7)
Block(0,1,-2,biomesoplenty:log_3:7)
Block(0,1,-1,biomesoplenty:log_3:7)
Block(0,1,0,biomesoplenty:log_3:7)
Block(0,1,1,biomesoplenty:log_3:7)
Block(0,1,2,biomesoplenty:log_3:7)
Block(0,1,3,biomesoplenty:log_3:7)
Block(0,1,4,biomesoplenty:log_3:7)
Block(0,2,-5,biomesoplenty:leaves_5:11)
Block(0,2,-4,biomesoplenty:log_3:7)
Block(0,2,-3,biomesoplenty:log_3:7)
Block(0,2,-2,biomesoplenty:log_3:7)
Block(0,2,-1,biomesoplenty:log_3:7)
Block(0,2,0,biomesoplenty:log_3:7)
Block(0,2,1,biomesoplenty:log_3:7)
Block(0,2,2,biomesoplenty:log_3:7)
Block(0,2,3,106:4)
Block(0,3,-4,biomesoplenty:log_3:7)
Block(0,3,-3,biomesoplenty:log_3:7)
Block(0,3,-2,biomesoplenty:log_3:7)
Block(0,3,-1,biomesoplenty:log_3:7)
Block(0,3,0,biomesoplenty:log_3:7)
Block(0,3,1,biomesoplenty:log_3:7)
Block(0,3,2,biomesoplenty:log_3:7)
Block(0,3,3,106:4)
Block(0,4,-3,biomesoplenty:log_3:7)
Block(0,4,-2,biomesoplenty:log_3:7)
Block(0,4,-1,biomesoplenty:log_3:7)
Block(0,4,0,biomesoplenty:log_3:7)
Block(0,4,1,biomesoplenty:log_3:7)
Block(0,4,2,106:4)
Block(0,5,-4,biomesoplenty:leaves_5:11)
Block(0,5,-3,biomesoplenty:log_3:7)
Block(0,5,-2,biomesoplenty:log_3:7)
Block(0,5,-1,biomesoplenty:log_3:7)
Block(0,5,0,biomesoplenty:log_3:7)
Block(0,5,1,biomesoplenty:log_3:7)
Block(0,5,2,106:4)
Block(0,6,-3,biomesoplenty:leaves_5:11)
Block(0,6,-2,biomesoplenty:log_3:7)
Block(0,6,-1,biomesoplenty:log_3:7)
Block(0,6,0,biomesoplenty:log_3:7)
Block(0,6,1,biomesoplenty:log_3:7)
Block(0,6,2,106:4)
Block(0,7,-3,biomesoplenty:leaves_5:11)
Block(0,7,-2,biomesoplenty:log_3:7)
Block(0,7,-1,biomesoplenty:log_3:7)
Block(0,7,0,biomesoplenty:log_3:7)
Block(0,7,1,biomesoplenty:log_3:7)
Block(0,7,2,106:4)
Block(0,8,-2,biomesoplenty:log_3:7)
Block(0,8,-1,biomesoplenty:log_3:7)
Block(0,8,0,biomesoplenty:log_3:7)
Block(0,8,1,biomesoplenty:log_3:7)
Block(0,8,2,106:4)
Block(0,9,-2,biomesoplenty:log_3:7)
Block(0,9,-1,biomesoplenty:log_3:7)
Block(0,9,0,biomesoplenty:log_3:7)
Block(0,9,1,biomesoplenty:log_3:7)
Block(0,10,-2,biomesoplenty:log_3:7)
Block(0,10,-1,biomesoplenty:log_3:7)
Block(0,10,0,biomesoplenty:log_3:7)
Block(0,10,1,biomesoplenty:log_3:7)
Block(0,11,-3,biomesoplenty:leaves_5:11)
Block(0,11,-2,biomesoplenty:log_3:7)
Block(0,11,-1,biomesoplenty:log_3:7)
Block(0,11,0,biomesoplenty:log_3:7)
Block(0,11,1,biomesoplenty:log_3:7)
Block(0,12,-3,106:1)
Block(0,12,-2,biomesoplenty:log_3:7)
Block(0,12,-1,biomesoplenty:log_3:7)
Block(0,12,0,biomesoplenty:log_3:7)
Block(0,12,1,biomesoplenty:log_3:7)
Block(0,13,-3,106:1)
Block(0,13,-2,biomesoplenty:log_3:7)
Block(0,13,-1,biomesoplenty:log_3:7)
Block(0,13,0,biomesoplenty:log_3:7)
Block(0,13,1,biomesoplenty:log_3:7)
Block(0,13,3,biomesoplenty:leaves_5:11)
Block(0,14,-3,106:1)
Block(0,14,-2,biomesoplenty:log_3:7)
Block(0,14,-1,biomesoplenty:log_3:7)
Block(0,14,0,biomesoplenty:log_3:7)
Block(0,14,1,biomesoplenty:log_3:7)
Block(0,15,-3,106:1)
Block(0,15,-2,biomesoplenty:log_3:7)
Block(0,15,-1,biomesoplenty:log_3:7)
Block(0,15,0,biomesoplenty:log_3:7)
Block(0,15,1,biomesoplenty:log_3:7)
Block(0,16,-3,106:1)
Block(0,16,-2,biomesoplenty:log_3:7)
Block(0,16,-1,biomesoplenty:log_3:7)
Block(0,16,0,biomesoplenty:log_3:7)
Block(0,16,1,biomesoplenty:log_3:7)
Block(0,16,2,biomesoplenty:leaves_5:11)
Block(0,17,-3,106:1)
Block(0,17,-2,biomesoplenty:log_3:7)
Block(0,17,-1,biomesoplenty:log_3:7)
Block(0,17,0,biomesoplenty:log_3:7)
Block(0,17,1,biomesoplenty:log_3:7)
Block(0,17,2,biomesoplenty:log_3:7)
Block(0,17,3,biomesoplenty:leaves_5:11)
Block(0,18,-3,106:1)
Block(0,18,-2,biomesoplenty:log_3:7)
Block(0,18,-1,biomesoplenty:log_3:7)
Block(0,18,0,biomesoplenty:log_3:7)
Block(0,18,1,biomesoplenty:log_3:7)
Block(0,18,2,biomesoplenty:log_3:7)
Block(0,18,3,biomesoplenty:leaves_5:11)
Block(0,19,-3,106:1)
Block(0,19,-2,biomesoplenty:log_3:7)
Block(0,19,-1,biomesoplenty:log_3:7)
Block(0,19,0,biomesoplenty:log_3:7)
Block(0,19,1,biomesoplenty:log_3:7)
Block(0,19,2,biomesoplenty:log_3:7)
Block(0,19,3,biomesoplenty:log_3:7)
Block(0,20,-3,106:1)
Block(0,20,-2,biomesoplenty:log_3:7)
Block(0,20,-1,biomesoplenty:log_3:7)
Block(0,20,0,biomesoplenty:log_3:7)
Block(0,20,1,biomesoplenty:log_3:7)
Block(0,20,2,biomesoplenty:log_3:7)
Block(0,21,-3,106:1)
Block(0,21,-2,biomesoplenty:log_3:7)
Block(0,21,-1,biomesoplenty:log_3:7)
Block(0,21,0,biomesoplenty:log_3:7)
Block(0,21,1,biomesoplenty:log_3:7)
Block(0,22,-3,106:1)
Block(0,22,-2,biomesoplenty:log_3:7)
Block(0,22,-1,biomesoplenty:log_3:7)
Block(0,22,0,biomesoplenty:log_3:7)
Block(0,22,1,biomesoplenty:log_3:7)
Block(0,23,-3,106:1)
Block(0,23,-2,biomesoplenty:log_3:7)
Block(0,23,-1,biomesoplenty:log_3:7)
Block(0,23,0,biomesoplenty:log_3:7)
Block(0,23,1,biomesoplenty:log_3:7)
Block(0,23,8,biomesoplenty:leaves_5:11)
Block(0,24,-3,106:1)
Block(0,24,-2,biomesoplenty:log_3:7)
Block(0,24,-1,biomesoplenty:log_3:7)
Block(0,24,0,biomesoplenty:log_3:7)
Block(0,24,1,biomesoplenty:log_3:7)
Block(0,25,-3,106:1)
Block(0,25,-2,biomesoplenty:log_3:7)
Block(0,25,-1,biomesoplenty:log_3:7)
Block(0,25,0,biomesoplenty:log_3:7)
Block(0,25,1,biomesoplenty:log_3:7)
Block(0,25,7,biomesoplenty:leaves_5:11)
Block(0,25,10,biomesoplenty:leaves_5:11)
Block(0,26,-3,106:1)
Block(0,26,-2,biomesoplenty:log_3:7)
Block(0,26,-1,biomesoplenty:log_3:7)
Block(0,26,0,biomesoplenty:log_3:7)
Block(0,26,1,biomesoplenty:log_3:7)
Block(0,27,-11,biomesoplenty:leaves_5:11)
Block(0,27,-3,biomesoplenty:log_3:7)
Block(0,27,-2,biomesoplenty:log_3:7)
Block(0,27,-1,biomesoplenty:log_3:7)
Block(0,27,0,biomesoplenty:log_3:7)
Block(0,27,1,biomesoplenty:log_3:7)
Block(0,27,2,biomesoplenty:leaves_5:11)
Block(0,28,-10,biomesoplenty:leaves_5:11)
Block(0,28,-8,biomesoplenty:leaves_5:11)
Block(0,28,-7,biomesoplenty:leaves_5:11)
Block(0,28,-3,biomesoplenty:log_3:7)
Block(0,28,-2,biomesoplenty:log_3:7)
Block(0,28,-1,biomesoplenty:log_3:7)
Block(0,28,0,biomesoplenty:log_3:7)
Block(0,28,1,biomesoplenty:log_3:7)
Block(0,28,2,biomesoplenty:leaves_5:11)
Block(0,28,6,biomesoplenty:leaves_5:11)
Block(0,29,-14,biomesoplenty:leaves_5:11)
Block(0,29,-11,biomesoplenty:leaves_5:11)
Block(0,29,-10,biomesoplenty:leaves_5:11)
Block(0,29,-9,biomesoplenty:leaves_5:11)
Block(0,29,-8,biomesoplenty:leaves_5:11)
Block(0,29,-7,biomesoplenty:leaves_5:11)
Block(0,29,-6,biomesoplenty:leaves_5:11)
Block(0,29,-2,biomesoplenty:log_3:7)
Block(0,29,-1,biomesoplenty:log_3:7)
Block(0,29,0,biomesoplenty:log_3:7)
Block(0,29,1,biomesoplenty:log_3:7)
Block(0,29,2,biomesoplenty:leaves_5:11)
Block(0,29,4,biomesoplenty:leaves_5:11)
Block(0,29,5,biomesoplenty:leaves_5:11)
Block(0,29,6,biomesoplenty:leaves_5:11)
Block(0,30,-13,biomesoplenty:leaves_5:11)
Block(0,30,-12,biomesoplenty:leaves_5:11)
Block(0,30,-11,biomesoplenty:leaves_5:11)
Block(0,30,-10,biomesoplenty:leaves_5:11)
Block(0,30,-9,biomesoplenty:leaves_5:11)
Block(0,30,-8,biomesoplenty:leaves_5:11)
Block(0,30,-7,biomesoplenty:leaves_5:11)
Block(0,30,-6,biomesoplenty:leaves_5:11)
Block(0,30,-5,biomesoplenty:leaves_5:11)
Block(0,30,-4,biomesoplenty:leaves_5:11)
Block(0,30,-2,biomesoplenty:leaves_5:11)
Block(0,30,-1,biomesoplenty:leaves_5:11)
Block(0,30,0,biomesoplenty:log_3:7)
Block(0,30,1,biomesoplenty:leaves_5:11)
Block(0,30,2,biomesoplenty:leaves_5:11)
Block(0,30,3,biomesoplenty:leaves_5:11)
Block(0,30,4,biomesoplenty:leaves_5:11)
Block(0,30,5,biomesoplenty:leaves_5:11)
Block(0,30,6,biomesoplenty:leaves_5:11)
Block(0,30,7,biomesoplenty:leaves_5:11)
Block(0,30,8,biomesoplenty:leaves_5:11)
Block(0,31,-12,biomesoplenty:leaves_5:11)
Block(0,31,-11,biomesoplenty:leaves_5:11)
Block(0,31,-10,biomesoplenty:leaves_5:11)
Block(0,31,-9,biomesoplenty:leaves_5:11)
Block(0,31,-8,biomesoplenty:leaves_5:11)
Block(0,31,-7,biomesoplenty:leaves_5:11)
Block(0,31,-6,biomesoplenty:leaves_5:11)
Block(0,31,-5,biomesoplenty:leaves_5:11)
Block(0,31,-4,biomesoplenty:leaves_5:11)
Block(0,31,-3,biomesoplenty:leaves_5:11)
Block(0,31,-2,biomesoplenty:leaves_5:11)
Block(0,31,-1,biomesoplenty:leaves_5:11)
Block(0,31,0,biomesoplenty:log_3:7)
Block(0,31,1,biomesoplenty:leaves_5:11)
Block(0,31,2,biomesoplenty:leaves_5:11)
Block(0,31,3,biomesoplenty:leaves_5:11)
Block(0,31,4,biomesoplenty:leaves_5:11)
Block(0,31,5,biomesoplenty:leaves_5:11)
Block(0,31,6,biomesoplenty:leaves_5:11)
Block(0,31,7,biomesoplenty:leaves_5:11)
Block(0,31,10,biomesoplenty:leaves_5:11)
Block(0,32,-13,biomesoplenty:leaves_5:11)
Block(0,32,-10,biomesoplenty:leaves_5:11)
Block(0,32,-9,biomesoplenty:leaves_5:11)
Block(0,32,-8,biomesoplenty:leaves_5:11)
Block(0,32,-7,biomesoplenty:leaves_5:11)
Block(0,32,-6,biomesoplenty:leaves_5:11)
Block(0,32,-5,biomesoplenty:leaves_5:11)
Block(0,32,-4,biomesoplenty:leaves_5:11)
Block(0,32,-3,biomesoplenty:leaves_5:11)
Block(0,32,-2,biomesoplenty:leaves_5:11)
Block(0,32,-1,biomesoplenty:leaves_5:11)
Block(0,32,0,biomesoplenty:leaves_5:11)
Block(0,32,1,biomesoplenty:leaves_5:11)
Block(0,32,2,biomesoplenty:leaves_5:11)
Block(0,32,3,biomesoplenty:leaves_5:11)
Block(0,32,4,biomesoplenty:leaves_5:11)
Block(0,32,5,biomesoplenty:leaves_5:11)
Block(0,32,6,biomesoplenty:leaves_5:11)
Block(0,32,7,biomesoplenty:leaves_5:11)
Block(0,32,8,biomesoplenty:leaves_5:11)
Block(0,33,-10,biomesoplenty:leaves_5:11)
Block(0,33,-9,biomesoplenty:leaves_5:11)
Block(0,33,-8,biomesoplenty:leaves_5:11)
Block(0,33,-7,biomesoplenty:leaves_5:11)
Block(0,33,-6,biomesoplenty:leaves_5:11)
Block(0,33,-5,biomesoplenty:leaves_5:11)
Block(0,33,-4,biomesoplenty:leaves_5:11)
Block(0,33,-3,biomesoplenty:leaves_5:11)
Block(0,33,-2,biomesoplenty:leaves_5:11)
Block(0,33,-1,biomesoplenty:leaves_5:11)
Block(0,33,0,biomesoplenty:leaves_5:11)
Block(0,33,1,biomesoplenty:leaves_5:11)
Block(0,33,2,biomesoplenty:leaves_5:11)
Block(0,33,3,biomesoplenty:leaves_5:11)
Block(0,33,4,biomesoplenty:leaves_5:11)
Block(0,33,5,biomesoplenty:leaves_5:11)
Block(0,33,6,biomesoplenty:leaves_5:11)
Block(0,33,9,biomesoplenty:leaves_5:11)
Block(0,34,-11,biomesoplenty:leaves_5:11)
Block(0,34,-8,biomesoplenty:leaves_5:11)
Block(0,34,-7,biomesoplenty:leaves_5:11)
Block(0,34,-6,biomesoplenty:leaves_5:11)
Block(0,34,-5,biomesoplenty:leaves_5:11)
Block(0,34,-4,biomesoplenty:leaves_5:11)
Block(0,34,-3,biomesoplenty:leaves_5:11)
Block(0,34,-2,biomesoplenty:leaves_5:11)
Block(0,34,-1,biomesoplenty:leaves_5:11)
Block(0,34,0,biomesoplenty:leaves_5:11)
Block(0,34,1,biomesoplenty:leaves_5:11)
Block(0,34,2,biomesoplenty:leaves_5:11)
Block(0,34,3,biomesoplenty:leaves_5:11)
Block(0,34,4,biomesoplenty:leaves_5:11)
Block(0,34,5,biomesoplenty:leaves_5:11)
Block(0,35,-9,biomesoplenty:leaves_5:11)
Block(0,35,-6,biomesoplenty:leaves_5:11)
Block(0,35,-5,biomesoplenty:leaves_5:11)
Block(0,35,-4,biomesoplenty:leaves_5:11)
Block(0,35,-3,biomesoplenty:leaves_5:11)
Block(0,35,-2,biomesoplenty:leaves_5:11)
Block(0,35,-1,biomesoplenty:leaves_5:11)
Block(0,35,0,biomesoplenty:leaves_5:11)
Block(0,35,1,biomesoplenty:leaves_5:11)
Block(0,35,2,biomesoplenty:leaves_5:11)
Block(0,35,3,biomesoplenty:leaves_5:11)
Block(0,35,4,biomesoplenty:leaves_5:11)
Block(0,35,7,biomesoplenty:leaves_5:11)
Block(0,36,-10,biomesoplenty:leaves_5:11)
Block(0,36,-7,biomesoplenty:leaves_5:11)
Block(0,36,-3,biomesoplenty:leaves_5:11)
Block(0,36,-2,biomesoplenty:leaves_5:11)
Block(0,36,-1,biomesoplenty:leaves_5:11)
Block(0,36,0,biomesoplenty:leaves_5:11)
Block(0,36,1,biomesoplenty:leaves_5:11)
Block(0,36,2,biomesoplenty:leaves_5:11)
Block(0,36,8,biomesoplenty:leaves_5:11)
Block(0,37,-2,biomesoplenty:leaves_5:11)
Block(0,37,0,biomesoplenty:leaves_5:11)
Block(0,37,2,biomesoplenty:leaves_5:11)
Block(0,38,0,biomesoplenty:leaves_5:11)
Block(0,38,3,biomesoplenty:leaves_5:11)
Block(1,0,-7,biomesoplenty:log_3:7)
Block(1,0,-6,biomesoplenty:leaves_5:11)
Block(1,0,-3,106:2)
Block(1,0,-2,106:2)
Block(1,0,-1,biomesoplenty:log_3:7)
Block(1,0,0,biomesoplenty:log_3:7)
Block(1,0,1,biomesoplenty:log_3:7)
Block(1,1,-5,biomesoplenty:leaves_5:11)
Block(1,1,-3,106:2)
Block(1,1,-2,biomesoplenty:log_3:7)
Block(1,1,-1,biomesoplenty:log_3:7)
Block(1,1,0,biomesoplenty:log_3:7)
Block(1,1,1,biomesoplenty:log_3:7)
Block(1,2,-3,106:2)
Block(1,2,-2,biomesoplenty:log_3:7)
Block(1,2,-1,biomesoplenty:log_3:7)
Block(1,2,0,biomesoplenty:log_3:7)
Block(1,2,1,biomesoplenty:log_3:7)
Block(1,3,-2,biomesoplenty:log_3:7)
Block(1,3,-1,biomesoplenty:log_3:7)
Block(1,3,0,biomesoplenty:log_3:7)
Block(1,3,1,biomesoplenty:log_3:7)
Block(1,4,-2,106:2)
Block(1,4,-1,biomesoplenty:log_3:7)
Block(1,4,0,biomesoplenty:log_3:7)
Block(1,4,1,biomesoplenty:log_3:7)
Block(1,5,-2,106:2)
Block(1,5,-1,biomesoplenty:log_3:7)
Block(1,5,0,biomesoplenty:log_3:7)
Block(1,5,1,106:4)
Block(1,6,-2,106:2)
Block(1,6,-1,biomesoplenty:log_3:7)
Block(1,6,0,biomesoplenty:log_3:7)
Block(1,6,1,106:4)
Block(1,7,-1,biomesoplenty:log_3:7)
Block(1,7,0,biomesoplenty:log_3:7)
Block(1,7,1,106:4)
Block(1,8,-1,biomesoplenty:log_3:7)
Block(1,8,0,biomesoplenty:log_3:7)
Block(1,8,1,106:4)
Block(1,9,-1,biomesoplenty:log_3:7)
Block(1,9,0,biomesoplenty:log_3:7)
Block(1,9,1,106:4)
Block(1,10,-2,biomesoplenty:log_3:7)
Block(1,10,-1,biomesoplenty:log_3:7)
Block(1,10,0,biomesoplenty:log_3:7)
Block(1,10,1,106:4)
Block(1,11,-2,biomesoplenty:log_3:7)
Block(1,11,-1,biomesoplenty:log_3:7)
Block(1,11,0,biomesoplenty:log_3:7)
Block(1,11,1,106:4)
Block(1,12,-3,biomesoplenty:leaves_5:11)
Block(1,12,-2,biomesoplenty:log_3:7)
Block(1,12,-1,biomesoplenty:log_3:7)
Block(1,12,0,biomesoplenty:log_3:7)
Block(1,12,1,106:4)
Block(1,13,-2,biomesoplenty:log_3:7)
Block(1,13,-1,biomesoplenty:log_3:7)
Block(1,13,0,biomesoplenty:log_3:7)
Block(1,14,-2,biomesoplenty:leaves_5:11)
Block(1,14,-1,biomesoplenty:log_3:7)
Block(1,14,0,biomesoplenty:log_3:7)
Block(1,15,-2,106:2)
Block(1,15,-1,biomesoplenty:log_3:7)
Block(1,15,0,biomesoplenty:log_3:7)
Block(1,15,1,biomesoplenty:leaves_5:11)
Block(1,16,-2,106:2)
Block(1,16,-1,biomesoplenty:log_3:7)
Block(1,16,0,biomesoplenty:log_3:7)
Block(1,17,-2,106:2)
Block(1,17,-1,biomesoplenty:log_3:7)
Block(1,17,0,biomesoplenty:log_3:7)
Block(1,18,-2,106:2)
Block(1,18,-1,biomesoplenty:log_3:7)
Block(1,18,0,biomesoplenty:log_3:7)
Block(1,18,1,biomesoplenty:log_3:7)
Block(1,18,3,biomesoplenty:leaves_5:11)
Block(1,19,-2,106:2)
Block(1,19,-1,biomesoplenty:log_3:7)
Block(1,19,0,biomesoplenty:log_3:7)
Block(1,19,1,biomesoplenty:log_3:7)
Block(1,19,2,biomesoplenty:log_3:7)
Block(1,19,3,biomesoplenty:log_3:7)
Block(1,19,4,biomesoplenty:leaves_5:11)
Block(1,20,-2,106:2)
Block(1,20,-1,biomesoplenty:log_3:7)
Block(1,20,0,biomesoplenty:log_3:7)
Block(1,20,1,biomesoplenty:log_3:7)
Block(1,20,2,biomesoplenty:log_3:7)
Block(1,20,3,biomesoplenty:log_3:7)
Block(1,20,4,biomesoplenty:leaves_5:11)
Block(1,21,-1,biomesoplenty:log_3:7)
Block(1,21,0,biomesoplenty:log_3:7)
Block(1,21,1,biomesoplenty:log_3:7)
Block(1,21,2,biomesoplenty:log_3:7)
Block(1,21,3,biomesoplenty:log_3:7)
Block(1,21,4,biomesoplenty:leaves_5:11)
Block(1,22,-1,biomesoplenty:log_3:7)
Block(1,22,0,biomesoplenty:log_3:7)
Block(1,22,2,biomesoplenty:log_3:7)
Block(1,22,3,biomesoplenty:leaves_5:11)
Block(1,22,5,biomesoplenty:leaves_5:11)
Block(1,23,-1,biomesoplenty:log_3:7)
Block(1,23,0,biomesoplenty:log_3:7)
Block(1,23,7,biomesoplenty:leaves_5:11)
Block(1,24,-1,biomesoplenty:log_3:7)
Block(1,24,0,biomesoplenty:log_3:7)
Block(1,24,8,biomesoplenty:leaves_5:11)
Block(1,24,9,biomesoplenty:leaves_5:11)
Block(1,25,-1,biomesoplenty:log_3:7)
Block(1,25,0,biomesoplenty:log_3:7)
Block(1,25,4,biomesoplenty:leaves_5:11)
Block(1,25,6,biomesoplenty:leaves_5:11)
Block(1,26,-2,biomesoplenty:log_3:7)
Block(1,26,-1,biomesoplenty:log_3:7)
Block(1,26,0,biomesoplenty:log_3:7)
Block(1,26,9,biomesoplenty:leaves_5:11)
Block(1,26,12,biomesoplenty:leaves_5:11)
Block(1,27,-3,biomesoplenty:log_3:7)
Block(1,27,-2,biomesoplenty:log_3:7)
Block(1,27,-1,biomesoplenty:log_3:7)
Block(1,27,0,biomesoplenty:log_3:7)
Block(1,28,-10,biomesoplenty:leaves_5:11)
Block(1,28,-8,biomesoplenty:leaves_5:11)
Block(1,28,-4,biomesoplenty:log_3:7)
Block(1,28,-3,biomesoplenty:log_3:7)
Block(1,28,-2,biomesoplenty:log_3:7)
Block(1,28,-1,biomesoplenty:log_3:7)
Block(1,28,0,biomesoplenty:log_3:7)
Block(1,28,7,biomesoplenty:leaves_5:11)
Block(1,29,-10,biomesoplenty:leaves_5:11)
Block(1,29,-8,biomesoplenty:leaves_5:11)
Block(1,29,-7,biomesoplenty:leaves_5:11)
Block(1,29,-4,biomesoplenty:log_3:7)
Block(1,29,0,biomesoplenty:log_3:7)
Block(1,29,1,biomesoplenty:leaves_5:11)
Block(1,29,2,biomesoplenty:leaves_5:11)
Block(1,29,3,biomesoplenty:leaves_5:11)
Block(1,29,4,biomesoplenty:leaves_5:11)
Block(1,29,5,biomesoplenty:leaves_5:11)
Block(1,30,-12,biomesoplenty:leaves_5:11)
Block(1,30,-11,biomesoplenty:leaves_5:11)
Block(1,30,-10,biomesoplenty:leaves_5:11)
Block(1,30,-9,biomesoplenty:leaves_5:11)
Block(1,30,-8,biomesoplenty:leaves_5:11)
Block(1,30,-7,biomesoplenty:leaves_5:11)
Block(1,30,-6,biomesoplenty:leaves_5:11)
Block(1,30,-5,biomesoplenty:leaves_5:11)
Block(1,30,-4,biomesoplenty:leaves_5:11)
Block(1,30,0,biomesoplenty:leaves_5:11)
Block(1,30,1,biomesoplenty:leaves_5:11)
Block(1,30,2,biomesoplenty:leaves_5:11)
Block(1,30,3,biomesoplenty:leaves_5:11)
Block(1,30,4,biomesoplenty:leaves_5:11)
Block(1,30,5,biomesoplenty:leaves_5:11)
Block(1,30,6,biomesoplenty:leaves_5:11)
Block(1,30,7,biomesoplenty:leaves_5:11)
Block(1,31,-11,biomesoplenty:leaves_5:11)
Block(1,31,-10,biomesoplenty:leaves_5:11)
Block(1,31,-9,biomesoplenty:leaves_5:11)
Block(1,31,-8,biomesoplenty:leaves_5:11)
Block(1,31,-7,biomesoplenty:leaves_5:11)
Block(1,31,-6,biomesoplenty:leaves_5:11)
Block(1,31,-5,biomesoplenty:leaves_5:11)
Block(1,31,-4,biomesoplenty:leaves_5:11)
Block(1,31,-3,biomesoplenty:leaves_5:11)
Block(1,31,-2,biomesoplenty:leaves_5:11)
Block(1,31,-1,biomesoplenty:leaves_5:11)
Block(1,31,0,biomesoplenty:leaves_5:11)
Block(1,31,1,biomesoplenty:leaves_5:11)
Block(1,31,2,biomesoplenty:leaves_5:11)
Block(1,31,3,biomesoplenty:leaves_5:11)
Block(1,31,4,biomesoplenty:leaves_5:11)
Block(1,31,5,biomesoplenty:leaves_5:11)
Block(1,31,6,biomesoplenty:leaves_5:11)
Block(1,31,7,biomesoplenty:leaves_5:11)
Block(1,32,-9,biomesoplenty:leaves_5:11)
Block(1,32,-8,biomesoplenty:leaves_5:11)
Block(1,32,-7,biomesoplenty:leaves_5:11)
Block(1,32,-6,biomesoplenty:leaves_5:11)
Block(1,32,-5,biomesoplenty:leaves_5:11)
Block(1,32,-4,biomesoplenty:leaves_5:11)
Block(1,32,-3,biomesoplenty:leaves_5:11)
Block(1,32,-2,biomesoplenty:leaves_5:11)
Block(1,32,-1,biomesoplenty:leaves_5:11)
Block(1,32,0,biomesoplenty:leaves_5:11)
Block(1,32,1,biomesoplenty:leaves_5:11)
Block(1,32,2,biomesoplenty:leaves_5:11)
Block(1,32,3,biomesoplenty:leaves_5:11)
Block(1,32,4,biomesoplenty:leaves_5:11)
Block(1,32,5,biomesoplenty:leaves_5:11)
Block(1,32,6,biomesoplenty:leaves_5:11)
Block(1,33,-8,biomesoplenty:leaves_5:11)
Block(1,33,-7,biomesoplenty:leaves_5:11)
Block(1,33,-6,biomesoplenty:leaves_5:11)
Block(1,33,-5,biomesoplenty:leaves_5:11)
Block(1,33,-4,biomesoplenty:leaves_5:11)
Block(1,33,-3,biomesoplenty:leaves_5:11)
Block(1,33,-2,biomesoplenty:leaves_5:11)
Block(1,33,-1,biomesoplenty:leaves_5:11)
Block(1,33,0,biomesoplenty:leaves_5:11)
Block(1,33,1,biomesoplenty:leaves_5:11)
Block(1,33,2,biomesoplenty:leaves_5:11)
Block(1,33,3,biomesoplenty:leaves_5:11)
Block(1,33,4,biomesoplenty:leaves_5:11)
Block(1,33,5,biomesoplenty:leaves_5:11)
Block(1,33,6,biomesoplenty:leaves_5:11)
Block(1,34,-8,biomesoplenty:leaves_5:11)
Block(1,34,-7,biomesoplenty:leaves_5:11)
Block(1,34,-6,biomesoplenty:leaves_5:11)
Block(1,34,-5,biomesoplenty:leaves_5:11)
Block(1,34,-4,biomesoplenty:leaves_5:11)
Block(1,34,-3,biomesoplenty:leaves_5:11)
Block(1,34,-2,biomesoplenty:leaves_5:11)
Block(1,34,-1,biomesoplenty:leaves_5:11)
Block(1,34,0,biomesoplenty:leaves_5:11)
Block(1,34,1,biomesoplenty:leaves_5:11)
Block(1,34,2,biomesoplenty:leaves_5:11)
Block(1,34,3,biomesoplenty:leaves_5:11)
Block(1,34,4,biomesoplenty:leaves_5:11)
Block(1,35,-7,biomesoplenty:leaves_5:11)
Block(1,35,-5,biomesoplenty:leaves_5:11)
Block(1,35,-4,biomesoplenty:leaves_5:11)
Block(1,35,-3,biomesoplenty:leaves_5:11)
Block(1,35,-2,biomesoplenty:leaves_5:11)
Block(1,35,-1,biomesoplenty:leaves_5:11)
Block(1,35,0,biomesoplenty:leaves_5:11)
Block(1,35,1,biomesoplenty:leaves_5:11)
Block(1,35,2,biomesoplenty:leaves_5:11)
Block(1,35,3,biomesoplenty:leaves_5:11)
Block(1,36,-5,biomesoplenty:leaves_5:11)
Block(1,36,-2,biomesoplenty:leaves_5:11)
Block(1,36,-1,biomesoplenty:leaves_5:11)
Block(1,36,0,biomesoplenty:leaves_5:11)
Block(1,36,1,biomesoplenty:leaves_5:11)
Block(1,36,2,biomesoplenty:leaves_5:11)
Block(1,36,3,biomesoplenty:leaves_5:11)
Block(1,36,4,biomesoplenty:leaves_5:11)
Block(1,37,-6,biomesoplenty:leaves_5:11)
Block(1,37,5,biomesoplenty:leaves_5:11)
Block(1,38,-2,biomesoplenty:leaves_5:11)
Block(1,39,-1,biomesoplenty:leaves_5:11)
Block(2,0,-1,106:1)
Block(2,0,0,biomesoplenty:log_3:7)
Block(2,0,1,biomesoplenty:log_3:7)
Block(2,1,-2,biomesoplenty:log_3:7)
Block(2,1,-1,106:1)
Block(2,1,0,biomesoplenty:log_3:7)
Block(2,1,1,biomesoplenty:log_3:7)
Block(2,1,2,biomesoplenty:log_3:7)
Block(2,2,-1,106:1)
Block(2,2,0,biomesoplenty:log_3:7)
Block(2,2,1,biomesoplenty:log_3:7)
Block(2,3,-1,biomesoplenty:log_3:7)
Block(2,3,0,biomesoplenty:log_3:7)
Block(2,3,1,biomesoplenty:leaves_5:11)
Block(2,4,-1,biomesoplenty:log_3:7)
Block(2,4,0,biomesoplenty:log_3:7)
Block(2,5,-1,106:2)
Block(2,5,0,biomesoplenty:log_3:7)
Block(2,6,-1,106:2)
Block(2,6,0,biomesoplenty:log_3:7)
Block(2,7,-1,106:2)
Block(2,7,0,106:2)
Block(2,8,-1,106:2)
Block(2,8,0,106:2)
Block(2,9,-1,106:2)
Block(2,9,0,106:2)
Block(2,10,-1,106:2)
Block(2,10,0,106:2)
Block(2,11,0,106:2)
Block(2,12,0,106:2)
Block(2,13,-2,biomesoplenty:leaves_5:11)
Block(2,14,0,biomesoplenty:leaves_5:11)
Block(2,19,2,biomesoplenty:log_3:7)
Block(2,20,1,biomesoplenty:log_3:7)
Block(2,20,2,biomesoplenty:log_3:7)
Block(2,20,3,biomesoplenty:log_3:7)
Block(2,20,4,biomesoplenty:leaves_5:11)
Block(2,21,1,biomesoplenty:leaves_5:11)
Block(2,21,2,biomesoplenty:log_3:7)
Block(2,21,3,biomesoplenty:log_3:7)
Block(2,21,4,biomesoplenty:log_3:7)
Block(2,21,8,biomesoplenty:leaves_5:11)
Block(2,22,2,biomesoplenty:leaves_5:11)
Block(2,22,3,biomesoplenty:log_3:7)
Block(2,22,4,biomesoplenty:log_3:7)
Block(2,22,5,biomesoplenty:log_3:7)
Block(2,22,6,biomesoplenty:leaves_5:11)
Block(2,23,3,biomesoplenty:log_3:7)
Block(2,23,4,biomesoplenty:log_3:7)
Block(2,23,5,biomesoplenty:leaves_5:11)
Block(2,23,6,biomesoplenty:leaves_5:11)
Block(2,23,7,biomesoplenty:leaves_5:11)
Block(2,23,8,biomesoplenty:leaves_5:11)
Block(2,23,11,biomesoplenty:leaves_5:11)
Block(2,24,-1,127:9)
Block(2,24,4,biomesoplenty:leaves_5:11)
Block(2,24,6,biomesoplenty:leaves_5:11)
Block(2,24,7,biomesoplenty:leaves_5:11)
Block(2,24,8,biomesoplenty:leaves_5:11)
Block(2,24,9,biomesoplenty:leaves_5:11)
Block(2,24,10,biomesoplenty:leaves_5:11)
Block(2,25,8,biomesoplenty:leaves_5:11)
Block(2,25,9,biomesoplenty:leaves_5:11)
Block(2,25,11,biomesoplenty:leaves_5:11)
Block(2,26,-9,biomesoplenty:leaves_5:11)
Block(2,26,-1,biomesoplenty:leaves_5:11)
Block(2,27,-11,biomesoplenty:leaves_5:11)
Block(2,27,-10,biomesoplenty:leaves_5:11)
Block(2,27,-8,biomesoplenty:leaves_5:11)
Block(2,27,-5,biomesoplenty:leaves_5:11)
Block(2,27,-1,biomesoplenty:leaves_5:11)
Block(2,27,0,biomesoplenty:leaves_5:11)
Block(2,27,6,biomesoplenty:leaves_5:11)
Block(2,27,12,biomesoplenty:leaves_5:11)
Block(2,28,-8,biomesoplenty:leaves_5:11)
Block(2,28,-3,biomesoplenty:log_3:7)
Block(2,28,0,biomesoplenty:leaves_5:11)
Block(2,28,1,biomesoplenty:leaves_5:11)
Block(2,28,2,biomesoplenty:leaves_5:11)
Block(2,29,-9,biomesoplenty:leaves_5:11)
Block(2,29,-8,biomesoplenty:leaves_5:11)
Block(2,29,-7,biomesoplenty:leaves_5:11)
Block(2,29,-5,biomesoplenty:log_3:7)
Block(2,29,-4,biomesoplenty:log_3:7)
Block(2,29,-3,biomesoplenty:log_3:7)
Block(2,29,1,biomesoplenty:leaves_5:11)
Block(2,29,2,biomesoplenty:leaves_5:11)
Block(2,29,3,biomesoplenty:leaves_5:11)
Block(2,29,4,biomesoplenty:leaves_5:11)
Block(2,29,10,biomesoplenty:leaves_5:11)
Block(2,30,-11,biomesoplenty:leaves_5:11)
Block(2,30,-10,biomesoplenty:leaves_5:11)
Block(2,30,-9,biomesoplenty:leaves_5:11)
Block(2,30,-8,biomesoplenty:leaves_5:11)
Block(2,30,-7,biomesoplenty:leaves_5:11)
Block(2,30,-6,biomesoplenty:leaves_5:11)
Block(2,30,-5,biomesoplenty:leaves_5:11)
Block(2,30,-4,biomesoplenty:log_3:7)
Block(2,30,-1,biomesoplenty:leaves_5:11)
Block(2,30,0,biomesoplenty:leaves_5:11)
Block(2,30,1,biomesoplenty:leaves_5:11)
Block(2,30,2,biomesoplenty:leaves_5:11)
Block(2,30,3,biomesoplenty:leaves_5:11)
Block(2,30,4,biomesoplenty:leaves_5:11)
Block(2,30,5,biomesoplenty:leaves_5:11)
Block(2,30,6,biomesoplenty:leaves_5:11)
Block(2,30,8,biomesoplenty:leaves_5:11)
Block(2,30,9,biomesoplenty:leaves_5:11)
Block(2,31,-10,biomesoplenty:leaves_5:11)
Block(2,31,-8,biomesoplenty:leaves_5:11)
Block(2,31,-7,biomesoplenty:leaves_5:11)
Block(2,31,-6,biomesoplenty:leaves_5:11)
Block(2,31,-5,biomesoplenty:leaves_5:11)
Block(2,31,-4,biomesoplenty:leaves_5:11)
Block(2,31,-3,biomesoplenty:leaves_5:11)
Block(2,31,-2,biomesoplenty:leaves_5:11)
Block(2,31,-1,biomesoplenty:leaves_5:11)
Block(2,31,0,biomesoplenty:leaves_5:11)
Block(2,31,1,biomesoplenty:leaves_5:11)
Block(2,31,2,biomesoplenty:leaves_5:11)
Block(2,31,3,biomesoplenty:leaves_5:11)
Block(2,31,4,biomesoplenty:leaves_5:11)
Block(2,31,5,biomesoplenty:leaves_5:11)
Block(2,31,6,biomesoplenty:leaves_5:11)
Block(2,31,9,biomesoplenty:leaves_5:11)
Block(2,32,-9,biomesoplenty:leaves_5:11)
Block(2,32,-8,biomesoplenty:leaves_5:11)
Block(2,32,-7,biomesoplenty:leaves_5:11)
Block(2,32,-6,biomesoplenty:leaves_5:11)
Block(2,32,-5,biomesoplenty:leaves_5:11)
Block(2,32,-4,biomesoplenty:leaves_5:11)
Block(2,32,-3,biomesoplenty:leaves_5:11)
Block(2,32,-2,biomesoplenty:leaves_5:11)
Block(2,32,-1,biomesoplenty:leaves_5:11)
Block(2,32,0,biomesoplenty:leaves_5:11)
Block(2,32,1,biomesoplenty:leaves_5:11)
Block(2,32,2,biomesoplenty:leaves_5:11)
Block(2,32,3,biomesoplenty:leaves_5:11)
Block(2,32,4,biomesoplenty:leaves_5:11)
Block(2,32,5,biomesoplenty:leaves_5:11)
Block(2,32,10,biomesoplenty:leaves_5:11)
Block(2,33,-11,biomesoplenty:leaves_5:11)
Block(2,33,-10,biomesoplenty:leaves_5:11)
Block(2,33,-8,biomesoplenty:leaves_5:11)
Block(2,33,-7,biomesoplenty:leaves_5:11)
Block(2,33,-6,biomesoplenty:leaves_5:11)
Block(2,33,-5,biomesoplenty:leaves_5:11)
Block(2,33,-4,biomesoplenty:leaves_5:11)
Block(2,33,-3,biomesoplenty:leaves_5:11)
Block(2,33,-2,biomesoplenty:leaves_5:11)
Block(2,33,-1,biomesoplenty:leaves_5:11)
Block(2,33,0,biomesoplenty:leaves_5:11)
Block(2,33,1,biomesoplenty:leaves_5:11)
Block(2,33,2,biomesoplenty:leaves_5:11)
Block(2,33,3,biomesoplenty:leaves_5:11)
Block(2,33,4,biomesoplenty:leaves_5:11)
Block(2,33,5,biomesoplenty:leaves_5:11)
Block(2,33,7,biomesoplenty:leaves_5:11)
Block(2,34,-10,biomesoplenty:leaves_5:11)
Block(2,34,-7,biomesoplenty:leaves_5:11)
Block(2,34,-6,biomesoplenty:leaves_5:11)
Block(2,34,-5,biomesoplenty:leaves_5:11)
Block(2,34,-4,biomesoplenty:leaves_5:11)
Block(2,34,-3,biomesoplenty:leaves_5:11)
Block(2,34,-2,biomesoplenty:leaves_5:11)
Block(2,34,-1,biomesoplenty:leaves_5:11)
Block(2,34,0,biomesoplenty:leaves_5:11)
Block(2,34,1,biomesoplenty:leaves_5:11)
Block(2,34,2,biomesoplenty:leaves_5:11)
Block(2,34,3,biomesoplenty:leaves_5:11)
Block(2,34,4,biomesoplenty:leaves_5:11)
Block(2,34,8,biomesoplenty:leaves_5:11)
Block(2,35,-4,biomesoplenty:leaves_5:11)
Block(2,35,-3,biomesoplenty:leaves_5:11)
Block(2,35,-2,biomesoplenty:leaves_5:11)
Block(2,35,-1,biomesoplenty:leaves_5:11)
Block(2,35,0,biomesoplenty:leaves_5:11)
Block(2,35,1,biomesoplenty:leaves_5:11)
Block(2,35,2,biomesoplenty:leaves_5:11)
Block(2,35,3,biomesoplenty:leaves_5:11)
Block(2,35,4,biomesoplenty:leaves_5:11)
Block(2,36,-4,biomesoplenty:leaves_5:11)
Block(2,36,-2,biomesoplenty:leaves_5:11)
Block(2,36,0,biomesoplenty:leaves_5:11)
Block(2,36,1,biomesoplenty:leaves_5:11)
Block(2,36,2,biomesoplenty:leaves_5:11)
Block(2,37,1,biomesoplenty:leaves_5:11)
Block(2,38,1,biomesoplenty:leaves_5:11)
Block(2,38,3,biomesoplenty:leaves_5:11)
Block(2,39,2,biomesoplenty:leaves_5:11)
Block(3,0,-2,biomesoplenty:log_3:7)
Block(3,0,0,biomesoplenty:log_3:7)
Block(3,0,1,biomesoplenty:leaves_5:11)
Block(3,0,3,biomesoplenty:log_3:7)
Block(3,1,0,106:2)
Block(3,1,1,biomesoplenty:leaves_5:11)
Block(3,2,0,106:2)
Block(3,17,1,biomesoplenty:leaves_5:11)
Block(3,18,1,biomesoplenty:leaves_5:11)
Block(3,18,7,biomesoplenty:leaves_5:11)
Block(3,19,1,biomesoplenty:leaves_5:11)
Block(3,20,1,biomesoplenty:leaves_5:11)
Block(3,21,4,biomesoplenty:log_3:7)
Block(3,22,3,biomesoplenty:log_3:7)
Block(3,22,4,biomesoplenty:log_3:7)
Block(3,22,5,biomesoplenty:log_3:7)
Block(3,22,6,biomesoplenty:log_3:7)
Block(3,22,8,biomesoplenty:leaves_5:11)
Block(3,23,4,biomesoplenty:log_3:7)
Block(3,23,5,biomesoplenty:log_3:7)
Block(3,23,6,biomesoplenty:log_3:7)
Block(3,23,7,biomesoplenty:log_3:7)
Block(3,23,8,biomesoplenty:leaves_5:11)
Block(3,23,9,biomesoplenty:leaves_5:11)
Block(3,24,5,biomesoplenty:leaves_5:11)
Block(3,24,6,biomesoplenty:leaves_5:11)
Block(3,24,7,biomesoplenty:leaves_5:11)
Block(3,24,8,biomesoplenty:leaves_5:11)
Block(3,24,9,biomesoplenty:leaves_5:11)
Block(3,24,10,biomesoplenty:leaves_5:11)
Block(3,25,6,biomesoplenty:leaves_5:11)
Block(3,25,7,biomesoplenty:leaves_5:11)
Block(3,25,8,biomesoplenty:leaves_5:11)
Block(3,25,9,biomesoplenty:log_3:7)
Block(3,25,10,biomesoplenty:leaves_5:11)
Block(3,25,14,biomesoplenty:leaves_5:11)
Block(3,26,9,biomesoplenty:leaves_5:11)
Block(3,27,2,biomesoplenty:leaves_5:11)
Block(3,27,6,biomesoplenty:leaves_5:11)
Block(3,27,10,biomesoplenty:leaves_5:11)
Block(3,28,-7,biomesoplenty:leaves_5:11)
Block(3,28,-5,biomesoplenty:leaves_5:11)
Block(3,28,0,biomesoplenty:leaves_5:11)
Block(3,29,-12,biomesoplenty:leaves_5:11)
Block(3,29,-9,biomesoplenty:leaves_5:11)
Block(3,29,-8,biomesoplenty:leaves_5:11)
Block(3,29,-7,biomesoplenty:leaves_5:11)
Block(3,29,-6,biomesoplenty:leaves_5:11)
Block(3,29,-5,biomesoplenty:leaves_5:11)
Block(3,29,-1,biomesoplenty:leaves_5:11)
Block(3,29,0,biomesoplenty:leaves_5:11)
Block(3,29,1,biomesoplenty:leaves_5:11)
Block(3,29,2,biomesoplenty:leaves_5:11)
Block(3,30,-11,biomesoplenty:leaves_5:11)
Block(3,30,-10,biomesoplenty:leaves_5:11)
Block(3,30,-9,biomesoplenty:leaves_5:11)
Block(3,30,-8,biomesoplenty:leaves_5:11)
Block(3,30,-7,biomesoplenty:leaves_5:11)
Block(3,30,-6,biomesoplenty:leaves_5:11)
Block(3,30,-5,biomesoplenty:log_3:7)
Block(3,30,-4,biomesoplenty:log_3:7)
Block(3,30,-2,biomesoplenty:leaves_5:11)
Block(3,30,-1,biomesoplenty:leaves_5:11)
Block(3,30,0,biomesoplenty:leaves_5:11)
Block(3,30,1,biomesoplenty:leaves_5:11)
Block(3,30,2,biomesoplenty:leaves_5:11)
Block(3,30,3,biomesoplenty:leaves_5:11)
Block(3,30,4,biomesoplenty:leaves_5:11)
Block(3,30,5,biomesoplenty:leaves_5:11)
Block(3,30,6,biomesoplenty:leaves_5:11)
Block(3,31,-13,biomesoplenty:leaves_5:11)
Block(3,31,-12,biomesoplenty:leaves_5:11)
Block(3,31,-9,biomesoplenty:leaves_5:11)
Block(3,31,-7,biomesoplenty:leaves_5:11)
Block(3,31,-6,biomesoplenty:log_3:7)
Block(3,31,-5,biomesoplenty:log_3:7)
Block(3,31,-4,biomesoplenty:leaves_5:11)
Block(3,31,-3,biomesoplenty:leaves_5:11)
Block(3,31,-2,biomesoplenty:leaves_5:11)
Block(3,31,-1,biomesoplenty:leaves_5:11)
Block(3,31,0,biomesoplenty:leaves_5:11)
Block(3,31,1,biomesoplenty:leaves_5:11)
Block(3,31,2,biomesoplenty:leaves_5:11)
Block(3,31,3,biomesoplenty:leaves_5:11)
Block(3,31,4,biomesoplenty:leaves_5:11)
Block(3,31,5,biomesoplenty:leaves_5:11)
Block(3,31,7,biomesoplenty:leaves_5:11)
Block(3,32,-8,biomesoplenty:leaves_5:11)
Block(3,32,-7,biomesoplenty:leaves_5:11)
Block(3,32,-6,biomesoplenty:leaves_5:11)
Block(3,32,-5,biomesoplenty:leaves_5:11)
Block(3,32,-4,biomesoplenty:leaves_5:11)
Block(3,32,-3,biomesoplenty:leaves_5:11)
Block(3,32,-2,biomesoplenty:leaves_5:11)
Block(3,32,-1,biomesoplenty:leaves_5:11)
Block(3,32,0,biomesoplenty:leaves_5:11)
Block(3,32,1,biomesoplenty:leaves_5:11)
Block(3,32,2,biomesoplenty:leaves_5:11)
Block(3,32,3,biomesoplenty:leaves_5:11)
Block(3,32,4,biomesoplenty:leaves_5:11)
Block(3,32,5,biomesoplenty:leaves_5:11)
Block(3,33,-10,biomesoplenty:leaves_5:11)
Block(3,33,-7,biomesoplenty:leaves_5:11)
Block(3,33,-6,biomesoplenty:leaves_5:11)
Block(3,33,-5,biomesoplenty:leaves_5:11)
Block(3,33,-4,biomesoplenty:leaves_5:11)
Block(3,33,-3,biomesoplenty:leaves_5:11)
Block(3,33,-2,biomesoplenty:leaves_5:11)
Block(3,33,-1,biomesoplenty:leaves_5:11)
Block(3,33,0,biomesoplenty:leaves_5:11)
Block(3,33,1,biomesoplenty:leaves_5:11)
Block(3,33,2,biomesoplenty:leaves_5:11)
Block(3,33,3,biomesoplenty:leaves_5:11)
Block(3,33,4,biomesoplenty:leaves_5:11)
Block(3,34,-6,biomesoplenty:leaves_5:11)
Block(3,34,-5,biomesoplenty:leaves_5:11)
Block(3,34,-4,biomesoplenty:leaves_5:11)
Block(3,34,-3,biomesoplenty:leaves_5:11)
Block(3,34,-2,biomesoplenty:leaves_5:11)
Block(3,34,-1,biomesoplenty:leaves_5:11)
Block(3,34,0,biomesoplenty:leaves_5:11)
Block(3,34,1,biomesoplenty:leaves_5:11)
Block(3,34,2,biomesoplenty:leaves_5:11)
Block(3,34,3,biomesoplenty:leaves_5:11)
Block(3,34,4,biomesoplenty:leaves_5:11)
Block(3,35,-10,biomesoplenty:leaves_5:11)
Block(3,35,-7,biomesoplenty:leaves_5:11)
Block(3,35,-6,biomesoplenty:leaves_5:11)
