#######################################################################
# +-----------------------------------------------------------------+ #
# |                            BO3 object                           | #
# +-----------------------------------------------------------------+ #
#######################################################################

# The descriptions in this file are accurate only for TerrainControl and OTG.
# For MCW and OTG+ these descriptions are only accurate if the BO3 is used as a CustomObject.
# MCW and OTG+ completely reimplemented CustomStructure, check the MCW/OTG+ documentation for more information.

# This is the config file of a custom object.
# If you add this object correctly to your BiomeConfigs, it will spawn in the world.

# This is the creator of this BO3 object
Author: Unknown

# A short description of this BO3 object
Description: This BO3 was converted from a schematic using OTGEdit. The author and description information of the schematic could not be found. If you know who the author of the schematic is then please add this information.

# The BO3 version, don't change this! It can be used by external applications to do a version check.
Version: 3

# The settings mode, WriteAll, WriteWithoutComments or WriteDisable. See WorldConfig.
SettingsMode: WriteDisable

#######################################################################
# +-----------------------------------------------------------------+ #
# |                          Main settings                          | #
# +-----------------------------------------------------------------+ #
#######################################################################

# This needs to be set to true to spawn the object in the Tree and Sapling resources.
Tree: false

# The frequency of the BO3 from 1 to 200. Tries this many times to spawn this BO3 when using the CustomObject(...) resource.
# Ignored by Tree(..), Sapling(..) and CustomStructure(..)
Frequency: 40

# The rarity of the BO3 from 0 to 100. Each spawn attempt has rarity% chance to succeed when using the CustomObject(...) resource.
# Ignored by Tree(..), Sapling(..) and CustomStructure(..)
Rarity: 100.0

# If you set this to true, the BO3 will be placed with a random rotation.
RotateRandomly: true

# The spawn height of the BO3 - randomY, highestBlock or highestSolidBlock.
SpawnHeight: randomY

# The height limits for the BO3.
MinHeight: 92

MaxHeight: 256

# Objects can have other objects attached to it: branches. Branches can also
# have branches attached to it, which can also have branches, etc. This is the
# maximum branch depth for this objects.
MaxBranchDepth: 10

# When spawned with the UseWorld keyword, this BO3 should NOT spawn in the following biomes.
# If you writer.write the BO3 name directly in the BiomeConfigs, this will be ignored.
ExcludedBiomes: All

# To optimise this BO3 for faster loading times you can use Notepad++ to find/replace comments and abbreviate things.
# Notepad++ find/replace with regex:
# Find: ^[#;].* replace to nothing removes all lines starting with # 
# Find: ^\s*$ replace to nothing removes most empty lines 
# Notepad++ find/replace without regex:
# *Warning: This will only work for OTG 1.10.2 v21 / OTG 1.11.2 v6 or higher. B( is not recognised by lower versions.
# Find: Block( replace to B(

#######################################################################
# +-----------------------------------------------------------------+ #
# |                      Source block settings                      | #
# +-----------------------------------------------------------------+ #
#######################################################################

# The block(s) the BO3 should spawn in.
SourceBlocks: AIR

# The maximum percentage of the BO3 that can be outside the SourceBlock.
# The BO3 won't be placed on a location with more blocks outside the SourceBlock than this percentage.
MaxPercentageOutsideSourceBlock: 100

# What to do when a block is about to be placed outside the SourceBlock? (dontPlace, placeAnyway)
OutsideSourceBlock: placeAnyway

#######################################################################
# +-----------------------------------------------------------------+ #
# |                              Blocks                             | #
# +-----------------------------------------------------------------+ #
#######################################################################

# All the blocks used in the BO3 are listed here. Possible blocks:
# Block(x,y,z,id[.data][,nbtfile.nbt) or B(x,y,z,id[.data][,nbtfile.nbt)
# RandomBlock(x,y,z,id[:data][,nbtfile.nbt],chance[,id[:data][,nbtfile.nbt],chance[,...]])
# So RandomBlock(0,0,0,CHEST,chest.nbt,50,CHEST,anotherchest.nbt,100) will spawn a chest at
# the BO3 origin, and give it a 50% chance to have the contents of chest.nbt, or, if that
# fails, a 100% percent chance to have the contents of anotherchest.nbt.

Block(-32,38,8,161:1)
Block(-32,39,8,161:1)
Block(-32,40,8,161:1)
Block(-32,41,8,161:1)
Block(-32,43,8,161:1)
Block(-32,44,8,161:1)
Block(-32,45,6,162:12)
Block(-32,45,8,161:1)
Block(-32,46,5,162:12)
Block(-32,46,6,162:12)
Block(-32,46,7,162:12)
Block(-32,46,8,161:1)
Block(-32,47,6,162:12)
Block(-31,45,6,162:12)
Block(-31,45,7,162:12)
Block(-31,46,6,162:12)
Block(-31,46,7,162:12)
Block(-31,46,8,162:12)
Block(-31,46,9,162:12)
Block(-31,47,6,161:1)
Block(-31,48,6,161:1)
Block(-30,37,16,161:1)
Block(-30,38,16,161:1)
Block(-30,39,16,161:1)
Block(-30,40,16,161:1)
Block(-30,41,16,161:1)
Block(-30,42,16,161:1)
Block(-30,43,16,161:1)
Block(-30,44,17,161:1)
Block(-30,45,8,162:12)
Block(-30,45,16,161:1)
Block(-30,45,17,161:1)
Block(-30,45,18,162:12)
Block(-30,46,6,162:12)
Block(-30,46,7,162:12)
Block(-30,46,8,162:12)
Block(-30,46,9,162:12)
Block(-30,46,16,162:12)
Block(-30,46,17,162:12)
Block(-30,46,18,162:12)
Block(-30,46,19,162:12)
Block(-30,46,20,162:12)
Block(-30,47,7,161:1)
Block(-30,47,8,162:12)
Block(-30,47,18,161:1)
Block(-30,47,20,161:1)
Block(-29,44,16,161:1)
Block(-29,45,8,162:12)
Block(-29,45,9,162:12)
Block(-29,45,10,162:12)
Block(-29,45,13,162:12)
Block(-29,45,14,162:12)
Block(-29,45,15,162:12)
Block(-29,45,16,162:12)
Block(-29,45,17,162:12)
Block(-29,45,18,162:12)
Block(-29,46,7,162:12)
Block(-29,46,8,162:12)
Block(-29,46,9,162:12)
Block(-29,46,10,162:12)
Block(-29,46,11,162:12)
Block(-29,46,15,162:12)
Block(-29,46,16,162:12)
Block(-29,46,17,162:12)
Block(-29,46,18,162:12)
Block(-29,46,19,162:12)
Block(-29,47,8,162:12)
Block(-29,47,9,162:12)
Block(-29,47,10,162:12)
Block(-29,47,16,162:12)
Block(-29,47,18,161:1)
Block(-29,48,8,161:1)
Block(-28,44,8,162:12)
Block(-28,44,10,162:12)
Block(-28,45,7,162:12)
Block(-28,45,8,162:12)
Block(-28,45,9,162:12)
Block(-28,45,10,162:12)
Block(-28,45,11,162:12)
Block(-28,45,12,162:12)
Block(-28,45,13,162:12)
Block(-28,45,14,162:12)
Block(-28,45,16,162:12)
Block(-28,45,18,161:1)
Block(-28,46,7,162:12)
Block(-28,46,8,162:12)
Block(-28,46,9,162:12)
Block(-28,46,10,162:12)
Block(-28,46,11,162:12)
Block(-28,46,12,162:12)
Block(-28,46,13,162:12)
Block(-28,46,14,162:12)
Block(-28,46,15,162:12)
Block(-28,46,16,162:12)
Block(-28,46,18,161:1)
Block(-28,47,7,162:12)
Block(-28,47,8,162:12)
Block(-28,47,9,162:12)
Block(-28,47,10,162:12)
Block(-28,47,13,162:12)
Block(-28,47,14,162:12)
Block(-28,47,15,162:12)
Block(-28,47,16,161:1)
Block(-28,48,8,161:1)
Block(-28,48,9,162:12)
Block(-28,48,13,161:1)
Block(-28,48,15,161:1)
Block(-27,40,16,161:1)
Block(-27,41,16,161:1)
Block(-27,42,16,161:1)
Block(-27,43,16,161:1)
Block(-27,44,7,162:12)
Block(-27,44,8,162:12)
Block(-27,44,9,162:12)
Block(-27,44,11,162:12)
Block(-27,44,16,161:1)
Block(-27,45,7,162:12)
Block(-27,45,8,162:12)
Block(-27,45,9,162:12)
Block(-27,45,10,162:12)
Block(-27,45,11,162:12)
Block(-27,45,12,162:12)
Block(-27,45,13,162:12)
Block(-27,45,16,161:1)
Block(-27,46,7,162:12)
Block(-27,46,8,162:12)
Block(-27,46,9,162:12)
Block(-27,46,10,162:12)
Block(-27,46,11,162:12)
Block(-27,46,12,162:12)
Block(-27,46,13,162:12)
Block(-27,46,14,162:12)
Block(-27,46,16,161:1)
Block(-27,47,8,162:12)
Block(-27,47,9,162:12)
Block(-27,47,10,162:12)
Block(-27,47,11,162:12)
Block(-27,47,12,162:12)
Block(-27,47,13,161:1)
Block(-27,47,16,161:1)
Block(-27,48,8,161:1)
Block(-27,48,9,162:12)
Block(-27,48,12,161:1)
Block(-26,38,13,161:1)
Block(-26,39,13,161:1)
Block(-26,40,13,161:1)
Block(-26,41,13,161:1)
Block(-26,42,13,161:1)
Block(-26,43,8,162:12)
Block(-26,43,13,161:1)
Block(-26,44,7,162:12)
Block(-26,44,8,162:12)
Block(-26,44,9,162:12)
Block(-26,44,10,162:12)
Block(-26,44,13,161:1)
Block(-26,45,7,162:12)
Block(-26,45,8,162:12)
Block(-26,45,9,162:12)
Block(-26,45,10,162:12)
Block(-26,45,11,162:12)
Block(-26,45,13,161:1)
Block(-26,46,7,162:12)
Block(-26,46,8,162:12)
Block(-26,46,9,162:12)
Block(-26,46,10,162:12)
Block(-26,46,11,162:12)
Block(-26,46,12,162:12)
Block(-26,46,13,161:1)
Block(-26,47,7,162:12)
Block(-26,47,8,162:12)
Block(-26,47,9,162:12)
Block(-26,47,10,162:12)
Block(-26,47,11,161:1)
Block(-26,48,8,161:1)
Block(-25,43,7,162:12)
Block(-25,43,8,162:12)
Block(-25,44,6,162:12)
Block(-25,44,7,162:12)
Block(-25,44,8,162:12)
Block(-25,44,9,162:12)
Block(-25,45,6,162:12)
Block(-25,45,7,162:12)
Block(-25,45,8,162:12)
Block(-25,45,9,162:12)
Block(-25,45,10,162:12)
Block(-25,46,7,162:12)
Block(-25,46,8,162:12)
Block(-25,46,9,162:12)
Block(-25,46,10,162:12)
Block(-25,47,8,162:12)
Block(-25,47,9,162:12)
Block(-25,47,10,161:1)
Block(-25,48,8,161:1)
Block(-24,38,8,161:1)
Block(-24,39,8,161:1)
Block(-24,40,8,161:1)
Block(-24,41,8,161:1)
Block(-24,42,8,161:1)
Block(-24,43,7,162:12)
Block(-24,43,8,161:1)
Block(-24,44,5,162:12)
Block(-24,44,6,162:12)
Block(-24,44,7,162:12)
Block(-24,44,8,162:12)
Block(-24,45,5,162:12)
Block(-24,45,6,162:12)
Block(-24,45,7,162:12)
Block(-24,45,8,162:12)
Block(-24,45,9,162:12)
Block(-24,46,6,162:12)
Block(-24,46,7,162:12)
Block(-24,46,8,162:12)
Block(-24,46,9,162:12)
Block(-24,47,6,161:1)
Block(-24,47,9,161:1)
Block(-24,47,10,161:1)
Block(-24,48,-20,161:1)
Block(-24,48,-19,161:1)
Block(-24,49,-20,161:1)
Block(-24,49,-19,161:1)
Block(-23,43,7,162:12)
Block(-23,44,5,162:12)
Block(-23,44,6,162:12)
Block(-23,44,7,162:12)
Block(-23,44,8,162:12)
Block(-23,45,5,162:12)
Block(-23,45,6,162:12)
Block(-23,45,7,162:12)
Block(-23,45,8,162:12)
Block(-23,46,-18,161:1)
Block(-23,46,6,162:12)
Block(-23,46,7,162:12)
Block(-23,46,8,161:1)
Block(-23,47,-20,161:1)
Block(-23,47,-19,161:1)
Block(-23,47,-18,161:1)
Block(-23,48,-20,162:12)
Block(-23,48,-19,161:1)
Block(-23,48,-18,161:1)
Block(-23,49,-20,162:12)
Block(-23,49,-19,162:12)
Block(-23,49,-18,161:1)
Block(-23,50,-20,161:1)
Block(-23,50,-19,161:1)
Block(-22,34,5,161:1)
Block(-22,35,5,161:1)
Block(-22,36,5,161:1)
Block(-22,37,5,161:1)
Block(-22,38,5,161:1)
Block(-22,39,5,161:1)
Block(-22,40,5,161:1)
Block(-22,41,5,161:1)
Block(-22,42,5,161:1)
Block(-22,42,6,162:12)
Block(-22,43,5,162:12)
Block(-22,43,6,162:12)
Block(-22,43,7,162:12)
Block(-22,44,5,162:12)
Block(-22,44,6,162:12)
Block(-22,44,7,162:12)
Block(-22,45,5,162:12)
Block(-22,45,6,162:12)
Block(-22,45,7,162:12)
Block(-22,45,8,162:12)
Block(-22,46,5,161:1)
Block(-22,46,6,162:12)
Block(-22,46,7,162:12)
Block(-22,47,-20,162:12)
Block(-22,48,-21,162:12)
Block(-22,48,-20,162:12)
Block(-22,48,-19,162:12)
Block(-22,49,-21,162:12)
Block(-22,49,-20,162:12)
Block(-22,49,-19,162:12)
Block(-22,49,-18,162:12)
Block(-22,50,-21,161:1)
Block(-22,50,-20,162:12)
Block(-22,50,-19,162:12)
Block(-22,50,-18,161:1)
Block(-22,51,-21,161:1)
Block(-22,51,-20,161:1)
Block(-22,51,-19,161:1)
Block(-21,41,5,161:1)
Block(-21,41,6,162:12)
Block(-21,42,5,162:12)
Block(-21,42,6,162:12)
Block(-21,43,-23,161:1)
Block(-21,43,4,162:12)
Block(-21,43,5,162:12)
Block(-21,43,6,162:12)
Block(-21,44,-23,161:1)
Block(-21,44,5,162:12)
Block(-21,44,6,162:12)
Block(-21,44,7,162:12)
Block(-21,45,-23,161:1)
Block(-21,45,6,162:12)
Block(-21,45,7,162:12)
Block(-21,45,8,162:12)
Block(-21,46,-23,161:1)
Block(-21,46,7,161:1)
Block(-21,47,-23,161:1)
Block(-21,47,-22,162:12)
Block(-21,47,-21,162:12)
Block(-21,48,-23,161:1)
Block(-21,48,-22,162:12)
Block(-21,48,-21,162:12)
Block(-21,48,-20,162:12)
Block(-21,49,-23,161:1)
Block(-21,49,-22,161:1)
Block(-21,49,-21,162:12)
Block(-21,49,-20,162:12)
Block(-21,49,-19,162:12)
Block(-21,50,-21,161:1)
Block(-21,50,-20,161:1)
Block(-21,50,-19,161:1)
Block(-20,40,4,162:12)
Block(-20,40,5,162:12)
Block(-20,40,6,162:12)
Block(-20,41,5,162:12)
Block(-20,41,6,162:12)
Block(-20,42,4,162:12)
Block(-20,42,5,162:12)
Block(-20,42,6,162:12)
Block(-20,43,4,162:12)
Block(-20,43,5,162:12)
Block(-20,43,6,162:12)
Block(-20,43,7,162:12)
Block(-20,44,5,162:12)
Block(-20,44,6,162:12)
Block(-20,44,7,162:12)
Block(-20,45,7,161:1)
Block(-20,46,-22,162:12)
Block(-20,47,-23,162:12)
Block(-20,47,-22,162:12)
Block(-20,47,-21,161:1)
Block(-20,48,-23,162:12)
Block(-20,48,-22,162:12)
Block(-20,48,-21,162:12)
Block(-20,48,-20,162:12)
Block(-20,49,-23,161:1)
Block(-20,49,-22,162:12)
Block(-20,49,-21,162:12)
Block(-20,49,-20,161:1)
Block(-20,50,-22,161:1)
Block(-20,50,-21,161:1)
Block(-19,37,-28,161:1)
Block(-19,38,-28,161:1)
Block(-19,38,4,162:12)
Block(-19,38,5,162:12)
Block(-19,39,-28,161:1)
Block(-19,39,4,162:12)
Block(-19,39,5,162:12)
Block(-19,39,6,162:12)
Block(-19,40,-28,161:1)
Block(-19,40,3,162:12)
Block(-19,40,4,162:12)
Block(-19,40,5,162:12)
Block(-19,40,6,162:12)
Block(-19,40,7,162:12)
Block(-19,41,3,162:12)
Block(-19,41,4,162:12)
Block(-19,41,5,162:12)
Block(-19,41,6,162:12)
Block(-19,42,4,162:12)
Block(-19,42,5,162:12)
Block(-19,42,6,162:12)
Block(-19,42,7,162:12)
Block(-19,43,5,162:12)
Block(-19,43,6,162:12)
Block(-19,43,7,161:1)
Block(-19,46,-23,162:12)
Block(-19,46,-22,162:12)
Block(-19,47,-23,162:12)
Block(-19,47,-22,162:12)
Block(-19,47,-21,161:1)
Block(-19,48,-23,161:1)
Block(-19,48,-22,161:1)
Block(-19,48,-21,161:1)
Block(-19,49,-22,161:1)
Block(-18,35,-9,161:1)
Block(-18,36,-9,161:1)
Block(-18,36,2,162:12)
Block(-18,37,-9,161:1)
Block(-18,37,2,162:12)
Block(-18,37,3,162:12)
Block(-18,37,4,162:12)
Block(-18,38,2,162:12)
Block(-18,38,3,162:12)
Block(-18,38,4,162:12)
Block(-18,38,5,162:12)
Block(-18,39,3,162:12)
Block(-18,39,4,162:12)
Block(-18,39,5,162:12)
Block(-18,39,6,162:12)
Block(-18,40,3,162:12)
Block(-18,40,4,162:12)
Block(-18,40,5,162:12)
Block(-18,40,6,162:12)
Block(-18,40,7,162:12)
Block(-18,41,-28,161:1)
Block(-18,41,3,162:12)
Block(-18,41,4,162:12)
Block(-18,41,5,162:12)
Block(-18,41,6,162:12)
Block(-18,41,7,162:12)
Block(-18,42,-28,161:1)
Block(-18,42,4,162:12)
Block(-18,42,5,162:12)
Block(-18,42,6,162:12)
Block(-18,42,7,161:1)
Block(-18,43,-28,161:1)
Block(-18,44,-28,161:1)
Block(-18,45,-28,161:1)
Block(-18,46,-24,162:12)
Block(-18,46,-23,162:12)
Block(-18,46,-22,162:12)
Block(-18,47,-25,162:12)
Block(-18,47,-24,162:12)
Block(-18,47,-23,162:12)
Block(-18,47,-22,161:1)
Block(-18,48,-23,161:1)
Block(-18,49,-23,161:1)
Block(-17,36,1,162:12)
Block(-17,36,2,162:12)
Block(-17,36,3,162:12)
Block(-17,37,0,162:12)
Block(-17,37,1,162:12)
Block(-17,37,2,162:12)
Block(-17,37,3,162:12)
Block(-17,37,4,162:12)
Block(-17,38,-9,161:1)
Block(-17,38,1,162:12)
Block(-17,38,2,162:12)
Block(-17,38,3,162:12)
Block(-17,38,4,162:12)
Block(-17,38,5,162:12)
Block(-17,39,-9,161:1)
Block(-17,39,2,162:12)
Block(-17,39,3,162:12)
Block(-17,39,4,162:12)
Block(-17,39,5,162:12)
Block(-17,39,6,162:12)
Block(-17,40,-9,161:1)
Block(-17,40,3,162:12)
Block(-17,40,4,162:12)
Block(-17,40,5,162:12)
Block(-17,40,6,162:12)
Block(-17,40,7,162:12)
Block(-17,41,-22,161:1)
Block(-17,41,-9,161:1)
Block(-17,41,4,162:12)
Block(-17,41,5,162:12)
Block(-17,41,6,162:12)
Block(-17,42,-22,161:1)
Block(-17,42,6,161:1)
Block(-17,43,-22,161:1)
Block(-17,43,27,161:1)
Block(-17,44,-22,161:1)
Block(-17,44,27,161:1)
Block(-17,45,-28,162:12)
Block(-17,45,-27,162:12)
Block(-17,45,-26,162:12)
Block(-17,45,-25,162:12)
Block(-17,45,-22,161:1)
Block(-17,45,27,161:1)
Block(-17,46,-28,161:1)
Block(-17,46,-27,162:12)
Block(-17,46,-26,162:12)
Block(-17,46,-25,162:12)
Block(-17,46,-24,162:12)
Block(-17,46,-23,162:12)
Block(-17,46,-22,161:1)
Block(-17,46,27,161:1)
Block(-17,46,28,162:12)
Block(-17,47,-27,162:12)
Block(-17,47,-26,162:12)
Block(-17,47,-25,162:12)
Block(-17,47,-24,162:12)
Block(-17,47,-23,161:1)
Block(-17,47,27,161:1)
Block(-17,47,28,161:1)
Block(-17,48,-25,162:12)
Block(-17,48,-24,162:12)
Block(-17,49,-25,161:1)
Block(-17,49,-24,161:1)
Block(-16,35,0,162:12)
Block(-16,35,1,162:12)
Block(-16,35,2,162:12)
Block(-16,35,3,162:12)
Block(-16,36,0,162:12)
Block(-16,36,1,162:12)
Block(-16,36,2,162:12)
Block(-16,36,3,162:12)
Block(-16,36,4,162:12)
Block(-16,37,0,162:12)
Block(-16,37,1,162:12)
Block(-16,37,2,162:12)
Block(-16,37,3,162:12)
Block(-16,37,4,162:12)
Block(-16,37,5,162:12)
Block(-16,38,0,162:12)
Block(-16,38,1,162:12)
Block(-16,38,2,162:12)
Block(-16,38,3,162:12)
Block(-16,38,4,162:12)
Block(-16,38,5,162:12)
Block(-16,38,6,162:12)
Block(-16,39,2,162:12)
Block(-16,39,3,162:12)
Block(-16,39,4,162:12)
Block(-16,39,5,162:12)
Block(-16,39,6,162:12)
Block(-16,39,7,162:12)
Block(-16,40,3,162:12)
Block(-16,40,4,162:12)
Block(-16,40,5,162:12)
Block(-16,40,6,162:12)
Block(-16,41,-9,162:12)
Block(-16,41,6,161:1)
Block(-16,41,23,161:1)
Block(-16,42,-9,161:1)
Block(-16,42,23,161:1)
Block(-16,43,23,161:1)
Block(-16,43,24,161:1)
Block(-16,43,25,161:1)
Block(-16,44,-27,162:12)
Block(-16,44,-26,162:12)
Block(-16,44,25,161:1)
Block(-16,45,-29,162:12)
Block(-16,45,-28,162:12)
Block(-16,45,-27,162:12)
Block(-16,45,-26,162:12)
Block(-16,45,-25,162:12)
Block(-16,45,-24,162:12)
Block(-16,45,27,162:12)
Block(-16,45,28,162:12)
Block(-16,46,-29,30)
Block(-16,46,-28,162:12)
Block(-16,46,-27,162:12)
Block(-16,46,-26,162:12)
Block(-16,46,-25,162:12)
Block(-16,46,-24,162:12)
Block(-16,46,-23,162:12)
Block(-16,46,27,162:12)
Block(-16,46,28,162:12)
Block(-16,47,-30,162:12)
Block(-16,47,-29,162:12)
Block(-16,47,-28,162:12)
Block(-16,47,-27,162:12)
Block(-16,47,-26,162:12)
Block(-16,47,-25,162:12)
Block(-16,47,-24,162:12)
Block(-16,47,-23,161:1)
Block(-16,48,-31,162:12)
Block(-16,48,-30,162:12)
Block(-16,48,-29,162:12)
Block(-16,48,-27,162:12)
Block(-16,48,-26,162:12)
Block(-16,48,-25,162:12)
Block(-16,48,-24,161:1)
Block(-16,49,-31,162:12)
Block(-16,49,-30,161:1)
Block(-16,49,-25,161:1)
Block(-16,50,-31,161:1)
Block(-15,34,0,162:12)
Block(-15,34,1,162:12)
Block(-15,34,2,30)
Block(-15,35,-1,162:12)
Block(-15,35,0,162:12)
Block(-15,35,1,162:12)
Block(-15,35,2,162:12)
Block(-15,35,3,162:12)
Block(-15,36,-1,162:12)
Block(-15,36,0,162:12)
Block(-15,36,1,162:12)
Block(-15,36,2,162:12)
Block(-15,36,3,162:12)
Block(-15,36,4,162:12)
Block(-15,36,5,162:12)
Block(-15,37,0,162:12)
Block(-15,37,1,162:12)
Block(-15,37,2,162:12)
Block(-15,37,3,162:12)
Block(-15,37,4,162:12)
Block(-15,37,5,162:12)
Block(-15,38,1,162:12)
Block(-15,38,2,162:12)
Block(-15,38,3,162:12)
Block(-15,38,4,162:12)
Block(-15,38,5,162:12)
Block(-15,38,6,162:12)
Block(-15,39,3,162:12)
Block(-15,39,4,162:12)
Block(-15,39,5,162:12)
Block(-15,39,6,162:12)
Block(-15,40,-9,162:12)
Block(-15,40,4,162:12)
Block(-15,40,5,162:12)
Block(-15,40,6,161:1)
Block(-15,41,-9,162:12)
Block(-15,41,-8,162:12)
Block(-15,42,-9,161:1)
Block(-15,43,24,162:12)
Block(-15,43,25,162:12)
Block(-15,43,26,162:12)
Block(-15,44,-26,162:12)
Block(-15,44,-25,162:12)
Block(-15,44,24,161:1)
Block(-15,44,25,162:12)
Block(-15,44,26,162:12)
Block(-15,44,27,162:12)
Block(-15,45,-29,162:12)
Block(-15,45,-28,162:12)
Block(-15,45,-27,162:12)
Block(-15,45,-26,162:12)
Block(-15,45,-25,162:12)
Block(-15,45,-24,162:12)
Block(-15,45,-23,162:12)
Block(-15,45,26,162:12)
Block(-15,45,27,162:12)
Block(-15,45,28,162:12)
Block(-15,46,-30,162:12)
Block(-15,46,-29,30)
Block(-15,46,-28,162:12)
Block(-15,46,-27,162:12)
Block(-15,46,-26,162:12)
Block(-15,46,-25,162:12)
Block(-15,46,-24,162:12)
Block(-15,46,-23,162:12)
Block(-15,46,27,162:12)
Block(-15,47,-31,162:12)
Block(-15,47,-30,162:12)
Block(-15,47,-29,162:12)
Block(-15,47,-28,162:12)
Block(-15,47,-27,162:12)
Block(-15,47,-26,162:12)
Block(-15,47,-25,162:12)
Block(-15,47,-24,162:12)
Block(-15,48,-32,162:12)
Block(-15,48,-31,162:12)
Block(-15,48,-30,162:12)
Block(-15,48,-29,161:1)
Block(-15,48,-28,162:12)
Block(-15,48,-27,162:12)
Block(-15,48,-26,162:12)
Block(-15,48,-25,162:12)
Block(-15,48,-24,161:1)
Block(-15,49,-33,162:12)
Block(-15,49,-32,162:12)
Block(-15,49,-31,162:12)
Block(-15,49,-30,162:12)
Block(-15,49,-28,161:1)
Block(-15,49,-25,161:1)
Block(-15,50,-33,161:1)
Block(-15,50,-32,161:1)
Block(-15,50,-31,162:12)
Block(-15,50,-30,161:1)
Block(-15,51,-31,161:1)
Block(-14,28,3,161:1)
Block(-14,29,3,161:1)
Block(-14,30,3,161:1)
Block(-14,31,3,161:1)
Block(-14,32,3,161:1)
Block(-14,33,-1,162:12)
Block(-14,33,0,162:12)
Block(-14,33,1,162:12)
Block(-14,33,3,161:1)
Block(-14,34,-1,162:12)
Block(-14,34,0,162:12)
Block(-14,34,1,162:12)
Block(-14,34,2,162:12)
Block(-14,34,3,161:1)
Block(-14,35,-1,162:12)
Block(-14,35,0,162:12)
Block(-14,35,1,162:12)
Block(-14,35,2,162:12)
Block(-14,35,3,161:1)
Block(-14,36,0,162:12)
Block(-14,36,1,162:12)
Block(-14,36,2,162:12)
Block(-14,36,3,162:12)
Block(-14,36,4,162:12)
Block(-14,37,2,162:12)
Block(-14,37,3,162:12)
Block(-14,37,4,162:12)
Block(-14,38,3,162:12)
Block(-14,38,4,162:12)
Block(-14,38,20,161:1)
Block(-14,39,6,161:1)
Block(-14,39,20,161:1)
Block(-14,40,-9,162:12)
Block(-14,40,20,161:1)
Block(-14,40,21,161:1)
Block(-14,41,-9,162:12)
Block(-14,41,-8,161:1)
Block(-14,41,20,161:1)
Block(-14,42,-29,161:1)
Block(-14,42,-9,161:1)
Block(-14,42,23,162:12)
Block(-14,42,24,162:12)
Block(-14,43,-29,161:1)
Block(-14,43,23,161:1)
Block(-14,43,24,162:12)
Block(-14,43,25,162:12)
Block(-14,44,-29,161:1)
Block(-14,44,-25,162:12)
Block(-14,44,-24,162:12)
Block(-14,44,-23,161:1)
Block(-14,44,-22,161:1)
Block(-14,44,-21,161:1)
Block(-14,44,24,162:12)
Block(-14,44,25,162:12)
Block(-14,44,26,162:12)
Block(-14,45,-29,161:1)
Block(-14,45,-28,162:12)
Block(-14,45,-27,162:12)
Block(-14,45,-26,162:12)
Block(-14,45,-25,162:12)
Block(-14,45,-24,162:12)
Block(-14,45,-23,162:12)
Block(-14,45,-22,162:12)
Block(-14,45,-20,161:1)
Block(-14,45,26,162:12)
Block(-14,45,27,162:12)
Block(-14,46,-35,161:1)
Block(-14,46,-30,161:1)
Block(-14,46,-29,162:12)
Block(-14,46,-28,162:12)
Block(-14,46,-27,162:12)
Block(-14,46,-26,162:12)
Block(-14,46,-25,162:12)
Block(-14,46,-24,162:12)
Block(-14,46,-23,162:12)
Block(-14,46,-22,162:12)
Block(-14,47,-35,161:1)
Block(-14,47,-30,161:1)
Block(-14,47,-29,162:12)
Block(-14,47,-28,162:12)
Block(-14,47,-27,162:12)
Block(-14,47,-26,162:12)
Block(-14,47,-25,162:12)
Block(-14,47,-24,162:12)
Block(-14,47,-23,162:12)
Block(-14,47,-22,161:1)
Block(-14,48,-35,161:1)
Block(-14,48,-33,162:12)
Block(-14,48,-32,162:12)
Block(-14,48,-31,162:12)
Block(-14,48,-30,161:1)
Block(-14,48,-29,161:1)
Block(-14,48,-28,161:1)
Block(-14,48,-27,161:1)
Block(-14,48,-26,162:12)
Block(-14,48,-25,162:12)
Block(-14,48,-24,161:1)
Block(-14,49,-35,161:1)
Block(-14,49,-34,162:12)
Block(-14,49,-33,162:12)
Block(-14,49,-32,162:12)
Block(-14,49,-31,162:12)
Block(-14,49,-30,162:12)
Block(-14,50,-34,161:1)
Block(-14,50,-33,162:12)
Block(-14,50,-32,162:12)
Block(-14,50,-31,162:12)
Block(-14,50,-30,161:1)
Block(-14,51,-33,161:1)
Block(-14,51,-32,161:1)
Block(-14,51,-31,161:1)
Block(-13,0,5,162:12)
Block(-13,0,15,162:12)
Block(-13,1,5,162:12)
Block(-13,23,-2,161:1)
Block(-13,23,2,161:1)
Block(-13,24,-2,161:1)
Block(-13,24,2,161:1)
Block(-13,25,-2,161:1)
Block(-13,25,2,161:1)
Block(-13,26,-2,161:1)
Block(-13,27,-2,161:1)
Block(-13,28,-2,161:1)
Block(-13,29,-2,161:1)
Block(-13,30,-2,161:1)
Block(-13,30,-1,162:12)
Block(-13,30,0,162:12)
Block(-13,31,-2,161:1)
Block(-13,31,-1,162:12)
Block(-13,31,0,162:12)
Block(-13,31,1,162:12)
Block(-13,32,-1,162:12)
Block(-13,32,0,162:12)
Block(-13,32,1,162:12)
Block(-13,33,-2,162:12)
Block(-13,33,-1,162:12)
Block(-13,33,0,162:12)
Block(-13,33,1,162:12)
Block(-13,33,2,162:12)
Block(-13,34,-1,162:12)
Block(-13,34,0,162:12)
Block(-13,34,1,162:12)
Block(-13,34,2,162:12)
Block(-13,35,0,162:12)
Block(-13,35,1,162:12)
Block(-13,39,21,161:1)
Block(-13,40,-10,162:12)
Block(-13,40,-9,161:1)
Block(-13,40,20,162:12)
Block(-13,40,21,162:12)
Block(-13,40,22,162:12)
Block(-13,41,-10,162:12)
Block(-13,41,-9,161:1)
Block(-13,41,20,161:1)
Block(-13,41,21,162:12)
Block(-13,41,22,162:12)
Block(-13,41,23,162:12)
Block(-13,42,-19,161:1)
Block(-13,42,-10,161:1)
Block(-13,42,21,161:1)
Block(-13,42,22,162:12)
Block(-13,42,23,162:12)
Block(-13,42,24,162:12)
Block(-13,43,-24,161:1)
Block(-13,43,-23,161:1)
Block(-13,43,-19,161:1)
Block(-13,43,23,161:1)
Block(-13,43,24,162:12)
Block(-13,43,25,162:12)
Block(-13,44,-25,162:12)
Block(-13,44,-24,162:12)
Block(-13,44,-23,162:12)
Block(-13,44,-22,162:12)
Block(-13,44,-21,162:12)
Block(-13,44,-19,161:1)
Block(-13,44,25,30)
Block(-13,45,-27,162:12)
Block(-13,45,-26,162:12)
Block(-13,45,-25,162:12)
Block(-13,45,-24,162:12)
Block(-13,45,-23,162:12)
Block(-13,45,-22,162:12)
Block(-13,45,-21,162:12)
Block(-13,45,-20,162:12)
Block(-13,45,-19,161:1)
Block(-13,46,-29,161:1)
Block(-13,46,-27,162:12)
Block(-13,46,-26,162:12)
Block(-13,46,-25,162:12)
Block(-13,46,-24,162:12)
Block(-13,46,-23,162:12)
Block(-13,46,-22,162:12)
Block(-13,46,-21,162:12)
Block(-13,46,-20,161:1)
Block(-13,47,-29,162:12)
Block(-13,47,-27,161:1)
Block(-13,47,-26,162:12)
Block(-13,47,-25,162:12)
Block(-13,47,-24,162:12)
Block(-13,47,-23,162:12)
Block(-13,47,-22,162:12)
Block(-13,48,-33,162:12)
Block(-13,48,-24,161:1)
Block(-13,48,-23,161:1)
Block(-13,49,-34,162:12)
Block(-13,49,-33,162:12)
Block(-13,49,-32,162:12)
Block(-13,49,-31,162:12)
Block(-13,50,-34,162:12)
Block(-13,50,-33,162:12)
Block(-13,50,-32,162:12)
Block(-13,50,-31,161:1)
Block(-13,51,-34,161:1)
Block(-13,51,-33,162:12)
Block(-13,51,-32,161:1)
Block(-13,52,-33,161:1)
Block(-12,0,3,162:12)
Block(-12,0,4,162:12)
Block(-12,0,5,162:12)
Block(-12,0,6,162:12)
Block(-12,0,13,162:12)
Block(-12,0,14,162:12)
Block(-12,0,15,162:12)
Block(-12,0,16,162:12)
Block(-12,1,3,162:12)
Block(-12,1,4,162:12)
Block(-12,1,5,162:12)
Block(-12,1,6,162:12)
Block(-12,1,13,162:12)
Block(-12,1,14,162:12)
Block(-12,1,15,162:12)
Block(-12,2,4,162:12)
Block(-12,2,5,162:12)
Block(-12,2,6,162:12)
Block(-12,2,14,162:12)
Block(-12,3,5,162:12)
Block(-12,3,6,162:12)
Block(-12,17,8,161:1)
Block(-12,18,8,161:1)
Block(-12,26,2,161:1)
Block(-12,27,2,161:1)
Block(-12,28,2,161:1)
Block(-12,29,-2,162:12)
Block(-12,29,-1,162:12)
Block(-12,29,0,162:12)
Block(-12,29,2,161:1)
Block(-12,30,-2,162:12)
Block(-12,30,-1,162:12)
Block(-12,30,0,162:12)
Block(-12,30,1,162:12)
Block(-12,31,-2,162:12)
Block(-12,31,-1,162:12)
Block(-12,31,0,162:12)
Block(-12,31,1,162:12)
Block(-12,32,-2,162:12)
Block(-12,32,-1,162:12)
Block(-12,32,0,162:12)
Block(-12,32,1,162:12)
Block(-12,32,2,162:12)
Block(-12,33,-2,162:12)
Block(-12,33,-1,162:12)
Block(-12,33,0,162:12)
Block(-12,33,1,162:12)
Block(-12,33,2,162:12)
Block(-12,34,-1,162:12)
Block(-12,34,0,162:12)
Block(-12,34,1,162:12)
Block(-12,35,0,162:12)
Block(-12,39,20,162:12)
Block(-12,39,21,162:12)
Block(-12,40,-10,162:12)
Block(-12,40,-9,162:12)
Block(-12,40,19,162:12)
Block(-12,40,20,162:12)
Block(-12,40,21,162:12)
Block(-12,40,22,162:12)
Block(-12,40,23,162:12)
Block(-12,41,-10,162:12)
Block(-12,41,-9,161:1)
Block(-12,41,20,162:12)
Block(-12,41,21,162:12)
Block(-12,41,22,162:12)
Block(-12,41,23,162:12)
Block(-12,42,-27,161:1)
Block(-12,42,21,162:12)
Block(-12,42,22,162:12)
Block(-12,42,23,30)
Block(-12,43,-27,161:1)
Block(-12,43,-23,161:1)
Block(-12,43,22,161:1)
Block(-12,44,-27,161:1)
Block(-12,44,-24,162:12)
Block(-12,44,-23,162:12)
Block(-12,44,-22,162:12)
Block(-12,44,-21,162:12)
Block(-12,44,-19,162:12)
Block(-12,44,-18,162:12)
Block(-12,45,-27,161:1)
Block(-12,45,-26,162:12)
Block(-12,45,-25,162:12)
Block(-12,45,-24,162:12)
Block(-12,45,-23,162:12)
Block(-12,45,-22,162:12)
Block(-12,45,-21,162:12)
Block(-12,45,-20,162:12)
Block(-12,45,-19,162:12)
Block(-12,45,-18,162:12)
Block(-12,46,-27,161:1)
Block(-12,46,-26,162:12)
Block(-12,46,-25,162:12)
Block(-12,46,-24,162:12)
Block(-12,46,-23,162:12)
Block(-12,46,-22,162:12)
Block(-12,46,-21,162:12)
Block(-12,46,-20,162:12)
Block(-12,46,-19,162:12)
Block(-12,47,-24,162:12)
Block(-12,47,-23,162:12)
Block(-12,47,-22,162:12)
Block(-12,47,-21,162:12)
Block(-12,47,-20,161:1)
Block(-12,48,-24,161:1)
Block(-12,48,-23,161:1)
Block(-12,48,-22,161:1)
Block(-12,49,-34,162:12)
Block(-12,49,-33,162:12)
Block(-12,50,-35,162:12)
Block(-12,50,-34,162:12)
Block(-12,50,-33,162:12)
Block(-12,50,-32,162:12)
Block(-12,51,-35,161:1)
Block(-12,51,-34,162:12)
Block(-12,51,-33,162:12)
Block(-12,51,-32,161:1)
Block(-12,52,-34,161:1)
Block(-12,52,-33,161:1)
Block(-11,0,2,162:12)
Block(-11,0,3,162:12)
Block(-11,0,4,162:12)
Block(-11,0,5,162:12)
Block(-11,0,6,162:12)
Block(-11,0,12,162:12)
Block(-11,0,13,162:12)
Block(-11,0,14,162:12)
Block(-11,0,15,162:12)
Block(-11,0,16,162:12)
Block(-11,0,17,162:12)
Block(-11,1,3,162:12)
Block(-11,1,4,162:12)
Block(-11,1,5,162:12)
Block(-11,1,6,162:12)
Block(-11,1,7,162:12)
Block(-11,1,12,162:12)
Block(-11,1,13,162:12)
Block(-11,1,14,162:12)
Block(-11,1,15,162:12)
Block(-11,1,16,162:12)
Block(-11,2,3,162:12)
Block(-11,2,4,162:12)
Block(-11,2,5,162:12)
Block(-11,2,6,162:12)
Block(-11,2,7,162:12)
Block(-11,2,12,162:12)
Block(-11,2,13,162:12)
Block(-11,2,14,162:12)
Block(-11,2,15,162:12)
Block(-11,3,4,162:12)
Block(-11,3,5,162:12)
Block(-11,3,6,162:12)
Block(-11,3,7,162:12)
Block(-11,3,12,162:12)
Block(-11,3,13,162:12)
Block(-11,3,14,162:12)
Block(-11,4,5,162:12)
Block(-11,4,6,162:12)
Block(-11,4,7,162:12)
Block(-11,4,11,162:12)
Block(-11,4,12,162:12)
Block(-11,5,6,162:12)
Block(-11,19,8,161:1)
Block(-11,20,8,161:1)
Block(-11,22,7,162:12)
Block(-11,22,8,161:1)
Block(-11,23,7,162:12)
Block(-11,23,8,162:12)
Block(-11,24,7,162:12)
Block(-11,24,8,162:12)
Block(-11,28,0,162:12)
Block(-11,29,-1,162:12)
Block(-11,29,0,162:12)
Block(-11,29,1,162:12)
Block(-11,29,2,162:12)
Block(-11,30,-2,162:12)
Block(-11,30,-1,162:12)
Block(-11,30,0,162:12)
Block(-11,30,1,162:12)
Block(-11,30,2,161:1)
Block(-11,31,-2,162:12)
Block(-11,31,-1,162:12)
Block(-11,31,0,162:12)
Block(-11,31,1,162:12)
Block(-11,31,2,162:12)
Block(-11,32,-2,162:12)
Block(-11,32,-1,162:12)
Block(-11,32,0,162:12)
Block(-11,32,1,162:12)
Block(-11,32,2,162:12)
Block(-11,33,-1,162:12)
Block(-11,33,0,162:12)
Block(-11,33,1,162:12)
Block(-11,34,0,162:12)
Block(-11,37,20,162:12)
Block(-11,37,21,162:12)
Block(-11,38,19,162:12)
Block(-11,38,20,162:12)
Block(-11,38,21,162:12)
Block(-11,38,24,161:1)
Block(-11,39,18,162:12)
Block(-11,39,19,162:12)
Block(-11,39,20,162:12)
Block(-11,39,21,162:12)
Block(-11,39,22,162:12)
Block(-11,39,23,161:1)
Block(-11,39,24,161:1)
Block(-11,40,-10,162:12)
Block(-11,40,-9,162:12)
Block(-11,40,19,162:12)
Block(-11,40,20,162:12)
Block(-11,40,21,162:12)
Block(-11,40,22,162:12)
Block(-11,40,23,162:12)
Block(-11,40,24,161:1)
Block(-11,41,-9,162:12)
Block(-11,41,20,162:12)
Block(-11,41,21,162:12)
Block(-11,41,22,162:12)
Block(-11,41,23,162:12)
Block(-11,42,-22,161:1)
Block(-11,42,-17,161:1)
Block(-11,42,20,161:1)
Block(-11,42,21,162:12)
Block(-11,42,22,161:1)
Block(-11,43,-23,161:1)
Block(-11,43,-22,162:12)
Block(-11,43,-21,162:12)
Block(-11,43,-19,161:1)
Block(-11,43,-18,161:1)
Block(-11,43,-17,162:12)
Block(-11,43,-16,161:1)
Block(-11,43,21,161:1)
Block(-11,44,-23,162:12)
Block(-11,44,-22,162:12)
Block(-11,44,-21,162:12)
Block(-11,44,-20,162:12)
Block(-11,44,-19,162:12)
Block(-11,44,-18,162:12)
Block(-11,44,-17,162:12)
Block(-11,44,-16,162:12)
Block(-11,45,-25,162:12)
Block(-11,45,-24,162:12)
Block(-11,45,-23,162:12)
Block(-11,45,-22,162:12)
Block(-11,45,-21,162:12)
Block(-11,45,-20,162:12)
Block(-11,45,-19,162:12)
Block(-11,45,-18,162:12)
Block(-11,45,-17,162:12)
Block(-11,46,-24,162:12)
Block(-11,46,-23,162:12)
Block(-11,46,-22,162:12)
Block(-11,46,-21,162:12)
Block(-11,46,-20,162:12)
Block(-11,46,-19,162:12)
Block(-11,46,-18,162:12)
Block(-11,47,-32,161:1)
Block(-11,47,-24,161:1)
Block(-11,47,-23,161:1)
Block(-11,47,-22,162:12)
Block(-11,47,-21,162:12)
Block(-11,47,-20,162:12)
Block(-11,47,-18,161:1)
Block(-11,48,-32,161:1)
Block(-11,48,-22,161:1)
Block(-11,48,-21,161:1)
Block(-11,48,-20,161:1)
Block(-11,49,-34,162:12)
Block(-11,49,-32,161:1)
Block(-11,50,-35,162:12)
Block(-11,50,-34,162:12)
Block(-11,50,-33,162:12)
Block(-11,50,-32,161:1)
Block(-11,51,-34,162:12)
Block(-11,51,-33,161:1)
Block(-11,52,-34,161:1)
Block(-10,0,3,162:12)
Block(-10,0,4,162:12)
Block(-10,0,5,162:12)
Block(-10,0,12,162:12)
Block(-10,0,13,162:12)
Block(-10,0,14,162:12)
Block(-10,0,15,162:12)
Block(-10,0,16,162:12)
Block(-10,1,3,162:12)
Block(-10,1,4,162:12)
Block(-10,1,5,162:12)
Block(-10,1,6,162:12)
Block(-10,1,11,162:12)
Block(-10,1,12,162:12)
Block(-10,1,13,162:12)
Block(-10,1,14,162:12)
Block(-10,1,15,162:12)
Block(-10,1,16,162:12)
Block(-10,2,3,162:12)
Block(-10,2,4,162:12)
Block(-10,2,5,162:12)
Block(-10,2,6,162:12)
Block(-10,2,7,162:12)
Block(-10,2,11,162)
Block(-10,2,12,162:12)
Block(-10,2,13,162:12)
Block(-10,2,14,162:12)
Block(-10,2,15,162:12)
Block(-10,3,4,162:12)
Block(-10,3,5,162:12)
Block(-10,3,6,162:12)
Block(-10,3,7,162:12)
Block(-10,3,8,162:12)
Block(-10,3,10,162:12)
Block(-10,3,11,162:12)
Block(-10,3,12,162:12)
Block(-10,3,13,162:12)
Block(-10,3,14,162:12)
Block(-10,4,5,162:12)
Block(-10,4,6,162:12)
Block(-10,4,7,162:12)
Block(-10,4,8,162:12)
Block(-10,4,9,162:12)
Block(-10,4,10,162:12)
Block(-10,4,11,162:12)
Block(-10,4,12,162:12)
Block(-10,4,13,162:12)
Block(-10,5,6,162:12)
Block(-10,5,7,162:12)
Block(-10,5,8,162:12)
Block(-10,5,9,162:12)
Block(-10,5,10,162:12)
Block(-10,5,11,162:12)
Block(-10,5,12,162:12)
Block(-10,6,6,162:12)
Block(-10,6,7,162:12)
Block(-10,6,8,162:12)
Block(-10,6,9,162:12)
Block(-10,6,10,162:12)
Block(-10,7,7,161:1)
Block(-10,7,8,162:12)
Block(-10,7,9,162:12)
Block(-10,7,10,162:12)
Block(-10,8,7,161:1)
Block(-10,8,8,162:12)
Block(-10,8,9,162:12)
Block(-10,14,9,162:12)
Block(-10,15,9,162:12)
Block(-10,18,8,162:12)
Block(-10,19,7,162:12)
Block(-10,19,8,162:12)
Block(-10,19,9,162:12)
Block(-10,20,7,162:12)
Block(-10,20,8,162:12)
Block(-10,21,6,162:12)
Block(-10,21,7,162:12)
Block(-10,21,8,162:12)
Block(-10,22,6,162:12)
Block(-10,22,7,162:12)
Block(-10,22,8,162:12)
Block(-10,22,9,30)
Block(-10,23,4,162:12)
Block(-10,23,5,162:12)
Block(-10,23,6,162:12)
Block(-10,23,7,162:12)
Block(-10,23,8,162:12)
Block(-10,23,9,162:12)
Block(-10,24,3,162:12)
Block(-10,24,4,162:12)
Block(-10,24,5,162:12)
Block(-10,24,6,162:12)
Block(-10,24,7,162:12)
Block(-10,24,8,162:12)
Block(-10,25,3,162:12)
Block(-10,25,4,162:12)
Block(-10,25,7,162:12)
Block(-10,25,8,162:12)
Block(-10,26,3,162:12)
Block(-10,28,0,162:12)
Block(-10,28,1,162:12)
Block(-10,28,2,162:12)
Block(-10,29,-2,30)
Block(-10,29,-1,162:12)
Block(-10,29,0,162:12)
Block(-10,29,1,162:12)
Block(-10,29,2,162:12)
Block(-10,29,3,162:12)
Block(-10,30,-2,162:12)
Block(-10,30,-1,162:12)
Block(-10,30,0,162:12)
Block(-10,30,1,162:12)
Block(-10,30,2,162:12)
Block(-10,31,-2,162:12)
Block(-10,31,-1,162:12)
Block(-10,31,0,162:12)
Block(-10,31,1,162:12)
Block(-10,31,2,162:12)
Block(-10,32,-1,162:12)
Block(-10,32,0,162:12)
Block(-10,32,1,162:12)
Block(-10,32,2,162:12)
Block(-10,33,-1,162:12)
Block(-10,33,0,162:12)
Block(-10,33,1,162:12)
Block(-10,34,0,162:12)
Block(-10,35,-12,161:1)
Block(-10,36,-12,161:1)
Block(-10,36,19,162:12)
Block(-10,36,20,162:12)
Block(-10,37,-12,161:1)
Block(-10,37,20,162:12)
Block(-10,37,21,162:12)
Block(-10,37,22,162:12)
Block(-10,38,-12,161:1)
Block(-10,38,18,162:12)
Block(-10,38,19,162:12)
Block(-10,38,20,162:12)
Block(-10,38,21,162:12)
Block(-10,38,22,162:12)
Block(-10,39,-12,161:1)
Block(-10,39,-10,162:12)
Block(-10,39,18,162:12)
Block(-10,39,19,162:12)
Block(-10,39,20,162:12)
Block(-10,39,21,162:12)
Block(-10,39,22,162:12)
Block(-10,40,-12,161:1)
Block(-10,40,-11,162:12)
Block(-10,40,-10,162:12)
Block(-10,40,-9,162:12)
Block(-10,40,19,162:12)
Block(-10,40,20,162:12)
Block(-10,40,21,162:12)
Block(-10,40,22,162:12)
Block(-10,41,-12,161:1)
Block(-10,41,-10,162:12)
Block(-10,41,19,162:12)
Block(-10,41,20,162:12)
Block(-10,41,21,162:12)
Block(-10,42,-18,162:12)
Block(-10,42,-17,162:12)
Block(-10,42,-16,161:1)
Block(-10,42,-15,162:12)
Block(-10,42,-14,162:12)
Block(-10,42,-12,161:1)
Block(-10,42,20,162:12)
Block(-10,43,-22,161:1)
Block(-10,43,-21,162:12)
Block(-10,43,-20,162:12)
Block(-10,43,-19,162:12)
Block(-10,43,-18,162:12)
Block(-10,43,-17,162:12)
Block(-10,43,-16,162:12)
Block(-10,43,-15,162:12)
Block(-10,43,-14,162:12)
Block(-10,43,-12,161:1)
Block(-10,44,-22,162:12)
Block(-10,44,-21,162:12)
Block(-10,44,-20,162:12)
Block(-10,44,-19,162:12)
Block(-10,44,-18,162:12)
Block(-10,44,-17,162:12)
Block(-10,44,-16,162:12)
Block(-10,44,-15,162:12)
Block(-10,45,-23,162:12)
Block(-10,45,-22,162:12)
Block(-10,45,-21,162:12)
Block(-10,45,-20,162:12)
Block(-10,45,-19,162:12)
Block(-10,45,-18,162:12)
Block(-10,45,-17,162:12)
Block(-10,45,-16,162:12)
Block(-10,45,-15,162:12)
Block(-10,46,-23,161:1)
Block(-10,46,-22,162:12)
Block(-10,46,-21,162:12)
Block(-10,46,-20,162:12)
Block(-10,46,-19,162:12)
Block(-10,46,-18,162:12)
Block(-10,46,-17,162:12)
Block(-10,47,-22,161:1)
Block(-10,47,-21,162:12)
Block(-10,47,-20,162:12)
Block(-10,47,-19,161:1)
Block(-10,47,-17,161:1)
Block(-10,48,-21,161:1)
Block(-10,48,-20,161:1)
Block(-10,50,-34,162:12)
Block(-10,51,-34,161:1)
Block(-9,0,4,162:12)
Block(-9,0,13,162:12)
Block(-9,0,14,162:12)
Block(-9,0,15,162:12)
Block(-9,1,4,162:12)
Block(-9,1,13,162:12)
Block(-9,1,14,162:12)
Block(-9,2,5,162:12)
Block(-9,2,7,162:12)
Block(-9,2,11,162:12)
Block(-9,2,12,162:12)
Block(-9,2,13,162:12)
Block(-9,2,14,162:12)
Block(-9,3,6,162:12)
Block(-9,3,7,162:12)
Block(-9,3,8,162:12)
Block(-9,3,9,162:12)
Block(-9,3,10,162:12)
Block(-9,3,11,162:12)
Block(-9,3,12,162:12)
Block(-9,3,13,162:12)
Block(-9,4,5,162:12)
Block(-9,4,6,162:12)
Block(-9,4,7,162:12)
Block(-9,4,8,162:12)
Block(-9,4,9,162:12)
Block(-9,4,10,162:12)
Block(-9,4,11,162:12)
Block(-9,4,12,162:12)
Block(-9,4,13,162:12)
Block(-9,5,5,162:12)
Block(-9,5,6,162:12)
Block(-9,5,7,162:12)
Block(-9,5,8,162:12)
Block(-9,5,9,162:12)
Block(-9,5,10,162:12)
Block(-9,5,11,162:12)
Block(-9,5,12,162:12)
Block(-9,6,5,162:12)
Block(-9,6,6,162:12)
Block(-9,6,7,162:12)
Block(-9,6,8,162:12)
Block(-9,6,9,162:12)
Block(-9,6,10,162:12)
Block(-9,6,11,162:12)
Block(-9,6,12,161:1)
Block(-9,7,6,162:12)
Block(-9,7,7,162:12)
Block(-9,7,8,162:12)
Block(-9,7,9,162:12)
Block(-9,7,10,162:12)
Block(-9,7,11,162:12)
Block(-9,7,12,161:1)
Block(-9,8,7,161:1)
Block(-9,8,8,162:12)
Block(-9,8,9,162:12)
Block(-9,8,10,162:12)
Block(-9,8,11,161:1)
Block(-9,9,8,162:12)
Block(-9,9,9,162:12)
Block(-9,9,10,162:12)
Block(-9,10,9,162:12)
Block(-9,10,10,162:12)
Block(-9,11,9,162:12)
Block(-9,11,10,162:12)
Block(-9,11,11,162:12)
Block(-9,12,9,162:12)
Block(-9,12,10,162:12)
Block(-9,13,8,162:12)
Block(-9,13,9,162:12)
Block(-9,13,10,162:12)
Block(-9,14,8,162:12)
Block(-9,14,9,162:12)
Block(-9,14,10,162:12)
Block(-9,15,3,161:1)
Block(-9,15,8,162:12)
Block(-9,15,9,162:12)
Block(-9,15,10,162:12)
Block(-9,16,3,161:1)
Block(-9,16,9,162:12)
Block(-9,17,3,161:1)
Block(-9,17,8,162:12)
Block(-9,17,9,162:12)
Block(-9,18,3,161:1)
Block(-9,18,8,162:12)
Block(-9,18,9,162)
Block(-9,19,3,161:1)
Block(-9,19,6,162:12)
Block(-9,19,7,162:12)
Block(-9,19,8,162:12)
Block(-9,19,9,162:12)
Block(-9,20,3,161:1)
Block(-9,20,6,162:12)
Block(-9,20,7,162:12)
Block(-9,20,8,162:12)
Block(-9,20,9,162:12)
Block(-9,20,10,161:1)
Block(-9,21,3,161:1)
Block(-9,21,5,162:12)
Block(-9,21,6,162:12)
Block(-9,21,7,162:12)
Block(-9,21,8,162:12)
Block(-9,21,9,162:12)
Block(-9,22,3,161:1)
Block(-9,22,4,162:12)
Block(-9,22,5,162:12)
Block(-9,22,6,162:12)
Block(-9,22,7,162:12)
Block(-9,22,8,162:12)
Block(-9,22,9,162:12)
Block(-9,23,3,162:12)
Block(-9,23,4,162:12)
Block(-9,23,5,162:12)
Block(-9,23,6,162:12)
Block(-9,23,7,162:12)
Block(-9,23,8,162:12)
Block(-9,23,9,162:12)
Block(-9,24,2,162:12)
Block(-9,24,3,162:12)
Block(-9,24,4,162:12)
Block(-9,24,5,162:12)
Block(-9,24,6,162:12)
Block(-9,24,7,162:12)
Block(-9,24,8,162:12)
Block(-9,24,9,162:12)
Block(-9,24,10,162)
Block(-9,25,2,162:12)
Block(-9,25,3,162:12)
Block(-9,25,4,162:12)
Block(-9,25,5,162:12)
Block(-9,25,6,162:12)
Block(-9,25,7,162:12)
Block(-9,25,8,162:12)
Block(-9,25,9,162:12)
Block(-9,25,10,162:12)
Block(-9,26,2,162:12)
Block(-9,26,3,162:12)
Block(-9,26,4,162:12)
Block(-9,26,8,162:12)
Block(-9,26,9,162:12)
Block(-9,26,10,162:12)
Block(-9,27,1,162:12)
Block(-9,27,2,162:12)
Block(-9,27,3,162:12)
Block(-9,27,10,162:12)
Block(-9,28,-1,162:12)
Block(-9,28,0,162:12)
Block(-9,28,1,162:12)
Block(-9,28,2,162:12)
Block(-9,28,3,162:12)
Block(-9,29,-2,162:12)
Block(-9,29,-1,162:12)
Block(-9,29,0,162:12)
Block(-9,29,1,162:12)
Block(-9,29,2,162:12)
Block(-9,29,3,162:12)
Block(-9,30,-3,162:12)
Block(-9,30,-2,162:12)
Block(-9,30,-1,162:12)
Block(-9,30,0,162:12)
Block(-9,30,1,162:12)
Block(-9,30,2,162:12)
Block(-9,30,3,162:12)
Block(-9,31,-2,162:12)
Block(-9,31,-1,162:12)
Block(-9,31,0,162:12)
Block(-9,31,1,162:12)
Block(-9,31,2,162:12)
Block(-9,32,-2,162:12)
Block(-9,32,-1,162:12)
Block(-9,32,0,162:12)
Block(-9,32,1,162:12)
Block(-9,32,2,162:12)
Block(-9,33,-3,162:12)
Block(-9,33,-2,162:12)
Block(-9,33,-1,162:12)
Block(-9,33,0,162:12)
Block(-9,33,1,162:12)
Block(-9,34,0,162:12)
Block(-9,35,18,162:12)
Block(-9,35,20,162:12)
Block(-9,35,21,162:12)
Block(-9,36,18,162:12)
Block(-9,36,19,162:12)
Block(-9,36,20,162:12)
Block(-9,36,21,162:12)
Block(-9,37,18,162:12)
Block(-9,37,19,162:12)
Block(-9,37,20,162:12)
Block(-9,37,21,162:12)
Block(-9,38,-12,161:1)
Block(-9,38,-11,162:12)
Block(-9,38,-10,162:12)
Block(-9,38,-9,162:12)
Block(-9,38,18,162:12)
Block(-9,38,19,162:12)
Block(-9,38,20,162:12)
Block(-9,38,21,162:12)
Block(-9,39,-12,162:12)
Block(-9,39,-11,162:12)
Block(-9,39,-10,162:12)
Block(-9,39,-9,162:12)
Block(-9,39,19,162:12)
Block(-9,39,20,162:12)
Block(-9,39,21,162:12)
Block(-9,39,22,162:12)
Block(-9,40,-15,161:1)
Block(-9,40,-14,161:1)
Block(-9,40,-13,161:1)
Block(-9,40,-12,162:12)
Block(-9,40,-11,162:12)
Block(-9,40,-10,162:12)
Block(-9,40,19,162:12)
Block(-9,40,20,162:12)
Block(-9,40,21,162:12)
Block(-9,41,-17,161:1)
Block(-9,41,-16,161:1)
Block(-9,41,-15,162:12)
Block(-9,41,-14,162:12)
Block(-9,41,-13,162:12)
Block(-9,41,-12,162:12)
Block(-9,41,-11,162:12)
Block(-9,41,20,162:12)
Block(-9,42,-23,161:1)
Block(-9,42,-18,161:1)
Block(-9,42,-17,162:12)
Block(-9,42,-16,162:12)
Block(-9,42,-15,162:12)
Block(-9,42,-14,162:12)
Block(-9,42,-13,162:12)
Block(-9,42,-12,162:12)
Block(-9,43,-23,161:1)
Block(-9,43,-21,161:1)
Block(-9,43,-20,162:12)
Block(-9,43,-19,162:12)
Block(-9,43,-18,162:12)
Block(-9,43,-17,162:12)
Block(-9,43,-16,162:12)
Block(-9,43,-15,162:12)
Block(-9,43,-14,162:12)
Block(-9,43,-13,162:12)
Block(-9,43,-12,161:1)
Block(-9,44,-23,161:1)
Block(-9,44,-22,161:1)
Block(-9,44,-21,162:12)
Block(-9,44,-20,162:12)
Block(-9,44,-19,162:12)
Block(-9,44,-18,162:12)
Block(-9,44,-17,162:12)
Block(-9,44,-16,162:12)
Block(-9,44,-15,162:12)
Block(-9,44,-14,162:12)
Block(-9,45,-23,161:1)
Block(-9,45,-22,162:12)
Block(-9,45,-21,162:12)
Block(-9,45,-20,162:12)
Block(-9,45,-19,162:12)
Block(-9,45,-18,162:12)
Block(-9,45,-17,162:12)
Block(-9,45,-16,162:12)
Block(-9,45,-15,162:12)
Block(-9,45,-14,161:1)
Block(-9,46,-21,162:12)
Block(-9,46,-20,162:12)
Block(-9,46,-19,162:12)
Block(-9,46,-18,162:12)
Block(-9,46,-17,162:12)
Block(-9,46,-16,162:12)
Block(-9,47,-34,161:1)
Block(-9,47,-21,161:1)
Block(-9,47,-20,162:12)
Block(-9,47,-19,161:1)
Block(-9,47,-16,161:1)
Block(-9,48,-34,161:1)
Block(-9,48,-19,161:1)
Block(-9,49,-34,161:1)
Block(-9,50,-34,161:1)
Block(-8,1,13,162:12)
Block(-8,2,8,161:1)
Block(-8,2,13,162:12)
Block(-8,3,6,162:12)
Block(-8,3,7,162:12)
Block(-8,3,8,162:12)
Block(-8,3,9,162:12)
Block(-8,3,10,162:12)
Block(-8,3,11,162:12)
Block(-8,3,12,162:12)
Block(-8,3,13,162:12)
Block(-8,4,6,162:12)
Block(-8,4,7,162:12)
Block(-8,4,8,162:12)
Block(-8,4,9,162:12)
Block(-8,4,10,162:12)
Block(-8,4,11,162:12)
Block(-8,4,12,162:12)
Block(-8,4,13,162:12)
Block(-8,4,14,161:1)
Block(-8,5,5,162:12)
Block(-8,5,6,162:12)
Block(-8,5,7,162:12)
Block(-8,5,8,162:12)
Block(-8,5,9,162:12)
Block(-8,5,10,162:12)
Block(-8,5,11,162:12)
Block(-8,5,12,162:12)
Block(-8,5,13,162:12)
Block(-8,5,14,161:1)
Block(-8,6,5,162:12)
Block(-8,6,6,162:12)
Block(-8,6,7,162:12)
Block(-8,6,8,162:12)
Block(-8,6,9,162:12)
Block(-8,6,10,162:12)
Block(-8,6,11,162:12)
Block(-8,6,12,162:12)
Block(-8,6,13,161:1)
Block(-8,7,5,162:12)
Block(-8,7,6,162:12)
Block(-8,7,7,162:12)
Block(-8,7,8,162:12)
Block(-8,7,9,162:12)
Block(-8,7,10,162:12)
Block(-8,7,11,162:12)
Block(-8,7,12,162:12)
Block(-8,8,7,162:12)
Block(-8,8,8,162:12)
Block(-8,8,9,162:12)
Block(-8,8,10,162:12)
Block(-8,8,11,162:12)
Block(-8,9,7,162:12)
Block(-8,9,8,162:12)
Block(-8,9,9,162:12)
Block(-8,9,10,162:12)
Block(-8,9,11,162:12)
Block(-8,10,8,162:12)
Block(-8,10,9,162:12)
Block(-8,10,10,162:12)
Block(-8,10,11,162:12)
Block(-8,11,8,162:12)
Block(-8,11,9,162:12)
Block(-8,11,10,162:12)
Block(-8,11,11,162:12)
Block(-8,11,12,162:12)
Block(-8,12,5,161:1)
Block(-8,12,6,161:1)
Block(-8,12,8,162:12)
Block(-8,12,9,162:12)
Block(-8,12,10,162:12)
Block(-8,12,11,162:12)
Block(-8,13,5,161:1)
Block(-8,13,6,161:1)
Block(-8,13,7,162:12)
Block(-8,13,8,162:12)
Block(-8,13,9,162:12)
Block(-8,13,10,162:12)
Block(-8,13,11,162:12)
Block(-8,14,6,161:1)
Block(-8,14,7,162:12)
Block(-8,14,8,162:12)
Block(-8,14,9,162:12)
Block(-8,14,10,162:12)
Block(-8,14,11,162:12)
Block(-8,15,6,161:1)
Block(-8,15,7,162:12)
Block(-8,15,8,162:12)
Block(-8,15,9,162:12)
Block(-8,15,10,162:12)
Block(-8,15,11,162:12)
Block(-8,16,6,161:1)
Block(-8,16,7,161:1)
Block(-8,16,8,162:12)
Block(-8,16,9,162:12)
Block(-8,16,10,162:12)
Block(-8,17,7,162:12)
Block(-8,17,8,162:12)
Block(-8,17,9,162:12)
Block(-8,17,10,162:12)
Block(-8,18,6,30)
Block(-8,18,7,162:12)
Block(-8,18,8,162:12)
Block(-8,18,9,162:12)
Block(-8,18,10,162)
Block(-8,19,5,162:12)
Block(-8,19,6,162:12)
Block(-8,19,7,162:12)
Block(-8,19,8,162:12)
Block(-8,19,9,162:12)
Block(-8,19,10,162:12)
Block(-8,19,11,161:1)
Block(-8,20,5,162:12)
Block(-8,20,6,162:12)
Block(-8,20,7,162:12)
Block(-8,20,8,162:12)
Block(-8,20,9,162:12)
Block(-8,20,10,161:1)
Block(-8,20,11,161:1)
Block(-8,21,3,161:1)
Block(-8,21,4,162:12)
Block(-8,21,5,162:12)
Block(-8,21,6,162:12)
Block(-8,21,7,162:12)
Block(-8,21,8,162:12)
Block(-8,21,9,162:12)
Block(-8,21,10,162:12)
Block(-8,21,11,161:1)
Block(-8,22,3,162:12)
Block(-8,22,4,162:12)
Block(-8,22,5,162:12)
Block(-8,22,6,162:12)
Block(-8,22,7,162:12)
Block(-8,22,8,162:12)
Block(-8,22,9,162:12)
Block(-8,22,10,162:12)
Block(-8,23,3,162:12)
Block(-8,23,4,162:12)
Block(-8,23,5,162:12)
Block(-8,23,6,162:12)
Block(-8,23,7,162:12)
Block(-8,23,8,162:12)
Block(-8,23,9,162:12)
Block(-8,23,10,162:12)
Block(-8,24,2,162:12)
Block(-8,24,3,162:12)
Block(-8,24,4,162:12)
Block(-8,24,5,162:12)
Block(-8,24,6,162:12)
Block(-8,24,7,162:12)
Block(-8,24,8,162:12)
Block(-8,24,9,162:12)
Block(-8,24,10,162:12)
Block(-8,25,0,30)
Block(-8,25,1,162:12)
Block(-8,25,2,162:12)
Block(-8,25,3,162:12)
Block(-8,25,4,162:12)
Block(-8,25,5,162:12)
Block(-8,25,6,162:12)
Block(-8,25,7,162:12)
Block(-8,25,8,162:12)
Block(-8,25,9,162:12)
Block(-8,25,10,162:12)
Block(-8,26,0,162:12)
Block(-8,26,1,162:12)
Block(-8,26,2,162:12)
Block(-8,26,3,162:12)
Block(-8,26,4,162:12)
Block(-8,26,5,162:12)
Block(-8,26,6,30)
Block(-8,26,7,162:12)
Block(-8,26,8,162:12)
Block(-8,26,9,162:12)
Block(-8,26,10,162:12)
Block(-8,26,11,162:12)
Block(-8,27,-1,162:12)
Block(-8,27,0,162:12)
Block(-8,27,1,162:12)
Block(-8,27,2,162:12)
Block(-8,27,3,162:12)
Block(-8,27,4,162:12)
Block(-8,27,8,162:12)
Block(-8,27,10,162:12)
Block(-8,28,-2,162:12)
Block(-8,28,-1,162:12)
Block(-8,28,0,162:12)
Block(-8,28,1,162:12)
Block(-8,28,2,162:12)
Block(-8,28,3,162:12)
Block(-8,29,-3,162:12)
Block(-8,29,-2,162:12)
Block(-8,29,-1,162:12)
Block(-8,29,0,162:12)
Block(-8,29,1,162:12)
Block(-8,29,2,162:12)
Block(-8,29,3,162:12)
Block(-8,30,-3,162:12)
Block(-8,30,-2,162:12)
Block(-8,30,-1,162:12)
Block(-8,30,0,162:12)
Block(-8,30,1,162:12)
Block(-8,30,2,162:12)
Block(-8,30,3,162:12)
Block(-8,31,-3,162:12)
Block(-8,31,-2,162:12)
Block(-8,31,-1,162:12)
Block(-8,31,0,162:12)
Block(-8,31,1,162:12)
Block(-8,31,2,162:12)
Block(-8,32,-2,162:12)
Block(-8,32,-1,162:12)
Block(-8,32,0,162:12)
Block(-8,32,1,162:12)
Block(-8,33,-3,162:12)
Block(-8,33,-2,162:12)
Block(-8,33,-1,162:12)
Block(-8,33,0,162:12)
Block(-8,34,-3,162:12)
Block(-8,35,18,162:12)
Block(-8,35,19,162:12)
Block(-8,35,20,162:12)
Block(-8,36,-7,162:12)
Block(-8,36,17,162:12)
Block(-8,36,18,162:12)
Block(-8,36,19,162:12)
Block(-8,36,20,162:12)
Block(-8,37,-10,162:12)
Block(-8,37,-9,162:12)
Block(-8,37,-8,162:12)
Block(-8,37,-7,162:12)
Block(-8,37,18,162:12)
Block(-8,37,19,162:12)
Block(-8,37,20,162:12)
Block(-8,37,21,162:12)
Block(-8,38,-13,161:1)
Block(-8,38,-12,161:1)
Block(-8,38,-11,162:12)
Block(-8,38,-10,162:12)
Block(-8,38,-9,162:12)
Block(-8,38,-8,162:12)
Block(-8,38,-7,30)
Block(-8,38,19,162:12)
Block(-8,38,20,162:12)
Block(-8,38,21,162:12)
Block(-8,39,-14,161:1)
Block(-8,39,-13,161:1)
Block(-8,39,-12,162:12)
Block(-8,39,-11,162:12)
Block(-8,39,-10,162:12)
Block(-8,39,-9,162:12)
Block(-8,39,20,162:12)
Block(-8,39,21,162:12)
Block(-8,40,-15,161:1)
Block(-8,40,-14,162:12)
Block(-8,40,-13,162:12)
Block(-8,40,-12,162:12)
Block(-8,40,-11,162:12)
Block(-8,40,-10,162:12)
Block(-8,41,-16,161:1)
Block(-8,41,-15,162:12)
Block(-8,41,-14,162:12)
Block(-8,41,-13,162:12)
Block(-8,41,-12,162:12)
Block(-8,41,-11,162:12)
Block(-8,41,-10,162:12)
Block(-8,42,-16,162:12)
Block(-8,42,-15,162:12)
Block(-8,42,-14,162:12)
Block(-8,42,-13,162:12)
Block(-8,42,-12,162:12)
Block(-8,42,-11,162:12)
Block(-8,43,-20,162:12)
Block(-8,43,-19,162:12)
Block(-8,43,-17,162:12)
Block(-8,43,-16,162:12)
Block(-8,43,-15,162:12)
Block(-8,43,-14,162:12)
Block(-8,43,-13,162:12)
Block(-8,43,-12,162:12)
Block(-8,44,-22,30)
Block(-8,44,-21,162:12)
Block(-8,44,-20,162:12)
Block(-8,44,-19,162:12)
Block(-8,44,-18,162:12)
Block(-8,44,-17,162:12)
Block(-8,44,-16,162:12)
Block(-8,44,-15,162:12)
Block(-8,44,-14,162:12)
Block(-8,44,-13,161:1)
Block(-8,45,-23,161:1)
Block(-8,45,-22,162:12)
Block(-8,45,-21,162:12)
Block(-8,45,-20,162:12)
Block(-8,45,-19,162:12)
Block(-8,45,-18,162:12)
Block(-8,45,-17,162:12)
Block(-8,45,-16,162:12)
Block(-8,45,-15,162:12)
Block(-8,45,-14,161:1)
Block(-8,46,-23,161:1)
Block(-8,46,-22,162:12)
Block(-8,46,-21,162:12)
Block(-8,46,-20,162:12)
Block(-8,46,-19,162:12)
Block(-8,46,-18,162:12)
Block(-8,46,-16,161:1)
Block(-8,46,-15,161:1)
Block(-8,47,-21,162:12)
Block(-8,47,-20,162:12)
Block(-8,48,-21,161:1)
Block(-8,48,-20,161:1)
Block(-7,2,6,161:1)
Block(-7,3,6,161:1)
Block(-7,3,7,162:12)
Block(-7,3,8,162:12)
Block(-7,3,9,162:12)
Block(-7,3,10,162:12)
Block(-7,3,11,162:12)
Block(-7,3,13,162:12)
Block(-7,4,6,162:12)
Block(-7,4,7,162:12)
Block(-7,4,8,162:12)
Block(-7,4,9,162)
Block(-7,4,10,162:12)
Block(-7,4,11,162:12)
Block(-7,4,12,162:12)
Block(-7,4,13,162:12)
Block(-7,5,5,162:12)
Block(-7,5,6,162:12)
Block(-7,5,7,162:12)
Block(-7,5,8,162:12)
Block(-7,5,9,162:12)
Block(-7,5,10,162:12)
Block(-7,5,11,162:12)
Block(-7,5,12,162:12)
Block(-7,5,13,162:12)
Block(-7,6,5,162:12)
Block(-7,6,6,162:12)
Block(-7,6,7,162:12)
Block(-7,6,8,162:12)
Block(-7,6,9,162:12)
Block(-7,6,10,162:12)
Block(-7,6,11,162:12)
Block(-7,6,12,162:12)
Block(-7,6,13,162)
Block(-7,7,5,162:12)
Block(-7,7,6,162:12)
Block(-7,7,7,162:12)
Block(-7,7,8,162:12)
Block(-7,7,9,162:12)
Block(-7,7,10,162:12)
Block(-7,7,11,162:12)
Block(-7,7,12,162:12)
Block(-7,7,13,162:12)
Block(-7,8,6,162:12)
Block(-7,8,7,162:12)
Block(-7,8,8,162:12)
Block(-7,8,9,162:12)
Block(-7,8,10,162:12)
Block(-7,8,11,162:12)
Block(-7,8,12,162:12)
Block(-7,9,6,162:12)
Block(-7,9,7,162:12)
Block(-7,9,8,162:12)
Block(-7,9,9,162:12)
Block(-7,9,10,162:12)
Block(-7,9,11,162:12)
Block(-7,9,12,162:12)
Block(-7,10,7,162:12)
Block(-7,10,8,162:12)
Block(-7,10,9,162:12)
Block(-7,10,10,162:12)
Block(-7,10,11,162:12)
Block(-7,10,12,162:12)
Block(-7,11,7,162:12)
Block(-7,11,8,162:12)
Block(-7,11,9,162:12)
Block(-7,11,10,162:12)
Block(-7,11,11,162:12)
Block(-7,11,12,162:12)
Block(-7,11,13,162:12)
Block(-7,12,7,162:12)
Block(-7,12,8,162:12)
Block(-7,12,9,162:12)
Block(-7,12,10,162:12)
Block(-7,12,11,162:12)
Block(-7,12,12,162:12)
Block(-7,13,6,162:12)
Block(-7,13,7,162:12)
Block(-7,13,8,162:12)
Block(-7,13,9,162:12)
Block(-7,13,10,162:12)
Block(-7,13,11,162:12)
Block(-7,13,12,162:12)
Block(-7,14,6,162:12)
Block(-7,14,7,162:12)
Block(-7,14,8,162:12)
Block(-7,14,9,162:12)
Block(-7,14,10,162:12)
Block(-7,14,11,162:12)
Block(-7,14,12,162:12)
Block(-7,15,6,162:12)
Block(-7,15,7,162:12)
Block(-7,15,8,162:12)
Block(-7,15,9,162:12)
Block(-7,15,10,162:12)
Block(-7,15,11,162:12)
Block(-7,15,12,162:12)
Block(-7,16,7,162:12)
Block(-7,16,8,162:12)
Block(-7,16,9,162:12)
Block(-7,16,10,162:12)
Block(-7,16,11,162:12)
Block(-7,17,6,162:12)
Block(-7,17,7,162:12)
Block(-7,17,8,162:12)
Block(-7,17,9,162:12)
Block(-7,17,10,162:12)
Block(-7,17,11,162:12)
Block(-7,18,6,162:12)
Block(-7,18,7,162:12)
Block(-7,18,8,162:12)
Block(-7,18,9,162:12)
Block(-7,18,10,162:12)
Block(-7,18,11,162)
Block(-7,19,4,162:12)
Block(-7,19,5,162:12)
Block(-7,19,6,162:12)
Block(-7,19,7,162:12)
Block(-7,19,8,162:12)
Block(-7,19,9,162:12)
Block(-7,19,10,162:12)
Block(-7,19,11,162:12)
Block(-7,20,0,161:1)
Block(-7,20,4,162:12)
Block(-7,20,5,162:12)
Block(-7,20,6,162:12)
Block(-7,20,7,162:12)
Block(-7,20,8,162:12)
Block(-7,20,9,162:12)
Block(-7,20,10,162:12)
Block(-7,20,11,161:1)
Block(-7,21,0,161:1)
Block(-7,21,4,162:12)
Block(-7,21,5,162:12)
Block(-7,21,6,162:12)
Block(-7,21,7,162:12)
Block(-7,21,8,162:12)
Block(-7,21,9,162:12)
Block(-7,21,10,162:12)
Block(-7,22,0,161:1)
Block(-7,22,3,162:12)
Block(-7,22,4,162:12)
Block(-7,22,5,162:12)
Block(-7,22,6,162:12)
Block(-7,22,7,162:12)
Block(-7,22,8,162:12)
Block(-7,22,9,162:12)
Block(-7,22,10,162:12)
Block(-7,23,0,161:1)
Block(-7,23,2,162:12)
Block(-7,23,3,162:12)
Block(-7,23,4,162:12)
Block(-7,23,5,162:12)
Block(-7,23,6,162:12)
Block(-7,23,7,162:12)
Block(-7,23,8,162:12)
Block(-7,23,9,162:12)
Block(-7,23,10,162:12)
Block(-7,23,11,162:12)
Block(-7,24,0,161:1)
Block(-7,24,1,162:12)
Block(-7,24,2,162:12)
Block(-7,24,3,162:12)
Block(-7,24,4,162:12)
Block(-7,24,5,162:12)
Block(-7,24,6,162:12)
Block(-7,24,7,162:12)
Block(-7,24,8,162:12)
Block(-7,24,9,162:12)
Block(-7,24,10,162:12)
Block(-7,24,11,162)
Block(-7,25,-1,161:1)
Block(-7,25,0,162:12)
Block(-7,25,1,162:12)
Block(-7,25,2,162:12)
Block(-7,25,3,162:12)
Block(-7,25,4,162:12)
Block(-7,25,5,162:12)
Block(-7,25,6,162:12)
Block(-7,25,7,162:12)
Block(-7,25,8,162:12)
Block(-7,25,9,162:12)
Block(-7,25,10,162:12)
Block(-7,25,11,162:12)
Block(-7,26,-1,162:12)
Block(-7,26,0,162:12)
Block(-7,26,1,162:12)
Block(-7,26,2,162:12)
Block(-7,26,3,162:12)
Block(-7,26,4,162:12)
Block(-7,26,5,162:12)
Block(-7,26,6,162:12)
Block(-7,26,7,162:12)
Block(-7,26,8,162:12)
Block(-7,26,9,162:12)
Block(-7,26,10,162:12)
Block(-7,26,11,162:12)
Block(-7,26,12,162:12)
Block(-7,27,-2,162:12)
Block(-7,27,-1,162:12)
Block(-7,27,0,162:12)
Block(-7,27,1,162:12)
Block(-7,27,2,162:12)
Block(-7,27,3,162:12)
Block(-7,27,4,162:12)
Block(-7,27,5,162:12)
Block(-7,27,7,162:12)
Block(-7,27,8,162:12)
Block(-7,27,9,162:12)
Block(-7,27,10,162:12)
Block(-7,27,11,162:12)
Block(-7,27,12,162:12)
Block(-7,28,-3,162:12)
Block(-7,28,-2,162:12)
Block(-7,28,-1,162:12)
Block(-7,28,0,162:12)
Block(-7,28,1,162:12)
Block(-7,28,2,162:12)
Block(-7,28,3,162:12)
Block(-7,28,10,162:12)
Block(-7,28,11,162:12)
Block(-7,28,12,162:12)
Block(-7,29,-5,161:1)
Block(-7,29,-3,162:12)
Block(-7,29,-2,162:12)
Block(-7,29,-1,162:12)
Block(-7,29,0,162:12)
Block(-7,29,1,162:12)
Block(-7,29,2,162:12)
Block(-7,29,3,162:12)
Block(-7,29,13,162:12)
Block(-7,30,-15,161:1)
Block(-7,30,-3,162:12)
Block(-7,30,-2,162:12)
Block(-7,30,-1,162:12)
Block(-7,30,0,162:12)
Block(-7,30,1,162:12)
Block(-7,30,2,162:12)
Block(-7,30,14,162:12)
Block(-7,30,16,161:1)
Block(-7,31,-15,161:1)
Block(-7,31,-8,161:1)
Block(-7,31,-4,162:12)
Block(-7,31,-3,162:12)
Block(-7,31,-2,162:12)
Block(-7,31,-1,162:12)
Block(-7,31,0,162:12)
Block(-7,31,1,162:12)
Block(-7,31,2,30)
Block(-7,31,15,162:12)
Block(-7,31,16,162:12)
Block(-7,31,17,161:1)
Block(-7,32,-15,161:1)
Block(-7,32,-8,161:1)
Block(-7,32,-3,162:12)
Block(-7,32,-2,162:12)
Block(-7,32,-1,162:12)
Block(-7,32,0,162:12)
Block(-7,32,16,162:12)
Block(-7,32,17,161:1)
Block(-7,33,-15,161:1)
Block(-7,33,-8,161:1)
Block(-7,33,-5,162:12)
Block(-7,33,-4,162:12)
Block(-7,33,-3,162:12)
Block(-7,33,-2,162:12)
Block(-7,33,-1,162:12)
Block(-7,33,17,162:12)
Block(-7,33,18,161:1)
Block(-7,34,-15,161:1)
Block(-7,34,-8,161:1)
Block(-7,34,-7,162:12)
Block(-7,34,-6,162:12)
Block(-7,34,-5,162:12)
Block(-7,34,-4,162:12)
Block(-7,34,18,162:12)
Block(-7,34,19,162:12)
Block(-7,35,-14,161:1)
Block(-7,35,-10,30)
Block(-7,35,-9,162:12)
Block(-7,35,-8,162:12)
Block(-7,35,-7,162:12)
Block(-7,35,-6,162:12)
Block(-7,35,-5,162:12)
Block(-7,35,-4,162:12)
Block(-7,35,17,162:12)
Block(-7,35,18,162:12)
Block(-7,35,19,162:12)
Block(-7,36,-14,161:1)
Block(-7,36,-11,162:12)
Block(-7,36,-10,162:12)
Block(-7,36,-9,162:12)
Block(-7,36,-8,162:12)
Block(-7,36,-7,162:12)
Block(-7,36,-6,162:12)
Block(-7,36,17,162:12)
Block(-7,36,18,162:12)
Block(-7,36,19,162:12)
Block(-7,36,20,162:12)
Block(-7,36,21,162:12)
Block(-7,37,-14,161:1)
Block(-7,37,-12,162:12)
Block(-7,37,-11,162:12)
Block(-7,37,-10,162:12)
Block(-7,37,-9,162:12)
Block(-7,37,-8,162:12)
Block(-7,37,-7,162:12)
Block(-7,37,-6,162:12)
Block(-7,37,18,162:12)
Block(-7,37,19,162:12)
Block(-7,37,20,162:12)
Block(-7,37,21,162:12)
Block(-7,38,-14,161:1)
Block(-7,38,-13,162:12)
Block(-7,38,-12,162:12)
Block(-7,38,-11,162:12)
Block(-7,38,-10,162:12)
Block(-7,38,-9,162:12)
Block(-7,38,-8,162:12)
Block(-7,38,-7,162:12)
Block(-7,38,20,162:12)
Block(-7,39,-14,162:12)
Block(-7,39,-13,162:12)
Block(-7,39,-12,162:12)
Block(-7,39,-11,162:12)
Block(-7,39,-10,162:12)
Block(-7,39,-9,162:12)
Block(-7,39,-8,30)
Block(-7,40,-14,162:12)
Block(-7,40,-13,162:12)
Block(-7,40,-12,162:12)
Block(-7,40,-11,162:12)
Block(-7,40,-10,162:12)
Block(-7,41,-15,162:12)
Block(-7,41,-14,162:12)
Block(-7,41,-13,162:12)
Block(-7,41,-12,162:12)
Block(-7,41,-11,162:12)
Block(-7,41,-10,162:12)
Block(-7,42,-15,162:12)
Block(-7,42,-14,162:12)
Block(-7,42,-13,162:12)
Block(-7,42,-12,162:12)
Block(-7,42,-11,162:12)
Block(-7,43,-16,162:12)
Block(-7,43,-15,162:12)
Block(-7,43,-14,162:12)
Block(-7,43,-13,162:12)
Block(-7,43,-12,162:12)
Block(-7,44,-21,162:12)
Block(-7,44,-20,162:12)
Block(-7,44,-19,162:12)
Block(-7,44,-17,162:12)
Block(-7,44,-16,162:12)
Block(-7,44,-15,162:12)
Block(-7,45,-22,162:12)
Block(-7,45,-21,162:12)
Block(-7,45,-20,162:12)
Block(-7,45,-19,162:12)
Block(-7,45,-18,162:12)
Block(-7,46,-22,162:12)
Block(-7,46,-21,162:12)
Block(-7,46,-20,162:12)
Block(-7,46,-19,162:12)
Block(-7,47,-23,161:1)
Block(-7,47,-22,162:12)
Block(-7,47,-21,162:12)
Block(-7,47,-20,162:12)
Block(-7,47,-19,161:1)
Block(-7,48,-22,161:1)
Block(-6,2,13,161:1)
Block(-6,3,6,162:12)
Block(-6,3,7,162:12)
Block(-6,3,8,162:12)
Block(-6,3,9,162:8)
Block(-6,3,10,162:12)
Block(-6,3,11,162:12)
Block(-6,3,12,162:12)
Block(-6,3,13,161:1)
Block(-6,4,5,162:12)
Block(-6,4,6,162:12)
Block(-6,4,7,162:12)
Block(-6,4,8,162:12)
Block(-6,4,9,162:4)
Block(-6,4,10,162:12)
Block(-6,4,11,162:12)
Block(-6,4,12,162:12)
Block(-6,4,13,161:1)
Block(-6,5,5,162:12)
Block(-6,5,6,162:12)
Block(-6,5,7,162:12)
Block(-6,5,8,162:12)
Block(-6,5,9,162:12)
Block(-6,5,10,162:12)
Block(-6,5,11,162:12)
Block(-6,5,12,162:12)
Block(-6,5,13,162:12)
Block(-6,6,5,162:12)
Block(-6,6,6,162:12)
Block(-6,6,7,162:12)
Block(-6,6,8,162:12)
Block(-6,6,9,162:12)
Block(-6,6,10,162:12)
Block(-6,6,11,162:12)
Block(-6,6,12,162:12)
Block(-6,6,13,162:12)
Block(-6,7,4,162:12)
Block(-6,7,5,162:12)
Block(-6,7,6,162:12)
Block(-6,7,7,162:12)
Block(-6,7,8,162:12)
Block(-6,7,9,162:12)
Block(-6,7,10,162:12)
Block(-6,7,11,162:12)
Block(-6,7,12,162:12)
Block(-6,7,13,162:12)
Block(-6,8,5,162:12)
Block(-6,8,6,162:12)
Block(-6,8,7,162:12)
Block(-6,8,8,162:12)
Block(-6,8,9,162:12)
Block(-6,8,10,162:12)
Block(-6,8,11,162:12)
Block(-6,8,12,162:12)
Block(-6,8,13,162:12)
Block(-6,9,6,162:12)
Block(-6,9,7,162:12)
Block(-6,9,8,162:12)
Block(-6,9,9,162:12)
Block(-6,9,10,162:12)
Block(-6,9,11,162:12)
Block(-6,9,12,162:12)
Block(-6,9,13,162:12)
Block(-6,10,6,162:12)
Block(-6,10,7,162:12)
Block(-6,10,8,162:12)
Block(-6,10,9,162:12)
Block(-6,10,10,162:12)
Block(-6,10,11,162:12)
Block(-6,10,12,162:12)
Block(-6,10,13,162:12)
Block(-6,11,6,162:12)
Block(-6,11,7,162:12)
Block(-6,11,8,162:12)
Block(-6,11,9,162:12)
Block(-6,11,10,162:12)
Block(-6,11,11,162:12)
Block(-6,11,12,162:12)
Block(-6,11,13,162:12)
Block(-6,11,14,162:12)
Block(-6,12,6,162:12)
Block(-6,12,7,162:12)
Block(-6,12,8,162:12)
Block(-6,12,9,162:12)
Block(-6,12,10,162:12)
Block(-6,12,11,162:12)
Block(-6,12,12,162:12)
Block(-6,12,13,162:12)
Block(-6,13,6,162:12)
Block(-6,13,7,162:12)
Block(-6,13,8,162:12)
Block(-6,13,9,162:12)
Block(-6,13,10,162:12)
Block(-6,13,11,162:12)
Block(-6,13,12,162:12)
Block(-6,13,13,162:12)
Block(-6,14,5,162:12)
Block(-6,14,6,162:12)
Block(-6,14,7,162:12)
Block(-6,14,8,162:12)
Block(-6,14,9,162:12)
Block(-6,14,10,162:12)
Block(-6,14,11,162:12)
Block(-6,14,12,162:12)
Block(-6,14,13,162:12)
Block(-6,15,5,162:12)
Block(-6,15,6,162:12)
Block(-6,15,7,162:12)
Block(-6,15,8,162:12)
Block(-6,15,9,162:12)
Block(-6,15,10,162:12)
Block(-6,15,11,162:12)
Block(-6,15,12,162:12)
Block(-6,15,13,162:12)
Block(-6,16,6,162:12)
Block(-6,16,7,162:12)
Block(-6,16,8,162:12)
Block(-6,16,9,162:12)
Block(-6,16,10,162:12)
Block(-6,16,11,162:12)
Block(-6,16,12,162:12)
Block(-6,17,5,162:12)
Block(-6,17,6,162:12)
Block(-6,17,7,162:12)
Block(-6,17,8,162:12)
Block(-6,17,9,162:12)
Block(-6,17,10,162:12)
Block(-6,17,11,162:12)
Block(-6,17,12,162:12)
Block(-6,18,4,162:12)
Block(-6,18,5,162:12)
Block(-6,18,6,162:12)
Block(-6,18,7,162:12)
Block(-6,18,8,162:12)
Block(-6,18,9,162:12)
Block(-6,18,10,162:12)
Block(-6,18,11,162:12)
Block(-6,18,12,162)
Block(-6,19,4,162:12)
Block(-6,19,5,162:12)
Block(-6,19,6,162:12)
Block(-6,19,7,162:12)
Block(-6,19,8,162:12)
Block(-6,19,9,162:12)
Block(-6,19,10,162:12)
Block(-6,19,11,162:12)
Block(-6,19,12,162:12)
Block(-6,20,4,162:12)
Block(-6,20,5,162:12)
Block(-6,20,6,162:12)
Block(-6,20,7,162:12)
Block(-6,20,8,162:12)
Block(-6,20,9,162:12)
Block(-6,20,10,162:12)
Block(-6,20,11,162:12)
Block(-6,21,2,162:12)
Block(-6,21,3,162:12)
Block(-6,21,4,162:12)
Block(-6,21,5,162:12)
Block(-6,21,6,162:12)
Block(-6,21,7,162:12)
Block(-6,21,8,162:12)
Block(-6,21,9,162:12)
Block(-6,21,10,162:12)
Block(-6,22,2,162:12)
Block(-6,22,3,162:12)
Block(-6,22,4,162:12)
Block(-6,22,5,162:12)
Block(-6,22,7,162:12)
Block(-6,22,8,162:12)
Block(-6,22,9,162:12)
Block(-6,22,10,162:12)
Block(-6,22,11,162:12)
Block(-6,23,1,162:12)
Block(-6,23,2,162:12)
Block(-6,23,3,162:12)
Block(-6,23,4,162:12)
Block(-6,23,5,162:12)
Block(-6,23,7,162:12)
Block(-6,23,8,162:12)
Block(-6,23,9,162:12)
Block(-6,23,10,162:12)
Block(-6,23,11,162:12)
Block(-6,24,0,162:12)
Block(-6,24,1,162:12)
Block(-6,24,2,162:12)
Block(-6,24,3,162:12)
Block(-6,24,4,162:12)
Block(-6,24,5,162:12)
Block(-6,24,7,162:12)
Block(-6,24,8,162:12)
Block(-6,24,9,162:12)
Block(-6,24,10,162:12)
Block(-6,24,11,162:12)
Block(-6,25,-1,162:12)
Block(-6,25,0,162:12)
Block(-6,25,1,162:12)
Block(-6,25,2,162:12)
Block(-6,25,3,162:12)
Block(-6,25,4,162:12)
Block(-6,25,5,162:12)
Block(-6,25,7,162:12)
Block(-6,25,8,162:12)
Block(-6,25,9,162:12)
Block(-6,25,10,162:12)
Block(-6,25,11,162:12)
Block(-6,25,12,162:12)
Block(-6,26,-1,162:12)
Block(-6,26,0,162:12)
Block(-6,26,1,162:12)
Block(-6,26,2,162:12)
Block(-6,26,3,162:12)
Block(-6,26,4,162:12)
Block(-6,26,5,162:12)
Block(-6,26,7,162:12)
Block(-6,26,8,162:12)
Block(-6,26,9,162:12)
Block(-6,26,10,162:12)
Block(-6,26,11,162:12)
Block(-6,26,12,162:12)
Block(-6,26,13,162:12)
Block(-6,27,-2,162:12)
Block(-6,27,-1,162:12)
Block(-6,27,0,162:12)
Block(-6,27,1,162:12)
Block(-6,27,2,162:12)
Block(-6,27,3,162:12)
Block(-6,27,4,162:12)
Block(-6,27,6,162:12)
Block(-6,27,7,162:12)
Block(-6,27,8,162:12)
Block(-6,27,9,162:12)
Block(-6,27,10,162:12)
Block(-6,27,11,162:12)
Block(-6,27,12,162:12)
Block(-6,27,13,162:12)
Block(-6,28,-5,161:1)
Block(-6,28,-3,162:12)
Block(-6,28,-2,162:12)
Block(-6,28,-1,162:12)
Block(-6,28,0,162:12)
Block(-6,28,1,162:12)
Block(-6,28,2,162:12)
Block(-6,28,3,162:12)
Block(-6,28,7,162:12)
Block(-6,28,8,162:12)
Block(-6,28,9,162:12)
Block(-6,28,10,162:12)
Block(-6,28,11,162:12)
Block(-6,28,12,162:12)
Block(-6,28,13,162:12)
Block(-6,28,14,30)
Block(-6,29,-5,161:1)
Block(-6,29,-4,162:12)
Block(-6,29,-3,162:12)
Block(-6,29,-2,162:12)
Block(-6,29,-1,162:12)
Block(-6,29,0,162:12)
Block(-6,29,1,162:12)
Block(-6,29,2,162:12)
Block(-6,29,10,162:12)
Block(-6,29,11,162:12)
Block(-6,29,12,162:12)
Block(-6,29,13,162:12)
Block(-6,29,14,162:12)
Block(-6,30,-5,161:1)
Block(-6,30,-4,162:12)
Block(-6,30,-3,162:12)
Block(-6,30,-2,162:12)
Block(-6,30,-1,162:12)
Block(-6,30,0,162:12)
Block(-6,30,1,162:12)
Block(-6,30,12,161:1)
Block(-6,30,13,162:12)
Block(-6,30,14,162:12)
Block(-6,30,15,162:12)
Block(-6,30,16,162:12)
Block(-6,31,-5,161:1)
Block(-6,31,-4,162:12)
Block(-6,31,-3,162:12)
Block(-6,31,-2,162:12)
Block(-6,31,-1,162:12)
Block(-6,31,0,162:12)
Block(-6,31,13,161:1)
Block(-6,31,14,162:12)
Block(-6,31,15,162:12)
Block(-6,31,16,162:12)
Block(-6,31,17,162:12)
Block(-6,31,18,161:1)
Block(-6,32,-6,162:12)
Block(-6,32,-5,162:12)
Block(-6,32,-4,162:12)
Block(-6,32,-3,162:12)
Block(-6,32,-2,162:12)
Block(-6,32,-1,162:12)
Block(-6,32,14,162:12)
Block(-6,32,15,162:12)
Block(-6,32,16,162:12)
Block(-6,32,17,162:12)
Block(-6,32,18,161:1)
Block(-6,33,-7,162:12)
Block(-6,33,-6,162:12)
Block(-6,33,-5,162:12)
Block(-6,33,-4,162:12)
Block(-6,33,-3,162:12)
Block(-6,33,-2,162:12)
Block(-6,33,-1,162:12)
Block(-6,33,16,162:12)
Block(-6,33,17,162:12)
Block(-6,33,18,162:12)
Block(-6,33,19,161:1)
Block(-6,34,-8,162:12)
Block(-6,34,-7,162:12)
Block(-6,34,-6,162:12)
Block(-6,34,-5,162:12)
Block(-6,34,17,162:12)
Block(-6,34,18,162:12)
Block(-6,34,19,162:12)
Block(-6,35,-10,162:12)
Block(-6,35,-9,162:12)
Block(-6,35,-8,162:12)
Block(-6,35,-7,162:12)
Block(-6,35,-6,162:12)
Block(-6,35,-5,162:12)
Block(-6,35,17,30)
Block(-6,35,18,162:12)
Block(-6,35,19,162:12)
Block(-6,36,-12,162:12)
Block(-6,36,-11,162:12)
Block(-6,36,-10,162:12)
Block(-6,36,-9,162:12)
Block(-6,36,-8,162:12)
Block(-6,36,-7,162:12)
Block(-6,36,-6,162:12)
Block(-6,36,18,30)
Block(-6,36,20,162:12)
Block(-6,37,-12,162:12)
Block(-6,37,-11,162:12)
Block(-6,37,-10,162:12)
Block(-6,37,-9,162:12)
Block(-6,37,-8,162:12)
Block(-6,37,-7,162:12)
Block(-6,37,-6,162:12)
Block(-6,37,20,162:12)
Block(-6,38,-13,162:12)
Block(-6,38,-12,162:12)
Block(-6,38,-11,162:12)
Block(-6,38,-10,162:12)
Block(-6,38,-9,162:12)
Block(-6,38,-8,162:12)
Block(-6,38,-7,162:12)
Block(-6,39,-13,162:12)
Block(-6,39,-12,162:12)
Block(-6,39,-11,162:12)
Block(-6,39,-10,162:12)
Block(-6,39,-9,162:12)
Block(-6,40,-14,162:12)
Block(-6,40,-13,162:12)
Block(-6,40,-12,162:12)
Block(-6,40,-11,162:12)
Block(-6,40,-10,162:12)
Block(-6,41,-14,162:12)
Block(-6,41,-13,162:12)
Block(-6,41,-12,162:12)
Block(-6,41,-11,162:12)
Block(-6,42,-14,162:12)
Block(-6,42,-13,162:12)
Block(-6,42,-12,162:12)
Block(-6,42,-11,162:12)
Block(-6,43,-13,161:1)
Block(-6,43,-11,161:1)
Block(-6,44,-21,162:12)
Block(-6,44,-20,162:12)
Block(-6,45,-22,162:12)
Block(-6,45,-21,162:12)
Block(-6,45,-20,162:12)
Block(-6,45,-19,162:12)
Block(-6,46,-23,162:12)
Block(-6,46,-22,162:12)
Block(-6,46,-21,162:12)
Block(-6,46,-20,162:12)
Block(-6,46,-19,162:12)
Block(-6,47,-23,161:1)
Block(-6,47,-22,162:12)
Block(-6,47,-21,162:12)
Block(-6,47,-20,162:12)
Block(-6,47,-19,161:1)
Block(-6,48,-22,161:1)
Block(-6,48,-21,162:12)
Block(-6,48,-20,161:1)
Block(-5,2,11,162:12)
Block(-5,3,5,162:12)
Block(-5,3,6,162:12)
Block(-5,3,7,162:12)
Block(-5,3,8,162:12)
Block(-5,3,9,162:12)
Block(-5,3,10,162:12)
Block(-5,3,11,162:12)
Block(-5,4,5,162:12)
Block(-5,4,6,162:12)
Block(-5,4,7,162:12)
Block(-5,4,8,162:12)
Block(-5,4,9,162:12)
Block(-5,4,10,162:12)
Block(-5,4,11,162:12)
Block(-5,5,5,162:12)
Block(-5,5,6,162:12)
Block(-5,5,7,162:12)
Block(-5,5,8,162:12)
Block(-5,5,9,162:12)
Block(-5,5,10,162:12)
Block(-5,5,11,162:12)
Block(-5,5,12,162:12)
Block(-5,6,5,162:12)
Block(-5,6,6,162:12)
Block(-5,6,7,162:12)
Block(-5,6,8,162:12)
Block(-5,6,9,162:12)
Block(-5,6,10,162:12)
Block(-5,6,11,162:12)
Block(-5,6,12,162:12)
Block(-5,6,13,162:12)
Block(-5,7,5,162:12)
Block(-5,7,6,162:12)
Block(-5,7,7,162:12)
Block(-5,7,8,162:12)
Block(-5,7,9,162:12)
Block(-5,7,10,162:12)
Block(-5,7,11,162:12)
Block(-5,7,12,162:12)
Block(-5,7,13,162:12)
Block(-5,8,5,162:12)
Block(-5,8,6,162:12)
Block(-5,8,7,162:12)
Block(-5,8,8,162:12)
Block(-5,8,9,162:12)
Block(-5,8,10,162:12)
Block(-5,8,11,162:12)
Block(-5,8,12,162:12)
Block(-5,8,13,162:12)
Block(-5,9,6,162:12)
Block(-5,9,7,162:12)
Block(-5,9,8,162:12)
Block(-5,9,9,162:12)
Block(-5,9,10,162:12)
Block(-5,9,11,162:12)
Block(-5,9,12,162:12)
Block(-5,9,13,162:12)
Block(-5,10,6,162:12)
Block(-5,10,7,162:12)
Block(-5,10,8,162:12)
Block(-5,10,9,162:12)
Block(-5,10,10,162:12)
Block(-5,10,11,162:12)
Block(-5,10,12,162:12)
Block(-5,10,13,162:12)
Block(-5,10,14,162:12)
Block(-5,11,6,162:12)
Block(-5,11,7,162:12)
Block(-5,11,8,162:12)
Block(-5,11,9,162:12)
Block(-5,11,10,162:12)
Block(-5,11,11,162:12)
Block(-5,11,12,162:12)
Block(-5,11,13,162:12)
Block(-5,11,14,162:12)
Block(-5,12,6,162:12)
Block(-5,12,7,162:12)
Block(-5,12,8,162:12)
Block(-5,12,9,162:12)
Block(-5,12,10,162:12)
Block(-5,12,11,162:12)
Block(-5,12,12,162:12)
Block(-5,12,13,162:12)
Block(-5,12,14,162:12)
Block(-5,13,6,162:12)
Block(-5,13,7,162:12)
Block(-5,13,8,162:12)
Block(-5,13,9,162:12)
Block(-5,13,10,162:12)
Block(-5,13,11,162:12)
Block(-5,13,12,162:12)
Block(-5,13,13,162:12)
Block(-5,14,6,162:12)
Block(-5,14,7,162:12)
Block(-5,14,8,162:12)
Block(-5,14,9,162:12)
Block(-5,14,10,162:12)
Block(-5,14,11,162:12)
Block(-5,14,12,162:12)
Block(-5,14,13,162:12)
Block(-5,15,5,162:12)
Block(-5,15,6,162:12)
Block(-5,15,7,162:12)
Block(-5,15,8,162:12)
Block(-5,15,9,162:12)
Block(-5,15,10,162:12)
Block(-5,15,11,162:12)
Block(-5,15,12,162:12)
Block(-5,15,13,162:12)
Block(-5,16,6,162:12)
Block(-5,16,7,162:12)
Block(-5,16,8,162:12)
Block(-5,16,9,162:12)
Block(-5,16,10,162:12)
Block(-5,16,11,162:12)
Block(-5,16,12,162:12)
Block(-5,17,5,162:12)
Block(-5,17,6,162:12)
Block(-5,17,7,162:12)
Block(-5,17,8,162:12)
Block(-5,17,9,162:12)
Block(-5,17,10,162:12)
Block(-5,17,11,162:12)
Block(-5,18,5,162:12)
Block(-5,18,6,162:12)
Block(-5,18,7,162:12)
Block(-5,18,8,162:12)
Block(-5,18,9,162:12)
Block(-5,18,10,162:12)
Block(-5,18,11,162:12)
Block(-5,19,4,162:12)
Block(-5,19,5,162:12)
Block(-5,19,6,162:12)
Block(-5,19,7,162:12)
Block(-5,19,8,162:12)
Block(-5,19,9,162:12)
Block(-5,19,10,162:12)
Block(-5,19,11,162:12)
Block(-5,20,4,162:12)
Block(-5,20,5,162:12)
Block(-5,20,6,162:12)
Block(-5,20,7,162:12)
Block(-5,20,8,162:12)
Block(-5,20,9,162:12)
Block(-5,20,10,162:12)
Block(-5,21,3,162:12)
Block(-5,21,4,162:12)
Block(-5,21,5,162:12)
Block(-5,21,6,162:12)
Block(-5,21,7,162:12)
Block(-5,21,8,162:12)
Block(-5,21,9,162:12)
Block(-5,21,10,162:12)
Block(-5,22,2,162:12)
Block(-5,22,3,162:12)
Block(-5,22,4,162:12)
Block(-5,22,5,162:12)
Block(-5,22,6,162:12)
Block(-5,22,7,162:12)
Block(-5,22,8,162:12)
Block(-5,22,9,162:12)
Block(-5,22,10,162:12)
Block(-5,23,2,162:12)
Block(-5,23,3,162:12)
Block(-5,23,4,162:12)
Block(-5,23,5,162:12)
Block(-5,23,6,162:12)
Block(-5,23,7,162:12)
Block(-5,23,8,162:12)
Block(-5,23,9,162:12)
Block(-5,23,10,162:12)
Block(-5,23,11,162:12)
Block(-5,24,0,162:12)
Block(-5,24,1,162:12)
Block(-5,24,2,162:12)
Block(-5,24,3,162:12)
Block(-5,24,4,162:12)
Block(-5,24,5,162:12)
Block(-5,24,6,162:12)
Block(-5,24,7,162:12)
Block(-5,24,8,162:12)
Block(-5,24,9,162:12)
Block(-5,24,10,162:12)
Block(-5,24,11,162:12)
Block(-5,24,12,162:12)
Block(-5,25,-1,162:12)
Block(-5,25,0,162:12)
Block(-5,25,1,162:12)
Block(-5,25,2,162:12)
Block(-5,25,3,162:12)
Block(-5,25,4,162:12)
Block(-5,25,5,162:12)
Block(-5,25,6,162:12)
Block(-5,25,7,162:12)
Block(-5,25,8,162:12)
Block(-5,25,9,162:12)
Block(-5,25,10,162:12)
Block(-5,25,11,162:12)
Block(-5,25,12,162:12)
Block(-5,25,13,162:12)
Block(-5,26,-2,162:12)
Block(-5,26,-1,162:12)
Block(-5,26,0,162:12)
Block(-5,26,1,162:12)
Block(-5,26,2,162:12)
Block(-5,26,3,162:12)
Block(-5,26,4,162:12)
Block(-5,26,5,162:12)
Block(-5,26,6,162:12)
Block(-5,26,7,162:12)
Block(-5,26,8,162:12)
Block(-5,26,9,162:12)
Block(-5,26,10,162:12)
Block(-5,26,11,162:12)
Block(-5,26,12,162:12)
Block(-5,26,13,162:12)
Block(-5,26,14,162:12)
Block(-5,27,-3,162:12)
Block(-5,27,-2,162:12)
Block(-5,27,-1,162:12)
Block(-5,27,0,162:12)
Block(-5,27,1,162:12)
Block(-5,27,2,162:12)
Block(-5,27,3,162:12)
Block(-5,27,6,162:12)
Block(-5,27,7,162:12)
Block(-5,27,8,162:12)
Block(-5,27,9,162:12)
Block(-5,27,10,162:12)
Block(-5,27,11,162:12)
Block(-5,27,12,162:12)
Block(-5,27,13,162:12)
Block(-5,27,14,162:12)
Block(-5,28,-4,162:12)
Block(-5,28,-3,162:12)
Block(-5,28,-2,162:12)
Block(-5,28,-1,162:12)
Block(-5,28,0,162:12)
Block(-5,28,1,162:12)
Block(-5,28,2,162:12)
Block(-5,28,6,162:12)
Block(-5,28,7,162:12)
Block(-5,28,8,162:12)
Block(-5,28,9,162:12)
Block(-5,28,10,162:12)
Block(-5,28,11,162:12)
Block(-5,28,12,162:12)
Block(-5,28,13,162:12)
Block(-5,28,14,162:12)
Block(-5,28,15,162:12)
Block(-5,29,-4,162:12)
Block(-5,29,-3,162:12)
Block(-5,29,-2,162:12)
Block(-5,29,-1,162:12)
Block(-5,29,0,162:12)
Block(-5,29,1,162:12)
Block(-5,29,7,161:1)
Block(-5,29,8,161:1)
Block(-5,29,9,162:12)
Block(-5,29,10,162:12)
Block(-5,29,11,162:12)
Block(-5,29,12,162:12)
Block(-5,29,13,162:12)
Block(-5,29,14,162:12)
Block(-5,29,15,162:12)
Block(-5,29,16,162:12)
Block(-5,29,17,161:1)
Block(-5,30,-4,162:12)
Block(-5,30,-3,162:12)
Block(-5,30,-2,162:12)
Block(-5,30,-1,162:12)
Block(-5,30,0,162:12)
Block(-5,30,10,162:12)
Block(-5,30,11,162:12)
Block(-5,30,12,162:12)
Block(-5,30,13,162:12)
Block(-5,30,14,162:12)
Block(-5,30,15,162:12)
Block(-5,30,16,162:12)
Block(-5,30,17,162:12)
Block(-5,31,-9,161:1)
Block(-5,31,-5,162:12)
Block(-5,31,-4,162:12)
Block(-5,31,-3,162:12)
Block(-5,31,-2,162:12)
Block(-5,31,-1,162:12)
Block(-5,31,12,162:12)
Block(-5,31,13,162:12)
Block(-5,31,14,162:12)
Block(-5,31,15,162:12)
Block(-5,31,16,162:12)
Block(-5,31,17,162:12)
Block(-5,32,-9,161:1)
Block(-5,32,-6,162:12)
Block(-5,32,-5,162:12)
Block(-5,32,-4,162:12)
Block(-5,32,-3,162:12)
Block(-5,32,-2,162:12)
Block(-5,32,-1,162:12)
Block(-5,32,13,162:12)
Block(-5,32,14,162:12)
Block(-5,32,15,162:12)
Block(-5,32,16,162:12)
Block(-5,32,17,162:12)
Block(-5,32,18,162:12)
Block(-5,32,19,161:1)
Block(-5,33,-9,161:1)
Block(-5,33,-7,162:12)
Block(-5,33,-6,162:12)
Block(-5,33,-5,162:12)
Block(-5,33,-4,162:12)
Block(-5,33,-3,162:12)
Block(-5,33,-2,162:12)
Block(-5,33,15,162:12)
Block(-5,33,16,162:12)
Block(-5,33,17,162:12)
Block(-5,33,18,162:12)
Block(-5,33,19,162:12)
Block(-5,33,20,161:1)
Block(-5,34,-9,161:1)
Block(-5,34,-8,162:12)
Block(-5,34,-7,162:12)
Block(-5,34,-6,162:12)
Block(-5,34,-5,162:12)
Block(-5,34,-4,161:1)
Block(-5,34,-3,161:1)
Block(-5,34,-2,161:1)
Block(-5,34,17,162:12)
Block(-5,34,18,162:12)
Block(-5,34,19,162:12)
Block(-5,35,-9,162:12)
Block(-5,35,-8,162:12)
Block(-5,35,-7,162:12)
Block(-5,35,-6,162:12)
Block(-5,35,-5,162:12)
Block(-5,36,-12,161:1)
Block(-5,36,-11,162:12)
Block(-5,36,-10,162:12)
Block(-5,36,-9,162:12)
Block(-5,36,-8,162:12)
Block(-5,36,-7,162:12)
Block(-5,37,-12,161:1)
Block(-5,37,-10,162:12)
Block(-5,37,-9,162:12)
Block(-5,37,-8,162:12)
Block(-5,37,-7,162:12)
Block(-5,38,-12,161:1)
Block(-5,38,-11,162:12)
Block(-5,38,-10,162:12)
Block(-5,38,-9,162:12)
Block(-5,38,-8,162:12)
Block(-5,38,-7,162:12)
Block(-5,39,-12,161:1)
Block(-5,39,-11,162:12)
Block(-5,39,-10,162:12)
Block(-5,40,-13,162:12)
Block(-5,40,-12,162:12)
Block(-5,40,-11,162:12)
Block(-5,41,-13,162:12)
Block(-5,41,-12,162:12)
Block(-5,41,-11,162:12)
Block(-5,45,-22,162:12)
Block(-5,45,-21,162:12)
Block(-5,45,-20,162:12)
Block(-5,46,-23,161:1)
Block(-5,46,-22,162:12)
Block(-5,46,-21,162:12)
Block(-5,46,-20,162:12)
Block(-5,47,-23,161:1)
Block(-5,47,-22,162:12)
Block(-5,47,-21,162:12)
Block(-5,47,-20,162:12)
Block(-5,48,-22,162:12)
Block(-5,48,-21,162:12)
Block(-5,48,-20,161:1)
Block(-5,49,-22,161:1)
Block(-5,49,-21,161:1)
Block(-4,0,4,162:12)
Block(-4,1,12,161:1)
Block(-4,1,13,162:12)
Block(-4,2,5,162:12)
Block(-4,2,6,162:12)
Block(-4,2,8,162:12)
Block(-4,2,9,161:1)
Block(-4,2,10,162:12)
Block(-4,2,11,162:12)
Block(-4,2,12,162:12)
Block(-4,3,5,162:12)
Block(-4,3,6,162:12)
Block(-4,3,7,162:12)
Block(-4,3,8,162:12)
Block(-4,3,9,162:12)
Block(-4,3,10,162:12)
Block(-4,3,11,162:12)
Block(-4,3,12,162:12)
Block(-4,3,13,162:12)
Block(-4,4,5,162:12)
Block(-4,4,6,162:12)
Block(-4,4,7,162:12)
Block(-4,4,8,162:12)
Block(-4,4,9,162:12)
Block(-4,4,10,162:12)
Block(-4,4,11,162:12)
Block(-4,4,12,162:12)
Block(-4,5,5,162:12)
Block(-4,5,6,162:12)
Block(-4,5,7,162:12)
Block(-4,5,8,162:12)
Block(-4,5,9,162:12)
Block(-4,5,10,162:12)
Block(-4,5,11,162:12)
Block(-4,5,12,162:12)
Block(-4,6,5,162:12)
Block(-4,6,6,162:12)
Block(-4,6,7,162:12)
Block(-4,6,8,162:12)
Block(-4,6,9,162:12)
Block(-4,6,10,162:12)
Block(-4,6,11,162:12)
Block(-4,6,12,162:12)
Block(-4,7,5,162:12)
Block(-4,7,6,162:12)
Block(-4,7,7,162:12)
Block(-4,7,8,162:12)
Block(-4,7,9,162:12)
Block(-4,7,10,162:12)
Block(-4,7,11,162:12)
Block(-4,7,12,162:12)
Block(-4,7,13,162:12)
Block(-4,8,6,162:12)
Block(-4,8,7,162:12)
Block(-4,8,8,162:12)
Block(-4,8,9,162:12)
Block(-4,8,10,162:12)
Block(-4,8,11,162:12)
Block(-4,8,12,162:12)
Block(-4,8,13,162)
Block(-4,9,6,162:12)
Block(-4,9,7,162:12)
Block(-4,9,8,162:12)
Block(-4,9,9,162:12)
Block(-4,9,10,162:12)
Block(-4,9,11,162:12)
Block(-4,9,12,162:12)
Block(-4,9,13,162:12)
Block(-4,10,6,162:12)
Block(-4,10,7,162:12)
Block(-4,10,8,162:12)
Block(-4,10,9,162:12)
Block(-4,10,10,162:12)
Block(-4,10,11,162:12)
Block(-4,10,12,162:12)
Block(-4,10,13,162:12)
Block(-4,11,6,162:12)
Block(-4,11,7,162:12)
Block(-4,11,8,162:12)
Block(-4,11,9,162:12)
Block(-4,11,10,162:12)
Block(-4,11,11,162:12)
Block(-4,11,12,162:12)
Block(-4,11,13,162:12)
Block(-4,11,14,162:12)
Block(-4,12,6,39)
Block(-4,12,7,162:12)
Block(-4,12,8,162:12)
Block(-4,12,9,162:12)
Block(-4,12,10,162:12)
Block(-4,12,11,162:12)
Block(-4,12,12,162:12)
Block(-4,12,13,162:12)
Block(-4,13,7,162:12)
Block(-4,13,8,162:12)
Block(-4,13,9,162:12)
Block(-4,13,10,162:12)
Block(-4,13,11,162:12)
Block(-4,13,12,162:12)
Block(-4,13,13,162:12)
Block(-4,14,7,162:12)
Block(-4,14,8,162:12)
Block(-4,14,9,162:12)
Block(-4,14,10,162:12)
Block(-4,14,11,162:12)
Block(-4,14,12,162:12)
Block(-4,15,7,162:12)
Block(-4,15,8,162:12)
Block(-4,15,9,162:12)
Block(-4,15,10,162:12)
Block(-4,15,11,162:12)
Block(-4,15,12,162:12)
Block(-4,16,7,162:12)
Block(-4,16,8,162:12)
Block(-4,16,9,162:12)
Block(-4,16,10,162:12)
Block(-4,16,11,162:12)
Block(-4,17,6,162:12)
Block(-4,17,7,162:12)
Block(-4,17,8,162:12)
Block(-4,17,9,162:12)
Block(-4,17,10,162:12)
Block(-4,17,11,162:12)
Block(-4,18,6,162:12)
Block(-4,18,7,162:12)
Block(-4,18,8,162:12)
Block(-4,18,9,162:12)
Block(-4,18,10,162:12)
Block(-4,19,4,162:12)
Block(-4,19,5,162:12)
Block(-4,19,6,162:12)
Block(-4,19,7,162:12)
Block(-4,19,8,162:12)
Block(-4,19,9,162:12)
Block(-4,19,10,162:12)
Block(-4,20,6,162:12)
Block(-4,20,7,162:12)
Block(-4,20,8,162:12)
Block(-4,20,9,162:12)
Block(-4,21,4,162:12)
Block(-4,21,5,162:12)
Block(-4,21,6,162:12)
Block(-4,21,7,162:12)
Block(-4,21,8,162:12)
Block(-4,21,9,162:12)
Block(-4,22,3,162:12)
Block(-4,22,4,162:12)
Block(-4,22,5,162:12)
Block(-4,22,6,162:12)
Block(-4,22,7,162:12)
Block(-4,22,8,162:12)
Block(-4,22,9,162:12)
Block(-4,23,2,162:12)
Block(-4,23,3,162:12)
Block(-4,23,4,162:12)
Block(-4,23,5,162:12)
Block(-4,23,6,162:12)
Block(-4,23,7,162:12)
Block(-4,23,8,162:12)
Block(-4,23,9,162:12)
Block(-4,23,10,162:12)
Block(-4,23,11,162:12)
Block(-4,24,1,162:12)
Block(-4,24,2,162:12)
Block(-4,24,3,162:12)
Block(-4,24,4,162:12)
Block(-4,24,5,162:12)
Block(-4,24,6,162:12)
Block(-4,24,7,162:12)
Block(-4,24,8,162:12)
Block(-4,24,9,162:12)
Block(-4,24,10,162:12)
Block(-4,24,11,162:12)
Block(-4,24,12,162:12)
Block(-4,25,0,162:12)
Block(-4,25,1,162:12)
Block(-4,25,2,162:12)
Block(-4,25,3,162:12)
Block(-4,25,4,162:12)
Block(-4,25,5,162:12)
Block(-4,25,6,162:12)
Block(-4,25,7,162:12)
Block(-4,25,8,162:12)
Block(-4,25,9,162:12)
Block(-4,25,10,162:12)
Block(-4,25,11,162:12)
Block(-4,25,12,162:12)
Block(-4,25,13,162:12)
Block(-4,26,-1,162:12)
Block(-4,26,0,162:12)
Block(-4,26,1,162:12)
Block(-4,26,2,162:12)
Block(-4,26,3,162:12)
Block(-4,26,4,162:12)
Block(-4,26,5,162:12)
Block(-4,26,6,162:12)
Block(-4,26,7,162:12)
Block(-4,26,8,162:12)
Block(-4,26,9,162:12)
Block(-4,26,10,162:12)
Block(-4,26,11,162:12)
Block(-4,26,12,162:12)
Block(-4,26,13,162:12)
Block(-4,27,-3,162:12)
Block(-4,27,-2,162:12)
Block(-4,27,-1,162:12)
Block(-4,27,0,162:12)
Block(-4,27,1,162:12)
Block(-4,27,2,162:12)
Block(-4,27,6,162:12)
Block(-4,27,7,162:12)
Block(-4,27,8,162:12)
Block(-4,27,9,162:12)
Block(-4,27,10,162:12)
Block(-4,27,11,162:12)
Block(-4,27,12,162:12)
Block(-4,27,13,162:12)
Block(-4,27,14,162:12)
Block(-4,27,15,162:12)
Block(-4,27,16,161:1)
Block(-4,28,-4,162:12)
Block(-4,28,-3,162:12)
Block(-4,28,-2,162:12)
Block(-4,28,-1,162:12)
Block(-4,28,0,162:12)
Block(-4,28,1,162:12)
Block(-4,28,8,162:12)
Block(-4,28,9,162:12)
Block(-4,28,10,162:12)
Block(-4,28,11,162:12)
Block(-4,28,12,162:12)
Block(-4,28,13,162:12)
Block(-4,28,14,162:12)
Block(-4,28,15,162:12)
Block(-4,28,16,162:12)
Block(-4,29,-5,162:12)
Block(-4,29,-4,162:12)
Block(-4,29,-3,162:12)
Block(-4,29,-2,162:12)
Block(-4,29,-1,162:12)
Block(-4,29,0,162:12)
Block(-4,29,1,162:12)
Block(-4,29,9,161:1)
Block(-4,29,10,162:12)
Block(-4,29,11,162:12)
Block(-4,29,12,162:12)
Block(-4,29,13,162:12)
Block(-4,29,14,162:12)
Block(-4,29,15,162:12)
Block(-4,29,16,162:12)
Block(-4,29,17,162:12)
Block(-4,30,-5,162:12)
Block(-4,30,-4,162:12)
Block(-4,30,-3,162:12)
Block(-4,30,-2,162:12)
Block(-4,30,-1,162:12)
Block(-4,30,0,162:12)
Block(-4,30,1,162:12)
Block(-4,30,11,162:12)
Block(-4,30,12,162:12)
Block(-4,30,13,162:12)
Block(-4,30,14,162:12)
Block(-4,30,15,162:12)
Block(-4,30,16,162:12)
Block(-4,30,17,162:12)
Block(-4,30,18,161:1)
Block(-4,31,-8,161:1)
Block(-4,31,-6,162:12)
Block(-4,31,-5,162:12)
Block(-4,31,-4,162:12)
Block(-4,31,-3,162:12)
Block(-4,31,-2,162:12)
Block(-4,31,-1,162:12)
Block(-4,31,0,162:12)
Block(-4,31,11,162:12)
Block(-4,31,12,162:12)
Block(-4,31,13,162:12)
Block(-4,31,14,162:12)
Block(-4,31,15,162:12)
Block(-4,31,16,162:12)
Block(-4,31,17,162:12)
Block(-4,31,18,161:1)
Block(-4,32,-8,161:1)
Block(-4,32,-6,162:12)
Block(-4,32,-5,162:12)
Block(-4,32,-4,162:12)
Block(-4,32,-3,162:12)
Block(-4,32,-2,162:12)
Block(-4,32,-1,162:12)
Block(-4,32,12,162:12)
Block(-4,32,13,162:12)
Block(-4,32,14,162:12)
Block(-4,32,15,162:12)
Block(-4,32,16,162:12)
Block(-4,32,17,162:12)
Block(-4,32,18,162:12)
Block(-4,32,19,161:1)
Block(-4,33,-8,161:1)
Block(-4,33,-6,162:12)
Block(-4,33,-5,162:12)
Block(-4,33,-4,162:12)
Block(-4,33,-3,162:12)
Block(-4,33,-2,162:12)
Block(-4,33,-1,161:1)
Block(-4,33,13,162:12)
Block(-4,33,14,162:12)
Block(-4,33,15,162:12)
Block(-4,33,16,162:12)
Block(-4,33,17,162:12)
Block(-4,33,18,162:12)
Block(-4,33,19,161:1)
Block(-4,34,-8,161:1)
Block(-4,34,-7,162:12)
Block(-4,34,-6,162:12)
Block(-4,34,-5,162:12)
Block(-4,34,-4,162:12)
Block(-4,34,-3,162:12)
Block(-4,34,-2,161:1)
Block(-4,35,-7,162:12)
Block(-4,35,-4,161:1)
Block(-4,35,-3,162:12)
Block(-4,36,-8,162:12)
Block(-4,36,-3,161:1)
Block(-4,37,-9,162:12)
Block(-4,37,-8,162:12)
Block(-4,43,-20,161:1)
Block(-4,44,-25,161:1)
Block(-4,44,-20,161:1)
Block(-4,45,-25,161:1)
Block(-4,45,-20,161:1)
Block(-4,46,-25,161:1)
Block(-4,46,-23,162:12)
Block(-4,46,-22,162:12)
Block(-4,46,-21,162:12)
Block(-4,46,-20,161:1)
Block(-4,47,-25,161:1)
Block(-4,47,-24,162:12)
Block(-4,47,-23,162:12)
Block(-4,47,-22,162:12)
Block(-4,47,-21,162:12)
Block(-4,47,-20,161:1)
Block(-4,48,-24,161:1)
Block(-4,48,-23,162:12)
Block(-4,48,-22,161:1)
Block(-4,48,-21,161:1)
Block(-3,0,3,162:12)
Block(-3,0,4,162:12)
Block(-3,0,5,162:12)
Block(-3,0,13,162:12)
Block(-3,0,14,162:12)
Block(-3,1,3,162:12)
Block(-3,1,4,162:12)
Block(-3,1,5,162:12)
Block(-3,1,6,162:12)
Block(-3,1,12,162:12)
Block(-3,1,13,162:12)
Block(-3,1,14,162:12)
Block(-3,2,4,162:12)
Block(-3,2,5,162:12)
Block(-3,2,6,162:12)
Block(-3,2,7,162:12)
Block(-3,2,8,162:12)
Block(-3,2,9,162:12)
Block(-3,2,10,162:12)
Block(-3,2,11,162:12)
Block(-3,2,12,162:12)
Block(-3,2,13,162:12)
Block(-3,2,14,162:12)
Block(-3,3,4,162:12)
Block(-3,3,5,162:12)
Block(-3,3,6,162:12)
Block(-3,3,7,162:12)
Block(-3,3,8,162:12)
Block(-3,3,9,162:12)
Block(-3,3,10,162:12)
Block(-3,3,11,162:12)
Block(-3,3,12,162:12)
Block(-3,3,13,162:12)
Block(-3,4,5,162:12)
Block(-3,4,6,162:12)
Block(-3,4,7,162:12)
Block(-3,4,8,162:12)
Block(-3,4,9,162:12)
Block(-3,4,10,162:12)
Block(-3,4,11,162:12)
Block(-3,4,12,162:12)
Block(-3,5,5,162:12)
Block(-3,5,6,162:12)
Block(-3,5,7,162:12)
Block(-3,5,8,162:12)
Block(-3,5,9,162:12)
Block(-3,5,10,162:12)
Block(-3,5,11,162:12)
Block(-3,5,12,162:12)
Block(-3,6,5,161:1)
Block(-3,6,6,161:1)
Block(-3,6,7,162:12)
Block(-3,6,8,162:12)
Block(-3,6,9,162:12)
Block(-3,6,10,162:12)
Block(-3,6,11,162:12)
Block(-3,7,6,162:12)
Block(-3,7,7,162:12)
Block(-3,7,8,162:12)
Block(-3,7,9,162:12)
Block(-3,7,10,162:12)
Block(-3,7,11,162:12)
Block(-3,7,12,162:12)
Block(-3,8,7,162:12)
Block(-3,8,8,162:12)
Block(-3,8,9,162:12)
Block(-3,8,10,162:12)
Block(-3,8,11,162:12)
Block(-3,8,12,162)
Block(-3,9,7,162:12)
Block(-3,9,8,162:12)
Block(-3,9,9,162:12)
Block(-3,9,10,162:12)
Block(-3,9,11,162:12)
Block(-3,9,12,162:12)
Block(-3,10,7,162:12)
Block(-3,10,8,162:12)
Block(-3,10,9,162:12)
Block(-3,10,10,162:12)
Block(-3,10,11,162:12)
Block(-3,10,12,162:12)
Block(-3,10,13,30)
Block(-3,11,7,162:12)
Block(-3,11,8,162:12)
Block(-3,11,9,162:12)
Block(-3,11,10,162:12)
Block(-3,11,11,162:12)
Block(-3,11,12,162:12)
Block(-3,11,13,162:12)
Block(-3,12,7,39)
Block(-3,12,8,162:12)
Block(-3,12,9,162:12)
Block(-3,12,10,162:12)
Block(-3,12,11,162:12)
Block(-3,12,12,162:12)
Block(-3,13,8,162:12)
Block(-3,13,9,162:12)
Block(-3,13,10,162:12)
Block(-3,13,11,162:12)
Block(-3,13,12,162:12)
Block(-3,14,7,30)
Block(-3,14,8,162:12)
Block(-3,14,9,162:12)
Block(-3,14,10,162:12)
Block(-3,14,11,162:12)
Block(-3,15,7,162:12)
Block(-3,15,8,162:12)
Block(-3,15,9,162:12)
Block(-3,15,10,162:12)
Block(-3,15,11,162:12)
Block(-3,16,7,162)
Block(-3,16,8,162:12)
Block(-3,16,9,162:12)
Block(-3,16,10,162:12)
Block(-3,17,7,162:12)
Block(-3,17,8,162:12)
Block(-3,17,9,162:12)
Block(-3,17,10,162:12)
Block(-3,18,7,162:12)
Block(-3,18,8,162:12)
Block(-3,18,9,162:12)
Block(-3,19,6,162:12)
Block(-3,19,7,162:12)
Block(-3,19,8,162:12)
Block(-3,19,9,162:12)
Block(-3,20,6,162:12)
Block(-3,20,7,162:12)
Block(-3,20,8,162:12)
Block(-3,21,6,162:12)
Block(-3,21,7,162:12)
Block(-3,21,8,162:12)
Block(-3,22,4,161:1)
Block(-3,22,5,162:12)
Block(-3,22,6,162:12)
Block(-3,22,7,162:12)
Block(-3,22,8,162:12)
Block(-3,23,3,162:12)
Block(-3,23,4,161:1)
Block(-3,23,5,162:12)
Block(-3,23,6,162:12)
Block(-3,23,7,162:12)
Block(-3,23,8,162:12)
Block(-3,23,9,162:12)
Block(-3,23,10,162:12)
Block(-3,24,1,162:12)
Block(-3,24,2,162:12)
Block(-3,24,3,162:12)
Block(-3,24,4,162:12)
Block(-3,24,5,162:12)
Block(-3,24,6,162:12)
Block(-3,24,7,162:12)
Block(-3,24,8,162:12)
Block(-3,24,9,162:12)
Block(-3,24,10,162:12)
Block(-3,24,11,162:12)
Block(-3,25,1,162:12)
Block(-3,25,2,162:12)
Block(-3,25,3,162:12)
Block(-3,25,4,162:12)
Block(-3,25,5,162:12)
Block(-3,25,6,162:12)
Block(-3,25,7,162:12)
Block(-3,25,8,162:12)
Block(-3,25,9,162:12)
Block(-3,25,10,162:12)
Block(-3,25,11,162:12)
Block(-3,25,12,162:12)
Block(-3,25,13,162:12)
Block(-3,26,-5,161:1)
Block(-3,26,0,162:12)
Block(-3,26,1,162:12)
Block(-3,26,2,162:12)
Block(-3,26,3,162:12)
Block(-3,26,4,162:12)
Block(-3,26,6,162:12)
Block(-3,26,7,162:12)
Block(-3,26,8,162:12)
Block(-3,26,9,162:12)
Block(-3,26,10,162:12)
Block(-3,26,11,162:12)
Block(-3,26,12,162:12)
Block(-3,26,13,162:12)
Block(-3,26,14,162:12)
Block(-3,26,15,162:12)
Block(-3,26,16,161:1)
Block(-3,27,-5,161:1)
Block(-3,27,-2,162:12)
Block(-3,27,-1,162:12)
Block(-3,27,0,162:12)
Block(-3,27,1,162:12)
Block(-3,27,2,162:12)
Block(-3,27,3,162:12)
Block(-3,27,8,162:12)
Block(-3,27,9,162:12)
Block(-3,27,10,162:12)
Block(-3,27,11,162:12)
Block(-3,27,12,162:12)
Block(-3,27,13,162:12)
Block(-3,27,14,162:12)
Block(-3,27,15,162:12)
Block(-3,27,16,162:12)
Block(-3,27,17,161:1)
Block(-3,28,-5,161:1)
Block(-3,28,-3,162:12)
Block(-3,28,-2,162:12)
Block(-3,28,-1,162:12)
Block(-3,28,0,162:12)
Block(-3,28,1,162:12)
Block(-3,28,9,162:12)
Block(-3,28,10,162:12)
Block(-3,28,11,162:12)
Block(-3,28,12,162:12)
Block(-3,28,13,162:12)
Block(-3,28,14,162:12)
Block(-3,28,15,162:12)
Block(-3,28,16,162:12)
Block(-3,28,17,162:12)
Block(-3,29,-5,161:1)
Block(-3,29,-4,162:12)
Block(-3,29,-3,162:12)
Block(-3,29,-2,162:12)
Block(-3,29,-1,162:12)
Block(-3,29,0,162:12)
Block(-3,29,9,162:12)
Block(-3,29,10,162:12)
Block(-3,29,11,162:12)
Block(-3,29,12,162:12)
Block(-3,29,13,162:12)
Block(-3,29,14,162:12)
Block(-3,29,15,162:12)
Block(-3,29,16,162:12)
Block(-3,29,17,162:12)
Block(-3,30,-5,161:1)
Block(-3,30,-4,162:12)
Block(-3,30,-3,162:12)
Block(-3,30,-2,162:12)
Block(-3,30,-1,162:12)
Block(-3,30,0,162:12)
Block(-3,30,10,162:12)
Block(-3,30,11,162:12)
Block(-3,30,12,162:12)
Block(-3,30,13,162:12)
Block(-3,30,14,162:12)
Block(-3,30,15,162:12)
Block(-3,30,16,162:12)
Block(-3,30,17,162:12)
Block(-3,31,-6,162:12)
Block(-3,31,-5,162:12)
Block(-3,31,-4,162:12)
Block(-3,31,-3,162:12)
Block(-3,31,-2,162:12)
Block(-3,31,-1,162:12)
Block(-3,31,0,162)
Block(-3,31,10,162:12)
Block(-3,31,11,162:12)
Block(-3,31,12,162:12)
Block(-3,31,13,162:12)
Block(-3,31,14,162:12)
Block(-3,31,15,162:12)
Block(-3,31,16,162:12)
Block(-3,31,17,162:12)
Block(-3,31,18,162:12)
Block(-3,32,-6,162:12)
Block(-3,32,-5,162:12)
Block(-3,32,-4,162:12)
Block(-3,32,-3,162:12)
Block(-3,32,-2,162:12)
Block(-3,32,-1,162:12)
Block(-3,32,0,162:12)
Block(-3,32,1,162:12)
Block(-3,32,11,162:12)
Block(-3,32,12,162:12)
Block(-3,32,13,162:12)
Block(-3,32,14,162:12)
Block(-3,32,15,162:12)
Block(-3,32,16,162:12)
Block(-3,32,17,162:12)
Block(-3,32,18,162:12)
Block(-3,33,-5,162:12)
Block(-3,33,-4,162:12)
Block(-3,33,-3,162:12)
Block(-3,33,-2,162:12)
Block(-3,33,-1,162:12)
Block(-3,33,0,162:12)
Block(-3,33,12,162:12)
Block(-3,33,13,162:12)
Block(-3,33,14,162:12)
Block(-3,33,15,162:12)
Block(-3,33,16,161:1)
Block(-3,33,17,161:1)
Block(-3,33,18,161:1)
Block(-3,34,-4,161:1)
Block(-3,34,-3,162:12)
Block(-3,34,-2,162:12)
Block(-3,34,-1,162:12)
Block(-3,34,0,161:1)
Block(-3,35,-3,161:1)
Block(-3,35,-2,162:12)
Block(-3,35,-1,161:1)
Block(-3,46,-24,161:1)
Block(-3,46,-23,162:12)
Block(-3,46,-22,162:12)
Block(-3,47,-23,162:12)
Block(-3,47,-22,162:12)
Block(-3,47,-21,162:12)
Block(-3,48,-23,161:1)
Block(-3,48,-22,162:12)
Block(-3,49,-22,161:1)
Block(-2,0,2,162:12)
Block(-2,0,3,162:12)
Block(-2,0,4,162:12)
Block(-2,0,5,162:12)
Block(-2,0,6,162:12)
Block(-2,0,12,162:12)
Block(-2,0,13,162:12)
Block(-2,0,14,162:12)
Block(-2,0,15,162:12)
Block(-2,1,2,161:1)
Block(-2,1,3,162:12)
Block(-2,1,4,162:12)
Block(-2,1,5,162:12)
Block(-2,1,6,162:12)
Block(-2,1,7,162:12)
Block(-2,1,11,162:12)
Block(-2,1,12,162:12)
Block(-2,1,13,162:12)
Block(-2,1,14,162:12)
Block(-2,1,15,162:12)
Block(-2,2,3,161:1)
Block(-2,2,4,162:12)
Block(-2,2,5,162:12)
Block(-2,2,6,162:12)
Block(-2,2,7,162:12)
Block(-2,2,8,162:12)
Block(-2,2,10,162:12)
Block(-2,2,11,162:12)
Block(-2,2,12,162:12)
Block(-2,2,13,162:12)
Block(-2,2,14,162:12)
Block(-2,3,4,161:1)
Block(-2,3,5,162:12)
Block(-2,3,6,162:12)
Block(-2,3,7,162:12)
Block(-2,3,10,162:12)
Block(-2,3,11,162:12)
Block(-2,3,12,162:12)
Block(-2,3,13,162:12)
Block(-2,4,4,161:1)
Block(-2,4,5,162:12)
Block(-2,4,6,162:12)
Block(-2,4,7,162:12)
Block(-2,4,10,162:12)
Block(-2,4,11,162:12)
Block(-2,5,5,161:1)
Block(-2,5,9,162:12)
Block(-2,5,10,162:12)
Block(-2,5,11,162:12)
Block(-2,6,8,162:12)
Block(-2,6,9,162:12)
Block(-2,6,10,162:12)
Block(-2,7,7,162:12)
Block(-2,7,8,162:12)
Block(-2,7,9,162:12)
Block(-2,7,10,162:12)
Block(-2,7,11,162:12)
Block(-2,8,8,162:12)
Block(-2,8,9,162:12)
Block(-2,8,10,162:12)
Block(-2,8,11,162)
Block(-2,9,8,162:12)
Block(-2,9,9,162:12)
Block(-2,9,10,162:12)
Block(-2,9,11,162:12)
Block(-2,10,8,162:12)
Block(-2,10,9,162:12)
Block(-2,10,10,162:12)
Block(-2,10,11,162:12)
Block(-2,11,8,162:12)
Block(-2,11,9,162:12)
Block(-2,11,10,162:12)
Block(-2,11,11,162:12)
Block(-2,11,12,162:12)
Block(-2,12,9,162:12)
Block(-2,12,10,162:12)
Block(-2,12,11,162:12)
Block(-2,13,9,162:12)
Block(-2,13,10,162:12)
Block(-2,13,11,162:12)
Block(-2,14,9,162:12)
Block(-2,14,10,162:12)
Block(-2,15,8,162:12)
Block(-2,15,9,162:12)
Block(-2,15,10,162:12)
Block(-2,16,7,161:1)
Block(-2,16,8,161:1)
Block(-2,16,9,162:12)
Block(-2,17,7,161:1)
Block(-2,17,8,162:12)
Block(-2,17,9,162:12)
Block(-2,18,8,162:12)
Block(-2,19,8,162:12)
Block(-2,24,5,161:1)
Block(-2,24,8,162:12)
Block(-2,24,10,162:12)
Block(-2,25,1,162:12)
Block(-2,25,2,162:12)
Block(-2,25,6,161:1)
Block(-2,25,9,162:12)
Block(-2,25,10,162:12)
Block(-2,25,11,162:12)
Block(-2,25,12,162:12)
Block(-2,26,0,162:12)
Block(-2,26,1,162:12)
Block(-2,26,2,162:12)
Block(-2,26,3,162:12)
Block(-2,26,9,162:12)
Block(-2,26,10,162:12)
Block(-2,26,11,162:12)
Block(-2,26,12,162:12)
Block(-2,26,13,162:12)
Block(-2,26,14,162:12)
Block(-2,27,-2,162:12)
Block(-2,27,-1,162:12)
Block(-2,27,0,162:12)
Block(-2,27,1,162:12)
Block(-2,27,2,162:12)
Block(-2,27,9,162:12)
Block(-2,27,10,162:12)
Block(-2,27,11,162:12)
Block(-2,27,12,162:12)
Block(-2,27,13,162:12)
Block(-2,27,14,162:12)
Block(-2,27,15,162:12)
Block(-2,28,-3,162:12)
Block(-2,28,-2,162:12)
Block(-2,28,-1,162:12)
Block(-2,28,0,162:12)
Block(-2,28,1,162:12)
Block(-2,28,9,162:12)
Block(-2,28,10,162:12)
Block(-2,28,11,162:12)
Block(-2,28,12,162:12)
Block(-2,28,13,162:12)
Block(-2,28,14,162:12)
Block(-2,28,15,162:12)
Block(-2,28,16,162:12)
Block(-2,29,-5,162:12)
Block(-2,29,-4,162:12)
Block(-2,29,-3,162:12)
Block(-2,29,-2,162:12)
Block(-2,29,-1,162:12)
Block(-2,29,0,162:12)
Block(-2,29,2,161:1)
Block(-2,29,9,162:12)
Block(-2,29,10,162:12)
Block(-2,29,11,162:12)
Block(-2,29,12,162:12)
Block(-2,29,13,162:12)
Block(-2,29,14,162:12)
Block(-2,29,15,162:12)
Block(-2,29,16,162:12)
Block(-2,29,17,162:12)
Block(-2,30,-4,162:12)
Block(-2,30,-3,162:12)
Block(-2,30,-2,162:12)
Block(-2,30,-1,162:12)
Block(-2,30,0,162:12)
Block(-2,30,2,161:1)
Block(-2,30,10,162:12)
Block(-2,30,11,162:12)
Block(-2,30,12,162:12)
Block(-2,30,13,162:12)
Block(-2,30,14,162:12)
Block(-2,30,15,162:12)
Block(-2,30,16,162:12)
Block(-2,30,17,162:12)
Block(-2,30,18,161:1)
Block(-2,31,-5,162:12)
Block(-2,31,-4,162:12)
Block(-2,31,-3,162:12)
Block(-2,31,-2,162:12)
Block(-2,31,-1,162:12)
Block(-2,31,0,162)
Block(-2,31,2,161:1)
Block(-2,31,11,162:12)
Block(-2,31,12,162:12)
Block(-2,31,13,162:12)
Block(-2,31,14,162:12)
Block(-2,31,15,162:12)
Block(-2,31,16,162:12)
Block(-2,31,17,162:12)
Block(-2,31,18,161:1)
Block(-2,32,-4,162:12)
Block(-2,32,-3,162:12)
Block(-2,32,-2,162:12)
Block(-2,32,-1,162:12)
Block(-2,32,0,162:12)
Block(-2,32,2,161:1)
Block(-2,32,12,162:12)
Block(-2,32,13,162:12)
Block(-2,32,14,162:12)
Block(-2,32,15,162:12)
Block(-2,32,16,162:12)
Block(-2,32,17,162:12)
Block(-2,32,18,162:12)
Block(-2,32,19,161:1)
Block(-2,33,-3,162:12)
Block(-2,33,-2,162:12)
Block(-2,33,-1,162:12)
Block(-2,33,0,162:12)
Block(-2,33,1,162:12)
Block(-2,33,2,161:1)
Block(-2,33,13,162:12)
Block(-2,33,14,162:12)
Block(-2,33,15,162:12)
Block(-2,33,16,162:12)
Block(-2,33,17,161:1)
Block(-2,34,-3,161:1)
Block(-2,34,-2,162:12)
Block(-2,34,-1,162:12)
Block(-2,34,0,162:12)
Block(-2,34,1,161:1)
Block(-2,34,16,162:12)
Block(-2,35,-2,161:1)
Block(-2,35,-1,162:12)
Block(-2,35,0,161:1)
Block(-2,36,-1,161:1)
Block(-2,42,30,162:12)
Block(-2,43,29,161:1)
Block(-2,43,30,162:12)
Block(-2,43,31,162:12)
Block(-2,44,30,161:1)
Block(-2,44,31,161:1)
Block(-2,47,-23,162:12)
Block(-2,48,-23,162:12)
Block(-2,48,-22,162:12)
Block(-2,49,-23,161:1)
Block(-2,49,-22,161:1)
Block(-1,0,3,162:12)
Block(-1,0,4,162:12)
Block(-1,0,5,162:12)
Block(-1,0,6,162:12)
Block(-1,0,12,162:12)
Block(-1,0,13,162:12)
Block(-1,0,14,162:12)
Block(-1,0,15,162:12)
Block(-1,0,16,162:12)
Block(-1,1,3,162:12)
Block(-1,1,4,162:12)
Block(-1,1,5,162:12)
Block(-1,1,6,162:12)
Block(-1,1,12,162:12)
Block(-1,1,13,162:12)
Block(-1,1,14,162:12)
Block(-1,1,15,162:12)
Block(-1,2,4,161:1)
Block(-1,2,5,162:12)
Block(-1,2,6,162:12)
Block(-1,2,7,162:12)
Block(-1,2,11,162:12)
Block(-1,2,12,162:12)
Block(-1,2,13,162:12)
Block(-1,3,5,162:12)
Block(-1,3,6,162:12)
Block(-1,3,7,162:12)
Block(-1,9,10,162:12)
Block(-1,10,9,162:12)
Block(-1,10,10,162:12)
Block(-1,11,9,162:12)
Block(-1,11,10,162:12)
Block(-1,11,11,162:12)
Block(-1,12,7,161:1)
Block(-1,12,10,162:12)
Block(-1,13,7,161:1)
Block(-1,14,7,161:1)
Block(-1,15,7,161:1)
Block(-1,15,8,161:1)
Block(-1,25,6,161:1)
Block(-1,25,10,162:12)
Block(-1,26,9,162:12)
Block(-1,26,10,162:12)
Block(-1,26,11,162:12)
Block(-1,26,12,162:12)
Block(-1,27,-5,161:1)
Block(-1,27,0,162:12)
Block(-1,27,10,162:12)
Block(-1,27,11,162:12)
Block(-1,27,12,162:12)
Block(-1,27,13,162:12)
Block(-1,27,14,162:12)
Block(-1,27,15,162:12)
Block(-1,27,16,161:1)
Block(-1,28,-5,161:1)
Block(-1,28,-2,162:12)
Block(-1,28,-1,162:12)
Block(-1,28,0,162:12)
Block(-1,28,10,162:12)
Block(-1,28,11,162:12)
Block(-1,28,12,162:12)
Block(-1,28,13,162:12)
Block(-1,28,14,162:12)
Block(-1,28,15,162:12)
Block(-1,28,16,161:1)
Block(-1,29,-5,161:1)
Block(-1,29,-3,162:12)
Block(-1,29,-2,162:12)
Block(-1,29,-1,162:12)
Block(-1,29,10,162:12)
Block(-1,29,11,162:12)
Block(-1,29,12,162:12)
Block(-1,29,13,162:12)
Block(-1,29,14,162:12)
Block(-1,29,15,162:12)
Block(-1,29,16,162:12)
Block(-1,29,17,161:1)
Block(-1,30,-5,161:1)
Block(-1,30,-3,162:12)
Block(-1,30,-2,162:12)
Block(-1,30,-1,162:12)
Block(-1,30,11,162:12)
Block(-1,30,12,162:12)
Block(-1,30,13,162:12)
Block(-1,30,14,162:12)
Block(-1,30,15,162:12)
Block(-1,30,16,162:12)
Block(-1,30,17,161:1)
Block(-1,31,-5,161:1)
Block(-1,31,-4,162:12)
Block(-1,31,-3,162:12)
Block(-1,31,-2,162:12)
Block(-1,31,-1,162)
Block(-1,31,11,162:12)
Block(-1,31,12,162:12)
Block(-1,31,13,162:12)
Block(-1,31,14,162:12)
Block(-1,31,15,162:12)
Block(-1,31,16,162:12)
Block(-1,31,17,162:12)
Block(-1,32,-4,161:1)
Block(-1,32,-3,162:12)
Block(-1,32,-2,162:12)
Block(-1,32,-1,162:12)
Block(-1,32,13,162:12)
Block(-1,32,14,162:12)
Block(-1,32,15,162:12)
Block(-1,32,16,162:12)
Block(-1,32,17,162:12)
Block(-1,32,18,162:12)
Block(-1,33,-2,162:12)
Block(-1,33,-1,162:12)
Block(-1,33,0,162:12)
Block(-1,33,14,162:12)
Block(-1,33,15,162:12)
Block(-1,33,16,162:12)
Block(-1,33,17,162:12)
Block(-1,34,-2,162:12)
Block(-1,34,-1,162:12)
Block(-1,34,0,162:12)
Block(-1,34,1,162:12)
Block(-1,34,15,162:12)
Block(-1,34,16,162:12)
Block(-1,34,17,162:12)
Block(-1,34,18,162:12)
Block(-1,34,19,161:1)
Block(-1,35,-1,162:12)
Block(-1,35,0,162:12)
Block(-1,35,1,161:1)
Block(-1,35,15,161:1)
Block(-1,36,-1,161:1)
Block(-1,36,0,162:12)
Block(-1,36,15,161:1)
Block(-1,37,0,161:1)
Block(-1,37,1,162:12)
Block(-1,37,15,161:1)
Block(-1,38,1,161:1)
Block(-1,41,30,162:12)
Block(-1,42,28,162:12)
Block(-1,42,29,162:12)
Block(-1,42,30,162:12)
Block(-1,42,31,162:12)
Block(-1,43,28,161:1)
Block(-1,43,29,162:12)
Block(-1,43,30,162:12)
Block(-1,43,31,162:12)
Block(-1,43,32,162:12)
Block(-1,44,29,161:1)
Block(-1,44,30,162:12)
Block(-1,44,31,162:12)
Block(-1,44,32,161:1)
Block(-1,45,30,161:1)
Block(-1,45,31,161:1)
Block(-1,47,-23,162:12)
Block(-1,48,-24,161:1)
Block(-1,48,-23,162:12)
Block(-1,49,-24,161:1)
Block(-1,49,-23,162:12)
Block(-1,50,-23,161:1)
Block(0,0,4,162:12)
Block(0,0,5,162:12)
Block(0,0,6,162:12)
Block(0,0,13,162:12)
Block(0,0,14,162:12)
Block(0,0,15,162:12)
Block(0,1,4,161:1)
Block(0,1,6,162:12)
Block(0,1,13,162:12)
Block(0,1,14,162:12)
Block(0,21,6,161:1)
Block(0,22,6,161:1)
Block(0,23,6,161:1)
Block(0,24,6,161:1)
Block(0,27,13,162:12)
Block(0,28,12,162:12)
Block(0,28,13,162:12)
Block(0,28,14,162:12)
Block(0,29,11,162:12)
Block(0,29,12,162:12)
Block(0,29,13,162:12)
Block(0,29,14,162:12)
Block(0,29,15,162:12)
Block(0,30,11,161:1)
Block(0,30,12,162:12)
Block(0,30,13,162:12)
Block(0,30,14,162:12)
Block(0,30,15,162:12)
Block(0,31,-3,162:12)
Block(0,31,13,162:12)
Block(0,31,14,162:12)
Block(0,31,15,162:12)
Block(0,31,16,162:12)
Block(0,32,-2,162:12)
Block(0,32,14,162:12)
Block(0,32,15,162:12)
Block(0,32,16,162:12)
Block(0,32,17,162:12)
Block(0,33,-1,162:12)
Block(0,33,15,162:12)
Block(0,33,16,162:12)
Block(0,33,17,162:12)
Block(0,33,18,162:12)
Block(0,33,19,161:1)
