#######################################################################
# +-----------------------------------------------------------------+ #
# |                            BO3 object                           | #
# +-----------------------------------------------------------------+ #
#######################################################################

# The descriptions in this file are accurate only for TerrainControl and OTG.
# For MCW and OTG+ these descriptions are only accurate if the BO3 is used as a CustomObject.
# MCW and OTG+ completely reimplemented CustomStructure, check the MCW/OTG+ documentation for more information.

# This is the config file of a custom object.
# If you add this object correctly to your BiomeConfigs, it will spawn in the world.

# This is the creator of this BO3 object
Author: Unknown

# A short description of this BO3 object
Description: This BO3 was converted from a schematic using OTGEdit. The author and description information of the schematic could not be found. If you know who the author of the schematic is then please add this information.

# The BO3 version, don't change this! It can be used by external applications to do a version check.
Version: 3

# The settings mode, WriteAll, WriteWithoutComments or WriteDisable. See WorldConfig.
SettingsMode: WriteDisable

#######################################################################
# +-----------------------------------------------------------------+ #
# |                          Main settings                          | #
# +-----------------------------------------------------------------+ #
#######################################################################

# This needs to be set to true to spawn the object in the Tree and Sapling resources.
Tree: false

# The frequency of the BO3 from 1 to 200. Tries this many times to spawn this BO3 when using the CustomObject(...) resource.
# Ignored by Tree(..), Sapling(..) and CustomStructure(..)
Frequency: 40

# The rarity of the BO3 from 0 to 100. Each spawn attempt has rarity% chance to succeed when using the CustomObject(...) resource.
# Ignored by Tree(..), Sapling(..) and CustomStructure(..)
Rarity: 100.0

# If you set this to true, the BO3 will be placed with a random rotation.
RotateRandomly: true

# The spawn height of the BO3 - randomY, highestBlock or highestSolidBlock.
SpawnHeight: randomY

# The height limits for the BO3.
MinHeight: 92

MaxHeight: 256

# Objects can have other objects attached to it: branches. Branches can also
# have branches attached to it, which can also have branches, etc. This is the
# maximum branch depth for this objects.
MaxBranchDepth: 10

# When spawned with the UseWorld keyword, this BO3 should NOT spawn in the following biomes.
# If you writer.write the BO3 name directly in the BiomeConfigs, this will be ignored.
ExcludedBiomes: All

# To optimise this BO3 for faster loading times you can use Notepad++ to find/replace comments and abbreviate things.
# Notepad++ find/replace with regex:
# Find: ^[#;].* replace to nothing removes all lines starting with # 
# Find: ^\s*$ replace to nothing removes most empty lines 
# Notepad++ find/replace without regex:
# *Warning: This will only work for OTG 1.10.2 v21 / OTG 1.11.2 v6 or higher. B( is not recognised by lower versions.
# Find: Block( replace to B(

#######################################################################
# +-----------------------------------------------------------------+ #
# |                      Source block settings                      | #
# +-----------------------------------------------------------------+ #
#######################################################################

# The block(s) the BO3 should spawn in.
SourceBlocks: AIR

# The maximum percentage of the BO3 that can be outside the SourceBlock.
# The BO3 won't be placed on a location with more blocks outside the SourceBlock than this percentage.
MaxPercentageOutsideSourceBlock: 100

# What to do when a block is about to be placed outside the SourceBlock? (dontPlace, placeAnyway)
OutsideSourceBlock: placeAnyway

#######################################################################
# +-----------------------------------------------------------------+ #
# |                              Blocks                             | #
# +-----------------------------------------------------------------+ #
#######################################################################

# All the blocks used in the BO3 are listed here. Possible blocks:
# Block(x,y,z,id[.data][,nbtfile.nbt) or B(x,y,z,id[.data][,nbtfile.nbt)
# RandomBlock(x,y,z,id[:data][,nbtfile.nbt],chance[,id[:data][,nbtfile.nbt],chance[,...]])
# So RandomBlock(0,0,0,CHEST,chest.nbt,50,CHEST,anotherchest.nbt,100) will spawn a chest at
# the BO3 origin, and give it a 50% chance to have the contents of chest.nbt, or, if that
# fails, a 100% percent chance to have the contents of anotherchest.nbt.

Block(-30,38,2,18:3)
Block(-30,39,2,18:3)
Block(-29,39,2,18:3)
Block(-29,40,2,18:3)
Block(-28,39,1,18:3)
Block(-28,39,2,18:3)
Block(-28,40,1,18:3)
Block(-28,40,2,18:3)
Block(-28,40,3,18:3)
Block(-28,41,2,18:3)
Block(-27,39,1,18:3)
Block(-27,39,2,18:3)
Block(-27,40,0,18:3)
Block(-27,40,1,18:3)
Block(-27,40,2,18:3)
Block(-27,40,3,18:3)
Block(-27,41,1,18:3)
Block(-27,41,2,18:3)
Block(-26,39,0,18:3)
Block(-26,39,1,18:3)
Block(-26,39,2,18:3)
Block(-26,40,0,18:3)
Block(-26,40,1,18:3)
Block(-26,40,2,18:3)
Block(-26,40,3,18:3)
Block(-26,40,4,18:3)
Block(-26,41,0,18:3)
Block(-26,41,1,18:3)
Block(-26,41,2,18:3)
Block(-26,41,3,18:3)
Block(-26,42,2,18:3)
Block(-25,38,1,103)
Block(-25,39,-20,18:3)
Block(-25,39,0,18:3)
Block(-25,39,1,18:3)
Block(-25,39,2,18:3)
Block(-25,39,3,18:3)
Block(-25,40,-1,18:3)
Block(-25,40,0,18:3)
Block(-25,40,1,18:3)
Block(-25,40,2,18:3)
Block(-25,40,3,18:3)
Block(-25,40,4,18:3)
Block(-25,41,0,18:3)
Block(-25,41,1,18:3)
Block(-25,41,2,18:3)
Block(-25,41,3,18:3)
Block(-25,41,4,18:3)
Block(-25,42,0,18:3)
Block(-25,42,1,18:3)
Block(-25,42,2,18:3)
Block(-25,42,3,18:3)
Block(-25,43,1,18:3)
Block(-24,39,-20,18:3)
Block(-24,39,0,18:3)
Block(-24,39,1,18:3)
Block(-24,39,2,18:3)
Block(-24,40,-20,18:3)
Block(-24,40,-19,18:3)
Block(-24,40,-18,18:3)
Block(-24,40,0,18:3)
Block(-24,40,1,18:3)
Block(-24,40,2,18:3)
Block(-24,40,3,18:3)
Block(-24,41,-18,18:3)
Block(-24,41,-17,18:3)
Block(-24,41,-1,18:3)
Block(-24,41,0,18:3)
Block(-24,41,1,18:3)
Block(-24,41,2,18:3)
Block(-24,41,3,18:3)
Block(-24,41,4,18:3)
Block(-24,42,0,18:3)
Block(-24,42,1,18:3)
Block(-24,42,2,18:3)
Block(-24,42,3,18:3)
Block(-24,43,0,18:3)
Block(-24,43,1,18:3)
Block(-24,43,2,18:3)
Block(-23,39,1,18:3)
Block(-23,39,2,18:3)
Block(-23,40,-19,18:3)
Block(-23,40,-18,18:3)
Block(-23,40,-17,18:3)
Block(-23,40,-16,18:3)
Block(-23,40,0,18:3)
Block(-23,40,1,18:3)
Block(-23,40,2,18:3)
Block(-23,40,3,18:3)
Block(-23,41,-19,18:3)
Block(-23,41,-18,18:3)
Block(-23,41,-17,18:3)
Block(-23,41,-16,18:3)
Block(-23,41,-15,18:3)
Block(-23,41,-1,18:3)
Block(-23,41,0,18:3)
Block(-23,41,1,18:3)
Block(-23,41,2,18:3)
Block(-23,41,3,18:3)
Block(-23,42,-18,18:3)
Block(-23,42,-17,18:3)
Block(-23,42,-16,18:3)
Block(-23,42,-1,18:3)
Block(-23,42,0,18:3)
Block(-23,42,1,18:3)
Block(-23,42,2,18:3)
Block(-23,42,3,18:3)
Block(-23,43,-17,18:3)
Block(-23,43,-16,18:3)
Block(-23,43,0,18:3)
Block(-23,43,1,18:3)
Block(-23,43,2,18:3)
Block(-22,40,-18,18:3)
Block(-22,40,-17,18:3)
Block(-22,40,-16,18:3)
Block(-22,40,0,18:3)
Block(-22,40,1,18:3)
Block(-22,40,2,18:3)
Block(-22,40,3,18:3)
Block(-22,41,-19,18:3)
Block(-22,41,-18,18:3)
Block(-22,41,-17,18:3)
Block(-22,41,-16,18:3)
Block(-22,41,-15,18:3)
Block(-22,41,-1,18:3)
Block(-22,41,0,18:3)
Block(-22,41,1,18:3)
Block(-22,41,2,18:3)
Block(-22,41,3,18:3)
Block(-22,42,-19,18:3)
Block(-22,42,-18,18:3)
Block(-22,42,-17,18:3)
Block(-22,42,-16,18:3)
Block(-22,42,-15,18:3)
Block(-22,42,-1,18:3)
Block(-22,42,0,18:3)
Block(-22,42,1,18:3)
Block(-22,42,2,18:3)
Block(-22,42,3,18:3)
Block(-22,43,-18,18:3)
Block(-22,43,-17,18:3)
Block(-22,43,-16,18:3)
Block(-22,43,-15,18:3)
Block(-22,43,-1,18:3)
Block(-22,43,0,18:3)
Block(-22,43,1,18:3)
Block(-22,43,2,18:3)
Block(-22,43,3,18:3)
Block(-22,44,-17,18:3)
Block(-22,44,-16,18:3)
Block(-22,44,1,18:3)
Block(-21,40,-17,18:3)
Block(-21,40,-16,18:3)
Block(-21,40,-15,18:3)
Block(-21,40,0,18:3)
Block(-21,40,1,18:3)
Block(-21,40,2,18:3)
Block(-21,41,-19,18:3)
Block(-21,41,-18,18:3)
Block(-21,41,-17,18:3)
Block(-21,41,-16,18:3)
Block(-21,41,-15,18:3)
Block(-21,41,-1,18:3)
Block(-21,41,0,18:3)
Block(-21,41,1,18:3)
Block(-21,41,2,18:3)
Block(-21,42,-19,18:3)
Block(-21,42,-18,18:3)
Block(-21,42,-17,18:3)
Block(-21,42,-16,18:3)
Block(-21,42,-15,18:3)
Block(-21,42,-14,18:3)
Block(-21,42,-1,18:3)
Block(-21,42,0,18:3)
Block(-21,42,1,18:3)
Block(-21,42,2,18:3)
Block(-21,42,3,18:3)
Block(-21,43,-18,18:3)
Block(-21,43,-17,18:3)
Block(-21,43,-16,18:3)
Block(-21,43,-15,18:3)
Block(-21,43,-14,18:3)
Block(-21,43,-1,18:3)
Block(-21,43,0,18:3)
Block(-21,43,1,18:3)
Block(-21,43,2,18:3)
Block(-21,43,3,18:3)
Block(-21,44,-17,18:3)
Block(-21,44,-16,18:3)
Block(-21,44,-15,18:3)
Block(-21,44,0,18:3)
Block(-21,44,1,18:3)
Block(-21,45,-17,18:3)
Block(-21,45,-16,18:3)
Block(-20,40,-16,18:3)
Block(-20,40,-15,18:3)
Block(-20,41,-17,18:3)
Block(-20,41,-16,18:3)
Block(-20,41,-15,18:3)
Block(-20,41,0,18:3)
Block(-20,41,1,18:3)
Block(-20,41,2,18:3)
Block(-20,41,3,18:3)
Block(-20,42,-18,18:3)
Block(-20,42,-17,18:3)
Block(-20,42,-16,18:3)
Block(-20,42,-15,18:3)
Block(-20,42,-14,18:3)
Block(-20,42,-1,18:3)
Block(-20,42,0,18:3)
Block(-20,42,1,18:3)
Block(-20,42,2,18:3)
Block(-20,42,3,18:3)
Block(-20,43,-18,18:3)
Block(-20,43,-17,18:3)
Block(-20,43,-16,18:3)
Block(-20,43,-15,18:3)
Block(-20,43,-14,18:3)
Block(-20,43,-1,18:3)
Block(-20,43,0,18:3)
Block(-20,43,1,18:3)
Block(-20,43,2,18:3)
Block(-20,43,3,18:3)
Block(-20,44,-18,18:3)
Block(-20,44,-17,18:3)
Block(-20,44,-16,18:3)
Block(-20,44,-15,18:3)
Block(-20,44,-14,18:3)
Block(-20,44,0,18:3)
Block(-20,44,1,18:3)
Block(-20,44,2,18:3)
Block(-20,45,-17,18:3)
Block(-20,45,-16,18:3)
Block(-20,45,-15,18:3)
Block(-20,45,1,18:3)
Block(-19,41,-16,18:3)
Block(-19,41,-15,18:3)
Block(-19,41,0,18:3)
Block(-19,41,1,18:3)
Block(-19,41,2,18:3)
Block(-19,42,-17,18:3)
Block(-19,42,-16,18:3)
Block(-19,42,-15,18:3)
Block(-19,42,-14,18:3)
Block(-19,42,-1,18:3)
Block(-19,42,0,18:3)
Block(-19,42,1,18:3)
Block(-19,42,2,18:3)
Block(-19,43,-18,18:3)
Block(-19,43,-17,18:3)
Block(-19,43,-16,18:3)
Block(-19,43,-15,18:3)
Block(-19,43,-14,18:3)
Block(-19,43,-13,18:3)
Block(-19,43,-1,18:3)
Block(-19,43,0,18:3)
Block(-19,43,1,18:3)
Block(-19,43,2,18:3)
Block(-19,43,3,18:3)
Block(-19,44,-18,18:3)
Block(-19,44,-17,18:3)
Block(-19,44,-16,18:3)
Block(-19,44,-15,18:3)
Block(-19,44,-14,18:3)
Block(-19,44,-13,18:3)
Block(-19,44,0,18:3)
Block(-19,44,1,18:3)
Block(-19,44,2,18:3)
Block(-19,45,-16,18:3)
Block(-19,45,-15,18:3)
Block(-19,45,-14,18:3)
Block(-19,45,1,18:3)
Block(-18,41,1,18:3)
Block(-18,42,-15,18:3)
Block(-18,42,0,18:3)
Block(-18,42,1,18:3)
Block(-18,42,2,18:3)
Block(-18,42,3,18:3)
Block(-18,43,-17,18:3)
Block(-18,43,-16,18:3)
Block(-18,43,-15,18:3)
Block(-18,43,-14,18:3)
Block(-18,43,-13,18:3)
Block(-18,43,-1,18:3)
Block(-18,43,0,18:3)
Block(-18,43,1,18:3)
Block(-18,43,2,18:3)
Block(-18,43,3,18:3)
Block(-18,44,-17,18:3)
Block(-18,44,-16,18:3)
Block(-18,44,-15,18:3)
Block(-18,44,-14,18:3)
Block(-18,44,-13,18:3)
Block(-18,44,-12,18:3)
Block(-18,44,-1,18:3)
Block(-18,44,0,18:3)
Block(-18,44,1,18:3)
Block(-18,44,2,18:3)
Block(-18,44,3,18:3)
Block(-18,45,-16,18:3)
Block(-18,45,-15,18:3)
Block(-18,45,-14,18:3)
Block(-18,45,-13,18:3)
Block(-18,45,-12,18:3)
Block(-18,45,-11,18:3)
Block(-18,45,0,18:3)
Block(-18,45,1,18:3)
Block(-18,45,2,18:3)
Block(-18,46,-16,18:3)
Block(-18,46,-15,18:3)
Block(-18,46,-14,18:3)
Block(-18,46,-13,18:3)
Block(-18,46,-12,18:3)
Block(-18,47,-12,18:3)
Block(-17,42,-14,103)
Block(-17,42,0,18:3)
Block(-17,42,1,18:3)
Block(-17,42,2,18:3)
Block(-17,43,-16,18:3)
Block(-17,43,-15,18:3)
Block(-17,43,-14,18:3)
Block(-17,43,-13,18:3)
Block(-17,43,0,18:3)
Block(-17,43,1,18:3)
Block(-17,43,2,18:3)
Block(-17,43,3,18:3)
Block(-17,44,-17,18:3)
Block(-17,44,-16,18:3)
Block(-17,44,-15,18:3)
Block(-17,44,-14,18:3)
Block(-17,44,-13,18:3)
Block(-17,44,-12,18:3)
Block(-17,44,-11,18:3)
Block(-17,44,-1,18:3)
Block(-17,44,0,18:3)
Block(-17,44,1,18:3)
Block(-17,44,2,18:3)
Block(-17,44,3,18:3)
Block(-17,45,-15,18:3)
Block(-17,45,-14,18:3)
Block(-17,45,-13,18:3)
Block(-17,45,-12,18:3)
Block(-17,45,-11,18:3)
Block(-17,45,0,18:3)
Block(-17,45,1,18:3)
Block(-17,45,2,18:3)
Block(-17,46,-15,18:3)
Block(-17,46,-14,18:3)
Block(-17,46,-13,18:3)
Block(-17,46,-12,18:3)
Block(-17,46,-11,18:3)
Block(-17,46,-10,18:3)
Block(-17,47,-14,18:3)
Block(-17,47,-13,18:3)
Block(-17,47,-12,18:3)
Block(-17,47,-11,18:3)
Block(-17,47,-10,18:3)
Block(-17,47,-9,18:3)
Block(-16,41,2,103)
Block(-16,42,0,18:3)
Block(-16,42,1,18:3)
Block(-16,42,2,18:3)
Block(-16,43,-15,18:3)
Block(-16,43,-14,18:3)
Block(-16,43,-13,18:3)
Block(-16,43,-1,18:3)
Block(-16,43,0,18:3)
Block(-16,43,1,18:3)
Block(-16,43,2,18:3)
Block(-16,43,3,18:3)
Block(-16,44,-16,18:3)
Block(-16,44,-15,18:3)
Block(-16,44,-14,18:3)
Block(-16,44,-13,18:3)
Block(-16,44,-12,18:3)
Block(-16,44,-11,18:3)
Block(-16,44,-1,18:3)
Block(-16,44,0,18:3)
Block(-16,44,1,18:3)
Block(-16,44,2,18:3)
Block(-16,44,3,18:3)
Block(-16,45,-15,18:3)
Block(-16,45,-14,18:3)
Block(-16,45,-13,18:3)
Block(-16,45,-12,18:3)
Block(-16,45,-11,18:3)
Block(-16,45,0,18:3)
Block(-16,45,1,18:3)
Block(-16,45,2,18:3)
Block(-16,46,-15,18:3)
Block(-16,46,-14,18:3)
Block(-16,46,-13,18:3)
Block(-16,46,-12,18:3)
Block(-16,46,-11,18:3)
Block(-16,46,-10,18:3)
Block(-16,46,-9,18:3)
Block(-16,47,-14,18:3)
Block(-16,47,-13,18:3)
Block(-16,47,-12,18:3)
Block(-16,47,-11,18:3)
Block(-16,47,-10,18:3)
Block(-16,47,-9,18:3)
Block(-16,48,-12,18:3)
Block(-16,48,-11,18:3)
Block(-15,42,-1,18:3)
Block(-15,42,0,18:3)
Block(-15,42,1,18:3)
Block(-15,42,2,18:3)
Block(-15,43,-1,18:3)
Block(-15,43,0,18:3)
Block(-15,43,1,18:3)
Block(-15,43,2,18:3)
Block(-15,43,3,18:3)
Block(-15,44,-15,18:3)
Block(-15,44,-14,18:3)
Block(-15,44,-13,18:3)
Block(-15,44,-12,18:3)
Block(-15,44,-11,18:3)
Block(-15,44,0,18:3)
Block(-15,44,1,18:3)
Block(-15,44,2,18:3)
Block(-15,45,-15,18:3)
Block(-15,45,-14,18:3)
Block(-15,45,-13,18:3)
Block(-15,45,-12,18:3)
Block(-15,45,-11,18:3)
Block(-15,45,-10,18:3)
Block(-15,45,-9,18:3)
Block(-15,45,0,18:3)
Block(-15,45,1,18:3)
Block(-15,45,2,18:3)
Block(-15,46,-15,18:3)
Block(-15,46,-14,18:3)
Block(-15,46,-13,18:3)
Block(-15,46,-12,18:3)
Block(-15,46,-11,18:3)
Block(-15,46,-10,18:3)
Block(-15,46,-9,18:3)
Block(-15,46,-8,18:3)
Block(-15,47,-14,18:3)
Block(-15,47,-13,18:3)
Block(-15,47,-12,18:3)
Block(-15,47,-11,18:3)
Block(-15,47,-10,18:3)
Block(-15,47,-9,18:3)
Block(-15,48,-13,18:3)
Block(-15,48,-12,18:3)
Block(-15,48,-11,18:3)
Block(-15,48,-10,18:3)
Block(-15,48,-9,18:3)
Block(-14,41,1,18:3)
Block(-14,42,-1,18:3)
Block(-14,42,0,18:3)
Block(-14,42,1,18:3)
Block(-14,42,2,18:3)
Block(-14,42,3,18:3)
Block(-14,43,-1,18:3)
Block(-14,43,0,18:3)
Block(-14,43,1,18:3)
Block(-14,43,2,18:3)
Block(-14,43,3,18:3)
Block(-14,44,-14,18:3)
Block(-14,44,-13,18:3)
Block(-14,44,-12,18:3)
Block(-14,44,-1,18:3)
Block(-14,44,0,18:3)
Block(-14,44,1,18:3)
Block(-14,44,2,18:3)
Block(-14,44,3,18:3)
Block(-14,45,-14,18:3)
Block(-14,45,-13,18:3)
Block(-14,45,-12,18:3)
Block(-14,45,-11,18:3)
Block(-14,45,-10,18:3)
Block(-14,45,-9,18:3)
Block(-14,45,-8,18:3)
Block(-14,45,1,18:3)
Block(-14,46,-14,18:3)
Block(-14,46,-13,18:3)
Block(-14,46,-12,18:3)
Block(-14,46,-11,18:3)
Block(-14,46,-10,18:3)
Block(-14,46,-9,18:3)
Block(-14,46,-8,18:3)
Block(-14,46,-7,18:3)
Block(-14,47,-14,18:3)
Block(-14,47,-13,18:3)
Block(-14,47,-12,18:3)
Block(-14,47,-11,18:3)
Block(-14,47,-10,18:3)
Block(-14,47,-9,18:3)
Block(-14,47,-8,18:3)
Block(-14,48,-12,18:3)
Block(-14,48,-11,18:3)
Block(-14,48,-10,18:3)
Block(-14,48,-9,18:3)
Block(-13,41,0,18:3)
Block(-13,41,1,18:3)
Block(-13,41,2,18:3)
Block(-13,42,-1,18:3)
Block(-13,42,0,18:3)
Block(-13,42,1,18:3)
Block(-13,42,2,18:3)
Block(-13,42,3,18:3)
Block(-13,43,-1,18:3)
Block(-13,43,0,18:3)
Block(-13,43,1,18:3)
Block(-13,43,2,18:3)
Block(-13,43,3,18:3)
Block(-13,44,-9,18:3)
Block(-13,44,-8,18:3)
Block(-13,44,-7,18:3)
Block(-13,44,-1,18:3)
Block(-13,44,0,18:3)
Block(-13,44,1,18:3)
Block(-13,44,2,18:3)
Block(-13,44,3,18:3)
Block(-13,45,-11,18:3)
Block(-13,45,-10,18:3)
Block(-13,45,-9,18:3)
Block(-13,45,-8,18:3)
Block(-13,45,-7,18:3)
Block(-13,45,-6,18:3)
Block(-13,45,-5,18:3)
Block(-13,45,1,18:3)
Block(-13,46,-12,18:3)
Block(-13,46,-11,18:3)
Block(-13,46,-10,18:3)
Block(-13,46,-9,18:3)
Block(-13,46,-8,18:3)
Block(-13,46,-7,18:3)
Block(-13,46,-6,18:3)
Block(-13,47,-12,18:3)
Block(-13,47,-11,18:3)
Block(-13,47,-10,18:3)
Block(-13,47,-9,18:3)
Block(-13,47,-8,18:3)
Block(-13,47,-7,18:3)
Block(-13,47,-6,18:3)
Block(-13,48,-10,18:3)
Block(-13,48,-9,18:3)
Block(-13,48,-8,18:3)
Block(-12,41,-1,18:3)
Block(-12,41,0,18:3)
Block(-12,41,1,18:3)
Block(-12,41,2,18:3)
Block(-12,41,3,18:3)
Block(-12,42,-1,18:3)
Block(-12,42,0,18:3)
Block(-12,42,1,18:3)
Block(-12,42,2,18:3)
Block(-12,42,3,18:3)
Block(-12,43,-1,18:3)
Block(-12,43,0,18:3)
Block(-12,43,1,18:3)
Block(-12,43,2,18:3)
Block(-12,43,3,18:3)
Block(-12,44,-9,18:3)
Block(-12,44,-8,18:3)
Block(-12,44,-7,18:3)
Block(-12,44,-6,18:3)
Block(-12,44,-5,18:3)
Block(-12,44,0,18:3)
Block(-12,44,1,18:3)
Block(-12,44,2,18:3)
Block(-12,45,-11,18:3)
Block(-12,45,-10,18:3)
Block(-12,45,-9,18:3)
Block(-12,45,-8,18:3)
Block(-12,45,-7,18:3)
Block(-12,45,-6,18:3)
Block(-12,45,-5,18:3)
Block(-12,46,-11,18:3)
Block(-12,46,-10,18:3)
Block(-12,46,-9,18:3)
Block(-12,46,-8,18:3)
Block(-12,46,-7,18:3)
Block(-12,46,-6,18:3)
Block(-12,46,-5,18:3)
Block(-12,47,-10,18:3)
Block(-12,47,-9,18:3)
Block(-12,47,-8,18:3)
Block(-12,47,-7,18:3)
Block(-12,47,-6,18:3)
Block(-12,47,-5,18:3)
Block(-12,48,-9,18:3)
Block(-12,48,-8,18:3)
Block(-12,48,-7,18:3)
Block(-11,40,-1,18:3)
Block(-11,40,0,18:3)
Block(-11,40,1,18:3)
Block(-11,41,-2,18:3)
Block(-11,41,-1,18:3)
Block(-11,41,0,18:3)
Block(-11,41,1,18:3)
Block(-11,41,2,18:3)
Block(-11,41,3,18:3)
Block(-11,42,-2,18:3)
Block(-11,42,-1,18:3)
Block(-11,42,0,18:3)
Block(-11,42,1,18:3)
Block(-11,42,2,18:3)
Block(-11,42,3,18:3)
Block(-11,43,-7,18:3)
Block(-11,43,-6,18:3)
Block(-11,43,-5,18:3)
Block(-11,43,-4,18:3)
Block(-11,43,-1,18:3)
Block(-11,43,0,18:3)
Block(-11,43,1,18:3)
Block(-11,43,2,18:3)
Block(-11,44,-9,18:3)
Block(-11,44,-8,18:3)
Block(-11,44,-7,18:3)
Block(-11,44,-6,18:3)
Block(-11,44,-5,18:3)
Block(-11,44,-4,18:3)
Block(-11,44,0,18:3)
Block(-11,44,1,18:3)
Block(-11,45,-10,18:3)
Block(-11,45,-9,18:3)
Block(-11,45,-8,18:3)
Block(-11,45,-7,18:3)
Block(-11,45,-6,18:3)
Block(-11,45,-5,18:3)
Block(-11,45,-4,18:3)
Block(-11,46,-10,18:3)
Block(-11,46,-9,18:3)
Block(-11,46,-8,18:3)
Block(-11,46,-7,18:3)
Block(-11,46,-6,18:3)
Block(-11,46,-5,18:3)
Block(-11,47,-9,18:3)
Block(-11,47,-8,18:3)
Block(-11,47,-7,18:3)
Block(-11,47,-6,18:3)
Block(-11,47,-5,18:3)
Block(-11,48,-6,18:3)
Block(-10,40,-2,18:3)
Block(-10,40,-1,18:3)
Block(-10,40,0,18:3)
Block(-10,40,1,18:3)
Block(-10,40,2,18:3)
Block(-10,41,-2,18:3)
Block(-10,41,-1,18:3)
Block(-10,41,0,18:3)
Block(-10,41,1,18:3)
Block(-10,41,2,18:3)
Block(-10,41,3,18:3)
Block(-10,42,-4,18:3)
Block(-10,42,-3,18:3)
Block(-10,42,-2,18:3)
Block(-10,42,-1,18:3)
Block(-10,42,0,18:3)
Block(-10,42,1,18:3)
Block(-10,42,2,18:3)
Block(-10,42,3,18:3)
Block(-10,43,-7,18:3)
Block(-10,43,-6,18:3)
Block(-10,43,-5,18:3)
Block(-10,43,-4,18:3)
Block(-10,43,-3,18:3)
Block(-10,43,-2,18:3)
Block(-10,43,-1,18:3)
Block(-10,43,0,18:3)
Block(-10,43,1,18:3)
Block(-10,43,2,18:3)
Block(-10,43,3,18:3)
Block(-10,44,-9,18:3)
Block(-10,44,-8,18:3)
Block(-10,44,-7,18:3)
Block(-10,44,-6,18:3)
Block(-10,44,-5,18:3)
Block(-10,44,-4,18:3)
Block(-10,44,-3,18:3)
Block(-10,44,-1,18:3)
Block(-10,44,0,18:3)
Block(-10,44,1,18:3)
Block(-10,44,2,18:3)
Block(-10,45,-9,18:3)
Block(-10,45,-8,18:3)
Block(-10,45,-7,18:3)
Block(-10,45,-6,18:3)
Block(-10,45,-5,18:3)
Block(-10,45,-4,18:3)
Block(-10,45,-3,18:3)
Block(-10,46,-9,18:3)
Block(-10,46,-8,18:3)
Block(-10,46,-7,18:3)
Block(-10,46,-6,18:3)
Block(-10,46,-5,18:3)
Block(-10,46,-4,18:3)
Block(-10,46,-3,18:3)
Block(-10,47,-7,18:3)
Block(-10,47,-6,18:3)
Block(-10,47,-5,18:3)
Block(-10,47,-3,18:3)
Block(-9,39,-1,18:3)
Block(-9,39,0,18:3)
Block(-9,39,1,18:3)
Block(-9,40,-2,18:3)
Block(-9,40,-1,18:3)
Block(-9,40,0,18:3)
Block(-9,40,1,18:3)
Block(-9,40,2,18:3)
Block(-9,41,-5,18:3)
Block(-9,41,-4,18:3)
Block(-9,41,-3,18:3)
Block(-9,41,-2,18:3)
Block(-9,41,-1,18:3)
Block(-9,41,0,18:3)
Block(-9,41,1,18:3)
Block(-9,41,2,18:3)
Block(-9,41,3,18:3)
Block(-9,42,-6,18:3)
Block(-9,42,-5,18:3)
Block(-9,42,-4,18:3)
Block(-9,42,-3,18:3)
Block(-9,42,-2,18:3)
Block(-9,42,-1,18:3)
Block(-9,42,0,18:3)
Block(-9,42,1,18:3)
Block(-9,42,2,18:3)
Block(-9,42,3,18:3)
Block(-9,43,-7,18:3)
Block(-9,43,-6,18:3)
Block(-9,43,-5,18:3)
Block(-9,43,-4,18:3)
Block(-9,43,-3,18:3)
Block(-9,43,-2,18:3)
Block(-9,43,-1,18:3)
Block(-9,43,0,18:3)
Block(-9,43,1,18:3)
Block(-9,43,2,18:3)
Block(-9,44,-8,18:3)
Block(-9,44,-7,18:3)
Block(-9,44,-6,18:3)
Block(-9,44,-5,18:3)
Block(-9,44,-4,18:3)
Block(-9,44,-3,18:3)
Block(-9,44,-2,18:3)
Block(-9,44,-1,18:3)
Block(-9,44,0,18:3)
Block(-9,44,1,18:3)
Block(-9,45,-9,18:3)
Block(-9,45,-8,18:3)
Block(-9,45,-7,18:3)
Block(-9,45,-6,18:3)
Block(-9,45,-5,18:3)
Block(-9,45,-4,18:3)
Block(-9,45,-3,18:3)
Block(-9,45,0,18:3)
Block(-9,46,-7,18:3)
Block(-9,46,-6,18:3)
Block(-9,46,-5,18:3)
Block(-9,46,-4,18:3)
Block(-9,46,-3,18:3)
Block(-9,47,-7,18:3)
Block(-9,47,-6,18:3)
Block(-9,47,-5,18:3)
Block(-9,47,-4,18:3)
Block(-9,47,-3,18:3)
Block(-8,37,0,127:11)
Block(-8,39,-2,18:3)
Block(-8,39,-1,18:3)
Block(-8,39,0,18:3)
Block(-8,39,1,18:3)
Block(-8,39,2,18:3)
Block(-8,40,-2,18:3)
Block(-8,40,-1,18:3)
Block(-8,40,0,18:3)
Block(-8,40,1,18:3)
Block(-8,40,2,18:3)
Block(-8,41,-6,18:3)
Block(-8,41,-5,18:3)
Block(-8,41,-4,18:3)
Block(-8,41,-3,18:3)
Block(-8,41,-2,18:3)
Block(-8,41,-1,18:3)
Block(-8,41,0,18:3)
Block(-8,41,1,18:3)
Block(-8,41,2,18:3)
Block(-8,41,3,18:3)
Block(-8,42,-6,18:3)
Block(-8,42,-5,18:3)
Block(-8,42,-4,18:3)
Block(-8,42,-3,18:3)
Block(-8,42,-2,18:3)
Block(-8,42,-1,18:3)
Block(-8,42,0,18:3)
Block(-8,42,1,18:3)
Block(-8,42,2,18:3)
Block(-8,42,3,18:3)
Block(-8,43,-7,18:3)
Block(-8,43,-6,18:3)
Block(-8,43,-5,18:3)
Block(-8,43,-4,18:3)
Block(-8,43,-3,18:3)
Block(-8,43,-2,18:3)
Block(-8,43,-1,18:3)
Block(-8,43,0,18:3)
Block(-8,43,1,18:3)
Block(-8,43,2,18:3)
Block(-8,44,-7,18:3)
Block(-8,44,-6,18:3)
Block(-8,44,-5,18:3)
Block(-8,44,-4,18:3)
Block(-8,44,-3,18:3)
Block(-8,44,-2,18:3)
Block(-8,44,-1,18:3)
Block(-8,44,0,18:3)
Block(-8,44,1,18:3)
Block(-8,45,-7,18:3)
Block(-8,45,-6,18:3)
Block(-8,45,-5,18:3)
Block(-8,45,-4,18:3)
Block(-8,45,-3,18:3)
Block(-8,45,-2,18:3)
Block(-8,45,-1,18:3)
Block(-8,45,0,18:3)
Block(-8,46,-7,18:3)
Block(-8,46,-6,18:3)
Block(-8,46,-5,18:3)
Block(-8,46,-4,18:3)
Block(-8,46,-3,18:3)
Block(-8,47,-6,18:3)
Block(-8,47,-5,18:3)
Block(-8,47,-4,18:3)
Block(-7,34,1,127:11)
Block(-7,36,0,17:15)
Block(-7,37,-2,127:11)
Block(-7,37,-1,17:15)
Block(-7,37,0,17:15)
Block(-7,37,1,17:15)
Block(-7,38,-1,17:15)
Block(-7,38,0,18:3)
Block(-7,38,1,18:3)
Block(-7,38,2,18:3)
Block(-7,38,3,18:3)
Block(-7,39,-5,18:3)
Block(-7,39,-4,18:3)
Block(-7,39,-3,18:3)
Block(-7,39,-2,18:3)
Block(-7,39,-1,18:3)
Block(-7,39,0,18:3)
Block(-7,39,1,18:3)
Block(-7,39,2,18:3)
Block(-7,39,3,18:3)
Block(-7,39,4,18:3)
Block(-7,40,-6,18:3)
Block(-7,40,-5,18:3)
Block(-7,40,-4,18:3)
Block(-7,40,-3,18:3)
Block(-7,40,-2,18:3)
Block(-7,40,-1,18:3)
Block(-7,40,0,18:3)
Block(-7,40,1,18:3)
Block(-7,40,2,18:3)
Block(-7,40,3,18:3)
Block(-7,40,4,18:3)
Block(-7,41,-6,18:3)
Block(-7,41,-5,18:3)
Block(-7,41,-4,18:3)
Block(-7,41,-3,18:3)
Block(-7,41,-2,18:3)
Block(-7,41,-1,18:3)
Block(-7,41,0,18:3)
Block(-7,41,1,18:3)
Block(-7,41,2,18:3)
Block(-7,41,3,18:3)
Block(-7,41,4,18:3)
Block(-7,41,23,18:3)
Block(-7,41,24,18:3)
Block(-7,42,-6,18:3)
Block(-7,42,-5,18:3)
Block(-7,42,-4,18:3)
Block(-7,42,-3,18:3)
Block(-7,42,-2,18:3)
Block(-7,42,-1,18:3)
Block(-7,42,0,18:3)
Block(-7,42,1,18:3)
Block(-7,42,2,18:3)
Block(-7,42,3,18:3)
Block(-7,42,19,18:3)
Block(-7,42,20,18:3)
Block(-7,42,21,18:3)
Block(-7,42,22,18:3)
Block(-7,43,-7,18:3)
Block(-7,43,-6,18:3)
Block(-7,43,-5,18:3)
Block(-7,43,-4,18:3)
Block(-7,43,-3,18:3)
Block(-7,43,-2,18:3)
Block(-7,43,-1,18:3)
Block(-7,43,0,18:3)
Block(-7,43,1,18:3)
Block(-7,43,2,18:3)
Block(-7,43,3,18:3)
Block(-7,43,12,18:3)
Block(-7,43,13,18:3)
Block(-7,43,16,18:3)
Block(-7,43,17,18:3)
Block(-7,43,18,18:3)
Block(-7,44,-7,18:3)
Block(-7,44,-6,18:3)
Block(-7,44,-5,18:3)
Block(-7,44,-4,18:3)
Block(-7,44,-3,18:3)
Block(-7,44,-2,18:3)
Block(-7,44,-1,18:3)
Block(-7,44,0,18:3)
Block(-7,44,1,18:3)
Block(-7,44,2,18:3)
Block(-7,44,14,18:3)
Block(-7,44,15,18:3)
Block(-7,45,-6,18:3)
Block(-7,45,-5,18:3)
Block(-7,45,-4,18:3)
Block(-7,45,-3,18:3)
Block(-7,45,-2,18:3)
Block(-7,45,-1,18:3)
Block(-7,45,0,18:3)
Block(-7,45,1,18:3)
Block(-7,46,-6,18:3)
Block(-7,46,-5,18:3)
Block(-7,46,-4,18:3)
Block(-7,46,-3,18:3)
Block(-7,46,-2,18:3)
Block(-7,46,-1,18:3)
Block(-7,47,-5,18:3)
Block(-7,47,-4,18:3)
Block(-7,47,-3,18:3)
Block(-6,27,-1,17:15)
Block(-6,28,-1,17:15)
Block(-6,28,0,17:15)
Block(-6,29,-2,17:15)
Block(-6,29,-1,17:15)
Block(-6,29,0,17:15)
Block(-6,29,1,17:15)
Block(-6,29,2,17:15)
Block(-6,30,-2,17:15)
Block(-6,30,-1,17:15)
Block(-6,30,0,17:15)
Block(-6,30,1,17:15)
Block(-6,30,2,17:15)
Block(-6,31,-3,17:15)
Block(-6,31,-2,17:15)
Block(-6,31,-1,17:15)
Block(-6,31,0,17:15)
Block(-6,31,1,17:15)
Block(-6,31,2,17:15)
Block(-6,31,3,17:15)
Block(-6,32,-3,17:15)
Block(-6,32,-2,17:15)
Block(-6,32,-1,17:15)
Block(-6,32,0,17:15)
Block(-6,32,1,17:15)
Block(-6,32,2,17:15)
Block(-6,33,-3,17:15)
Block(-6,33,-2,17:15)
Block(-6,33,-1,17:15)
Block(-6,33,0,17:15)
Block(-6,33,1,17:15)
Block(-6,33,2,17:15)
Block(-6,34,-2,17:15)
Block(-6,34,-1,17:15)
Block(-6,34,0,17:15)
Block(-6,34,1,17:15)
Block(-6,34,2,17:15)
Block(-6,35,-2,17:15)
Block(-6,35,-1,17:15)
Block(-6,35,0,17:15)
Block(-6,35,1,17:15)
Block(-6,35,2,17:15)
Block(-6,36,-3,17:15)
Block(-6,36,-2,17:15)
Block(-6,36,-1,17:15)
Block(-6,36,0,17:15)
Block(-6,36,1,17:15)
Block(-6,36,2,17:15)
Block(-6,36,3,17:15)
Block(-6,37,-3,17:15)
Block(-6,37,-2,17:15)
Block(-6,37,-1,17:15)
Block(-6,37,0,17:15)
Block(-6,37,1,17:15)
Block(-6,37,2,17:15)
Block(-6,38,-3,17:15)
Block(-6,38,-2,17:15)
Block(-6,38,-1,17:15)
Block(-6,38,0,18:3)
Block(-6,38,1,18:3)
Block(-6,38,2,18:3)
Block(-6,38,3,18:3)
Block(-6,38,4,18:3)
Block(-6,39,-6,18:3)
Block(-6,39,-5,18:3)
Block(-6,39,-4,18:3)
Block(-6,39,-3,18:3)
Block(-6,39,-2,18:3)
Block(-6,39,-1,18:3)
Block(-6,39,0,18:3)
Block(-6,39,1,18:3)
Block(-6,39,2,18:3)
Block(-6,39,3,18:3)
Block(-6,39,4,18:3)
Block(-6,39,22,18:3)
Block(-6,39,23,18:3)
Block(-6,39,24,18:3)
Block(-6,40,-6,18:3)
Block(-6,40,-5,18:3)
Block(-6,40,-4,18:3)
Block(-6,40,-3,18:3)
Block(-6,40,-2,18:3)
Block(-6,40,-1,18:3)
Block(-6,40,0,18:3)
Block(-6,40,1,18:3)
Block(-6,40,2,18:3)
Block(-6,40,3,18:3)
Block(-6,40,4,18:3)
Block(-6,40,21,18:3)
Block(-6,40,22,18:3)
Block(-6,40,23,18:3)
Block(-6,40,24,18:3)
Block(-6,40,25,18:3)
Block(-6,41,-6,18:3)
Block(-6,41,-5,18:3)
Block(-6,41,-4,18:3)
Block(-6,41,-3,18:3)
Block(-6,41,-2,18:3)
Block(-6,41,-1,18:3)
Block(-6,41,0,18:3)
Block(-6,41,1,18:3)
Block(-6,41,2,18:3)
Block(-6,41,3,18:3)
Block(-6,41,4,18:3)
Block(-6,41,5,18:3)
Block(-6,41,6,18:3)
Block(-6,41,10,18:3)
Block(-6,41,11,18:3)
Block(-6,41,12,18:3)
Block(-6,41,18,18:3)
Block(-6,41,19,18:3)
Block(-6,41,20,18:3)
Block(-6,41,21,18:3)
Block(-6,41,22,18:3)
Block(-6,41,23,18:3)
Block(-6,41,24,18:3)
Block(-6,41,25,18:3)
Block(-6,42,-7,18:3)
Block(-6,42,-6,18:3)
Block(-6,42,-5,18:3)
Block(-6,42,-4,18:3)
Block(-6,42,-3,18:3)
Block(-6,42,-2,18:3)
Block(-6,42,-1,18:3)
Block(-6,42,0,18:3)
Block(-6,42,1,18:3)
Block(-6,42,2,18:3)
Block(-6,42,3,18:3)
Block(-6,42,4,18:3)
Block(-6,42,5,18:3)
Block(-6,42,9,18:3)
Block(-6,42,10,18:3)
Block(-6,42,11,18:3)
Block(-6,42,12,18:3)
Block(-6,42,13,18:3)
Block(-6,42,14,18:3)
Block(-6,42,16,18:3)
Block(-6,42,17,18:3)
Block(-6,42,18,18:3)
Block(-6,42,19,18:3)
Block(-6,42,20,18:3)
Block(-6,42,21,18:3)
Block(-6,42,22,18:3)
Block(-6,42,23,18:3)
Block(-6,42,24,18:3)
Block(-6,43,-8,18:3)
Block(-6,43,-7,18:3)
Block(-6,43,-6,18:3)
Block(-6,43,-5,18:3)
Block(-6,43,-4,18:3)
Block(-6,43,-3,18:3)
Block(-6,43,-2,18:3)
Block(-6,43,-1,18:3)
Block(-6,43,0,18:3)
Block(-6,43,1,18:3)
Block(-6,43,2,18:3)
Block(-6,43,3,18:3)
Block(-6,43,4,18:3)
Block(-6,43,10,18:3)
Block(-6,43,11,18:3)
Block(-6,43,12,18:3)
Block(-6,43,13,18:3)
Block(-6,43,14,18:3)
Block(-6,43,15,18:3)
Block(-6,43,16,18:3)
Block(-6,43,17,18:3)
Block(-6,43,18,18:3)
Block(-6,43,19,18:3)
Block(-6,43,20,18:3)
Block(-6,43,21,18:3)
Block(-6,43,22,18:3)
Block(-6,43,23,18:3)
Block(-6,44,-9,18:3)
Block(-6,44,-8,18:3)
Block(-6,44,-7,18:3)
Block(-6,44,-6,18:3)
Block(-6,44,-5,18:3)
Block(-6,44,-4,18:3)
Block(-6,44,-3,18:3)
Block(-6,44,-2,18:3)
Block(-6,44,-1,18:3)
Block(-6,44,0,18:3)
Block(-6,44,1,18:3)
Block(-6,44,2,18:3)
Block(-6,44,3,18:3)
Block(-6,44,10,18:3)
Block(-6,44,11,18:3)
Block(-6,44,12,18:3)
Block(-6,44,13,18:3)
Block(-6,44,14,18:3)
Block(-6,44,15,18:3)
Block(-6,44,16,18:3)
Block(-6,44,17,18:3)
Block(-6,44,18,18:3)
Block(-6,44,19,18:3)
Block(-6,44,20,18:3)
Block(-6,45,-7,18:3)
Block(-6,45,-6,18:3)
Block(-6,45,-5,18:3)
Block(-6,45,-4,18:3)
Block(-6,45,-3,18:3)
Block(-6,45,-2,18:3)
Block(-6,45,-1,18:3)
Block(-6,45,0,18:3)
Block(-6,45,1,18:3)
Block(-6,45,2,18:3)
Block(-6,45,3,18:3)
Block(-6,45,14,18:3)
Block(-6,45,15,18:3)
Block(-6,45,16,18:3)
Block(-6,45,17,18:3)
Block(-6,46,-6,18:3)
Block(-6,46,-5,18:3)
Block(-6,46,-4,18:3)
Block(-6,46,-3,18:3)
Block(-6,46,-2,18:3)
Block(-6,46,-1,18:3)
Block(-6,46,0,18:3)
Block(-6,46,1,18:3)
Block(-6,46,2,18:3)
Block(-6,47,-5,18:3)
Block(-6,47,-4,18:3)
Block(-6,47,-3,18:3)
Block(-6,47,-2,18:3)
Block(-6,47,-1,18:3)
Block(-6,47,0,18:3)
Block(-6,47,1,18:3)
Block(-6,48,-4,18:3)
Block(-5,23,-2,17:15)
Block(-5,24,-2,17:15)
Block(-5,24,-1,17:15)
Block(-5,25,-3,17:15)
Block(-5,25,-2,17:15)
Block(-5,25,-1,17:15)
Block(-5,25,0,17:15)
Block(-5,25,1,17:15)
Block(-5,26,-3,17:15)
Block(-5,26,-2,17:15)
Block(-5,26,-1,17:15)
Block(-5,26,0,17:15)
Block(-5,26,1,17:15)
Block(-5,27,-4,17:15)
Block(-5,27,-3,17:15)
Block(-5,27,-2,17:15)
Block(-5,27,-1,17:15)
Block(-5,27,0,17:15)
Block(-5,27,1,17:15)
Block(-5,27,2,17:15)
Block(-5,28,-3,17:15)
Block(-5,28,-2,17:15)
Block(-5,28,-1,17:15)
Block(-5,28,0,17:15)
Block(-5,28,1,17:15)
Block(-5,28,2,17:15)
Block(-5,29,-3,17:15)
Block(-5,29,-2,17:15)
Block(-5,29,-1,17:15)
Block(-5,29,0,17:15)
Block(-5,29,1,17:15)
Block(-5,29,2,17:15)
Block(-5,29,3,17:15)
Block(-5,30,-3,17:15)
Block(-5,30,-2,17:15)
Block(-5,30,-1,17:15)
Block(-5,30,0,17:15)
Block(-5,30,1,17:15)
Block(-5,30,2,17:15)
Block(-5,30,3,17:15)
Block(-5,31,-4,17:15)
Block(-5,31,-3,17:15)
Block(-5,31,-2,17:15)
Block(-5,31,-1,17:15)
Block(-5,31,0,17:15)
Block(-5,31,1,17:15)
Block(-5,31,2,17:15)
Block(-5,31,3,17:15)
Block(-5,31,4,17:15)
Block(-5,32,-4,17:15)
Block(-5,32,-3,17:15)
Block(-5,32,-2,17:15)
Block(-5,32,-1,17:15)
Block(-5,32,0,17:15)
Block(-5,32,1,17:15)
Block(-5,32,2,17:15)
Block(-5,32,3,17:15)
Block(-5,32,4,18:3)
Block(-5,33,-3,17:15)
Block(-5,33,-2,17:15)
Block(-5,33,-1,17:15)
Block(-5,33,0,17:15)
Block(-5,33,1,17:15)
Block(-5,33,2,17:15)
Block(-5,33,3,17:15)
Block(-5,34,-3,17:15)
Block(-5,34,-2,17:15)
Block(-5,34,-1,17:15)
Block(-5,34,0,17:15)
Block(-5,34,1,17:15)
Block(-5,34,2,17:15)
Block(-5,34,3,17:15)
Block(-5,35,-3,17:15)
Block(-5,35,-2,17:15)
Block(-5,35,-1,17:15)
Block(-5,35,0,17:15)
Block(-5,35,1,17:15)
Block(-5,35,2,17:15)
Block(-5,35,3,17:15)
Block(-5,36,-4,17:15)
Block(-5,36,-3,17:15)
Block(-5,36,-2,17:15)
Block(-5,36,-1,17:15)
Block(-5,36,0,17:15)
Block(-5,36,1,17:15)
Block(-5,36,2,17:15)
Block(-5,36,3,17:15)
Block(-5,36,4,17:15)
Block(-5,37,-4,17:15)
Block(-5,37,-3,17:15)
Block(-5,37,-2,17:15)
Block(-5,37,-1,17:15)
Block(-5,37,0,17:15)
Block(-5,37,1,17:15)
Block(-5,37,2,18:3)
Block(-5,37,3,17:15)
Block(-5,38,-28,18:3)
Block(-5,38,-4,18:3)
Block(-5,38,-3,17:15)
Block(-5,38,-2,17:15)
Block(-5,38,-1,17:15)
Block(-5,38,0,18:3)
Block(-5,38,1,18:3)
Block(-5,38,2,18:3)
Block(-5,38,3,18:3)
Block(-5,38,4,18:3)
Block(-5,39,-27,18:3)
Block(-5,39,-26,18:3)
Block(-5,39,-6,18:3)
Block(-5,39,-5,18:3)
Block(-5,39,-4,18:3)
Block(-5,39,-3,18:3)
Block(-5,39,-2,18:3)
Block(-5,39,-1,18:3)
Block(-5,39,0,18:3)
Block(-5,39,1,18:3)
Block(-5,39,2,18:3)
Block(-5,39,3,18:3)
Block(-5,39,4,18:3)
Block(-5,39,5,18:3)
Block(-5,39,6,18:3)
Block(-5,39,21,18:3)
Block(-5,39,22,18:3)
Block(-5,39,23,18:3)
Block(-5,39,24,18:3)
Block(-5,39,25,18:3)
Block(-5,39,26,18:3)
Block(-5,40,-26,18:3)
Block(-5,40,-25,18:3)
Block(-5,40,-24,18:3)
Block(-5,40,-6,18:3)
Block(-5,40,-5,18:3)
Block(-5,40,-4,18:3)
Block(-5,40,-3,18:3)
Block(-5,40,-2,18:3)
Block(-5,40,-1,18:3)
Block(-5,40,0,18:3)
Block(-5,40,1,18:3)
Block(-5,40,2,18:3)
Block(-5,40,3,18:3)
Block(-5,40,4,18:3)
Block(-5,40,5,18:3)
Block(-5,40,6,18:3)
Block(-5,40,7,18:3)
Block(-5,40,21,18:3)
Block(-5,40,22,18:3)
Block(-5,40,23,18:3)
Block(-5,40,24,18:3)
Block(-5,40,25,18:3)
Block(-5,40,26,18:3)
Block(-5,41,-25,18:3)
Block(-5,41,-24,18:3)
Block(-5,41,-23,18:3)
Block(-5,41,-22,18:3)
Block(-5,41,-21,18:3)
Block(-5,41,-20,18:3)
Block(-5,41,-8,18:3)
Block(-5,41,-7,18:3)
Block(-5,41,-6,18:3)
Block(-5,41,-5,18:3)
Block(-5,41,-4,18:3)
Block(-5,41,-3,18:3)
Block(-5,41,-2,18:3)
Block(-5,41,-1,18:3)
Block(-5,41,0,18:3)
Block(-5,41,1,18:3)
Block(-5,41,2,18:3)
Block(-5,41,3,18:3)
Block(-5,41,4,18:3)
Block(-5,41,5,18:3)
Block(-5,41,6,18:3)
Block(-5,41,7,18:3)
Block(-5,41,8,18:3)
Block(-5,41,9,18:3)
Block(-5,41,10,18:3)
Block(-5,41,11,18:3)
Block(-5,41,12,18:3)
Block(-5,41,13,18:3)
Block(-5,41,17,18:3)
Block(-5,41,18,18:3)
Block(-5,41,19,18:3)
Block(-5,41,20,18:3)
Block(-5,41,21,18:3)
Block(-5,41,22,18:3)
Block(-5,41,23,18:3)
Block(-5,41,24,18:3)
Block(-5,41,25,18:3)
Block(-5,42,-24,18:3)
Block(-5,42,-23,18:3)
Block(-5,42,-22,18:3)
Block(-5,42,-21,18:3)
Block(-5,42,-20,18:3)
Block(-5,42,-19,18:3)
Block(-5,42,-18,18:3)
Block(-5,42,-10,18:3)
Block(-5,42,-9,18:3)
Block(-5,42,-8,18:3)
Block(-5,42,-7,18:3)
Block(-5,42,-6,18:3)
Block(-5,42,-5,18:3)
Block(-5,42,-4,18:3)
Block(-5,42,-3,18:3)
Block(-5,42,-2,18:3)
Block(-5,42,-1,18:3)
Block(-5,42,0,18:3)
Block(-5,42,1,18:3)
Block(-5,42,2,18:3)
Block(-5,42,3,18:3)
Block(-5,42,4,18:3)
Block(-5,42,5,18:3)
Block(-5,42,6,18:3)
Block(-5,42,7,18:3)
Block(-5,42,8,18:3)
Block(-5,42,9,18:3)
Block(-5,42,10,18:3)
Block(-5,42,11,18:3)
Block(-5,42,12,18:3)
Block(-5,42,13,18:3)
Block(-5,42,14,18:3)
Block(-5,42,15,18:3)
Block(-5,42,16,18:3)
Block(-5,42,17,18:3)
Block(-5,42,18,18:3)
Block(-5,42,19,18:3)
Block(-5,42,20,18:3)
Block(-5,42,21,18:3)
Block(-5,42,22,18:3)
Block(-5,42,23,18:3)
Block(-5,42,24,18:3)
Block(-5,42,25,18:3)
Block(-5,43,-21,18:3)
Block(-5,43,-20,18:3)
Block(-5,43,-19,18:3)
Block(-5,43,-18,18:3)
Block(-5,43,-17,18:3)
Block(-5,43,-16,18:3)
Block(-5,43,-11,18:3)
Block(-5,43,-10,18:3)
Block(-5,43,-9,18:3)
Block(-5,43,-8,18:3)
Block(-5,43,-7,18:3)
Block(-5,43,-6,18:3)
Block(-5,43,-5,18:3)
Block(-5,43,-4,18:3)
Block(-5,43,-3,18:3)
Block(-5,43,-2,18:3)
Block(-5,43,-1,18:3)
Block(-5,43,0,18:3)
Block(-5,43,1,18:3)
Block(-5,43,2,18:3)
Block(-5,43,3,18:3)
Block(-5,43,4,18:3)
Block(-5,43,5,18:3)
Block(-5,43,6,18:3)
Block(-5,43,7,18:3)
Block(-5,43,8,18:3)
Block(-5,43,9,18:3)
Block(-5,43,10,18:3)
Block(-5,43,11,18:3)
Block(-5,43,12,18:3)
Block(-5,43,13,18:3)
Block(-5,43,14,18:3)
Block(-5,43,15,18:3)
Block(-5,43,16,18:3)
Block(-5,43,17,18:3)
Block(-5,43,18,18:3)
Block(-5,43,19,18:3)
Block(-5,43,20,18:3)
Block(-5,43,21,18:3)
Block(-5,43,22,18:3)
Block(-5,43,23,18:3)
Block(-5,44,-15,18:3)
Block(-5,44,-14,18:3)
Block(-5,44,-13,18:3)
Block(-5,44,-12,18:3)
Block(-5,44,-11,18:3)
Block(-5,44,-10,18:3)
Block(-5,44,-9,18:3)
Block(-5,44,-8,18:3)
Block(-5,44,-7,18:3)
Block(-5,44,-6,18:3)
Block(-5,44,-5,18:3)
Block(-5,44,-4,18:3)
Block(-5,44,-3,18:3)
Block(-5,44,-2,18:3)
Block(-5,44,-1,18:3)
Block(-5,44,0,18:3)
Block(-5,44,1,18:3)
Block(-5,44,2,18:3)
Block(-5,44,3,18:3)
Block(-5,44,4,18:3)
Block(-5,44,7,18:3)
Block(-5,44,8,18:3)
Block(-5,44,9,18:3)
Block(-5,44,10,18:3)
Block(-5,44,11,18:3)
Block(-5,44,12,18:3)
Block(-5,44,13,18:3)
Block(-5,44,14,18:3)
Block(-5,44,15,18:3)
Block(-5,44,16,18:3)
Block(-5,44,17,18:3)
Block(-5,44,18,18:3)
Block(-5,44,19,18:3)
Block(-5,44,20,18:3)
Block(-5,44,21,18:3)
Block(-5,44,22,18:3)
Block(-5,45,-12,18:3)
Block(-5,45,-11,18:3)
Block(-5,45,-10,18:3)
Block(-5,45,-9,18:3)
Block(-5,45,-8,18:3)
Block(-5,45,-7,18:3)
Block(-5,45,-6,18:3)
Block(-5,45,-5,18:3)
Block(-5,45,-4,18:3)
Block(-5,45,-3,18:3)
Block(-5,45,-2,18:3)
Block(-5,45,-1,18:3)
Block(-5,45,0,18:3)
Block(-5,45,1,18:3)
Block(-5,45,2,18:3)
Block(-5,45,3,18:3)
Block(-5,45,4,18:3)
Block(-5,45,10,18:3)
Block(-5,45,11,18:3)
Block(-5,45,12,18:3)
Block(-5,45,13,18:3)
Block(-5,45,14,18:3)
Block(-5,45,15,18:3)
Block(-5,45,16,18:3)
Block(-5,45,17,18:3)
Block(-5,45,18,18:3)
Block(-5,45,19,18:3)
Block(-5,45,20,18:3)
Block(-5,46,-6,18:3)
Block(-5,46,-5,18:3)
Block(-5,46,-4,18:3)
Block(-5,46,-3,18:3)
Block(-5,46,-2,18:3)
Block(-5,46,-1,18:3)
Block(-5,46,0,18:3)
Block(-5,46,1,18:3)
Block(-5,46,2,18:3)
Block(-5,46,3,18:3)
Block(-5,46,13,18:3)
Block(-5,46,14,18:3)
Block(-5,46,15,18:3)
Block(-5,46,16,18:3)
Block(-5,46,17,18:3)
Block(-5,47,-5,18:3)
Block(-5,47,-4,18:3)
Block(-5,47,-3,18:3)
Block(-5,47,-2,18:3)
Block(-5,47,-1,18:3)
Block(-5,47,0,18:3)
Block(-5,47,1,18:3)
Block(-5,47,2,18:3)
Block(-5,48,-4,18:3)
Block(-5,48,-3,18:3)
Block(-5,48,-2,18:3)
Block(-5,48,-1,18:3)
Block(-4,0,-7,17:15)
Block(-4,0,-6,17:15)
Block(-4,16,-3,17:15)
Block(-4,17,-3,17:15)
Block(-4,18,-3,17:15)
Block(-4,18,-2,17:15)
Block(-4,19,-3,17:15)
Block(-4,19,-2,17:15)
Block(-4,20,-4,17:15)
Block(-4,20,-3,17:15)
Block(-4,20,-2,17:15)
Block(-4,21,-4,17:15)
Block(-4,21,-3,17:15)
Block(-4,21,-2,17:15)
Block(-4,21,-1,17:15)
Block(-4,21,0,17:15)
Block(-4,22,-4,17:15)
Block(-4,22,-3,17:15)
Block(-4,22,-2,17:15)
Block(-4,22,-1,17:15)
Block(-4,22,0,17:15)
Block(-4,23,-5,17:15)
Block(-4,23,-4,17:15)
Block(-4,23,-3,17:15)
Block(-4,23,-2,17:15)
Block(-4,23,-1,17:15)
Block(-4,23,0,17:15)
Block(-4,23,1,17:15)
Block(-4,24,-4,17:15)
Block(-4,24,-3,17:15)
Block(-4,24,-2,17:15)
Block(-4,24,-1,17:15)
Block(-4,24,0,17:15)
Block(-4,24,1,17:15)
Block(-4,25,-4,17:15)
Block(-4,25,-3,17:15)
Block(-4,25,-2,17:15)
Block(-4,25,-1,17:15)
Block(-4,25,0,17:15)
Block(-4,25,1,17:15)
Block(-4,25,2,17:15)
Block(-4,26,-4,17:15)
Block(-4,26,-3,17:15)
Block(-4,26,-2,17:15)
Block(-4,26,-1,17:15)
Block(-4,26,0,17:15)
Block(-4,26,1,17:15)
Block(-4,26,2,17:15)
Block(-4,27,-5,17:15)
Block(-4,27,-4,17:15)
Block(-4,27,-3,17:15)
Block(-4,27,-2,17:15)
Block(-4,27,-1,17:15)
Block(-4,27,0,17:15)
Block(-4,27,1,17:15)
Block(-4,27,2,17:15)
Block(-4,27,3,17:15)
Block(-4,28,-4,17:15)
Block(-4,28,-3,17:15)
Block(-4,28,-2,17:15)
Block(-4,28,-1,17:15)
Block(-4,28,0,17:15)
Block(-4,28,1,17:15)
Block(-4,28,2,17:15)
Block(-4,28,3,17:15)
Block(-4,29,-4,17:15)
Block(-4,29,-3,17:15)
Block(-4,29,-2,17:15)
Block(-4,29,-1,17:15)
Block(-4,29,0,17:15)
Block(-4,29,1,17:15)
Block(-4,29,2,17:15)
Block(-4,29,3,17:15)
Block(-4,29,4,17:15)
Block(-4,29,5,18:3)
Block(-4,30,-4,17:15)
Block(-4,30,-3,17:15)
Block(-4,30,-2,17:15)
Block(-4,30,-1,17:15)
Block(-4,30,0,17:15)
Block(-4,30,1,17:15)
Block(-4,30,2,17:15)
Block(-4,30,3,17:15)
Block(-4,30,4,17:15)
Block(-4,30,5,18:3)
Block(-4,31,-4,17:15)
Block(-4,31,-3,17:15)
Block(-4,31,-2,17:15)
Block(-4,31,-1,17:15)
Block(-4,31,0,17:15)
Block(-4,31,1,17:15)
Block(-4,31,2,17:15)
Block(-4,31,3,17:15)
Block(-4,31,4,17:15)
Block(-4,32,-4,17:15)
Block(-4,32,-3,17:15)
Block(-4,32,-2,17:15)
Block(-4,32,-1,17:15)
Block(-4,32,0,17:15)
Block(-4,32,1,17:15)
Block(-4,32,2,17:15)
Block(-4,32,3,17:15)
Block(-4,32,4,17:15)
Block(-4,33,-4,17:15)
Block(-4,33,-3,17:15)
Block(-4,33,-2,17:15)
Block(-4,33,-1,17:15)
Block(-4,33,0,17:15)
Block(-4,33,1,17:15)
Block(-4,33,2,17:15)
Block(-4,33,3,17:15)
Block(-4,33,4,17:15)
Block(-4,34,-4,17:15)
Block(-4,34,-3,17:15)
Block(-4,34,-2,17:15)
Block(-4,34,-1,17:15)
Block(-4,34,0,17:15)
Block(-4,34,1,17:15)
Block(-4,34,2,17:15)
Block(-4,34,3,17:15)
Block(-4,34,4,17:15)
Block(-4,35,-4,17:15)
Block(-4,35,-3,17:15)
Block(-4,35,-2,17:15)
Block(-4,35,-1,17:15)
Block(-4,35,0,17:15)
Block(-4,35,1,17:15)
Block(-4,35,2,17:15)
Block(-4,35,3,17:15)
Block(-4,35,4,17:15)
Block(-4,36,-4,17:15)
Block(-4,36,-3,17:15)
Block(-4,36,-2,17:15)
Block(-4,36,-1,17:15)
Block(-4,36,0,17:15)
Block(-4,36,1,17:15)
Block(-4,36,2,17:15)
Block(-4,36,3,17:15)
Block(-4,36,4,17:15)
Block(-4,37,-4,17:15)
Block(-4,37,-3,17:15)
Block(-4,37,-2,17:15)
Block(-4,37,-1,17:15)
Block(-4,37,0,17:15)
Block(-4,37,1,17:15)
Block(-4,37,2,17:15)
Block(-4,37,3,17:15)
Block(-4,37,4,17:15)
Block(-4,38,-29,18:3)
Block(-4,38,-28,18:3)
Block(-4,38,-4,17:15)
Block(-4,38,-3,17:15)
Block(-4,38,-2,17:15)
Block(-4,38,-1,18:3)
Block(-4,38,0,18:3)
Block(-4,38,1,18:3)
Block(-4,38,2,18:3)
Block(-4,38,3,18:3)
Block(-4,38,4,18:3)
Block(-4,38,23,18:3)
Block(-4,38,24,18:3)
Block(-4,38,25,18:3)
Block(-4,39,-28,18:3)
Block(-4,39,-27,18:3)
Block(-4,39,-26,18:3)
Block(-4,39,-25,18:3)
Block(-4,39,-24,18:3)
Block(-4,39,-23,18:3)
Block(-4,39,-6,18:3)
Block(-4,39,-5,18:3)
Block(-4,39,-4,18:3)
Block(-4,39,-3,18:3)
Block(-4,39,-2,18:3)
Block(-4,39,-1,18:3)
Block(-4,39,0,18:3)
Block(-4,39,1,18:3)
Block(-4,39,2,18:3)
Block(-4,39,3,18:3)
Block(-4,39,4,18:3)
Block(-4,39,5,18:3)
Block(-4,39,6,18:3)
Block(-4,39,7,18:3)
Block(-4,39,21,18:3)
Block(-4,39,22,18:3)
Block(-4,39,23,18:3)
Block(-4,39,24,18:3)
Block(-4,39,25,18:3)
Block(-4,39,26,18:3)
Block(-4,39,27,18:3)
Block(-4,39,28,18:3)
Block(-4,40,-27,18:3)
Block(-4,40,-26,18:3)
Block(-4,40,-25,18:3)
Block(-4,40,-24,18:3)
Block(-4,40,-23,18:3)
Block(-4,40,-22,18:3)
Block(-4,40,-21,18:3)
Block(-4,40,-20,18:3)
Block(-4,40,-7,18:3)
Block(-4,40,-6,18:3)
Block(-4,40,-5,18:3)
Block(-4,40,-4,18:3)
Block(-4,40,-3,18:3)
Block(-4,40,-2,18:3)
Block(-4,40,-1,18:3)
Block(-4,40,0,18:3)
Block(-4,40,1,18:3)
Block(-4,40,2,18:3)
Block(-4,40,3,18:3)
Block(-4,40,4,18:3)
Block(-4,40,5,18:3)
Block(-4,40,6,18:3)
Block(-4,40,7,18:3)
Block(-4,40,8,18:3)
Block(-4,40,9,18:3)
Block(-4,40,10,18:3)
Block(-4,40,11,18:3)
Block(-4,40,19,18:3)
Block(-4,40,21,18:3)
Block(-4,40,22,18:3)
Block(-4,40,23,18:3)
Block(-4,40,24,18:3)
Block(-4,40,25,18:3)
Block(-4,40,26,18:3)
Block(-4,40,27,18:3)
Block(-4,41,-26,18:3)
Block(-4,41,-25,18:3)
Block(-4,41,-24,18:3)
Block(-4,41,-23,18:3)
Block(-4,41,-22,18:3)
Block(-4,41,-21,18:3)
Block(-4,41,-20,18:3)
Block(-4,41,-19,18:3)
Block(-4,41,-18,18:3)
Block(-4,41,-17,18:3)
Block(-4,41,-16,103)
Block(-4,41,-9,18:3)
Block(-4,41,-8,18:3)
Block(-4,41,-7,18:3)
Block(-4,41,-6,18:3)
Block(-4,41,-5,18:3)
Block(-4,41,-4,18:3)
Block(-4,41,-3,18:3)
Block(-4,41,-2,18:3)
Block(-4,41,-1,18:3)
Block(-4,41,0,18:3)
Block(-4,41,1,18:3)
Block(-4,41,2,18:3)
Block(-4,41,3,18:3)
Block(-4,41,4,18:3)
Block(-4,41,5,18:3)
Block(-4,41,6,18:3)
Block(-4,41,7,18:3)
Block(-4,41,8,18:3)
Block(-4,41,9,18:3)
Block(-4,41,10,18:3)
Block(-4,41,11,18:3)
Block(-4,41,12,18:3)
Block(-4,41,13,18:3)
Block(-4,41,14,18:3)
Block(-4,41,17,18:3)
Block(-4,41,18,18:3)
Block(-4,41,19,18:3)
Block(-4,41,20,18:3)
Block(-4,41,21,18:3)
Block(-4,41,22,18:3)
Block(-4,41,23,18:3)
Block(-4,41,24,18:3)
Block(-4,41,25,18:3)
Block(-4,41,26,18:3)
Block(-4,42,-25,18:3)
Block(-4,42,-24,18:3)
Block(-4,42,-23,18:3)
Block(-4,42,-22,18:3)
Block(-4,42,-21,18:3)
Block(-4,42,-20,18:3)
Block(-4,42,-19,18:3)
Block(-4,42,-18,18:3)
Block(-4,42,-17,18:3)
Block(-4,42,-16,18:3)
Block(-4,42,-15,18:3)
Block(-4,42,-11,18:3)
Block(-4,42,-10,18:3)
Block(-4,42,-9,18:3)
Block(-4,42,-8,18:3)
Block(-4,42,-7,18:3)
Block(-4,42,-6,18:3)
Block(-4,42,-5,18:3)
Block(-4,42,-4,18:3)
Block(-4,42,-3,18:3)
Block(-4,42,-2,18:3)
Block(-4,42,-1,18:3)
Block(-4,42,0,18:3)
Block(-4,42,1,18:3)
Block(-4,42,2,18:3)
Block(-4,42,3,18:3)
Block(-4,42,4,18:3)
Block(-4,42,5,18:3)
Block(-4,42,6,18:3)
Block(-4,42,7,18:3)
Block(-4,42,8,18:3)
Block(-4,42,9,18:3)
Block(-4,42,10,18:3)
Block(-4,42,11,18:3)
Block(-4,42,12,18:3)
Block(-4,42,13,18:3)
Block(-4,42,14,18:3)
Block(-4,42,15,18:3)
Block(-4,42,16,18:3)
Block(-4,42,17,18:3)
Block(-4,42,18,18:3)
Block(-4,42,19,18:3)
Block(-4,42,20,18:3)
Block(-4,42,21,18:3)
Block(-4,42,22,18:3)
Block(-4,42,23,18:3)
Block(-4,42,24,18:3)
Block(-4,42,25,18:3)
Block(-4,43,-24,18:3)
Block(-4,43,-23,18:3)
Block(-4,43,-22,18:3)
Block(-4,43,-21,18:3)
Block(-4,43,-20,18:3)
Block(-4,43,-19,18:3)
Block(-4,43,-18,18:3)
Block(-4,43,-17,18:3)
Block(-4,43,-16,18:3)
Block(-4,43,-15,18:3)
Block(-4,43,-14,18:3)
Block(-4,43,-13,18:3)
Block(-4,43,-12,18:3)
Block(-4,43,-11,18:3)
Block(-4,43,-10,18:3)
Block(-4,43,-9,18:3)
Block(-4,43,-8,18:3)
Block(-4,43,-7,18:3)
Block(-4,43,-6,18:3)
Block(-4,43,-5,18:3)
Block(-4,43,-4,18:3)
Block(-4,43,-3,18:3)
Block(-4,43,-2,18:3)
Block(-4,43,-1,18:3)
Block(-4,43,0,18:3)
Block(-4,43,1,18:3)
Block(-4,43,2,18:3)
Block(-4,43,3,18:3)
Block(-4,43,4,18:3)
Block(-4,43,5,18:3)
Block(-4,43,6,18:3)
Block(-4,43,7,18:3)
Block(-4,43,8,18:3)
Block(-4,43,9,18:3)
Block(-4,43,10,18:3)
Block(-4,43,11,18:3)
Block(-4,43,12,18:3)
Block(-4,43,13,18:3)
Block(-4,43,14,18:3)
Block(-4,43,15,18:3)
Block(-4,43,16,18:3)
Block(-4,43,17,18:3)
Block(-4,43,18,18:3)
Block(-4,43,19,18:3)
Block(-4,43,20,18:3)
Block(-4,43,21,18:3)
Block(-4,43,22,18:3)
Block(-4,43,23,18:3)
Block(-4,43,24,18:3)
Block(-4,44,-19,18:3)
Block(-4,44,-18,18:3)
Block(-4,44,-17,18:3)
Block(-4,44,-16,18:3)
Block(-4,44,-15,18:3)
Block(-4,44,-14,18:3)
Block(-4,44,-13,18:3)
Block(-4,44,-12,18:3)
Block(-4,44,-11,18:3)
Block(-4,44,-10,18:3)
Block(-4,44,-9,18:3)
Block(-4,44,-8,18:3)
Block(-4,44,-7,18:3)
Block(-4,44,-6,18:3)
Block(-4,44,-5,18:3)
Block(-4,44,-4,18:3)
Block(-4,44,-3,18:3)
Block(-4,44,-2,18:3)
Block(-4,44,-1,18:3)
Block(-4,44,0,18:3)
Block(-4,44,1,18:3)
Block(-4,44,2,18:3)
Block(-4,44,3,18:3)
Block(-4,44,4,18:3)
Block(-4,44,5,18:3)
Block(-4,44,6,18:3)
Block(-4,44,7,18:3)
Block(-4,44,8,18:3)
Block(-4,44,9,18:3)
Block(-4,44,10,18:3)
Block(-4,44,11,18:3)
Block(-4,44,12,18:3)
Block(-4,44,13,18:3)
Block(-4,44,14,18:3)
Block(-4,44,15,18:3)
Block(-4,44,16,18:3)
Block(-4,44,17,18:3)
Block(-4,44,18,18:3)
Block(-4,44,19,18:3)
Block(-4,44,20,18:3)
Block(-4,44,21,18:3)
Block(-4,44,22,18:3)
Block(-4,44,23,18:3)
Block(-4,45,-15,18:3)
Block(-4,45,-14,18:3)
Block(-4,45,-13,18:3)
Block(-4,45,-12,18:3)
Block(-4,45,-11,18:3)
Block(-4,45,-10,18:3)
Block(-4,45,-9,18:3)
Block(-4,45,-8,18:3)
Block(-4,45,-7,18:3)
Block(-4,45,-6,18:3)
Block(-4,45,-5,18:3)
Block(-4,45,-4,18:3)
Block(-4,45,-3,18:3)
Block(-4,45,-2,18:3)
Block(-4,45,-1,18:3)
Block(-4,45,0,18:3)
Block(-4,45,1,18:3)
Block(-4,45,2,18:3)
Block(-4,45,3,18:3)
Block(-4,45,4,18:3)
Block(-4,45,5,18:3)
Block(-4,45,6,18:3)
Block(-4,45,7,18:3)
Block(-4,45,8,18:3)
Block(-4,45,9,18:3)
Block(-4,45,10,18:3)
Block(-4,45,11,18:3)
Block(-4,45,12,18:3)
Block(-4,45,13,18:3)
Block(-4,45,14,18:3)
Block(-4,45,15,18:3)
Block(-4,45,16,18:3)
Block(-4,45,17,18:3)
Block(-4,45,18,18:3)
Block(-4,45,19,18:3)
Block(-4,45,20,18:3)
Block(-4,46,-14,18:3)
Block(-4,46,-13,18:3)
Block(-4,46,-12,18:3)
Block(-4,46,-11,18:3)
Block(-4,46,-10,18:3)
Block(-4,46,-9,18:3)
Block(-4,46,-8,18:3)
Block(-4,46,-7,18:3)
Block(-4,46,-6,18:3)
Block(-4,46,-5,18:3)
Block(-4,46,-4,18:3)
Block(-4,46,-3,18:3)
Block(-4,46,-2,18:3)
Block(-4,46,-1,18:3)
Block(-4,46,0,18:3)
Block(-4,46,1,18:3)
Block(-4,46,2,18:3)
Block(-4,46,3,18:3)
Block(-4,46,4,18:3)
Block(-4,46,5,18:3)
Block(-4,46,11,18:3)
Block(-4,46,12,18:3)
Block(-4,46,13,18:3)
Block(-4,46,14,18:3)
Block(-4,46,15,18:3)
Block(-4,46,16,18:3)
Block(-4,46,17,18:3)
Block(-4,46,18,18:3)
Block(-4,47,-6,18:3)
Block(-4,47,-5,18:3)
Block(-4,47,-4,18:3)
Block(-4,47,-3,18:3)
Block(-4,47,-2,18:3)
Block(-4,47,-1,18:3)
Block(-4,47,0,18:3)
Block(-4,47,1,18:3)
Block(-4,47,2,18:3)
Block(-4,47,3,18:3)
Block(-4,47,4,18:3)
Block(-4,48,-5,18:3)
Block(-4,48,-4,18:3)
Block(-4,48,-3,18:3)
Block(-4,48,-2,18:3)
Block(-4,48,-1,18:3)
Block(-4,48,0,18:3)
Block(-4,49,-3,18:3)
Block(-4,49,-2,18:3)
Block(-3,0,-7,17:15)
Block(-3,0,-6,17:15)
Block(-3,0,-5,17:15)
Block(-3,1,-6,17:15)
Block(-3,8,-3,17:15)
Block(-3,9,-3,17:15)
Block(-3,10,-4,17:15)
Block(-3,10,-3,17:15)
Block(-3,11,-4,17:15)
Block(-3,11,-3,17:15)
Block(-3,11,-2,17:15)
Block(-3,12,-5,17:15)
Block(-3,12,-4,17:15)
Block(-3,12,-3,17:15)
Block(-3,12,-2,17:15)
Block(-3,12,-1,17:15)
Block(-3,13,-5,17:15)
Block(-3,13,-4,17:15)
Block(-3,13,-3,17:15)
Block(-3,13,-2,17:15)
Block(-3,13,-1,17:15)
Block(-3,14,-6,17:15)
Block(-3,14,-5,17:15)
Block(-3,14,-4,17:15)
Block(-3,14,-3,17:15)
Block(-3,14,-2,17:15)
Block(-3,14,-1,17:15)
Block(-3,15,-5,17:15)
Block(-3,15,-4,17:15)
Block(-3,15,-3,17:15)
Block(-3,15,-2,17:15)
Block(-3,15,-1,17:15)
Block(-3,16,-5,17:15)
Block(-3,16,-4,17:15)
Block(-3,16,-3,17:15)
Block(-3,16,-2,17:15)
Block(-3,16,-1,17:15)
Block(-3,16,0,17:15)
Block(-3,17,-5,17:15)
Block(-3,17,-4,17:15)
Block(-3,17,-3,17:15)
Block(-3,17,-2,17:15)
Block(-3,17,-1,17:15)
Block(-3,17,0,17:15)
Block(-3,18,-5,17:15)
Block(-3,18,-4,17:15)
Block(-3,18,-3,17:15)
Block(-3,18,-2,17:15)
Block(-3,18,-1,17:15)
Block(-3,18,0,17:15)
Block(-3,19,-6,17:15)
Block(-3,19,-5,17:15)
Block(-3,19,-4,17:15)
Block(-3,19,-3,17:15)
Block(-3,19,-2,17:15)
Block(-3,19,-1,17:15)
Block(-3,19,0,17:15)
Block(-3,20,-6,17:15)
Block(-3,20,-5,17:15)
Block(-3,20,-4,17:15)
Block(-3,20,-3,17:15)
Block(-3,20,-2,17:15)
Block(-3,20,-1,17:15)
Block(-3,20,0,17:15)
Block(-3,21,-6,17:15)
Block(-3,21,-5,17:15)
Block(-3,21,-4,17:15)
Block(-3,21,-3,17:15)
Block(-3,21,-2,17:15)
Block(-3,21,-1,17:15)
Block(-3,21,0,17:15)
Block(-3,21,1,17:15)
Block(-3,22,-6,17:15)
Block(-3,22,-5,17:15)
Block(-3,22,-4,17:15)
Block(-3,22,-3,17:15)
Block(-3,22,-2,17:15)
Block(-3,22,-1,17:15)
Block(-3,22,0,17:15)
Block(-3,22,1,17:15)
Block(-3,23,-6,17:15)
Block(-3,23,-5,17:15)
Block(-3,23,-4,17:15)
Block(-3,23,-3,17:15)
Block(-3,23,-2,17:15)
Block(-3,23,-1,17:15)
Block(-3,23,0,17:15)
Block(-3,23,1,17:15)
Block(-3,23,2,17:15)
Block(-3,24,-5,17:15)
Block(-3,24,-4,17:15)
Block(-3,24,-3,17:15)
Block(-3,24,-2,17:15)
Block(-3,24,-1,17:15)
Block(-3,24,0,17:15)
Block(-3,24,1,17:15)
Block(-3,24,2,17:15)
Block(-3,25,-5,17:15)
Block(-3,25,-4,17:15)
Block(-3,25,-3,17:15)
Block(-3,25,-2,17:15)
Block(-3,25,-1,17:15)
Block(-3,25,0,17:15)
Block(-3,25,1,17:15)
Block(-3,25,2,17:15)
Block(-3,25,3,17:15)
Block(-3,26,-5,17:15)
Block(-3,26,-4,17:15)
Block(-3,26,-3,17:15)
Block(-3,26,-2,17:15)
Block(-3,26,-1,17:15)
Block(-3,26,0,17:15)
Block(-3,26,1,17:15)
Block(-3,26,2,17:15)
Block(-3,26,3,17:15)
Block(-3,27,-5,17:15)
Block(-3,27,-4,17:15)
Block(-3,27,-3,17:15)
Block(-3,27,-2,17:15)
Block(-3,27,-1,17:15)
Block(-3,27,0,17:15)
Block(-3,27,1,17:15)
Block(-3,27,2,17:15)
Block(-3,27,3,17:15)
Block(-3,28,-5,17:15)
Block(-3,28,-4,17:15)
Block(-3,28,-3,17:15)
Block(-3,28,-2,17:15)
Block(-3,28,-1,17:15)
Block(-3,28,0,17:15)
Block(-3,28,1,17:15)
Block(-3,28,2,17:15)
Block(-3,28,3,17:15)
Block(-3,28,4,18:3)
Block(-3,29,-5,17:15)
Block(-3,29,-4,17:15)
Block(-3,29,-3,17:15)
Block(-3,29,-2,17:15)
Block(-3,29,-1,17:15)
Block(-3,29,0,17:15)
Block(-3,29,1,17:15)
Block(-3,29,2,17:15)
Block(-3,29,3,17:15)
Block(-3,29,4,17:15)
Block(-3,30,-4,17:15)
Block(-3,30,-3,17:15)
Block(-3,30,-2,17:15)
Block(-3,30,-1,17:15)
Block(-3,30,0,17:15)
Block(-3,30,1,17:15)
Block(-3,30,2,17:15)
Block(-3,30,3,17:15)
Block(-3,30,4,17:15)
Block(-3,31,-4,17:15)
Block(-3,31,-3,17:15)
Block(-3,31,-2,17:15)
Block(-3,31,-1,17:15)
Block(-3,31,0,17:15)
Block(-3,31,1,17:15)
Block(-3,31,2,17:15)
Block(-3,31,3,17:15)
Block(-3,31,4,17:15)
Block(-3,32,-4,17:15)
Block(-3,32,-3,17:15)
Block(-3,32,-2,17:15)
Block(-3,32,-1,17:15)
Block(-3,32,0,17:15)
Block(-3,32,1,17:15)
Block(-3,32,2,17:15)
Block(-3,32,3,17:15)
Block(-3,32,4,17:15)
Block(-3,33,-4,17:15)
Block(-3,33,-3,17:15)
Block(-3,33,-2,17:15)
Block(-3,33,-1,17:15)
Block(-3,33,0,17:15)
Block(-3,33,1,17:15)
Block(-3,33,2,17:15)
Block(-3,33,3,17:15)
Block(-3,33,4,17:15)
Block(-3,34,-5,127:8)
Block(-3,34,-4,17:15)
Block(-3,34,-3,17:15)
Block(-3,34,-2,17:15)
Block(-3,34,-1,17:15)
Block(-3,34,0,17:15)
Block(-3,34,1,17:15)
Block(-3,34,2,17:15)
Block(-3,34,3,17:15)
Block(-3,34,4,17:15)
Block(-3,35,-4,17:15)
Block(-3,35,-3,17:15)
Block(-3,35,-2,17:15)
Block(-3,35,-1,17:15)
Block(-3,35,0,17:15)
Block(-3,35,1,17:15)
Block(-3,35,2,17:15)
Block(-3,35,3,17:15)
Block(-3,35,4,17:15)
Block(-3,35,5,127:10)
Block(-3,36,-4,17:15)
Block(-3,36,-3,17:15)
Block(-3,36,-2,17:15)
Block(-3,36,-1,17:15)
Block(-3,36,0,17:15)
Block(-3,36,1,17:15)
Block(-3,36,2,17:15)
Block(-3,36,3,17:15)
Block(-3,36,4,17:15)
Block(-3,37,-5,17:15)
Block(-3,37,-4,17:15)
Block(-3,37,-3,17:15)
Block(-3,37,-2,17:15)
Block(-3,37,-1,17:15)
Block(-3,37,0,17:15)
Block(-3,37,1,17:15)
Block(-3,37,2,17:15)
Block(-3,37,3,17:15)
Block(-3,37,4,17:15)
Block(-3,37,5,17:15)
Block(-3,38,-28,18:3)
Block(-3,38,-5,17:15)
Block(-3,38,-4,17:15)
Block(-3,38,-3,18:3)
Block(-3,38,-2,18:3)
Block(-3,38,-1,18:3)
Block(-3,38,0,18:3)
Block(-3,38,1,18:3)
Block(-3,38,2,18:3)
Block(-3,38,3,18:3)
Block(-3,38,4,17:15)
Block(-3,38,5,18:3)
Block(-3,39,-28,18:3)
Block(-3,39,-27,18:3)
Block(-3,39,-26,18:3)
Block(-3,39,-25,18:3)
Block(-3,39,-24,18:3)
Block(-3,39,-23,18:3)
Block(-3,39,-22,18:3)
Block(-3,39,-21,18:3)
Block(-3,39,-5,18:3)
Block(-3,39,-4,18:3)
Block(-3,39,-3,18:3)
Block(-3,39,-2,18:3)
Block(-3,39,-1,18:3)
Block(-3,39,0,18:3)
Block(-3,39,1,18:3)
Block(-3,39,2,18:3)
Block(-3,39,3,18:3)
Block(-3,39,4,18:3)
Block(-3,39,5,18:3)
Block(-3,39,6,18:3)
Block(-3,39,7,18:3)
Block(-3,39,22,18:3)
Block(-3,39,23,18:3)
Block(-3,39,24,18:3)
Block(-3,39,25,18:3)
Block(-3,40,-26,18:3)
Block(-3,40,-25,18:3)
Block(-3,40,-24,18:3)
Block(-3,40,-23,18:3)
Block(-3,40,-22,18:3)
Block(-3,40,-21,18:3)
Block(-3,40,-20,18:3)
Block(-3,40,-19,18:3)
Block(-3,40,-7,18:3)
Block(-3,40,-6,18:3)
Block(-3,40,-5,18:3)
Block(-3,40,-4,18:3)
Block(-3,40,-3,18:3)
Block(-3,40,-2,18:3)
Block(-3,40,-1,18:3)
Block(-3,40,0,18:3)
Block(-3,40,1,18:3)
Block(-3,40,2,18:3)
Block(-3,40,3,18:3)
Block(-3,40,4,18:3)
Block(-3,40,5,18:3)
Block(-3,40,6,18:3)
Block(-3,40,7,18:3)
Block(-3,40,8,18:3)
Block(-3,40,9,18:3)
Block(-3,40,20,103)
Block(-3,40,21,18:3)
Block(-3,40,22,18:3)
Block(-3,40,23,18:3)
Block(-3,40,24,18:3)
Block(-3,40,25,18:3)
Block(-3,40,26,18:3)
Block(-3,41,-25,18:3)
Block(-3,41,-24,18:3)
Block(-3,41,-23,18:3)
Block(-3,41,-22,18:3)
Block(-3,41,-21,18:3)
Block(-3,41,-20,18:3)
Block(-3,41,-19,18:3)
Block(-3,41,-18,18:3)
Block(-3,41,-17,18:3)
Block(-3,41,-9,18:3)
Block(-3,41,-8,18:3)
Block(-3,41,-7,18:3)
Block(-3,41,-6,18:3)
Block(-3,41,-5,18:3)
Block(-3,41,-4,18:3)
Block(-3,41,-3,18:3)
Block(-3,41,-2,18:3)
Block(-3,41,-1,18:3)
Block(-3,41,0,18:3)
Block(-3,41,1,18:3)
Block(-3,41,2,18:3)
Block(-3,41,3,18:3)
Block(-3,41,4,18:3)
Block(-3,41,5,18:3)
Block(-3,41,6,18:3)
Block(-3,41,7,18:3)
Block(-3,41,8,18:3)
Block(-3,41,9,18:3)
Block(-3,41,10,18:3)
Block(-3,41,11,18:3)
Block(-3,41,12,18:3)
Block(-3,41,13,18:3)
Block(-3,41,17,18:3)
Block(-3,41,18,18:3)
Block(-3,41,19,18:3)
Block(-3,41,20,18:3)
Block(-3,41,21,18:3)
Block(-3,41,22,18:3)
Block(-3,41,23,18:3)
Block(-3,41,24,18:3)
Block(-3,41,25,18:3)
Block(-3,42,-25,18:3)
Block(-3,42,-24,18:3)
Block(-3,42,-23,18:3)
Block(-3,42,-22,18:3)
Block(-3,42,-21,18:3)
Block(-3,42,-20,18:3)
Block(-3,42,-19,18:3)
Block(-3,42,-18,18:3)
Block(-3,42,-17,18:3)
Block(-3,42,-16,18:3)
Block(-3,42,-15,18:3)
Block(-3,42,-11,18:3)
Block(-3,42,-10,18:3)
Block(-3,42,-9,18:3)
Block(-3,42,-8,18:3)
Block(-3,42,-7,18:3)
Block(-3,42,-6,18:3)
Block(-3,42,-5,18:3)
Block(-3,42,-4,18:3)
Block(-3,42,-3,18:3)
Block(-3,42,-2,18:3)
Block(-3,42,-1,18:3)
Block(-3,42,0,18:3)
Block(-3,42,1,18:3)
Block(-3,42,2,18:3)
Block(-3,42,3,18:3)
Block(-3,42,4,18:3)
Block(-3,42,5,18:3)
Block(-3,42,6,18:3)
Block(-3,42,7,18:3)
Block(-3,42,8,18:3)
Block(-3,42,9,18:3)
Block(-3,42,10,18:3)
Block(-3,42,11,18:3)
Block(-3,42,12,18:3)
Block(-3,42,13,18:3)
Block(-3,42,14,18:3)
Block(-3,42,15,18:3)
Block(-3,42,16,18:3)
Block(-3,42,17,18:3)
Block(-3,42,18,18:3)
Block(-3,42,19,18:3)
Block(-3,42,20,18:3)
Block(-3,42,21,18:3)
Block(-3,42,22,18:3)
Block(-3,42,23,18:3)
Block(-3,42,24,18:3)
Block(-3,42,25,18:3)
Block(-3,43,-23,18:3)
Block(-3,43,-22,18:3)
Block(-3,43,-21,18:3)
Block(-3,43,-20,18:3)
Block(-3,43,-19,18:3)
Block(-3,43,-18,18:3)
Block(-3,43,-17,18:3)
Block(-3,43,-16,18:3)
Block(-3,43,-15,18:3)
Block(-3,43,-14,18:3)
Block(-3,43,-13,18:3)
Block(-3,43,-12,18:3)
Block(-3,43,-11,18:3)
Block(-3,43,-10,18:3)
Block(-3,43,-9,18:3)
Block(-3,43,-8,18:3)
Block(-3,43,-7,18:3)
Block(-3,43,-6,18:3)
Block(-3,43,-5,18:3)
Block(-3,43,-4,18:3)
Block(-3,43,-3,18:3)
Block(-3,43,-2,18:3)
Block(-3,43,-1,18:3)
Block(-3,43,0,18:3)
Block(-3,43,1,18:3)
Block(-3,43,2,18:3)
Block(-3,43,3,18:3)
Block(-3,43,4,18:3)
Block(-3,43,5,18:3)
Block(-3,43,6,18:3)
Block(-3,43,7,18:3)
Block(-3,43,8,18:3)
Block(-3,43,9,18:3)
Block(-3,43,10,18:3)
Block(-3,43,11,18:3)
Block(-3,43,12,18:3)
Block(-3,43,13,18:3)
Block(-3,43,14,18:3)
Block(-3,43,15,18:3)
Block(-3,43,16,18:3)
Block(-3,43,17,18:3)
Block(-3,43,18,18:3)
Block(-3,43,19,18:3)
Block(-3,43,20,18:3)
Block(-3,43,21,18:3)
Block(-3,43,22,18:3)
Block(-3,43,23,18:3)
Block(-3,44,-21,18:3)
Block(-3,44,-20,18:3)
Block(-3,44,-19,18:3)
Block(-3,44,-18,18:3)
Block(-3,44,-17,18:3)
Block(-3,44,-16,18:3)
Block(-3,44,-15,18:3)
Block(-3,44,-14,18:3)
Block(-3,44,-13,18:3)
Block(-3,44,-12,18:3)
Block(-3,44,-11,18:3)
Block(-3,44,-10,18:3)
Block(-3,44,-9,18:3)
Block(-3,44,-8,18:3)
Block(-3,44,-7,18:3)
Block(-3,44,-6,18:3)
Block(-3,44,-5,18:3)
Block(-3,44,-4,18:3)
Block(-3,44,-3,18:3)
Block(-3,44,-2,18:3)
Block(-3,44,-1,18:3)
Block(-3,44,0,18:3)
Block(-3,44,1,18:3)
Block(-3,44,2,18:3)
Block(-3,44,3,18:3)
Block(-3,44,4,18:3)
Block(-3,44,5,18:3)
Block(-3,44,6,18:3)
Block(-3,44,7,18:3)
Block(-3,44,8,18:3)
Block(-3,44,9,18:3)
Block(-3,44,10,18:3)
Block(-3,44,11,18:3)
Block(-3,44,12,18:3)
Block(-3,44,13,18:3)
Block(-3,44,14,18:3)
Block(-3,44,15,18:3)
Block(-3,44,16,18:3)
Block(-3,44,17,18:3)
Block(-3,44,18,18:3)
Block(-3,44,19,18:3)
Block(-3,44,20,18:3)
Block(-3,44,21,18:3)
Block(-3,44,22,18:3)
Block(-3,45,-16,18:3)
Block(-3,45,-15,18:3)
Block(-3,45,-14,18:3)
Block(-3,45,-13,18:3)
Block(-3,45,-12,18:3)
Block(-3,45,-11,18:3)
Block(-3,45,-10,18:3)
Block(-3,45,-9,18:3)
Block(-3,45,-8,18:3)
Block(-3,45,-7,18:3)
Block(-3,45,-6,18:3)
Block(-3,45,-5,18:3)
Block(-3,45,-4,18:3)
Block(-3,45,-3,18:3)
Block(-3,45,-2,18:3)
Block(-3,45,-1,18:3)
Block(-3,45,0,18:3)
Block(-3,45,1,18:3)
Block(-3,45,2,18:3)
Block(-3,45,3,18:3)
Block(-3,45,4,18:3)
Block(-3,45,5,18:3)
Block(-3,45,6,18:3)
Block(-3,45,7,18:3)
Block(-3,45,8,18:3)
Block(-3,45,9,18:3)
Block(-3,45,10,18:3)
Block(-3,45,11,18:3)
Block(-3,45,12,18:3)
Block(-3,45,13,18:3)
Block(-3,45,14,18:3)
Block(-3,45,15,18:3)
Block(-3,45,16,18:3)
Block(-3,45,17,18:3)
Block(-3,45,18,18:3)
Block(-3,46,-14,18:3)
Block(-3,46,-13,18:3)
Block(-3,46,-12,18:3)
Block(-3,46,-11,18:3)
Block(-3,46,-10,18:3)
Block(-3,46,-9,18:3)
Block(-3,46,-8,18:3)
Block(-3,46,-7,18:3)
Block(-3,46,-6,18:3)
Block(-3,46,-5,18:3)
Block(-3,46,-4,18:3)
Block(-3,46,-3,18:3)
Block(-3,46,-2,18:3)
Block(-3,46,-1,18:3)
Block(-3,46,0,18:3)
Block(-3,46,1,18:3)
Block(-3,46,2,18:3)
Block(-3,46,3,18:3)
Block(-3,46,4,18:3)
Block(-3,46,5,18:3)
Block(-3,46,6,18:3)
Block(-3,46,7,18:3)
Block(-3,46,8,18:3)
Block(-3,46,9,18:3)
Block(-3,46,13,18:3)
Block(-3,46,14,18:3)
Block(-3,46,15,18:3)
Block(-3,47,-12,18:3)
Block(-3,47,-11,18:3)
Block(-3,47,-10,18:3)
Block(-3,47,-7,18:3)
Block(-3,47,-6,18:3)
Block(-3,47,-5,18:3)
Block(-3,47,-4,18:3)
Block(-3,47,-3,18:3)
Block(-3,47,-2,18:3)
Block(-3,47,-1,18:3)
Block(-3,47,0,18:3)
Block(-3,47,1,18:3)
Block(-3,47,2,18:3)
Block(-3,47,3,18:3)
Block(-3,47,4,18:3)
Block(-3,47,5,18:3)
Block(-3,48,-6,18:3)
Block(-3,48,-5,18:3)
Block(-3,48,-4,18:3)
Block(-3,48,-3,18:3)
Block(-3,48,-2,18:3)
Block(-3,48,-1,18:3)
Block(-3,48,0,18:3)
Block(-3,48,1,18:3)
Block(-3,48,2,18:3)
Block(-3,48,3,18:3)
Block(-3,49,-5,18:3)
Block(-3,49,-4,18:3)
Block(-3,49,-3,18:3)
Block(-3,49,-2,18:3)
Block(-3,49,-1,18:3)
Block(-3,49,0,18:3)
Block(-2,0,-9,17:15)
Block(-2,0,-8,17:15)
Block(-2,0,-7,17:15)
Block(-2,0,-6,17:15)
Block(-2,0,-5,17:15)
Block(-2,0,-2,18:3)
Block(-2,0,-1,17:15)
Block(-2,0,0,17:15)
Block(-2,1,-8,17:15)
Block(-2,1,-7,17:15)
Block(-2,1,-6,17:15)
Block(-2,1,-5,17:15)
Block(-2,1,-4,17:15)
Block(-2,1,-1,18:3)
Block(-2,2,-6,17:15)
Block(-2,2,-5,17:15)
Block(-2,2,-4,17:15)
Block(-2,2,-3,17:15)
Block(-2,3,-6,17:15)
Block(-2,3,-5,17:15)
Block(-2,3,-4,17:15)
Block(-2,3,-3,17:15)
Block(-2,4,-5,17:15)
Block(-2,4,-4,17:15)
Block(-2,4,-3,17:15)
Block(-2,4,-2,17:15)
Block(-2,5,-7,18:3)
Block(-2,5,-5,17:15)
Block(-2,5,-4,17:15)
Block(-2,5,-3,17:15)
Block(-2,5,-2,17:15)
Block(-2,6,-7,18:3)
Block(-2,6,-5,17:15)
Block(-2,6,-4,17:15)
Block(-2,6,-3,17:15)
Block(-2,6,-2,17:15)
Block(-2,7,-5,17:15)
Block(-2,7,-4,17:15)
Block(-2,7,-3,17:15)
Block(-2,7,-2,17:15)
Block(-2,7,-1,17:15)
Block(-2,8,-5,17:15)
Block(-2,8,-4,17:15)
Block(-2,8,-3,17:15)
Block(-2,8,-2,17:15)
Block(-2,8,-1,17:15)
Block(-2,9,-5,17:15)
Block(-2,9,-4,17:15)
Block(-2,9,-3,17:15)
Block(-2,9,-2,17:15)
Block(-2,9,-1,17:15)
Block(-2,10,-6,17:15)
Block(-2,10,-5,17:15)
Block(-2,10,-4,17:15)
Block(-2,10,-3,17:15)
Block(-2,10,-2,17:15)
Block(-2,10,-1,17:15)
Block(-2,10,0,17:15)
Block(-2,11,-5,17:15)
Block(-2,11,-4,17:15)
Block(-2,11,-3,17:15)
Block(-2,11,-2,17:15)
Block(-2,11,-1,17:15)
Block(-2,11,0,17:15)
Block(-2,12,-6,17:15)
Block(-2,12,-5,17:15)
Block(-2,12,-4,17:15)
Block(-2,12,-3,17:15)
Block(-2,12,-2,17:15)
Block(-2,12,-1,17:15)
Block(-2,12,0,17:15)
Block(-2,13,-6,17:15)
Block(-2,13,-5,17:15)
Block(-2,13,-4,17:15)
Block(-2,13,-3,17:15)
Block(-2,13,-2,17:15)
Block(-2,13,-1,17:15)
Block(-2,13,0,17:15)
Block(-2,14,-7,17:15)
Block(-2,14,-6,17:15)
Block(-2,14,-5,17:15)
Block(-2,14,-4,17:15)
Block(-2,14,-3,17:15)
Block(-2,14,-2,17:15)
Block(-2,14,-1,17:15)
Block(-2,14,0,17:15)
Block(-2,14,1,17:15)
Block(-2,15,-6,17:15)
Block(-2,15,-5,17:15)
Block(-2,15,-4,17:15)
Block(-2,15,-3,17:15)
Block(-2,15,-2,17:15)
Block(-2,15,-1,17:15)
Block(-2,15,0,17:15)
Block(-2,15,1,17:15)
Block(-2,16,-6,17:15)
Block(-2,16,-5,17:15)
Block(-2,16,-4,17:15)
Block(-2,16,-3,17:15)
Block(-2,16,-2,17:15)
Block(-2,16,-1,17:15)
Block(-2,16,0,17:15)
Block(-2,16,1,17:15)
Block(-2,17,-6,17:15)
Block(-2,17,-5,17:15)
Block(-2,17,-4,17:15)
Block(-2,17,-3,17:15)
Block(-2,17,-2,17:15)
Block(-2,17,-1,17:15)
Block(-2,17,0,17:15)
Block(-2,18,-6,17:15)
Block(-2,18,-5,17:15)
Block(-2,18,-4,17:15)
Block(-2,18,-3,17:15)
Block(-2,18,-2,17:15)
Block(-2,18,-1,17:15)
Block(-2,18,0,17:15)
Block(-2,19,-7,17:15)
Block(-2,19,-6,17:15)
Block(-2,19,-5,17:15)
Block(-2,19,-4,17:15)
Block(-2,19,-3,17:15)
Block(-2,19,-2,17:15)
Block(-2,19,-1,17:15)
Block(-2,19,0,17:15)
Block(-2,19,1,17:15)
Block(-2,20,-6,17:15)
Block(-2,20,-5,17:15)
Block(-2,20,-4,17:15)
Block(-2,20,-3,17:15)
Block(-2,20,-2,17:15)
Block(-2,20,-1,17:15)
Block(-2,20,0,17:15)
Block(-2,20,1,17:15)
Block(-2,21,-6,17:15)
Block(-2,21,-5,17:15)
Block(-2,21,-4,17:15)
Block(-2,21,-3,17:15)
Block(-2,21,-2,17:15)
Block(-2,21,-1,17:15)
Block(-2,21,0,17:15)
Block(-2,21,1,17:15)
Block(-2,21,2,17:15)
Block(-2,22,-6,17:15)
Block(-2,22,-5,17:15)
Block(-2,22,-4,17:15)
Block(-2,22,-3,17:15)
Block(-2,22,-2,17:15)
Block(-2,22,-1,17:15)
Block(-2,22,0,17:15)
Block(-2,22,1,17:15)
Block(-2,22,2,17:15)
Block(-2,23,-6,17:15)
Block(-2,23,-5,17:15)
Block(-2,23,-4,17:15)
Block(-2,23,-3,17:15)
Block(-2,23,-2,17:15)
Block(-2,23,-1,17:15)
Block(-2,23,0,17:15)
Block(-2,23,1,17:15)
Block(-2,23,2,17:15)
Block(-2,24,-6,17:15)
Block(-2,24,-5,17:15)
Block(-2,24,-4,17:15)
Block(-2,24,-3,17:15)
Block(-2,24,-2,17:15)
Block(-2,24,-1,17:15)
Block(-2,24,0,17:15)
Block(-2,24,1,17:15)
Block(-2,24,2,17:15)
Block(-2,25,-6,17:15)
Block(-2,25,-5,17:15)
Block(-2,25,-4,17:15)
Block(-2,25,-3,17:15)
Block(-2,25,-2,17:15)
Block(-2,25,-1,17:15)
Block(-2,25,0,17:15)
Block(-2,25,1,17:15)
Block(-2,25,2,17:15)
Block(-2,25,3,17:15)
Block(-2,26,-5,17:15)
Block(-2,26,-4,17:15)
Block(-2,26,-3,17:15)
Block(-2,26,-2,17:15)
Block(-2,26,-1,17:15)
Block(-2,26,0,17:15)
Block(-2,26,1,17:15)
Block(-2,26,2,17:15)
Block(-2,26,3,17:15)
Block(-2,26,4,18:3)
Block(-2,27,-5,17:15)
Block(-2,27,-4,17:15)
Block(-2,27,-3,17:15)
Block(-2,27,-2,17:15)
Block(-2,27,-1,17:15)
Block(-2,27,0,17:15)
Block(-2,27,1,17:15)
Block(-2,27,2,17:15)
Block(-2,27,3,17:15)
Block(-2,27,4,18:3)
Block(-2,28,-5,17:15)
Block(-2,28,-4,17:15)
Block(-2,28,-3,17:15)
Block(-2,28,-2,17:15)
Block(-2,28,-1,17:15)
Block(-2,28,0,17:15)
Block(-2,28,1,17:15)
Block(-2,28,2,17:15)
Block(-2,28,3,17:15)
Block(-2,28,4,17:15)
Block(-2,29,-5,17:15)
Block(-2,29,-4,17:15)
Block(-2,29,-3,17:15)
Block(-2,29,-2,17:15)
Block(-2,29,-1,17:15)
Block(-2,29,0,17:15)
Block(-2,29,1,17:15)
Block(-2,29,2,17:15)
Block(-2,29,3,17:15)
Block(-2,29,4,17:15)
Block(-2,30,-5,17:15)
Block(-2,30,-4,17:15)
Block(-2,30,-3,17:15)
Block(-2,30,-2,17:15)
Block(-2,30,-1,17:15)
Block(-2,30,0,17:15)
Block(-2,30,1,17:15)
Block(-2,30,2,17:15)
Block(-2,30,3,17:15)
Block(-2,30,4,17:15)
Block(-2,31,-5,17:15)
Block(-2,31,-4,17:15)
Block(-2,31,-3,17:15)
Block(-2,31,-2,17:15)
Block(-2,31,-1,17:15)
Block(-2,31,0,17:15)
Block(-2,31,1,17:15)
Block(-2,31,2,17:15)
Block(-2,31,3,17:15)
Block(-2,31,4,17:15)
Block(-2,32,-4,17:15)
Block(-2,32,-3,17:15)
Block(-2,32,-2,17:15)
Block(-2,32,-1,17:15)
Block(-2,32,0,17:15)
Block(-2,32,1,17:15)
Block(-2,32,2,17:15)
Block(-2,32,3,17:15)
Block(-2,32,4,17:15)
Block(-2,33,-4,17:15)
Block(-2,33,-3,17:15)
Block(-2,33,-2,17:15)
Block(-2,33,-1,17:15)
Block(-2,33,0,17:15)
Block(-2,33,1,17:15)
Block(-2,33,2,17:15)
Block(-2,33,3,17:15)
Block(-2,33,4,17:15)
Block(-2,34,-4,17:15)
Block(-2,34,-3,17:15)
Block(-2,34,-2,17:15)
Block(-2,34,-1,17:15)
Block(-2,34,0,17:15)
Block(-2,34,1,17:15)
Block(-2,34,2,17:15)
Block(-2,34,3,17:15)
Block(-2,34,4,17:15)
Block(-2,34,5,17:15)
Block(-2,35,-4,17:15)
Block(-2,35,-3,17:15)
Block(-2,35,-2,17:15)
Block(-2,35,-1,17:15)
Block(-2,35,0,17:15)
Block(-2,35,1,17:15)
Block(-2,35,2,17:15)
Block(-2,35,3,17:15)
Block(-2,35,4,17:15)
Block(-2,35,5,17:15)
Block(-2,36,-5,17:15)
Block(-2,36,-4,17:15)
Block(-2,36,-3,17:15)
Block(-2,36,-2,17:15)
Block(-2,36,-1,17:15)
Block(-2,36,0,17:15)
Block(-2,36,1,17:15)
Block(-2,36,2,17:15)
Block(-2,36,3,17:15)
Block(-2,36,4,17:15)
Block(-2,36,5,17:15)
Block(-2,37,-6,127:8)
Block(-2,37,-5,17:15)
Block(-2,37,-4,17:15)
Block(-2,37,-3,17:15)
Block(-2,37,-2,17:15)
Block(-2,37,-1,17:15)
Block(-2,37,0,18:3)
Block(-2,37,1,17:15)
Block(-2,37,2,17:15)
Block(-2,37,3,17:15)
Block(-2,37,4,17:15)
Block(-2,37,5,17:15)
Block(-2,38,-5,17:15)
Block(-2,38,-4,17:15)
Block(-2,38,-3,17:15)
Block(-2,38,-2,18:3)
Block(-2,38,-1,18:3)
Block(-2,38,0,18:3)
Block(-2,38,1,18:3)
Block(-2,38,2,18:3)
Block(-2,38,3,17:15)
Block(-2,38,4,17:15)
Block(-2,38,5,17:15)
Block(-2,39,-23,18:3)
Block(-2,39,-22,18:3)
Block(-2,39,-20,103)
Block(-2,39,-5,18:3)
Block(-2,39,-4,18:3)
Block(-2,39,-3,18:3)
Block(-2,39,-2,18:3)
Block(-2,39,-1,18:3)
Block(-2,39,0,18:3)
Block(-2,39,1,18:3)
Block(-2,39,2,18:3)
Block(-2,39,3,18:3)
Block(-2,39,4,18:3)
Block(-2,39,5,18:3)
Block(-2,39,6,18:3)
Block(-2,39,7,18:3)
Block(-2,40,-25,18:3)
Block(-2,40,-24,18:3)
Block(-2,40,-23,18:3)
Block(-2,40,-22,18:3)
Block(-2,40,-21,18:3)
Block(-2,40,-20,18:3)
Block(-2,40,-19,18:3)
Block(-2,40,-7,18:3)
Block(-2,40,-6,18:3)
Block(-2,40,-5,18:3)
Block(-2,40,-4,18:3)
Block(-2,40,-3,18:3)
Block(-2,40,-2,18:3)
Block(-2,40,-1,18:3)
Block(-2,40,0,18:3)
Block(-2,40,1,18:3)
Block(-2,40,2,18:3)
Block(-2,40,3,18:3)
Block(-2,40,4,18:3)
Block(-2,40,5,18:3)
Block(-2,40,6,18:3)
Block(-2,40,7,18:3)
Block(-2,40,23,18:3)
Block(-2,40,24,18:3)
Block(-2,40,25,18:3)
Block(-2,41,-24,18:3)
Block(-2,41,-23,18:3)
Block(-2,41,-22,18:3)
Block(-2,41,-21,18:3)
Block(-2,41,-20,18:3)
Block(-2,41,-19,18:3)
Block(-2,41,-18,18:3)
Block(-2,41,-17,18:3)
Block(-2,41,-9,18:3)
Block(-2,41,-8,18:3)
Block(-2,41,-7,18:3)
Block(-2,41,-6,18:3)
Block(-2,41,-5,18:3)
Block(-2,41,-4,18:3)
Block(-2,41,-3,18:3)
Block(-2,41,-2,18:3)
Block(-2,41,-1,18:3)
Block(-2,41,0,18:3)
Block(-2,41,1,18:3)
Block(-2,41,2,18:3)
Block(-2,41,3,18:3)
Block(-2,41,4,18:3)
Block(-2,41,5,18:3)
Block(-2,41,6,18:3)
Block(-2,41,7,18:3)
Block(-2,41,8,18:3)
Block(-2,41,9,18:3)
Block(-2,41,10,18:3)
Block(-2,41,11,18:3)
Block(-2,41,12,18:3)
Block(-2,41,21,18:3)
Block(-2,41,22,18:3)
Block(-2,41,23,18:3)
Block(-2,41,24,18:3)
Block(-2,42,-24,18:3)
Block(-2,42,-23,18:3)
Block(-2,42,-22,18:3)
Block(-2,42,-21,18:3)
Block(-2,42,-20,18:3)
Block(-2,42,-19,18:3)
Block(-2,42,-18,18:3)
Block(-2,42,-17,18:3)
Block(-2,42,-16,18:3)
Block(-2,42,-15,18:3)
Block(-2,42,-11,18:3)
Block(-2,42,-10,18:3)
Block(-2,42,-9,18:3)
Block(-2,42,-8,18:3)
Block(-2,42,-7,18:3)
Block(-2,42,-6,18:3)
Block(-2,42,-5,18:3)
Block(-2,42,-4,18:3)
Block(-2,42,-3,18:3)
Block(-2,42,-2,18:3)
Block(-2,42,-1,18:3)
Block(-2,42,0,18:3)
Block(-2,42,1,18:3)
Block(-2,42,2,18:3)
Block(-2,42,3,18:3)
Block(-2,42,4,18:3)
Block(-2,42,5,18:3)
Block(-2,42,6,18:3)
Block(-2,42,7,18:3)
Block(-2,42,8,18:3)
Block(-2,42,9,18:3)
Block(-2,42,10,18:3)
Block(-2,42,11,18:3)
Block(-2,42,12,18:3)
Block(-2,42,13,18:3)
Block(-2,42,14,18:3)
Block(-2,42,17,18:3)
Block(-2,42,18,18:3)
Block(-2,42,19,18:3)
Block(-2,42,20,18:3)
Block(-2,42,21,18:3)
Block(-2,42,22,18:3)
Block(-2,42,23,18:3)
Block(-2,42,24,18:3)
Block(-2,43,-22,18:3)
Block(-2,43,-21,18:3)
Block(-2,43,-20,18:3)
Block(-2,43,-19,18:3)
Block(-2,43,-18,18:3)
Block(-2,43,-17,18:3)
Block(-2,43,-16,18:3)
Block(-2,43,-15,18:3)
Block(-2,43,-14,18:3)
Block(-2,43,-13,18:3)
Block(-2,43,-12,18:3)
Block(-2,43,-11,18:3)
Block(-2,43,-10,18:3)
Block(-2,43,-9,18:3)
Block(-2,43,-8,18:3)
Block(-2,43,-7,18:3)
Block(-2,43,-6,18:3)
Block(-2,43,-5,18:3)
Block(-2,43,-4,18:3)
Block(-2,43,-3,18:3)
Block(-2,43,-2,18:3)
Block(-2,43,-1,18:3)
Block(-2,43,0,18:3)
Block(-2,43,1,18:3)
Block(-2,43,2,18:3)
Block(-2,43,3,18:3)
Block(-2,43,4,18:3)
Block(-2,43,5,18:3)
Block(-2,43,6,18:3)
Block(-2,43,7,18:3)
Block(-2,43,8,18:3)
Block(-2,43,9,18:3)
Block(-2,43,10,18:3)
Block(-2,43,11,18:3)
Block(-2,43,12,18:3)
Block(-2,43,13,18:3)
Block(-2,43,14,18:3)
Block(-2,43,15,18:3)
Block(-2,43,16,18:3)
Block(-2,43,17,18:3)
Block(-2,43,18,18:3)
Block(-2,43,19,18:3)
Block(-2,43,20,18:3)
Block(-2,43,21,18:3)
Block(-2,43,22,18:3)
Block(-2,44,-20,18:3)
Block(-2,44,-19,18:3)
Block(-2,44,-18,18:3)
Block(-2,44,-17,18:3)
Block(-2,44,-16,18:3)
Block(-2,44,-15,18:3)
Block(-2,44,-14,18:3)
Block(-2,44,-13,18:3)
Block(-2,44,-12,18:3)
Block(-2,44,-11,18:3)
Block(-2,44,-10,18:3)
Block(-2,44,-9,18:3)
Block(-2,44,-8,18:3)
Block(-2,44,-7,18:3)
Block(-2,44,-6,18:3)
Block(-2,44,-5,18:3)
Block(-2,44,-4,18:3)
Block(-2,44,-3,18:3)
Block(-2,44,-2,18:3)
Block(-2,44,-1,18:3)
Block(-2,44,0,18:3)
Block(-2,44,1,18:3)
Block(-2,44,2,18:3)
Block(-2,44,3,18:3)
Block(-2,44,4,18:3)
Block(-2,44,5,18:3)
Block(-2,44,6,18:3)
Block(-2,44,7,18:3)
Block(-2,44,8,18:3)
Block(-2,44,9,18:3)
Block(-2,44,10,18:3)
Block(-2,44,11,18:3)
Block(-2,44,12,18:3)
Block(-2,44,13,18:3)
Block(-2,44,14,18:3)
Block(-2,44,15,18:3)
Block(-2,44,16,18:3)
Block(-2,44,17,18:3)
Block(-2,44,18,18:3)
Block(-2,44,20,18:3)
Block(-2,44,21,18:3)
Block(-2,45,-17,18:3)
Block(-2,45,-16,18:3)
Block(-2,45,-15,18:3)
Block(-2,45,-14,18:3)
Block(-2,45,-13,18:3)
Block(-2,45,-12,18:3)
Block(-2,45,-11,18:3)
Block(-2,45,-10,18:3)
Block(-2,45,-9,18:3)
Block(-2,45,-8,18:3)
Block(-2,45,-7,18:3)
Block(-2,45,-6,18:3)
Block(-2,45,-5,18:3)
Block(-2,45,-4,18:3)
Block(-2,45,-3,18:3)
Block(-2,45,-2,18:3)
Block(-2,45,-1,18:3)
Block(-2,45,0,18:3)
Block(-2,45,1,18:3)
Block(-2,45,2,18:3)
Block(-2,45,3,18:3)
Block(-2,45,4,18:3)
Block(-2,45,5,18:3)
Block(-2,45,6,18:3)
Block(-2,45,7,18:3)
Block(-2,45,8,18:3)
Block(-2,45,9,18:3)
Block(-2,45,10,18:3)
Block(-2,45,13,18:3)
Block(-2,45,14,18:3)
Block(-2,45,15,18:3)
Block(-2,45,16,18:3)
Block(-2,45,17,18:3)
Block(-2,46,-15,18:3)
Block(-2,46,-14,18:3)
Block(-2,46,-13,18:3)
Block(-2,46,-12,18:3)
Block(-2,46,-11,18:3)
Block(-2,46,-10,18:3)
Block(-2,46,-9,18:3)
Block(-2,46,-8,18:3)
Block(-2,46,-7,18:3)
Block(-2,46,-6,18:3)
Block(-2,46,-5,18:3)
Block(-2,46,-4,18:3)
Block(-2,46,-3,18:3)
Block(-2,46,-2,18:3)
Block(-2,46,-1,18:3)
Block(-2,46,0,18:3)
Block(-2,46,1,18:3)
Block(-2,46,2,18:3)
Block(-2,46,3,18:3)
Block(-2,46,4,18:3)
Block(-2,46,5,18:3)
Block(-2,46,6,18:3)
Block(-2,46,7,18:3)
Block(-2,47,-13,18:3)
Block(-2,47,-12,18:3)
Block(-2,47,-11,18:3)
Block(-2,47,-10,18:3)
Block(-2,47,-9,18:3)
Block(-2,47,-8,18:3)
Block(-2,47,-7,18:3)
Block(-2,47,-6,18:3)
Block(-2,47,-5,18:3)
Block(-2,47,-4,18:3)
Block(-2,47,-3,18:3)
Block(-2,47,-2,18:3)
Block(-2,47,-1,18:3)
Block(-2,47,0,18:3)
Block(-2,47,1,18:3)
Block(-2,47,2,18:3)
Block(-2,47,3,18:3)
Block(-2,47,4,18:3)
Block(-2,47,5,18:3)
Block(-2,47,6,18:3)
Block(-2,48,-7,18:3)
Block(-2,48,-6,18:3)
Block(-2,48,-5,18:3)
Block(-2,48,-4,18:3)
Block(-2,48,-3,18:3)
Block(-2,48,-2,18:3)
Block(-2,48,-1,18:3)
Block(-2,48,0,18:3)
Block(-2,48,1,18:3)
Block(-2,48,2,18:3)
Block(-2,48,3,18:3)
Block(-2,48,4,18:3)
Block(-2,49,-5,18:3)
Block(-2,49,-4,18:3)
Block(-2,49,-3,18:3)
Block(-2,49,-2,18:3)
Block(-2,49,-1,18:3)
Block(-2,49,0,18:3)
Block(-2,49,1,18:3)
Block(-2,50,-3,18:3)
Block(-2,50,-2,18:3)
Block(-1,0,-9,17:15)
Block(-1,0,-8,17:15)
Block(-1,0,-7,17:15)
Block(-1,0,-6,17:15)
Block(-1,0,-5,17:15)
Block(-1,0,-4,17:15)
Block(-1,0,-3,17:15)
Block(-1,0,-2,17:15)
Block(-1,0,-1,17:15)
Block(-1,0,0,17:15)
Block(-1,0,1,17:15)
Block(-1,1,-9,17:15)
Block(-1,1,-8,17:15)
Block(-1,1,-7,17:15)
Block(-1,1,-6,17:15)
Block(-1,1,-5,17:15)
Block(-1,1,-4,17:15)
Block(-1,1,-3,17:15)
Block(-1,1,-2,17:15)
Block(-1,1,-1,17:15)
Block(-1,1,0,17:15)
Block(-1,2,-9,18:3)
Block(-1,2,-8,17:15)
Block(-1,2,-7,17:15)
Block(-1,2,-6,17:15)
Block(-1,2,-5,17:15)
Block(-1,2,-4,17:15)
Block(-1,2,-3,17:15)
Block(-1,2,-2,17:15)
Block(-1,2,-1,17:15)
Block(-1,2,0,18:3)
Block(-1,3,-7,17:15)
Block(-1,3,-6,17:15)
Block(-1,3,-5,17:15)
Block(-1,3,-4,17:15)
Block(-1,3,-3,17:15)
Block(-1,3,-2,17:15)
Block(-1,3,-1,17:15)
Block(-1,4,-7,17:15)
Block(-1,4,-6,17:15)
Block(-1,4,-5,17:15)
Block(-1,4,-4,17:15)
Block(-1,4,-3,17:15)
Block(-1,4,-2,17:15)
Block(-1,4,-1,17:15)
Block(-1,5,-7,17:15)
Block(-1,5,-6,17:15)
Block(-1,5,-5,17:15)
Block(-1,5,-4,17:15)
Block(-1,5,-3,17:15)
Block(-1,5,-2,17:15)
Block(-1,5,-1,17:15)
Block(-1,5,0,17:15)
Block(-1,6,-7,17:15)
Block(-1,6,-6,17:15)
Block(-1,6,-5,17:15)
Block(-1,6,-4,17:15)
Block(-1,6,-3,17:15)
Block(-1,6,-2,17:15)
Block(-1,6,-1,17:15)
Block(-1,6,0,17:15)
Block(-1,7,-7,18:3)
Block(-1,7,-6,17:15)
Block(-1,7,-5,17:15)
Block(-1,7,-4,17:15)
Block(-1,7,-3,17:15)
Block(-1,7,-2,17:15)
Block(-1,7,-1,17:15)
Block(-1,7,0,17:15)
Block(-1,8,-6,17:15)
Block(-1,8,-5,17:15)
Block(-1,8,-4,17:15)
Block(-1,8,-3,17:15)
Block(-1,8,-2,17:15)
Block(-1,8,-1,17:15)
Block(-1,8,0,17:15)
Block(-1,9,-6,17:15)
Block(-1,9,-5,17:15)
Block(-1,9,-4,17:15)
Block(-1,9,-3,17:15)
Block(-1,9,-2,17:15)
Block(-1,9,-1,17:15)
Block(-1,9,0,17:15)
Block(-1,10,-7,17:15)
Block(-1,10,-6,17:15)
Block(-1,10,-5,17:15)
Block(-1,10,-4,17:15)
Block(-1,10,-3,17:15)
Block(-1,10,-2,17:15)
Block(-1,10,-1,17:15)
Block(-1,10,0,17:15)
Block(-1,10,1,17:15)
Block(-1,11,-6,17:15)
Block(-1,11,-5,17:15)
Block(-1,11,-4,17:15)
Block(-1,11,-3,17:15)
Block(-1,11,-2,17:15)
Block(-1,11,-1,17:15)
Block(-1,11,0,17:15)
Block(-1,11,1,17:15)
Block(-1,12,-7,17:15)
Block(-1,12,-6,17:15)
Block(-1,12,-5,17:15)
Block(-1,12,-4,17:15)
Block(-1,12,-3,17:15)
Block(-1,12,-2,17:15)
Block(-1,12,-1,17:15)
Block(-1,12,0,17:15)
Block(-1,12,1,17:15)
Block(-1,13,-7,17:15)
Block(-1,13,-6,17:15)
Block(-1,13,-5,17:15)
Block(-1,13,-4,17:15)
Block(-1,13,-3,17:15)
Block(-1,13,-2,17:15)
Block(-1,13,-1,17:15)
Block(-1,13,0,17:15)
Block(-1,13,1,17:15)
Block(-1,14,-7,17:15)
Block(-1,14,-6,17:15)
Block(-1,14,-5,17:15)
Block(-1,14,-4,17:15)
Block(-1,14,-3,17:15)
Block(-1,14,-2,17:15)
Block(-1,14,-1,17:15)
Block(-1,14,0,17:15)
Block(-1,14,1,17:15)
Block(-1,15,-7,17:15)
Block(-1,15,-6,17:15)
Block(-1,15,-5,17:15)
Block(-1,15,-4,17:15)
Block(-1,15,-3,17:15)
Block(-1,15,-2,17:15)
Block(-1,15,-1,17:15)
Block(-1,15,0,17:15)
Block(-1,15,1,17:15)
Block(-1,16,-7,17:15)
Block(-1,16,-6,17:15)
Block(-1,16,-5,17:15)
Block(-1,16,-4,17:15)
Block(-1,16,-3,17:15)
Block(-1,16,-2,17:15)
Block(-1,16,-1,17:15)
Block(-1,16,0,17:15)
Block(-1,16,1,17:15)
Block(-1,17,-7,17:15)
Block(-1,17,-6,17:15)
Block(-1,17,-5,17:15)
Block(-1,17,-4,17:15)
Block(-1,17,-3,17:15)
Block(-1,17,-2,17:15)
Block(-1,17,-1,17:15)
Block(-1,17,0,17:15)
Block(-1,17,1,17:15)
Block(-1,18,-7,17:15)
Block(-1,18,-6,17:15)
Block(-1,18,-5,17:15)
Block(-1,18,-4,17:15)
Block(-1,18,-3,17:15)
Block(-1,18,-2,17:15)
Block(-1,18,-1,17:15)
Block(-1,18,0,17:15)
Block(-1,18,1,17:15)
Block(-1,19,-7,17:15)
Block(-1,19,-6,17:15)
Block(-1,19,-5,17:15)
Block(-1,19,-4,17:15)
Block(-1,19,-3,17:15)
Block(-1,19,-2,17:15)
Block(-1,19,-1,17:15)
Block(-1,19,0,17:15)
Block(-1,19,1,17:15)
Block(-1,20,-7,17:15)
Block(-1,20,-6,17:15)
Block(-1,20,-5,17:15)
Block(-1,20,-4,17:15)
Block(-1,20,-3,17:15)
Block(-1,20,-2,17:15)
Block(-1,20,-1,17:15)
Block(-1,20,0,17:15)
Block(-1,20,1,17:15)
Block(-1,21,-7,17:15)
Block(-1,21,-6,17:15)
Block(-1,21,-5,17:15)
Block(-1,21,-4,17:15)
Block(-1,21,-3,17:15)
Block(-1,21,-2,17:15)
Block(-1,21,-1,17:15)
Block(-1,21,0,17:15)
Block(-1,21,1,17:15)
Block(-1,21,2,17:15)
Block(-1,22,-6,17:15)
Block(-1,22,-5,17:15)
Block(-1,22,-4,17:15)
Block(-1,22,-3,17:15)
Block(-1,22,-2,17:15)
Block(-1,22,-1,17:15)
Block(-1,22,0,17:15)
Block(-1,22,1,17:15)
Block(-1,22,2,17:15)
Block(-1,23,-6,17:15)
Block(-1,23,-5,17:15)
Block(-1,23,-4,17:15)
Block(-1,23,-3,17:15)
Block(-1,23,-2,17:15)
Block(-1,23,-1,17:15)
Block(-1,23,0,17:15)
Block(-1,23,1,17:15)
Block(-1,23,2,17:15)
Block(-1,24,-6,17:15)
Block(-1,24,-5,17:15)
Block(-1,24,-4,17:15)
Block(-1,24,-3,17:15)
Block(-1,24,-2,17:15)
Block(-1,24,-1,17:15)
Block(-1,24,0,17:15)
Block(-1,24,1,17:15)
Block(-1,24,2,17:15)
Block(-1,24,3,17:15)
Block(-1,25,-6,17:15)
Block(-1,25,-5,17:15)
Block(-1,25,-4,17:15)
Block(-1,25,-3,17:15)
Block(-1,25,-2,17:15)
Block(-1,25,-1,17:15)
Block(-1,25,0,17:15)
Block(-1,25,1,17:15)
Block(-1,25,2,17:15)
Block(-1,25,3,17:15)
Block(-1,26,-6,17:15)
Block(-1,26,-5,17:15)
Block(-1,26,-4,17:15)
Block(-1,26,-3,17:15)
Block(-1,26,-2,17:15)
Block(-1,26,-1,17:15)
Block(-1,26,0,17:15)
Block(-1,26,1,17:15)
Block(-1,26,2,17:15)
Block(-1,26,3,17:15)
Block(-1,27,-6,17:15)
Block(-1,27,-5,17:15)
Block(-1,27,-4,17:15)
Block(-1,27,-3,17:15)
Block(-1,27,-2,17:15)
Block(-1,27,-1,17:15)
Block(-1,27,0,17:15)
Block(-1,27,1,17:15)
Block(-1,27,2,17:15)
Block(-1,27,3,17:15)
Block(-1,27,4,17:15)
Block(-1,28,-5,17:15)
Block(-1,28,-4,17:15)
Block(-1,28,-3,17:15)
Block(-1,28,-2,17:15)
Block(-1,28,-1,17:15)
Block(-1,28,0,17:15)
Block(-1,28,1,17:15)
Block(-1,28,2,17:15)
Block(-1,28,3,17:15)
Block(-1,28,4,17:15)
Block(-1,29,-5,17:15)
Block(-1,29,-4,17:15)
Block(-1,29,-3,17:15)
Block(-1,29,-2,17:15)
Block(-1,29,-1,17:15)
Block(-1,29,0,17:15)
Block(-1,29,1,17:15)
Block(-1,29,2,17:15)
Block(-1,29,3,17:15)
Block(-1,29,4,17:15)
Block(-1,30,-5,17:15)
Block(-1,30,-4,17:15)
Block(-1,30,-3,17:15)
Block(-1,30,-2,17:15)
Block(-1,30,-1,17:15)
Block(-1,30,0,17:15)
Block(-1,30,1,17:15)
Block(-1,30,2,17:15)
Block(-1,30,3,17:15)
Block(-1,30,4,17:15)
Block(-1,31,-4,17:15)
Block(-1,31,-3,17:15)
Block(-1,31,-2,17:15)
Block(-1,31,-1,17:15)
Block(-1,31,0,17:15)
Block(-1,31,1,17:15)
Block(-1,31,2,17:15)
Block(-1,31,3,17:15)
Block(-1,31,4,17:15)
Block(-1,32,-4,17:15)
Block(-1,32,-3,17:15)
Block(-1,32,-2,17:15)
Block(-1,32,-1,17:15)
Block(-1,32,0,17:15)
Block(-1,32,1,17:15)
Block(-1,32,2,17:15)
Block(-1,32,3,17:15)
Block(-1,32,4,17:15)
Block(-1,33,-4,17:15)
Block(-1,33,-3,17:15)
Block(-1,33,-2,17:15)
Block(-1,33,-1,17:15)
Block(-1,33,0,17:15)
Block(-1,33,1,17:15)
Block(-1,33,2,17:15)
Block(-1,33,3,17:15)
Block(-1,33,4,17:15)
Block(-1,34,-4,17:15)
Block(-1,34,-3,17:15)
Block(-1,34,-2,17:15)
Block(-1,34,-1,17:15)
Block(-1,34,0,17:15)
Block(-1,34,1,17:15)
Block(-1,34,2,17:15)
Block(-1,34,3,17:15)
Block(-1,34,4,17:15)
Block(-1,35,-4,17:15)
Block(-1,35,-3,17:15)
Block(-1,35,-2,17:15)
Block(-1,35,-1,17:15)
Block(-1,35,0,17:15)
Block(-1,35,1,17:15)
Block(-1,35,2,17:15)
Block(-1,35,3,17:15)
Block(-1,35,4,17:15)
Block(-1,36,-4,17:15)
Block(-1,36,-3,17:15)
Block(-1,36,-2,17:15)
Block(-1,36,-1,17:15)
Block(-1,36,0,17:15)
Block(-1,36,1,17:15)
Block(-1,36,2,17:15)
Block(-1,36,3,17:15)
Block(-1,36,4,17:15)
Block(-1,36,5,17:15)
Block(-1,37,-4,17:15)
Block(-1,37,-3,17:15)
Block(-1,37,-2,17:15)
Block(-1,37,-1,17:15)
Block(-1,37,0,17:15)
Block(-1,37,1,17:15)
Block(-1,37,2,17:15)
Block(-1,37,3,17:15)
Block(-1,37,4,17:15)
Block(-1,37,5,17:15)
Block(-1,37,6,127:10)
Block(-1,38,-5,17:15)
Block(-1,38,-4,17:15)
Block(-1,38,-3,17:15)
Block(-1,38,-2,18:3)
Block(-1,38,-1,18:3)
Block(-1,38,0,18:3)
Block(-1,38,1,18:3)
Block(-1,38,2,18:3)
Block(-1,38,3,17:15)
Block(-1,38,4,17:15)
Block(-1,38,5,17:15)
Block(-1,39,-4,18:3)
Block(-1,39,-3,18:3)
Block(-1,39,-2,18:3)
Block(-1,39,-1,18:3)
Block(-1,39,0,18:3)
Block(-1,39,1,18:3)
Block(-1,39,2,18:3)
Block(-1,39,3,18:3)
Block(-1,39,4,18:3)
Block(-1,39,5,18:3)
Block(-1,39,6,18:3)
Block(-1,40,-6,18:3)
Block(-1,40,-5,18:3)
Block(-1,40,-4,18:3)
Block(-1,40,-3,18:3)
Block(-1,40,-2,18:3)
Block(-1,40,-1,18:3)
Block(-1,40,0,18:3)
Block(-1,40,1,18:3)
Block(-1,40,2,18:3)
Block(-1,40,3,18:3)
Block(-1,40,4,18:3)
Block(-1,40,5,18:3)
Block(-1,40,6,18:3)
Block(-1,40,7,18:3)
Block(-1,41,-22,18:3)
Block(-1,41,-21,18:3)
Block(-1,41,-20,18:3)
Block(-1,41,-8,18:3)
Block(-1,41,-7,18:3)
Block(-1,41,-6,18:3)
Block(-1,41,-5,18:3)
Block(-1,41,-4,18:3)
Block(-1,41,-3,18:3)
Block(-1,41,-2,18:3)
Block(-1,41,-1,18:3)
Block(-1,41,0,18:3)
Block(-1,41,1,18:3)
Block(-1,41,2,18:3)
Block(-1,41,3,18:3)
Block(-1,41,4,18:3)
Block(-1,41,5,18:3)
Block(-1,41,6,18:3)
Block(-1,41,7,18:3)
Block(-1,41,8,18:3)
Block(-1,41,9,18:3)
Block(-1,41,10,18:3)
Block(-1,42,-21,18:3)
Block(-1,42,-20,18:3)
Block(-1,42,-19,18:3)
Block(-1,42,-18,18:3)
Block(-1,42,-10,18:3)
Block(-1,42,-9,18:3)
Block(-1,42,-8,18:3)
Block(-1,42,-7,18:3)
Block(-1,42,-6,18:3)
Block(-1,42,-5,18:3)
Block(-1,42,-4,18:3)
Block(-1,42,-3,18:3)
Block(-1,42,-2,18:3)
Block(-1,42,-1,18:3)
Block(-1,42,0,18:3)
Block(-1,42,1,18:3)
Block(-1,42,2,18:3)
Block(-1,42,3,18:3)
Block(-1,42,4,18:3)
Block(-1,42,5,18:3)
Block(-1,42,6,18:3)
Block(-1,42,7,18:3)
Block(-1,42,8,18:3)
Block(-1,42,9,18:3)
Block(-1,42,10,18:3)
Block(-1,42,11,18:3)
Block(-1,43,-20,18:3)
Block(-1,43,-19,18:3)
Block(-1,43,-18,18:3)
Block(-1,43,-17,18:3)
Block(-1,43,-16,18:3)
Block(-1,43,-12,18:3)
Block(-1,43,-11,18:3)
Block(-1,43,-10,18:3)
Block(-1,43,-9,18:3)
Block(-1,43,-8,18:3)
Block(-1,43,-7,18:3)
Block(-1,43,-6,18:3)
Block(-1,43,-5,18:3)
Block(-1,43,-4,18:3)
Block(-1,43,-3,18:3)
Block(-1,43,-2,18:3)
Block(-1,43,-1,18:3)
Block(-1,43,0,18:3)
Block(-1,43,1,18:3)
Block(-1,43,2,18:3)
Block(-1,43,3,18:3)
Block(-1,43,4,18:3)
Block(-1,43,5,18:3)
Block(-1,43,6,18:3)
Block(-1,43,7,18:3)
Block(-1,43,8,18:3)
Block(-1,43,9,18:3)
Block(-1,43,10,18:3)
Block(-1,44,-18,18:3)
Block(-1,44,-17,18:3)
Block(-1,44,-16,18:3)
Block(-1,44,-15,18:3)
Block(-1,44,-14,18:3)
Block(-1,44,-13,18:3)
Block(-1,44,-12,18:3)
Block(-1,44,-11,18:3)
Block(-1,44,-10,18:3)
Block(-1,44,-9,18:3)
Block(-1,44,-8,18:3)
Block(-1,44,-7,18:3)
Block(-1,44,-6,18:3)
Block(-1,44,-5,18:3)
Block(-1,44,-4,18:3)
Block(-1,44,-3,18:3)
Block(-1,44,-2,18:3)
Block(-1,44,-1,18:3)
Block(-1,44,0,18:3)
Block(-1,44,1,18:3)
Block(-1,44,2,18:3)
Block(-1,44,3,18:3)
Block(-1,44,4,18:3)
Block(-1,44,5,18:3)
Block(-1,44,6,18:3)
Block(-1,44,7,18:3)
Block(-1,44,8,18:3)
Block(-1,44,9,18:3)
Block(-1,44,10,18:3)
Block(-1,44,13,18:3)
Block(-1,45,-15,18:3)
Block(-1,45,-14,18:3)
Block(-1,45,-13,18:3)
Block(-1,45,-12,18:3)
Block(-1,45,-11,18:3)
Block(-1,45,-10,18:3)
Block(-1,45,-9,18:3)
Block(-1,45,-8,18:3)
Block(-1,45,-7,18:3)
Block(-1,45,-6,18:3)
Block(-1,45,-5,18:3)
Block(-1,45,-4,18:3)
Block(-1,45,-3,18:3)
Block(-1,45,-2,18:3)
Block(-1,45,-1,18:3)
Block(-1,45,0,18:3)
Block(-1,45,1,18:3)
Block(-1,45,2,18:3)
Block(-1,45,3,18:3)
Block(-1,45,4,18:3)
Block(-1,45,5,18:3)
Block(-1,45,6,18:3)
Block(-1,45,7,18:3)
Block(-1,45,8,18:3)
Block(-1,46,-14,18:3)
Block(-1,46,-13,18:3)
Block(-1,46,-12,18:3)
Block(-1,46,-11,18:3)
Block(-1,46,-10,18:3)
Block(-1,46,-9,18:3)
Block(-1,46,-8,18:3)
Block(-1,46,-7,18:3)
Block(-1,46,-6,18:3)
Block(-1,46,-5,18:3)
Block(-1,46,-4,18:3)
Block(-1,46,-3,18:3)
Block(-1,46,-2,18:3)
Block(-1,46,-1,18:3)
Block(-1,46,0,18:3)
Block(-1,46,1,18:3)
Block(-1,46,2,18:3)
Block(-1,46,3,18:3)
Block(-1,46,4,18:3)
Block(-1,46,5,18:3)
Block(-1,46,6,18:3)
Block(-1,47,-9,18:3)
Block(-1,47,-8,18:3)
Block(-1,47,-7,18:3)
Block(-1,47,-6,18:3)
Block(-1,47,-5,18:3)
Block(-1,47,-4,18:3)
Block(-1,47,-3,18:3)
Block(-1,47,-2,18:3)
Block(-1,47,-1,18:3)
Block(-1,47,0,18:3)
Block(-1,47,1,18:3)
Block(-1,47,2,18:3)
Block(-1,47,3,18:3)
Block(-1,47,4,18:3)
Block(-1,47,5,18:3)
Block(-1,48,-8,18:3)
Block(-1,48,-7,18:3)
Block(-1,48,-6,18:3)
Block(-1,48,-5,18:3)
Block(-1,48,-4,18:3)
Block(-1,48,-3,18:3)
Block(-1,48,-2,18:3)
Block(-1,48,-1,18:3)
Block(-1,48,0,18:3)
Block(-1,48,1,18:3)
Block(-1,48,2,18:3)
Block(-1,48,3,18:3)
Block(-1,49,-6,18:3)
Block(-1,49,-5,18:3)
Block(-1,49,-4,18:3)
Block(-1,49,-3,18:3)
Block(-1,49,-2,18:3)
Block(-1,49,-1,18:3)
Block(-1,49,0,18:3)
Block(-1,49,1,18:3)
Block(-1,49,2,18:3)
Block(-1,50,-3,18:3)
Block(-1,50,-2,18:3)
Block(-1,50,-1,18:3)
Block(0,0,-10,17:15)
Block(0,0,-9,17:15)
Block(0,0,-8,17:15)
Block(0,0,-7,17:15)
Block(0,0,-6,17:15)
Block(0,0,-5,17:15)
Block(0,0,-4,17:15)
Block(0,0,-3,17:15)
Block(0,0,-2,17:15)
Block(0,0,-1,17:15)
Block(0,0,0,17:15)
Block(0,1,-9,17:15)
Block(0,1,-8,17:15)
Block(0,1,-7,17:15)
Block(0,1,-6,17:15)
Block(0,1,-5,17:15)
Block(0,1,-4,17:15)
Block(0,1,-3,17:15)
Block(0,1,-2,17:15)
Block(0,1,-1,17:15)
Block(0,1,0,17:15)
Block(0,2,-9,17:15)
Block(0,2,-8,17:15)
Block(0,2,-7,17:15)
Block(0,2,-6,17:15)
Block(0,2,-5,17:15)
Block(0,2,-4,17:15)
Block(0,2,-3,17:15)
Block(0,2,-2,17:15)
Block(0,2,-1,17:15)
Block(0,2,0,17:15)
Block(0,3,-9,18:3)
Block(0,3,-8,17:15)
Block(0,3,-7,17:15)
Block(0,3,-6,17:15)
Block(0,3,-5,17:15)
Block(0,3,-4,17:15)
Block(0,3,-3,17:15)
Block(0,3,-2,17:15)
Block(0,3,-1,17:15)
Block(0,3,0,17:15)
Block(0,4,-9,18:3)
Block(0,4,-8,17:15)
Block(0,4,-7,17:15)
Block(0,4,-6,17:15)
Block(0,4,-5,17:15)
Block(0,4,-4,17:15)
Block(0,4,-3,17:15)
Block(0,4,-2,17:15)
Block(0,4,-1,17:15)
Block(0,4,0,17:15)
Block(0,5,-8,18:3)
Block(0,5,-7,17:15)
Block(0,5,-6,17:15)
Block(0,5,-5,17:15)
Block(0,5,-4,17:15)
Block(0,5,-3,17:15)
Block(0,5,-2,17:15)
Block(0,5,-1,17:15)
Block(0,5,0,17:15)
Block(0,6,-7,17:15)
Block(0,6,-6,17:15)
Block(0,6,-5,17:15)
Block(0,6,-4,17:15)
Block(0,6,-3,17:15)
Block(0,6,-2,17:15)
Block(0,6,-1,17:15)
Block(0,6,0,17:15)
Block(0,6,1,17:15)
Block(0,7,-7,17:15)
Block(0,7,-6,17:15)
Block(0,7,-5,17:15)
Block(0,7,-4,17:15)
Block(0,7,-3,17:15)
Block(0,7,-2,17:15)
Block(0,7,-1,17:15)
Block(0,7,0,17:15)
Block(0,7,1,17:15)
Block(0,8,-7,17:15)
Block(0,8,-6,17:15)
Block(0,8,-5,17:15)
Block(0,8,-4,17:15)
Block(0,8,-3,17:15)
Block(0,8,-2,17:15)
Block(0,8,-1,17:15)
Block(0,8,0,17:15)
Block(0,8,1,17:15)
Block(0,9,-7,17:15)
Block(0,9,-6,17:15)
Block(0,9,-5,17:15)
Block(0,9,-4,17:15)
Block(0,9,-3,17:15)
Block(0,9,-2,17:15)
Block(0,9,-1,17:15)
Block(0,9,0,17:15)
Block(0,9,1,17:15)
Block(0,10,-7,17:15)
Block(0,10,-6,17:15)
Block(0,10,-5,17:15)
Block(0,10,-4,17:15)
Block(0,10,-3,17:15)
Block(0,10,-2,17:15)
Block(0,10,-1,17:15)
Block(0,10,0,17:15)
Block(0,10,1,17:15)
Block(0,11,-7,17:15)
Block(0,11,-6,17:15)
Block(0,11,-5,17:15)
Block(0,11,-4,17:15)
Block(0,11,-3,17:15)
Block(0,11,-2,17:15)
Block(0,11,-1,17:15)
Block(0,11,0,17:15)
Block(0,11,1,17:15)
Block(0,12,-7,17:15)
Block(0,12,-6,17:15)
Block(0,12,-5,17:15)
Block(0,12,-4,17:15)
Block(0,12,-3,17:15)
Block(0,12,-2,17:15)
Block(0,12,-1,17:15)
Block(0,12,0,17:15)
Block(0,12,1,17:15)
Block(0,13,-7,17:15)
Block(0,13,-6,17:15)
Block(0,13,-5,17:15)
Block(0,13,-4,17:15)
Block(0,13,-3,17:15)
Block(0,13,-2,17:15)
Block(0,13,-1,17:15)
Block(0,13,0,17:15)
Block(0,13,1,17:15)
Block(0,14,-7,17:15)
Block(0,14,-6,17:15)
Block(0,14,-5,17:15)
Block(0,14,-4,17:15)
Block(0,14,-3,17:15)
Block(0,14,-2,17:15)
Block(0,14,-1,17:15)
Block(0,14,0,17:15)
Block(0,14,1,17:15)
Block(0,15,-7,17:15)
Block(0,15,-6,17:15)
Block(0,15,-5,17:15)
Block(0,15,-4,17:15)
Block(0,15,-3,17:15)
Block(0,15,-2,17:15)
Block(0,15,-1,17:15)
Block(0,15,0,17:15)
Block(0,15,1,17:15)
Block(0,16,-8,17:15)
Block(0,16,-7,17:15)
Block(0,16,-6,17:15)
Block(0,16,-5,17:15)
Block(0,16,-4,17:15)
Block(0,16,-3,17:15)
Block(0,16,-2,17:15)
Block(0,16,-1,17:15)
Block(0,16,0,17:15)
Block(0,16,1,17:15)
Block(0,17,-8,17:15)
Block(0,17,-7,17:15)
Block(0,17,-6,17:15)
Block(0,17,-5,17:15)
Block(0,17,-4,17:15)
Block(0,17,-3,17:15)
Block(0,17,-2,17:15)
Block(0,17,-1,17:15)
Block(0,17,0,17:15)
Block(0,17,1,17:15)
Block(0,18,-8,17:15)
Block(0,18,-7,17:15)
Block(0,18,-6,17:15)
Block(0,18,-5,17:15)
Block(0,18,-4,17:15)
Block(0,18,-3,17:15)
Block(0,18,-2,17:15)
Block(0,18,-1,17:15)
Block(0,18,0,17:15)
Block(0,18,1,17:15)
Block(0,19,-7,17:15)
Block(0,19,-6,17:15)
Block(0,19,-5,17:15)
Block(0,19,-4,17:15)
Block(0,19,-3,17:15)
Block(0,19,-2,17:15)
Block(0,19,-1,17:15)
Block(0,19,0,17:15)
Block(0,19,1,17:15)
Block(0,20,-7,17:15)
Block(0,20,-6,17:15)
Block(0,20,-5,17:15)
Block(0,20,-4,17:15)
Block(0,20,-3,17:15)
Block(0,20,-2,17:15)
Block(0,20,-1,17:15)
Block(0,20,0,17:15)
Block(0,20,1,17:15)
Block(0,20,2,17:15)
Block(0,21,-7,17:15)
Block(0,21,-6,17:15)
Block(0,21,-5,17:15)
Block(0,21,-4,17:15)
Block(0,21,-3,17:15)
Block(0,21,-2,17:15)
Block(0,21,-1,17:15)
Block(0,21,0,17:15)
Block(0,21,1,17:15)
Block(0,21,2,17:15)
Block(0,22,-7,17:15)
Block(0,22,-6,17:15)
Block(0,22,-5,17:15)
Block(0,22,-4,17:15)
Block(0,22,-3,17:15)
Block(0,22,-2,17:15)
Block(0,22,-1,17:15)
Block(0,22,0,17:15)
Block(0,22,1,17:15)
Block(0,22,2,17:15)
Block(0,23,-7,17:15)
Block(0,23,-6,17:15)
Block(0,23,-5,17:15)
Block(0,23,-4,17:15)
Block(0,23,-3,17:15)
Block(0,23,-2,17:15)
Block(0,23,-1,17:15)
Block(0,23,0,17:15)
Block(0,23,1,17:15)
Block(0,23,2,17:15)
Block(0,23,3,17:15)
Block(0,24,-6,17:15)
Block(0,24,-5,17:15)
Block(0,24,-4,17:15)
Block(0,24,-3,17:15)
Block(0,24,-2,17:15)
Block(0,24,-1,17:15)
Block(0,24,0,17:15)
Block(0,24,1,17:15)
Block(0,24,2,17:15)
Block(0,25,-6,17:15)
Block(0,25,-5,17:15)
Block(0,25,-4,17:15)
Block(0,25,-3,17:15)
Block(0,25,-2,17:15)
Block(0,25,-1,17:15)
Block(0,25,0,17:15)
Block(0,25,1,17:15)
Block(0,25,2,17:15)
Block(0,25,3,17:15)
Block(0,26,-6,17:15)
Block(0,26,-5,17:15)
Block(0,26,-4,17:15)
Block(0,26,-3,17:15)
Block(0,26,-2,17:15)
Block(0,26,-1,17:15)
Block(0,26,0,17:15)
Block(0,26,1,17:15)
Block(0,26,2,17:15)
Block(0,26,3,17:15)
Block(0,27,-5,17:15)
Block(0,27,-4,17:15)
Block(0,27,-3,17:15)
Block(0,27,-2,17:15)
Block(0,27,-1,17:15)
Block(0,27,0,17:15)
Block(0,27,1,17:15)
Block(0,27,2,17:15)
Block(0,27,3,17:15)
Block(0,28,-5,17:15)
Block(0,28,-4,17:15)
Block(0,28,-3,17:15)
Block(0,28,-2,17:15)
Block(0,28,-1,17:15)
Block(0,28,0,17:15)
Block(0,28,1,17:15)
Block(0,28,2,17:15)
Block(0,28,3,17:15)
Block(0,29,-5,17:15)
Block(0,29,-4,17:15)
Block(0,29,-3,17:15)
Block(0,29,-2,17:15)
Block(0,29,-1,17:15)
Block(0,29,0,17:15)
Block(0,29,1,17:15)
Block(0,29,2,17:15)
Block(0,29,3,17:15)
Block(0,29,4,17:15)
Block(0,30,-4,17:15)
Block(0,30,-3,17:15)
Block(0,30,-2,17:15)
Block(0,30,-1,17:15)
Block(0,30,0,17:15)
Block(0,30,1,17:15)
Block(0,30,2,17:15)
Block(0,30,3,17:15)
Block(0,30,4,17:15)
Block(0,31,-4,17:15)
Block(0,31,-3,17:15)
Block(0,31,-2,17:15)
Block(0,31,-1,17:15)
Block(0,31,0,17:15)
Block(0,31,1,17:15)
Block(0,31,2,17:15)
Block(0,31,3,17:15)
Block(0,31,4,17:15)
Block(0,32,-4,17:15)
Block(0,32,-3,17:15)
Block(0,32,-2,17:15)
Block(0,32,-1,17:15)
Block(0,32,0,17:15)
Block(0,32,1,17:15)
Block(0,32,2,17:15)
Block(0,32,3,17:15)
Block(0,32,4,17:15)
Block(0,33,-4,17:15)
Block(0,33,-3,17:15)
Block(0,33,-2,17:15)
Block(0,33,-1,17:15)
Block(0,33,0,17:15)
Block(0,33,1,17:15)
Block(0,33,2,17:15)
Block(0,33,3,17:15)
Block(0,33,4,17:15)
Block(0,34,-4,17:15)
Block(0,34,-3,17:15)
Block(0,34,-2,17:15)
Block(0,34,-1,17:15)
Block(0,34,0,17:15)
Block(0,34,1,17:15)
Block(0,34,2,17:15)
Block(0,34,3,17:15)
Block(0,34,4,17:15)
Block(0,35,-4,17:15)
Block(0,35,-3,17:15)
Block(0,35,-2,17:15)
Block(0,35,-1,17:15)
Block(0,35,0,17:15)
Block(0,35,1,17:15)
Block(0,35,2,17:15)
Block(0,35,3,17:15)
Block(0,35,4,17:15)
Block(0,36,-5,127:8)
Block(0,36,-4,17:15)
Block(0,36,-3,17:15)
Block(0,36,-2,17:15)
Block(0,36,-1,17:15)
Block(0,36,0,17:15)
Block(0,36,1,17:15)
Block(0,36,2,17:15)
Block(0,36,3,17:15)
Block(0,36,4,17:15)
Block(0,37,-4,17:15)
Block(0,37,-3,17:15)
Block(0,37,-2,17:15)
Block(0,37,-1,17:15)
Block(0,37,0,17:15)
Block(0,37,1,17:15)
Block(0,37,2,17:15)
Block(0,37,3,17:15)
Block(0,37,4,17:15)
Block(0,38,-4,17:15)
Block(0,38,-3,17:15)
Block(0,38,-2,17:15)
Block(0,38,-1,18:3)
Block(0,38,0,18:3)
Block(0,38,1,18:3)
Block(0,38,2,17:15)
Block(0,38,3,17:15)
Block(0,38,4,17:15)
Block(0,39,-4,17:15)
Block(0,39,-3,17:15)
Block(0,39,-2,18:3)
Block(0,39,-1,18:3)
Block(0,39,0,18:3)
Block(0,39,1,18:3)
Block(0,39,2,18:3)
Block(0,39,3,17:15)
Block(0,39,4,17:15)
Block(0,39,5,17:15)
Block(0,40,-4,18:3)
Block(0,40,-3,18:3)
Block(0,40,-2,18:3)
Block(0,40,-1,18:3)
Block(0,40,0,18:3)
Block(0,40,1,18:3)
Block(0,40,2,18:3)
Block(0,40,3,18:3)
Block(0,40,4,18:3)
Block(0,40,5,17:15)
Block(0,41,-4,18:3)
Block(0,41,-3,18:3)
Block(0,41,-2,18:3)
Block(0,41,-1,18:3)
Block(0,41,0,18:3)
Block(0,41,1,18:3)
Block(0,41,2,18:3)
Block(0,41,3,18:3)
Block(0,41,4,18:3)
Block(0,41,5,18:3)
Block(0,41,6,18:3)
Block(0,41,7,18:3)
Block(0,41,8,18:3)
Block(0,42,-6,18:3)
Block(0,42,-5,18:3)
Block(0,42,-4,18:3)
Block(0,42,-3,18:3)
Block(0,42,-2,18:3)
Block(0,42,-1,18:3)
Block(0,42,0,18:3)
Block(0,42,1,18:3)
Block(0,42,2,18:3)
Block(0,42,3,18:3)
Block(0,42,4,18:3)
Block(0,42,5,18:3)
Block(0,42,6,18:3)
Block(0,42,7,18:3)
Block(0,42,8,18:3)
Block(0,42,9,18:3)
Block(0,43,-7,18:3)
Block(0,43,-6,18:3)
Block(0,43,-5,18:3)
Block(0,43,-4,18:3)
Block(0,43,-3,18:3)
Block(0,43,-2,18:3)
Block(0,43,-1,18:3)
Block(0,43,0,18:3)
Block(0,43,1,18:3)
Block(0,43,2,18:3)
Block(0,43,3,18:3)
Block(0,43,4,18:3)
Block(0,43,5,18:3)
Block(0,43,6,18:3)
Block(0,43,7,18:3)
Block(0,43,8,18:3)
Block(0,44,-12,18:3)
Block(0,44,-9,18:3)
Block(0,44,-7,18:3)
Block(0,44,-6,18:3)
Block(0,44,-5,18:3)
Block(0,44,-4,18:3)
Block(0,44,-3,18:3)
Block(0,44,-2,18:3)
Block(0,44,-1,18:3)
Block(0,44,0,18:3)
Block(0,44,1,18:3)
Block(0,44,2,18:3)
Block(0,44,3,18:3)
Block(0,44,4,18:3)
Block(0,44,5,18:3)
Block(0,44,6,18:3)
Block(0,44,7,18:3)
Block(0,44,8,18:3)
Block(0,45,-13,18:3)
Block(0,45,-12,18:3)
Block(0,45,-11,18:3)
Block(0,45,-10,18:3)
Block(0,45,-9,18:3)
Block(0,45,-7,18:3)
Block(0,45,-6,18:3)
Block(0,45,-5,18:3)
Block(0,45,-4,18:3)
Block(0,45,-3,18:3)
Block(0,45,-2,18:3)
Block(0,45,-1,18:3)
Block(0,45,0,18:3)
Block(0,45,1,18:3)
Block(0,45,2,18:3)
Block(0,45,3,18:3)
Block(0,45,4,18:3)
Block(0,45,5,18:3)
Block(0,45,6,18:3)
Block(0,45,7,18:3)
Block(0,46,-13,18:3)
Block(0,46,-12,18:3)
Block(0,46,-11,18:3)
Block(0,46,-10,18:3)
Block(0,46,-9,18:3)
Block(0,46,-8,18:3)
Block(0,46,-7,18:3)
Block(0,46,-6,18:3)
Block(0,46,-5,18:3)
Block(0,46,-4,18:3)
Block(0,46,-3,18:3)
Block(0,46,-2,18:3)
Block(0,46,-1,18:3)
Block(0,46,0,18:3)
Block(0,46,1,18:3)
Block(0,46,2,18:3)
Block(0,46,3,18:3)
Block(0,46,4,18:3)
Block(0,46,5,18:3)
Block(0,47,-8,18:3)
Block(0,47,-7,18:3)
Block(0,47,-6,18:3)
Block(0,47,-5,18:3)
Block(0,47,-4,18:3)
Block(0,47,-3,18:3)
Block(0,47,-2,18:3)
Block(0,47,-1,18:3)
Block(0,47,0,18:3)
Block(0,47,1,18:3)
Block(0,47,2,18:3)
Block(0,47,3,18:3)
Block(0,47,4,18:3)
Block(0,48,-7,18:3)
Block(0,48,-6,18:3)
Block(0,48,-5,18:3)
Block(0,48,-4,18:3)
Block(0,48,-3,18:3)
Block(0,48,-2,18:3)
Block(0,48,-1,18:3)
Block(0,48,0,18:3)
Block(0,48,1,18:3)
Block(0,48,2,18:3)
Block(0,48,3,18:3)
Block(0,49,-6,18:3)
Block(0,49,-5,18:3)
Block(0,49,-4,18:3)
Block(0,49,-3,18:3)
Block(0,49,-2,18:3)
Block(0,49,-1,18:3)
Block(0,49,0,18:3)
Block(0,49,1,18:3)
Block(0,50,-4,18:3)
Block(0,50,-3,18:3)
Block(0,50,-2,18:3)
Block(1,0,-11,17:15)
Block(1,0,-10,17:15)
Block(1,0,-9,17:15)
Block(1,0,-8,17:15)
Block(1,0,-7,17:15)
Block(1,0,-6,17:15)
Block(1,0,-5,17:15)
Block(1,0,-4,17:15)
Block(1,0,-3,17:15)
Block(1,0,-2,17:15)
Block(1,0,-1,17:15)
Block(1,0,0,17:15)
Block(1,0,1,17:15)
Block(1,1,-10,17:15)
Block(1,1,-9,17:15)
Block(1,1,-8,17:15)
Block(1,1,-7,17:15)
Block(1,1,-6,17:15)
Block(1,1,-5,17:15)
Block(1,1,-4,17:15)
Block(1,1,-3,17:15)
Block(1,1,-2,17:15)
Block(1,1,-1,17:15)
Block(1,1,0,17:15)
Block(1,2,-9,17:15)
Block(1,2,-8,17:15)
Block(1,2,-7,17:15)
Block(1,2,-6,17:15)
Block(1,2,-5,17:15)
Block(1,2,-4,17:15)
Block(1,2,-3,17:15)
Block(1,2,-2,17:15)
Block(1,2,-1,17:15)
Block(1,2,0,17:15)
Block(1,3,-9,17:15)
Block(1,3,-8,17:15)
Block(1,3,-7,17:15)
Block(1,3,-6,17:15)
Block(1,3,-5,17:15)
Block(1,3,-4,17:15)
Block(1,3,-3,17:15)
Block(1,3,-2,17:15)
Block(1,3,-1,17:15)
Block(1,3,0,17:15)
Block(1,4,-9,17:15)
Block(1,4,-8,17:15)
Block(1,4,-7,17:15)
Block(1,4,-6,17:15)
Block(1,4,-5,17:15)
Block(1,4,-4,17:15)
Block(1,4,-3,17:15)
Block(1,4,-2,17:15)
Block(1,4,-1,17:15)
Block(1,4,0,17:15)
Block(1,4,1,17:15)
Block(1,5,-8,17:15)
Block(1,5,-7,17:15)
Block(1,5,-6,17:15)
Block(1,5,-5,17:15)
Block(1,5,-4,17:15)
Block(1,5,-3,17:15)
Block(1,5,-2,17:15)
Block(1,5,-1,17:15)
Block(1,5,0,17:15)
Block(1,5,1,17:15)
Block(1,6,-8,18:3)
Block(1,6,-7,17:15)
Block(1,6,-6,17:15)
Block(1,6,-5,17:15)
Block(1,6,-4,17:15)
Block(1,6,-3,17:15)
Block(1,6,-2,17:15)
Block(1,6,-1,17:15)
Block(1,6,0,17:15)
Block(1,6,1,17:15)
Block(1,7,-7,17:15)
Block(1,7,-6,17:15)
Block(1,7,-5,17:15)
Block(1,7,-4,17:15)
Block(1,7,-3,17:15)
Block(1,7,-2,17:15)
Block(1,7,-1,17:15)
Block(1,7,0,17:15)
Block(1,7,1,17:15)
Block(1,8,-7,17:15)
Block(1,8,-6,17:15)
Block(1,8,-5,17:15)
Block(1,8,-4,17:15)
Block(1,8,-3,17:15)
Block(1,8,-2,17:15)
Block(1,8,-1,17:15)
Block(1,8,0,17:15)
Block(1,8,1,17:15)
Block(1,9,-7,17:15)
Block(1,9,-6,17:15)
Block(1,9,-5,17:15)
Block(1,9,-4,17:15)
Block(1,9,-3,17:15)
Block(1,9,-2,17:15)
Block(1,9,-1,17:15)
Block(1,9,0,17:15)
Block(1,9,1,17:15)
Block(1,10,-7,17:15)
Block(1,10,-6,17:15)
Block(1,10,-5,17:15)
Block(1,10,-4,17:15)
Block(1,10,-3,17:15)
Block(1,10,-2,17:15)
Block(1,10,-1,17:15)
Block(1,10,0,17:15)
Block(1,10,1,17:15)
Block(1,11,-7,17:15)
Block(1,11,-6,17:15)
Block(1,11,-5,17:15)
Block(1,11,-4,17:15)
Block(1,11,-3,17:15)
Block(1,11,-2,17:15)
Block(1,11,-1,17:15)
Block(1,11,0,17:15)
Block(1,11,1,17:15)
Block(1,12,-7,17:15)
Block(1,12,-6,17:15)
Block(1,12,-5,17:15)
Block(1,12,-4,17:15)
Block(1,12,-3,17:15)
Block(1,12,-2,17:15)
Block(1,12,-1,17:15)
Block(1,12,0,17:15)
Block(1,12,1,17:15)
Block(1,13,-7,17:15)
Block(1,13,-6,17:15)
Block(1,13,-5,17:15)
Block(1,13,-4,17:15)
Block(1,13,-3,17:15)
Block(1,13,-2,17:15)
Block(1,13,-1,17:15)
Block(1,13,0,17:15)
Block(1,13,1,17:15)
Block(1,13,2,17:15)
Block(1,14,-8,17:15)
Block(1,14,-7,17:15)
Block(1,14,-6,17:15)
Block(1,14,-5,17:15)
Block(1,14,-4,17:15)
Block(1,14,-3,17:15)
Block(1,14,-2,17:15)
Block(1,14,-1,17:15)
Block(1,14,0,17:15)
Block(1,14,1,17:15)
Block(1,14,2,17:15)
Block(1,15,-8,17:15)
Block(1,15,-7,17:15)
Block(1,15,-6,17:15)
Block(1,15,-5,17:15)
Block(1,15,-4,17:15)
Block(1,15,-3,17:15)
Block(1,15,-2,17:15)
Block(1,15,-1,17:15)
Block(1,15,0,17:15)
Block(1,15,1,17:15)
Block(1,15,2,17:15)
Block(1,16,-8,17:15)
Block(1,16,-7,17:15)
Block(1,16,-6,17:15)
Block(1,16,-5,17:15)
Block(1,16,-4,17:15)
Block(1,16,-3,17:15)
Block(1,16,-2,17:15)
Block(1,16,-1,17:15)
Block(1,16,0,17:15)
Block(1,16,1,17:15)
Block(1,17,-8,17:15)
Block(1,17,-7,17:15)
Block(1,17,-6,17:15)
Block(1,17,-5,17:15)
Block(1,17,-4,17:15)
Block(1,17,-3,17:15)
Block(1,17,-2,17:15)
Block(1,17,-1,17:15)
Block(1,17,0,17:15)
Block(1,17,1,17:15)
Block(1,18,-8,17:15)
Block(1,18,-7,17:15)
Block(1,18,-6,17:15)
Block(1,18,-5,17:15)
Block(1,18,-4,17:15)
Block(1,18,-3,17:15)
Block(1,18,-2,17:15)
Block(1,18,-1,17:15)
Block(1,18,0,17:15)
Block(1,18,1,17:15)
Block(1,19,-8,17:15)
Block(1,19,-7,17:15)
Block(1,19,-6,17:15)
Block(1,19,-5,17:15)
Block(1,19,-4,17:15)
Block(1,19,-3,17:15)
Block(1,19,-2,17:15)
Block(1,19,-1,17:15)
Block(1,19,0,17:15)
Block(1,19,1,17:15)
Block(1,19,2,17:15)
Block(1,20,-7,17:15)
Block(1,20,-6,17:15)
Block(1,20,-5,17:15)
Block(1,20,-4,17:15)
Block(1,20,-3,17:15)
Block(1,20,-2,17:15)
Block(1,20,-1,17:15)
Block(1,20,0,17:15)
Block(1,20,1,17:15)
Block(1,21,-7,17:15)
Block(1,21,-6,17:15)
Block(1,21,-5,17:15)
Block(1,21,-4,17:15)
